{"E":1783504331120,"T":1783504331119,"U":10998401313214,"a":[["62067.90","12.195"],["62068.00","0.904"],["62068.10","0.001"],["62068.20","0.042"],["62068.40","0.000"],["62068.80","0.024"],["62068.90","0.160"],["62069.30","1.800"],["62069.40","0.002"],["62069.50","0.230"],["62069.60","0.000"],["62069.90","0.000"],["62070.00","1.904"],["62070.10","0.004"],["62070.20","0.001"],["62070.30","0.000"],["62070.60","0.001"],["62071.10","0.001"],["62071.20","0.001"],["62071.30","1.257"],["62071.40","0.278"],["62071.50","3.506"],["62071.60","0.296"],["62071.80","0.064"],["62071.90","0.000"],["62072.30","0.000"],["62072.80","0.576"],["62072.90","0.079"],["62073.00","0.003"],["62073.70","0.001"],["62073.80","0.000"],["62074.00","0.164"],["62074.10","0.306"],["62074.30","0.404"],["62074.40","0.029"],["62074.90","0.268"],["62075.00","0.007"],["62075.10","0.279"],["62075.30","0.676"],["62075.70","0.060"],["62075.80","0.121"],["62076.30","0.007"],["62076.60","0.000"],["62077.00","0.091"],["62077.20","0.000"],["62077.30","0.271"],["62077.60","0.166"],["62077.70","0.510"],["62077.80","0.812"],["62077.90","0.178"],["62078.00","0.301"],["62078.30","0.191"],["62078.50","0.623"],["62078.60","0.458"],["62078.70","1.364"],["62078.80","0.722"],["62079.00","0.001"],["62079.60","0.581"],["62080.50","0.051"],["62080.70","0.667"],["62080.90","0.055"],["62081.00","0.292"],["62081.10","0.003"],["62081.30","0.337"],["62081.50","0.000"],["62081.60","0.203"],["62081.80","0.050"],["62082.10","0.020"],["62082.40","0.737"],["62082.80","0.350"],["62083.00","0.000"],["62083.60","0.003"],["62083.70","2.244"],["62083.80","0.882"],["62084.00","0.086"],["62084.30","0.170"],["62084.60","0.392"],["62084.70","1.012"],["62086.50","0.702"],["62086.60","0.010"],["62086.70","0.788"],["62086.80","0.010"],["62087.90","0.003"],["62088.30","0.051"],["62088.70","0.049"],["62088.80","0.175"],["62089.50","0.068"],["62089.60","0.291"],["62090.20","0.004"],["62090.40","1.712"],["62090.90","0.001"],["62091.10","0.052"],["62092.20","0.423"],["62092.40","0.009"],["62092.90","0.248"],["62093.00","1.685"],["62093.10","1.474"],["62093.30","0.295"],["62093.80","0.095"],["62094.10","0.783"],["62095.80","0.453"],["62095.90","0.520"],["62096.00","1.557"],["62096.10","0.861"],["62096.20","0.002"],["62096.40","0.067"],["62096.90","0.099"],["62097.10","0.002"],["62097.40","0.001"],["62097.50","0.088"],["62097.60","0.455"],["62097.70","0.070"],["62098.60","0.012"],["62098.80","0.000"],["62098.90","0.839"],["62099.00","0.030"],["62099.40","1.562"],["62099.60","1.451"],["62100.00","0.645"],["62100.20","0.017"],["62100.80","0.052"],["62101.00","0.049"],["62101.30","0.001"],["62101.70","0.173"],["62101.80","2.786"],["62102.00","0.129"],["62102.30","2.480"],["62105.60","0.672"],["62107.20","0.007"],["62107.80","0.384"],["62108.30","0.184"],["62108.40","0.037"],["62108.90","0.001"],["62109.60","0.055"],["62110.00","0.454"],["62110.30","0.003"],["62110.60","0.825"],["62111.00","0.518"],["62111.30","0.006"],["62111.60","2.445"],["62111.90","0.000"],["62112.10","0.103"],["62112.50","0.015"],["62112.60","0.282"],["62112.70","0.005"],["62113.10","0.001"],["62113.70","0.104"],["62113.90","0.001"],["62114.80","0.102"],["62115.00","0.392"],["62115.80","0.706"],["62116.00","0.103"],["62116.50","0.079"],["62117.00","0.869"],["62119.20","0.000"],["62122.00","0.210"],["62123.60","0.004"],["62126.20","0.026"],["62127.90","0.001"],["62130.00","1.119"],["62134.30","4.217"],["62134.60","0.391"],["62134.70","22.657"],["62136.20","0.228"],["62136.30","1.631"],["62136.70","2.234"],["62137.30","0.133"],["62138.90","0.022"],["62139.80","3.787"],["62147.10","0.001"],["62151.70","0.163"],["62151.80","1.533"],["62155.40","0.059"],["62161.30","0.010"],["62164.90","1.853"],["62172.60","0.877"],["62172.70","2.198"],["62193.40","0.000"],["62193.50","1.528"],["62249.80","0.138"],["62260.60","0.000"],["62688.60","0.161"],["62688.80","0.000"],["62690.10","0.000"],["62785.90","4.730"],["62786.20","0.960"],["62788.90","0.946"],["62790.00","3.786"],["62848.00","2.550"],["62848.30","5.516"],["62848.40","0.806"],["62852.10","3.158"],["63025.10","1.068"],["89523.20","0.264"]],"b":[["11570.10","0.000"],["11767.80","0.272"],["11768.00","0.032"],["11867.80","0.112"],["11870.10","0.528"],["11875.50","0.656"],["11967.80","0.032"],["11975.50","0.848"],["49657.00","0.000"],["55861.00","0.013"],["55862.30","0.000"],["58964.40","0.004"],["61416.90","2.451"],["61447.10","0.000"],["61447.20","0.000"],["61447.30","0.000"],["61447.90","0.000"],["61449.40","5.240"],["61480.40","6.886"],["61727.10","0.357"],["61742.60","0.000"],["61761.10","0.015"],["61765.10","0.002"],["61766.40","0.113"],["61806.80","0.652"],["61807.60","0.436"],["61851.10","0.283"],["61860.50","0.411"],["61860.60","1.536"],["61863.50","0.000"],["61891.20","0.327"],["61900.50","0.001"],["61948.80","0.001"],["61974.70","0.009"],["61975.10","2.936"],["61981.40","0.003"],["61982.00","0.000"],["61985.10","0.001"],["61985.20","1.533"],["61994.20","19.397"],["61996.20","4.455"],["61998.40","0.006"],["61998.60","0.675"],["61998.70","1.898"],["62000.30","0.000"],["62000.50","0.004"],["62002.70","3.831"],["62003.40","0.098"],["62003.60","0.035"],["62004.70","0.023"],["62004.80","0.141"],["62004.90","0.001"],["62005.50","0.000"],["62005.70","0.245"],["62005.90","0.010"],["62006.00","1.633"],["62006.10","1.253"],["62007.10","0.158"],["62008.00","0.263"],["62009.40","0.000"],["62010.00","0.140"],["62010.80","0.000"],["62011.30","0.000"],["62012.70","0.878"],["62013.50","0.563"],["62014.80","0.000"],["62015.30","0.001"],["62016.40","0.032"],["62016.60","0.026"],["62017.70","0.122"],["62018.30","0.000"],["62019.80","0.067"],["62021.60","2.445"],["62021.90","0.164"],["62022.40","0.129"],["62022.50","0.000"],["62023.70","0.020"],["62024.60","0.294"],["62026.00","0.754"],["62026.10","0.002"],["62026.50","0.528"],["62026.70","0.003"],["62026.80","0.003"],["62027.30","0.006"],["62027.80","0.000"],["62027.90","0.005"],["62028.30","0.150"],["62030.60","0.286"],["62030.80","1.245"],["62031.50","0.065"],["62033.00","0.000"],["62033.70","0.071"],["62034.30","0.000"],["62035.10","0.002"],["62036.90","0.162"],["62037.50","0.037"],["62039.30","0.018"],["62040.90","1.295"],["62041.20","0.528"],["62041.30","0.004"],["62041.50","0.000"],["62041.80","0.049"],["62042.10","0.373"],["62042.60","1.507"],["62043.40","0.006"],["62044.30","0.016"],["62044.40","0.002"],["62044.50","0.413"],["62045.40","0.002"],["62045.70","0.129"],["62045.80","0.699"],["62046.40","0.080"],["62046.70","0.002"],["62047.50","1.941"],["62047.70","0.008"],["62048.30","0.034"],["62048.70","0.024"],["62049.00","1.023"],["62049.10","0.008"],["62049.20","0.003"],["62049.30","0.055"],["62049.40","1.721"],["62049.60","0.154"],["62049.70","0.001"],["62049.80","0.236"],["62049.90","1.413"],["62050.10","0.663"],["62050.20","0.003"],["62050.40","0.279"],["62050.90","0.001"],["62051.30","0.898"],["62051.40","0.567"],["62052.70","1.580"],["62052.80","0.534"],["62052.90","0.096"],["62053.50","0.001"],["62053.70","1.298"],["62054.20","1.174"],["62054.30","0.015"],["62055.30","0.003"],["62055.40","0.711"],["62055.50","0.001"],["62055.60","0.000"],["62055.80","0.004"],["62055.90","0.265"],["62056.00","0.022"],["62056.10","0.003"],["62056.30","0.008"],["62056.40","1.634"],["62056.80","0.878"],["62056.90","0.457"],["62057.00","0.001"],["62057.10","0.010"],["62057.20","0.002"],["62057.40","0.002"],["62057.70","0.165"],["62057.90","0.816"],["62058.00","1.368"],["62058.10","2.198"],["62058.20","0.004"],["62058.30","0.000"],["62058.50","0.129"],["62059.30","0.123"],["62059.40","0.820"],["62059.50","0.292"],["62059.60","0.048"],["62060.90","0.060"],["62061.00","0.064"],["62061.10","0.111"],["62061.20","0.080"],["62061.50","0.416"],["62061.60","0.377"],["62061.90","0.034"],["62062.50","0.101"],["62062.60","0.003"],["62062.80","0.112"],["62062.90","0.000"],["62063.10","0.006"],["62063.20","0.378"],["62063.50","0.051"],["62063.60","0.001"],["62064.60","0.000"],["62065.00","0.002"],["62066.20","0.061"],["62067.30","0.000"],["62067.40","0.049"],["62067.60","0.001"],["62067.70","0.004"],["62067.80","7.209"]],"e":"depthUpdate","ps":"BTCUSDT","pu":10998401313181,"s":"BTCUSDT","st":1,"u":10998401335117}
{"E":1783504331222,"T":1783504331221,"U":10998401335256,"a":[["62067.90","11.915"],["62068.00","0.497"],["62068.30","0.000"],["62068.70","0.080"],["62069.30","0.000"],["62070.00","1.808"],["62070.10","0.003"],["62070.30","0.000"],["62071.20","0.005"],["62071.30","0.919"],["62071.50","2.145"],["62071.80","0.000"],["62072.00","0.122"],["62072.30","0.002"],["62073.00","0.004"],["62074.20","1.308"],["62074.30","0.408"],["62074.40","0.006"],["62074.90","0.027"],["62075.20","0.295"],["62075.70","0.301"],["62076.60","0.580"],["62077.60","0.162"],["62077.70","0.514"],["62079.60","0.001"],["62080.00","0.064"],["62080.70","0.001"],["62081.10","0.567"],["62081.20","1.362"],["62081.30","0.253"],["62081.60","0.101"],["62082.30","0.004"],["62082.40","0.012"],["62083.00","0.000"],["62083.50","1.627"],["62084.70","0.432"],["62085.80","0.096"],["62086.40","0.584"],["62086.70","0.673"],["62088.70","0.169"],["62090.40","1.702"],["62090.50","0.018"],["62092.20","0.318"],["62092.40","0.007"],["62092.90","0.143"],["62093.00","1.580"],["62098.90","0.001"],["62101.80","2.786"],["62103.80","0.518"],["62104.00","0.090"],["62105.20","0.005"],["62105.70","0.430"],["62110.70","0.060"],["62111.60","1.549"],["62112.10","0.002"],["62112.20","0.380"],["62113.80","0.084"],["62115.80","0.708"],["62121.10","0.835"],["62123.50","0.000"],["62124.00","0.005"],["62124.70","1.236"],["62127.00","0.002"],["62128.00","0.955"],["62128.40","23.826"],["62130.40","4.502"],["62130.50","0.031"],["62131.00","0.001"],["62131.30","0.001"],["62131.50","0.001"],["62131.70","0.000"],["62132.60","0.090"],["62133.10","0.184"],["62134.30","0.858"],["62134.70","0.000"],["62146.90","0.019"],["62149.90","16.125"],["62154.60","0.033"],["62160.00","0.386"],["62178.00","0.002"],["62185.70","0.162"],["62240.00","0.448"],["62246.20","0.000"],["62320.00","0.384"],["62378.30","0.001"],["62380.20","0.022"],["62400.00","14.339"],["62573.30","0.019"],["62688.60","0.161"],["62752.10","3.787"],["63309.20","0.003"]],"b":[["1000.00","210.542"],["11767.80","0.544"],["11867.80","0.256"],["11870.10","0.400"],["11875.50","0.512"],["11975.50","0.704"],["55861.00","0.013"],["56546.80","0.612"],["58964.40","0.004"],["59585.00","0.028"],["61186.40","7.569"],["61198.90","3.263"],["61291.90","0.406"],["61447.10","0.000"],["61680.00","0.940"],["61760.00","0.432"],["61765.10","0.000"],["61840.00","0.288"],["61863.50","0.001"],["61891.20","0.326"],["61920.00","0.345"],["61927.90","0.024"],["61941.40","0.000"],["61957.70","0.003"],["61965.50","0.002"],["61980.80","0.222"],["61988.70","0.003"],["61991.30","0.007"],["61993.20","0.002"],["61994.20","0.287"],["61996.10","0.000"],["61996.20","0.591"],["61996.50","0.000"],["61998.00","0.292"],["62000.00","8.756"],["62000.20","1.033"],["62002.70","3.829"],["62003.30","0.420"],["62003.40","0.002"],["62004.70","0.023"],["62006.10","1.253"],["62006.80","21.283"],["62008.50","3.762"],["62016.60","0.001"],["62017.10","0.928"],["62018.20","0.002"],["62018.50","0.000"],["62019.80","0.009"],["62021.90","0.164"],["62023.20","0.002"],["62023.70","0.021"],["62024.30","0.001"],["62024.90","0.005"],["62025.50","0.004"],["62027.60","0.171"],["62030.70","0.529"],["62031.50","0.125"],["62032.20","0.017"],["62034.90","0.452"],["62038.40","0.123"],["62041.20","0.512"],["62043.40","0.004"],["62043.60","0.137"],["62044.30","0.006"],["62044.60","1.406"],["62044.90","0.005"],["62046.40","0.084"],["62046.70","0.004"],["62050.90","0.003"],["62051.40","0.003"],["62051.50","0.635"],["62052.70","1.660"],["62052.80","0.534"],["62053.20","0.022"],["62056.00","0.002"],["62056.30","0.000"],["62057.20","0.004"],["62057.60","0.004"],["62058.00","1.660"],["62058.20","0.012"],["62062.80","0.114"],["62063.30","0.003"],["62064.00","0.116"],["62064.20","0.000"],["62064.40","0.000"],["62065.70","0.000"],["62066.80","0.002"],["62067.80","7.223"]],"e":"depthUpdate","ps":"BTCUSDT","pu":10998401335117,"s":"BTCUSDT","st":1,"u":10998401350044}
{"E":1783504331324,"T":1783504331323,"U":10998401350209,"a":[["62067.90","11.899"],["62068.00","0.348"],["62068.70","0.000"],["62071.50","1.867"],["62071.60","0.295"],["62071.80","0.005"],["62072.10","0.462"],["62072.90","0.095"],["62076.30","0.002"],["62080.40","0.002"],["62081.30","0.127"],["62081.90","0.032"],["62083.80","0.962"],["62084.50","0.292"],["62091.50","1.363"],["62095.90","0.415"],["62096.00","1.452"],["62097.90","0.824"],["62104.00","0.090"],["62106.40","0.121"],["62113.70","0.003"],["62114.60","4.729"],["62114.80","0.001"],["62115.00","0.291"],["62119.80","0.423"],["62126.30","24.273"],["62128.00","1.056"],["62128.10","1.807"],["62128.30","0.000"],["62128.40","1.169"],["62128.50","0.117"],["62128.60","1.953"],["62130.40","0.989"],["62137.50","8.772"],["62155.40","0.001"],["62160.00","0.563"],["62179.80","1.361"],["62182.10","0.001"],["62224.40","0.012"],["62240.00","0.625"],["62320.00","0.561"],["62328.20","0.151"],["62378.30","0.002"],["62400.00","14.516"],["62480.00","1.182"],["62688.60","0.161"],["62782.30","1.894"],["62784.60","5.077"],["62785.90","0.000"],["62844.40","1.106"],["62844.60","0.788"],["62846.70","0.791"],["62847.50","0.271"],["62848.00","0.186"],["63232.20","0.741"],["89523.20","0.270"]],"b":[["1000.00","210.542"],["11767.80","0.816"],["11867.80","0.384"],["11870.10","0.256"],["11875.50","0.384"],["11975.50","0.576"],["55861.00","0.013"],["58964.40","0.004"],["59585.00","0.025"],["61259.70","0.001"],["61447.10","0.000"],["61680.00","1.117"],["61707.80","0.245"],["61760.00","0.609"],["61840.00","0.465"],["61863.50","0.000"],["61909.60","0.003"],["61920.00","0.522"],["61964.00","0.821"],["61964.10","2.041"],["61981.10","0.001"],["61991.30","8.365"],["62000.00","8.933"],["62000.20","1.031"],["62003.00","0.100"],["62004.10","0.002"],["62005.70","0.080"],["62006.40","0.016"],["62008.80","0.002"],["62014.20","4.702"],["62016.80","1.354"],["62023.70","0.020"],["62024.70","0.060"],["62030.90","2.196"],["62031.50","0.065"],["62037.90","0.006"],["62046.40","0.083"],["62049.10","0.009"],["62050.20","0.004"],["62051.30","0.900"],["62061.60","0.382"],["62066.20","0.007"]],"e":"depthUpdate","ps":"BTCUSDT","pu":10998401350044,"s":"BTCUSDT","st":1,"u":10998401357867}
{"E":1783504331426,"T":1783504331425,"U":10998401357891,"a":[["62070.00","1.810"],["62071.40","0.279"],["62072.90","0.079"],["62073.90","0.024"],["62074.30","0.432"],["62074.90","0.004"],["62075.20","0.536"],["62075.70","0.060"],["62076.50","0.017"],["62080.70","0.487"],["62096.10","0.756"],["62098.90","0.129"],["62102.00","0.001"],["62103.70","0.557"],["62104.00","0.027"],["62106.50","0.001"],["62110.70","0.074"],["62115.00","0.391"],["62115.80","0.607"],["62116.00","0.002"],["62117.00","0.768"],["62126.30","1.616"],["62127.00","0.103"],["62127.80","0.325"],["62128.00","0.955"],["62130.40","1.090"],["62130.50","22.688"],["62688.60","0.163"],["62752.20","0.722"],["62782.50","0.946"],["62784.60","4.131"]],"b":[["11767.80","1.088"],["11867.80","0.528"],["11870.10","0.128"],["11875.50","0.240"],["11975.50","0.432"],["55861.00","0.011"],["59585.00","0.028"],["61447.10","0.001"],["61471.90","1.077"],["61537.60","4.412"],["61727.00","0.000"],["61757.70","0.010"],["61761.10","0.005"],["61863.50","0.001"],["61960.90","1.462"],["61963.80","0.121"],["62002.40","0.034"],["62007.00","0.275"],["62021.90","0.082"],["62030.00","0.106"],["62032.20","0.001"],["62033.70","0.001"],["62041.70","0.071"],["62044.60","1.390"],["62046.90","0.001"],["62056.90","0.325"],["62058.10","2.066"],["62058.50","0.129"],["62063.30","0.085"],["62067.40","0.051"]],"e":"depthUpdate","ps":"BTCUSDT","pu":10998401357867,"s":"BTCUSDT","st":1,"u":10998401370677}
{"E":1783504331528,"T":1783504331525,"U":10998401370732,"a":[["62067.90","11.928"],["62068.00","0.352"],["62068.30","0.049"],["62070.60","0.017"],["62071.20","0.005"],["62071.40","0.281"],["62073.00","1.366"],["62073.90","0.024"],["62074.30","0.432"],["62074.40","0.006"],["62075.10","0.278"],["62075.20","0.295"],["62076.50","0.001"],["62076.60","0.000"],["62078.30","0.207"],["62078.40","0.877"],["62081.50","0.725"],["62081.60","0.181"],["62083.50","0.902"],["62083.80","0.882"],["62089.50","0.149"],["62089.60","0.163"],["62095.10","0.343"],["62095.70","0.225"],["62095.80","0.453"],["62100.90","0.017"],["62101.60","0.000"],["62101.90","0.383"],["62102.60","0.016"],["62103.00","0.127"],["62103.70","0.452"],["62103.80","0.413"],["62105.20","0.107"],["62107.10","0.039"],["62109.00","2.545"],["62109.10","0.149"],["62126.20","0.127"],["62126.30","1.616"],["62127.00","0.002"],["62130.00","1.364"],["62130.40","4.345"],["62130.50","22.688"],["62167.10","0.004"],["62174.40","0.011"],["62202.20","0.012"],["62203.70","0.870"],["62444.10","0.002"],["62688.60","0.161"],["63300.80","0.021"],["67487.30","0.002"],["89523.20","0.276"]],"b":[["1000.00","210.542"],["11667.80","0.144"],["11767.80","1.216"],["11775.50","0.304"],["11867.80","0.656"],["11875.50","0.112"],["11975.50","0.304"],["49654.00","0.000"],["55861.00","0.013"],["61112.40","0.061"],["61268.50","0.326"],["61447.10","0.001"],["61571.30","0.327"],["61863.50","0.000"],["61937.20","1.924"],["61938.30","0.000"],["62002.40","0.032"],["62002.60","0.048"],["62002.80","0.443"],["62012.70","1.763"],["62021.90","0.518"],["62024.70","0.000"],["62025.00","0.012"],["62025.40","0.370"],["62031.70","0.061"],["62041.30","0.004"],["62041.70","2.529"],["62044.80","1.686"],["62047.60","0.218"],["62048.00","0.755"],["62050.50","0.824"],["62050.60","1.067"],["62050.90","0.729"],["62051.00","0.161"],["62051.30","0.175"],["62051.50","0.071"],["62052.70","1.580"],["62052.90","0.258"],["62053.60","0.405"],["62055.00","1.811"],["62056.10","0.001"],["62056.20","1.194"],["62057.20","0.085"],["62057.50","0.003"],["62058.20","0.388"],["62058.30","0.082"],["62058.60","0.000"],["62058.70","0.052"],["62059.60","0.210"],["62060.70","0.358"],["62063.30","0.135"],["62063.40","0.056"],["62067.40","0.002"],["62067.80","6.267"]],"e":"depthUpdate","ps":"BTCUSDT","pu":10998401370677,"s":"BTCUSDT","st":1,"u":10998401378667}
{"E":1783504331630,"T":1783504331629,"U":10998401379320,"a":[["62067.90","11.995"],["62068.00","0.344"],["62068.80","0.056"],["62070.60","0.001"],["62071.20","0.001"],["62071.80","0.000"],["62074.30","0.428"],["62074.50","0.080"],["62074.60","0.000"],["62076.80","1.300"],["62081.60","0.101"],["62128.30","0.101"],["62128.40","23.826"],["62130.40","0.989"],["62130.50","0.031"],["62151.10","0.008"],["62335.30","0.000"],["62688.60","0.161"],["62782.50","1.892"],["62784.60","3.185"],["62851.60","5.639"],["63309.20","0.006"]],"b":[["1000.00","210.542"],["11667.80","0.272"],["11767.80","1.360"],["11775.50","0.176"],["11867.80","0.800"],["11874.30","0.000"],["11875.40","0.000"],["11875.50","0.000"],["11975.50","0.160"],["55861.00","0.015"],["59585.00","0.025"],["61447.10","0.001"],["61759.70","0.324"],["61761.10","0.003"],["61854.80","0.000"],["61863.50","0.001"],["61963.40","0.003"],["62002.80","0.007"],["62003.20","0.000"],["62008.80","0.158"],["62024.10","0.179"],["62031.70","0.001"],["62035.70","0.016"],["62038.90","0.013"],["62041.20","0.510"],["62041.30","0.002"],["62041.40","0.000"],["62051.30","0.173"],["62055.70","0.005"],["62057.30","0.333"],["62057.40","0.000"],["62057.50","0.001"],["62059.70","0.002"],["62061.60","0.377"],["62067.80","6.269"]],"e":"depthUpdate","ps":"BTCUSDT","pu":10998401378667,"s":"BTCUSDT","st":1,"u":10998401387388}
{"E":1783504331732,"T":1783504331731,"U":10998401387503,"a":[["62067.90","12.488"],["62068.80","0.058"],["62069.40","0.004"],["62069.90","1.654"],["62070.20","0.324"],["62070.40","0.002"],["62071.20","0.146"],["62071.50","1.803"],["62071.80","0.004"],["62073.00","1.382"],["62073.60","0.123"],["62073.90","0.024"],["62074.00","0.164"],["62074.10","0.165"],["62074.30","0.404"],["62074.40","0.006"],["62074.50","0.000"],["62075.00","0.006"],["62076.60","0.322"],["62077.80","1.057"],["62078.30","0.771"],["62078.40","1.752"],["62080.20","0.005"],["62081.10","0.003"],["62081.30","0.207"],["62082.80","0.028"],["62084.90","0.051"],["62086.70","0.669"],["62087.80","0.335"],["62089.50","0.068"],["62089.60","0.291"],["62090.50","0.008"],["62092.00","0.011"],["62095.70","0.064"],["62096.70","0.008"],["62097.00","0.003"],["62097.50","0.080"],["62098.20","0.056"],["62098.60","0.004"],["62099.10","0.126"],["62099.30","0.163"],["62101.80","2.776"],["62103.80","0.413"],["62110.00","0.450"],["62110.20","0.507"],["62110.40","0.004"],["62111.70","4.022"],["62112.20","0.378"],["62113.80","0.082"],["62114.60","4.731"],["62118.90","0.037"],["62121.40","0.020"],["62136.20","0.096"],["62137.30","0.001"],["62217.20","2.662"],["62688.60","0.163"],["62782.50","2.838"],["62788.90","0.000"],["62844.40","1.894"],["62848.30","4.728"],["63300.70","0.061"],["63300.80","0.018"],["89523.20","0.282"]],"b":[["11667.80","0.416"],["11767.80","1.488"],["11775.50","0.032"],["11867.80","0.928"],["11870.10","0.064"],["11871.70","0.000"],["11871.90","0.000"],["11975.50","0.032"],["55861.00","0.013"],["56546.80","0.000"],["59585.00","0.028"],["60816.90","0.000"],["61447.10","0.001"],["61757.70","0.010"],["61863.50","0.000"],["61891.20","0.327"],["61975.80","0.132"],["61986.00","0.038"],["62002.10","0.646"],["62007.00","0.407"],["62007.90","0.026"],["62013.90","0.294"],["62014.20","4.704"],["62018.20","0.018"],["62018.70","0.002"],["62018.80","1.366"],["62018.90","0.294"],["62020.20","0.706"],["62020.50","0.016"],["62020.70","9.352"],["62022.00","0.100"],["62022.10","0.000"],["62027.60","0.146"],["62028.50","0.885"],["62029.70","0.016"],["62030.80","1.235"],["62031.50","0.079"],["62031.70","0.004"],["62031.80","0.002"],["62034.00","1.601"],["62034.10","0.064"],["62035.50","1.342"],["62035.70","0.000"],["62037.60","0.698"],["62039.20","0.017"],["62039.30","0.004"],["62039.60","0.009"],["62039.90","0.013"],["62040.50","0.069"],["62040.80","0.001"],["62040.90","1.307"],["62041.20","0.502"],["62041.70","2.459"],["62041.90","0.000"],["62042.10","0.383"],["62043.30","0.001"],["62043.60","0.125"],["62044.50","0.403"],["62044.80","1.364"],["62046.40","0.079"],["62046.70","0.002"],["62047.60","0.218"],["62048.30","0.054"],["62048.40","0.758"],["62049.00","1.027"],["62049.70","1.001"],["62050.20","0.568"],["62050.60","0.342"],["62050.90","0.487"],["62051.00","0.000"],["62052.20","0.008"],["62052.90","0.258"],["62053.20","0.002"],["62054.20","0.174"],["62054.90","0.016"],["62055.40","0.707"],["62055.90","0.002"],["62056.40","0.808"],["62056.70","0.001"],["62056.90","0.003"],["62057.10","0.006"],["62057.20","0.002"],["62058.00","0.006"],["62058.10","1.149"],["62058.20","0.166"],["62058.30","0.000"],["62058.50","0.179"],["62059.30","0.002"],["62059.40","0.822"],["62059.60","0.790"],["62060.60","0.008"],["62061.50","0.000"],["62061.60","0.331"],["62061.90","0.038"],["62062.40","0.004"],["62062.60","0.001"],["62063.10","0.008"],["62063.20","0.055"],["62063.30","0.003"],["62064.00","0.112"],["62067.70","0.103"],["62067.80","0.816"]],"e":"depthUpdate","ps":"BTCUSDT","pu":10998401387388,"s":"BTCUSDT","st":1,"u":10998401401891}
{"E":1783504331834,"T":1783504331833,"U":10998401402052,"a":[["62067.00","9.187"],["62067.10","0.002"],["62067.20","0.001"],["62067.30","0.001"],["62067.50","0.000"],["62067.70","1.800"],["62067.80","1.804"],["62067.90","0.198"],["62068.00","0.002"],["62068.10","0.000"],["62068.30","0.000"],["62068.40","0.001"],["62068.50","0.001"],["62068.80","0.056"],["62069.20","0.005"],["62069.40","0.002"],["62069.80","0.000"],["62070.00","1.812"],["62070.10","0.003"],["62070.20","0.323"],["62070.40","0.001"],["62071.10","0.003"],["62071.20","0.005"],["62071.30","0.920"],["62071.40","0.734"],["62071.50","0.066"],["62071.60","0.119"],["62071.70","0.001"],["62071.80","0.004"],["62071.90","0.000"],["62072.10","0.703"],["62072.60","0.000"],["62072.70","0.000"],["62072.90","0.221"],["62073.00","1.366"],["62073.10","0.051"],["62073.20","1.001"],["62073.60","0.044"],["62073.70","0.246"],["62073.90","0.024"],["62074.00","0.002"],["62074.10","0.003"],["62074.20","0.308"],["62074.60","0.000"],["62074.80","0.001"],["62074.90","0.004"],["62075.00","0.330"],["62075.30","0.680"],["62075.70","0.382"],["62076.30","0.003"],["62076.50","0.325"],["62076.60","0.008"],["62076.90","0.055"],["62077.40","1.218"],["62077.50","0.004"],["62077.60","0.000"],["62077.70","0.838"],["62078.30","0.191"],["62078.40","1.188"],["62078.50","0.301"],["62079.10","0.001"],["62079.20","0.000"],["62079.50","0.002"],["62080.20","0.327"],["62080.30","0.001"],["62080.40","0.001"],["62080.60","0.007"],["62080.70","1.051"],["62081.10","0.004"],["62081.20","2.087"],["62081.30","0.127"],["62081.50","0.000"],["62082.10","0.000"],["62082.20","0.000"],["62082.30","0.002"],["62082.90","0.450"],["62083.00","0.000"],["62083.30","0.279"],["62083.70","2.246"],["62083.80","0.882"],["62084.00","0.084"],["62084.20","0.583"],["62084.30","0.170"],["62084.60","0.392"],["62085.10","0.003"],["62085.70","0.012"],["62085.80","0.096"],["62086.40","0.004"],["62086.50","0.702"],["62086.60","0.001"],["62087.30","0.121"],["62087.80","0.325"],["62088.30","0.115"],["62088.70","0.049"],["62088.80","0.174"],["62089.00","0.000"],["62089.50","0.004"],["62089.60","0.001"],["62089.90","0.341"],["62090.00","1.848"],["62090.20","0.003"],["62091.80","0.465"],["62092.20","0.067"],["62092.40","0.006"],["62092.60","0.050"],["62092.90","0.054"],["62093.50","0.000"],["62094.00","0.764"],["62094.40","0.661"],["62094.60","0.011"],["62095.80","0.325"],["62095.90","0.001"],["62096.00","1.363"],["62096.10","0.667"],["62096.30","0.058"],["62096.70","0.000"],["62097.50","0.091"],["62097.80","0.069"],["62097.90","0.824"],["62098.00","0.168"],["62098.20","0.048"],["62098.30","0.001"],["62098.60","0.001"],["62098.80","0.000"],["62098.90","0.001"],["62099.00","0.030"],["62099.10","0.116"],["62099.30","0.163"],["62099.70","0.660"],["62099.80","0.606"],["62100.30","0.026"],["62101.10","0.129"],["62101.30","0.011"],["62101.70","0.173"],["62101.90","0.061"],["62102.30","2.480"],["62103.00","0.129"],["62103.50","0.007"],["62103.80","0.324"],["62106.00","0.009"],["62107.50","0.307"],["62107.70","0.002"],["62109.50","0.021"],["62110.10","3.540"],["62110.40","0.001"],["62111.60","2.200"],["62111.70","4.123"],["62111.90","0.003"],["62112.50","0.030"],["62112.70","0.106"],["62113.30","0.003"],["62114.40","0.102"],["62116.90","0.000"],["62117.00","0.771"],["62119.50","0.001"],["62121.10","0.820"],["62124.00","0.008"],["62124.80","0.667"],["62126.20","0.026"],["62126.60","0.001"],["62127.00","0.000"],["62128.10","1.807"],["62128.30","0.101"],["62128.40","23.748"],["62128.50","0.121"],["62128.60","1.949"],["62132.60","0.090"],["62132.90","0.796"],["62133.00","1.370"],["62133.10","0.180"],["62136.20","0.228"],["62136.60","0.040"],["62136.80","0.116"],["62141.00","0.016"],["62142.50","0.153"],["62145.20","0.322"],["62151.80","0.005"],["62151.90","2.767"],["62193.50","0.001"],["62193.60","1.539"],["62242.40","0.010"],["62242.90","0.005"],["62331.30","0.683"],["62380.20","0.004"],["62643.90","0.187"],["62687.70","0.002"],["62688.60","0.161"],["62712.90","0.188"],["62781.80","4.470"],["62782.30","2.840"],["62784.60","2.239"],["62844.40","2.682"],["62844.60","2.364"],["62847.50","0.541"],["62848.30","3.152"],["62852.10","2.370"],["63067.80","0.162"],["63067.90","0.002"],["63071.60","0.000"],["63071.80","0.000"]],"b":[["1000.00","210.542"],["11666.90","0.176"],["11667.80","0.448"],["11766.90","0.016"],["11767.80","1.536"],["11771.50","0.960"],["11774.10","0.000"],["11775.50","0.000"],["11866.90","0.112"],["11867.80","0.960"],["11870.10","0.000"],["11971.50","0.464"],["11974.10","0.000"],["11975.50","0.000"],["55860.20","0.003"],["55861.00","0.011"],["58939.00","0.100"],["59585.00","0.025"],["60783.20","0.187"],["60825.60","0.006"],["60852.10","0.213"],["60921.10","0.187"],["60990.00","1.502"],["61058.90","0.187"],["61127.80","0.235"],["61161.60","0.572"],["61196.70","1.003"],["61265.60","0.189"],["61334.50","1.849"],["61403.50","0.682"],["61446.20","0.000"],["61446.30","0.000"],["61447.00","0.027"],["61447.10","0.001"],["61797.40","0.009"],["61805.50","1.121"],["61860.60","0.000"],["61860.70","1.538"],["61863.50","0.001"],["61963.20","0.000"],["61963.60","0.005"],["61964.50","0.001"],["61968.00","0.076"],["61974.70","0.001"],["61975.80","0.000"],["61978.20","0.026"],["61985.20","0.003"],["61985.30","1.530"],["61992.40","0.000"],["61998.40","19.205"],["62002.80","0.102"],["62003.30","0.324"],["62004.30","0.002"],["62005.30","0.015"],["62006.00","0.104"],["62006.10","2.205"],["62006.80","2.173"],["62007.00","0.711"],["62012.70","0.878"],["62014.30","0.001"],["62016.40","0.017"],["62018.00","0.258"],["62018.20","0.020"],["62018.80","1.363"],["62019.80","0.007"],["62022.00","0.100"],["62022.90","0.000"],["62024.30","0.000"],["62024.90","0.004"],["62025.40","0.309"],["62027.20","0.001"],["62028.30","0.151"],["62028.50","0.878"],["62029.70","0.026"],["62030.80","1.239"],["62033.30","0.041"],["62033.40","0.122"],["62033.60","1.383"],["62033.90","0.339"],["62034.60","2.268"],["62036.90","0.122"],["62038.80","0.011"],["62039.20","0.004"],["62039.50","0.003"],["62039.60","0.001"],["62040.10","0.048"],["62040.40","0.010"],["62040.50","0.061"],["62040.70","0.026"],["62040.90","1.295"],["62041.00","0.881"],["62041.30","0.002"],["62041.60","0.001"],["62042.10","0.383"],["62043.20","0.048"],["62043.50","0.005"],["62044.00","0.210"],["62044.70","0.005"],["62044.90","0.053"],["62045.30","0.580"],["62045.50","0.122"],["62046.00","0.002"],["62046.50","0.085"],["62046.90","0.009"],["62047.60","0.056"],["62047.70","0.000"],["62048.00","0.739"],["62048.60","0.011"],["62049.10","0.573"],["62049.60","0.106"],["62049.70","0.001"],["62050.20","0.004"],["62050.80","2.145"],["62050.90","0.003"],["62051.00","0.000"],["62051.40","0.131"],["62051.60","0.154"],["62051.80","0.004"],["62051.90","0.124"],["62052.20","0.005"],["62052.90","0.258"],["62053.20","0.002"],["62053.40","0.124"],["62053.60","0.401"],["62053.90","0.325"],["62054.00","0.003"],["62054.10","1.050"],["62054.50","0.391"],["62054.90","0.014"],["62055.00","2.074"],["62055.10","0.002"],["62055.40","1.139"],["62055.60","0.005"],["62055.70","0.000"],["62055.90","0.002"],["62056.30","0.000"],["62056.40","0.486"],["62056.90","0.003"],["62057.30","0.325"],["62057.60","0.132"],["62057.90","0.818"],["62058.00","0.994"],["62058.10","2.336"],["62058.20","1.224"],["62058.30","0.000"],["62058.50","0.001"],["62058.60","0.000"],["62059.20","0.445"],["62059.40","0.828"],["62059.60","0.048"],["62059.90","0.001"],["62060.10","0.052"],["62060.30","0.006"],["62060.80","0.063"],["62061.00","0.064"],["62061.60","0.003"],["62061.70","0.054"],["62061.90","0.034"],["62062.10","0.005"],["62062.40","0.001"],["62062.50","0.092"],["62062.70","0.002"],["62062.80","0.080"],["62062.90","0.049"],["62063.10","0.002"],["62063.20","0.006"],["62063.30","0.001"],["62063.90","0.323"],["62064.00","0.111"],["62064.20","0.001"],["62064.70","0.005"],["62065.10","0.006"],["62066.20","0.010"],["62066.30","0.001"],["62066.80","0.006"],["62066.90","8.625"],["62067.10","0.000"],["62067.20","0.000"],["62067.40","0.000"],["62067.60","0.000"],["62067.70","0.000"],["62067.80","0.000"]],"e":"depthUpdate","ps":"BTCUSDT","pu":10998401401891,"s":"BTCUSDT","st":1,"u":10998401417788}
{"E":1783504331936,"T":1783504331933,"U":10998401417876,"a":[["62067.00","9.197"],["62067.70","0.000"],["62067.80","0.000"],["62067.90","0.102"],["62069.30","0.004"],["62069.40","0.004"],["62069.80","0.569"],["62070.00","1.811"],["62070.10","0.005"],["62070.20","0.000"],["62071.40","0.733"],["62071.70","0.004"],["62072.20","0.002"],["62073.10","0.052"],["62073.60","0.021"],["62073.70","0.005"],["62074.80","0.001"],["62075.30","0.921"],["62075.70","0.382"],["62077.40","1.268"],["62079.00","0.017"],["62081.20","1.362"],["62082.20","0.725"],["62084.20","0.003"],["62084.90","0.049"],["62085.60","0.583"],["62085.70","0.004"],["62086.90","0.009"],["62087.00","0.081"],["62087.20","0.070"],["62087.30","0.001"],["62088.40","0.120"],["62094.10","0.713"],["62094.80","0.002"],["62103.80","0.413"],["62112.50","0.015"],["62118.80","0.015"],["62137.30","0.133"],["62217.90","1.326"],["62243.10","0.028"],["62687.70","0.002"],["62770.90","2.882"],["62782.20","2.058"],["62782.30","3.786"],["62789.90","2.838"],["62790.00","2.840"],["62820.50","1.065"],["62850.70","0.187"],["62919.60","0.187"],["62988.50","0.187"],["63057.40","0.201"],["63126.30","0.187"],["63195.30","0.187"],["63264.20","0.187"],["89523.20","0.288"]],"b":[["1000.00","210.542"],["11666.90","0.448"],["11771.50","0.688"],["11866.90","0.240"],["11971.50","0.336"],["55860.20","0.003"],["59584.20","0.042"],["61293.10","1.064"],["61446.20","0.000"],["61756.60","0.001"],["61863.50","0.000"],["61871.30","0.001"],["61885.60","0.025"],["61998.40","0.006"],["62001.70","0.156"],["62002.60","0.144"],["62002.80","0.006"],["62004.80","0.394"],["62005.30","0.000"],["62006.80","21.372"],["62007.20","0.158"],["62008.50","0.959"],["62012.40","2.015"],["62020.20","0.681"],["62027.30","0.031"],["62042.90","0.023"],["62043.50","0.003"],["62046.30","0.099"],["62048.40","0.033"],["62049.40","1.723"],["62050.70","0.329"],["62050.80","2.870"],["62052.40","0.051"],["62054.50","0.138"],["62054.90","0.012"],["62058.30","0.132"],["62060.70","0.486"],["62062.10","0.009"],["62062.90","0.052"],["62064.10","0.002"],["62066.90","8.627"]],"e":"depthUpdate","ps":"BTCUSDT","pu":10998401417788,"s":"BTCUSDT","st":1,"u":10998401424396}
{"E":1783504332038,"T":1783504332037,"U":10998401424628,"a":[["62067.00","8.515"],["62067.80","0.000"],["62067.90","0.034"],["62070.00","1.806"],["62070.70","0.016"],["62072.20","0.001"],["62072.90","0.222"],["62074.20","0.308"],["62075.00","0.330"],["62075.30","0.680"],["62079.00","0.001"],["62082.20","0.805"],["62083.80","0.880"],["62084.30","0.170"],["62086.70","0.714"],["62087.00","0.001"],["62103.80","0.518"],["62110.00","0.450"],["62111.60","2.099"],["62111.70","4.022"],["62112.70","0.005"],["62126.20","0.127"],["62126.30","24.193"],["62126.40","0.118"],["62128.30","0.000"],["62128.40","1.171"],["62168.50","3.646"],["62169.50","11.495"],["62188.00","0.110"],["62687.70","0.002"],["62782.20","3.004"],["62789.90","1.892"],["62844.30","1.579"],["62846.70","0.003"],["62852.10","1.582"]],"b":[["11666.90","0.720"],["11771.50","0.416"],["11866.90","0.384"],["11971.50","0.192"],["49653.50","0.002"],["55860.20","0.003"],["61446.20","0.000"],["61757.50","0.017"],["61757.70","0.000"],["61863.50","0.001"],["61955.90","11.861"],["61956.30","2.154"],["62024.10","0.119"],["62031.50","0.139"],["62042.70","0.165"],["62049.10","0.009"],["62049.30","0.006"],["62050.90","0.729"],["62052.70","1.578"],["62052.90","0.420"],["62053.70","1.300"],["62055.00","2.072"],["62060.90","0.061"],["62061.40","0.245"],["62066.80","0.008"]],"e":"depthUpdate","ps":"BTCUSDT","pu":10998401424396,"s":"BTCUSDT","st":1,"u":10998401433967}
{"E":1783504332140,"T":1783504332139,"U":10998401434326,"a":[["62067.00","7.667"],["62067.10","0.001"],["62067.90","0.041"],["62068.00","0.027"],["62069.60","0.001"],["62069.90","1.665"],["62070.70","0.000"],["62080.00","0.046"],["62080.80","1.105"],["62082.20","0.725"],["62082.90","0.452"],["62085.00","0.701"],["62086.50","0.002"],["62104.00","0.116"],["62111.20","0.055"],["62114.40","0.001"],["62119.90","0.012"],["62160.00","0.545"],["62240.00","0.607"],["62320.00","0.543"],["62400.00","14.498"],["62687.70","0.002"],["62770.90","1.927"],["62782.20","3.950"],["62782.50","3.784"],["62789.90","0.946"],["62790.00","1.894"],["62844.30","2.367"],["62852.10","0.794"],["63005.80","0.277"],["67642.80","0.012"],["89523.20","0.294"]],"b":[["1000.00","210.542"],["11666.90","0.992"],["11771.50","0.144"],["11866.90","0.512"],["11971.50","0.064"],["49653.50","0.000"],["49654.00","0.000"],["55860.20","0.003"],["59584.20","0.039"],["61082.00","0.000"],["61104.60","0.009"],["61291.10","0.287"],["61293.10","0.086"],["61446.20","0.000"],["61567.00","200.390"],["61598.70","0.410"],["61680.00","1.099"],["61760.00","0.591"],["61840.00","0.447"],["61863.50","0.000"],["61920.00","0.504"],["61988.60","0.047"],["62000.00","8.915"],["62001.00","0.061"],["62008.50","0.975"],["62010.30","0.051"],["62013.40","0.447"],["62038.00","0.003"],["62041.80","0.002"],["62048.90","0.138"],["62051.40","0.003"],["62051.80","0.006"],["62054.10","1.003"],["62054.50","0.010"],["62057.30","0.278"],["62057.60","0.004"],["62058.00","0.298"],["62058.30","1.640"],["62061.70","0.052"],["62066.90","8.476"]],"e":"depthUpdate","ps":"BTCUSDT","pu":10998401433967,"s":"BTCUSDT","st":1,"u":10998401442796}
{"E":1783504332242,"T":1783504332241,"U":10998401442989,"a":[["62067.00","7.589"],["62068.00","0.011"],["62068.40","0.001"],["62069.20","0.001"],["62071.80","0.008"],["62074.20","0.549"],["62080.00","0.062"],["62080.80","1.025"],["62090.70","0.085"],["62091.80","0.337"],["62094.60","0.001"],["62098.00","0.129"],["62099.00","0.069"],["62101.10","0.001"],["62104.00","0.221"],["62242.90","0.002"],["62243.30","0.006"],["62377.40","0.053"],["62378.30","0.001"],["62687.70","0.002"],["62806.50","0.954"],["63029.20","0.009"]],"b":[["1000.00","210.542"],["11666.90","1.264"],["11766.90","0.032"],["11767.80","1.472"],["11768.00","0.000"],["11769.90","0.000"],["11770.00","0.000"],["11771.50","0.000"],["11866.90","0.640"],["11867.80","0.944"],["11967.80","0.000"],["11969.30","0.000"],["11971.30","0.000"],["11971.50","0.000"],["55860.20","0.003"],["59584.20","0.042"],["61053.40","0.279"],["61073.80","1.145"],["61328.30","0.977"],["61446.20","0.000"],["61756.60","0.002"],["61818.90","0.000"],["61863.50","0.001"],["61868.70","0.027"],["61887.00","0.733"],["61920.70","2.039"],["61963.60","0.002"],["61964.00","0.824"],["61988.60","0.000"],["62000.30","0.000"],["62000.80","0.001"],["62001.00","0.014"],["62002.80","0.004"],["62010.30","0.004"],["62013.40","0.400"],["62024.10","0.135"],["62029.10","0.040"],["62033.20","0.152"],["62033.30","0.001"],["62039.60","0.017"],["62042.30","2.054"],["62042.90","0.021"],["62043.00","0.700"],["62045.60","0.051"],["62054.90","0.059"],["62057.90","0.865"],["62058.00","0.298"],["62058.10","0.974"],["62058.20","2.586"],["62058.40","0.132"],["62064.00","0.113"],["62064.70","0.001"],["62065.90","0.004"],["62066.90","8.481"]],"e":"depthUpdate","ps":"BTCUSDT","pu":10998401442796,"s":"BTCUSDT","st":1,"u":10998401451731}
{"E":1783504332344,"T":1783504332343,"U":10998401451948,"a":[["62067.00","7.590"],["62080.00","0.028"],["62080.80","1.750"],["62082.20","0.000"],["62087.50","0.073"],["62090.70","0.005"],["62101.10","0.129"],["62101.50","0.013"],["62152.00","0.730"],["62158.20","1.285"],["62160.00","0.545"],["62162.30","0.001"],["62164.40","1.467"],["62168.50","3.630"],["62174.70","0.014"],["62240.00","0.607"],["62320.00","0.543"],["62378.30","0.000"],["62400.00","14.498"],["62480.00","1.200"],["62687.70","0.002"],["62949.50","0.278"],["63228.80","0.947"],["89523.20","0.300"]],"b":[["11666.90","1.536"],["11766.90","0.160"],["11767.80","1.200"],["11867.80","0.816"],["49654.00","0.000"],["55860.20","0.003"],["59584.20","0.039"],["60908.80","0.003"],["61294.40","1.757"],["61446.20","0.000"],["61447.10","0.000"],["61537.60","0.356"],["61680.00","1.099"],["61756.50","0.002"],["61757.50","0.007"],["61757.70","0.010"],["61760.00","0.591"],["61840.00","0.447"],["61849.50","0.540"],["61863.50","0.000"],["61908.00","1.040"],["61920.00","0.504"],["62000.00","8.915"],["62001.80","0.682"],["62013.80","0.059"],["62025.00","0.002"],["62025.20","0.098"],["62041.70","3.079"],["62045.10","0.304"],["62045.40","0.006"],["62049.60","0.831"],["62050.30","0.024"],["62050.80","2.145"],["62065.50","0.002"],["62066.90","8.532"]],"e":"depthUpdate","ps":"BTCUSDT","pu":10998401451731,"s":"BTCUSDT","st":1,"u":10998401460260}
{"E":1783504332446,"T":1783504332445,"U":10998401460342,"a":[["62067.70","0.001"],["62068.30","0.049"],["62069.40","0.014"],["62069.70","0.816"],["62069.80","1.145"],["62070.10","0.328"],["62072.80","0.000"],["62073.60","0.262"],["62074.20","0.308"],["62074.90","0.801"],["62076.60","0.330"],["62077.30","0.287"],["62078.70","1.364"],["62080.10","0.726"],["62080.20","0.005"],["62080.70","1.051"],["62080.80","1.025"],["62081.60","0.101"],["62087.50","0.057"],["62088.70","0.129"],["62101.50","0.003"],["62102.30","2.375"],["62103.70","0.557"],["62104.00","0.027"],["62126.30","24.195"],["62126.40","0.017"],["62126.50","2.413"],["62136.20","0.096"],["62137.30","0.001"],["62160.00","0.563"],["62240.00","0.625"],["62320.00","0.561"],["62400.00","14.516"],["62480.00","1.218"],["62687.70","0.002"],["62778.40","3.167"],["62781.40","5.045"],["62782.20","1.112"],["62789.90","0.000"],["62806.70","1.749"],["62843.50","2.364"],["62844.30","0.003"],["62968.10","0.079"]],"b":[["1000.00","210.542"],["11666.90","1.808"],["11766.90","0.304"],["11767.80","0.928"],["11867.80","0.672"],["55860.20","0.003"],["59584.20","0.042"],["60818.50","0.009"],["61252.90","1.893"],["61291.20","1.630"],["61328.40","1.399"],["61446.20","0.002"],["61570.40","4.054"],["61680.00","1.117"],["61760.00","0.609"],["61840.00","0.465"],["61863.50","0.001"],["61920.00","0.522"],["61986.20","0.001"],["61998.60","0.675"],["62000.00","8.933"],["62007.10","0.290"],["62007.90","0.073"],["62010.90","0.013"],["62021.90","0.164"],["62022.00","0.018"],["62033.20","0.152"],["62041.30","0.014"],["62041.70","2.459"],["62042.10","0.373"],["62042.30","2.052"],["62042.70","0.003"],["62045.40","0.004"],["62045.60","0.051"],["62049.00","1.752"],["62049.60","0.106"],["62050.90","0.567"],["62051.00","0.322"],["62052.90","0.258"],["62054.90","0.012"],["62057.60","0.132"],["62057.90","0.049"],["62058.20","0.902"],["62058.30","0.851"],["62058.40","0.000"],["62059.30","0.004"],["62059.60","0.048"],["62060.70","0.358"],["62061.90","0.038"],["62063.50","0.048"],["62063.90","0.000"],["62064.00","0.111"],["62064.10","0.000"],["62064.60","0.004"],["62065.90","0.000"],["62066.80","0.006"],["62066.90","4.592"]],"e":"depthUpdate","ps":"BTCUSDT","pu":10998401460260,"s":"BTCUSDT","st":1,"u":10998401469887}
{"E":1783504332548,"T":1783504332546,"U":10998401469895,"a":[["62067.00","7.605"],["62068.10","0.004"],["62069.00","0.001"],["62069.30","0.000"],["62069.40","0.094"],["62069.50","1.162"],["62069.60","0.903"],["62069.80","0.576"],["62071.40","0.734"],["62071.50","0.067"],["62072.20","0.001"],["62072.90","0.221"],["62075.00","0.168"],["62076.60","0.000"],["62077.30","0.271"],["62077.40","0.374"],["62078.30","0.755"],["62080.00","0.350"],["62080.70","0.487"],["62088.70","0.049"],["62089.90","0.422"],["62096.10","0.828"],["62097.70","0.078"],["62099.30","0.295"],["62099.70","0.674"],["62101.70","0.305"],["62102.30","2.697"],["62103.60","0.111"],["62103.70","0.646"],["62103.80","0.413"],["62109.60","0.041"],["62687.70","0.002"],["62844.00","1.909"],["89523.20","0.306"]],"b":[["1000.00","210.542"],["11666.90","2.080"],["11766.90","0.432"],["11767.80","0.656"],["11867.80","0.544"],["49654.00","0.002"],["55860.20","0.003"],["61221.90","0.000"],["61343.20","0.000"],["61446.20","0.000"],["61715.00","0.166"],["61756.60","0.012"],["61757.70","0.000"],["61863.50","0.000"],["61964.00","0.821"],["61964.10","2.044"],["61975.80","0.000"],["61986.60","0.798"],["61999.00","0.010"],["62006.20","0.020"],["62007.90","0.026"],["62008.30","0.047"],["62011.30","0.000"],["62012.10","0.669"],["62014.40","0.000"],["62018.40","0.019"],["62025.10","0.017"],["62031.50","0.125"],["62033.20","0.152"],["62037.50","0.045"],["62042.60","1.140"],["62042.70","0.165"],["62044.10","0.177"],["62045.20","0.331"],["62045.40","0.002"],["62045.50","0.002"],["62045.60","0.051"],["62049.60","0.670"],["62050.00","0.005"],["62050.90","0.165"],["62051.00","0.000"],["62051.10","0.003"],["62051.40","0.164"],["62051.90","0.491"],["62052.90","0.420"],["62054.90","0.014"],["62055.50","0.163"],["62056.70","0.001"],["62056.90","0.003"],["62057.60","0.213"],["62057.80","0.005"],["62057.90","0.047"],["62058.30","1.173"],["62059.40","0.820"],["62059.60","0.130"],["62063.70","0.022"],["62064.60","0.005"],["62066.20","0.012"],["62066.40","0.000"],["62066.90","4.562"]],"e":"depthUpdate","ps":"BTCUSDT","pu":10998401469887,"s":"BTCUSDT","st":1,"u":10998401481985}
{"E":1783504332650,"T":1783504332649,"U":10998401482149,"a":[["62067.00","8.259"],["62069.20","0.017"],["62069.40","0.004"],["62069.80","0.000"],["62071.10","0.004"],["62071.20","0.581"],["62074.00","0.003"],["62074.80","0.163"],["62074.90","0.004"],["62075.90","0.080"],["62080.10","0.001"],["62080.60","0.732"],["62083.00","0.000"],["62083.90","0.190"],["62085.00","0.741"],["62091.10","0.012"],["62095.30","5.100"],["62102.30","2.802"],["62102.60","0.016"],["62102.90","0.002"],["62103.00","0.129"],["62103.60","0.006"],["62103.70","0.452"],["62103.80","0.324"],["62115.00","0.291"],["62124.70","4.375"],["62329.90","0.339"],["62331.30","0.002"],["62341.00","0.160"],["62341.60","0.041"],["62687.70","0.002"],["62782.50","4.730"],["62790.00","0.948"],["62945.90","1.116"],["63038.90","0.000"],["63308.30","0.127"],["67798.30","0.002"]],"b":[["11566.90","0.032"],["11666.90","2.320"],["11667.80","0.416"],["11766.90","0.576"],["11767.80","0.416"],["11867.80","0.400"],["49654.00","0.000"],["55860.20","0.003"],["59584.20","0.039"],["60898.40","0.819"],["61011.80","0.332"],["61328.30","1.954"],["61358.90","0.000"],["61446.20","0.002"],["61756.60","0.174"],["61757.10","0.073"],["61808.00","0.690"],["61863.50","0.001"],["62003.00","0.116"],["62007.10","0.158"],["62008.30","0.000"],["62008.50","3.798"],["62021.90","0.518"],["62024.10","0.119"],["62034.60","2.308"],["62040.10","0.008"],["62043.00","0.000"],["62045.20","0.009"],["62045.40","0.847"],["62049.40","1.721"],["62051.40","0.003"],["62052.50","1.465"],["62052.80","0.242"],["62054.90","0.059"],["62056.10","0.003"],["62056.90","0.295"],["62057.60","0.132"],["62058.00","0.006"],["62058.20","2.264"],["62059.60","0.292"],["62059.70","0.216"],["62060.30","0.757"],["62060.70","0.486"],["62066.90","4.587"]],"e":"depthUpdate","ps":"BTCUSDT","pu":10998401481985,"s":"BTCUSDT","st":1,"u":10998401493762}
{"E":1783504332752,"T":1783504332749,"U":10998401493819,"a":[["62067.00","7.353"],["62068.10","0.000"],["62068.30","0.000"],["62069.20","0.001"],["62069.30","1.049"],["62069.40","0.012"],["62069.50","0.840"],["62069.60","0.013"],["62069.70","0.000"],["62069.90","0.303"],["62070.10","0.005"],["62071.40","0.733"],["62071.70","0.004"],["62072.20","0.002"],["62073.60","0.021"],["62073.70","0.029"],["62074.40","0.247"],["62074.80","0.001"],["62075.90","0.000"],["62076.20","0.069"],["62076.50","0.163"],["62076.60","0.000"],["62077.70","0.676"],["62078.30","0.191"],["62080.00","0.028"],["62080.40","0.163"],["62080.50","0.615"],["62080.60","0.007"],["62081.70","0.333"],["62082.20","0.000"],["62082.70","0.726"],["62082.80","0.190"],["62082.90","0.290"],["62084.50","0.372"],["62085.00","0.701"],["62086.10","0.091"],["62089.90","0.341"],["62091.80","0.465"],["62093.10","2.142"],["62094.90","0.196"],["62095.30","5.102"],["62096.10","0.665"],["62098.00","0.001"],["62099.30","0.000"],["62101.10","0.001"],["62101.70","0.173"],["62102.30","2.480"],["62110.00","0.454"],["62118.80","0.000"],["62126.20","0.127"],["62128.90","0.016"],["62136.20","0.228"],["62137.30","0.133"],["62510.90","0.000"],["62687.70","0.002"],["62777.00","0.948"],["62781.40","5.991"],["62790.00","0.002"],["62843.50","3.152"],["62848.40","0.018"],["62997.70","0.001"],["63300.80","0.015"],["89523.20","0.312"]],"b":[["1000.00","210.542"],["11566.90","0.176"],["11666.90","2.448"],["11667.80","0.272"],["11766.90","0.704"],["11767.80","0.288"],["11867.80","0.272"],["55860.20","0.003"],["58963.50","0.000"],["59584.20","0.042"],["61246.60","0.588"],["61446.20","0.000"],["61810.80","0.381"],["61863.50","0.000"],["62000.30","0.016"],["62001.80","0.680"],["62002.20","0.123"],["62020.50","0.000"],["62022.00","0.100"],["62022.10","0.016"],["62031.30","0.110"],["62041.30","0.002"],["62042.90","0.023"],["62043.30","0.011"],["62049.00","1.027"],["62049.60","0.106"],["62050.60","0.342"],["62051.00","0.725"],["62052.60","1.248"],["62055.00","1.809"],["62056.10","0.001"],["62058.00","0.008"],["62059.60","0.210"],["62059.70","0.134"],["62060.70","0.481"],["62061.20","0.343"],["62061.30","0.789"],["62061.50","0.132"],["62062.90","0.054"],["62063.30","0.324"],["62063.40","0.058"],["62066.90","6.898"]],"e":"depthUpdate","ps":"BTCUSDT","pu":10998401493762,"s":"BTCUSDT","st":1,"u":10998401502904}
{"E":1783504332854,"T":1783504332853,"U":10998401503006,"a":[["62069.30","0.000"],["62069.40","0.004"],["62069.50","0.635"],["62069.60","0.005"],["62072.20","0.001"],["62073.10","0.052"],["62073.50","0.024"],["62073.90","0.000"],["62075.40","0.008"],["62076.20","0.053"],["62076.60","0.902"],["62077.40","0.052"],["62078.50","0.623"],["62079.60","0.000"],["62082.40","0.028"],["62083.60","0.004"],["62083.90","0.188"],["62084.50","0.292"],["62091.00","0.081"],["62094.00","0.701"],["62098.00","0.129"],["62687.70","0.002"],["62832.90","0.000"],["62999.10","0.357"],["63023.20","0.006"]],"b":[["1000.00","210.542"],["11566.90","0.304"],["11666.90","2.592"],["11667.80","0.144"],["11766.90","0.848"],["11767.80","0.144"],["11867.80","0.128"],["49654.00","0.000"],["55860.20","0.003"],["58939.00","0.102"],["58963.50","0.000"],["59584.20","0.039"],["61260.00","2.072"],["61346.30","0.814"],["61446.20","0.000"],["61550.00","8.943"],["61756.60","0.982"],["61797.10","0.008"],["61797.40","0.001"],["61863.50","0.001"],["62001.70","0.000"],["62002.20","0.123"],["62007.00","0.275"],["62007.90","0.182"],["62044.10","0.057"],["62047.40","1.415"],["62051.10","0.567"],["62052.60","0.684"],["62058.40","0.132"],["62061.50","0.000"],["62062.10","0.171"],["62066.90","6.915"]],"e":"depthUpdate","ps":"BTCUSDT","pu":10998401502904,"s":"BTCUSDT","st":1,"u":10998401508470}
{"E":1783504332956,"T":1783504332955,"U":10998401508587,"a":[["62067.00","7.355"],["62073.90","0.241"],["62074.40","0.006"],["62074.70","0.700"],["62074.90","1.100"],["62075.00","0.984"],["62075.30","0.010"],["62076.50","0.163"],["62078.60","1.022"],["62079.10","0.017"],["62080.40","0.001"],["62080.50","0.051"],["62081.00","1.017"],["62082.40","0.012"],["62082.60","0.011"],["62082.70","0.001"],["62082.80","0.028"],["62084.30","0.750"],["62085.60","0.003"],["62089.90","0.179"],["62093.10","1.474"],["62094.90","0.068"],["62095.30","0.102"],["62101.10","0.129"],["62104.10","1.685"],["62104.20","0.852"],["62105.30","0.247"],["62126.40","0.017"],["62203.70","0.203"],["62541.50","0.160"],["62687.70","0.002"],["62828.00","0.797"],["62844.60","3.152"],["62848.10","1.590"],["62968.10","1.189"],["63061.20","1.109"],["89523.20","0.318"]],"b":[["11566.90","0.448"],["11666.90","2.720"],["11667.80","0.000"],["11766.90","0.976"],["11767.80","0.016"],["11867.80","0.000"],["55860.20","0.003"],["58963.50","0.000"],["61299.60","5.441"],["61444.20","2.822"],["61446.20","0.002"],["61570.40","4.054"],["61863.50","0.000"],["61937.20","1.362"],["62002.20","0.121"],["62002.40","0.034"],["62022.00","0.018"],["62041.10","1.956"],["62042.50","0.304"],["62043.00","0.700"],["62043.30","0.001"],["62045.80","0.823"],["62047.40","1.295"],["62049.90","2.138"],["62050.20","0.568"],["62051.00","0.000"],["62051.10","0.003"],["62057.20","0.004"],["62057.40","0.005"],["62057.60","0.004"],["62058.00","0.006"],["62058.50","0.163"],["62059.60","0.048"],["62061.50","0.082"],["62062.10","0.009"],["62064.90","0.002"],["62066.90","4.858"]],"e":"depthUpdate","ps":"BTCUSDT","pu":10998401508470,"s":"BTCUSDT","st":1,"u":10998401515627}
{"E":1783504333058,"T":1783504333057,"U":10998401515650,"a":[["62067.00","7.372"],["62067.90","0.040"],["62068.20","0.091"],["62068.70","0.002"],["62070.30","0.323"],["62071.70","0.001"],["62074.60","0.322"],["62074.90","1.664"],["62076.60","0.016"],["62077.30","0.351"],["62078.60","0.458"],["62078.70","1.364"],["62079.10","0.001"],["62080.70","1.051"],["62081.00","0.292"],["62081.50","0.725"],["62091.00","0.001"],["62104.00","0.221"],["62104.20","0.658"],["62124.20","22.577"],["62124.70","1.236"],["62125.90","0.103"],["62126.20","0.026"],["62126.30","1.618"],["62126.40","0.118"],["62203.10","0.671"],["62687.70","0.002"]],"b":[["1000.00","210.542"],["11566.90","0.688"],["11666.90","2.512"],["11766.90","1.104"],["11767.80","0.000"],["11866.90","0.496"],["49653.50","0.000"],["55860.20","0.003"],["58963.50","0.000"],["59584.20","0.042"],["61274.30","0.004"],["61446.20","0.000"],["61756.60","1.144"],["61863.50","0.001"],["61936.30","0.579"],["62022.00","0.018"],["62030.70","0.000"],["62042.00","1.079"],["62049.90","2.140"],["62056.80","0.880"],["62057.20","0.002"],["62059.00","0.023"],["62059.70","0.002"],["62061.50","0.214"],["62061.60","0.085"],["62063.10","0.003"],["62066.80","0.106"],["62066.90","4.814"]],"e":"depthUpdate","ps":"BTCUSDT","pu":10998401515627,"s":"BTCUSDT","st":1,"u":10998401522508}
{"E":1783504333160,"T":1783504333157,"U":10998401522575,"a":[["62068.70","0.000"],["62072.00","0.125"],["62082.90","0.290"],["62091.80","0.337"],["62687.70","0.002"],["62781.40","7.883"],["62786.00","0.551"],["62786.20","0.014"],["63300.80","0.012"],["89523.20","0.324"]],"b":[["1000.00","210.542"],["11566.90","0.960"],["11666.90","2.240"],["11766.90","1.232"],["11866.90","0.368"],["55860.20","0.003"],["58500.00","26.977"],["58955.10","0.020"],["58955.20","0.003"],["58956.70","0.003"],["58963.50","0.000"],["59584.20","0.039"],["61291.10","1.102"],["61446.20","0.000"],["61477.30","0.730"],["61721.10","0.006"],["61756.60","1.144"],["61863.50","0.000"],["62022.00","0.100"],["62028.70","0.003"],["62042.00","1.784"],["62051.80","0.006"],["62061.50","0.132"],["62061.60","0.003"],["62064.30","0.002"]],"e":"depthUpdate","ps":"BTCUSDT","pu":10998401522508,"s":"BTCUSDT","st":1,"u":10998401529321}
{"E":1783504333262,"T":1783504333261,"U":10998401529586,"a":[["62067.00","7.355"],["62068.20","0.042"],["62073.50","0.000"],["62077.30","0.271"],["62081.70","0.349"],["62087.80","0.405"],["62091.80","0.465"],["62092.90","0.115"],["62094.10","5.713"],["62098.00","0.001"],["62098.90","0.040"],["62099.00","0.030"],["62102.30","2.480"],["62104.00","0.027"],["62104.10","1.491"],["62124.20","0.000"],["62124.80","0.768"],["62125.90","0.002"],["62126.40","0.017"],["62130.40","1.090"],["62130.50","22.810"],["62203.00","0.675"],["62203.10","0.000"],["62219.00","0.015"],["62224.60","1.294"],["62687.70","0.002"],["62843.50","4.728"],["62844.40","1.894"],["62844.60","2.364"]],"b":[["11566.90","1.232"],["11666.90","1.968"],["11766.90","1.376"],["11866.90","0.224"],["55860.20","0.003"],["58963.50","0.000"],["58963.60","0.004"],["59584.20","0.042"],["60819.30","0.000"],["60825.60","0.009"],["61277.50","0.817"],["61446.20","0.000"],["61600.00","50.191"],["61756.60","1.145"],["61863.50","0.001"],["61907.20","0.783"],["61909.10","0.472"],["61914.70","0.862"],["61936.30","0.579"],["61997.50","0.017"],["62041.10","1.336"],["62042.70","0.003"],["62045.80","0.819"],["62050.90","0.003"],["62051.20","0.004"],["62052.90","0.258"],["62055.50","0.001"],["62058.50","0.001"],["62060.70","0.481"],["62066.90","4.825"]],"e":"depthUpdate","ps":"BTCUSDT","pu":10998401529321,"s":"BTCUSDT","st":1,"u":10998401537466}
{"E":1783504333364,"T":1783504333362,"U":10998401537566,"a":[["62067.00","7.356"],["62081.50","0.000"],["62081.70","0.333"],["62082.50","0.728"],["62084.30","0.170"],["62085.70","0.584"],["62086.10","0.107"],["62087.80","0.325"],["62101.10","0.001"],["62126.20","0.127"],["62126.30","24.397"],["62130.40","0.989"],["62130.50","0.031"],["62687.70","0.002"],["62770.90","0.972"],["62781.40","8.829"],["62782.30","2.840"],["89523.20","0.330"]],"b":[["1000.00","210.542"],["11566.90","1.504"],["11666.90","1.696"],["11766.90","1.504"],["11866.90","0.096"],["55860.20","0.003"],["58963.50","0.000"],["59584.20","0.039"],["61446.20","0.000"],["61756.50","0.000"],["61756.60","1.549"],["61863.50","0.000"],["62022.00","0.100"],["62033.80","0.617"],["62045.30","0.000"],["62045.80","1.399"],["62046.60","0.000"],["62049.90","1.415"],["62050.20","0.004"],["62050.50","1.549"],["62050.90","0.567"],["62051.30","0.173"],["62051.40","0.003"],["62061.60","0.003"]],"e":"depthUpdate","ps":"BTCUSDT","pu":10998401537466,"s":"BTCUSDT","st":1,"u":10998401542103}
{"E":1783504333466,"T":1783504333465,"U":10998401542418,"a":[["62074.50","0.000"],["62074.60","0.000"],["62074.90","1.100"],["62076.60","0.000"],["62076.70","0.798"],["62077.00","0.008"],["62077.30","0.000"],["62077.60","0.000"],["62077.70","0.618"],["62077.80","0.644"],["62077.90","0.094"],["62078.00","0.009"],["62078.10","0.902"],["62078.30","0.089"],["62078.40","0.948"],["62078.50","0.323"],["62078.60","0.368"],["62079.30","0.177"],["62086.10","0.091"],["62086.80","0.090"],["62088.20","0.092"],["62088.30","0.117"],["62092.90","0.735"],["62093.20","2.187"],["62094.10","5.715"],["62102.60","0.121"],["62103.00","0.003"],["62103.60","0.006"],["62103.70","0.452"],["62105.20","0.005"],["62105.70","0.442"],["62106.10","0.086"],["62106.40","0.031"],["62109.00","2.455"],["62109.10","0.059"],["62111.00","0.428"],["62111.40","0.693"],["62111.60","2.032"],["62112.00","0.004"],["62112.20","0.294"],["62112.30","0.150"],["62115.00","0.391"],["62123.90","0.476"],["62124.60","0.251"],["62124.90","1.298"],["62125.00","0.160"],["62125.10","0.000"],["62125.20","0.004"],["62126.40","0.017"],["62132.60","0.000"],["62133.10","0.097"],["62133.30","0.015"],["62133.70","0.248"],["62133.90","0.255"],["62151.70","0.179"],["62152.00","0.714"],["62157.90","0.017"],["62158.20","1.269"],["62164.10","0.394"],["62164.40","1.451"],["62377.40","0.055"],["62687.70","0.002"],["62781.40","10.721"],["62782.30","1.894"],["62782.50","3.784"]],"b":[["1000.00","210.542"],["11566.90","1.776"],["11666.90","1.472"],["11766.90","1.552"],["11866.90","0.000"],["49654.00","0.000"],["55860.20","0.001"],["58952.40","0.000"],["58952.50","0.005"],["61128.00","0.555"],["61284.30","0.000"],["61446.20","0.000"],["61756.60","1.549"],["61863.50","0.001"],["62002.40","0.002"],["62002.70","3.797"],["62003.10","0.011"],["62003.30","0.292"],["62003.60","0.003"],["62017.30","0.262"],["62017.40","0.082"],["62017.60","0.323"],["62018.00","0.198"],["62018.60","0.004"],["62021.70","0.779"],["62022.00","0.018"],["62024.10","0.059"],["62026.40","0.172"],["62029.50","0.000"],["62030.10","0.053"],["62033.50","0.004"],["62034.10","0.004"],["62036.20","0.000"],["62037.50","0.013"],["62037.80","1.094"],["62038.10","0.324"],["62038.50","0.001"],["62038.70","0.012"],["62039.70","1.411"],["62059.00","0.083"],["62059.40","0.880"],["62060.70","0.421"],["62060.80","0.003"],["62060.90","0.001"],["62061.00","0.004"],["62061.10","0.051"],["62061.30","0.577"],["62061.40","0.087"],["62061.90","0.006"],["62062.00","0.004"],["62062.20","0.002"],["62062.50","0.000"],["62062.80","0.048"]],"e":"depthUpdate","ps":"BTCUSDT","pu":10998401542103,"s":"BTCUSDT","st":1,"u":10998401548784}
{"E":1783504333568,"T":1783504333567,"U":10998401548792,"a":[["62067.00","7.397"],["62067.70","0.001"],["62068.00","0.015"],["62068.40","0.050"],["62069.40","0.004"],["62069.60","0.001"],["62074.10","0.019"],["62074.60","0.902"],["62076.70","0.888"],["62077.00","0.091"],["62077.30","0.102"],["62077.40","0.119"],["62077.70","0.676"],["62077.90","0.178"],["62078.00","0.135"],["62078.10","0.000"],["62078.30","0.191"],["62078.50","0.431"],["62079.30","0.161"],["62082.20","0.080"],["62086.80","0.010"],["62098.40","0.091"],["62098.70","0.085"],["62099.00","0.097"],["62099.30","0.058"],["62099.60","1.661"],["62102.60","0.016"],["62105.20","0.107"],["62106.10","0.188"],["62106.40","0.139"],["62203.00","0.000"],["62224.60","0.002"],["62374.00","0.018"],["62377.40","0.037"],["62530.30","1.603"],["62687.70","0.002"],["63300.80","0.009"],["89523.20","0.336"]],"b":[["11566.90","2.048"],["11666.90","1.328"],["11766.90","1.424"],["55860.20","0.003"],["58963.50","0.000"],["59584.20","0.042"],["61134.50","2.499"],["61446.20","0.000"],["61537.60","0.032"],["61829.00","0.001"],["61863.50","0.000"],["61878.00","0.023"],["61914.70","0.000"],["61936.30","0.012"],["62016.20","4.133"],["62016.60","0.033"],["62016.80","1.386"],["62017.10","0.960"],["62039.60","0.001"],["62041.20","0.518"],["62048.90","0.122"],["62050.50","1.565"],["62051.00","0.322"],["62054.50","0.138"],["62058.20","1.378"],["62058.30","0.851"],["62058.40","0.000"],["62058.70","0.112"],["62059.00","0.120"],["62059.30","0.124"],["62059.60","0.966"],["62059.90","0.093"],["62060.20","0.033"],["62060.50","0.034"],["62060.70","0.421"],["62061.40","0.219"],["62063.90","0.008"],["62064.30","0.004"],["62066.90","4.675"]],"e":"depthUpdate","ps":"BTCUSDT","pu":10998401548784,"s":"BTCUSDT","st":1,"u":10998401554908}
{"E":1783504333670,"T":1783504333669,"U":10998401554986,"a":[["62067.00","7.310"],["62068.40","0.001"],["62069.90","0.011"],["62074.10","0.003"],["62075.00","0.168"],["62077.80","0.812"],["62078.00","0.193"],["62078.50","0.533"],["62079.30","0.177"],["62082.20","0.000"],["62086.50","0.082"],["62099.70","0.732"],["62105.70","0.610"],["62106.30","0.102"],["62202.90","0.688"],["62223.40","0.573"],["62224.50","2.127"],["62564.60","0.319"],["62687.70","0.002"],["62781.40","11.667"],["62782.50","2.838"],["62806.70","2.703"],["62957.00","0.115"],["63088.60","4.034"],["63123.30","3.480"]],"b":[["1000.00","210.542"],["11566.90","2.320"],["11666.90","1.200"],["11766.90","1.280"],["55860.20","0.003"],["58955.10","0.017"],["58955.20","0.006"],["58963.50","0.000"],["59584.20","0.039"],["61248.00","0.000"],["61257.20","4.275"],["61284.20","0.999"],["61446.20","0.002"],["61863.50","0.001"],["61914.70","0.860"],["61936.30","0.579"],["61982.80","0.002"],["61985.60","0.001"],["62000.20","1.031"],["62002.40","0.000"],["62015.90","0.032"],["62022.00","0.100"],["62042.60","1.670"],["62048.60","0.013"],["62050.00","0.007"],["62051.00","0.000"],["62054.90","0.061"],["62058.80","0.084"],["62059.30","0.156"],["62059.40","1.000"],["62059.70","0.324"],["62060.60","0.003"],["62060.70","0.421"],["62061.40","0.951"],["62063.70","0.024"],["62064.10","0.002"],["62066.90","6.712"]],"e":"depthUpdate","ps":"BTCUSDT","pu":10998401554908,"s":"BTCUSDT","st":1,"u":10998401561871}
{"E":1783504333772,"T":1783504333770,"U":10998401561907,"a":[["62067.00","7.000"],["62068.00","0.011"],["62069.30","0.004"],["62069.40","0.002"],["62069.50","0.726"],["62070.30","0.000"],["62071.20","1.723"],["62072.60","0.003"],["62072.70","0.000"],["62072.80","0.000"],["62072.90","0.797"],["62073.10","0.051"],["62073.30","0.003"],["62073.90","0.000"],["62074.00","0.003"],["62074.40","0.247"],["62074.50","0.000"],["62074.60","0.000"],["62077.30","0.204"],["62077.60","0.000"],["62078.00","0.301"],["62078.40","1.188"],["62078.50","0.623"],["62078.60","0.458"],["62079.30","0.161"],["62080.70","0.487"],["62081.10","0.568"],["62086.10","0.051"],["62086.50","0.002"],["62088.20","0.090"],["62088.30","0.115"],["62089.30","0.040"],["62091.50","1.379"],["62091.80","0.465"],["62092.90","0.115"],["62094.10","0.715"],["62098.00","0.129"],["62101.10","0.131"],["62101.20","0.002"],["62101.30","0.013"],["62104.20","0.852"],["62105.10","0.152"],["62105.20","0.107"],["62105.30","0.247"],["62105.80","0.109"],["62106.20","0.107"],["62106.30","0.246"],["62106.40","0.319"],["62122.00","0.306"],["62123.60","0.004"],["62124.20","22.791"],["62126.00","0.354"],["62126.30","1.618"],["62126.60","0.102"],["62127.70","0.014"],["62127.90","0.001"],["62128.00","0.955"],["62128.50","0.025"],["62129.80","0.000"],["62136.00","0.326"],["62138.40","0.000"],["62567.20","0.000"],["62687.70","0.002"],["62781.40","12.613"],["62782.50","1.892"],["89523.20","0.342"]],"b":[["11566.90","2.592"],["11666.90","1.056"],["11766.90","1.152"],["55860.20","0.003"],["58963.50","0.000"],["59584.20","0.042"],["60825.60","0.012"],["61146.40","0.000"],["61446.20","0.000"],["61756.60","1.549"],["61863.50","0.000"],["62001.90","0.000"],["62002.30","1.297"],["62012.40","2.000"],["62015.40","0.015"],["62022.40","0.129"],["62028.70","0.003"],["62032.00","0.692"],["62041.20","0.502"],["62045.80","1.279"],["62046.50","0.205"],["62046.90","0.001"],["62047.70","0.008"],["62048.50","0.009"],["62050.40","1.004"],["62050.50","0.840"],["62050.90","0.567"],["62051.00","0.000"],["62051.60","0.154"],["62051.70","0.178"],["62052.80","0.564"],["62052.90","0.258"],["62054.20","0.174"],["62056.60","0.171"],["62056.80","0.878"],["62057.20","0.004"],["62057.60","0.132"],["62058.10","0.974"],["62058.20","1.362"],["62058.70","0.292"],["62058.80","0.144"],["62059.30","0.216"],["62059.50","0.163"],["62059.60","0.080"],["62059.70","0.002"],["62060.00","0.062"],["62060.40","0.131"],["62061.40","0.819"],["62061.50","0.016"],["62061.60","0.003"],["62061.70","0.374"],["62061.80","0.696"],["62061.90","0.138"],["62062.80","0.048"],["62066.90","6.535"]],"e":"depthUpdate","ps":"BTCUSDT","pu":10998401561871,"s":"BTCUSDT","st":1,"u":10998401570063}
{"E":1783504333874,"T":1783504333873,"U":10998401570112,"a":[["62067.00","6.994"],["62069.30","0.004"],["62069.40","0.002"],["62069.90","0.827"],["62071.20","0.821"],["62071.30","0.936"],["62073.70","0.005"],["62073.90","0.024"],["62074.90","0.796"],["62075.00","0.006"],["62076.50","0.001"],["62077.60","0.902"],["62077.70","0.514"],["62082.90","0.208"],["62089.90","0.017"],["62091.50","1.363"],["62102.30","2.375"],["62104.10","1.685"],["62120.00","0.286"],["62120.30","0.021"],["62120.40","0.100"],["62120.70","0.067"],["62121.00","0.058"],["62122.00","0.210"],["62122.80","0.004"],["62122.90","1.015"],["62123.60","0.000"],["62124.20","0.014"],["62124.80","0.665"],["62126.40","0.118"],["62126.60","0.001"],["62127.00","0.000"],["62128.30","0.101"],["62128.40","24.098"],["62128.90","0.001"],["62308.10","0.001"],["62315.40","1.342"],["62428.40","0.249"],["62436.20","0.000"],["62463.90","0.165"],["62471.20","0.021"],["62620.00","0.013"],["62627.40","0.294"],["62687.70","0.002"],["62689.10","0.008"],["62696.90","0.001"],["62781.40","14.505"],["62782.30","0.002"],["62843.50","7.092"],["62844.40","1.106"],["62844.60","0.788"],["62929.70","1.610"]],"b":[["11566.90","2.736"],["11666.90","0.992"],["11766.90","1.008"],["11966.90","0.064"],["55860.20","0.003"],["58939.00","0.100"],["58945.90","0.000"],["58963.50","0.000"],["58963.60","0.007"],["59584.20","0.039"],["60818.50","0.006"],["61255.00","5.463"],["61294.40","0.779"],["61446.20","0.000"],["61504.20","0.000"],["61511.40","0.017"],["61657.90","0.004"],["61665.20","0.289"],["61688.10","1.679"],["61726.10","0.024"],["61797.10","0.000"],["61797.60","0.216"],["61812.10","0.000"],["61819.40","0.004"],["61863.50","0.000"],["61986.00","0.000"],["61994.60","0.032"],["61994.90","0.032"],["61995.10","0.033"],["61995.40","0.032"],["62012.10","0.653"],["62031.10","0.070"],["62031.50","0.185"],["62041.20","0.453"],["62044.70","0.021"],["62048.30","0.103"],["62051.00","0.322"],["62051.40","0.131"],["62052.80","0.242"],["62052.90","0.096"],["62053.90","0.001"],["62054.20","0.174"],["62056.80","0.880"],["62057.20","0.002"],["62057.70","0.003"],["62058.10","0.974"],["62058.80","0.120"],["62059.10","0.025"],["62059.30","0.239"],["62059.40","1.000"],["62059.50","0.001"],["62060.80","0.001"],["62061.50","0.564"],["62061.60","0.325"],["62061.70","0.052"],["62061.80","0.000"],["62061.90","0.156"],["62062.00","0.136"],["62066.90","4.724"]],"e":"depthUpdate","ps":"BTCUSDT","pu":10998401570063,"s":"BTCUSDT","st":1,"u":10998401575715}
{"E":1783504333976,"T":1783504333973,"U":10998401575775,"a":[["62067.40","0.016"],["62071.30","0.920"],["62080.00","0.108"],["62082.90","0.128"],["62084.50","0.872"],["62085.70","0.004"],["62098.00","0.001"],["62101.10","0.003"],["62121.30","0.745"],["62122.00","0.306"],["62126.20","0.026"],["62152.70","0.002"],["62160.00","0.565"],["62608.10","0.246"],["62687.70","0.002"],["63006.70","0.007"],["89523.20","0.348"]],"b":[["1000.00","210.542"],["11566.90","2.720"],["11666.90","0.992"],["11766.90","0.880"],["11966.90","0.208"],["55860.20","0.003"],["58963.50","0.000"],["61166.90","1.369"],["61446.20","0.000"],["61863.50","0.001"],["61966.60","0.124"],["61973.90","0.003"],["61994.30","0.032"],["62030.90","2.256"],["62031.10","0.130"],["62032.10","0.087"],["62037.60","0.818"],["62041.90","0.620"],["62045.40","0.849"],["62045.50","0.004"]],"e":"depthUpdate","ps":"BTCUSDT","pu":10998401575715,"s":"BTCUSDT","st":1,"u":10998401582324}
{"E":1783504334078,"T":1783504334077,"U":10998401582571,"a":[["62072.10","0.241"],["62078.60","0.538"],["62080.00","0.028"],["62099.30","0.221"],["62101.70","0.010"],["62104.40","0.090"],["62122.00","0.210"],["62189.10","0.493"],["62193.00","2.419"],["62202.80","1.204"],["62202.90","0.002"],["62224.40","1.318"],["62224.50","0.809"],["62530.30","1.285"],["62687.70","0.002"],["62843.50","5.516"],["62844.60","2.364"],["62963.50","18.559"],["63020.30","0.158"]],"b":[["11566.90","2.736"],["11666.90","0.992"],["11766.90","0.736"],["11966.90","0.336"],["49653.50","0.000"],["55860.20","0.003"],["58963.50","0.000"],["59584.20","0.042"],["60966.20","0.216"],["61095.90","0.003"],["61446.20","0.000"],["61756.60","1.539"],["61863.50","0.000"],["61914.70","0.869"],["61936.30","0.579"],["61974.20","0.152"],["61978.50","2.420"],["62030.90","2.376"],["62031.50","0.305"],["62063.70","0.026"]],"e":"depthUpdate","ps":"BTCUSDT","pu":10998401582324,"s":"BTCUSDT","st":1,"u":10998401588020}
{"E":1783504334180,"T":1783504334179,"U":10998401588182,"a":[["62067.40","0.000"],["62068.10","0.004"],["62068.80","0.518"],["62069.30","0.000"],["62069.80","0.002"],["62072.60","0.000"],["62072.80","0.016"],["62078.60","0.458"],["62082.90","0.128"],["62083.70","2.326"],["62101.50","0.013"],["62101.70","0.173"],["62104.40","0.001"],["62124.20","0.039"],["62126.30","24.545"],["62127.70","0.002"],["62128.30","0.000"],["62128.40","1.171"],["62153.70","0.434"],["62154.70","0.010"],["62159.90","0.200"],["62160.90","0.213"],["62243.30","0.003"],["62243.40","0.003"],["62374.00","0.000"],["62426.80","0.550"],["62427.80","0.001"],["62687.70","0.002"],["62811.80","0.794"],["62980.50","0.558"],["63161.30","1.975"],["63311.60","0.080"],["89523.20","0.354"]],"b":[["11566.90","2.720"],["11666.90","0.992"],["11766.90","0.608"],["11966.90","0.480"],["49654.00","0.000"],["55860.20","0.003"],["58956.70","0.000"],["58963.50","0.000"],["59584.20","0.039"],["60818.50","0.003"],["60822.50","0.000"],["60825.30","0.010"],["60825.60","0.015"],["60917.50","1.638"],["61004.00","0.731"],["61104.60","0.022"],["61197.80","7.558"],["61446.20","0.000"],["61756.60","1.540"],["61863.50","0.001"],["61970.40","0.001"],["61971.40","0.552"],["61976.60","0.000"],["61977.60","0.203"],["61989.00","0.001"],["61990.00","0.209"],["62016.80","1.370"],["62030.80","1.299"],["62030.90","2.436"],["62031.00","0.073"],["62031.30","0.094"],["62031.40","0.060"],["62032.10","0.147"],["62034.00","1.531"],["62035.50","1.358"],["62040.90","1.365"],["62041.90","0.000"],["62044.70","0.005"],["62045.50","0.002"],["62047.90","0.017"],["62048.70","0.026"],["62051.40","0.003"],["62051.80","0.006"],["62054.50","0.138"],["62057.60","0.132"],["62060.70","0.293"],["62061.70","0.054"],["62061.90","0.154"],["62063.00","0.003"],["62063.90","0.000"],["62065.60","0.011"],["62066.90","4.649"]],"e":"depthUpdate","ps":"BTCUSDT","pu":10998401588020,"s":"BTCUSDT","st":1,"u":10998401595671}
{"E":1783504334282,"T":1783504334281,"U":10998401595778,"a":[["62067.00","3.456"],["62067.10","0.001"],["62067.20","0.000"],["62067.30","0.000"],["62067.60","0.001"],["62067.90","0.036"],["62068.10","0.000"],["62068.90","0.000"],["62069.40","0.003"],["62069.50","0.500"],["62069.60","0.000"],["62069.80","0.000"],["62070.10","0.003"],["62070.30","0.004"],["62071.20","0.005"],["62071.30","0.616"],["62071.40","0.004"],["62071.80","0.004"],["62072.40","0.000"],["62072.80","0.000"],["62072.90","0.659"],["62073.00","0.004"],["62073.10","0.001"],["62073.20","1.004"],["62073.30","0.002"],["62073.60","0.001"],["62073.80","0.141"],["62074.40","0.006"],["62074.60","0.183"],["62074.90","0.366"],["62075.00","0.006"],["62075.20","0.003"],["62075.40","0.007"],["62075.50","0.051"],["62075.60","0.060"],["62075.70","0.060"],["62076.00","0.293"],["62076.40","0.050"],["62076.60","0.386"],["62076.70","0.908"],["62076.80","0.005"],["62077.40","0.120"],["62077.60","0.902"],["62078.30","0.192"],["62078.40","0.313"],["62080.70","1.051"],["62081.10","0.004"],["62081.70","0.011"],["62082.40","0.334"],["62082.50","0.003"],["62082.90","0.128"],["62083.00","0.725"],["62083.60","0.003"],["62083.70","2.246"],["62084.50","0.292"],["62085.10","0.003"],["62085.70","0.584"],["62086.90","0.001"],["62087.20","0.000"],["62087.70","0.302"],["62088.30","0.051"],["62088.40","0.000"],["62088.60","0.001"],["62088.70","0.177"],["62089.30","0.000"],["62089.40","0.001"],["62090.00","1.838"],["62090.20","0.123"],["62090.70","0.045"],["62091.30","0.465"],["62091.80","0.465"],["62094.20","0.781"],["62101.30","0.003"],["62101.50","0.003"],["62102.60","0.026"],["62104.10","1.580"],["62104.20","0.747"],["62105.30","0.352"],["62105.40","1.516"],["62105.50","0.105"],["62105.60","0.761"],["62106.30","0.256"],["62107.80","0.324"],["62108.60","0.194"],["62108.70","1.631"],["62114.10","0.064"],["62120.30","0.006"],["62122.00","0.210"],["62128.00","1.056"],["62129.50","0.016"],["62129.90","0.348"],["62130.20","0.131"],["62136.00","0.004"],["62202.80","1.040"],["62344.20","0.000"],["62687.70","0.002"],["62781.40","15.451"],["62782.50","0.946"],["63029.30","0.013"],["63308.60","0.000"],["63311.60","0.077"]],"b":[["1000.00","210.542"],["11566.90","2.448"],["11666.90","1.136"],["11766.90","0.464"],["11966.90","0.752"],["55860.20","0.003"],["59584.20","0.042"],["60828.70","0.000"],["60949.70","1.065"],["61300.00","88.593"],["61446.20","0.000"],["61723.60","0.162"],["61723.90","0.428"],["61863.50","0.000"],["61936.30","0.537"],["61965.10","0.305"],["62002.30","1.295"],["62002.80","0.006"],["62003.00","0.100"],["62013.50","0.353"],["62020.10","0.016"],["62020.80","0.260"],["62026.00","0.050"],["62026.50","0.186"],["62036.90","0.002"],["62042.00","2.488"],["62042.10","0.323"],["62042.50","0.294"],["62042.90","0.021"],["62043.20","0.038"],["62043.90","0.215"],["62044.30","0.008"],["62044.70","0.015"],["62044.90","0.182"],["62045.80","1.289"],["62046.50","0.085"],["62047.40","1.297"],["62047.70","0.000"],["62048.30","0.223"],["62048.60","0.009"],["62049.60","0.114"],["62049.70","0.051"],["62050.40","0.279"],["62050.80","2.225"],["62050.90","0.003"],["62051.00","0.000"],["62051.40","0.131"],["62051.70","0.903"],["62051.80","0.566"],["62052.60","0.684"],["62052.70","1.256"],["62052.80","0.564"],["62053.40","0.128"],["62054.20","0.496"],["62056.50","0.009"],["62056.80","0.878"],["62058.10","0.974"],["62059.20","0.445"],["62059.30","0.237"],["62060.20","0.035"],["62060.40","1.297"],["62060.70","0.421"],["62061.30","0.000"],["62061.50","2.241"],["62061.60","0.003"],["62061.90","0.880"],["62062.00","1.038"],["62062.10","0.005"],["62062.90","0.796"],["62063.00","0.035"],["62063.20","0.008"],["62063.90","0.689"],["62064.10","0.003"],["62064.30","0.125"],["62064.60","0.001"],["62066.00","0.005"],["62066.90","6.686"]],"e":"depthUpdate","ps":"BTCUSDT","pu":10998401595671,"s":"BTCUSDT","st":1,"u":10998401611896}
{"E":1783504334384,"T":1783504334383,"U":10998401612309,"a":[["62067.00","2.024"],["62067.90","0.008"],["62068.00","0.009"],["62068.20","0.001"],["62068.70","0.081"],["62068.80","0.462"],["62069.30","0.049"],["62069.50","0.000"],["62069.90","0.011"],["62070.00","0.006"],["62070.30","0.000"],["62070.50","0.000"],["62071.20","0.001"],["62071.30","0.236"],["62071.40","0.003"],["62071.50","0.003"],["62071.60","0.117"],["62071.80","0.000"],["62072.00","0.054"],["62072.40","0.096"],["62072.80","0.004"],["62072.90","0.083"],["62073.00","0.002"],["62073.20","0.008"],["62073.30","0.002"],["62073.70","0.064"],["62073.80","0.000"],["62073.90","0.001"],["62074.00","0.850"],["62074.10","0.003"],["62074.20","0.269"],["62074.30","0.001"],["62074.40","0.006"],["62074.50","0.109"],["62074.60","1.055"],["62074.70","0.697"],["62074.90","0.004"],["62075.00","0.007"],["62075.10","0.000"],["62075.30","0.006"],["62075.70","0.106"],["62075.80","0.161"],["62075.90","0.886"],["62076.00","0.807"],["62076.10","0.001"],["62076.20","0.053"],["62076.30","0.063"],["62076.40","0.001"],["62076.60","0.742"],["62076.70","0.755"],["62076.90","1.051"],["62077.20","0.000"],["62077.30","0.206"],["62077.40","0.119"],["62077.50","1.134"],["62077.60","1.549"],["62077.70","1.876"],["62077.80","0.171"],["62078.10","0.000"],["62078.30","0.191"],["62078.40","0.313"],["62078.50","0.301"],["62078.60","0.463"],["62078.70","0.002"],["62078.80","0.601"],["62079.00","0.142"],["62079.10","0.051"],["62079.20","0.000"],["62079.40","0.000"],["62079.70","0.001"],["62079.80","0.366"],["62080.00","0.028"],["62080.10","0.005"],["62080.20","0.005"],["62080.50","0.052"],["62080.70","0.488"],["62080.80","1.025"],["62080.90","0.055"],["62081.00","0.000"],["62081.20","0.000"],["62081.30","0.128"],["62081.50","0.322"],["62081.70","0.015"],["62082.40","0.012"],["62082.60","0.303"],["62082.90","1.490"],["62083.00","0.000"],["62083.10","0.002"],["62083.40","0.324"],["62083.60","2.023"],["62083.70","0.884"],["62084.00","0.004"],["62084.10","0.322"],["62084.30","0.734"],["62084.40","0.454"],["62084.50","0.243"],["62084.90","0.049"],["62085.00","0.001"],["62085.50","0.020"],["62085.70","0.004"],["62085.80","0.016"],["62086.10","0.065"],["62086.60","0.323"],["62086.80","0.010"],["62087.40","0.002"],["62087.70","0.294"],["62088.20","0.091"],["62088.30","0.001"],["62088.40","1.942"],["62088.50","0.004"],["62088.70","0.049"],["62089.10","0.085"],["62089.70","0.026"],["62089.90","1.054"],["62090.20","0.003"],["62091.30","0.455"],["62091.80","0.433"],["62091.90","0.323"],["62092.10","0.000"],["62092.20","0.008"],["62092.50","0.080"],["62092.60","0.154"],["62092.90","0.054"],["62093.00","1.278"],["62093.50","0.000"],["62093.60","0.100"],["62093.70","0.046"],["62093.80","0.040"],["62094.70","0.123"],["62095.40","0.020"],["62095.60","0.063"],["62095.70","0.074"],["62096.10","0.685"],["62096.30","0.050"],["62096.70","0.050"],["62097.00","0.003"],["62097.10","0.002"],["62097.50","0.091"],["62098.40","0.091"],["62098.80","0.008"],["62101.10","0.099"],["62102.20","0.019"],["62102.40","9.359"],["62102.60","0.106"],["62103.20","0.006"],["62103.50","0.004"],["62103.60","0.003"],["62104.80","0.050"],["62105.30","0.247"],["62105.50","0.000"],["62105.60","0.763"],["62105.90","0.004"],["62106.30","0.256"],["62107.20","0.005"],["62107.50","0.317"],["62108.40","0.200"],["62108.70","1.636"],["62108.90","0.195"],["62109.00","2.461"],["62109.50","0.018"],["62109.60","0.041"],["62110.00","0.452"],["62111.00","0.429"],["62111.50","0.001"],["62116.80","0.005"],["62117.00","0.768"],["62117.70","1.346"],["62119.00","0.005"],["62122.00","0.000"],["62122.80","0.000"],["62122.90","0.703"],["62123.60","0.004"],["62126.30","1.618"],["62126.40","0.017"],["62130.00","1.574"],["62130.30","0.101"],["62130.50","0.031"],["62131.00","0.102"],["62131.50","0.000"],["62132.20","0.413"],["62132.90","0.897"],["62133.10","0.001"],["62133.70","0.248"],["62134.60","0.396"],["62134.70","22.927"],["62136.20","0.132"],["62136.30","1.283"],["62136.40","0.834"],["62136.80","0.056"],["62155.50","1.319"],["62376.30","0.213"],["62377.30","0.804"],["62687.70","0.002"],["62968.10","2.299"],["63308.30","0.136"],["67589.60","0.000"],["89523.20","0.360"]],"b":[["11566.90","2.176"],["11666.90","1.264"],["11766.90","0.336"],["11966.90","1.024"],["55860.20","0.003"],["56546.80","0.599"],["60818.50","0.000"],["61198.00","2.457"],["61229.00","0.651"],["61322.10","0.163"],["61446.20","0.000"],["61756.60","1.551"],["61863.50","0.001"],["61960.90","1.362"],["61997.50","0.001"],["62002.80","0.004"],["62003.80","0.000"],["62004.70","0.023"],["62004.80","0.141"],["62004.90","0.001"],["62006.20","0.020"],["62006.60","1.182"],["62007.90","0.182"],["62008.80","0.002"],["62011.90","0.925"],["62012.20","0.229"],["62014.30","0.017"],["62014.40","0.002"],["62015.60","0.000"],["62017.10","0.962"],["62017.20","0.448"],["62017.40","0.082"],["62018.00","0.195"],["62018.40","0.017"],["62020.10","0.000"],["62020.30","0.129"],["62020.80","0.050"],["62022.00","0.100"],["62024.50","1.395"],["62025.20","0.035"],["62026.10","0.005"],["62027.40","0.002"],["62029.10","0.000"],["62029.70","0.016"],["62030.00","0.016"],["62030.40","0.005"],["62030.60","0.286"],["62031.00","0.071"],["62031.70","0.001"],["62033.30","0.001"],["62034.40","0.002"],["62034.60","2.268"],["62034.70","0.121"],["62035.50","1.340"],["62036.50","0.041"],["62036.70","1.022"],["62037.00","0.102"],["62038.80","0.003"],["62038.90","0.016"],["62039.20","0.001"],["62039.70","1.411"],["62040.10","0.008"],["62040.50","0.002"],["62040.90","1.365"],["62041.30","0.010"],["62043.00","0.740"],["62043.20","0.003"],["62043.50","0.003"],["62043.80","0.113"],["62043.90","0.095"],["62044.30","0.006"],["62044.70","0.005"],["62044.90","0.053"],["62045.00","0.504"],["62045.10","0.304"],["62045.80","0.699"],["62045.90","0.001"],["62046.20","0.326"],["62046.50","0.101"],["62046.90","0.130"],["62047.00","0.000"],["62047.10","0.001"],["62047.20","0.005"],["62047.60","0.636"],["62047.70","0.000"],["62047.90","0.001"],["62048.20","0.015"],["62048.30","0.103"],["62048.80","0.010"],["62049.00","1.025"],["62049.10","0.019"],["62049.60","0.118"],["62049.80","0.356"],["62050.20","0.038"],["62050.50","0.824"],["62050.60","0.342"],["62050.80","2.145"],["62051.50","0.071"],["62051.70","0.178"],["62051.80","0.002"],["62052.20","0.001"],["62052.50","2.190"],["62052.80","0.806"],["62052.90","0.032"],["62053.00","0.000"],["62053.30","0.001"],["62053.40","0.128"],["62053.80","0.875"],["62054.10","1.003"],["62054.20","0.496"],["62054.30","0.015"],["62054.50","0.138"],["62054.60","0.000"],["62054.70","0.001"],["62054.80","0.000"],["62055.10","0.000"],["62055.50","0.001"],["62055.60","0.004"],["62056.10","0.001"],["62056.30","0.322"],["62056.50","0.005"],["62056.80","0.062"],["62057.20","0.006"],["62057.40","0.007"],["62057.50","0.065"],["62057.60","0.002"],["62058.10","0.157"],["62058.30","0.622"],["62058.70","0.351"],["62059.10","0.002"],["62059.20","0.450"],["62059.30","0.214"],["62059.50","0.001"],["62060.20","0.033"],["62060.30","0.006"],["62060.50","0.058"],["62060.70","0.293"],["62060.80","0.001"],["62061.10","0.053"],["62061.40","0.823"],["62061.60","0.004"],["62061.70","0.004"],["62061.90","0.876"],["62062.00","0.152"],["62062.10","0.001"],["62062.80","0.008"],["62063.40","0.002"],["62063.80","0.003"],["62063.90","0.685"],["62064.00","1.473"],["62064.10","1.441"],["62064.20","0.001"],["62064.90","0.744"],["62065.00","0.052"],["62065.60","0.035"],["62066.00","0.001"],["62066.40","0.040"],["62066.90","8.053"]],"e":"depthUpdate","ps":"BTCUSDT","pu":10998401611896,"s":"BTCUSDT","st":1,"u":10998401634444}
{"E":1783504334486,"T":1783504334485,"U":10998401634521,"a":[["62067.00","0.125"],["62067.90","0.008"],["62068.70","0.000"],["62069.30","0.000"],["62069.80","0.049"],["62070.00","0.005"],["62070.10","0.002"],["62070.90","0.001"],["62071.30","0.357"],["62071.40","0.003"],["62071.60","0.002"],["62072.00","0.005"],["62072.30","0.002"],["62072.50","0.001"],["62072.80","0.049"],["62072.90","0.188"],["62073.00","0.744"],["62073.20","0.008"],["62073.40","0.005"],["62073.90","0.207"],["62074.50","0.689"],["62074.60","1.032"],["62074.80","0.001"],["62075.70","0.001"],["62075.90","0.105"],["62076.30","0.003"],["62076.50","0.323"],["62076.90","0.051"],["62077.30","0.204"],["62077.50","1.038"],["62079.00","1.222"],["62079.30","0.402"],["62079.80","0.125"],["62080.00","0.031"],["62080.10","0.007"],["62082.80","0.028"],["62083.60","1.298"],["62084.30","0.170"],["62084.50","0.243"],["62085.40","0.002"],["62086.60","0.887"],["62087.40","0.727"],["62087.50","0.077"],["62088.40","1.362"],["62089.70","0.018"],["62090.20","0.583"],["62090.70","0.005"],["62091.00","0.009"],["62091.50","1.403"],["62093.60","0.041"],["62094.90","0.059"],["62095.50","0.013"],["62096.10","0.665"],["62097.20","0.060"],["62101.10","0.411"],["62108.60","0.089"],["62128.00","0.955"],["62129.90","0.247"],["62130.20","0.030"],["62130.50","22.958"],["62132.20","0.000"],["62132.90","0.796"],["62134.60","0.295"],["62134.70","0.000"],["62168.60","7.488"],["62337.70","0.001"],["62377.40","0.035"],["62687.70","0.004"],["62811.80","1.064"],["63308.30","0.139"]],"b":[["11566.90","1.904"],["11666.90","1.408"],["11766.90","0.192"],["11966.90","1.296"],["55860.20","0.003"],["59584.20","0.039"],["60825.60","0.021"],["60830.30","0.000"],["60830.50","0.000"],["60906.30","0.821"],["60970.90","0.000"],["61042.90","0.737"],["61446.20","0.004"],["61863.50","0.000"],["62013.80","0.002"],["62017.20","0.442"],["62024.50","1.332"],["62030.80","1.359"],["62031.50","0.245"],["62032.00","0.682"],["62035.40","0.010"],["62036.70","1.012"],["62039.50","0.003"],["62040.60","0.623"],["62045.20","0.011"],["62046.50","0.085"],["62046.80","0.014"],["62048.00","0.751"],["62048.30","0.083"],["62049.00","1.023"],["62049.10","0.009"],["62052.00","1.368"],["62052.50","1.465"],["62052.80","0.242"],["62053.60","0.281"],["62054.00","0.002"],["62054.90","0.059"],["62055.10","0.322"],["62055.30","0.728"],["62056.10","0.021"],["62056.30","0.564"],["62057.40","0.005"],["62057.80","0.005"],["62059.20","0.445"],["62059.80","0.006"],["62060.20","0.035"],["62060.70","0.413"],["62061.70","0.002"],["62062.20","0.082"],["62062.90","0.793"],["62064.20","0.085"],["62065.00","0.052"],["62065.10","0.010"],["62065.40","0.002"],["62065.90","0.000"],["62066.80","0.132"],["62066.90","8.686"]],"e":"depthUpdate","ps":"BTCUSDT","pu":10998401634444,"s":"BTCUSDT","st":1,"u":10998401647646}
{"E":1783504334588,"T":1783504334586,"U":10998401647797,"a":[["62067.00","0.000"],["62067.10","0.000"],["62067.60","0.000"],["62067.70","0.000"],["62067.90","0.000"],["62068.00","0.000"],["62068.20","0.000"],["62068.40","0.000"],["62068.50","0.000"],["62068.70","0.000"],["62068.80","2.847"],["62068.90","0.001"],["62069.00","0.001"],["62069.20","0.000"],["62069.40","0.001"],["62069.80","0.000"],["62070.00","0.003"],["62070.10","0.001"],["62070.30","0.001"],["62070.60","0.049"],["62071.10","0.002"],["62071.20","0.002"],["62071.30","0.005"],["62071.50","0.001"],["62072.00","0.002"],["62072.10","0.000"],["62072.40","0.096"],["62072.60","0.000"],["62072.70","0.000"],["62072.80","0.000"],["62072.90","0.490"],["62073.20","0.004"],["62073.70","0.305"],["62073.80","0.000"],["62073.90","0.001"],["62074.00","0.745"],["62074.20","0.004"],["62074.40","0.006"],["62074.50","0.000"],["62074.60","0.849"],["62074.70","0.721"],["62074.80","0.001"],["62074.90","0.003"],["62075.50","0.065"],["62075.80","0.041"],["62075.90","0.000"],["62076.20","0.050"],["62076.30","0.040"],["62076.50","0.001"],["62076.60","0.000"],["62076.70","0.735"],["62077.20","0.902"],["62077.40","2.690"],["62077.50","0.746"],["62077.60","1.406"],["62077.70","0.062"],["62077.80","0.169"],["62078.60","0.458"],["62078.90","0.001"],["62079.00","0.222"],["62079.10","0.001"],["62079.30","0.161"],["62080.00","0.081"],["62080.10","0.003"],["62080.20","0.001"],["62080.30","0.242"],["62080.80","1.025"],["62081.20","0.350"],["62081.70","0.011"],["62081.80","0.098"],["62082.50","0.123"],["62082.70","0.001"],["62082.80","0.633"],["62083.30","0.126"],["62083.90","0.192"],["62084.40","0.002"],["62085.40","0.006"],["62085.50","0.000"],["62086.10","0.065"],["62086.60","0.891"],["62087.00","0.005"],["62087.40","0.002"],["62087.50","0.077"],["62088.40","1.382"],["62088.70","0.870"],["62089.80","0.135"],["62089.90","1.055"],["62091.30","0.469"],["62092.60","0.034"],["62093.00","1.278"],["62093.70","0.030"],["62095.10","0.359"],["62095.70","0.096"],["62095.80","0.334"],["62095.90","0.121"],["62096.70","0.000"],["62096.80","0.122"],["62097.50","0.080"],["62097.90","0.832"],["62098.00","0.061"],["62099.10","0.119"],["62099.20","0.026"],["62099.70","0.716"],["62100.00","0.646"],["62103.40","0.003"],["62107.60","0.707"],["62107.80","0.324"],["62108.70","1.631"],["62108.90","0.195"],["62109.00","2.461"],["62109.30","0.001"],["62109.90","0.002"],["62110.00","0.452"],["62110.10","3.542"],["62110.40","0.004"],["62110.50","0.002"],["62111.20","0.030"],["62117.70","1.343"],["62119.10","0.057"],["62120.90","0.025"],["62122.30","0.306"],["62123.00","0.269"],["62123.60","0.000"],["62124.00","0.005"],["62124.60","0.255"],["62125.80","0.004"],["62128.40","1.171"],["62128.50","0.021"],["62129.10","0.314"],["62129.50","0.001"],["62130.00","1.364"],["62130.20","0.031"],["62130.30","0.105"],["62130.40","1.004"],["62130.50","0.031"],["62132.00","0.102"],["62132.20","0.101"],["62132.60","0.000"],["62132.80","0.000"],["62132.90","0.796"],["62133.10","0.001"],["62133.40","0.000"],["62133.90","0.004"],["62134.20","0.122"],["62134.30","4.176"],["62134.60","0.396"],["62134.70","22.927"],["62135.20","0.328"],["62137.60","0.002"],["62141.70","0.882"],["62145.20","0.323"],["62158.00","0.181"],["62161.30","0.002"],["62161.70","0.150"],["62185.80","1.371"],["62188.00","0.107"],["62226.90","0.004"],["62242.30","0.002"],["62245.40","0.002"],["62371.30","0.019"],["62687.70","0.054"],["62689.50","0.000"],["62781.40","1.261"],["62782.80","14.290"],["62843.50","0.000"],["62844.90","5.526"],["62901.20","1.085"],["62999.40","0.238"],["63310.10","0.006"],["63313.40","0.000"],["89523.20","0.366"]],"b":[["1000.00","210.542"],["11566.90","1.632"],["11668.70","0.128"],["11766.90","0.064"],["11966.90","1.328"],["11968.70","0.240"],["55860.20","0.001"],["55861.80","0.002"],["58965.90","0.000"],["59585.90","0.003"],["61068.60","4.422"],["61068.70","0.021"],["61070.10","0.006"],["61071.70","0.039"],["61418.00","0.041"],["61446.20","0.000"],["61447.90","0.000"],["61448.00","0.003"],["61707.80","0.000"],["61756.50","0.001"],["61756.60","1.546"],["61758.30","0.084"],["61758.40","0.245"],["61863.50","0.001"],["61884.70","0.014"],["61884.90","0.130"],["61885.60","0.000"],["61964.20","0.039"],["61966.10","0.002"],["61966.50","0.000"],["61968.00","0.068"],["61975.10","2.944"],["61985.00","0.692"],["61994.10","0.055"],["61994.20","0.363"],["62005.20","0.324"],["62005.90","0.011"],["62006.60","1.180"],["62006.80","21.317"],["62007.30","0.000"],["62008.50","0.975"],["62010.00","0.136"],["62012.20","0.034"],["62012.50","0.149"],["62012.70","0.882"],["62013.40","0.414"],["62013.70","0.273"],["62015.40","0.000"],["62017.10","0.960"],["62017.20","0.439"],["62018.60","0.006"],["62018.80","1.366"],["62018.90","0.294"],["62019.30","0.211"],["62020.30","0.001"],["62021.90","0.437"],["62022.00","0.100"],["62022.10","0.016"],["62022.30","0.011"],["62022.40","0.210"],["62023.20","0.002"],["62025.20","0.097"],["62025.50","0.003"],["62025.90","0.027"],["62026.10","0.001"],["62027.30","0.006"],["62027.50","0.003"],["62030.20","0.001"],["62030.80","1.299"],["62031.00","0.067"],["62031.90","0.004"],["62033.60","1.380"],["62034.40","0.000"],["62034.70","0.001"],["62035.20","0.008"],["62035.30","0.034"],["62035.40","0.000"],["62035.80","0.003"],["62036.50","0.051"],["62037.50","0.005"],["62039.00","0.070"],["62039.70","1.471"],["62039.80","0.732"],["62039.90","0.013"],["62040.90","1.295"],["62041.00","0.878"],["62041.30","0.002"],["62041.70","2.587"],["62042.70","0.135"],["62043.70","0.027"],["62045.50","0.016"],["62046.00","0.001"],["62046.30","0.019"],["62046.50","0.084"],["62046.80","0.000"],["62046.90","0.050"],["62047.20","0.001"],["62047.40","1.297"],["62048.00","0.739"],["62048.30","0.034"],["62048.80","0.000"],["62049.10","0.010"],["62049.20","0.019"],["62049.30","0.016"],["62049.40","1.771"],["62049.50","1.267"],["62049.60","0.249"],["62049.70","0.001"],["62049.80","0.356"],["62049.90","1.425"],["62050.00","0.008"],["62050.20","0.003"],["62050.50","0.744"],["62051.40","0.003"],["62052.30","0.019"],["62052.70","1.336"],["62052.90","0.000"],["62053.40","0.124"],["62054.10","0.003"],["62054.50","0.010"],["62055.30","0.726"],["62055.50","0.133"],["62055.60","1.004"],["62055.80","0.084"],["62056.20","1.274"],["62056.30","0.000"],["62056.50","0.001"],["62057.20","0.002"],["62057.80","0.003"],["62058.20","1.366"],["62058.40","0.564"],["62058.50","0.005"],["62059.10","0.010"],["62059.40","0.182"],["62059.50","0.895"],["62059.80","0.001"],["62060.00","0.085"],["62060.50","0.039"],["62061.10","0.051"],["62061.20","0.080"],["62061.40","0.007"],["62061.50","1.366"],["62061.60","0.823"],["62061.90","0.002"],["62062.00","0.300"],["62062.20","0.002"],["62062.30","0.000"],["62062.60","0.003"],["62062.70","0.454"],["62062.90","0.314"],["62063.70","0.025"],["62063.90","0.002"],["62064.00","1.474"],["62064.10","0.553"],["62064.20","0.003"],["62064.90","0.002"],["62065.00","0.002"],["62065.30","0.049"],["62065.60","0.031"],["62065.80","0.050"],["62066.60","0.001"],["62066.80","0.102"],["62066.90","0.212"],["62067.00","1.834"],["62067.10","0.003"],["62067.20","0.001"],["62067.30","0.002"],["62067.50","0.032"],["62067.60","0.024"],["62067.70","0.004"],["62067.80","0.692"],["62067.90","0.000"],["62068.00","0.002"],["62068.10","0.000"],["62068.20","0.286"],["62068.30","0.000"],["62068.40","0.001"],["62068.50","0.005"],["62068.60","0.068"],["62068.70","10.712"]],"e":"depthUpdate","ps":"BTCUSDT","pu":10998401647646,"s":"BTCUSDT","st":1,"u":10998401663998}
{"E":1783504334690,"T":1783504334689,"U":10998401664189,"a":[["62068.80","3.638"],["62071.50","0.005"],["62072.40","0.098"],["62073.40","0.001"],["62073.90","0.005"],["62074.60","1.172"],["62074.70","0.025"],["62075.80","0.161"],["62075.90","0.004"],["62076.00","1.807"],["62076.50","0.453"],["62076.60","0.000"],["62077.20","0.000"],["62077.40","1.690"],["62079.10","0.242"],["62080.30","0.001"],["62082.50","0.004"],["62082.70","0.903"],["62083.70","1.448"],["62085.80","0.741"],["62086.60","0.327"],["62086.90","0.036"],["62088.70","0.145"],["62093.10","1.719"],["62093.80","0.005"],["62095.60","0.001"],["62130.50","23.035"],["62132.20","0.000"],["62134.30","0.858"],["62134.60","0.295"],["62134.70","0.000"],["62155.30","0.003"],["62172.70","0.670"],["62172.80","2.890"],["62193.60","0.012"],["62193.70","1.535"],["62428.40","0.241"],["62429.10","0.008"],["62689.50","0.000"],["62782.50","0.000"],["62783.20","3.311"],["62963.50","17.458"],["63237.80","0.005"]],"b":[["11566.90","1.360"],["11568.70","0.080"],["11668.70","0.112"],["11766.90","0.000"],["11968.70","0.512"],["55861.80","0.002"],["59585.90","0.000"],["60974.00","25.819"],["61285.80","0.000"],["61448.00","0.003"],["61468.10","0.325"],["61756.60","1.546"],["61758.40","0.246"],["61760.10","0.205"],["61860.70","0.002"],["61860.80","1.536"],["61863.50","0.000"],["61963.80","0.070"],["61985.30","0.000"],["61985.40","1.942"],["61998.40","0.006"],["61998.70","1.898"],["62000.50","19.072"],["62002.80","0.440"],["62006.10","0.676"],["62006.20","1.549"],["62006.80","2.173"],["62021.60","2.470"],["62021.90","0.001"],["62026.50","0.345"],["62027.40","0.001"],["62033.30","0.061"],["62035.30","0.009"],["62039.70","1.411"],["62048.30","0.036"],["62048.50","0.019"],["62049.10","0.008"],["62049.30","0.006"],["62052.00","2.068"],["62055.40","1.703"],["62055.80","0.004"],["62056.30","0.000"],["62057.60","0.082"],["62058.40","0.000"],["62059.00","0.122"],["62064.10","0.377"],["62065.40","0.003"],["62066.90","0.206"],["62067.20","0.005"],["62068.60","0.064"],["62068.70","10.719"]],"e":"depthUpdate","ps":"BTCUSDT","pu":10998401663998,"s":"BTCUSDT","st":1,"u":10998401669836}
{"E":1783504334792,"T":1783504334791,"U":10998401669884,"a":[["62068.80","5.956"],["62069.30","0.049"],["62070.60","0.000"],["62071.20","0.001"],["62072.80","0.164"],["62073.70","0.241"],["62074.40","0.070"],["62074.50","1.362"],["62074.90","1.003"],["62075.40","0.009"],["62075.90","0.000"],["62076.00","0.807"],["62076.50","0.456"],["62077.70","0.063"],["62078.90","0.121"],["62080.70","0.002"],["62082.50","0.003"],["62088.10","0.082"],["62088.70","0.109"],["62091.80","0.397"],["62092.70","0.022"],["62094.30","0.162"],["62095.70","0.186"],["62099.30","0.058"],["62100.50","1.013"],["62101.10","0.375"],["62101.70","0.010"],["62102.60","0.016"],["62108.40","0.037"],["62108.60","0.194"],["62108.90","0.001"],["62109.00","2.455"],["62123.90","0.476"],["62128.40","24.175"],["62129.90","0.348"],["62130.30","0.004"],["62130.50","0.031"],["62131.00","0.001"],["62131.30","0.001"],["62132.00","0.001"],["62530.30","0.327"],["62689.50","0.000"],["62778.40","1.258"],["63025.10","0.277"],["89523.20","0.372"]],"b":[["1000.00","210.692"],["11566.90","1.088"],["11568.70","0.208"],["11666.90","1.392"],["11668.70","0.000"],["11968.70","0.784"],["55861.80","0.002"],["58966.50","0.002"],["59585.90","0.003"],["61448.00","0.007"],["61558.30","0.136"],["61797.60","0.208"],["61799.10","0.008"],["61863.50","0.001"],["61877.60","0.028"],["62021.90","0.083"],["62040.20","0.016"],["62043.70","0.027"],["62048.30","0.116"],["62050.00","0.008"],["62053.90","0.565"],["62054.10","0.728"],["62055.30","0.001"],["62055.40","1.139"],["62055.50","0.001"],["62056.10","0.023"],["62056.20","1.276"],["62057.60","0.002"],["62058.40","0.644"],["62059.50","0.331"],["62060.70","0.333"],["62061.60","0.612"],["62065.10","0.006"],["62065.80","0.055"],["62066.50","0.004"],["62066.90","0.195"],["62067.10","0.007"],["62067.70","0.007"],["62068.50","0.002"],["62068.60","0.064"],["62068.70","10.728"]],"e":"depthUpdate","ps":"BTCUSDT","pu":10998401669836,"s":"BTCUSDT","st":1,"u":10998401676014}
{"E":1783504334894,"T":1783504334893,"U":10998401676067,"a":[["62074.80","0.007"],["62077.40","1.686"],["62085.80","0.821"],["62087.40","0.582"],["62088.10","0.001"],["62088.70","0.049"],["62090.20","0.003"],["62091.00","0.709"],["62092.30","2.542"],["62092.50","0.000"],["62094.00","0.001"],["62094.50","0.079"],["62095.90","0.001"],["62098.00","0.061"],["62101.10","0.315"],["62123.90","0.572"],["62689.10","0.000"],["62689.50","0.000"],["62689.80","0.008"],["62721.50","0.008"],["62770.90","0.017"],["63237.90","0.792"]],"b":[["1000.00","210.542"],["11566.90","0.816"],["11568.70","0.352"],["11666.90","1.248"],["11968.70","1.056"],["55861.80","0.002"],["61004.50","0.002"],["61042.80","0.869"],["61129.30","0.010"],["61277.30","1.635"],["61448.00","0.003"],["61863.50","0.000"],["62012.50","0.147"],["62021.90","0.215"],["62022.40","0.129"],["62022.70","0.090"],["62025.10","0.003"],["62032.00","0.696"],["62046.80","0.080"],["62048.30","0.036"],["62054.20","0.174"],["62058.00","0.046"],["62058.40","0.966"],["62058.50","0.327"],["62058.90","0.009"],["62059.50","0.009"],["62060.50","0.034"],["62060.70","0.293"],["62063.20","0.008"],["62063.90","0.000"],["62064.90","0.007"],["62065.80","0.050"],["62065.90","0.004"],["62066.50","0.000"],["62067.10","0.009"],["62067.70","0.004"],["62067.80","0.324"],["62068.60","0.066"]],"e":"depthUpdate","ps":"BTCUSDT","pu":10998401676014,"s":"BTCUSDT","st":1,"u":10998401682004}
{"E":1783504334996,"T":1783504334993,"U":10998401682091,"a":[["62068.80","6.018"],["62068.90","0.002"],["62075.50","0.003"],["62079.70","0.001"],["62080.40","0.323"],["62081.50","0.000"],["62088.10","0.017"],["62092.70","0.006"],["62098.00","0.097"],["62098.20","0.100"],["62123.90","0.476"],["62687.70","0.002"],["62689.50","0.000"],["62844.60","1.576"],["62845.30","0.788"],["62968.50","1.110"],["63061.60","0.877"],["89523.20","0.378"]],"b":[["11566.90","0.544"],["11568.70","0.480"],["11666.90","1.120"],["11968.70","1.328"],["55861.80","0.002"],["59585.90","0.000"],["61446.20","0.072"],["61448.00","0.003"],["61476.70","0.715"],["61534.90","0.730"],["61756.60","1.536"],["61758.40","0.257"],["61808.00","0.013"],["61811.20","0.000"],["61813.30","0.136"],["61863.50","0.001"],["61994.20","19.431"],["62000.50","0.004"],["62000.60","0.002"],["62021.90","0.083"],["62022.70","0.009"],["62023.00","0.283"],["62036.50","0.011"],["62043.10","0.040"],["62043.90","0.175"],["62046.80","0.000"],["62047.40","1.309"],["62048.30","0.034"],["62048.50","0.019"],["62049.90","1.415"],["62052.90","0.725"],["62054.10","0.003"]],"e":"depthUpdate","ps":"BTCUSDT","pu":10998401682004,"s":"BTCUSDT","st":1,"u":10998401687193}
{"E":1783504335098,"T":1783504335097,"U":10998401687299,"a":[["62068.80","3.751"],["62072.80","0.001"],["62073.80","0.002"],["62074.90","0.003"],["62075.90","1.000"],["62076.50","0.453"],["62082.60","0.867"],["62083.70","0.884"],["62084.20","0.728"],["62085.80","0.096"],["62090.90","0.017"],["62092.40","0.022"],["62093.10","1.474"],["62094.00","0.060"],["62094.30","0.001"],["62097.20","0.001"],["62099.30","0.221"],["62100.50","0.691"],["62108.70","1.631"],["62108.90","0.090"],["62116.20","0.025"],["62123.90","0.476"],["62124.00","0.005"],["62124.30","0.042"],["62126.20","0.001"],["62130.10","0.105"],["62130.20","0.031"],["62130.30","0.105"],["62131.00","0.102"],["62131.80","0.427"],["62565.00","0.958"],["62689.50","0.000"],["62745.00","0.476"],["62813.30","2.178"]],"b":[["1000.00","210.542"],["11566.90","0.368"],["11568.70","0.624"],["11666.90","0.976"],["11868.70","0.096"],["11968.70","1.408"],["49655.00","0.000"],["55861.80","0.002"],["59585.90","0.003"],["61135.00","0.384"],["61206.50","0.000"],["61443.30","1.299"],["61448.00","0.003"],["61863.50","0.000"],["61991.90","0.000"],["62004.30","0.002"],["62013.60","0.724"],["62016.60","0.033"],["62021.90","0.519"],["62028.70","0.003"],["62033.20","0.105"],["62035.00","0.051"],["62043.90","0.095"],["62045.60","0.004"],["62047.40","1.356"],["62053.00","0.132"],["62054.90","0.012"],["62057.90","0.000"],["62059.70","0.049"],["62064.90","0.002"],["62066.50","0.004"],["62067.10","0.005"],["62067.70","0.004"],["62068.70","10.730"]],"e":"depthUpdate","ps":"BTCUSDT","pu":10998401687193,"s":"BTCUSDT","st":1,"u":10998401695348}
{"E":1783504335200,"T":1783504335198,"U":10998401695411,"a":[["62068.80","2.380"],["62069.80","0.002"],["62073.90","0.165"],["62074.40","0.650"],["62074.60","0.849"],["62075.90","0.000"],["62076.60","0.004"],["62077.10","1.011"],["62077.70","0.062"],["62078.10","0.001"],["62082.50","0.325"],["62082.60","0.303"],["62082.70","0.001"],["62082.90","1.488"],["62083.40","0.888"],["62084.20","0.003"],["62084.70","0.434"],["62084.90","0.774"],["62085.80","0.016"],["62086.60","0.005"],["62087.30","0.081"],["62087.40","0.324"],["62087.50","0.057"],["62088.10","0.001"],["62088.30","0.581"],["62088.60","0.021"],["62101.10","0.409"],["62101.20","0.000"],["62101.30","0.001"],["62101.70","0.173"],["62106.30","0.246"],["62108.80","2.355"],["62108.90","0.195"],["62109.00","2.461"],["62124.00","0.005"],["62132.00","0.102"],["62132.20","0.101"],["62132.60","0.000"],["62243.40","0.000"],["62243.70","0.004"],["62371.30","0.001"],["62689.50","0.000"],["62777.10","3.354"],["62778.30","2.384"],["62963.50","16.357"],["63310.10","0.009"],["89523.20","0.384"]],"b":[["1000.00","210.542"],["11566.90","0.240"],["11568.70","0.752"],["11666.90","0.848"],["11868.70","0.240"],["11968.70","1.392"],["55861.80","0.002"],["58939.10","0.000"],["59585.90","0.000"],["61161.50","3.557"],["61253.30","1.384"],["61448.00","0.003"],["61863.50","0.001"],["61964.10","2.041"],["61964.40","0.022"],["61984.20","0.452"],["61994.20","0.363"],["62000.50","19.072"],["62012.60","1.969"],["62013.60","0.677"],["62014.30","0.001"],["62023.00","0.202"],["62023.10","0.082"],["62031.30","0.110"],["62039.90","0.053"],["62042.70","0.003"],["62043.10","0.000"],["62047.60","0.056"],["62049.50","1.847"],["62049.60","0.241"],["62049.80","0.236"],["62051.70","0.186"],["62051.80","0.000"],["62052.10","0.122"],["62052.90","0.000"],["62053.60","0.283"],["62053.70","1.380"],["62053.90","0.001"],["62054.00","0.134"],["62054.20","0.899"],["62055.10","0.886"],["62056.50","0.693"],["62056.70","0.048"],["62057.20","0.000"],["62058.60","0.711"],["62058.90","0.004"],["62060.20","0.040"],["62064.30","0.127"],["62065.60","0.023"],["62066.90","0.194"],["62068.40","0.009"],["62068.70","11.830"]],"e":"depthUpdate","ps":"BTCUSDT","pu":10998401695348,"s":"BTCUSDT","st":1,"u":10998401704318}
{"E":1783504335302,"T":1783504335301,"U":10998401704433,"a":[["62068.80","0.283"],["62069.30","0.000"],["62071.50","0.001"],["62071.80","0.049"],["62072.90","0.441"],["62073.10","0.005"],["62073.80","0.000"],["62073.90","0.161"],["62074.30","0.001"],["62074.40","0.070"],["62074.50","0.000"],["62074.80","0.001"],["62075.80","0.049"],["62075.90","0.000"],["62076.10","0.005"],["62076.30","1.487"],["62076.40","0.001"],["62076.50","0.001"],["62076.60","0.012"],["62077.10","0.015"],["62077.40","1.689"],["62077.90","0.178"],["62078.10","0.000"],["62078.50","0.301"],["62078.90","0.000"],["62079.00","0.081"],["62079.10","0.001"],["62079.40","0.000"],["62079.70","0.001"],["62080.10","1.003"],["62080.20","0.001"],["62080.40","0.142"],["62080.90","0.056"],["62081.20","0.251"],["62082.20","0.002"],["62082.50","0.325"],["62082.70","0.001"],["62082.80","0.600"],["62083.40","0.324"],["62083.90","0.152"],["62084.60","0.392"],["62084.70","0.434"],["62084.80","0.008"],["62084.90","0.049"],["62085.90","0.001"],["62086.00","0.568"],["62086.10","0.065"],["62086.60","0.158"],["62086.80","0.008"],["62087.20","0.001"],["62087.40","0.002"],["62087.80","1.050"],["62088.20","0.011"],["62088.30","0.323"],["62088.40","1.362"],["62088.70","0.145"],["62089.30","0.000"],["62089.60","0.001"],["62090.40","1.822"],["62090.80","0.001"],["62091.00","0.001"],["62091.50","1.363"],["62092.30","2.422"],["62093.20","2.195"],["62093.30","0.875"],["62093.50","0.040"],["62094.00","0.001"],["62094.40","0.681"],["62095.20","0.000"],["62095.70","0.176"],["62097.20","0.121"],["62097.40","0.011"],["62099.30","1.206"],["62099.70","0.715"],["62105.20","0.108"],["62105.50","0.926"],["62108.40","0.200"],["62109.00","2.566"],["62109.60","0.041"],["62110.00","0.557"],["62111.70","4.948"],["62117.90","0.956"],["62124.00","0.101"],["62128.40","1.171"],["62130.90","0.102"],["62131.80","0.326"],["62132.00","0.001"],["62132.20","0.000"],["62132.60","0.000"],["62134.60","0.396"],["62134.70","23.004"],["62142.60","0.003"],["62151.70","0.163"],["62157.90","0.001"],["62164.10","0.378"],["62689.50","0.006"],["63317.10","0.000"]],"b":[["11566.90","0.096"],["11568.70","0.896"],["11666.90","0.704"],["11868.70","0.368"],["11968.70","1.408"],["55861.80","0.002"],["59585.90","0.003"],["60834.00","0.036"],["60979.20","2.045"],["61291.10","1.378"],["61448.00","0.005"],["61464.90","0.698"],["61758.40","0.258"],["61863.50","0.000"],["61897.10","0.000"],["61970.60","0.028"],["61994.20","0.363"],["61998.40","19.074"],["62000.40","0.167"],["62000.50","0.004"],["62002.80","0.004"],["62003.90","0.017"],["62013.00","0.211"],["62016.00","0.021"],["62017.20","0.283"],["62019.30","0.001"],["62040.20","0.000"],["62042.60","1.550"],["62043.80","0.054"],["62047.40","1.344"],["62048.50","0.009"],["62048.90","0.242"],["62049.40","1.773"],["62049.50","1.326"],["62050.00","0.018"],["62050.40","0.295"],["62051.70","0.188"],["62052.00","2.648"],["62052.10","0.002"],["62052.90","0.008"],["62053.00","0.000"],["62053.70","1.300"],["62054.00","0.002"],["62054.20","0.174"],["62054.30","0.015"],["62054.40","0.122"],["62054.60","0.000"],["62054.80","0.000"],["62054.90","0.014"],["62055.10","0.000"],["62055.40","0.707"],["62055.70","0.564"],["62056.20","1.276"],["62056.70","0.773"],["62057.00","0.001"],["62058.10","0.157"],["62058.30","0.000"],["62058.40","0.402"],["62058.50","0.005"],["62058.60","1.649"],["62058.80","0.861"],["62059.70","0.790"],["62060.20","0.035"],["62060.60","0.026"],["62060.80","0.742"],["62061.40","0.001"],["62061.60","0.008"],["62061.70","0.880"],["62061.80","1.918"],["62061.90","0.324"],["62063.60","0.005"],["62064.20","0.876"],["62064.70","0.798"],["62065.00","0.004"],["62065.80","0.054"],["62065.90","0.000"],["62066.50","0.000"],["62066.80","0.002"],["62066.90","0.177"],["62067.10","0.003"],["62067.20","0.001"],["62067.90","0.398"],["62068.00","0.004"],["62068.70","12.354"]],"e":"depthUpdate","ps":"BTCUSDT","pu":10998401704318,"s":"BTCUSDT","st":1,"u":10998401716342}
{"E":1783504335404,"T":1783504335402,"U":10998401716399,"a":[["62068.80","0.000"],["62068.90","0.000"],["62069.00","0.000"],["62069.10","0.000"],["62069.40","0.000"],["62069.80","0.000"],["62069.90","0.000"],["62070.00","0.000"],["62070.10","0.000"],["62070.30","0.000"],["62070.40","0.000"],["62070.90","0.000"],["62071.00","0.000"],["62071.10","0.000"],["62071.20","0.000"],["62071.30","0.000"],["62071.40","0.000"],["62071.50","0.000"],["62071.60","0.000"],["62071.70","0.000"],["62071.80","0.000"],["62072.00","0.000"],["62072.20","0.000"],["62072.30","0.000"],["62072.40","0.000"],["62072.50","0.000"],["62072.80","0.000"],["62072.90","0.000"],["62073.00","0.000"],["62073.10","0.000"],["62073.20","0.000"],["62073.30","0.000"],["62073.40","0.000"],["62073.50","0.000"],["62073.60","0.000"],["62073.70","0.000"],["62073.80","4.652"],["62073.90","0.002"],["62074.00","0.001"],["62074.10","0.002"],["62074.20","0.000"],["62074.30","0.000"],["62074.40","0.006"],["62074.50","0.001"],["62074.60","0.118"],["62074.70","0.001"],["62074.80","0.001"],["62074.90","0.004"],["62075.00","0.002"],["62075.10","0.000"],["62075.30","0.009"],["62075.40","0.000"],["62075.50","0.003"],["62075.60","0.060"],["62075.80","0.001"],["62075.90","0.000"],["62076.00","0.049"],["62076.10","0.001"],["62076.20","0.000"],["62076.30","0.003"],["62076.40","0.000"],["62076.50","0.050"],["62076.60","0.065"],["62076.70","0.645"],["62076.80","0.002"],["62076.90","0.001"],["62077.00","0.008"],["62077.10","0.000"],["62077.20","0.032"],["62077.30","0.000"],["62077.40","0.006"],["62077.50","0.004"],["62077.60","0.279"],["62077.70","0.004"],["62077.80","0.001"],["62077.90","0.004"],["62078.00","0.250"],["62078.20","0.000"],["62078.30","0.001"],["62078.40","0.154"],["62078.50","0.002"],["62078.60","0.001"],["62078.70","0.002"],["62078.80","0.000"],["62079.00","0.009"],["62079.10","0.002"],["62079.30","0.001"],["62079.40","0.000"],["62079.60","1.362"],["62079.70","1.001"],["62079.80","0.003"],["62080.00","0.028"],["62080.10","0.001"],["62080.20","0.121"],["62080.40","0.002"],["62080.50","0.116"],["62080.70","0.066"],["62080.90","0.055"],["62081.00","0.020"],["62081.10","0.003"],["62081.20","0.000"],["62081.30","0.003"],["62081.40","0.206"],["62081.50","0.000"],["62081.90","0.761"],["62082.10","2.434"],["62082.20","0.002"],["62082.30","0.707"],["62082.40","0.729"],["62082.50","0.003"],["62082.60","0.010"],["62082.70","0.001"],["62082.80","0.000"],["62082.90","0.003"],["62083.00","0.000"],["62083.50","0.902"],["62083.60","1.298"],["62083.70","0.607"],["62083.80","0.890"],["62083.90","0.067"],["62084.00","0.004"],["62084.10","0.050"],["62084.20","0.003"],["62084.30","0.161"],["62084.80","0.008"],["62085.40","0.002"],["62085.70","0.122"],["62085.90","0.323"],["62086.00","0.004"],["62086.10","0.016"],["62086.50","0.155"],["62086.60","0.001"],["62086.70","0.051"],["62086.80","0.326"],["62086.90","0.001"],["62087.00","0.005"],["62087.10","0.052"],["62087.20","0.000"],["62087.30","0.001"],["62087.50","1.113"],["62087.80","0.325"],["62088.20","0.019"],["62088.30","0.565"],["62088.50","0.008"],["62088.70","0.049"],["62089.00","0.000"],["62089.60","0.001"],["62089.70","1.780"],["62089.80","0.405"],["62089.90","0.178"],["62090.00","1.842"],["62090.10","0.005"],["62090.40","1.702"],["62090.60","0.001"],["62090.70","0.006"],["62090.80","0.001"],["62090.90","0.017"],["62091.80","0.337"],["62091.90","0.101"],["62092.00","0.342"],["62092.40","0.355"],["62092.50","0.002"],["62093.00","0.749"],["62093.10","1.478"],["62093.20","2.187"],["62093.50","0.000"],["62093.90","0.215"],["62094.00","0.002"],["62094.20","0.711"],["62094.30","0.001"],["62094.40","0.661"],["62094.50","0.017"],["62095.10","0.343"],["62095.20","0.088"],["62095.30","0.172"],["62095.40","0.018"],["62095.70","0.126"],["62095.80","0.325"],["62096.60","0.284"],["62096.80","0.002"],["62097.10","0.051"],["62097.20","0.001"],["62097.40","0.012"],["62097.70","0.070"],["62097.80","0.128"],["62097.90","0.824"],["62098.00","0.001"],["62098.20","0.413"],["62098.40","0.091"],["62098.50","0.000"],["62098.70","0.422"],["62098.80","0.000"],["62099.00","0.237"],["62099.10","0.116"],["62099.30","0.220"],["62099.60","1.677"],["62099.90","0.709"],["62100.00","0.646"],["62100.20","0.003"],["62100.40","0.059"],["62100.70","0.001"],["62100.90","0.001"],["62101.10","0.349"],["62101.20","0.008"],["62101.30","0.001"],["62101.40","0.002"],["62101.70","0.173"],["62102.00","0.001"],["62102.10","0.008"],["62102.20","0.905"],["62102.40","9.368"],["62102.60","0.018"],["62103.00","0.001"],["62103.10","0.003"],["62103.20","0.003"],["62103.70","0.467"],["62104.00","0.001"],["62104.40","0.121"],["62104.90","0.003"],["62105.00","0.122"],["62105.30","0.247"],["62105.40","1.522"],["62105.90","0.002"],["62106.20","0.096"],["62106.80","0.029"],["62107.10","0.011"],["62107.20","0.005"],["62107.50","0.307"],["62107.60","0.693"],["62107.90","0.002"],["62108.20","0.003"],["62108.30","0.185"],["62108.40","0.037"],["62108.60","0.089"],["62108.80","2.404"],["62109.00","0.111"],["62109.10","0.002"],["62109.60","0.215"],["62109.70","1.295"],["62109.80","0.000"],["62109.90","0.119"],["62110.00","0.452"],["62110.10","3.540"],["62110.20","0.601"],["62110.40","0.001"],["62110.80","0.573"],["62110.90","0.001"],["62111.00","0.429"],["62111.10","0.531"],["62111.30","0.016"],["62111.50","0.107"],["62111.60","2.032"],["62111.70","4.948"],["62111.90","0.001"],["62112.10","0.002"],["62112.30","0.150"],["62112.50","0.018"],["62112.90","0.001"],["62113.00","0.008"],["62113.40","0.660"],["62113.50","0.659"],["62113.60","0.001"],["62114.00","0.001"],["62114.10","0.004"],["62114.20","0.000"],["62114.40","0.001"],["62114.80","0.003"],["62115.10","0.005"],["62115.20","0.149"],["62115.40","0.061"],["62115.70","0.000"],["62116.80","0.005"],["62118.20","0.025"],["62118.40","0.013"],["62118.60","0.005"],["62118.90","0.021"],["62119.10","0.054"],["62119.80","0.343"],["62120.30","0.006"],["62120.90","0.000"],["62121.20","0.954"],["62121.30","0.735"],["62121.70","0.000"],["62121.80","0.004"],["62122.10","0.033"],["62122.40","0.001"],["62122.80","0.926"],["62123.00","0.059"],["62123.80","0.327"],["62124.00","0.085"],["62124.30","0.017"],["62124.50","0.689"],["62124.60","0.251"],["62124.80","0.657"],["62124.90","1.295"],["62125.60","0.000"],["62125.80","0.000"],["62125.90","0.010"],["62126.20","0.164"],["62127.80","0.350"],["62127.90","0.164"],["62128.00","0.955"],["62128.20","1.370"],["62128.80","0.214"],["62128.90","0.001"],["62129.40","0.004"],["62129.90","0.251"],["62130.30","0.101"],["62130.40","0.989"],["62130.50","0.025"],["62130.70","0.001"],["62131.20","0.097"],["62132.30","0.248"],["62132.60","0.253"],["62133.10","0.102"],["62133.40","0.000"],["62133.60","0.022"],["62133.70","0.252"],["62133.80","0.021"],["62134.20","0.122"],["62134.30","0.952"],["62134.60","0.295"],["62134.70","0.002"],["62135.00","0.133"],["62135.80","0.360"],["62135.90","0.060"],["62136.20","0.132"],["62136.30","1.032"],["62136.60","0.040"],["62137.40","7.796"],["62138.00","0.684"],["62138.90","23.026"],["62139.30","0.000"],["62141.40","0.671"],["62144.50","0.696"],["62147.10","0.002"],["62148.40","0.172"],["62149.00","0.003"],["62150.00","102.319"],["62161.70","0.142"],["62168.40","0.067"],["62169.80","0.700"],["62171.60","0.004"],["62173.40","0.029"],["62188.50","0.676"],["62195.80","0.676"],["62226.70","0.489"],["62247.30","0.001"],["62250.40","0.004"],["62333.20","1.329"],["62334.80","0.678"],["62369.20","0.018"],["62396.10","0.001"],["62563.20","0.000"],["62568.80","0.487"],["62689.50","0.000"],["62692.80","0.000"],["62692.90","0.000"],["62693.60","0.000"],["62694.10","0.000"],["62694.40","0.003"],["62694.50","0.000"],["62782.80","0.100"],["62783.20","2.365"],["62786.40","2.838"],["62788.10","12.298"],["62808.10","2.663"],["62816.90","1.271"],["62817.20","2.066"],["62844.40","0.318"],["62844.60","0.000"],["62844.90","0.010"],["62845.30","0.000"],["62848.50","2.225"],["62848.80","0.788"],["62850.10","7.886"],["62973.70","1.114"],["89523.20","0.390"]],"b":[["1000.00","210.542"],["11566.90","0.000"],["11568.70","0.912"],["11572.10","0.064"],["11573.70","0.048"],["11666.90","0.576"],["11868.70","0.384"],["11872.10","0.064"],["11873.30","0.016"],["11873.70","0.080"],["11968.70","1.280"],["11972.10","0.048"],["11973.60","0.000"],["55861.80","0.000"],["55864.80","0.000"],["55865.90","0.000"],["55866.30","0.002"],["60830.70","0.006"],["60917.50","0.819"],["61068.80","0.014"],["61071.70","0.035"],["61072.00","0.017"],["61072.10","0.007"],["61072.80","0.012"],["61074.30","1.514"],["61075.40","0.490"],["61075.50","0.008"],["61153.30","0.874"],["61291.10","1.621"],["61412.30","0.001"],["61448.00","0.003"],["61448.10","0.000"],["61451.40","0.003"],["61452.10","0.002"],["61452.60","0.001"],["61453.00","0.031"],["61570.50","0.509"],["61600.40","0.248"],["61806.80","0.000"],["61863.50","0.001"],["61884.90","0.092"],["61885.70","0.000"],["61894.90","0.005"],["61896.00","0.063"],["61898.00","0.000"],["61909.60","0.000"],["61932.50","3.794"],["61963.40","0.000"],["61964.50","0.065"],["61968.30","0.280"],["61977.60","0.201"],["61979.90","0.000"],["61981.90","1.296"],["61984.10","0.001"],["61984.30","1.147"],["61985.80","19.070"],["61991.30","8.364"],["61992.20","0.600"],["61992.60","0.038"],["61993.20","0.001"],["61993.50","4.836"],["61994.10","0.055"],["61995.10","0.032"],["61998.40","0.006"],["62000.50","0.160"],["62000.60","0.000"],["62001.60","0.066"],["62002.40","0.038"],["62003.90","0.001"],["62004.90","0.004"],["62005.20","0.001"],["62005.70","0.000"],["62006.20","1.533"],["62007.90","0.026"],["62008.40","0.002"],["62010.00","0.216"],["62010.50","0.002"],["62012.20","0.034"],["62012.60","1.296"],["62012.70","0.878"],["62013.00","0.001"],["62014.30","0.001"],["62014.40","0.000"],["62016.00","0.005"],["62016.30","0.000"],["62016.90","0.005"],["62017.20","0.281"],["62018.20","0.002"],["62018.60","0.004"],["62018.80","1.363"],["62019.30","0.001"],["62019.40","0.001"],["62019.50","0.001"],["62020.00","1.142"],["62020.40","1.018"],["62020.90","0.002"],["62021.00","0.000"],["62021.60","2.445"],["62021.80","1.751"],["62021.90","0.437"],["62022.00","0.100"],["62022.10","0.016"],["62022.40","0.131"],["62022.60","0.000"],["62022.70","0.001"],["62022.80","0.035"],["62023.00","0.204"],["62023.10","0.001"],["62023.30","0.003"],["62023.50","0.016"],["62024.40","0.001"],["62024.60","0.294"],["62024.90","0.004"],["62025.20","0.035"],["62025.40","0.311"],["62025.50","0.084"],["62026.10","0.009"],["62026.40","0.172"],["62026.70","0.658"],["62026.80","0.000"],["62027.30","0.013"],["62027.50","0.000"],["62027.60","0.000"],["62028.30","0.151"],["62028.50","0.875"],["62029.20","0.005"],["62029.30","0.055"],["62030.30","0.003"],["62030.40","0.002"],["62030.60","0.282"],["62030.80","1.295"],["62030.90","3.095"],["62031.30","0.088"],["62031.50","0.231"],["62031.70","0.004"],["62032.00","0.682"],["62032.10","0.087"],["62032.20","0.004"],["62032.70","0.492"],["62032.80","0.263"],["62033.30","0.004"],["62033.60","1.378"],["62034.00","1.529"],["62034.40","0.006"],["62034.90","0.456"],["62035.00","0.049"],["62035.10","0.062"],["62035.20","0.005"],["62035.30","0.009"],["62035.60","0.000"],["62035.80","0.001"],["62036.00","0.004"],["62036.40","0.281"],["62036.50","0.004"],["62037.00","0.012"],["62037.50","0.001"],["62037.60","0.818"],["62038.40","0.123"],["62038.70","0.000"],["62038.90","0.013"],["62039.00","0.000"],["62039.10","0.001"],["62039.20","0.014"],["62039.70","1.531"],["62040.10","0.000"],["62040.20","0.014"],["62040.30","0.182"],["62040.50","0.006"],["62040.60","0.625"],["62040.90","1.385"],["62041.20","0.455"],["62041.50","0.000"],["62041.70","0.001"],["62042.00","2.500"],["62042.60","1.550"],["62042.80","0.001"],["62043.00","0.700"],["62043.50","0.010"],["62043.70","0.019"],["62043.80","0.057"],["62044.20","0.040"],["62044.50","0.411"],["62044.80","1.364"],["62044.90","0.005"],["62045.00","0.512"],["62045.70","0.133"],["62046.30","0.867"],["62046.50","0.003"],["62046.70","0.002"],["62046.90","0.001"],["62047.30","1.367"],["62047.60","0.105"],["62048.00","0.719"],["62048.20","0.018"],["62048.50","0.205"],["62048.60","0.057"],["62048.70","0.025"],["62048.90","0.290"],["62049.00","1.071"],["62049.10","0.004"],["62049.20","0.003"],["62049.40","1.056"],["62049.50","1.291"],["62049.60","0.111"],["62049.70","0.084"],["62049.80","0.276"],["62049.90","1.416"],["62050.00","0.004"],["62050.10","0.663"],["62050.40","0.281"],["62050.60","0.471"],["62050.70","0.326"],["62050.90","0.003"],["62051.30","0.172"],["62051.60","0.235"],["62051.70","0.180"],["62051.90","0.367"],["62052.00","1.281"],["62052.30","0.003"],["62052.50","1.467"],["62052.60","0.694"],["62052.70","1.266"],["62053.00","0.000"],["62053.10","0.001"],["62053.30","0.001"],["62053.40","0.001"],["62053.50","0.001"],["62053.70","1.300"],["62054.10","0.003"],["62054.20","0.174"],["62054.30","0.004"],["62054.50","0.011"],["62054.60","0.330"],["62054.70","0.334"],["62054.90","0.014"],["62055.00","1.688"],["62055.50","0.017"],["62055.60","0.000"],["62055.70","0.000"],["62055.90","0.002"],["62056.00","0.677"],["62056.30","0.000"],["62056.50","0.001"],["62056.60","0.050"],["62056.70","0.048"],["62057.10","0.731"],["62057.30","0.298"],["62057.40","0.005"],["62057.50","0.001"],["62057.60","0.128"],["62058.10","0.156"],["62058.30","0.002"],["62058.40","0.402"],["62058.50","0.001"],["62058.60","0.938"],["62058.70","0.231"],["62058.80","0.684"],["62059.00","0.120"],["62059.10","0.125"],["62059.30","0.154"],["62059.40","0.182"],["62059.50","0.001"],["62059.70","0.371"],["62059.80","0.001"],["62060.00","0.062"],["62060.10","0.002"],["62060.20","0.033"],["62060.30","1.006"],["62060.50","0.002"],["62060.60","0.002"],["62060.70","0.438"],["62060.80","0.001"],["62061.00","0.002"],["62061.60","0.004"],["62061.70","0.002"],["62061.80","1.092"],["62061.90","0.062"],["62062.00","0.420"],["62062.10","0.323"],["62062.20","0.261"],["62062.50","0.071"],["62062.60","0.001"],["62062.80","0.000"],["62062.90","0.049"],["62063.00","0.043"],["62063.10","0.667"],["62063.20","0.006"],["62063.40","0.002"],["62063.50","0.004"],["62063.60","0.001"],["62063.70","0.061"],["62064.10","0.003"],["62064.20","0.001"],["62064.40","0.599"],["62064.60","0.001"],["62064.70","0.060"],["62064.80","0.020"],["62065.00","0.006"],["62065.30","0.202"],["62065.40","0.003"],["62065.60","0.005"],["62065.80","0.000"],["62065.90","0.009"],["62066.20","0.016"],["62066.40","0.000"],["62066.50","0.006"],["62066.70","0.077"],["62066.80","0.012"],["62066.90","0.089"],["62067.00","0.000"],["62067.30","0.052"],["62067.60","0.004"],["62067.70","0.000"],["62067.80","0.368"],["62067.90","0.475"],["62068.10","0.001"],["62068.20","0.001"],["62068.50","0.000"],["62068.60","0.006"],["62068.70","0.114"],["62068.80","0.012"],["62068.90","0.003"],["62069.00","0.004"],["62069.10","0.000"],["62069.20","0.001"],["62069.30","0.000"],["62069.40","0.001"],["62069.50","0.121"],["62069.60","0.050"],["62069.70","0.000"],["62069.80","0.050"],["62069.90","0.285"],["62070.00","0.201"],["62070.10","0.001"],["62070.20","0.001"],["62070.30","0.000"],["62070.50","0.003"],["62070.60","0.001"],["62070.80","0.001"],["62070.90","0.001"],["62071.00","0.000"],["62071.20","0.042"],["62071.30","0.001"],["62071.50","0.000"],["62071.70","0.000"],["62071.80","0.057"],["62071.90","0.001"],["62072.00","0.002"],["62072.10","2.708"],["62072.20","1.801"],["62072.30","0.000"],["62072.40","0.000"],["62072.60","0.001"],["62072.70","0.003"],["62072.80","0.000"],["62072.90","0.198"],["62073.00","1.800"],["62073.10","0.000"],["62073.20","0.000"],["62073.30","0.007"],["62073.40","1.801"],["62073.50","0.002"],["62073.60","0.050"],["62073.70","10.346"]],"e":"depthUpdate","ps":"BTCUSDT","pu":10998401716342,"s":"BTCUSDT","st":1,"u":10998401740735}
{"E":1783504335506,"T":1783504335505,"U":10998401741039,"a":[["62073.80","6.727"],["62073.90","0.002"],["62077.10","0.000"],["62077.60","0.694"],["62078.40","0.158"],["62078.50","0.025"],["62078.90","0.120"],["62079.20","0.002"],["62079.30","0.324"],["62079.40","1.065"],["62079.50","0.722"],["62079.60","1.362"],["62080.00","0.030"],["62080.20","0.121"],["62080.40","0.006"],["62080.70","0.002"],["62081.00","0.000"],["62081.10","0.006"],["62081.40","0.296"],["62081.50","0.268"],["62081.80","1.025"],["62082.20","0.003"],["62083.00","0.003"],["62083.50","0.342"],["62083.60","1.665"],["62083.70","0.727"],["62084.70","0.675"],["62085.70","0.010"],["62086.20","0.132"],["62087.40","0.002"],["62087.50","0.783"],["62088.20","0.011"],["62088.30","0.001"],["62088.40","1.373"],["62088.60","0.001"],["62090.00","1.843"],["62090.30","0.828"],["62091.70","0.043"],["62092.50","0.022"],["62093.40","0.248"],["62094.20","0.739"],["62094.40","0.701"],["62095.90","0.001"],["62096.10","2.734"],["62096.40","0.131"],["62096.50","14.402"],["62097.80","0.069"],["62098.70","0.387"],["62099.00","0.217"],["62100.60","0.522"],["62100.90","0.091"],["62101.70","0.010"],["62105.30","0.352"],["62105.50","0.926"],["62105.60","0.672"],["62105.80","0.109"],["62106.20","0.096"],["62108.60","0.000"],["62108.70","1.437"],["62108.80","2.299"],["62108.90","0.001"],["62109.00","0.000"],["62109.90","0.029"],["62110.20","0.496"],["62110.50","0.002"],["62111.00","0.429"],["62111.40","0.693"],["62111.50","0.002"],["62113.10","0.002"],["62113.70","0.004"],["62114.30","0.007"],["62114.90","2.008"],["62115.50","0.876"],["62116.10","1.363"],["62116.50","0.081"],["62121.30","0.945"],["62126.20","0.001"],["62127.90","0.001"],["62130.60","0.027"],["62133.50","0.092"],["62133.80","0.006"],["62134.00","0.245"],["62134.60","0.396"],["62134.70","0.002"],["62136.30","1.034"],["62136.40","0.935"],["62137.40","7.695"],["62138.90","0.022"],["62141.00","23.020"],["62141.60","0.139"],["62143.00","0.062"],["62186.30","0.623"],["62202.10","0.282"],["62694.50","0.000"],["62786.40","0.000"],["62788.10","15.136"],["62820.10","0.955"],["62839.10","3.813"],["62848.50","1.437"],["62848.80","0.000"],["62850.10","9.462"],["62901.20","0.815"],["63242.60","4.382"]],"b":[["1000.00","210.542"],["11573.70","0.192"],["11666.90","0.432"],["11873.70","0.352"],["11968.70","1.056"],["11972.10","0.000"],["55866.30","0.002"],["59585.90","0.000"],["60834.00","0.033"],["61011.80","3.933"],["61261.80","1.141"],["61453.00","0.031"],["61650.00","21.328"],["61756.50","0.000"],["61848.50","0.000"],["61863.50","0.000"],["61865.40","0.000"],["61927.90","0.000"],["61948.50","0.024"],["61970.90","0.100"],["61975.10","2.936"],["61980.20","0.300"],["61980.40","0.000"],["61985.80","0.002"],["61986.30","0.054"],["61992.10","0.002"],["61992.60","0.089"],["61992.90","0.100"],["61994.10","0.055"],["61998.90","0.030"],["62000.10","1.816"],["62000.50","0.160"],["62000.60","0.000"],["62002.80","0.440"],["62006.40","0.258"],["62008.90","19.081"],["62012.20","0.019"],["62022.00","0.232"],["62025.40","0.309"],["62025.50","0.018"],["62025.60","0.002"],["62025.70","0.011"],["62025.90","0.027"],["62026.00","0.131"],["62027.90","0.004"],["62028.30","0.150"],["62028.60","1.109"],["62029.20","0.004"],["62029.80","0.014"],["62030.40","0.001"],["62039.70","1.571"],["62039.90","0.013"],["62045.80","0.679"],["62046.80","0.040"],["62047.40","1.344"],["62047.60","0.164"],["62049.50","1.232"],["62049.80","0.236"],["62051.60","0.247"],["62052.50","1.465"],["62052.60","0.684"],["62052.80","0.374"],["62054.90","0.094"],["62055.30","0.021"],["62055.50","0.001"],["62056.10","0.003"],["62056.20","2.641"],["62057.10","0.732"],["62057.20","0.564"],["62057.80","0.002"],["62058.80","0.060"],["62059.00","0.060"],["62059.10","0.128"],["62059.30","0.122"],["62059.90","0.061"],["62060.00","0.002"],["62060.70","0.415"],["62062.20","0.813"],["62062.50","0.223"],["62062.60","0.081"],["62063.10","0.103"],["62065.00","0.007"],["62065.20","0.002"],["62067.30","0.053"],["62068.00","0.005"],["62068.60","0.004"],["62068.70","0.029"],["62069.20","0.003"],["62070.00","0.003"],["62070.60","0.006"],["62071.10","0.001"],["62071.90","0.005"],["62072.00","0.004"],["62072.10","0.372"],["62072.20","1.804"],["62072.70","0.001"],["62073.00","1.802"],["62073.60","0.050"],["62073.70","10.222"]],"e":"depthUpdate","ps":"BTCUSDT","pu":10998401740735,"s":"BTCUSDT","st":1,"u":10998401752650}
{"E":1783504335608,"T":1783504335607,"U":10998401752898,"a":[["62074.50","0.000"],["62078.50","0.002"],["62079.00","0.009"],["62079.20","0.165"],["62079.40","1.478"],["62080.60","0.090"],["62080.90","0.157"],["62081.20","0.058"],["62081.40","0.374"],["62082.10","2.542"],["62082.30","0.002"],["62082.40","0.153"],["62083.40","0.565"],["62084.20","0.003"],["62084.70","0.434"],["62085.70","0.002"],["62092.70","0.022"],["62095.30","0.170"],["62096.50","14.404"],["62097.90","0.002"],["62102.80","0.001"],["62105.20","0.213"],["62105.30","0.441"],["62116.10","1.362"],["62121.30","0.861"],["62124.80","0.667"],["62130.10","0.004"],["62130.30","0.000"],["62133.00","1.472"],["62133.50","0.171"],["62134.20","0.122"],["62135.80","0.461"],["62136.20","0.233"],["62136.30","0.933"],["62136.40","0.935"],["62136.70","6.817"],["62138.90","23.026"],["62141.00","0.016"],["62142.00","7.595"],["62142.70","0.058"],["62151.50","0.218"],["62151.90","1.239"],["62152.00","2.242"],["62157.70","0.000"],["62163.90","0.000"],["62172.80","1.362"],["62172.90","1.569"],["62193.70","0.008"],["62193.80","1.527"],["62202.80","0.523"],["62384.20","0.417"],["62429.10","0.000"],["62434.50","1.271"],["62689.80","0.000"],["62694.50","0.000"],["62695.20","0.010"],["62800.10","0.557"],["89523.20","0.396"]],"b":[["11573.70","0.320"],["11666.90","0.304"],["11873.70","0.624"],["11966.90","1.248"],["11968.70","0.864"],["49659.00","0.000"],["55866.30","0.002"],["58970.00","0.000"],["59590.70","0.003"],["60189.10","0.000"],["60906.20","0.819"],["61230.80","0.570"],["61253.30","1.058"],["61330.10","0.977"],["61453.00","0.031"],["61590.50","0.162"],["61758.30","0.083"],["61758.40","0.258"],["61806.90","0.085"],["61807.60","0.271"],["61863.50","0.001"],["61936.30","0.012"],["61963.10","0.001"],["61964.10","0.000"],["61965.50","0.727"],["61985.40","0.412"],["61985.50","1.530"],["62005.40","12.086"],["62006.20","0.004"],["62006.30","1.547"],["62006.90","0.749"],["62008.90","0.013"],["62013.10","19.078"],["62014.20","4.702"],["62026.00","0.050"],["62026.90","0.149"],["62028.70","0.084"],["62030.90","3.035"],["62031.00","0.066"],["62031.60","0.001"],["62037.60","0.758"],["62038.90","0.008"],["62039.70","1.451"],["62041.20","0.471"],["62046.60","0.120"],["62048.50","0.059"],["62048.70","0.040"],["62050.50","0.760"],["62052.00","0.581"],["62053.50","0.701"],["62054.90","0.014"],["62055.50","0.006"],["62058.60","1.018"],["62059.30","0.062"],["62059.40","0.122"],["62059.60","0.048"],["62059.90","0.001"],["62061.90","0.122"],["62062.60","0.141"],["62062.80","0.773"],["62063.10","0.163"],["62063.40","0.034"],["62063.60","0.001"],["62066.60","0.003"],["62067.40","0.001"],["62067.90","0.395"],["62068.80","0.007"],["62070.40","0.001"],["62070.70","0.005"],["62071.90","0.001"],["62072.00","0.002"],["62072.30","0.002"],["62073.00","1.800"],["62073.40","0.001"]],"e":"depthUpdate","ps":"BTCUSDT","pu":10998401752650,"s":"BTCUSDT","st":1,"u":10998401760594}
{"E":1783504335710,"T":1783504335709,"U":10998401760692,"a":[["62074.80","0.003"],["62077.50","0.005"],["62079.10","0.165"],["62079.20","0.726"],["62080.20","0.211"],["62080.90","0.225"],["62081.40","0.464"],["62082.00","0.104"],["62082.10","2.632"],["62082.20","0.002"],["62092.50","0.023"],["62092.70","0.006"],["62096.00","1.379"],["62096.40","0.135"],["62096.80","0.061"],["62100.60","0.463"],["62131.00","0.001"],["62133.00","1.370"],["62133.50","0.171"],["62134.00","0.161"],["62134.20","0.212"],["62136.20","0.132"],["62136.30","0.933"],["62136.40","0.834"],["62141.70","0.972"],["62142.40","0.071"],["62143.00","0.004"],["62151.60","0.027"],["62157.80","0.045"],["62164.00","0.016"],["62224.40","0.012"],["62274.00","0.817"],["62653.00","0.012"],["62694.50","0.000"],["63222.20","1.037"]],"b":[["1000.00","210.542"],["11573.70","0.464"],["11666.90","0.160"],["11873.70","0.896"],["11966.90","1.120"],["11968.70","0.720"],["55866.30","0.002"],["58970.00","0.000"],["59590.70","0.000"],["61453.00","0.031"],["61528.90","0.008"],["61863.50","0.000"],["61914.70","0.000"],["61993.10","2.008"],["62003.00","0.000"],["62006.40","0.016"],["62007.90","0.268"],["62013.10","0.010"],["62015.20","21.696"],["62022.50","0.100"],["62030.90","2.975"],["62042.70","0.135"],["62051.90","0.000"],["62052.80","0.242"],["62056.00","1.402"],["62056.30","0.564"],["62057.10","0.007"],["62057.20","0.000"],["62058.70","0.171"],["62059.00","0.000"],["62059.30","0.002"],["62059.40","0.002"],["62060.20","0.001"],["62061.90","0.182"],["62062.00","0.480"],["62062.60","0.201"],["62062.70","0.821"],["62064.10","0.684"],["62064.40","0.910"],["62065.50","0.003"],["62068.60","0.003"],["62068.70","0.028"],["62068.80","0.006"],["62068.90","0.000"],["62069.00","0.002"]],"e":"depthUpdate","ps":"BTCUSDT","pu":10998401760594,"s":"BTCUSDT","st":1,"u":10998401770821}
{"E":1783504335812,"T":1783504335810,"U":10998401770910,"a":[["62073.80","6.654"],["62079.20","0.165"],["62080.80","1.127"],["62080.90","0.224"],["62081.50","0.377"],["62082.00","0.434"],["62082.20","0.000"],["62087.20","0.002"],["62087.40","0.018"],["62090.90","0.098"],["62092.50","0.103"],["62096.00","1.363"],["62097.10","0.212"],["62103.40","0.325"],["62104.70","0.105"],["62105.00","0.227"],["62105.20","0.108"],["62105.30","0.336"],["62107.60","1.534"],["62114.90","4.463"],["62121.30","0.735"],["62128.00","1.051"],["62133.00","1.472"],["62133.40","0.101"],["62133.50","0.093"],["62133.60","0.022"],["62133.70","0.360"],["62134.00","0.059"],["62134.10","0.528"],["62134.30","0.952"],["62134.60","0.295"],["62134.70","0.017"],["62135.10","0.452"],["62135.80","0.360"],["62136.70","2.234"],["62138.90","0.022"],["62141.00","22.143"],["62141.60","0.124"],["62142.70","0.000"],["62147.30","0.003"],["62205.40","0.003"],["62227.00","1.206"],["62239.10","0.391"],["62239.20","0.000"],["62243.70","0.001"],["62245.40","0.005"],["62263.50","3.793"],["62570.40","0.323"],["62694.50","0.000"],["63313.00","0.106"],["89523.20","0.402"]],"b":[["1000.00","210.542"],["11573.70","0.592"],["11666.90","0.032"],["11873.70","1.168"],["11966.90","0.976"],["11968.70","0.592"],["55866.30","0.002"],["58966.50","0.000"],["58970.00","0.000"],["60192.90","2.406"],["60832.30","0.003"],["61261.10","1.141"],["61453.00","0.031"],["61560.30","0.162"],["61799.10","0.000"],["61803.50","8.105"],["61858.80","0.000"],["61863.50","0.001"],["61879.60","3.094"],["61881.10","0.000"],["61916.10","1.156"],["61937.60","0.007"],["61964.40","0.019"],["61966.10","0.005"],["61998.40","0.006"],["62006.90","0.747"],["62007.10","0.160"],["62013.10","19.043"],["62015.20","2.628"],["62022.00","0.232"],["62022.10","0.098"],["62032.00","0.698"],["62035.30","0.069"],["62042.70","0.003"],["62046.70","0.324"],["62047.60","2.621"],["62050.90","0.135"],["62052.90","0.169"],["62053.50","0.001"],["62058.00","0.746"],["62058.80","0.000"],["62059.10","0.209"],["62067.20","0.002"],["62068.00","0.007"],["62068.40","0.001"],["62068.70","0.017"],["62069.90","0.293"],["62070.00","0.005"],["62073.70","10.223"]],"e":"depthUpdate","ps":"BTCUSDT","pu":10998401770821,"s":"BTCUSDT","st":1,"u":10998401778607}
{"E":1783504335914,"T":1783504335913,"U":10998401778746,"a":[["62073.80","5.693"],["62077.90","0.010"],["62078.40","0.154"],["62078.90","0.000"],["62079.40","0.902"],["62080.30","0.005"],["62080.40","0.002"],["62080.70","0.578"],["62081.50","0.376"],["62081.90","0.021"],["62083.50","0.664"],["62085.90","0.001"],["62087.40","0.002"],["62088.40","1.493"],["62090.90","0.017"],["62091.00","0.001"],["62092.10","0.000"],["62092.50","0.023"],["62093.00","1.329"],["62093.30","0.295"],["62095.50","0.713"],["62095.90","0.001"],["62096.80","0.002"],["62097.10","0.051"],["62097.20","0.001"],["62098.30","0.121"],["62098.40","0.107"],["62098.90","0.099"],["62099.00","0.097"],["62103.40","0.003"],["62105.20","0.213"],["62105.30","0.441"],["62105.40","1.627"],["62112.60","0.337"],["62129.40","0.000"],["62130.80","0.006"],["62133.00","1.370"],["62133.50","0.003"],["62133.60","0.123"],["62134.10","0.384"],["62134.20","0.223"],["62138.90","22.149"],["62141.00","0.016"],["62142.00","7.512"],["62205.40","0.582"],["62227.00","1.193"],["62694.50","0.000"],["63129.10","0.316"]],"b":[["11573.70","0.512"],["11666.90","0.000"],["11873.70","1.440"],["11966.90","0.848"],["11968.70","0.448"],["11973.70","0.112"],["55866.30","0.002"],["58970.00","0.000"],["59590.70","0.003"],["61453.00","0.031"],["61488.50","0.162"],["61758.40","0.258"],["61763.30","0.003"],["61806.10","0.084"],["61863.50","0.000"],["61896.40","0.169"],["61916.10","0.000"],["61916.70","1.279"],["61938.30","0.663"],["62007.10","0.158"],["62022.00","0.100"],["62027.20","0.065"],["62037.70","0.005"],["62039.70","1.411"],["62040.80","0.061"],["62041.20","0.455"],["62047.30","1.365"],["62047.40","1.384"],["62049.20","0.003"],["62052.00","0.001"],["62052.90","0.161"],["62054.30","0.584"],["62055.50","0.014"],["62056.00","0.677"],["62056.30","0.000"],["62058.40","0.080"],["62058.70","0.997"],["62059.00","0.725"],["62059.70","0.049"],["62061.10","0.053"],["62061.80","1.128"],["62064.40","0.912"],["62064.70","0.801"],["62065.70","0.730"],["62066.90","0.091"],["62068.00","0.005"],["62068.70","0.020"],["62070.60","0.001"],["62071.30","0.005"],["62072.00","0.000"],["62072.20","1.801"],["62072.60","0.003"],["62073.60","0.054"]],"e":"depthUpdate","ps":"BTCUSDT","pu":10998401778607,"s":"BTCUSDT","st":1,"u":10998401785532}
{"E":1783504336016,"T":1783504336014,"U":10998401785636,"a":[["62073.80","4.119"],["62074.60","0.000"],["62076.40","0.121"],["62078.30","0.005"],["62078.90","0.120"],["62079.10","0.002"],["62079.20","0.002"],["62079.30","0.225"],["62080.30","0.001"],["62081.30","0.002"],["62081.80","0.990"],["62083.40","0.566"],["62087.80","1.050"],["62088.40","1.373"],["62088.60","0.000"],["62089.70","1.055"],["62089.80","0.399"],["62091.90","0.102"],["62095.70","0.111"],["62095.90","0.164"],["62096.00","1.379"],["62096.40","0.071"],["62098.20","0.404"],["62098.40","0.091"],["62105.60","0.866"],["62205.40","0.586"],["62369.20","0.000"],["62384.20","0.577"],["62689.50","0.030"],["62694.50","0.000"],["63313.00","0.103"],["89523.20","0.408"]],"b":[["1000.00","210.542"],["11573.70","0.384"],["11873.70","1.712"],["11966.90","0.704"],["11968.70","0.320"],["11973.70","0.240"],["55866.30","0.002"],["58970.00","0.000"],["59590.70","0.000"],["61368.90","0.000"],["61453.00","0.031"],["61758.40","0.420"],["61814.30","0.005"],["61818.00","0.295"],["61819.00","0.283"],["61846.50","0.000"],["61863.50","0.001"],["61938.30","0.659"],["61951.60","5.234"],["61999.70","0.016"],["62034.10","0.064"],["62040.80","0.101"],["62047.40","1.344"],["62050.90","0.003"],["62051.80","0.580"],["62053.00","0.000"],["62054.30","0.004"],["62056.30","0.132"],["62056.60","0.775"],["62057.80","0.002"],["62058.10","0.720"],["62058.70","0.433"],["62059.00","0.000"],["62064.80","0.152"],["62067.00","0.002"],["62067.60","0.000"],["62067.90","0.489"],["62069.50","0.125"],["62072.30","0.000"],["62073.70","10.225"]],"e":"depthUpdate","ps":"BTCUSDT","pu":10998401785532,"s":"BTCUSDT","st":1,"u":10998401793064}
{"E":1783504336118,"T":1783504336117,"U":10998401793266,"a":[["62073.80","6.665"],["62077.50","0.007"],["62077.60","0.986"],["62078.70","0.563"],["62078.80","0.742"],["62079.20","0.164"],["62079.30","0.548"],["62079.40","0.926"],["62081.10","0.003"],["62083.70","1.291"],["62087.30","0.726"],["62087.40","0.326"],["62087.50","0.219"],["62087.80","0.325"],["62088.30","0.323"],["62089.00","0.000"],["62089.80","0.077"],["62090.20","0.583"],["62092.20","0.170"],["62092.30","2.430"],["62093.00","0.749"],["62094.90","0.179"],["62095.20","0.080"],["62095.90","0.458"],["62096.00","1.363"],["62098.30","0.001"],["62104.10","1.685"],["62104.20","0.852"],["62104.60","0.002"],["62104.70","0.000"],["62105.00","0.122"],["62105.20","0.108"],["62105.30","0.247"],["62105.40","1.433"],["62105.60","0.672"],["62133.10","0.001"],["62133.40","0.000"],["62133.60","0.022"],["62134.10","0.288"],["62134.20","0.122"],["62136.20","0.132"],["62137.30","0.001"],["62142.40","0.004"],["62694.50","0.000"],["62808.10","2.394"],["62870.00","0.567"],["63313.00","0.100"]],"b":[["1000.00","210.542"],["11573.70","0.240"],["11873.70","1.984"],["11966.90","0.576"],["11968.70","0.176"],["11973.70","0.384"],["49657.70","0.000"],["55866.30","0.002"],["58970.00","0.000"],["59590.70","0.003"],["60832.80","0.004"],["61453.00","0.031"],["61595.50","0.013"],["61863.50","0.000"],["62002.60","0.048"],["62008.60","0.488"],["62021.90","0.569"],["62022.00","0.150"],["62032.00","0.681"],["62034.10","0.124"],["62042.00","2.501"],["62045.90","0.060"],["62046.70","0.002"],["62047.60","2.562"],["62050.00","0.584"],["62050.70","0.328"],["62051.60","0.245"],["62051.80","0.000"],["62052.70","1.386"],["62052.90","0.000"],["62053.90","0.009"],["62054.40","0.002"],["62054.80","0.725"],["62055.50","0.570"],["62055.60","0.000"],["62056.30","0.000"],["62056.60","0.050"],["62056.70","0.048"],["62058.10","0.156"],["62059.10","0.128"],["62061.80","1.391"],["62062.10","0.001"],["62062.20","0.249"],["62062.70","0.823"],["62063.90","0.002"],["62064.30","0.127"],["62064.40","0.910"],["62064.80","0.906"],["62065.00","0.030"],["62065.20","0.000"],["62065.90","0.005"],["62066.60","0.001"],["62067.90","0.228"],["62068.00","0.003"],["62069.50","0.009"],["62070.80","0.050"],["62071.10","0.001"],["62071.60","0.004"],["62071.90","0.003"],["62072.10","0.325"],["62072.60","0.001"],["62072.90","0.000"],["62073.00","0.000"],["62073.30","0.002"],["62073.60","0.052"],["62073.70","7.823"]],"e":"depthUpdate","ps":"BTCUSDT","pu":10998401793064,"s":"BTCUSDT","st":1,"u":10998401801820}
{"E":1783504336220,"T":1783504336219,"U":10998401801943,"a":[["62073.80","6.900"],["62075.40","0.002"],["62078.70","0.002"],["62079.30","0.484"],["62082.10","2.648"],["62083.00","0.244"],["62083.40","0.325"],["62083.70","0.727"],["62084.70","0.432"],["62086.10","0.096"],["62087.10","0.616"],["62087.20","0.002"],["62087.30","0.726"],["62087.40","0.002"],["62089.70","1.057"],["62090.60","0.003"],["62091.50","1.403"],["62092.20","0.008"],["62092.90","0.093"],["62095.70","0.071"],["62095.90","0.296"],["62096.00","1.427"],["62098.90","0.060"],["62104.00","0.195"],["62104.20","0.763"],["62104.40","0.121"],["62115.80","0.605"],["62121.70","0.002"],["62133.70","0.252"],["62141.70","0.882"],["62146.90","0.017"],["62152.80","0.018"],["62178.00","0.000"],["62183.90","0.003"],["62694.50","0.002"],["63518.20","0.000"],["64975.50","0.101"],["64994.20","0.002"],["89523.20","0.414"]],"b":[["11573.70","0.112"],["11873.70","2.256"],["11966.90","0.432"],["11968.70","0.048"],["11973.70","0.512"],["55866.30","0.002"],["58970.00","0.020"],["59590.70","0.000"],["61289.40","4.263"],["61392.20","1.056"],["61453.00","0.031"],["61758.40","0.420"],["61818.80","0.684"],["61863.50","0.001"],["61957.70","0.001"],["61963.60","0.004"],["61988.70","0.001"],["61994.60","0.034"],["62000.40","0.011"],["62013.10","0.010"],["62015.20","21.661"],["62019.80","0.005"],["62025.70","0.013"],["62035.70","0.016"],["62048.10","0.067"],["62050.50","0.770"],["62050.90","0.001"],["62051.60","0.235"],["62053.60","0.281"],["62056.80","0.064"],["62058.60","1.020"],["62064.30","0.125"],["62064.90","0.084"],["62065.20","0.004"],["62065.40","0.027"],["62069.30","0.002"]],"e":"depthUpdate","ps":"BTCUSDT","pu":10998401801820,"s":"BTCUSDT","st":1,"u":10998401810512}
{"E":1783504336322,"T":1783504336321,"U":10998401810586,"a":[["62074.60","0.049"],["62076.00","0.000"],["62078.70","0.563"],["62080.80","1.128"],["62081.90","0.020"],["62082.10","2.632"],["62082.50","0.244"],["62083.00","0.003"],["62086.10","0.016"],["62087.30","0.001"],["62088.20","0.736"],["62088.30","0.001"],["62088.50","0.010"],["62089.60","0.323"],["62090.40","1.718"],["62091.50","1.363"],["62092.80","0.148"],["62094.20","0.739"],["62095.70","0.111"],["62104.20","0.852"],["62111.00","0.439"],["62113.40","0.660"],["62136.20","0.000"],["62245.40","0.002"],["62245.50","0.003"],["62384.20","0.737"],["62694.50","0.000"],["62942.80","0.400"],["63174.30","0.010"],["63400.00","12.901"],["63800.00","14.726"]],"b":[["1000.00","210.542"],["11572.10","0.032"],["11573.70","0.000"],["11773.70","0.128"],["11873.70","2.272"],["11966.90","0.336"],["11968.70","0.000"],["11973.70","0.656"],["55866.30","0.002"],["58956.60","0.000"],["58956.70","0.003"],["58970.00","0.000"],["60832.30","0.006"],["61230.70","0.005"],["61453.00","0.031"],["61863.50","0.000"],["61966.10","0.002"],["61966.20","0.124"],["62000.50","0.004"],["62014.10","0.045"],["62020.30","0.017"],["62020.90","0.158"],["62040.80","0.061"],["62041.50","0.000"],["62049.20","0.043"],["62054.80","0.000"],["62055.50","0.006"],["62057.10","0.732"],["62057.20","0.564"],["62064.50","0.006"],["62065.90","0.000"],["62067.90","0.232"],["62069.50","0.005"],["62069.60","0.001"],["62069.90","0.285"],["62070.80","0.001"],["62073.70","7.797"]],"e":"depthUpdate","ps":"BTCUSDT","pu":10998401810512,"s":"BTCUSDT","st":1,"u":10998401819993}
{"E":1783504336424,"T":1783504336421,"U":10998401820106,"a":[["62073.80","6.920"],["62078.60","0.154"],["62078.70","0.002"],["62089.60","0.455"],["62090.40","1.702"],["62092.80","0.068"],["62095.50","0.773"],["62095.60","0.017"],["62097.00","0.083"],["62098.70","5.387"],["62694.50","0.000"],["62694.60","0.895"],["62778.30","1.749"],["62896.20","0.000"],["63173.60","0.837"],["63309.40","0.032"],["63450.50","0.674"],["89523.20","0.420"]],"b":[["1000.00","210.542"],["11568.70","0.816"],["11572.10","0.000"],["11773.70","0.272"],["11873.70","2.256"],["11966.90","0.208"],["11973.70","0.784"],["55866.30","0.002"],["58968.50","0.003"],["58970.00","0.000"],["59590.70","0.003"],["61142.80","0.169"],["61280.00","3.059"],["61453.00","0.031"],["61537.50","2.270"],["61763.30","0.004"],["61863.50","0.001"],["62002.80","0.004"],["62008.80","0.000"],["62013.70","0.215"],["62027.20","0.001"],["62043.70","0.029"],["62056.30","1.289"],["62057.10","0.007"],["62057.20","0.000"],["62059.80","0.003"],["62068.40","0.002"],["62070.80","0.050"],["62071.80","0.059"]],"e":"depthUpdate","ps":"BTCUSDT","pu":10998401819993,"s":"BTCUSDT","st":1,"u":10998401829137}
{"E":1783504336526,"T":1783504336525,"U":10998401829412,"a":[["62073.80","6.978"],["62094.00","0.702"],["62095.50","0.073"],["62102.30","2.480"],["62104.00","0.001"],["62104.10","1.491"],["62104.20","0.658"],["62126.50","2.428"],["62134.70","0.002"],["62138.90","0.022"],["62147.30","22.130"],["62205.40","0.573"],["62622.50","0.713"],["62694.50","0.000"]],"b":[["11568.70","0.672"],["11773.70","0.400"],["11873.70","2.272"],["11966.90","0.064"],["11973.70","0.928"],["49654.00","0.000"],["55866.30","0.002"],["58970.00","0.000"],["59590.70","0.000"],["61261.80","1.467"],["61453.00","0.031"],["61758.40","0.410"],["61761.70","0.014"],["61863.50","0.000"],["61938.30","0.000"],["61938.50","0.659"],["62022.10","0.016"],["62035.70","0.000"],["62041.50","0.000"],["62043.70","0.019"]],"e":"depthUpdate","ps":"BTCUSDT","pu":10998401829137,"s":"BTCUSDT","st":1,"u":10998401836130}
{"E":1783504336628,"T":1783504336627,"U":10998401836329,"a":[["62073.80","6.955"],["62079.20","0.164"],["62084.00","0.008"],["62084.70","0.589"],["62085.60","0.007"],["62088.10","0.017"],["62088.40","2.003"],["62088.50","0.006"],["62089.40","0.081"],["62090.00","1.839"],["62095.60","0.001"],["62097.00","0.003"],["62098.70","0.387"],["62104.00","0.195"],["62104.20","0.658"],["62136.70","6.616"],["62138.90","21.808"],["62141.00","0.016"],["62147.30","0.003"],["62159.70","0.006"],["62384.20","0.735"],["62694.50","0.000"],["62812.40","1.749"],["89523.20","0.426"]],"b":[["1000.00","210.542"],["11568.70","0.544"],["11773.70","0.608"],["11873.70","2.128"],["11966.90","0.000"],["11973.70","1.056"],["55866.30","0.002"],["58970.00","0.000"],["59590.70","0.003"],["61453.00","0.031"],["61763.30","0.006"],["61863.50","0.001"],["62020.30","0.001"]],"e":"depthUpdate","ps":"BTCUSDT","pu":10998401836130,"s":"BTCUSDT","st":1,"u":10998401841847}
{"E":1783504336730,"T":1783504336729,"U":10998401841898,"a":[["62073.80","6.956"],["62076.00","0.002"],["62079.20","0.164"],["62082.80","0.121"],["62084.40","0.124"],["62086.00","0.127"],["62087.50","0.343"],["62088.10","0.001"],["62089.40","0.001"],["62092.10","0.016"],["62094.40","0.781"],["62112.60","0.282"],["62136.70","2.234"],["62138.90","0.022"],["62147.30","21.789"],["62205.40","0.003"],["62663.50","3.086"],["62694.50","0.000"],["63309.20","0.003"],["64000.00","108.267"]],"b":[["1000.00","210.542"],["11568.70","0.400"],["11773.70","0.880"],["11873.70","1.856"],["11973.70","1.200"],["55866.30","0.002"],["58970.00","0.000"],["59590.70","0.000"],["61453.00","0.031"],["61481.30","0.000"],["61516.30","2.810"],["61757.10","0.273"],["61763.30","0.007"],["61863.50","0.000"],["61887.50","0.676"],["61938.50","0.000"],["62015.20","20.395"],["62015.30","4.908"],["62018.10","0.057"],["62039.30","0.020"],["62067.90","0.228"],["62068.90","0.005"],["62069.20","0.007"],["62070.70","0.000"],["62070.90","0.003"],["62071.90","0.001"]],"e":"depthUpdate","ps":"BTCUSDT","pu":10998401841847,"s":"BTCUSDT","st":1,"u":10998401848666}
{"E":1783504336832,"T":1783504336830,"U":10998401848834,"a":[["62074.40","0.025"],["62076.40","0.122"],["62078.90","0.121"],["62079.30","0.484"],["62089.10","0.101"],["62091.20","0.089"],["62092.10","0.000"],["62094.40","0.701"],["62105.10","0.160"],["62107.60","0.693"],["62114.60","0.030"],["62136.80","0.056"],["62137.50","0.414"],["62147.30","0.003"],["62205.40","0.557"],["62227.00","1.212"],["62694.50","0.000"],["62870.10","3.888"],["89523.20","0.432"]],"b":[["11568.70","0.272"],["11773.70","1.152"],["11873.70","1.584"],["11973.70","1.328"],["55866.30","0.002"],["58966.50","0.002"],["58970.00","0.000"],["61080.90","0.000"],["61513.50","2.414"],["61590.50","0.000"],["61758.40","0.410"],["61761.70","0.004"],["61803.50","8.097"],["61804.10","0.008"],["61817.50","0.000"],["61840.30","0.001"],["61863.50","0.001"],["61916.70","0.140"],["61917.00","1.422"],["61938.60","0.942"],["61991.30","0.006"],["61993.10","0.001"],["61993.60","1.589"],["62013.70","0.231"],["62014.20","0.001"],["62030.90","2.142"],["62044.90","0.013"],["62071.20","0.043"]],"e":"depthUpdate","ps":"BTCUSDT","pu":10998401848666,"s":"BTCUSDT","st":1,"u":10998401856355}
{"E":1783504336934,"T":1783504336933,"U":10998401856452,"a":[["62073.80","6.720"],["62078.60","0.001"],["62082.70","0.021"],["62087.00","0.167"],["62087.40","0.164"],["62089.10","0.085"],["62089.60","0.323"],["62089.70","1.059"],["62090.30","0.808"],["62091.20","0.009"],["62092.20","0.170"],["62095.30","0.186"],["62095.70","0.192"],["62095.90","0.458"],["62097.50","0.160"],["62101.10","0.037"],["62101.90","0.222"],["62105.10","0.991"],["62108.10","0.325"],["62121.80","4.705"],["62135.90","0.372"],["62136.20","0.132"],["62136.80","21.842"],["62138.90","0.022"],["62144.70","8.358"],["62168.40","0.059"],["62168.50","2.085"],["62169.50","0.002"],["62694.50","0.000"],["62911.80","1.269"],["63309.20","0.000"]],"b":[["1000.00","210.542"],["11568.70","0.128"],["11773.70","1.424"],["11873.70","1.312"],["11973.70","1.472"],["55866.30","0.002"],["58970.00","0.000"],["59590.70","0.003"],["60211.50","0.010"],["60825.60","0.018"],["60833.90","0.197"],["61129.20","0.000"],["61193.50","0.653"],["61453.00","0.031"],["61863.50","0.000"],["61955.90","0.368"],["61956.30","0.482"],["61995.50","8.363"],["62018.30","4.701"],["62022.00","0.232"],["62023.80","0.017"],["62029.70","0.079"],["62035.00","0.912"],["62051.40","0.325"],["62054.10","0.005"],["62057.70","0.164"],["62058.30","0.000"],["62058.60","1.022"],["62061.80","1.128"],["62063.90","0.083"],["62064.90","0.002"],["62068.00","0.266"]],"e":"depthUpdate","ps":"BTCUSDT","pu":10998401856355,"s":"BTCUSDT","st":1,"u":10998401862972}
{"E":1783504337036,"T":1783504337033,"U":10998401863090,"a":[["62073.80","6.782"],["62078.70","0.007"],["62081.40","0.539"],["62081.80","0.928"],["62082.70","0.001"],["62084.30","0.181"],["62087.00","0.061"],["62087.40","0.002"],["62088.80","0.190"],["62089.80","0.002"],["62091.50","1.443"],["62092.20","0.051"],["62095.30","0.170"],["62095.70","0.136"],["62095.90","0.296"],["62096.80","0.032"],["62097.50","0.080"],["62098.20","0.361"],["62136.80","0.056"],["62141.00","21.802"],["62177.00","11.513"],["62689.50","0.000"],["62694.50","0.000"],["89523.20","0.438"]],"b":[["1000.00","210.542"],["11568.70","0.000"],["11773.70","1.696"],["11873.70","1.040"],["11973.70","1.600"],["55866.30","0.002"],["58970.00","0.000"],["59590.70","0.000"],["60665.00","0.072"],["60832.30","0.009"],["61453.00","0.031"],["61560.30","0.324"],["61763.30","0.008"],["61863.50","0.001"],["61963.30","11.493"],["62006.80","21.233"],["62008.50","1.131"],["62015.20","1.362"],["62015.30","0.001"],["62021.90","0.437"],["62022.00","0.100"],["62063.90","0.002"],["62064.90","0.002"],["62071.10","0.003"]],"e":"depthUpdate","ps":"BTCUSDT","pu":10998401862972,"s":"BTCUSDT","st":1,"u":10998401870198}
{"E":1783504337138,"T":1783504337136,"U":10998401870379,"a":[["62088.80","0.174"],["62091.50","1.363"],["62093.30","0.311"],["62093.60","0.121"],["62096.40","0.071"],["62097.20","0.001"],["62102.30","2.375"],["62176.80","3.152"],["62364.60","0.018"],["62694.50","0.000"],["62913.60","3.424"]],"b":[["11773.70","1.968"],["11872.10","0.000"],["11873.30","0.000"],["11873.70","0.992"],["11973.70","1.456"],["49655.00","0.000"],["55866.30","0.002"],["58963.60","0.004"],["58963.70","0.003"],["58970.00","0.000"],["59590.70","0.003"],["60641.10","0.825"],["61000.00","101.267"],["61117.50","0.296"],["61289.40","3.449"],["61408.00","5.625"],["61453.00","0.031"],["61537.50","1.946"],["61761.70","0.014"],["61863.50","0.000"],["61965.50","2.350"],["61966.20","0.121"],["61966.30","0.682"],["62011.70","0.017"],["62039.40","0.003"],["62039.50","0.005"],["62039.60","0.003"],["62055.50","0.008"],["62055.60","0.002"],["62055.70","0.002"],["62064.90","0.134"],["62073.40","0.009"],["62073.70","7.680"]],"e":"depthUpdate","ps":"BTCUSDT","pu":10998401870198,"s":"BTCUSDT","st":1,"u":10998401877539}
{"E":1783504337240,"T":1783504337238,"U":10998401877568,"a":[["62076.60","0.067"],["62089.70","1.059"],["62093.30","0.295"],["62093.60","0.041"],["62112.70","0.062"],["62138.90","21.808"],["62141.00","0.016"],["62205.40","0.552"],["62530.20","0.000"],["62694.50","0.000"],["62808.10","2.125"],["62849.70","0.269"],["62880.70","0.318"],["63020.20","0.010"],["89523.20","0.444"]],"b":[["1000.00","210.542"],["11773.70","2.240"],["11868.70","0.240"],["11873.70","0.992"],["11973.70","1.328"],["55866.30","0.002"],["61141.00","0.368"],["61448.00","0.166"],["61453.00","0.031"],["61863.50","0.001"],["61938.60","0.283"],["61938.70","0.659"],["61983.30","1.926"],["62006.80","2.173"],["62013.10","19.070"],["62050.50","0.754"],["62052.10","0.018"],["62058.60","1.022"],["62066.70","0.819"],["62067.90","0.329"],["62068.90","0.000"],["62071.90","0.003"]],"e":"depthUpdate","ps":"BTCUSDT","pu":10998401877539,"s":"BTCUSDT","st":1,"u":10998401883851}
{"E":1783504337342,"T":1783504337341,"U":10998401883991,"a":[["62073.80","6.783"],["62076.30","0.166"],["62081.80","0.187"],["62090.20","0.003"],["62091.20","0.589"],["62094.90","0.059"],["62095.90","0.133"],["62096.20","0.122"],["62104.00","0.090"],["62104.10","1.685"],["62104.20","0.747"],["62160.00","0.547"],["62240.00","0.607"],["62320.00","0.543"],["62400.00","14.498"],["62480.00","1.200"],["62694.50","0.000"],["62919.80","0.000"],["62930.90","5.881"],["62942.70","0.276"]],"b":[["1000.00","210.542"],["11773.70","2.512"],["11868.70","0.112"],["11873.70","0.992"],["11973.70","1.184"],["55866.30","0.002"],["58965.30","0.003"],["58970.00","0.000"],["59590.70","0.000"],["60833.40","0.000"],["61453.00","0.031"],["61532.30","0.000"],["61534.30","0.008"],["61680.00","1.099"],["61760.00","0.591"],["61761.90","0.016"],["61763.90","0.008"],["61840.00","0.447"],["61863.50","0.000"],["61920.00","0.504"],["62000.00","8.915"],["62002.40","0.054"],["62050.00","0.004"],["62051.00","0.080"],["62052.50","2.045"],["62056.30","0.725"],["62058.10","0.720"],["62058.70","0.433"],["62067.90","0.002"],["62068.10","0.743"],["62068.20","0.523"]],"e":"depthUpdate","ps":"BTCUSDT","pu":10998401883851,"s":"BTCUSDT","st":1,"u":10998401889852}
{"E":1783504337444,"T":1783504337441,"U":10998401889933,"a":[["62073.80","6.881"],["62076.30","0.003"],["62090.90","0.019"],["62095.90","0.296"],["62694.40","0.162"],["62694.50","0.000"],["62694.60","0.894"],["63066.90","0.791"],["89523.20","0.450"]],"b":[["11673.70","0.032"],["11773.70","2.720"],["11868.70","0.000"],["11873.70","0.992"],["11973.70","1.056"],["55866.30","0.002"],["58970.00","0.000"],["59590.70","0.003"],["61219.20","0.000"],["61417.00","0.893"],["61453.00","0.031"],["61758.40","0.410"],["61761.70","0.004"],["61863.50","0.001"],["61913.50","1.273"],["62006.80","21.233"],["62013.10","0.010"],["62020.90","0.002"],["62051.00","0.000"],["62056.40","0.486"],["62058.10","0.720"]],"e":"depthUpdate","ps":"BTCUSDT","pu":10998401889852,"s":"BTCUSDT","st":1,"u":10998401896155}
{"E":1783504337546,"T":1783504337545,"U":10998401896355,"a":[["62073.80","6.882"],["62074.10","0.004"],["62076.30","0.003"],["62078.70","0.007"],["62079.00","0.032"],["62087.10","0.618"],["62095.90","0.164"],["62137.30","0.133"],["62194.60","0.138"],["62570.30","0.957"],["62694.50","0.000"],["62908.60","0.000"],["62973.80","0.952"],["63315.20","0.003"]],"b":[["1000.00","210.542"],["11673.70","0.160"],["11773.70","2.736"],["11873.70","0.992"],["11973.70","0.912"],["55866.30","0.002"],["58970.00","0.000"],["59590.70","0.000"],["60849.10","0.156"],["61100.90","0.010"],["61270.20","0.869"],["61352.60","2.495"],["61397.10","0.651"],["61451.60","0.000"],["61453.00","0.031"],["61484.00","0.721"],["61863.50","0.000"],["61976.90","0.000"],["62041.50","0.010"],["62056.40","0.486"],["62058.10","0.156"],["62058.20","1.930"],["62073.70","7.781"]],"e":"depthUpdate","ps":"BTCUSDT","pu":10998401896155,"s":"BTCUSDT","st":1,"u":10998401901060}
{"E":1783504337648,"T":1783504337645,"U":10998401901184,"a":[["62073.80","6.869"],["62076.30","0.166"],["62078.70","0.170"],["62081.70","0.252"],["62082.50","0.003"],["62121.20","1.537"],["62126.50","2.413"],["62135.10","0.467"],["62143.70","2.861"],["62160.00","0.565"],["62240.00","0.625"],["62245.50","0.000"],["62245.60","0.026"],["62320.00","0.561"],["62363.10","0.018"],["62364.60","0.000"],["62384.20","0.737"],["62400.00","14.516"],["62480.00","1.218"],["62694.50","0.000"],["89523.20","0.456"]],"b":[["1000.00","210.542"],["11673.70","0.304"],["11773.70","2.720"],["11873.70","0.992"],["11973.70","0.784"],["55866.30","0.002"],["59590.70","0.003"],["61215.50","0.000"],["61222.20","1.125"],["61226.20","0.490"],["61436.70","0.001"],["61453.00","0.031"],["61484.00","1.446"],["61680.00","1.117"],["61758.40","0.407"],["61760.00","0.609"],["61763.30","0.002"],["61840.00","0.465"],["61863.50","0.001"],["61891.60","4.042"],["61894.40","0.838"],["61920.00","0.522"],["61922.50","8.081"],["61953.50","8.077"],["61969.00","5.481"],["61984.50","2.022"],["62000.00","8.933"],["62006.80","2.173"],["62011.00","19.300"],["62020.90","0.158"],["62042.60","1.552"],["62070.10","0.003"]],"e":"depthUpdate","ps":"BTCUSDT","pu":10998401901060,"s":"BTCUSDT","st":1,"u":10998401906494}
{"E":1783504337750,"T":1783504337749,"U":10998401906699,"a":[["62077.30","0.002"],["62100.60","0.381"],["62102.30","2.371"],["62110.50","0.006"],["62116.70","0.082"],["62205.40","0.003"],["62694.50","0.000"],["62901.20","0.545"],["62911.70","3.637"],["63006.40","0.000"],["63308.30","0.136"],["63500.00","37.738"]],"b":[["11673.70","0.432"],["11773.70","2.736"],["11873.70","0.992"],["11973.70","0.640"],["55866.30","0.004"],["60700.00","67.350"],["61453.00","0.031"],["61761.70","0.014"],["61819.00","0.008"],["61820.00","0.798"],["61863.50","0.000"],["61938.70","0.000"],["62017.10","0.034"],["62018.40","1.867"]],"e":"depthUpdate","ps":"BTCUSDT","pu":10998401906494,"s":"BTCUSDT","st":1,"u":10998401911565}
{"E":1783504337852,"T":1783504337850,"U":10998401911735,"a":[["62076.30","0.166"],["62078.70","0.007"],["62079.20","0.002"],["62088.20","0.011"],["62089.10","0.810"],["62098.20","0.299"],["62098.80","0.063"],["62104.00","0.195"],["62104.20","0.852"],["62104.40","0.121"],["62111.60","1.482"],["62111.70","4.033"],["62112.70","0.005"],["62205.40","0.557"],["62227.00","1.212"],["62263.50","4.435"],["62694.50","0.000"],["62849.70","0.538"],["89523.20","0.462"]],"b":[["1000.00","210.542"],["11673.70","0.672"],["11773.70","2.528"],["11873.70","1.088"],["11973.70","0.512"],["55866.30","0.002"],["58966.50","0.000"],["59590.70","0.000"],["61141.00","0.736"],["61453.00","0.031"],["61479.30","3.886"],["61513.40","0.815"],["61804.10","0.000"],["61804.40","0.040"],["61863.50","0.001"],["61879.60","0.011"],["61880.80","2.955"],["61917.00","0.283"],["61917.30","1.123"],["61938.80","0.670"],["62027.90","0.065"],["62029.70","0.016"],["62047.40","1.384"],["62049.20","0.003"],["62056.40","0.486"],["62056.50","0.001"],["62058.10","0.720"],["62058.20","1.366"]],"e":"depthUpdate","ps":"BTCUSDT","pu":10998401911565,"s":"BTCUSDT","st":1,"u":10998401916459}
{"E":1783504337954,"T":1783504337953,"U":10998401916687,"a":[["62073.80","6.872"],["62078.70","0.170"],["62082.10","2.308"],["62087.50","0.181"],["62089.70","0.897"],["62097.50","0.080"],["62098.80","0.000"],["62099.30","0.058"],["62104.60","0.196"],["62111.70","4.939"],["62193.00","0.002"],["62198.60","2.430"],["62694.50","0.000"]],"b":[["1000.00","210.542"],["11673.70","0.944"],["11773.70","2.256"],["11873.70","1.232"],["11973.70","0.368"],["55866.30","0.002"],["59590.70","0.003"],["60832.30","0.012"],["61242.00","0.285"],["61327.20","0.732"],["61453.00","0.031"],["61577.10","0.000"],["61863.50","0.000"],["61978.50","0.003"],["61984.00","2.444"],["62008.50","0.975"],["62035.60","0.132"],["62056.40","0.486"],["62058.10","0.720"],["62059.90","0.082"],["62064.90","0.134"],["62068.70","0.000"],["62073.70","7.799"]],"e":"depthUpdate","ps":"BTCUSDT","pu":10998401916459,"s":"BTCUSDT","st":1,"u":10998401924997}
{"E":1783504338056,"T":1783504338055,"U":10998401925125,"a":[["62073.80","6.874"],["62088.30","0.003"],["62092.20","0.053"],["62096.30","0.066"],["62097.20","0.081"],["62104.10","1.580"],["62104.40","0.226"],["62104.60","0.091"],["62136.80","0.056"],["62138.90","21.449"],["62694.50","0.000"],["62815.40","0.000"],["62942.80","0.670"],["62986.30","0.555"],["89523.20","0.468"]],"b":[["11673.70","1.216"],["11773.70","1.984"],["11873.70","1.360"],["11973.70","0.240"],["55866.30","0.002"],["59590.70","0.000"],["60825.60","0.015"],["61453.00","0.031"],["61479.30","1.873"],["61513.40","2.827"],["61761.70","0.004"],["61763.30","0.012"],["61863.50","0.001"],["62035.60","0.000"],["62056.40","0.486"],["62058.10","0.720"]],"e":"depthUpdate","ps":"BTCUSDT","pu":10998401924997,"s":"BTCUSDT","st":1,"u":10998401931153}
{"E":1783504338158,"T":1783504338157,"U":10998401931186,"a":[["62074.80","0.005"],["62087.50","0.197"],["62090.10","0.085"],["62095.90","0.001"],["62096.30","0.050"],["62097.20","0.001"],["62102.30","2.375"],["62110.50","0.002"],["62694.50","0.000"],["62819.80","0.795"],["62868.00","0.804"]],"b":[["1000.00","210.542"],["11673.70","1.488"],["11773.70","1.712"],["11873.70","1.504"],["11973.70","0.096"],["49659.00","0.000"],["55866.30","0.002"],["61032.70","0.000"],["61190.70","0.308"],["61257.20","3.868"],["61453.00","0.031"],["61863.50","0.001"],["61990.50","0.000"],["61992.40","0.016"],["61994.50","1.367"],["61996.50","0.016"],["61998.50","0.690"],["62000.50","0.020"],["62002.50","0.673"],["62004.50","0.016"],["62065.00","0.032"],["62069.20","0.008"],["62070.40","0.005"],["62070.90","0.001"]],"e":"depthUpdate","ps":"BTCUSDT","pu":10998401931153,"s":"BTCUSDT","st":1,"u":10998401939511}
{"E":1783504338260,"T":1783504338259,"U":10998401939647,"a":[["62073.80","6.873"],["62076.30","0.003"],["62078.70","0.007"],["62079.00","0.009"],["62079.50","0.722"],["62081.20","0.299"],["62081.70","0.011"],["62087.50","0.181"],["62089.70","0.897"],["62090.10","0.005"],["62095.40","0.098"],["62095.60","0.017"],["62095.90","0.164"],["62104.60","0.196"],["62105.00","0.122"],["62300.00","8.810"],["62363.10","0.000"],["62694.50","0.000"],["62818.70","0.635"],["63084.80","0.006"],["89523.20","0.474"]],"b":[["1000.00","210.542"],["11673.70","1.760"],["11773.70","1.472"],["11873.70","1.568"],["11973.70","0.000"],["55866.30","0.002"],["59590.70","0.003"],["61095.70","0.001"],["61218.90","0.000"],["61425.30","0.002"],["61453.00","0.031"],["61479.30","0.504"],["61515.00","1.648"],["61577.10","0.324"],["61763.30","0.012"],["61863.50","0.000"],["62011.00","0.240"],["62011.60","0.001"],["62013.10","19.150"],["62014.10","0.029"],["62015.70","0.016"],["62022.00","0.100"],["62023.80","0.001"],["62028.00","1.482"],["62042.00","1.972"],["62048.10","0.051"],["62048.70","0.569"],["62049.70","0.100"],["62058.60","1.022"],["62064.90","0.134"],["62066.90","0.071"],["62068.30","0.132"],["62070.90","0.006"],["62071.10","0.005"],["62071.30","0.001"],["62071.90","0.001"],["62072.10","0.323"],["62072.20","0.001"],["62073.70","7.749"]],"e":"depthUpdate","ps":"BTCUSDT","pu":10998401939511,"s":"BTCUSDT","st":1,"u":10998401947771}
{"E":1783504338362,"T":1783504338361,"U":10998401947865,"a":[["62073.80","6.869"],["62075.30","0.013"],["62076.20","0.002"],["62077.90","0.012"],["62079.40","0.902"],["62079.50","0.722"],["62080.00","0.010"],["62095.40","0.018"],["62095.60","0.001"],["62105.00","0.211"],["62112.80","1.418"],["62151.60","0.011"],["62154.70","0.026"],["62157.80","0.029"],["62160.00","0.547"],["62160.90","0.229"],["62164.00","0.000"],["62167.10","0.020"],["62240.00","0.607"],["62320.00","0.543"],["62400.00","14.498"],["62694.50","0.000"],["62801.50","0.796"],["62863.50","0.794"]],"b":[["11673.70","2.032"],["11773.70","1.344"],["11873.70","1.424"],["55866.30","0.002"],["59590.70","0.000"],["61019.70","1.355"],["61198.20","0.000"],["61453.00","0.033"],["61680.00","1.099"],["61760.00","0.591"],["61840.00","0.447"],["61863.50","0.001"],["61900.00","3.738"],["61920.00","0.504"],["62000.00","8.915"],["62022.00","0.018"],["62029.70","0.000"],["62031.30","0.104"],["62056.40","0.486"],["62058.10","0.720"],["62068.40","0.084"],["62073.70","7.751"]],"e":"depthUpdate","ps":"BTCUSDT","pu":10998401947771,"s":"BTCUSDT","st":1,"u":10998401955993}
{"E":1783504338464,"T":1783504338461,"U":10998401956026,"a":[["62079.50","0.722"],["62098.20","0.362"],["62105.00","0.211"],["62136.80","21.483"],["62138.90","0.022"],["62160.00","0.565"],["62240.00","0.625"],["62320.00","0.561"],["62400.00","14.516"],["62480.00","1.236"],["62694.50","0.000"],["62794.40","0.795"],["62888.00","4.487"],["62928.00","7.087"],["63129.10","0.710"]],"b":[["1000.00","210.542"],["11673.70","2.304"],["11773.70","1.200"],["11873.70","1.296"],["49659.00","0.000"],["55866.30","0.002"],["59590.70","0.003"],["61266.70","1.305"],["61289.40","2.798"],["61453.00","0.031"],["61680.00","1.117"],["61760.00","0.609"],["61840.00","0.465"],["61863.50","0.000"],["61920.00","0.522"],["62000.00","9.033"],["62027.90","0.004"],["62056.40","0.486"],["62056.50","0.565"],["62058.00","0.046"],["62058.10","0.156"],["62073.70","7.747"]],"e":"depthUpdate","ps":"BTCUSDT","pu":10998401955993,"s":"BTCUSDT","st":1,"u":10998401961372}
{"E":1783504338566,"T":1783504338565,"U":10998401961650,"a":[["62079.50","0.732"],["62085.80","0.024"],["62089.60","0.325"],["62093.00","1.278"],["62097.60","0.471"],["62098.60","0.081"],["62104.00","0.090"],["62104.20","0.852"],["62104.30","0.391"],["62104.40","0.121"],["62104.60","0.091"],["62105.00","0.122"],["62111.10","0.002"],["62694.50","0.000"],["62778.30","1.272"],["63087.50","0.001"],["89523.20","0.480"]],"b":[["1000.00","210.542"],["11673.70","2.576"],["11773.70","1.072"],["11873.70","1.152"],["49659.00","0.000"],["55866.30","0.002"],["58963.60","0.001"],["58963.70","0.006"],["59590.70","0.000"],["61075.60","0.245"],["61453.00","0.031"],["61763.30","0.002"],["61863.50","0.001"],["61865.80","0.275"],["61916.30","0.015"],["62056.50","0.001"],["62056.60","0.614"],["62058.70","0.433"]],"e":"depthUpdate","ps":"BTCUSDT","pu":10998401961372,"s":"BTCUSDT","st":1,"u":10998401968785}
{"E":1783504338668,"T":1783504338665,"U":10998401968889,"a":[["62073.80","7.111"],["62074.00","0.005"],["62075.30","0.009"],["62075.40","0.004"],["62076.30","0.013"],["62076.90","0.002"],["62079.20","0.002"],["62079.40","0.000"],["62079.50","0.732"],["62086.30","0.904"],["62086.40","0.004"],["62092.30","2.422"],["62093.40","0.250"],["62093.50","0.008"],["62097.60","0.455"],["62098.60","0.001"],["62104.40","0.210"],["62104.60","0.002"],["62136.80","0.056"],["62143.70","5.892"],["62145.20","21.709"],["62360.50","0.018"],["62384.20","0.735"],["62694.50","0.000"],["63315.20","0.006"],["64000.00","108.746"],["68281.20","13.805"]],"b":[["11573.70","0.064"],["11673.70","2.720"],["11773.70","0.992"],["11873.70","1.024"],["49659.00","0.000"],["55866.30","0.002"],["61242.00","0.570"],["61453.00","0.031"],["61763.30","0.004"],["61863.50","0.000"],["61960.80","0.006"],["61966.30","0.679"],["61966.40","0.018"],["61970.20","4.027"],["61972.10","3.188"],["61996.20","1.796"],["62022.00","0.018"],["62031.20","0.293"],["62039.30","0.004"],["62040.90","1.401"],["62044.00","0.250"],["62056.60","0.050"],["62056.70","0.612"],["62057.70","0.003"],["62058.70","0.433"],["62059.90","0.001"],["62066.80","1.374"],["62068.30","0.214"],["62068.60","0.001"],["62069.20","0.009"],["62070.50","0.002"],["62073.70","7.717"]],"e":"depthUpdate","ps":"BTCUSDT","pu":10998401968785,"s":"BTCUSDT","st":1,"u":10998401975530}
{"E":1783504338770,"T":1783504338769,"U":10998401975689,"a":[["62073.80","7.341"],["62074.70","0.024"],["62076.30","0.003"],["62104.10","1.685"],["62104.30","0.286"],["62104.40","0.121"],["62128.00","0.955"],["62138.90","21.408"],["62143.70","0.014"],["62145.20","0.323"],["62694.50","0.000"],["62803.10","0.397"],["62932.60","1.731"],["63067.00","0.491"],["68281.20","13.803"],["89523.20","0.486"]],"b":[["1000.00","210.542"],["11573.70","0.192"],["11673.70","2.736"],["11773.70","0.992"],["11873.70","0.880"],["49659.00","0.000"],["55866.30","0.002"],["59590.70","0.003"],["60825.60","0.012"],["61165.50","2.317"],["61252.50","1.073"],["61357.30","2.139"],["61390.90","4.136"],["61453.00","0.031"],["61517.50","0.000"],["61763.30","0.005"],["61863.50","0.001"],["62039.40","0.001"],["62039.50","0.003"],["62039.60","0.001"],["62055.00","2.388"],["62055.50","0.006"],["62055.60","0.000"],["62055.70","0.000"],["62065.40","0.003"],["62073.70","7.716"]],"e":"depthUpdate","ps":"BTCUSDT","pu":10998401975530,"s":"BTCUSDT","st":1,"u":10998401981648}
{"E":1783504338872,"T":1783504338871,"U":10998401981716,"a":[["62073.80","6.341"],["62078.50","0.004"],["62114.80","0.004"],["62118.60","0.004"],["62128.00","1.051"],["62694.50","0.000"],["62803.20","1.291"],["62818.70","1.112"],["62955.20","0.277"]],"b":[["1000.00","210.542"],["11573.70","0.336"],["11673.70","2.720"],["11773.70","0.992"],["11873.70","0.752"],["55866.30","0.002"],["58966.50","0.002"],["58970.00","0.000"],["59590.70","0.000"],["60942.80","0.167"],["61040.10","0.820"],["61124.70","0.000"],["61328.80","2.977"],["61453.00","0.031"],["61577.10","0.647"],["61763.30","0.015"],["61804.40","0.032"],["61804.60","0.008"],["61863.50","0.000"],["62022.00","0.150"],["62042.00","1.267"],["62048.70","1.274"],["62049.50","1.727"],["62064.90","0.002"],["62065.50","0.027"],["62068.30","0.082"]],"e":"depthUpdate","ps":"BTCUSDT","pu":10998401981648,"s":"BTCUSDT","st":1,"u":10998401987194}
{"E":1783504338974,"T":1783504338972,"U":10998401987223,"a":[["62073.80","6.341"],["62074.00","0.001"],["62076.10","0.005"],["62076.20","0.000"],["62076.30","0.003"],["62076.80","0.004"],["62078.70","0.007"],["62079.20","0.002"],["62079.30","0.722"],["62079.40","1.225"],["62079.50","0.722"],["62080.80","1.127"],["62081.50","0.377"],["62084.40","0.125"],["62086.30","0.002"],["62086.40","0.004"],["62092.00","0.341"],["62095.70","0.055"],["62095.90","0.164"],["62101.90","0.061"],["62104.40","0.226"],["62104.60","0.107"],["62104.90","0.007"],["62105.00","0.316"],["62106.80","0.025"],["62108.10","0.003"],["62134.00","0.056"],["62694.50","0.000"],["89523.20","0.492"]],"b":[["11573.70","0.464"],["11673.70","2.736"],["11773.70","0.992"],["11873.70","0.608"],["55866.30","0.002"],["58970.00","0.000"],["59590.70","0.003"],["61289.40","1.984"],["61453.00","0.031"],["61537.50","1.621"],["61700.00","37.008"],["61863.50","0.001"],["62022.00","0.100"],["62029.00","0.061"],["62068.30","0.132"],["62068.40","0.002"],["62068.50","0.132"],["62069.50","0.054"],["62070.40","0.001"],["62071.70","0.004"]],"e":"depthUpdate","ps":"BTCUSDT","pu":10998401987194,"s":"BTCUSDT","st":1,"u":10998401993516}
{"E":1783504339076,"T":1783504339075,"U":10998401993605,"a":[["62079.30","0.161"],["62104.60","0.196"],["62105.00","0.211"],["62136.80","21.442"],["62138.90","0.022"],["62694.50","0.000"],["62849.70","0.807"],["62911.80","1.824"],["62961.90","9.408"],["62973.90","0.952"]],"b":[["1000.00","210.542"],["11573.70","0.736"],["11673.70","2.464"],["11773.70","1.120"],["11873.70","0.480"],["55866.30","0.002"],["58970.00","0.023"],["59590.70","0.000"],["60654.00","0.004"],["60987.40","1.310"],["61080.50","0.949"],["61173.60","1.120"],["61240.30","0.814"],["61250.70","0.020"],["61297.40","3.137"],["61328.80","4.591"],["61438.50","0.716"],["61453.00","0.031"],["61484.00","2.493"],["61515.00","3.108"],["61863.50","0.000"],["61998.30","0.040"],["62004.20","0.021"],["62057.30","0.300"]],"e":"depthUpdate","ps":"BTCUSDT","pu":10998401993516,"s":"BTCUSDT","st":1,"u":10998401999691}
{"E":1783504339178,"T":1783504339177,"U":10998401999745,"a":[["62076.20","0.000"],["62076.30","0.003"],["62076.70","0.649"],["62078.30","0.001"],["62089.30","0.001"],["62091.60","0.081"],["62094.70","0.125"],["62097.80","0.230"],["62098.00","0.017"],["62098.40","0.171"],["62104.00","0.412"],["62104.60","0.091"],["62105.00","0.122"],["62132.70","0.059"],["62160.80","0.001"],["62174.10","0.003"],["62659.40","0.000"],["62694.50","0.000"],["89523.20","0.498"]],"b":[["11573.70","1.008"],["11673.70","2.192"],["11773.70","1.264"],["11873.70","0.336"],["49659.00","0.000"],["55866.30","0.002"],["58970.00","0.003"],["60166.30","0.031"],["60825.60","0.009"],["61226.50","0.569"],["61453.00","0.031"],["61763.30","0.015"],["61863.50","0.001"],["61912.60","0.000"],["61925.90","0.012"],["62002.40","0.038"],["62004.00","0.016"],["62006.80","21.543"],["62008.50","1.131"],["62011.70","0.001"],["62013.10","0.010"],["62013.30","0.028"],["62020.90","0.002"],["62053.70","1.461"],["62060.00","0.083"],["62073.70","7.717"]],"e":"depthUpdate","ps":"BTCUSDT","pu":10998401999691,"s":"BTCUSDT","st":1,"u":10998402006593}
{"E":1783504339280,"T":1783504339278,"U":10998402006727,"a":[["62076.00","0.004"],["62076.30","0.003"],["62079.30","0.725"],["62079.40","0.661"],["62086.40","0.004"],["62089.70","0.897"],["62098.00","0.001"],["62098.40","0.091"],["62104.20","0.747"],["62104.40","0.315"],["62104.60","0.091"],["62160.00","0.388"],["62240.00","0.448"],["62246.60","0.004"],["62285.40","0.002"],["62315.40","1.338"],["62320.00","0.384"],["62322.20","0.004"],["62400.00","14.339"],["62471.20","0.013"],["62478.00","0.016"],["62480.00","1.059"],["62591.10","2.583"],["62627.40","0.278"],["62634.20","1.391"],["62694.50","0.000"],["62955.30","0.277"]],"b":[["11573.70","1.280"],["11673.70","1.920"],["11773.70","1.392"],["11873.70","0.208"],["55866.30","0.002"],["58970.00","0.003"],["59590.70","0.003"],["60641.10","1.648"],["61235.70","0.815"],["61453.00","0.031"],["61511.40","0.001"],["61518.20","0.016"],["61665.20","0.281"],["61672.00","0.069"],["61680.00","0.940"],["61760.00","0.432"],["61763.30","0.016"],["61819.40","0.000"],["61826.10","0.004"],["61840.00","0.288"],["61863.50","0.000"],["61874.50","0.000"],["61912.90","0.002"],["61920.00","0.345"],["62000.00","8.856"],["62006.80","2.173"],["62011.00","19.610"],["62020.90","0.158"],["62049.80","0.316"],["62052.10","0.002"],["62053.70","1.477"],["62058.60","1.022"],["62073.70","7.718"]],"e":"depthUpdate","ps":"BTCUSDT","pu":10998402006593,"s":"BTCUSDT","st":1,"u":10998402012760}
{"E":1783504339382,"T":1783504339381,"U":10998402012916,"a":[["62074.70","0.001"],["62076.30","0.166"],["62079.10","0.004"],["62095.90","0.001"],["62104.30","0.391"],["62111.00","0.429"],["62160.00","0.386"],["62166.80","0.003"],["62657.70","1.264"],["62694.50","0.684"],["63004.90","1.310"],["89523.20","0.504"]],"b":[["1000.00","210.542"],["11573.70","1.552"],["11673.70","1.648"],["11773.70","1.536"],["11873.70","0.064"],["55866.30","0.002"],["58970.00","0.003"],["59590.70","0.000"],["60169.10","0.711"],["60900.00","38.710"],["61221.90","0.815"],["61266.70","1.631"],["61297.40","1.508"],["61328.80","6.205"],["61534.30","0.000"],["61539.20","0.010"],["61763.90","0.000"],["61768.90","0.008"],["61800.00","7.666"],["61863.50","0.001"],["61973.90","0.001"],["61980.70","0.002"],["61993.90","1.346"],["62006.30","1.547"],["62015.60","0.047"],["62018.60","0.004"],["62035.00","0.865"],["62040.00","0.053"],["62047.40","1.337"],["62049.80","0.236"],["62052.30","0.050"],["62052.70","1.402"],["62053.20","0.082"],["62056.70","0.565"],["62059.70","0.002"],["62064.70","0.848"]],"e":"depthUpdate","ps":"BTCUSDT","pu":10998402012760,"s":"BTCUSDT","st":1,"u":10998402018560}
{"E":1783504339484,"T":1783504339481,"U":10998402018616,"a":[["62076.30","0.003"],["62078.60","0.001"],["62078.70","0.007"],["62079.20","0.002"],["62079.30","0.161"],["62079.40","0.323"],["62086.40","0.906"],["62095.90","0.164"],["62104.10","1.580"],["62132.40","0.000"],["62633.80","0.040"],["62694.50","0.684"],["62942.80","0.940"]],"b":[["11573.70","1.824"],["11673.70","1.440"],["11773.70","1.536"],["11873.70","0.000"],["55866.30","0.002"],["58970.00","0.003"],["59590.70","0.003"],["60825.60","0.006"],["61453.00","0.031"],["61763.30","0.016"],["61863.50","0.000"],["62015.60","0.000"],["62052.70","1.386"],["62053.20","0.002"],["62061.70","0.049"]],"e":"depthUpdate","ps":"BTCUSDT","pu":10998402018560,"s":"BTCUSDT","st":1,"u":10998402022957}
{"E":1783504339586,"T":1783504339585,"U":10998402023056,"a":[["62073.80","6.403"],["62076.30","0.003"],["62079.30","0.161"],["62080.20","0.121"],["62080.30","0.091"],["62080.60","0.090"],["62080.80","1.025"],["62080.90","0.055"],["62081.00","0.169"],["62081.20","0.241"],["62081.30","0.060"],["62081.40","0.281"],["62081.50","0.001"],["62081.60","0.227"],["62081.80","0.001"],["62081.90","0.122"],["62082.00","0.002"],["62082.10","2.110"],["62082.20","0.108"],["62086.30","0.904"],["62086.40","0.004"],["62090.80","0.003"],["62091.30","0.455"],["62095.90","0.178"],["62098.40","0.001"],["62098.70","0.304"],["62099.00","0.030"],["62099.30","0.000"],["62099.60","1.467"],["62099.70","0.657"],["62102.00","0.091"],["62102.30","2.458"],["62102.70","0.115"],["62103.00","0.059"],["62103.30","0.126"],["62105.10","0.889"],["62105.20","0.111"],["62105.30","0.352"],["62105.40","1.522"],["62105.70","0.352"],["62105.80","0.001"],["62106.10","0.002"],["62106.20","0.000"],["62106.30","0.000"],["62106.40","0.031"],["62108.80","2.401"],["62109.80","0.102"],["62110.00","0.560"],["62111.00","0.439"],["62120.00","0.196"],["62120.40","0.017"],["62120.70","0.000"],["62121.00","0.000"],["62121.30","0.677"],["62122.30","0.292"],["62123.70","1.463"],["62124.00","0.168"],["62124.40","0.067"],["62124.70","1.294"],["62126.40","0.031"],["62158.00","0.167"],["62160.00","0.563"],["62161.50","0.680"],["62240.00","0.625"],["62320.00","0.561"],["62330.60","0.000"],["62349.80","0.005"],["62400.00","14.516"],["62480.00","1.236"],["62632.50","1.205"],["62694.50","0.684"],["62968.70","0.000"],["63308.30","0.133"],["63315.20","0.009"],["89523.20","0.510"]],"b":[["11573.70","2.096"],["11673.70","1.312"],["11773.70","1.392"],["49659.00","0.000"],["55866.30","0.002"],["61000.60","0.034"],["61176.30","0.000"],["61246.60","0.018"],["61453.00","0.031"],["61680.00","1.117"],["61760.00","0.609"],["61763.30","0.017"],["61840.00","0.465"],["61863.50","0.001"],["61920.00","0.522"],["61929.80","0.138"],["61930.10","0.039"],["61958.20","0.023"],["61977.40","0.006"],["61994.30","0.000"],["61994.60","0.002"],["61994.90","0.000"],["61995.10","0.000"],["61995.40","0.000"],["62000.00","9.033"],["62013.40","0.400"],["62015.90","0.000"],["62016.20","4.101"],["62016.60","0.001"],["62016.80","1.338"],["62017.10","0.002"],["62019.00","0.014"],["62019.70","0.056"],["62020.10","0.032"],["62020.30","0.033"],["62020.60","0.032"],["62022.00","0.100"],["62030.80","1.235"],["62030.90","2.022"],["62031.00","0.006"],["62031.10","0.010"],["62031.40","0.000"],["62031.50","0.051"],["62032.10","0.027"],["62034.10","0.004"],["62035.30","0.009"],["62037.60","0.698"],["62039.40","0.003"],["62039.50","0.005"],["62039.60","0.003"],["62040.80","0.001"],["62040.90","1.385"],["62045.50","0.002"],["62050.70","0.342"],["62055.50","0.008"],["62055.60","0.002"],["62055.70","0.002"],["62061.80","1.068"],["62061.90","0.002"],["62062.00","0.360"],["62062.20","0.189"],["62062.50","0.071"],["62062.60","0.021"],["62062.80","0.801"],["62063.10","0.043"],["62063.40","0.094"],["62063.70","0.061"],["62064.00","1.506"],["62064.80","0.020"],["62064.90","0.002"],["62065.00","0.032"],["62065.10","0.892"],["62067.00","0.010"],["62068.40","0.002"],["62073.70","7.727"]],"e":"depthUpdate","ps":"BTCUSDT","pu":10998402022957,"s":"BTCUSDT","st":1,"u":10998402028014}
{"E":1783504339688,"T":1783504339687,"U":10998402028057,"a":[["62073.80","6.383"],["62076.30","0.003"],["62079.20","0.904"],["62079.30","0.161"],["62080.30","0.115"],["62081.50","0.169"],["62081.60","0.285"],["62082.10","2.212"],["62082.20","0.198"],["62086.20","0.385"],["62086.30","0.002"],["62095.90","0.180"],["62096.10","2.750"],["62097.10","0.131"],["62102.30","2.454"],["62103.30","0.184"],["62105.00","0.122"],["62105.20","0.006"],["62105.30","0.247"],["62105.40","1.433"],["62109.30","0.169"],["62110.00","0.752"],["62110.50","0.006"],["62125.00","0.218"],["62130.20","0.030"],["62133.40","0.012"],["62134.70","21.388"],["62136.30","0.642"],["62136.50","0.826"],["62136.80","0.056"],["62205.40","0.003"],["62227.00","0.015"],["62245.60","0.023"],["62245.70","0.003"],["62357.80","0.018"],["62360.50","0.000"],["62694.50","0.684"]],"b":[["1000.00","210.542"],["11573.70","2.368"],["11673.70","1.168"],["11773.70","1.264"],["49659.00","0.000"],["55866.30","0.002"],["58968.50","0.000"],["58968.60","0.004"],["59590.70","0.000"],["61230.40","0.002"],["61271.40","0.120"],["61377.00","1.058"],["61453.00","0.031"],["61763.30","0.015"],["61863.50","0.000"],["61917.30","0.001"],["61938.80","0.011"],["61956.30","1.644"],["61966.40","0.015"],["61966.50","0.003"],["62005.90","0.010"],["62011.00","0.240"],["62013.10","19.380"],["62013.20","3.512"],["62019.40","0.033"],["62061.90","0.002"],["62062.20","0.249"],["62062.30","0.060"],["62062.80","0.833"],["62062.90","0.169"],["62064.80","0.906"],["62065.10","0.006"],["62068.20","0.775"]],"e":"depthUpdate","ps":"BTCUSDT","pu":10998402028014,"s":"BTCUSDT","st":1,"u":10998402033704}
{"E":1783504339790,"T":1783504339789,"U":10998402033760,"a":[["62073.80","6.399"],["62076.60","0.069"],["62078.60","0.001"],["62078.70","0.007"],["62079.20","0.340"],["62079.30","0.725"],["62080.90","0.157"],["62081.60","0.393"],["62082.00","0.098"],["62082.10","2.356"],["62082.20","0.288"],["62086.10","0.016"],["62086.30","0.002"],["62086.40","0.004"],["62096.10","2.734"],["62097.10","0.051"],["62104.60","0.091"],["62105.00","0.122"],["62108.80","2.503"],["62109.50","0.126"],["62109.90","0.269"],["62110.10","3.630"],["62384.20","0.737"],["62694.50","0.684"],["62949.00","0.807"],["63469.50","0.002"],["89523.20","0.516"]],"b":[["11573.70","2.640"],["11673.70","1.040"],["11773.70","1.120"],["55866.30","0.000"],["58966.50","0.000"],["59590.70","0.003"],["61223.80","0.819"],["61438.50","0.018"],["61453.00","0.031"],["61484.00","3.185"],["61763.30","0.015"],["61863.50","0.001"],["61929.80","0.177"],["61930.10","0.000"],["62042.00","0.563"],["62044.50","0.427"],["62048.70","1.978"],["62062.20","0.309"],["62062.30","0.120"],["62062.40","0.061"],["62062.80","0.893"],["62063.50","0.064"],["62073.70","7.712"]],"e":"depthUpdate","ps":"BTCUSDT","pu":10998402033704,"s":"BTCUSDT","st":1,"u":10998402039182}
{"E":1783504339892,"T":1783504339891,"U":10998402039184,"a":[["62073.80","6.416"],["62076.40","0.507"],["62076.50","1.412"],["62076.60","0.810"],["62077.50","0.748"],["62078.70","0.007"],["62079.20","0.002"],["62079.30","0.161"],["62081.50","0.259"],["62081.60","0.477"],["62081.90","0.206"],["62086.00","0.465"],["62086.10","0.580"],["62088.30","0.003"],["62089.30","0.000"],["62089.60","0.325"],["62092.50","0.031"],["62093.50","0.000"],["62094.10","0.835"],["62095.90","0.244"],["62096.00","1.363"],["62096.20","0.002"],["62098.60","0.081"],["62103.20","0.087"],["62103.80","0.518"],["62104.00","0.323"],["62104.10","1.491"],["62104.20","0.658"],["62104.30","0.286"],["62104.40","0.121"],["62104.60","0.002"],["62109.30","0.259"],["62109.80","0.186"],["62133.70","0.248"],["62134.70","0.002"],["62135.20","0.303"],["62135.40","0.004"],["62136.80","21.229"],["62141.00","0.016"],["62263.50","1.377"],["62694.50","0.684"],["63310.10","0.006"],["63450.60","0.674"]],"b":[["11573.70","2.720"],["11673.70","0.992"],["11773.70","0.992"],["11973.70","0.096"],["55866.30","0.002"],["59590.70","0.000"],["61161.20","1.306"],["61210.90","0.978"],["61453.00","0.033"],["61842.60","0.011"],["61863.50","0.000"],["61880.80","0.000"],["61964.90","0.000"],["61968.00","0.067"],["61998.10","0.032"],["61998.40","0.038"],["61998.60","0.707"],["61999.00","0.042"],["62015.70","0.000"],["62022.00","0.232"],["62022.50","0.152"],["62029.00","0.000"],["62031.30","0.088"],["62035.50","1.356"],["62044.50","0.411"],["62047.90","0.017"],["62050.60","0.342"],["62051.40","0.003"],["62051.80","0.580"],["62052.50","1.465"],["62053.70","1.316"],["62060.00","0.002"],["62062.50","0.131"],["62062.80","0.152"],["62062.90","0.289"],["62064.90","0.002"],["62066.00","0.130"],["62066.80","0.012"],["62068.00","0.268"],["62068.20","0.523"],["62068.30","0.000"],["62068.40","0.002"],["62068.50","0.000"],["62071.10","0.003"],["62073.70","6.447"]],"e":"depthUpdate","ps":"BTCUSDT","pu":10998402039182,"s":"BTCUSDT","st":1,"u":10998402044653}
{"E":1783504339994,"T":1783504339993,"U":10998402044703,"a":[["62075.80","0.742"],["62079.70","1.003"],["62079.80","0.004"],["62080.40","0.243"],["62081.20","0.000"],["62081.50","0.258"],["62085.80","0.346"],["62086.80","0.004"],["62088.30","0.325"],["62089.60","0.135"],["62091.80","0.417"],["62093.30","0.311"],["62098.60","0.001"],["62100.70","0.003"],["62116.50","0.079"],["62136.20","0.000"],["62137.30","0.001"],["62205.50","0.510"],["62227.10","1.097"],["62263.50","4.478"],["62694.50","0.684"],["89523.20","0.522"]],"b":[["1000.00","210.542"],["11573.70","2.736"],["11673.70","0.992"],["11773.70","0.848"],["11973.70","0.224"],["55866.30","0.002"],["59590.70","0.003"],["61297.80","2.461"],["61453.00","0.031"],["61863.50","0.001"],["61881.40","2.976"],["61917.90","1.127"],["61939.40","0.900"],["61964.50","0.064"],["61972.50","0.112"],["61972.70","0.112"],["61997.80","0.032"],["62022.40","0.167"],["62034.40","0.066"],["62034.60","2.328"],["62035.60","0.060"],["62040.60","0.005"],["62041.10","1.396"],["62042.60","1.022"],["62045.10","0.302"],["62052.40","0.171"],["62052.70","1.266"],["62058.30","0.322"],["62058.70","0.111"],["62069.50","0.005"],["62070.60","0.004"],["62070.90","0.003"],["62073.70","6.199"]],"e":"depthUpdate","ps":"BTCUSDT","pu":10998402044653,"s":"BTCUSDT","st":1,"u":10998402051174}
{"E":1783504340096,"T":1783504340093,"U":10998402051350,"a":[["62073.80","6.362"],["62076.00","0.006"],["62079.20","0.000"],["62086.00","0.545"],["62087.40","0.018"],["62087.60","0.932"],["62087.70","1.019"],["62089.10","0.085"],["62089.30","0.128"],["62089.90","0.016"],["62090.60","0.003"],["62090.80","0.583"],["62091.20","0.009"],["62091.80","0.337"],["62092.50","0.023"],["62092.90","0.101"],["62093.30","0.295"],["62095.80","0.389"],["62095.90","0.312"],["62101.80","2.780"],["62103.60","0.108"],["62103.70","0.661"],["62103.80","0.413"],["62110.50","0.002"],["62116.90","0.162"],["62131.70","0.101"],["62131.90","0.103"],["62132.00","0.102"],["62133.40","0.037"],["62134.70","21.175"],["62136.80","0.056"],["62245.70","0.000"],["62245.80","0.003"],["62694.50","0.684"],["63315.20","0.012"]],"b":[["11573.70","2.720"],["11673.70","0.992"],["11773.70","0.720"],["11973.70","0.368"],["55866.30","0.002"],["60923.70","0.702"],["61453.00","0.031"],["61763.30","0.016"],["61863.50","0.000"],["62006.70","0.000"],["62008.50","0.975"],["62021.90","0.569"],["62034.40","0.186"],["62035.00","0.985"],["62050.90","0.581"],["62051.80","0.000"],["62058.20","1.494"],["62068.30","0.082"],["62073.70","6.197"]],"e":"depthUpdate","ps":"BTCUSDT","pu":10998402051174,"s":"BTCUSDT","st":1,"u":10998402057858}
{"E":1783504340198,"T":1783504340197,"U":10998402058034,"a":[["62073.80","6.300"],["62075.70","0.001"],["62081.40","0.206"],["62086.00","0.465"],["62087.00","0.005"],["62087.40","0.002"],["62087.80","0.405"],["62088.30","0.003"],["62089.20","0.327"],["62089.60","0.003"],["62091.60","0.000"],["62091.90","0.118"],["62092.10","0.002"],["62092.20","0.010"],["62095.10","0.345"],["62095.90","0.180"],["62096.80","0.002"],["62097.80","0.069"],["62098.90","0.680"],["62099.00","5.030"],["62102.30","2.559"],["62103.60","0.003"],["62103.70","0.467"],["62103.80","0.324"],["62129.00","0.105"],["62129.50","0.102"],["62131.70","0.000"],["62131.80","0.326"],["62131.90","0.002"],["62132.00","0.001"],["62134.20","0.254"],["62134.60","0.427"],["62694.50","0.684"],["62907.10","0.000"],["63068.20","0.000"],["63310.10","0.003"],["89523.20","0.528"]],"b":[["1000.00","210.692"],["11573.70","2.672"],["11673.70","1.024"],["11773.70","0.576"],["11973.70","0.528"],["49659.00","0.000"],["55866.30","0.002"],["58963.70","0.003"],["59590.70","0.000"],["60906.70","1.640"],["61283.50","1.303"],["61453.00","0.031"],["61535.10","0.000"],["61863.50","0.001"],["62004.00","0.000"],["62006.70","0.000"],["62006.90","0.749"],["62021.90","0.437"],["62022.00","0.018"],["62028.00","1.466"],["62029.60","0.029"],["62034.30","0.060"],["62034.40","0.246"],["62034.50","0.062"],["62035.00","1.045"],["62035.60","0.120"],["62047.90","0.001"],["62048.60","0.379"],["62051.30","0.188"],["62054.80","0.161"],["62061.00","0.083"],["62068.30","0.132"],["62068.40","0.134"],["62068.50","0.082"],["62073.70","6.671"]],"e":"depthUpdate","ps":"BTCUSDT","pu":10998402057858,"s":"BTCUSDT","st":1,"u":10998402063786}
{"E":1783504340300,"T":1783504340299,"U":10998402063844,"a":[["62073.80","7.105"],["62089.70","0.897"],["62095.70","0.119"],["62095.80","0.325"],["62097.20","0.003"],["62128.60","2.050"],["62129.00","0.004"],["62129.50","0.001"],["62129.80","0.000"],["62694.50","0.684"],["62882.10","0.079"],["63049.80","0.795"],["63308.30","0.127"]],"b":[["1000.00","210.542"],["11573.70","2.400"],["11673.70","1.152"],["11773.70","0.448"],["11973.70","0.800"],["49659.00","0.000"],["55866.30","0.002"],["59590.70","0.003"],["61328.80","6.855"],["61453.00","0.033"],["61863.50","0.000"],["62022.00","0.150"],["62034.70","0.061"],["62035.10","0.122"],["62041.20","0.515"],["62048.60","0.057"],["62054.80","0.000"],["62058.60","1.022"],["62061.00","0.002"],["62064.90","0.134"],["62068.30","0.000"],["62068.40","0.084"],["62073.70","6.663"]],"e":"depthUpdate","ps":"BTCUSDT","pu":10998402063786,"s":"BTCUSDT","st":1,"u":10998402069821}
{"E":1783504340402,"T":1783504340401,"U":10998402069857,"a":[["62074.70","0.007"],["62075.70","0.001"],["62077.30","0.004"],["62079.60","1.515"],["62087.70","0.294"],["62087.80","0.325"],["62088.60","0.725"],["62091.90","0.102"],["62095.20","0.160"],["62095.40","0.082"],["62095.70","0.055"],["62205.50","0.557"],["62694.50","0.684"],["62830.20","2.843"],["63517.20","0.002"],["89523.20","0.534"]],"b":[["11573.70","2.128"],["11673.70","1.296"],["11773.70","0.304"],["11973.70","1.072"],["49659.00","0.000"],["55866.30","0.002"],["58965.30","0.000"],["58965.40","0.003"],["59590.70","0.000"],["60830.70","0.003"],["61142.60","2.646"],["61453.00","0.031"],["61763.30","0.017"],["61863.50","0.001"],["61864.60","1.841"],["61866.00","0.651"],["61908.00","2.055"],["61909.10","0.034"],["61909.60","0.695"],["61939.40","0.241"],["61939.50","0.687"],["61992.50","0.313"],["61995.10","0.047"],["62000.30","0.000"],["62007.50","0.098"],["62016.80","1.385"],["62019.80","0.052"],["62020.50","0.016"],["62029.70","0.061"],["62035.50","1.340"],["62040.00","0.006"],["62050.90","0.001"],["62051.80","0.580"],["62052.30","0.003"],["62052.70","1.266"],["62052.90","0.008"],["62053.90","0.001"],["62056.70","0.001"],["62056.80","0.628"],["62058.20","1.494"],["62058.30","0.322"],["62061.70","0.002"],["62064.70","0.801"],["62073.70","6.662"]],"e":"depthUpdate","ps":"BTCUSDT","pu":10998402069821,"s":"BTCUSDT","st":1,"u":10998402075682}
{"E":1783504340504,"T":1783504340501,"U":10998402075762,"a":[["62073.80","8.650"],["62073.90","0.003"],["62074.60","0.000"],["62074.80","0.746"],["62075.00","0.006"],["62075.30","0.332"],["62075.60","0.382"],["62075.70","0.809"],["62076.10","0.001"],["62076.20","0.132"],["62076.30","0.583"],["62076.40","0.001"],["62076.70","0.645"],["62077.70","0.005"],["62078.30","0.122"],["62078.50","0.003"],["62079.30","0.402"],["62079.60","1.656"],["62079.80","0.003"],["62080.00","0.010"],["62080.20","0.406"],["62080.30","0.091"],["62080.40","0.004"],["62080.50","0.175"],["62080.90","0.207"],["62081.50","0.660"],["62082.40","0.012"],["62083.50","0.342"],["62084.10","0.000"],["62084.60","0.392"],["62086.00","0.127"],["62086.10","0.016"],["62086.20","0.401"],["62086.50","0.159"],["62086.90","0.565"],["62087.00","0.730"],["62087.10","0.054"],["62088.30","0.166"],["62088.60","0.000"],["62089.30","0.228"],["62089.90","0.148"],["62092.20","0.173"],["62092.40","0.603"],["62092.50","0.003"],["62093.10","1.474"],["62093.80","0.069"],["62093.90","0.215"],["62094.10","0.715"],["62095.20","0.080"],["62095.40","0.018"],["62095.50","0.485"],["62095.90","0.190"],["62096.80","0.022"],["62098.70","1.008"],["62099.00","5.032"],["62099.50","1.394"],["62099.90","0.699"],["62101.80","2.776"],["62102.20","1.099"],["62104.00","0.001"],["62105.40","0.733"],["62121.80","4.707"],["62122.10","0.031"],["62128.10","1.908"],["62128.40","1.171"],["62128.50","0.021"],["62128.60","1.949"],["62134.20","0.122"],["62134.60","0.295"],["62134.70","0.002"],["62135.90","0.060"],["62136.30","0.542"],["62136.40","0.734"],["62139.00","21.177"],["62224.60","0.168"],["62626.70","1.501"],["62694.50","0.684"]],"b":[["1000.00","210.542"],["11573.70","1.856"],["11673.70","1.424"],["11773.70","0.176"],["11973.70","1.344"],["55866.30","0.002"],["59590.70","0.003"],["60832.30","0.015"],["61228.10","0.576"],["61453.00","0.031"],["61515.00","3.270"],["61538.70","0.000"],["61815.20","0.773"],["61863.50","0.000"],["61972.50","0.060"],["61972.60","0.000"],["61972.70","0.060"],["61985.00","0.858"],["61995.10","0.000"],["62007.50","0.051"],["62016.80","1.338"],["62018.20","0.000"],["62018.30","4.703"],["62019.20","0.028"],["62019.80","0.005"],["62020.50","0.000"],["62021.90","0.569"],["62022.00","0.232"],["62022.40","0.068"],["62025.50","0.003"],["62027.10","0.001"],["62028.30","0.179"],["62037.20","0.013"],["62039.20","0.004"],["62040.00","0.053"],["62045.20","0.009"],["62045.40","0.847"],["62049.60","0.113"],["62050.50","1.334"],["62050.70","0.340"],["62051.30","0.198"],["62051.80","0.000"],["62051.90","0.120"],["62052.30","0.050"],["62052.40","0.051"],["62052.70","1.256"],["62055.10","0.725"],["62056.10","0.567"],["62056.30","1.000"],["62056.50","0.742"],["62056.60","0.102"],["62056.70","0.742"],["62056.80","0.064"],["62057.00","0.001"],["62057.40","0.005"],["62058.10","0.156"],["62058.20","1.366"],["62058.30","0.741"],["62058.70","0.852"],["62059.10","0.130"],["62060.20","0.323"],["62060.30","0.008"],["62061.00","0.002"],["62061.40","0.001"],["62061.70","0.049"],["62061.80","1.009"],["62062.40","0.061"],["62062.50","0.136"],["62062.60","0.025"],["62062.70","0.821"],["62063.00","0.035"],["62063.10","0.035"],["62063.30","0.326"],["62063.90","0.000"],["62064.10","0.739"],["62064.40","0.727"],["62064.50","0.001"],["62064.70","0.048"],["62064.80","0.584"],["62064.90","0.026"],["62065.00","0.331"],["62065.50","0.003"],["62065.80","0.338"],["62065.90","0.000"],["62066.60","0.051"],["62066.70","0.077"],["62066.80","0.008"],["62067.20","0.007"],["62067.90","0.007"],["62068.00","0.003"],["62068.10","0.001"],["62068.20","0.001"],["62068.40","0.002"],["62068.50","0.000"],["62069.20","0.004"],["62069.40","0.008"],["62069.50","0.000"],["62069.70","0.004"],["62069.80","0.003"],["62070.60","0.001"],["62070.80","0.001"],["62070.90","0.001"],["62071.60","0.000"],["62071.70","0.000"],["62072.10","0.000"],["62073.30","0.000"],["62073.70","2.601"]],"e":"depthUpdate","ps":"BTCUSDT","pu":10998402075682,"s":"BTCUSDT","st":1,"u":10998402083108}
{"E":1783504340606,"T":1783504340605,"U":10998402083288,"a":[["62073.80","8.730"],["62075.60","0.946"],["62075.70","0.799"],["62076.10","0.009"],["62076.20","0.008"],["62076.30","0.003"],["62077.10","0.016"],["62079.20","0.000"],["62079.30","0.161"],["62079.50","0.722"],["62079.80","0.003"],["62080.40","0.028"],["62081.50","0.580"],["62083.30","0.126"],["62086.20","0.385"],["62088.90","0.591"],["62089.30","0.229"],["62089.60","0.135"],["62095.90","0.027"],["62096.80","0.002"],["62106.30","0.010"],["62111.00","0.429"],["62136.90","21.262"],["62139.00","0.004"],["62526.60","0.012"],["62694.50","0.684"],["62715.10","0.742"],["62716.60","0.005"],["62849.70","1.440"],["89523.20","0.540"]],"b":[["1000.00","210.542"],["11573.70","1.584"],["11673.70","1.568"],["11773.70","0.032"],["11973.70","1.616"],["55866.30","0.002"],["61297.80","2.704"],["61453.00","0.031"],["61763.30","0.012"],["61863.50","0.001"],["61970.90","0.000"],["61998.40","19.419"],["62000.00","9.233"],["62006.90","0.782"],["62007.00","0.711"],["62008.50","1.131"],["62013.10","0.010"],["62013.20","0.001"],["62020.90","0.002"],["62021.90","0.133"],["62051.30","0.182"],["62055.00","1.688"],["62056.20","3.643"],["62056.30","0.000"],["62056.40","0.484"],["62056.60","0.050"],["62057.30","0.300"],["62057.80","0.003"],["62061.30","0.099"],["62061.90","0.294"],["62062.00","0.068"],["62064.40","0.727"],["62064.80","0.020"],["62064.90","0.324"],["62065.00","0.331"],["62065.80","0.016"],["62065.90","0.000"],["62066.10","0.564"],["62068.30","0.003"],["62069.20","0.003"],["62069.40","0.005"],["62071.30","0.001"],["62073.70","1.679"]],"e":"depthUpdate","ps":"BTCUSDT","pu":10998402083108,"s":"BTCUSDT","st":1,"u":10998402090482}
{"E":1783504340708,"T":1783504340707,"U":10998402090611,"a":[["62073.80","8.794"],["62074.30","0.021"],["62074.40","0.006"],["62074.70","0.007"],["62075.20","0.005"],["62075.50","0.003"],["62075.60","0.060"],["62076.10","0.001"],["62076.20","0.000"],["62077.50","0.746"],["62078.40","0.152"],["62079.30","1.063"],["62079.50","0.722"],["62080.50","0.111"],["62083.30","0.126"],["62086.80","0.008"],["62087.00","0.005"],["62088.10","0.726"],["62093.30","0.297"],["62095.10","0.349"],["62105.40","0.731"],["62136.70","5.274"],["62136.90","0.089"],["62139.00","21.157"],["62663.50","3.770"],["62694.50","0.684"],["62710.00","3.050"],["62880.80","1.233"]],"b":[["11573.70","1.408"],["11673.70","1.504"],["11773.70","0.000"],["11973.70","1.888"],["55866.30","0.002"],["59590.70","0.000"],["61235.70","1.630"],["61357.30","1.413"],["61453.00","0.033"],["61577.10","0.971"],["61763.30","0.012"],["61863.50","0.000"],["61877.60","0.000"],["61998.40","0.038"],["62006.80","2.173"],["62006.90","0.749"],["62008.90","19.721"],["62015.20","2.523"],["62020.90","0.158"],["62021.90","0.651"],["62055.10","0.000"],["62057.00","0.726"],["62058.60","1.473"],["62061.90","0.294"],["62062.40","0.065"],["62064.40","0.727"],["62065.00","0.329"],["62065.20","0.000"],["62068.10","0.004"],["62069.80","0.000"]],"e":"depthUpdate","ps":"BTCUSDT","pu":10998402090482,"s":"BTCUSDT","st":1,"u":10998402099799}
