{"E":1783504322552,"T":1783504322551,"U":10998400103835,"a":[["62048.30","0.644"],["62048.40","0.006"],["62048.50","0.001"],["62049.00","0.001"],["62049.30","0.004"],["62049.50","0.002"],["62049.70","0.001"],["62049.80","0.002"],["62049.90","0.095"],["62050.00","0.007"],["62050.10","0.001"],["62050.70","0.147"],["62051.20","0.002"],["62051.30","0.646"],["62051.60","0.004"],["62051.90","0.000"],["62052.30","0.001"],["62052.40","0.217"],["62052.60","0.003"],["62052.70","0.004"],["62052.90","0.212"],["62053.00","0.004"],["62053.10","0.002"],["62053.30","0.001"],["62053.40","0.001"],["62053.50","0.006"],["62053.60","0.000"],["62053.70","0.000"],["62053.80","0.001"],["62053.90","0.001"],["62054.00","0.011"],["62054.10","0.001"],["62054.20","0.000"],["62054.30","0.001"],["62054.50","0.424"],["62054.60","0.000"],["62054.70","0.004"],["62054.80","0.968"],["62054.90","0.742"],["62055.20","0.622"],["62055.30","0.006"],["62055.70","0.005"],["62055.80","0.004"],["62056.00","0.860"],["62056.10","0.477"],["62056.20","0.893"],["62056.40","0.049"],["62056.50","0.081"],["62056.60","0.001"],["62056.70","0.001"],["62056.90","0.001"],["62057.00","0.001"],["62057.10","0.823"],["62057.20","0.000"],["62057.30","0.206"],["62057.40","0.161"],["62057.50","0.213"],["62057.60","0.645"],["62057.70","0.324"],["62057.80","0.874"],["62057.90","0.004"],["62058.10","0.000"],["62058.40","0.000"],["62058.50","0.000"],["62058.60","0.104"],["62058.80","1.823"],["62058.90","0.327"],["62059.00","0.110"],["62059.10","0.765"],["62059.20","0.599"],["62059.30","0.000"],["62059.40","1.312"],["62059.50","0.148"],["62059.60","0.003"],["62059.80","0.121"],["62059.90","0.092"],["62060.00","0.412"],["62060.10","0.000"],["62060.40","0.824"],["62060.50","0.000"],["62060.70","0.264"],["62060.80","1.328"],["62060.90","0.372"],["62061.20","0.815"],["62061.30","2.714"],["62061.60","1.298"],["62061.70","0.002"],["62061.80","0.343"],["62061.90","0.001"],["62062.10","0.000"],["62062.20","0.064"],["62062.30","0.005"],["62062.40","0.015"],["62062.70","0.907"],["62062.90","0.122"],["62063.20","0.633"],["62063.40","0.618"],["62063.60","0.009"],["62063.80","0.003"],["62063.90","0.404"],["62064.00","0.004"],["62064.10","0.130"],["62064.20","0.102"],["62064.40","0.001"],["62064.80","1.531"],["62065.00","1.380"],["62065.10","0.463"],["62065.20","0.000"],["62065.50","0.004"],["62065.80","1.461"],["62066.00","0.668"],["62066.10","0.016"],["62066.40","0.084"],["62066.50","0.004"],["62066.60","0.282"],["62066.80","0.000"],["62067.00","0.111"],["62067.90","0.001"],["62068.00","0.847"],["62068.20","1.021"],["62068.60","0.043"],["62068.70","0.584"],["62068.80","0.001"],["62068.90","0.001"],["62069.10","0.002"],["62069.30","0.000"],["62069.40","0.080"],["62069.50","0.000"],["62069.80","0.164"],["62070.00","1.116"],["62070.10","0.226"],["62070.30","0.011"],["62070.60","0.096"],["62070.70","0.211"],["62071.00","0.154"],["62072.00","0.001"],["62072.10","2.148"],["62072.20","0.002"],["62072.50","0.057"],["62073.10","0.284"],["62073.20","0.539"],["62073.50","0.002"],["62073.70","0.015"],["62073.80","0.010"],["62074.20","0.000"],["62074.30","0.888"],["62074.50","0.009"],["62074.70","0.004"],["62074.80","0.139"],["62075.10","0.328"],["62075.20","0.001"],["62075.30","0.333"],["62075.60","1.362"],["62076.40","0.061"],["62076.50","0.760"],["62076.80","0.076"],["62077.00","0.153"],["62077.10","0.020"],["62077.20","1.484"],["62077.40","0.112"],["62077.50","0.006"],["62077.60","0.059"],["62078.00","0.084"],["62078.10","0.875"],["62078.20","1.362"],["62078.40","0.175"],["62078.50","1.132"],["62078.60","0.091"],["62079.00","0.006"],["62079.70","0.001"],["62079.80","0.687"],["62079.90","0.000"],["62080.60","0.111"],["62081.10","0.005"],["62081.40","0.884"],["62081.50","0.003"],["62081.60","0.002"],["62082.70","0.085"],["62082.80","0.089"],["62082.90","0.030"],["62083.00","0.105"],["62083.70","0.158"],["62083.80","0.399"],["62084.40","0.924"],["62084.50","0.674"],["62085.10","0.011"],["62085.30","0.000"],["62085.60","0.717"],["62085.80","0.732"],["62086.10","0.016"],["62086.70","0.003"],["62087.10","0.762"],["62087.20","2.458"],["62088.30","0.023"],["62088.40","0.681"],["62088.50","3.778"],["62089.10","0.006"],["62090.00","0.384"],["62090.20","0.000"],["62090.30","1.621"],["62092.90","0.295"],["62095.10","0.061"],["62095.40","0.017"],["62097.10","0.164"],["62097.20","0.428"],["62099.10","0.033"],["62100.70","0.028"],["62100.80","0.014"],["62101.20","0.000"],["62101.30","0.003"],["62102.70","0.009"],["62102.80","0.005"],["62103.20","0.000"],["62103.40","0.001"],["62103.80","1.302"],["62104.00","0.005"],["62104.20","0.657"],["62104.30","0.289"],["62104.70","0.750"],["62105.10","0.103"],["62105.20","0.501"],["62105.30","0.007"],["62105.40","0.040"],["62105.80","0.109"],["62106.00","0.028"],["62106.30","0.342"],["62106.40","0.316"],["62106.70","0.001"],["62107.90","0.099"],["62108.10","0.100"],["62108.20","1.943"],["62109.40","0.000"],["62109.60","0.018"],["62109.80","0.210"],["62110.30","0.248"],["62110.90","6.327"],["62111.60","0.148"],["62111.80","0.323"],["62113.00","0.098"],["62113.40","0.762"],["62113.70","0.106"],["62113.80","0.000"],["62114.10","0.064"],["62114.20","0.083"],["62114.40","0.000"],["62114.50","0.700"],["62114.80","0.001"],["62114.90","1.031"],["62115.70","0.101"],["62115.80","0.282"],["62116.50","0.109"],["62117.10","1.541"],["62117.40","0.101"],["62117.70","1.345"],["62117.80","0.031"],["62118.80","0.030"],["62120.00","22.284"],["62122.20","1.321"],["62123.70","1.371"],["62124.30","0.017"],["62128.10","0.737"],["62129.00","0.190"],["62129.60","0.287"],["62134.20","0.122"],["62136.40","5.541"],["62141.40","0.667"],["62144.50","0.696"],["62147.50","0.003"],["62150.50","1.256"],["62151.80","0.004"],["62161.20","0.282"],["62165.00","1.112"],["62165.30","0.000"],["62167.50","0.001"],["62171.60","0.004"],["62171.80","0.000"],["62171.90","1.531"],["62222.70","0.093"],["62225.80","0.002"],["62227.30","0.000"],["62233.60","0.019"],["62289.30","0.000"],["62289.40","0.000"],["62351.40","0.002"],["62357.70","0.025"],["62364.90","0.001"],["62475.50","0.000"],["62480.00","0.808"],["62481.80","0.013"],["62667.90","0.028"],["62668.70","0.000"],["62668.80","0.009"],["62761.40","0.009"],["62762.20","21.498"],["62823.40","0.001"],["62823.60","1.461"],["62824.20","8.669"],["62830.50","0.794"],["62881.40","0.914"],["63282.80","0.022"],["67331.80","0.000"],["67567.10","0.002"],["89523.20","0.012"]],"b":[["1000.00","210.542"],["11543.90","1.728"],["11648.20","0.144"],["11743.90","0.112"],["11948.20","0.288"],["55842.50","0.000"],["55843.30","0.002"],["59565.40","0.000"],["60801.10","0.074"],["60807.30","0.012"],["61045.70","0.000"],["61045.80","0.007"],["61048.20","0.151"],["61298.50","0.008"],["61426.80","0.000"],["61427.70","0.002"],["61669.50","0.005"],["61675.90","0.103"],["61703.30","0.015"],["61728.30","0.016"],["61731.60","0.000"],["61733.70","0.013"],["61738.00","0.004"],["61817.80","0.161"],["61817.90","0.002"],["61834.80","0.207"],["61847.20","0.002"],["61847.30","27.690"],["61854.10","0.000"],["61854.20","0.000"],["61854.30","0.017"],["61855.20","0.000"],["61855.70","0.649"],["61862.10","0.001"],["61883.80","17.662"],["61884.00","23.540"],["61884.50","3.108"],["61886.10","0.000"],["61887.00","0.734"],["61899.40","0.672"],["61901.60","0.433"],["61903.60","0.001"],["61911.80","0.000"],["61917.60","0.282"],["61917.70","0.001"],["61922.70","0.015"],["61924.10","0.002"],["61929.00","0.016"],["61945.40","0.002"],["61946.50","4.421"],["61951.30","0.000"],["61951.70","0.008"],["61954.30","0.003"],["61954.40","0.000"],["61955.90","0.001"],["61957.10","0.187"],["61957.30","0.060"],["61958.00","3.000"],["61958.90","2.418"],["61962.50","0.027"],["61963.10","16.928"],["61964.20","0.001"],["61964.40","0.079"],["61966.30","0.735"],["61968.00","0.004"],["61968.90","4.837"],["61969.10","0.155"],["61969.90","0.077"],["61970.40","0.001"],["61973.20","0.001"],["61973.70","0.254"],["61975.50","0.672"],["61976.50","0.468"],["61977.40","0.002"],["61978.00","0.025"],["61979.90","0.032"],["61981.10","0.001"],["61981.30","0.000"],["61982.70","0.003"],["61983.20","0.003"],["61983.70","19.462"],["61984.10","0.002"],["61984.20","0.494"],["61984.30","0.001"],["61984.40","1.530"],["61984.80","0.000"],["61985.50","0.038"],["61986.10","0.935"],["61989.00","0.008"],["61989.80","0.000"],["61990.30","0.100"],["61990.80","0.689"],["61990.90","0.058"],["61991.10","0.076"],["61992.10","4.108"],["61992.20","1.289"],["61992.30","0.020"],["61995.60","0.263"],["61996.40","0.211"],["61997.10","0.002"],["61998.60","0.675"],["61998.70","1.924"],["61999.00","0.010"],["61999.20","0.027"],["62000.10","1.877"],["62000.70","0.282"],["62001.10","0.001"],["62001.90","0.000"],["62002.10","4.157"],["62002.80","0.522"],["62003.00","0.083"],["62003.90","0.001"],["62004.60","0.065"],["62004.80","0.002"],["62005.10","0.000"],["62005.20","2.163"],["62005.30","0.000"],["62005.60","0.001"],["62006.20","0.016"],["62006.40","0.004"],["62006.90","0.915"],["62007.00","1.277"],["62007.70","0.000"],["62007.90","0.131"],["62009.10","0.052"],["62011.80","0.004"],["62012.10","0.657"],["62012.40","2.793"],["62013.00","0.062"],["62014.00","0.099"],["62014.10","0.132"],["62014.20","0.012"],["62014.70","0.000"],["62014.90","0.002"],["62015.10","0.001"],["62015.90","0.014"],["62016.00","0.017"],["62016.30","0.002"],["62016.50","0.007"],["62017.20","0.029"],["62018.50","0.666"],["62019.00","0.001"],["62019.40","0.006"],["62019.50","0.029"],["62019.60","0.013"],["62019.70","0.003"],["62019.80","0.026"],["62019.90","2.461"],["62020.00","0.941"],["62020.30","0.005"],["62021.50","0.003"],["62021.90","0.050"],["62022.30","0.004"],["62022.40","0.004"],["62022.70","0.004"],["62023.20","0.537"],["62023.30","0.918"],["62023.40","0.211"],["62023.50","2.007"],["62023.60","0.004"],["62023.70","0.003"],["62024.40","0.033"],["62025.50","0.051"],["62025.90","0.050"],["62026.00","0.098"],["62026.10","0.011"],["62026.50","0.043"],["62027.00","0.000"],["62027.40","0.089"],["62027.70","0.305"],["62027.90","0.005"],["62028.00","2.469"],["62028.20","0.189"],["62028.40","2.066"],["62028.60","1.116"],["62028.90","0.003"],["62029.10","0.000"],["62029.20","0.100"],["62029.30","0.012"],["62029.40","0.322"],["62029.50","0.132"],["62029.70","0.001"],["62030.10","0.002"],["62031.00","0.331"],["62031.30","0.084"],["62031.60","0.012"],["62031.70","0.581"],["62032.00","0.002"],["62032.30","0.001"],["62032.60","0.315"],["62032.80","0.037"],["62032.90","0.000"],["62033.20","0.061"],["62033.50","0.038"],["62033.80","0.021"],["62034.00","1.289"],["62034.20","0.017"],["62034.50","1.002"],["62034.60","1.761"],["62034.70","0.565"],["62034.90","1.225"],["62035.00","0.348"],["62035.10","0.406"],["62035.20","0.002"],["62035.40","0.121"],["62035.60","0.080"],["62035.70","0.003"],["62035.80","0.143"],["62036.00","0.080"],["62036.10","0.096"],["62036.20","0.363"],["62036.30","1.706"],["62036.60","0.352"],["62036.70","0.092"],["62036.80","0.181"],["62036.90","0.124"],["62037.00","0.094"],["62037.10","0.100"],["62037.40","0.001"],["62037.50","0.061"],["62037.70","0.123"],["62038.00","0.131"],["62038.10","0.389"],["62038.40","0.306"],["62038.50","0.002"],["62038.60","0.565"],["62038.70","0.001"],["62039.00","0.026"],["62039.30","0.125"],["62039.60","0.002"],["62039.70","1.535"],["62039.80","0.488"],["62040.30","0.113"],["62040.40","0.064"],["62040.70","0.003"],["62041.10","0.053"],["62041.20","0.453"],["62041.40","0.020"],["62042.20","0.000"],["62042.40","0.697"],["62042.60","0.004"],["62043.00","0.006"],["62043.90","0.143"],["62044.00","0.208"],["62044.60","0.050"],["62044.80","0.042"],["62044.90","0.002"],["62045.10","0.032"],["62045.70","0.194"],["62046.10","1.803"],["62046.30","0.722"],["62046.70","0.001"],["62046.90","0.001"],["62047.20","0.000"],["62047.30","0.009"],["62047.40","1.802"],["62047.50","0.000"],["62047.60","0.132"],["62047.70","0.291"],["62047.90","0.339"],["62048.00","0.049"],["62048.10","0.369"],["62048.20","15.594"]],"e":"depthUpdate","ps":"BTCUSDT","pu":10998400103773,"s":"BTCUSDT","st":1,"u":10998400139137}
{"E":1783504322654,"T":1783504322653,"U":10998400139176,"a":[["62048.30","0.657"],["62048.40","0.006"],["62050.00","0.006"],["62050.70","0.147"],["62051.60","0.000"],["62052.30","0.001"],["62052.40","0.221"],["62052.90","0.445"],["62053.30","0.007"],["62054.30","0.581"],["62054.40","0.300"],["62054.50","0.612"],["62054.70","0.000"],["62054.80","0.874"],["62055.30","0.002"],["62055.90","0.326"],["62056.40","0.053"],["62057.00","0.001"],["62057.30","0.000"],["62057.50","0.007"],["62057.60","0.412"],["62057.70","0.002"],["62057.80","0.874"],["62058.30","0.453"],["62058.70","0.005"],["62059.00","0.113"],["62059.10","1.087"],["62059.20","0.689"],["62059.50","0.149"],["62059.60","1.087"],["62059.90","0.090"],["62060.10","0.001"],["62060.60","0.020"],["62060.80","0.006"],["62061.30","2.716"],["62061.80","0.342"],["62062.40","0.013"],["62063.00","0.348"],["62063.50","0.006"],["62064.20","0.104"],["62067.00","0.010"],["62068.60","0.003"],["62068.70","0.004"],["62069.90","0.323"],["62070.00","0.416"],["62070.10","0.246"],["62070.20","0.583"],["62070.30","0.061"],["62070.40","0.033"],["62071.70","0.000"],["62072.70","0.988"],["62073.70","0.014"],["62073.80","0.000"],["62074.10","0.047"],["62074.80","0.019"],["62075.10","0.263"],["62075.50","1.007"],["62076.10","0.710"],["62076.50","0.727"],["62077.10","0.000"],["62077.20","1.327"],["62077.30","0.000"],["62077.50","0.055"],["62077.90","0.370"],["62078.30","0.707"],["62078.40","0.171"],["62079.40","0.004"],["62080.10","0.001"],["62080.60","0.006"],["62081.40","0.779"],["62083.10","0.778"],["62084.00","0.036"],["62084.40","0.875"],["62085.10","0.001"],["62086.20","0.067"],["62086.90","0.105"],["62087.00","0.380"],["62087.10","0.657"],["62087.60","0.033"],["62088.10","0.106"],["62090.00","0.314"],["62093.60","0.000"],["62099.90","1.130"],["62102.90","0.213"],["62107.20","0.017"],["62109.00","0.000"],["62109.80","0.004"],["62110.40","0.001"],["62112.20","0.539"],["62114.50","0.685"],["62115.90","22.258"],["62117.00","0.016"],["62117.40","0.000"],["62118.00","0.499"],["62120.00","0.198"],["62128.10","0.737"],["62155.60","0.927"],["62155.90","1.702"],["62156.30","0.002"],["62179.80","3.042"],["62181.20","12.183"],["62189.70","0.677"],["62202.60","0.072"],["62202.90","0.006"],["62240.50","0.024"],["62668.80","0.003"],["62714.30","10.761"],["62910.80","0.951"],["63282.80","0.013"],["63289.20","0.009"]],"b":[["1000.00","210.542"],["11543.90","1.456"],["11548.20","0.032"],["11648.20","0.224"],["11743.90","0.000"],["11948.20","0.560"],["55843.30","0.002"],["57379.90","0.002"],["58939.80","0.000"],["58939.90","0.006"],["59566.20","0.003"],["60801.10","0.071"],["60807.30","0.015"],["61134.00","7.005"],["61221.30","0.000"],["61427.70","0.000"],["61733.60","0.001"],["61733.70","0.003"],["61735.90","3.407"],["61802.50","0.207"],["61834.60","11.769"],["61847.20","0.003"],["61847.40","0.216"],["61854.40","2.663"],["61884.10","0.082"],["61889.50","0.000"],["61897.30","0.001"],["61903.50","0.254"],["61910.20","1.617"],["61964.50","0.032"],["61981.70","0.000"],["61983.70","0.096"],["61984.00","0.028"],["61985.30","0.055"],["61985.80","0.002"],["61987.90","19.327"],["61988.10","0.014"],["61989.00","0.003"],["62000.30","0.016"],["62008.20","0.008"],["62012.30","0.683"],["62015.50","0.022"],["62016.00","0.007"],["62016.60","0.006"],["62019.60","0.006"],["62026.10","0.019"],["62027.90","0.017"],["62028.00","2.409"],["62028.10","1.297"],["62028.20","0.189"],["62028.40","2.061"],["62028.80","0.350"],["62029.00","0.010"],["62029.20","0.008"],["62029.30","0.002"],["62029.40","0.000"],["62029.80","0.101"],["62030.10","0.004"],["62030.20","0.003"],["62030.30","0.005"],["62030.70","0.580"],["62031.00","0.009"],["62031.60","0.020"],["62031.70","0.001"],["62032.40","0.001"],["62033.10","1.716"],["62034.30","0.121"],["62035.20","0.324"],["62035.40","0.000"],["62036.00","0.016"],["62036.50","0.001"],["62036.70","0.224"],["62037.40","0.565"],["62037.50","0.383"],["62038.00","0.003"],["62038.20","0.322"],["62038.60","0.001"],["62039.10","0.002"],["62039.40","0.001"],["62039.90","0.157"],["62040.60","0.085"],["62042.50","0.019"],["62043.00","0.000"],["62043.80","0.054"],["62043.90","0.126"],["62045.70","0.193"],["62045.80","0.005"],["62046.40","0.001"],["62047.30","0.006"],["62047.60","0.000"],["62048.10","0.371"],["62048.20","15.481"]],"e":"depthUpdate","ps":"BTCUSDT","pu":10998400139137,"s":"BTCUSDT","st":1,"u":10998400154639}
{"E":1783504322756,"T":1783504322755,"U":10998400154667,"a":[["62048.30","0.656"],["62052.20","0.001"],["62052.80","0.004"],["62053.00","0.100"],["62054.20","0.295"],["62054.30","0.682"],["62054.40","0.094"],["62054.50","0.484"],["62054.80","1.080"],["62055.90","0.431"],["62056.10","1.602"],["62057.60","0.184"],["62058.00","0.092"],["62058.40","1.083"],["62058.70","0.174"],["62059.00","0.171"],["62059.20","0.773"],["62059.30","0.126"],["62059.40","0.883"],["62059.60","0.189"],["62059.90","0.198"],["62060.40","0.003"],["62060.70","0.013"],["62061.20","0.003"],["62062.50","0.241"],["62070.30","0.053"],["62070.80","1.485"],["62073.20","0.529"],["62074.70","0.124"],["62077.90","0.280"],["62081.40","0.690"],["62083.00","0.000"],["62084.40","0.755"],["62086.90","0.000"],["62087.00","0.380"],["62087.10","0.762"],["62102.40","0.097"],["62104.00","0.030"],["62105.70","0.095"],["62106.10","0.591"],["62110.30","0.499"],["62110.90","6.302"],["62111.70","22.290"],["62113.40","0.661"],["62113.70","0.005"],["62114.90","0.973"],["62115.70","0.000"],["62115.80","0.282"],["62115.90","0.011"],["62358.50","0.160"],["62358.60","0.003"],["62407.70","0.000"],["62408.80","0.008"],["62625.00","0.040"],["62668.30","0.000"],["62668.80","0.007"],["62669.40","0.008"],["62812.70","0.000"],["63281.90","0.061"],["63282.80","0.004"],["63289.20","0.015"],["63574.30","0.474"],["89523.20","0.018"]],"b":[["11543.90","1.184"],["11548.20","0.160"],["11648.20","0.096"],["11948.20","0.832"],["55843.30","0.002"],["59566.20","0.000"],["60800.20","0.039"],["60801.10","0.068"],["60807.30","0.018"],["61136.70","0.975"],["61427.70","0.000"],["61631.60","0.166"],["61694.00","0.033"],["61732.80","0.024"],["61738.00","0.005"],["61740.10","0.013"],["61777.40","0.004"],["61847.20","0.002"],["61964.20","0.033"],["62003.60","0.159"],["62008.00","0.063"],["62014.10","0.004"],["62024.10","0.075"],["62026.10","0.003"],["62027.70","0.317"],["62027.90","0.005"],["62028.20","0.129"],["62028.60","1.126"],["62029.00","0.000"],["62032.50","0.712"],["62034.20","0.577"],["62037.10","0.422"],["62037.50","0.061"],["62039.00","0.002"],["62039.30","0.205"],["62039.90","0.133"],["62040.60","0.005"],["62041.20","0.457"],["62042.30","1.385"],["62042.70","0.026"],["62043.60","0.125"],["62045.90","0.010"],["62047.70","0.000"],["62048.00","0.105"],["62048.10","0.364"],["62048.20","15.422"]],"e":"depthUpdate","ps":"BTCUSDT","pu":10998400154639,"s":"BTCUSDT","st":1,"u":10998400171348}
{"E":1783504322858,"T":1783504322857,"U":10998400171457,"a":[["62048.30","0.658"],["62050.70","0.147"],["62054.50","0.484"],["62055.30","0.004"],["62058.40","1.087"],["62059.20","0.941"],["62059.30","0.184"],["62059.70","0.003"],["62059.80","0.223"],["62059.90","0.288"],["62070.60","0.006"],["62070.90","2.039"],["62071.30","0.005"],["62071.50","0.002"],["62071.80","0.009"],["62077.40","0.010"],["62077.90","0.112"],["62078.30","0.605"],["62078.50","1.024"],["62093.50","0.058"],["62105.70","0.107"],["62107.80","0.676"],["62110.30","0.499"],["62114.00","0.091"],["62120.20","0.000"],["62668.80","0.007"],["62792.90","0.159"],["62806.70","0.795"],["63281.90","0.049"],["63289.20","0.018"]],"b":[["1000.00","210.692"],["11543.90","0.912"],["11548.20","0.304"],["11647.30","0.256"],["11648.20","0.000"],["11948.20","1.104"],["55843.30","0.002"],["58939.00","0.105"],["59566.20","0.003"],["60800.20","0.033"],["60807.30","0.030"],["61144.30","2.123"],["61427.70","0.002"],["61847.20","0.003"],["61855.30","0.002"],["61858.10","0.004"],["61888.80","0.032"],["61905.60","0.000"],["61943.20","0.276"],["62008.40","0.063"],["62015.00","0.004"],["62015.10","0.011"],["62015.50","0.012"],["62024.10","0.059"],["62027.50","0.014"],["62027.70","0.305"],["62031.00","0.011"],["62032.70","0.502"],["62034.90","1.227"],["62039.30","0.125"],["62041.20","0.459"],["62042.10","0.325"],["62042.20","0.024"],["62042.30","1.362"],["62042.70","0.002"],["62046.60","0.080"],["62048.00","0.308"],["62048.10","0.366"],["62048.20","15.422"]],"e":"depthUpdate","ps":"BTCUSDT","pu":10998400171348,"s":"BTCUSDT","st":1,"u":10998400185809}
{"E":1783504322960,"T":1783504322959,"U":10998400185816,"a":[["62048.30","0.659"],["62048.40","0.102"],["62049.30","0.002"],["62050.70","0.003"],["62052.40","0.217"],["62053.80","0.003"],["62054.10","0.065"],["62054.20","0.089"],["62054.30","0.416"],["62054.50","0.172"],["62054.80","0.963"],["62055.20","0.624"],["62055.90","0.326"],["62056.10","0.240"],["62056.80","0.004"],["62057.90","0.007"],["62059.70","0.099"],["62062.50","0.000"],["62063.00","0.589"],["62076.40","0.053"],["62076.60","0.008"],["62077.40","0.002"],["62077.80","1.445"],["62085.00","0.552"],["62085.70","0.005"],["62086.50","0.019"],["62086.70","0.000"],["62087.70","0.001"],["62087.80","1.355"],["62088.30","0.015"],["62088.40","0.689"],["62088.60","0.010"],["62092.50","0.958"],["62093.00","0.071"],["62093.60","0.003"],["62093.70","0.004"],["62099.60","1.500"],["62099.70","0.671"],["62106.40","0.226"],["62109.60","22.265"],["62110.30","0.499"],["62110.80","0.673"],["62111.60","0.148"],["62111.70","0.043"],["62114.90","1.031"],["62117.40","0.000"],["62117.60","0.455"],["62125.70","0.016"],["62131.90","4.853"],["62138.10","6.365"],["62144.50","1.008"],["62211.60","3.235"],["62239.10","0.774"],["62668.80","0.007"],["63017.70","0.001"],["63281.90","0.037"],["63289.20","0.027"],["89523.20","0.024"]],"b":[["1000.00","210.542"],["11543.90","0.640"],["11548.20","0.432"],["11647.30","0.128"],["11948.20","1.376"],["49638.60","0.000"],["55843.30","0.002"],["60800.20","0.021"],["61237.30","1.631"],["61427.70","0.004"],["61551.80","0.001"],["61735.90","3.397"],["61738.00","0.015"],["61786.10","0.000"],["61790.00","0.078"],["61790.70","0.655"],["61847.20","0.002"],["61942.20","0.029"],["61963.50","0.000"],["61990.90","0.061"],["61996.30","0.017"],["61997.10","0.004"],["62001.50","0.032"],["62002.10","4.160"],["62002.20","0.129"],["62009.20","0.647"],["62013.20","0.001"],["62013.90","0.299"],["62018.70","0.002"],["62019.20","0.022"],["62019.80","0.018"],["62020.00","0.941"],["62020.40","0.984"],["62022.10","0.019"],["62022.30","0.001"],["62024.60","0.334"],["62026.50","0.003"],["62027.10","0.001"],["62027.70","0.000"],["62028.90","0.019"],["62032.70","0.486"],["62037.40","0.932"],["62039.40","0.017"],["62040.50","0.000"],["62042.10","0.405"],["62045.80","0.001"],["62046.30","0.723"],["62046.60","0.000"],["62047.00","0.004"],["62047.50","0.002"],["62047.70","0.004"],["62047.90","0.342"],["62048.00","0.313"],["62048.20","15.927"]],"e":"depthUpdate","ps":"BTCUSDT","pu":10998400185809,"s":"BTCUSDT","st":1,"u":10998400198225}
{"E":1783504323062,"T":1783504323061,"U":10998400198279,"a":[["62048.30","0.666"],["62050.20","0.003"],["62050.70","0.146"],["62050.80","0.000"],["62052.90","0.649"],["62053.00","0.064"],["62053.80","0.099"],["62053.90","0.065"],["62054.00","0.100"],["62054.10","0.887"],["62054.20","0.000"],["62054.30","0.005"],["62054.40","0.005"],["62054.50","0.172"],["62054.70","0.000"],["62054.80","0.399"],["62055.80","0.004"],["62055.90","0.415"],["62057.60","0.236"],["62064.70","0.578"],["62065.80","0.897"],["62066.80","0.725"],["62068.00","0.122"],["62069.70","0.052"],["62072.00","0.453"],["62073.00","0.751"],["62077.50","0.006"],["62078.40","0.075"],["62078.50","0.922"],["62078.60","0.001"],["62087.00","0.470"],["62087.30","0.057"],["62097.20","0.265"],["62107.20","0.017"],["62109.60","0.018"],["62110.30","0.811"],["62113.60","0.001"],["62117.00","0.117"],["62117.40","0.000"],["62118.00","22.746"],["62144.50","0.696"],["62150.70","0.026"],["62151.50","0.218"],["62171.00","0.000"],["62176.10","0.011"],["62290.30","0.720"],["62296.70","0.459"],["62358.60","0.004"],["62446.10","0.142"],["62452.40","0.008"],["62602.20","0.014"],["62608.50","0.040"],["62668.80","0.003"],["62781.70","2.094"],["62913.20","0.000"],["63001.30","0.284"],["63022.80","0.000"],["63281.90","0.028"],["63289.20","0.033"]],"b":[["11543.90","0.416"],["11548.20","0.576"],["11646.10","0.080"],["11647.30","0.000"],["11848.20","0.048"],["11948.20","1.552"],["55843.30","0.002"],["59566.20","0.000"],["60800.20","0.018"],["60807.30","0.036"],["60968.70","0.000"],["61147.60","0.980"],["61427.70","0.006"],["61486.60","0.000"],["61492.80","0.016"],["61640.30","0.001"],["61646.60","0.012"],["61733.60","0.000"],["61738.00","0.016"],["61847.20","0.003"],["61931.50","0.148"],["61956.30","0.006"],["61996.30","0.001"],["61996.40","0.227"],["62001.30","0.122"],["62002.90","0.106"],["62005.90","0.013"],["62020.60","0.000"],["62023.40","0.083"],["62023.80","0.019"],["62026.60","0.059"],["62028.90","0.003"],["62030.10","0.020"],["62034.70","0.001"],["62034.90","0.501"],["62035.60","0.806"],["62036.30","1.786"],["62036.40","1.503"],["62036.90","0.688"],["62037.40","0.368"],["62042.10","0.325"],["62044.80","0.002"],["62046.00","0.000"],["62046.40","0.005"],["62046.90","0.003"],["62047.00","0.000"],["62047.30","0.005"],["62047.40","1.800"],["62047.60","0.003"],["62047.90","0.341"],["62048.00","0.308"],["62048.20","15.606"]],"e":"depthUpdate","ps":"BTCUSDT","pu":10998400198225,"s":"BTCUSDT","st":1,"u":10998400213000}
{"E":1783504323164,"T":1783504323163,"U":10998400213013,"a":[["62048.30","0.667"],["62050.70","0.003"],["62051.20","0.136"],["62052.70","0.906"],["62052.80","0.004"],["62052.90","0.445"],["62053.70","0.000"],["62053.80","0.188"],["62053.90","0.065"],["62054.10","0.001"],["62054.70","0.000"],["62054.80","0.383"],["62055.80","0.004"],["62064.70","0.014"],["62065.70","0.566"],["62066.80","0.000"],["62067.50","1.407"],["62068.60","0.000"],["62070.10","0.182"],["62074.90","0.162"],["62075.00","2.769"],["62081.00","0.462"],["62089.90","0.655"],["62096.10","0.002"],["62097.20","0.428"],["62097.50","0.016"],["62106.40","0.229"],["62111.60","0.249"],["62111.70","22.290"],["62117.00","0.016"],["62117.10","1.541"],["62117.20","0.294"],["62117.40","0.000"],["62118.00","0.499"],["62121.00","0.001"],["62127.20","0.002"],["62135.00","2.755"],["62141.30","0.019"],["62152.10","0.029"],["62158.30","0.877"],["62360.50","0.112"],["62668.80","0.003"],["62888.20","0.020"],["62962.70","7.959"],["63281.90","0.013"],["89523.20","0.030"]],"b":[["1000.00","210.542"],["11543.90","0.288"],["11548.20","0.704"],["11645.90","0.000"],["11646.00","0.000"],["11646.10","0.000"],["11848.20","0.192"],["11948.20","1.536"],["55843.30","0.002"],["57224.40","0.012"],["58941.70","0.000"],["58945.70","0.000"],["59566.20","0.003"],["60800.20","0.015"],["60807.30","0.042"],["60932.20","0.000"],["61427.70","0.002"],["61794.40","0.537"],["61800.70","0.283"],["61847.20","0.002"],["61932.00","0.121"],["61938.20","0.680"],["61948.90","0.000"],["61955.20","0.002"],["61963.00","0.031"],["61964.00","0.836"],["61969.20","0.103"],["61988.00","0.008"],["61989.00","0.001"],["61994.00","0.002"],["62000.30","0.018"],["62007.90","0.003"],["62021.10","0.001"],["62024.30","0.002"],["62028.90","0.001"],["62029.90","0.342"],["62033.80","0.023"],["62034.70","0.001"],["62035.20","0.002"],["62035.60","0.080"],["62036.30","1.706"],["62036.40","1.322"],["62036.50","1.364"],["62037.00","0.094"],["62037.20","0.326"],["62043.80","0.056"],["62045.30","0.080"],["62048.20","15.195"]],"e":"depthUpdate","ps":"BTCUSDT","pu":10998400213000,"s":"BTCUSDT","st":1,"u":10998400230184}
{"E":1783504323266,"T":1783504323265,"U":10998400230199,"a":[["62048.30","0.672"],["62051.20","0.136"],["62052.70","0.004"],["62053.00","0.004"],["62054.40","0.110"],["62054.50","0.484"],["62054.60","0.089"],["62054.70","0.991"],["62064.70","0.578"],["62065.70","0.002"],["62066.60","1.007"],["62067.50","0.682"],["62073.40","0.002"],["62079.60","0.484"],["62085.80","1.054"],["62087.00","0.548"],["62087.70","0.196"],["62087.80","1.460"],["62096.50","4.500"],["62097.50","0.179"],["62109.60","0.018"],["62110.30","0.499"],["62111.60","0.148"],["62111.70","0.043"],["62116.00","0.101"],["62118.00","22.746"],["62118.20","8.000"],["62149.30","11.011"],["62175.50","0.000"],["62180.20","0.646"],["62359.90","0.256"],["62668.80","0.005"],["62775.70","0.984"],["62856.40","0.001"],["62917.00","0.793"],["63005.80","0.286"],["63281.90","0.010"],["63289.20","0.036"]],"b":[["11543.90","0.144"],["11548.20","0.848"],["11643.90","0.752"],["11644.00","0.000"],["11645.70","0.000"],["11645.80","0.000"],["11848.20","0.320"],["11948.20","1.552"],["55843.30","0.002"],["58945.70","0.000"],["59566.20","0.000"],["60663.80","0.526"],["60800.20","0.003"],["61134.00","6.276"],["61427.70","0.004"],["61738.00","0.017"],["61847.20","0.003"],["61908.80","0.000"],["61916.80","1.260"],["61945.70","11.000"],["61946.60","3.090"],["61950.90","0.100"],["61976.70","8.000"],["61995.90","0.325"],["61998.40","4.514"],["62011.40","0.297"],["62028.30","0.444"],["62029.90","0.326"],["62031.90","0.050"],["62034.30","0.137"],["62034.50","1.163"],["62034.70","0.001"],["62035.40","0.726"],["62035.50","0.111"],["62036.40","0.596"],["62036.70","0.092"],["62037.00","0.094"],["62037.20","0.326"],["62040.70","0.003"],["62042.00","0.556"],["62045.30","0.020"],["62047.30","0.005"],["62047.70","0.084"],["62047.80","0.002"],["62047.90","0.339"],["62048.10","0.088"],["62048.20","15.614"]],"e":"depthUpdate","ps":"BTCUSDT","pu":10998400230184,"s":"BTCUSDT","st":1,"u":10998400244482}
{"E":1783504323368,"T":1783504323367,"U":10998400244524,"a":[["62048.30","0.672"],["62054.40","0.211"],["62054.50","0.484"],["62062.00","0.246"],["62062.40","0.013"],["62063.00","0.348"],["62064.60","0.564"],["62064.70","0.014"],["62065.70","0.002"],["62066.60","1.007"],["62067.50","0.682"],["62070.80","1.477"],["62071.70","0.008"],["62087.00","0.443"],["62087.10","0.657"],["62104.00","0.029"],["62110.30","0.500"],["62115.70","0.101"],["62115.80","22.529"],["62116.00","0.000"],["62118.00","0.499"],["62224.30","0.000"],["62225.50","0.003"],["62410.10","0.018"],["62413.10","0.001"],["62668.80","0.003"],["62857.70","1.589"],["89523.20","0.036"]],"b":[["11543.90","0.016"],["11548.20","0.976"],["11643.90","0.624"],["11848.20","0.464"],["11948.20","1.536"],["55843.30","0.002"],["58945.70","0.010"],["58945.80","0.003"],["59566.20","0.003"],["60807.30","0.045"],["60992.60","0.408"],["61307.80","0.000"],["61427.70","0.000"],["61847.20","0.002"],["61945.10","1.362"],["61946.40","0.169"],["61979.90","0.031"],["61986.20","0.003"],["62002.10","4.158"],["62002.70","1.376"],["62014.50","0.001"],["62021.50","0.093"],["62030.30","0.021"],["62033.70","0.010"],["62034.30","0.121"],["62034.70","0.887"],["62035.40","0.000"],["62035.50","0.837"],["62036.30","1.706"],["62036.40","0.032"],["62037.20","0.136"],["62046.10","1.883"],["62046.40","0.001"],["62046.50","0.005"],["62047.30","0.005"],["62047.70","0.004"],["62047.80","0.002"],["62048.20","15.617"]],"e":"depthUpdate","ps":"BTCUSDT","pu":10998400244482,"s":"BTCUSDT","st":1,"u":10998400257624}
{"E":1783504323470,"T":1783504323469,"U":10998400257652,"a":[["62048.30","2.876"],["62048.90","0.000"],["62052.00","0.051"],["62052.90","0.710"],["62053.00","0.064"],["62053.60","0.564"],["62053.70","0.821"],["62053.80","0.293"],["62054.40","0.534"],["62054.50","0.149"],["62054.60","0.194"],["62054.70","0.532"],["62055.30","0.007"],["62055.90","0.520"],["62056.10","1.602"],["62056.40","1.053"],["62057.60","0.184"],["62057.90","0.008"],["62058.40","0.087"],["62059.50","0.148"],["62060.90","0.613"],["62061.50","0.163"],["62061.60","1.298"],["62062.00","0.005"],["62062.70","0.901"],["62063.10","0.888"],["62064.60","0.000"],["62065.40","0.731"],["62066.60","0.282"],["62068.10","0.680"],["62070.20","0.003"],["62072.00","1.938"],["62072.70","0.057"],["62073.80","0.120"],["62076.10","0.590"],["62079.60","0.323"],["62085.80","0.732"],["62087.00","0.548"],["62087.10","0.762"],["62087.70","0.091"],["62087.80","1.355"],["62088.10","0.107"],["62096.00","1.417"],["62096.20","0.000"],["62096.40","2.964"],["62096.50","4.502"],["62097.70","0.018"],["62104.00","0.004"],["62107.20","0.329"],["62110.30","0.812"],["62110.80","0.572"],["62114.90","1.132"],["62115.30","0.056"],["62115.40","4.343"],["62115.70","0.000"],["62358.50","2.561"],["62668.80","0.003"],["63289.20","0.039"]],"b":[["1000.00","210.542"],["11543.90","0.000"],["11548.20","1.120"],["11643.90","0.480"],["11848.20","0.720"],["11948.20","1.296"],["55843.30","0.002"],["58945.70","0.000"],["60674.60","0.705"],["60807.30","0.048"],["60885.50","0.819"],["61117.50","0.002"],["61178.70","0.277"],["61427.70","0.000"],["61847.20","0.003"],["61987.90","19.329"],["61988.30","1.075"],["62017.60","0.349"],["62021.80","1.962"],["62024.80","0.136"],["62026.30","0.062"],["62027.50","0.002"],["62028.00","1.709"],["62029.30","0.582"],["62030.30","0.005"],["62030.70","0.000"],["62031.90","0.049"],["62032.50","0.012"],["62032.80","0.156"],["62034.20","0.657"],["62034.30","0.726"],["62035.00","0.348"],["62035.50","0.111"],["62039.90","0.000"],["62046.10","1.803"],["62047.30","0.007"],["62047.50","0.005"],["62047.60","0.000"],["62047.80","0.000"],["62048.20","14.276"]],"e":"depthUpdate","ps":"BTCUSDT","pu":10998400257624,"s":"BTCUSDT","st":1,"u":10998400270402}
{"E":1783504323572,"T":1783504323571,"U":10998400270772,"a":[["62048.30","2.875"],["62049.60","0.019"],["62051.20","0.247"],["62052.40","0.209"],["62052.60","0.905"],["62052.70","0.825"],["62053.00","0.100"],["62053.60","0.070"],["62053.80","0.188"],["62053.90","0.001"],["62054.40","0.328"],["62054.60","0.089"],["62054.70","0.112"],["62057.20","0.001"],["62057.50","0.001"],["62057.70","0.123"],["62057.90","0.007"],["62059.50","0.164"],["62060.40","0.244"],["62060.90","0.372"],["62063.10","0.888"],["62063.30","0.035"],["62064.70","0.014"],["62065.40","0.006"],["62065.90","2.090"],["62070.10","0.162"],["62073.30","0.122"],["62074.20","0.020"],["62085.70","0.110"],["62086.20","0.067"],["62087.00","0.443"],["62087.10","0.657"],["62095.70","0.165"],["62097.10","0.001"],["62102.40","0.001"],["62102.60","0.096"],["62114.80","0.102"],["62115.80","0.282"],["62120.00","22.445"],["62134.50","1.399"],["62225.50","0.000"],["62356.40","0.804"],["62448.00","0.198"],["62588.00","0.955"],["62668.80","0.003"],["62880.80","0.280"],["89523.20","0.042"]],"b":[["11548.20","1.248"],["11643.90","0.352"],["11848.20","0.992"],["11948.20","1.024"],["49639.00","0.000"],["55843.30","0.002"],["58939.90","0.003"],["59566.20","0.000"],["60800.20","0.000"],["61142.30","0.735"],["61148.50","0.735"],["61427.70","0.000"],["61738.00","0.018"],["61819.00","0.482"],["61847.20","0.002"],["61856.50","1.147"],["61878.60","0.016"],["61959.00","2.726"],["61989.70","0.018"],["61990.70","3.571"],["62003.00","0.001"],["62023.20","0.839"],["62024.90","0.063"],["62026.50","0.175"],["62026.60","0.000"],["62033.10","1.414"],["62034.20","0.017"],["62042.50","0.311"],["62045.70","0.129"],["62046.20","2.126"],["62046.30","0.725"],["62046.90","0.005"],["62047.30","0.005"],["62048.20","13.500"]],"e":"depthUpdate","ps":"BTCUSDT","pu":10998400270402,"s":"BTCUSDT","st":1,"u":10998400283192}
{"E":1783504323674,"T":1783504323673,"U":10998400283252,"a":[["62048.30","2.878"],["62051.20","0.368"],["62052.40","0.210"],["62057.90","0.329"],["62059.10","0.765"],["62059.50","0.148"],["62059.90","0.610"],["62060.90","0.050"],["62064.20","0.102"],["62067.50","0.698"],["62070.30","0.003"],["62070.70","0.272"],["62071.60","0.062"],["62074.70","0.004"],["62077.70","0.100"],["62078.60","0.009"],["62083.50","0.241"],["62085.10","0.011"],["62085.50","0.105"],["62085.70","0.005"],["62102.90","0.003"],["62109.20","0.211"],["62115.40","1.135"],["62115.90","21.996"],["62120.00","0.198"],["62225.60","0.003"],["62358.50","2.721"],["62668.80","0.003"],["63281.90","0.007"]],"b":[["11548.20","1.392"],["11643.90","0.208"],["11848.20","1.264"],["11947.30","0.496"],["11948.20","0.848"],["55843.30","0.002"],["57068.90","0.003"],["59566.20","0.003"],["61309.80","1.978"],["61427.70","0.000"],["61847.20","0.003"],["61924.30","0.080"],["61983.70","19.273"],["61985.70","0.012"],["61987.00","0.016"],["61987.90","0.153"],["61988.00","0.006"],["61989.90","0.099"],["61990.00","0.011"],["61990.70","0.794"],["62001.30","0.061"],["62018.30","0.008"],["62032.20","0.122"],["62032.60","0.317"],["62032.80","0.035"],["62033.10","1.412"],["62033.70","0.736"],["62034.10","0.601"],["62034.30","0.000"],["62034.70","0.323"],["62037.00","0.416"],["62038.20","0.000"],["62044.60","0.051"],["62046.10","1.805"],["62047.30","0.003"]],"e":"depthUpdate","ps":"BTCUSDT","pu":10998400283192,"s":"BTCUSDT","st":1,"u":10998400293081}
{"E":1783504323776,"T":1783504323773,"U":10998400293215,"a":[["62048.30","2.877"],["62053.00","0.064"],["62054.50","0.097"],["62055.90","0.415"],["62058.30","0.454"],["62058.60","0.345"],["62060.40","0.003"],["62064.20","0.104"],["62084.90","0.155"],["62085.50","0.000"],["62110.30","0.843"],["62146.30","0.000"],["62180.20","0.000"],["62221.80","0.000"],["62240.50","0.028"],["62358.60","0.003"],["62402.40","0.018"],["62410.10","0.000"],["62668.80","0.003"],["64011.60","0.035"],["67569.50","0.613"],["89523.20","0.048"]],"b":[["1000.00","210.542"],["11548.20","1.520"],["11643.90","0.080"],["11848.20","1.536"],["11947.30","0.352"],["11948.20","0.720"],["49637.00","0.000"],["55843.30","0.002"],["59566.20","0.000"],["61242.60","1.422"],["61255.10","0.002"],["61427.70","0.000"],["61737.90","0.001"],["61847.20","0.002"],["61916.80","0.672"],["61966.20","0.121"],["61978.50","0.003"],["61983.70","0.096"],["61985.70","0.012"],["61987.90","19.377"],["61990.90","0.061"],["62010.20","0.010"],["62014.50","0.048"],["62022.60","0.002"],["62026.90","0.050"],["62031.90","0.002"],["62033.10","1.414"],["62034.50","1.002"],["62034.90","0.454"],["62037.70","0.125"],["62039.20","0.048"],["62044.20","0.635"],["62048.20","13.512"]],"e":"depthUpdate","ps":"BTCUSDT","pu":10998400293081,"s":"BTCUSDT","st":1,"u":10998400302521}
{"E":1783504323878,"T":1783504323876,"U":10998400302716,"a":[["62048.30","5.304"],["62052.30","0.565"],["62052.40","0.370"],["62052.50","0.323"],["62052.60","0.019"],["62053.60","0.064"],["62053.80","0.100"],["62054.70","0.434"],["62055.10","1.000"],["62055.80","0.004"],["62055.90","0.093"],["62056.00","0.771"],["62056.40","0.053"],["62056.50","0.082"],["62057.20","0.000"],["62057.50","0.000"],["62059.10","0.001"],["62064.40","0.017"],["62067.50","0.702"],["62070.30","0.011"],["62071.50","0.702"],["62071.70","0.000"],["62072.30","0.203"],["62072.50","0.053"],["62073.00","0.051"],["62073.80","0.000"],["62074.20","0.000"],["62075.60","1.366"],["62083.70","0.158"],["62084.40","0.860"],["62084.70","0.577"],["62084.90","0.050"],["62085.00","0.641"],["62085.10","0.001"],["62085.40","0.020"],["62085.70","0.094"],["62089.80","2.672"],["62113.30","0.104"],["62113.40","0.762"],["62114.40","0.000"],["62114.80","0.001"],["62114.90","1.031"],["62115.90","0.011"],["62117.80","0.043"],["62118.00","22.484"],["62131.40","0.747"],["62139.90","0.003"],["62180.00","1.894"],["62204.70","0.008"],["62217.20","2.661"],["62356.40","0.644"],["62668.80","0.003"],["63281.90","0.004"],["63328.80","0.000"],["63900.00","14.217"],["63951.90","0.672"]],"b":[["11548.20","1.536"],["11643.90","0.000"],["11848.20","1.808"],["11946.10","0.096"],["11947.30","0.288"],["11948.20","0.640"],["55843.30","0.002"],["58300.00","17.337"],["58939.00","0.103"],["59566.20","0.003"],["60000.00","124.175"],["60209.20","0.000"],["60500.00","312.535"],["60800.00","64.927"],["61040.70","0.575"],["61427.70","0.000"],["61735.90","3.235"],["61738.00","0.019"],["61847.20","0.003"],["61916.90","0.604"],["61968.60","0.000"],["61980.90","1.503"],["61987.90","19.330"],["61993.30","0.000"],["62014.50","0.048"],["62024.80","0.136"],["62026.10","0.001"],["62026.90","0.050"],["62028.30","0.122"],["62028.60","1.706"],["62029.30","0.002"],["62031.60","0.141"],["62032.20","0.001"],["62032.50","0.014"],["62036.20","0.410"],["62037.20","0.004"],["62039.20","0.048"],["62047.90","0.001"]],"e":"depthUpdate","ps":"BTCUSDT","pu":10998400302521,"s":"BTCUSDT","st":1,"u":10998400313154}
{"E":1783504323980,"T":1783504323979,"U":10998400313329,"a":[["62048.30","2.526"],["62052.00","0.002"],["62052.20","0.050"],["62053.00","0.004"],["62054.70","0.112"],["62055.00","0.003"],["62055.10","0.000"],["62055.60","0.018"],["62055.90","0.415"],["62056.50","0.081"],["62056.80","1.004"],["62057.20","0.000"],["62057.60","0.164"],["62057.70","0.002"],["62057.90","0.330"],["62060.40","0.023"],["62064.10","0.130"],["62064.40","0.001"],["62065.20","0.725"],["62065.90","1.365"],["62066.50","0.084"],["62066.90","0.002"],["62067.90","0.001"],["62068.10","0.100"],["62068.90","0.581"],["62070.00","0.452"],["62072.30","0.083"],["62073.60","2.708"],["62079.40","0.000"],["62084.90","0.155"],["62085.50","0.105"],["62085.70","0.199"],["62085.80","0.843"],["62086.20","0.067"],["62089.80","2.674"],["62090.70","0.001"],["62112.50","0.116"],["62112.70","0.104"],["62113.30","0.104"],["62113.40","0.762"],["62114.40","0.000"],["62114.80","0.001"],["62118.00","0.499"],["62120.00","22.183"],["62204.60","0.678"],["62668.80","0.003"],["62930.90","15.476"],["63142.70","0.569"],["63158.80","0.000"],["63281.90","0.001"],["64541.40","0.000"],["89523.20","0.054"]],"b":[["11548.20","1.408"],["11848.20","2.080"],["11945.80","0.000"],["11945.90","0.000"],["11946.00","0.000"],["11946.10","0.064"],["11948.20","0.640"],["49638.60","0.000"],["55843.30","0.002"],["60807.30","0.051"],["61427.70","0.000"],["61800.00","7.676"],["61847.20","0.002"],["61950.90","0.000"],["62024.80","0.004"],["62028.70","0.005"],["62032.90","0.726"],["62033.70","0.010"],["62037.20","0.136"],["62042.90","0.002"],["62045.80","0.005"],["62046.50","0.001"],["62047.00","0.003"],["62047.50","0.002"]],"e":"depthUpdate","ps":"BTCUSDT","pu":10998400313154,"s":"BTCUSDT","st":1,"u":10998400321583}
{"E":1783504324082,"T":1783504324081,"U":10998400321756,"a":[["62048.30","2.523"],["62054.50","0.061"],["62055.60","0.002"],["62055.70","1.005"],["62055.90","0.093"],["62056.80","0.004"],["62061.30","1.527"],["62064.40","0.323"],["62065.00","1.396"],["62066.50","0.004"],["62070.00","0.512"],["62071.60","0.098"],["62074.50","0.000"],["62076.60","0.017"],["62079.40","0.004"],["62086.20","0.172"],["62114.80","0.102"],["62131.40","0.709"],["62358.60","0.002"],["62620.70","5.536"],["62668.80","0.003"]],"b":[["1000.00","210.542"],["11548.20","1.264"],["11848.20","2.352"],["11943.90","0.192"],["11944.20","0.000"],["11945.70","0.000"],["11948.20","0.640"],["55843.30","0.002"],["59566.20","0.000"],["60807.30","0.054"],["61427.70","0.000"],["61737.90","0.002"],["61847.20","0.003"],["62025.00","0.056"],["62028.00","2.409"],["62028.70","0.137"],["62032.90","0.000"],["62033.90","1.049"],["62046.30","0.727"],["62047.50","0.005"]],"e":"depthUpdate","ps":"BTCUSDT","pu":10998400321583,"s":"BTCUSDT","st":1,"u":10998400329309}
{"E":1783504324184,"T":1783504324181,"U":10998400329455,"a":[["62049.90","0.097"],["62065.00","1.380"],["62071.10","0.025"],["62074.30","0.947"],["62077.60","0.000"],["62095.80","0.487"],["62096.00","1.392"],["62097.20","0.265"],["62097.50","0.016"],["62103.80","1.327"],["62115.90","0.011"],["62118.00","22.484"],["62120.00","0.198"],["62358.50","2.881"],["62668.80","0.003"],["62948.00","0.714"],["89523.20","0.060"]],"b":[["11548.20","1.136"],["11848.20","2.624"],["11943.90","0.048"],["11948.20","0.640"],["55843.30","0.002"],["59566.20","0.003"],["60186.80","2.406"],["60991.00","0.837"],["61427.70","0.000"],["61738.00","0.181"],["61847.20","0.002"],["61977.80","0.013"],["61983.20","0.099"],["62002.00","0.064"],["62028.70","0.005"],["62033.50","0.764"],["62033.90","0.323"]],"e":"depthUpdate","ps":"BTCUSDT","pu":10998400329309,"s":"BTCUSDT","st":1,"u":10998400336876}
{"E":1783504324286,"T":1783504324285,"U":10998400337132,"a":[["62048.40","0.002"],["62055.60","0.324"],["62059.60","0.504"],["62063.40","1.248"],["62064.40","0.001"],["62066.60","0.283"],["62071.10","0.009"],["62072.70","0.073"],["62076.00","0.008"],["62086.20","0.067"],["62110.30","0.879"],["62114.80","0.001"],["62115.90","0.011"],["62118.00","22.484"],["62668.80","0.003"],["63148.00","0.790"],["63414.10","0.013"],["64530.20","0.663"]],"b":[["1000.00","210.542"],["11548.20","0.992"],["11748.20","0.080"],["11848.20","2.736"],["11943.90","0.000"],["11948.20","0.640"],["55843.30","0.002"],["59566.20","0.000"],["60702.60","0.005"],["61161.90","1.705"],["61371.80","0.000"],["61427.70","0.000"],["61847.20","0.003"],["61990.00","0.009"]],"e":"depthUpdate","ps":"BTCUSDT","pu":10998400336876,"s":"BTCUSDT","st":1,"u":10998400345787}
{"E":1783504324388,"T":1783504324387,"U":10998400345997,"a":[["62048.30","2.528"],["62053.90","0.005"],["62056.40","0.049"],["62066.20","0.090"],["62071.60","0.158"],["62072.40","0.220"],["62072.70","0.057"],["62078.70","3.922"],["62082.10","0.000"],["62110.30","0.880"],["62668.80","0.003"],["62668.90","0.008"],["62771.80","0.000"],["89523.20","0.066"]],"b":[["1000.00","210.542"],["11548.20","0.864"],["11748.20","0.224"],["11848.20","2.720"],["11947.30","0.192"],["11948.20","0.736"],["55843.30","0.002"],["58945.80","0.006"],["61427.70","0.008"],["61738.00","0.182"],["61847.20","0.002"],["61971.00","0.002"],["61983.30","0.000"],["61986.20","0.004"],["61988.00","0.008"],["61992.70","0.047"],["61995.70","0.002"],["62014.50","0.048"],["62021.10","0.323"],["62025.70","0.098"],["62026.90","0.050"],["62027.30","0.161"],["62033.50","0.845"],["62036.20","0.363"],["62039.20","0.048"],["62041.50","0.004"],["62048.20","13.511"]],"e":"depthUpdate","ps":"BTCUSDT","pu":10998400345787,"s":"BTCUSDT","st":1,"u":10998400354344}
{"E":1783504324490,"T":1783504324489,"U":10998400354481,"a":[["62048.30","0.666"],["62052.40","0.372"],["62058.30","0.695"],["62058.60","0.104"],["62072.90","0.028"],["62078.00","1.581"],["62084.40","0.755"],["62084.70","0.472"],["62109.90","1.553"],["62225.60","0.000"],["62225.80","0.005"],["62357.90","0.531"],["62400.40","0.018"],["62402.40","0.000"],["62480.00","0.810"],["62668.80","0.003"]],"b":[["11548.20","0.720"],["11748.20","0.352"],["11848.20","2.736"],["11947.30","0.048"],["11948.20","0.880"],["49635.00","0.000"],["55843.30","0.002"],["59566.20","0.003"],["61137.20","0.016"],["61254.00","0.049"],["61427.70","0.010"],["61738.00","0.182"],["61847.20","0.003"],["61946.40","0.166"],["61946.60","3.093"],["61992.70","0.000"],["62025.70","0.018"],["62028.70","0.005"],["62031.20","0.300"],["62033.70","0.574"],["62034.10","0.037"],["62036.20","0.410"],["62042.50","0.335"],["62048.20","14.510"]],"e":"depthUpdate","ps":"BTCUSDT","pu":10998400354344,"s":"BTCUSDT","st":1,"u":10998400365491}
{"E":1783504324592,"T":1783504324591,"U":10998400366065,"a":[["62048.30","0.000"],["62048.40","0.000"],["62048.50","0.000"],["62048.60","0.000"],["62049.00","0.000"],["62049.10","0.000"],["62049.30","0.000"],["62049.50","0.000"],["62049.60","0.000"],["62049.70","0.000"],["62049.80","0.000"],["62049.90","0.000"],["62050.00","0.000"],["62050.10","0.000"],["62050.20","0.000"],["62050.30","0.000"],["62050.40","0.000"],["62050.50","0.000"],["62050.60","0.000"],["62050.70","0.000"],["62050.90","0.000"],["62051.10","0.000"],["62051.20","0.000"],["62051.30","0.000"],["62051.40","0.000"],["62051.50","0.000"],["62051.70","0.000"],["62051.80","0.000"],["62052.00","0.000"],["62052.10","0.000"],["62052.20","0.000"],["62052.30","0.000"],["62052.40","0.000"],["62052.50","0.000"],["62052.60","0.000"],["62052.70","0.000"],["62052.80","0.000"],["62052.90","0.000"],["62053.00","0.000"],["62053.10","0.000"],["62053.20","0.000"],["62053.30","0.000"],["62053.40","0.000"],["62053.50","0.000"],["62053.60","0.000"],["62053.70","0.864"],["62053.80","0.002"],["62053.90","0.001"],["62054.00","0.001"],["62054.30","0.001"],["62054.40","0.101"],["62054.50","0.000"],["62054.60","0.000"],["62054.70","0.000"],["62054.80","0.000"],["62054.90","0.000"],["62055.00","0.002"],["62055.10","0.001"],["62055.20","0.000"],["62055.30","0.097"],["62055.40","0.246"],["62055.50","0.001"],["62055.60","0.647"],["62055.70","0.000"],["62055.90","0.003"],["62056.00","0.051"],["62056.10","0.002"],["62056.20","0.493"],["62056.30","0.004"],["62056.40","0.000"],["62056.50","0.050"],["62056.60","0.002"],["62056.70","0.001"],["62056.80","0.001"],["62056.90","0.001"],["62057.00","0.003"],["62057.10","0.008"],["62057.20","0.000"],["62057.30","0.000"],["62057.40","0.001"],["62057.50","0.000"],["62057.60","0.002"],["62057.70","0.006"],["62057.80","0.002"],["62057.90","0.004"],["62058.00","0.093"],["62058.10","0.000"],["62058.20","0.002"],["62058.30","0.001"],["62058.40","0.087"],["62058.50","0.023"],["62058.60","0.104"],["62058.70","0.388"],["62058.80","0.007"],["62058.90","0.004"],["62059.00","0.172"],["62059.10","0.731"],["62059.20","0.574"],["62059.30","0.184"],["62059.40","0.003"],["62059.60","0.502"],["62059.70","0.099"],["62059.80","0.274"],["62059.90","0.288"],["62060.00","1.051"],["62060.10","0.000"],["62060.20","0.000"],["62060.40","0.004"],["62060.50","0.000"],["62060.70","0.589"],["62060.80","0.004"],["62061.20","0.067"],["62061.30","0.163"],["62061.50","0.005"],["62061.60","0.003"],["62061.70","0.085"],["62061.80","0.000"],["62061.90","0.001"],["62062.00","0.069"],["62062.20","0.126"],["62062.30","0.002"],["62062.40","2.439"],["62062.50","1.593"],["62062.60","0.231"],["62062.70","0.014"],["62062.90","0.002"],["62063.00","0.348"],["62063.10","0.324"],["62063.20","0.122"],["62063.30","0.000"],["62063.40","1.248"],["62063.50","0.006"],["62063.60","0.456"],["62063.70","0.324"],["62063.80","0.126"],["62063.90","0.404"],["62064.00","0.075"],["62064.10","0.050"],["62064.20","0.106"],["62064.40","0.241"],["62064.50","0.448"],["62064.60","0.000"],["62064.70","0.010"],["62064.80","1.529"],["62065.00","0.213"],["62065.10","0.007"],["62065.20","0.000"],["62065.30","0.123"],["62065.50","0.481"],["62065.60","0.003"],["62065.70","0.453"],["62065.80","0.018"],["62065.90","0.003"],["62066.00","0.002"],["62066.10","0.002"],["62066.20","0.001"],["62066.30","0.323"],["62066.40","0.076"],["62066.60","0.622"],["62066.90","0.126"],["62067.00","0.009"],["62067.10","0.343"],["62067.20","0.003"],["62067.30","0.327"],["62067.40","0.001"],["62067.50","0.001"],["62067.60","0.057"],["62067.70","0.003"],["62067.90","0.101"],["62068.00","0.127"],["62068.10","0.664"],["62068.50","0.176"],["62068.60","0.725"],["62068.70","0.003"],["62068.90","0.001"],["62069.40","0.000"],["62069.60","0.342"],["62069.70","0.003"],["62069.90","0.283"],["62070.00","0.415"],["62070.30","0.583"],["62070.40","0.030"],["62070.50","0.001"],["62070.60","0.408"],["62070.70","0.214"],["62071.00","0.016"],["62071.30","0.007"],["62071.40","0.328"],["62071.50","0.737"],["62071.60","0.015"],["62071.70","0.000"],["62071.80","0.011"],["62071.90","0.057"],["62072.20","0.003"],["62072.30","0.747"],["62072.40","0.039"],["62072.50","0.053"],["62072.60","0.051"],["62072.70","0.047"],["62072.80","1.362"],["62072.90","0.012"],["62073.00","0.132"],["62073.30","0.122"],["62073.50","0.002"],["62073.60","2.668"],["62073.80","0.000"],["62074.00","0.023"],["62074.10","0.015"],["62074.20","0.100"],["62074.30","0.902"],["62074.40","0.004"],["62074.50","0.008"],["62074.60","0.001"],["62074.80","0.003"],["62074.90","0.162"],["62075.10","0.261"],["62075.20","0.001"],["62075.40","9.354"],["62075.50","1.007"],["62075.60","1.362"],["62075.70","0.000"],["62075.80","0.010"],["62076.00","0.003"],["62076.10","0.289"],["62076.20","0.000"],["62076.40","0.056"],["62076.60","0.009"],["62076.70","0.004"],["62076.80","0.076"],["62077.10","0.000"],["62077.20","1.295"],["62077.30","0.010"],["62077.40","0.002"],["62077.50","0.003"],["62077.60","0.059"],["62077.70","0.053"],["62077.80","1.437"],["62077.90","0.223"],["62078.40","0.075"],["62078.50","0.931"],["62078.60","0.001"],["62078.70","3.530"],["62078.80","0.016"],["62078.90","0.000"],["62079.00","0.003"],["62079.20","0.000"],["62079.40","0.000"],["62079.50","0.002"],["62079.60","0.323"],["62079.80","0.687"],["62080.00","1.083"],["62080.10","0.001"],["62080.30","0.001"],["62080.40","0.001"],["62080.50","0.060"],["62081.20","0.001"],["62081.30","0.882"],["62081.50","0.000"],["62081.80","0.117"],["62082.10","0.000"],["62082.30","1.362"],["62082.50","0.043"],["62082.70","0.001"],["62082.80","0.089"],["62082.90","0.002"],["62083.00","0.002"],["62083.10","0.004"],["62083.20","0.070"],["62083.30","0.124"],["62083.40","0.303"],["62083.50","0.121"],["62083.60","1.297"],["62083.70","0.158"],["62083.90","0.151"],["62084.00","0.026"],["62084.40","0.760"],["62084.70","0.561"],["62084.80","1.415"],["62084.90","0.140"],["62085.00","0.552"],["62085.10","0.001"],["62085.40","0.021"],["62085.50","0.000"],["62085.60","0.795"],["62085.70","0.091"],["62085.80","0.731"],["62085.90","0.686"],["62086.10","0.016"],["62086.40","0.001"],["62086.50","0.047"],["62086.60","0.201"],["62086.80","0.025"],["62086.90","0.197"],["62087.00","0.637"],["62087.10","0.001"],["62087.20","0.002"],["62087.30","0.001"],["62087.40","0.000"],["62087.80","1.356"],["62087.90","0.295"],["62088.20","0.044"],["62088.30","0.015"],["62088.40","0.679"],["62088.50","3.779"],["62088.60","0.000"],["62088.70","0.098"],["62088.80","0.001"],["62088.90","0.229"],["62089.10","0.006"],["62089.20","0.001"],["62089.40","0.003"],["62089.50","0.061"],["62089.60","0.046"],["62089.70","0.882"],["62089.80","2.869"],["62089.90","0.655"],["62090.10","0.005"],["62090.20","0.000"],["62090.30","1.930"],["62090.40","1.298"],["62090.90","0.025"],["62091.00","0.733"],["62091.20","0.001"],["62091.30","0.940"],["62091.50","1.362"],["62091.70","0.042"],["62091.80","0.336"],["62091.90","0.003"],["62092.10","0.000"],["62092.60","0.000"],["62092.70","0.050"],["62092.80","0.099"],["62092.90","0.292"],["62093.10","0.153"],["62093.60","0.000"],["62093.80","0.008"],["62093.90","0.005"],["62094.00","0.856"],["62094.50","0.002"],["62094.60","0.003"],["62094.70","0.121"],["62094.80","0.003"],["62095.00","0.301"],["62095.10","0.001"],["62095.20","0.023"],["62095.40","0.017"],["62095.60","0.002"],["62095.70","0.002"],["62095.80","0.421"],["62096.20","0.000"],["62096.40","1.071"],["62096.60","0.287"],["62096.90","0.000"],["62097.20","0.265"],["62097.50","0.000"],["62097.60","0.574"],["62097.80","0.018"],["62098.00","0.003"],["62098.10","0.304"],["62098.20","0.003"],["62098.30","0.033"],["62098.40","0.003"],["62098.60","0.031"],["62098.80","0.000"],["62099.00","0.043"],["62099.60","1.485"],["62099.80","0.606"],["62099.90","0.730"],["62100.80","0.006"],["62101.10","0.080"],["62101.20","0.000"],["62101.50","0.003"],["62102.00","0.061"],["62102.30","0.042"],["62102.40","0.001"],["62102.60","0.000"],["62102.70","0.001"],["62102.90","0.659"],["62103.00","0.001"],["62103.60","0.001"],["62103.80","1.302"],["62104.00","0.010"],["62104.30","0.286"],["62104.50","0.452"],["62104.60","0.263"],["62105.00","0.124"],["62105.20","0.355"],["62105.30","0.003"],["62106.30","1.504"],["62106.60","0.662"],["62107.00","0.003"],["62107.20","0.220"],["62107.30","0.009"],["62108.10","0.104"],["62108.30","0.156"],["62109.20","0.001"],["62109.50","0.313"],["62109.60","0.130"],["62109.70","1.347"],["62109.80","0.000"],["62110.30","0.605"],["62110.40","0.061"],["62110.60","0.686"],["62110.70","0.064"],["62111.40","0.693"],["62111.60","0.148"],["62112.00","0.004"],["62112.10","0.101"],["62112.30","0.173"],["62112.50","0.015"],["62112.60","0.282"],["62112.70","0.104"],["62113.30","0.003"],["62113.40","0.762"],["62113.50","0.661"],["62114.20","0.483"],["62114.40","0.032"],["62114.60","0.067"],["62114.70","0.190"],["62114.80","0.001"],["62114.90","1.029"],["62115.00","4.383"],["62115.40","4.342"],["62115.80","0.605"],["62115.90","0.013"],["62116.80","0.002"],["62117.30","0.203"],["62117.40","0.000"],["62117.60","0.455"],["62117.90","0.001"],["62118.00","0.524"],["62118.90","0.050"],["62119.10","0.053"],["62119.20","12.972"],["62119.30","0.210"],["62120.00","21.935"],["62120.30","0.007"],["62120.70","0.012"],["62123.20","0.000"],["62123.50","0.000"],["62123.70","1.373"],["62126.20","0.001"],["62126.60","0.601"],["62126.70","0.060"],["62127.10","0.064"],["62127.20","0.013"],["62128.10","0.738"],["62130.00","0.865"],["62131.70","1.036"],["62131.90","0.017"],["62134.30","0.153"],["62134.40","0.657"],["62135.00","2.769"],["62135.30","0.745"],["62135.60","0.002"],["62137.00","0.000"],["62139.50","0.017"],["62139.90","0.000"],["62141.90","0.001"],["62142.30","0.883"],["62144.20","0.092"],["62145.10","0.001"],["62145.80","4.871"],["62146.10","0.167"],["62146.70","0.137"],["62146.90","2.815"],["62147.80","0.015"],["62153.60","1.600"],["62153.70","0.274"],["62153.80","0.671"],["62153.90","0.001"],["62155.40","0.001"],["62166.30","0.018"],["62168.00","0.528"],["62168.20","0.249"],["62168.40","0.316"],["62169.20","0.959"],["62172.20","0.141"],["62175.10","4.684"],["62176.60","2.417"],["62180.00","1.274"],["62181.10","0.025"],["62183.60","0.024"],["62183.80","0.682"],["62184.30","0.642"],["62184.70","0.003"],["62194.70","4.031"],["62207.50","0.021"],["62207.90","0.213"],["62218.30","0.003"],["62221.00","0.001"],["62225.70","0.001"],["62225.80","0.002"],["62226.40","0.003"],["62227.90","0.243"],["62228.80","0.001"],["62230.30","0.003"],["62233.60","0.018"],["62239.90","0.001"],["62247.40","0.010"],["62278.10","0.276"],["62278.40","0.000"],["62281.10","0.278"],["62312.20","1.337"],["62313.20","0.142"],["62313.30","0.680"],["62313.90","0.001"],["62316.10","0.001"],["62354.00","0.169"],["62354.50","0.000"],["62356.40","0.003"],["62357.70","0.024"],["62364.00","1.603"],["62367.00","0.059"],["62376.30","0.104"],["62419.70","0.000"],["62426.00","0.163"],["62449.90","2.643"],["62480.00","0.808"],["62481.80","0.012"],["62488.10","0.001"],["62542.60","0.000"],["62543.80","0.000"],["62547.50","0.008"],["62550.10","0.001"],["62668.80","0.003"],["62669.80","0.000"],["62670.40","0.011"],["62671.60","0.000"],["62672.30","0.000"],["62672.70","0.000"],["62672.80","0.020"],["62674.20","0.002"],["62762.20","6.362"],["62763.30","0.000"],["62764.00","0.000"],["62765.10","0.473"],["62766.30","9.460"],["62767.10","0.946"],["62767.60","4.736"],["62824.20","0.001"],["62825.30","0.000"],["62826.00","0.002"],["62827.20","0.033"],["62827.80","3.159"],["62828.40","6.304"],["63284.80","0.018"],["63292.00","0.006"],["63601.00","0.079"],["67176.30","0.000"],["67569.50","0.000"],["67569.60","0.000"],["89523.20","0.072"]],"b":[["1000.00","210.542"],["11548.20","0.592"],["11748.20","0.368"],["11749.80","0.016"],["11751.00","0.016"],["11752.10","0.064"],["11753.60","0.048"],["11848.20","2.592"],["11848.30","0.016"],["11851.00","0.032"],["11852.10","0.048"],["11853.60","0.000"],["11946.10","0.000"],["11947.30","0.000"],["11949.80","0.016"],["11951.00","0.016"],["11952.10","0.064"],["11953.60","0.032"],["55843.30","0.000"],["55844.80","0.000"],["55845.90","0.000"],["55846.80","0.000"],["55848.20","0.002"],["56500.50","0.050"],["56529.60","0.666"],["59566.20","0.000"],["60803.10","0.008"],["60811.10","0.007"],["60812.60","0.004"],["61035.60","0.000"],["61037.60","0.000"],["61037.70","0.491"],["61039.40","1.975"],["61045.80","0.001"],["61046.00","0.038"],["61046.10","0.000"],["61048.20","0.137"],["61048.30","0.005"],["61049.10","0.002"],["61051.00","0.023"],["61052.10","0.022"],["61052.20","0.014"],["61055.40","0.247"],["61106.30","0.000"],["61427.70","0.008"],["61427.80","0.000"],["61428.70","0.201"],["61429.30","0.000"],["61430.50","0.092"],["61431.40","0.000"],["61431.60","0.000"],["61431.70","0.000"],["61433.10","0.000"],["61509.70","0.295"],["61513.20","0.008"],["61547.80","0.000"],["61554.50","0.001"],["61609.90","0.002"],["61616.50","0.087"],["61632.00","0.062"],["61698.70","0.000"],["61707.60","0.000"],["61710.70","0.001"],["61713.70","0.001"],["61716.90","0.000"],["61735.90","2.426"],["61739.30","0.000"],["61742.70","0.011"],["61785.10","0.000"],["61785.20","0.003"],["61796.00","0.000"],["61802.50","0.000"],["61802.70","0.037"],["61804.10","0.000"],["61805.40","0.846"],["61835.10","0.315"],["61847.20","0.002"],["61848.10","6.439"],["61852.70","0.670"],["61866.60","0.006"],["61882.00","0.003"],["61882.10","0.001"],["61884.50","6.341"],["61885.20","0.003"],["61901.70","0.000"],["61911.40","0.000"],["61916.50","0.600"],["61916.90","0.028"],["61932.60","0.001"],["61942.00","4.323"],["61946.60","3.090"],["61947.20","0.708"],["61951.70","0.000"],["61952.10","1.403"],["61953.90","0.000"],["61956.30","0.660"],["61956.80","0.033"],["61957.10","0.065"],["61958.90","0.001"],["61959.20","3.095"],["61960.30","0.028"],["61961.70","0.000"],["61962.80","0.647"],["61963.40","0.000"],["61963.90","0.100"],["61964.20","0.001"],["61966.80","0.136"],["61966.90","0.021"],["61968.00","0.003"],["61970.00","0.136"],["61971.10","0.030"],["61972.20","0.002"],["61972.30","0.310"],["61973.20","0.001"],["61974.20","0.152"],["61975.10","3.924"],["61975.70","1.362"],["61975.80","0.030"],["61976.10","0.001"],["61976.20","0.029"],["61976.80","1.928"],["61977.40","19.179"],["61977.60","0.157"],["61977.70","0.700"],["61979.80","0.004"],["61980.80","0.238"],["61982.30","0.049"],["61983.70","0.015"],["61983.80","0.000"],["61983.90","1.364"],["61985.20","0.003"],["61986.10","0.935"],["61986.30","0.012"],["61987.00","0.000"],["61987.20","0.201"],["61987.40","0.008"],["61987.90","0.153"],["61988.00","0.006"],["61988.40","0.000"],["61989.50","0.000"],["61989.70","0.002"],["61990.10","0.613"],["61990.60","1.295"],["61990.70","0.767"],["61990.80","0.688"],["61990.90","0.005"],["61991.40","0.001"],["61991.50","0.101"],["61992.10","4.108"],["61992.20","1.288"],["61992.30","0.016"],["61992.60","0.000"],["61993.10","0.026"],["61993.20","0.325"],["61993.70","0.003"],["61993.80","9.354"],["61994.10","0.112"],["61994.30","0.101"],["61994.40","0.003"],["61994.50","1.382"],["61994.70","0.005"],["61995.40","0.000"],["61995.80","0.000"],["61995.90","0.000"],["61996.40","0.017"],["61996.80","0.002"],["61997.10","0.002"],["61997.40","0.277"],["61997.80","0.015"],["61997.90","3.789"],["61998.00","0.292"],["61998.10","0.000"],["61998.40","4.506"],["61998.60","0.675"],["61998.70","1.899"],["61999.10","0.000"],["61999.30","0.001"],["61999.50","0.001"],["61999.60","0.000"],["62000.10","1.877"],["62000.60","0.001"],["62000.90","0.084"],["62001.00","0.014"],["62001.10","0.001"],["62001.20","0.328"],["62001.60","0.018"],["62002.00","0.002"],["62002.10","4.155"],["62002.20","0.121"],["62002.30","1.305"],["62002.40","2.435"],["62002.50","0.829"],["62002.60","0.000"],["62002.70","1.374"],["62002.80","0.441"],["62002.90","0.024"],["62003.00","0.001"],["62003.10","0.003"],["62003.30","0.294"],["62003.50","0.061"],["62003.60","0.003"],["62003.70","0.026"],["62003.80","0.245"],["62004.10","0.003"],["62004.40","0.000"],["62005.20","2.163"],["62005.40","0.000"],["62005.50","0.003"],["62005.70","0.062"],["62005.90","0.010"],["62006.20","0.016"],["62006.60","0.003"],["62006.70","0.002"],["62006.80","2.064"],["62006.90","0.769"],["62007.10","0.321"],["62007.30","0.000"],["62007.50","0.002"],["62007.70","0.000"],["62008.40","0.070"],["62008.50","0.000"],["62008.60","0.300"],["62008.70","0.007"],["62008.90","0.013"],["62009.50","0.049"],["62009.70","0.002"],["62010.00","0.447"],["62011.30","0.060"],["62011.40","0.281"],["62011.50","0.002"],["62012.00","0.005"],["62012.10","0.682"],["62012.40","2.793"],["62012.80","0.086"],["62012.90","0.665"],["62013.00","0.002"],["62013.10","0.008"],["62013.20","0.001"],["62013.70","0.230"],["62013.80","1.287"],["62013.90","0.296"],["62014.00","0.097"],["62014.10","0.002"],["62014.20","0.010"],["62014.30","0.284"],["62014.60","0.293"],["62014.80","0.001"],["62014.90","0.002"],["62015.00","0.005"],["62015.10","0.001"],["62015.20","1.363"],["62015.30","0.050"],["62015.40","0.000"],["62015.50","0.009"],["62015.60","0.000"],["62015.70","0.003"],["62015.90","0.000"],["62016.00","0.005"],["62016.10","0.002"],["62016.50","0.013"],["62016.60","0.006"],["62016.90","0.091"],["62017.00","0.681"],["62017.30","0.000"],["62017.50","0.002"],["62017.60","0.335"],["62017.70","0.122"],["62017.80","0.017"],["62018.00","0.197"],["62018.10","0.662"],["62018.30","0.000"],["62018.40","0.001"],["62018.50","0.666"],["62018.60","0.005"],["62018.80","1.416"],["62019.00","0.071"],["62019.10","0.020"],["62019.20","0.014"],["62019.30","0.051"],["62019.70","0.003"],["62019.80","0.018"],["62019.90","0.003"],["62020.00","0.933"],["62020.20","0.681"],["62020.40","0.976"],["62020.50","0.020"],["62020.80","0.002"],["62020.90","0.001"],["62021.00","0.000"],["62021.10","0.001"],["62021.20","0.000"],["62021.40","1.363"],["62021.50","0.123"],["62021.60","1.507"],["62021.70","0.792"],["62021.80","1.962"],["62021.90","0.002"],["62022.10","0.016"],["62022.60","0.002"],["62022.70","0.001"],["62022.80","0.015"],["62023.00","0.255"],["62023.30","0.918"],["62023.40","0.083"],["62023.50","2.009"],["62023.80","0.003"],["62023.90","0.000"],["62024.10","0.059"],["62024.30","0.001"],["62024.40","0.001"],["62024.50","1.349"],["62024.60","0.294"],["62024.70","0.402"],["62024.80","0.687"],["62024.90","0.004"],["62025.00","0.007"],["62025.30","1.321"],["62025.50","0.100"],["62025.60","0.011"],["62025.80","0.327"],["62026.00","0.802"],["62026.20","0.002"],["62026.30","0.000"],["62026.50","0.173"],["62026.70","0.052"],["62026.80","0.002"],["62026.90","0.050"],["62027.10","0.049"],["62027.30","0.000"],["62027.40","0.100"],["62027.50","0.006"],["62027.80","0.000"],["62027.90","0.004"],["62028.00","2.171"],["62028.20","0.000"],["62028.50","0.875"],["62028.60","0.661"],["62028.70","0.708"],["62028.80","0.351"],["62028.90","0.001"],["62029.10","0.000"],["62029.30","0.016"],["62029.40","0.000"],["62029.50","0.131"],["62029.60","0.026"],["62029.80","0.115"],["62030.10","0.002"],["62030.20","0.003"],["62030.30","0.035"],["62030.40","0.007"],["62030.50","0.003"],["62030.60","0.363"],["62031.00","0.053"],["62031.10","0.231"],["62031.50","0.052"],["62031.60","0.012"],["62031.70","0.017"],["62032.00","0.681"],["62032.10","0.002"],["62032.20","0.592"],["62032.30","0.009"],["62032.70","0.494"],["62032.80","0.001"],["62032.90","0.002"],["62033.00","0.021"],["62033.10","0.005"],["62033.20","0.061"],["62033.30","0.011"],["62033.40","0.122"],["62033.50","0.046"],["62033.60","1.380"],["62033.70","0.003"],["62033.90","0.339"],["62034.10","0.009"],["62034.20","0.003"],["62034.30","0.001"],["62034.50","0.002"],["62034.60","1.637"],["62034.70","0.323"],["62034.80","0.000"],["62034.90","0.455"],["62035.00","1.011"],["62035.60","0.060"],["62035.90","0.171"],["62036.00","0.000"],["62036.20","0.322"],["62036.30","2.433"],["62036.40","0.032"],["62036.50","0.003"],["62036.60","0.916"],["62036.70","1.061"],["62036.80","0.173"],["62036.90","0.124"],["62037.00","0.094"],["62037.10","0.100"],["62037.20","0.004"],["62037.30","0.000"],["62037.40","0.368"],["62037.60","0.141"],["62037.70","0.001"],["62037.80","0.442"],["62037.90","0.035"],["62038.00","0.003"],["62038.10","0.388"],["62038.40","0.439"],["62038.50","0.002"],["62038.70","0.003"],["62038.80","0.057"],["62038.90","0.020"],["62039.00","0.000"],["62039.10","0.002"],["62039.20","0.171"],["62039.30","0.004"],["62039.40","0.001"],["62039.60","0.001"],["62039.80","0.915"],["62039.90","0.053"],["62040.20","0.001"],["62040.50","0.064"],["62040.70","0.125"],["62040.80","1.008"],["62040.90","1.295"],["62041.10","0.053"],["62041.20","0.453"],["62041.40","0.023"],["62041.70","0.003"],["62042.00","0.550"],["62042.10","0.334"],["62042.20","0.000"],["62042.30","1.483"],["62042.40","0.633"],["62042.50","1.191"],["62042.70","0.003"],["62042.90","0.003"],["62043.00","0.002"],["62043.10","0.003"],["62043.20","0.001"],["62043.40","0.324"],["62043.50","0.002"],["62043.90","0.088"],["62044.10","0.001"],["62044.60","0.000"],["62044.90","0.003"],["62045.30","0.000"],["62045.50","0.002"],["62045.60","0.003"],["62045.70","0.135"],["62045.80","0.001"],["62045.90","0.000"],["62046.00","0.001"],["62046.10","0.025"],["62046.20","0.479"],["62046.30","0.256"],["62046.40","0.009"],["62046.70","0.002"],["62047.00","0.000"],["62047.30","0.001"],["62047.40","0.000"],["62047.50","0.268"],["62047.70","0.000"],["62047.90","0.001"],["62048.00","0.080"],["62048.10","0.054"],["62048.20","0.097"],["62048.30","0.008"],["62048.40","0.036"],["62048.50","0.000"],["62048.70","0.002"],["62048.90","0.122"],["62049.00","0.102"],["62049.10","0.001"],["62049.20","0.001"],["62049.30","0.000"],["62049.40","0.001"],["62049.50","0.001"],["62049.60","0.057"],["62049.70","0.001"],["62049.80","0.234"],["62049.90","0.003"],["62050.00","0.002"],["62050.10","0.001"],["62050.20","0.001"],["62050.30","0.000"],["62050.40","0.279"],["62050.50","0.000"],["62050.60","0.000"],["62050.70","0.324"],["62050.80","0.003"],["62050.90","0.003"],["62051.00","0.041"],["62051.10","0.000"],["62051.20","0.004"],["62051.40","0.000"],["62051.60","0.001"],["62051.70","0.155"],["62051.80","0.000"],["62051.90","0.000"],["62052.00","1.800"],["62052.10","0.052"],["62052.20","2.202"],["62052.30","2.147"],["62052.40","0.002"],["62052.50","0.001"],["62052.60","0.049"],["62052.70","0.279"],["62052.80","0.000"],["62052.90","0.000"],["62053.00","0.000"],["62053.10","0.000"],["62053.20","0.132"],["62053.30","0.001"],["62053.40","0.002"],["62053.50","0.001"],["62053.60","13.302"]],"e":"depthUpdate","ps":"BTCUSDT","pu":10998400365491,"s":"BTCUSDT","st":1,"u":10998400412515}
{"E":1783504324694,"T":1783504324693,"U":10998400412970,"a":[["62053.70","0.000"],["62053.80","0.000"],["62053.90","0.000"],["62054.00","0.000"],["62054.10","0.000"],["62054.30","0.000"],["62054.40","0.000"],["62054.90","0.000"],["62055.00","0.000"],["62055.10","0.000"],["62055.30","5.700"],["62055.40","0.004"],["62055.50","0.001"],["62055.60","0.041"],["62055.90","0.001"],["62056.00","0.001"],["62056.20","0.056"],["62056.30","0.002"],["62056.50","0.002"],["62056.80","0.001"],["62056.90","0.092"],["62057.00","0.000"],["62057.10","0.002"],["62057.60","0.002"],["62057.70","0.004"],["62057.80","0.005"],["62057.90","0.003"],["62058.00","0.001"],["62058.20","0.000"],["62058.40","0.000"],["62058.50","0.000"],["62058.60","0.001"],["62058.70","0.002"],["62058.80","0.005"],["62059.00","0.001"],["62059.10","0.165"],["62059.20","0.002"],["62059.30","0.000"],["62059.40","0.000"],["62059.50","0.003"],["62059.60","0.316"],["62059.70","0.003"],["62059.80","0.646"],["62059.90","0.000"],["62060.00","0.074"],["62060.30","0.218"],["62060.60","0.006"],["62060.70","0.915"],["62060.80","0.004"],["62060.90","0.051"],["62061.00","0.178"],["62061.20","0.086"],["62061.50","0.001"],["62061.60","1.007"],["62061.70","0.002"],["62062.10","0.000"],["62062.20","1.466"],["62062.30","0.777"],["62062.40","0.165"],["62062.50","0.001"],["62062.60","0.165"],["62062.70","0.016"],["62062.90","0.203"],["62063.00","0.006"],["62063.20","0.002"],["62063.30","1.572"],["62063.60","0.189"],["62063.70","0.002"],["62063.80","0.003"],["62063.90","0.404"],["62064.20","0.104"],["62064.40","0.000"],["62064.50","0.001"],["62064.70","0.062"],["62064.80","0.405"],["62064.90","0.001"],["62065.00","0.211"],["62065.10","0.008"],["62065.20","0.322"],["62065.30","0.000"],["62065.40","0.700"],["62065.50","1.092"],["62065.60","0.023"],["62065.70","0.001"],["62065.90","0.003"],["62066.00","0.002"],["62066.10","0.003"],["62066.50","1.366"],["62066.70","0.065"],["62066.90","0.002"],["62067.00","0.004"],["62067.40","0.002"],["62067.60","0.057"],["62067.80","0.764"],["62067.90","0.081"],["62068.00","0.122"],["62068.10","0.664"],["62068.20","1.020"],["62068.60","0.000"],["62068.80","0.001"],["62068.90","0.001"],["62069.30","0.000"],["62069.60","0.020"],["62070.00","0.019"],["62070.30","0.003"],["62070.40","0.030"],["62070.50","0.322"],["62070.60","0.405"],["62070.70","0.052"],["62070.80","0.153"],["62070.90","1.395"],["62071.00","0.017"],["62071.20","0.005"],["62071.40","0.332"],["62071.50","0.002"],["62071.60","0.020"],["62071.70","0.753"],["62071.80","0.021"],["62071.90","0.067"],["62072.10","2.153"],["62072.30","0.094"],["62072.40","0.014"],["62072.90","0.584"],["62073.20","0.000"],["62073.60","2.672"],["62073.90","1.324"],["62074.00","0.025"],["62074.20","0.000"],["62074.30","0.018"],["62074.40","0.004"],["62074.50","0.000"],["62074.80","0.248"],["62074.90","0.162"],["62075.00","0.015"],["62075.10","0.266"],["62075.20","0.003"],["62075.30","0.001"],["62075.40","0.886"],["62076.00","0.005"],["62076.30","0.321"],["62076.50","0.679"],["62076.60","0.000"],["62077.00","0.057"],["62077.10","0.088"],["62077.20","1.295"],["62077.30","0.000"],["62077.60","0.000"],["62077.80","3.298"],["62077.90","13.615"],["62078.00","0.084"],["62078.30","0.666"],["62078.60","0.001"],["62078.70","0.364"],["62078.80","0.000"],["62078.90","0.000"],["62079.10","0.004"],["62079.20","0.453"],["62079.30","0.001"],["62079.40","0.010"],["62079.70","0.001"],["62079.90","0.000"],["62080.00","1.087"],["62080.10","0.049"],["62080.20","0.543"],["62080.60","0.026"],["62080.70","0.294"],["62080.80","0.012"],["62081.40","0.691"],["62081.50","0.025"],["62081.80","0.109"],["62082.10","0.000"],["62082.20","0.059"],["62082.60","0.008"],["62083.00","2.390"],["62083.10","0.002"],["62083.20","0.062"],["62083.60","1.298"],["62083.80","0.407"],["62084.00","0.001"],["62084.80","1.365"],["62084.90","0.062"],["62085.00","0.593"],["62085.20","0.004"],["62085.60","0.090"],["62085.80","0.746"],["62086.00","0.005"],["62086.40","0.041"],["62086.80","0.012"],["62086.90","0.194"],["62087.00","0.607"],["62087.70","0.253"],["62087.80","3.083"],["62088.00","0.374"],["62088.50","3.782"],["62088.70","0.049"],["62088.80","0.011"],["62089.00","0.194"],["62089.10","9.355"],["62089.20","0.003"],["62089.50","0.033"],["62089.60","0.031"],["62089.70","0.688"],["62089.80","2.675"],["62089.90","0.658"],["62090.00","0.287"],["62090.30","1.875"],["62090.70","0.001"],["62090.90","0.003"],["62091.00","0.853"],["62091.20","0.001"],["62091.40","0.000"],["62091.60","0.030"],["62091.80","0.337"],["62091.90","0.003"],["62092.30","0.094"],["62092.40","0.005"],["62092.60","0.719"],["62092.70","0.025"],["62092.80","0.100"],["62093.20","0.061"],["62093.40","0.088"],["62093.90","0.003"],["62094.10","0.685"],["62094.50","0.000"],["62095.40","0.019"],["62095.70","0.026"],["62095.80","0.325"],["62095.90","0.001"],["62096.10","0.004"],["62096.40","3.526"],["62097.00","0.030"],["62097.10","0.002"],["62097.30","0.697"],["62097.60","0.454"],["62097.90","0.040"],["62098.00","0.000"],["62098.10","0.292"],["62098.30","0.028"],["62098.40","0.000"],["62098.60","0.008"],["62098.70","0.039"],["62098.80","0.026"],["62098.90","0.031"],["62099.40","0.982"],["62099.90","0.736"],["62101.10","0.003"],["62101.30","0.000"],["62101.90","0.089"],["62102.30","0.002"],["62102.70","0.127"],["62103.90","1.370"],["62104.00","0.000"],["62104.60","0.273"],["62104.70","0.766"],["62105.00","0.154"],["62105.10","0.135"],["62107.20","0.217"],["62107.30","0.164"],["62107.70","0.002"],["62107.80","0.684"],["62108.10","0.100"],["62108.40","0.014"],["62108.50","1.362"],["62109.50","0.312"],["62109.60","0.293"],["62110.70","0.060"],["62110.80","0.576"],["62112.20","1.344"],["62112.30","0.173"],["62112.40","0.004"],["62113.30","0.315"],["62113.50","0.657"],["62114.10","0.034"],["62114.60","0.090"],["62114.90","2.934"],["62115.00","4.385"],["62115.10","0.086"],["62115.40","0.007"],["62115.80","0.706"],["62115.90","0.012"],["62116.40","0.003"],["62116.90","0.004"],["62117.80","0.144"],["62117.90","0.102"],["62118.00","6.848"],["62118.10","0.667"],["62118.20","8.000"],["62119.10","0.053"],["62119.20","13.182"],["62119.30","0.000"],["62120.40","0.000"],["62121.00","0.000"],["62124.50","0.702"],["62127.10","0.088"],["62128.10","0.747"],["62128.70","0.016"],["62130.00","0.866"],["62134.00","0.186"],["62137.10","0.001"],["62137.60","0.001"],["62139.00","0.004"],["62146.40","0.763"],["62146.90","2.807"],["62147.60","0.008"],["62148.80","0.307"],["62149.60","0.001"],["62152.10","0.028"],["62157.20","0.001"],["62158.60","1.148"],["62159.30","0.000"],["62167.20","0.000"],["62167.50","0.000"],["62171.40","2.751"],["62171.60","0.003"],["62173.50","0.001"],["62174.20","0.003"],["62176.60","2.418"],["62177.90","0.001"],["62196.20","0.001"],["62213.90","0.275"],["62226.50","0.658"],["62227.50","0.000"],["62228.60","0.166"],["62230.30","0.002"],["62232.00","0.013"],["62235.00","4.018"],["62238.50","0.003"],["62254.60","2.846"],["62257.30","18.131"],["62275.20","0.001"],["62295.70","0.000"],["62302.00","0.486"],["62313.20","0.325"],["62315.40","1.338"],["62316.40","0.854"],["62366.80","0.094"],["62367.70","0.000"],["62367.80","0.000"],["62373.10","0.080"],["62382.50","0.100"],["62399.90","3.174"],["62402.80","8.141"],["62452.70","0.187"],["62612.30","2.172"],["62644.60","0.632"],["62674.20","0.000"],["62674.80","0.003"],["62675.80","0.000"],["62675.90","0.004"],["62766.30","0.000"],["62767.10","0.000"],["62767.30","0.002"],["62767.40","0.795"],["62767.60","0.952"],["62768.00","0.008"],["62768.20","2.524"],["62769.40","14.192"],["62793.10","5.305"],["62799.80","12.608"],["62827.80","0.795"],["62828.40","0.000"],["62829.70","0.788"],["62830.40","0.007"],["62831.40","7.880"],["62891.40","0.271"],["62892.00","1.470"],["62892.20","0.944"],["62898.60","0.000"],["62922.90","2.364"],["62923.00","1.572"],["62923.20","1.788"],["62923.90","11.816"],["62954.90","2.205"],["62985.10","0.000"],["62985.30","0.000"],["63017.00","3.300"],["63047.30","0.001"],["63079.00","1.100"],["63264.30","0.000"],["63296.20","0.789"],["68259.70","0.002"]],"b":[["1000.00","210.542"],["11548.20","0.448"],["11753.60","0.096"],["11754.20","0.048"],["11755.20","0.176"],["11848.20","2.416"],["11848.30","0.000"],["11851.00","0.000"],["11852.10","0.000"],["11953.60","0.064"],["11954.20","0.016"],["11955.20","0.096"],["55848.20","0.000"],["55848.70","0.000"],["55849.60","0.002"],["58939.10","0.000"],["59572.90","0.003"],["60813.20","0.003"],["61048.30","0.003"],["61049.10","0.000"],["61051.00","0.009"],["61054.20","0.018"],["61267.40","0.004"],["61421.70","0.000"],["61433.10","0.000"],["61433.70","0.019"],["61434.60","0.000"],["61675.90","0.102"],["61682.90","0.001"],["61720.50","0.004"],["61730.50","0.100"],["61738.00","0.181"],["61744.90","0.001"],["61788.40","0.683"],["61788.90","0.464"],["61805.40","0.679"],["61847.20","0.003"],["61850.30","0.000"],["61862.10","0.000"],["61864.90","0.189"],["61869.00","0.001"],["61869.50","0.000"],["61872.60","0.675"],["61883.60","0.000"],["61884.40","0.002"],["61884.70","0.014"],["61891.90","0.000"],["61900.10","5.471"],["61902.70","0.004"],["61904.10","0.007"],["61905.90","0.235"],["61914.50","0.015"],["61916.80","0.673"],["61916.90","0.000"],["61917.00","0.283"],["61919.90","0.000"],["61924.10","0.001"],["61929.00","0.015"],["61929.10","0.876"],["61931.10","2.082"],["61931.50","0.145"],["61935.00","0.004"],["61946.10","0.001"],["61948.30","0.028"],["61948.40","8.983"],["61950.80","0.002"],["61952.10","1.387"],["61956.20","0.000"],["61956.30","0.485"],["61962.00","0.078"],["61963.20","0.003"],["61963.30","0.016"],["61963.60","6.302"],["61965.70","0.034"],["61965.90","0.001"],["61967.90","4.079"],["61968.30","0.281"],["61969.00","1.444"],["61971.60","0.172"],["61972.50","0.145"],["61973.20","0.000"],["61974.70","1.180"],["61975.10","4.101"],["61976.80","1.792"],["61977.40","0.002"],["61977.50","0.681"],["61978.00","0.001"],["61980.90","2.440"],["61981.00","0.011"],["61983.20","0.096"],["61983.30","1.913"],["61984.20","0.468"],["61984.30","1.147"],["61985.60","0.002"],["61985.80","0.002"],["61986.30","0.011"],["61986.50","1.362"],["61986.60","0.612"],["61987.20","0.122"],["61988.30","0.029"],["61988.40","1.179"],["61988.50","0.001"],["61989.20","0.000"],["61990.80","0.662"],["61990.90","0.003"],["61991.90","0.002"],["61992.00","0.087"],["61992.10","23.297"],["61992.90","0.009"],["61993.10","0.002"],["61993.20","0.342"],["61993.60","0.000"],["61994.10","0.055"],["61994.50","1.367"],["61994.70","0.001"],["61996.00","0.100"],["61998.00","0.292"],["61998.40","4.530"],["61998.50","0.695"],["61999.00","0.010"],["61999.80","0.052"],["62000.30","0.454"],["62000.90","0.002"],["62001.60","0.002"],["62001.70","0.015"],["62001.80","0.680"],["62002.00","1.073"],["62002.10","0.734"],["62002.30","1.295"],["62002.40","2.433"],["62002.80","0.005"],["62002.90","0.552"],["62003.00","0.083"],["62003.30","0.292"],["62003.50","0.059"],["62003.80","0.247"],["62004.00","0.017"],["62004.50","0.250"],["62004.70","0.002"],["62005.10","0.002"],["62005.20","2.097"],["62005.60","0.035"],["62005.70","0.000"],["62005.90","0.012"],["62006.10","1.102"],["62006.20","0.016"],["62006.60","0.002"],["62006.70","0.000"],["62006.80","2.061"],["62006.90","0.978"],["62007.00","0.303"],["62007.10","0.239"],["62007.40","0.016"],["62007.50","0.063"],["62007.90","0.005"],["62008.10","0.000"],["62008.30","0.004"],["62008.60","0.292"],["62009.20","0.655"],["62010.50","0.003"],["62010.80","0.026"],["62011.30","0.000"],["62011.80","0.059"],["62012.10","0.678"],["62012.20","0.002"],["62012.50","1.256"],["62012.80","0.004"],["62012.90","0.479"],["62014.50","0.001"],["62014.60","0.290"],["62014.70","0.003"],["62015.00","0.002"],["62015.70","0.000"],["62016.30","0.975"],["62016.50","0.016"],["62016.60","0.002"],["62016.80","1.341"],["62016.90","0.001"],["62017.70","0.125"],["62018.10","0.622"],["62018.20","0.060"],["62018.50","0.736"],["62019.00","0.001"],["62019.10","0.095"],["62019.40","0.001"],["62019.60","0.002"],["62019.80","0.010"],["62020.10","0.042"],["62020.50","0.023"],["62021.50","0.001"],["62021.70","0.779"],["62021.80","1.298"],["62021.90","0.001"],["62022.30","0.013"],["62022.60","0.000"],["62023.00","0.252"],["62023.20","0.530"],["62023.30","0.121"],["62023.50","2.047"],["62023.60","0.008"],["62023.80","0.003"],["62024.50","1.335"],["62024.60","0.294"],["62024.70","0.404"],["62025.10","0.011"],["62025.30","0.657"],["62025.40","0.058"],["62025.50","0.003"],["62025.60","0.003"],["62025.90","0.002"],["62026.00","0.754"],["62026.30","0.000"],["62026.40","0.180"],["62026.50","0.515"],["62026.70","0.002"],["62027.00","0.000"],["62027.10","0.001"],["62027.40","0.052"],["62027.50","0.005"],["62028.00","2.168"],["62028.10","1.306"],["62028.30","0.180"],["62028.40","1.370"],["62028.60","1.256"],["62028.70","0.708"],["62028.90","0.133"],["62029.10","2.458"],["62029.20","0.005"],["62029.30","0.032"],["62029.50","0.121"],["62029.60","0.048"],["62029.70","0.667"],["62029.80","0.029"],["62029.90","1.211"],["62030.10","0.002"],["62030.20","0.362"],["62030.50","0.001"],["62030.60","0.492"],["62030.70","0.001"],["62030.80","1.657"],["62031.00","0.013"],["62031.60","0.052"],["62031.70","0.001"],["62031.80","0.007"],["62032.10","0.050"],["62032.20","0.049"],["62032.40","0.033"],["62032.60","0.413"],["62032.80","0.003"],["62032.90","0.000"],["62033.00","0.021"],["62033.10","0.003"],["62033.30","0.013"],["62033.40","0.170"],["62033.50","0.040"],["62033.70","0.083"],["62033.80","0.029"],["62034.00","1.288"],["62034.20","0.583"],["62034.70","0.001"],["62034.80","0.000"],["62034.90","0.454"],["62035.00","0.348"],["62035.30","0.001"],["62035.40","0.000"],["62035.50","1.400"],["62035.70","0.003"],["62035.80","0.083"],["62035.90","0.050"],["62036.00","0.000"],["62036.10","0.062"],["62036.20","0.287"],["62036.30","1.709"],["62036.40","0.032"],["62036.50","0.664"],["62036.60","1.729"],["62036.70","1.141"],["62036.80","1.105"],["62037.60","0.017"],["62037.70","0.012"],["62037.80","0.445"],["62037.90","0.035"],["62038.10","0.384"],["62038.30","0.003"],["62038.40","0.310"],["62038.70","0.001"],["62038.80","0.056"],["62039.20","0.051"],["62039.30","0.730"],["62039.60","0.021"],["62039.70","1.633"],["62039.80","0.488"],["62039.90","0.609"],["62040.00","0.330"],["62040.10","0.002"],["62040.40","0.000"],["62040.50","0.064"],["62040.60","0.064"],["62040.70","0.001"],["62040.80","0.008"],["62041.00","0.010"],["62041.30","0.156"],["62041.70","0.001"],["62041.80","1.004"],["62041.90","0.000"],["62042.10","0.454"],["62042.30","1.362"],["62042.40","0.062"],["62042.50","1.249"],["62042.60","1.021"],["62042.70","0.740"],["62042.80","0.125"],["62043.00","0.000"],["62043.10","0.810"],["62043.40","0.327"],["62043.60","0.133"],["62043.70","0.001"],["62043.80","0.065"],["62043.90","0.108"],["62044.10","0.005"],["62044.40","0.123"],["62044.70","0.004"],["62044.80","0.066"],["62045.60","0.157"],["62045.70","0.133"],["62045.90","0.121"],["62046.10","0.001"],["62046.20","0.373"],["62046.30","0.255"],["62046.60","0.003"],["62046.90","0.003"],["62047.00","0.002"],["62047.50","0.006"],["62047.80","0.002"],["62047.90","0.001"],["62048.00","0.084"],["62048.10","0.052"],["62048.20","0.033"],["62048.30","0.009"],["62048.90","0.126"],["62049.00","0.062"],["62049.30","0.042"],["62049.40","0.264"],["62049.60","0.001"],["62049.80","0.234"],["62049.90","0.010"],["62050.20","0.043"],["62050.80","0.060"],["62050.90","0.001"],["62051.20","0.000"],["62051.70","0.050"],["62052.00","0.001"],["62052.10","0.051"],["62052.20","0.051"],["62052.30","1.801"],["62052.40","0.051"],["62052.60","0.004"],["62052.70","0.280"],["62053.10","0.001"],["62053.20","0.000"],["62053.40","0.000"],["62053.50","0.000"],["62053.60","0.284"],["62053.70","1.803"],["62053.80","0.000"],["62053.90","0.000"],["62054.00","0.000"],["62054.10","0.000"],["62054.20","0.080"],["62054.30","1.998"],["62054.40","0.685"],["62054.80","0.000"],["62054.90","0.000"],["62055.00","0.325"],["62055.10","0.006"],["62055.20","13.540"]],"e":"depthUpdate","ps":"BTCUSDT","pu":10998400412515,"s":"BTCUSDT","st":1,"u":10998400449791}
{"E":1783504324796,"T":1783504324795,"U":10998400449934,"a":[["62055.30","0.000"],["62055.40","0.000"],["62055.50","0.000"],["62055.60","0.000"],["62055.80","0.000"],["62055.90","0.000"],["62056.00","0.000"],["62056.10","0.000"],["62056.20","0.000"],["62056.30","0.000"],["62056.50","0.000"],["62056.60","0.000"],["62056.70","0.000"],["62056.80","0.000"],["62056.90","0.000"],["62057.00","0.000"],["62057.10","0.000"],["62057.40","0.000"],["62057.60","0.000"],["62057.70","0.000"],["62057.80","0.000"],["62057.90","0.000"],["62058.00","0.000"],["62058.10","4.929"],["62058.20","0.002"],["62058.40","0.000"],["62058.50","0.000"],["62058.60","0.000"],["62059.00","0.001"],["62059.10","0.000"],["62059.20","0.001"],["62059.50","0.001"],["62059.60","0.000"],["62059.70","0.090"],["62059.90","0.000"],["62060.00","0.001"],["62060.20","0.000"],["62060.30","0.002"],["62060.40","0.003"],["62060.50","0.000"],["62060.60","0.006"],["62060.70","0.013"],["62060.90","0.049"],["62061.00","0.007"],["62061.10","0.004"],["62061.20","0.002"],["62061.30","0.001"],["62061.40","0.000"],["62061.50","0.001"],["62061.60","0.002"],["62061.70","0.026"],["62061.80","0.000"],["62061.90","0.001"],["62062.00","0.005"],["62062.10","0.000"],["62062.20","0.005"],["62062.30","0.001"],["62062.40","1.145"],["62062.50","0.000"],["62062.60","0.003"],["62062.70","0.108"],["62062.80","0.002"],["62062.90","0.002"],["62063.00","0.061"],["62063.10","0.001"],["62063.20","0.162"],["62063.30","0.754"],["62063.40","0.097"],["62063.60","0.187"],["62063.70","0.058"],["62063.80","0.003"],["62063.90","0.512"],["62064.00","0.003"],["62064.10","0.218"],["62064.20","0.004"],["62064.30","0.000"],["62064.40","0.821"],["62064.50","0.001"],["62064.60","0.120"],["62064.70","0.014"],["62064.80","0.065"],["62064.90","1.001"],["62065.00","0.050"],["62065.10","2.856"],["62065.20","1.694"],["62065.30","0.000"],["62065.40","0.700"],["62065.50","0.367"],["62065.60","0.004"],["62065.70","0.065"],["62065.80","0.003"],["62066.00","0.004"],["62066.10","0.001"],["62066.20","0.001"],["62066.30","0.082"],["62066.40","0.076"],["62066.50","0.004"],["62066.60","0.622"],["62066.70","0.065"],["62066.80","0.000"],["62066.90","0.001"],["62067.10","0.001"],["62067.20","0.006"],["62067.30","0.325"],["62067.40","0.053"],["62067.50","0.324"],["62067.60","0.219"],["62067.70","1.366"],["62067.80","0.010"],["62067.90","0.022"],["62068.00","0.001"],["62068.10","0.030"],["62068.20","1.101"],["62068.50","0.173"],["62068.60","0.000"],["62068.70","0.163"],["62069.00","0.391"],["62069.10","0.003"],["62069.20","0.003"],["62069.30","0.000"],["62069.40","0.020"],["62069.50","0.000"],["62069.60","0.020"],["62069.80","0.164"],["62069.90","0.283"],["62070.00","0.464"],["62070.10","0.564"],["62070.20","1.365"],["62070.30","0.325"],["62070.40","0.191"],["62070.50","0.251"],["62070.60","0.003"],["62070.70","0.008"],["62070.80","0.564"],["62070.90","1.360"],["62071.00","0.017"],["62071.10","0.243"],["62071.30","0.005"],["62071.60","0.012"],["62071.70","0.028"],["62071.80","0.011"],["62071.90","0.066"],["62072.00","2.058"],["62072.20","0.350"],["62072.30","0.064"],["62072.40","0.005"],["62072.60","0.003"],["62072.70","0.000"],["62072.80","1.363"],["62072.90","0.004"],["62073.00","0.052"],["62073.60","2.682"],["62073.90","0.000"],["62074.00","0.026"],["62074.10","0.740"],["62074.20","0.100"],["62074.30","0.004"],["62074.50","0.040"],["62074.60","0.017"],["62074.70","0.004"],["62075.10","0.261"],["62075.20","0.004"],["62075.50","1.369"],["62075.60","1.363"],["62076.00","0.003"],["62076.20","0.292"],["62076.30","0.281"],["62076.40","0.053"],["62076.70","0.584"],["62076.80","0.158"],["62076.90","0.334"],["62077.10","0.000"],["62077.50","0.006"],["62077.60","0.001"],["62077.70","0.051"],["62077.80","3.218"],["62077.90","13.618"],["62078.00","0.084"],["62078.10","0.875"],["62078.30","0.605"],["62078.50","0.931"],["62078.60","0.003"],["62078.80","0.000"],["62079.10","0.084"],["62079.40","0.000"],["62079.60","0.358"],["62079.70","0.009"],["62079.90","0.000"],["62080.00","1.087"],["62080.10","0.000"],["62080.50","0.057"],["62080.60","0.025"],["62080.70","0.002"],["62080.90","0.069"],["62081.00","0.460"],["62081.10","0.003"],["62081.20","0.293"],["62081.30","0.880"],["62081.40","0.690"],["62081.50","0.009"],["62081.60","0.043"],["62081.70","0.037"],["62081.80","0.091"],["62081.90","0.028"],["62082.00","0.033"],["62082.10","0.010"],["62082.20","0.066"],["62082.40","0.001"],["62082.60","0.000"],["62082.70","0.001"],["62082.80","0.000"],["62082.90","0.002"],["62083.20","0.058"],["62083.30","0.244"],["62083.40","0.303"],["62083.60","1.315"],["62083.80","0.399"],["62083.90","0.005"],["62084.10","0.000"],["62084.30","0.161"],["62084.70","0.472"],["62084.80","1.415"],["62085.00","0.453"],["62085.10","0.002"],["62085.50","0.008"],["62085.60","0.101"],["62085.70","0.002"],["62086.10","0.002"],["62086.20","0.359"],["62086.50","0.032"],["62086.70","0.008"],["62086.90","0.089"],["62087.00","0.502"],["62087.20","0.004"],["62087.50","0.021"],["62087.90","0.052"],["62088.00","0.304"],["62088.10","0.197"],["62088.50","3.779"],["62088.90","0.231"],["62089.10","9.357"],["62089.30","0.004"],["62089.40","0.003"],["62089.50","0.004"],["62089.60","0.016"],["62089.70","0.882"],["62089.80","2.673"],["62089.90","0.659"],["62090.00","0.325"],["62090.20","0.000"],["62090.30","2.226"],["62090.40","1.296"],["62090.60","0.001"],["62090.80","0.001"],["62090.90","0.006"],["62091.00","0.758"],["62091.30","0.941"],["62091.40","0.000"],["62091.70","0.042"],["62091.90","0.000"],["62092.00","0.003"],["62092.10","0.000"],["62092.20","0.000"],["62092.30","0.091"],["62092.60","0.014"],["62092.70","0.000"],["62092.80","0.149"],["62092.90","0.049"],["62093.00","0.364"],["62093.40","0.088"],["62093.60","0.000"],["62093.80","0.011"],["62093.90","0.163"],["62094.00","0.851"],["62094.20","0.811"],["62094.60","0.005"],["62094.80","0.006"],["62095.20","0.037"],["62095.30","0.000"],["62095.40","0.016"],["62095.50","0.012"],["62095.60","0.026"],["62095.80","0.328"],["62096.00","1.366"],["62096.10","0.002"],["62096.40","3.540"],["62096.50","4.557"],["62096.90","0.002"],["62097.00","0.003"],["62097.60","0.456"],["62097.70","0.018"],["62098.10","0.294"],["62098.70","0.026"],["62099.00","0.043"],["62099.40","0.980"],["62099.70","0.671"],["62099.80","0.631"],["62099.90","0.730"],["62100.00","0.645"],["62100.50","0.691"],["62100.70","0.032"],["62101.00","0.028"],["62101.10","0.003"],["62101.50","0.003"],["62101.60","0.012"],["62101.80","0.046"],["62101.90","0.116"],["62102.00","0.001"],["62102.30","0.008"],["62102.40","0.061"],["62102.70","0.060"],["62103.30","0.009"],["62104.60","0.266"],["62104.70","0.750"],["62104.90","0.028"],["62105.00","0.151"],["62106.10","0.191"],["62106.50","0.026"],["62106.80","0.000"],["62107.20","0.219"],["62107.40","0.687"],["62107.70","0.352"],["62107.80","0.577"],["62108.00","0.958"],["62108.10","0.000"],["62108.40","0.011"],["62108.60","0.032"],["62108.70","0.011"],["62109.00","0.003"],["62109.40","0.000"],["62109.50","0.000"],["62109.60","0.293"],["62110.30","0.346"],["62110.60","0.686"],["62110.80","0.575"],["62111.80","0.331"],["62112.10","0.002"],["62112.40","0.000"],["62112.70","0.007"],["62113.30","0.015"],["62113.40","0.661"],["62113.50","0.665"],["62113.90","0.037"],["62114.30","0.037"],["62114.40","0.132"],["62114.80","0.101"],["62114.90","2.340"],["62115.00","0.291"],["62115.10","0.090"],["62115.40","0.001"],["62115.80","0.605"],["62115.90","0.012"],["62116.90","0.000"],["62117.00","0.328"],["62117.10","1.853"],["62117.50","1.200"],["62117.60","0.480"],["62117.70","1.343"],["62118.00","6.949"],["62118.10","0.768"],["62118.20","8.002"],["62118.30","0.018"],["62118.40","0.005"],["62118.50","0.000"],["62118.90","0.008"],["62119.80","0.323"],["62120.30","0.004"],["62120.40","0.400"],["62120.80","0.024"],["62120.90","0.000"],["62121.60","0.002"],["62122.10","0.004"],["62122.30","0.294"],["62124.20","0.002"],["62124.50","0.677"],["62125.80","0.048"],["62127.10","0.052"],["62128.10","0.718"],["62128.60","0.000"],["62128.70","0.001"],["62128.90","0.001"],["62129.70","0.000"],["62131.90","0.021"],["62132.70","0.089"],["62132.90","1.396"],["62133.00","1.505"],["62133.50","0.092"],["62133.80","0.002"],["62134.00","0.084"],["62134.20","0.230"],["62135.00","2.890"],["62135.90","0.110"],["62136.50","0.728"],["62136.80","0.726"],["62138.10","0.303"],["62139.90","0.071"],["62140.00","0.045"],["62140.10","0.015"],["62140.90","0.043"],["62142.50","0.153"],["62145.70","2.795"],["62146.40","0.830"],["62146.90","0.017"],["62147.60","0.000"],["62147.70","0.001"],["62149.80","0.300"],["62150.00","102.192"],["62150.70","0.023"],["62153.70","0.234"],["62155.60","0.673"],["62155.90","0.001"],["62156.50","0.092"],["62159.00","0.001"],["62160.00","0.563"],["62160.80","0.001"],["62161.40","1.478"],["62161.80","6.127"],["62176.10","0.003"],["62182.00","0.001"],["62186.30","0.887"],["62186.40","1.572"],["62186.80","0.030"],["62188.70","0.000"],["62190.40","0.000"],["62191.00","0.422"],["62192.30","0.001"],["62199.60","0.295"],["62201.50","0.281"],["62201.90","0.342"],["62216.50","0.097"],["62217.10","2.401"],["62217.40","0.002"],["62217.50","0.023"],["62219.20","2.995"],["62230.40","0.154"],["62233.50","0.001"],["62235.40","5.103"],["62235.60","1.581"],["62235.70","3.368"],["62236.20","0.000"],["62250.30","0.257"],["62250.40","43.372"],["62250.80","0.000"],["62271.10","1.684"],["62272.10","9.500"],["62272.50","0.027"],["62284.30","1.676"],["62299.40","1.337"],["62316.30","0.276"],["62316.40","0.679"],["62366.80","0.180"],["62367.10","0.643"],["62367.20","0.101"],["62383.70","0.003"],["62408.80","0.000"],["62415.70","0.008"],["62455.90","0.309"],["62491.30","0.251"],["62493.00","0.321"],["62493.10","0.003"],["62503.70","0.246"],["62634.90","0.000"],["62659.90","2.271"],["62669.40","0.000"],["62675.90","0.000"],["62676.30","0.008"],["62676.40","0.004"],["62677.50","1.580"],["62678.70","0.000"],["62767.60","0.006"],["62769.40","0.002"],["62771.10","13.244"],["62772.20","8.063"],["62829.70","0.000"],["62831.40","0.000"],["62833.10","6.308"],["62834.20","2.368"],["62889.80","2.382"],["62923.00","0.461"],["62925.40","0.000"],["62956.60","3.788"],["62984.50","0.792"],["63017.00","4.400"],["63298.00","0.003"],["67576.40","0.000"],["67576.70","0.000"],["67577.50","0.003"],["67577.60","0.000"],["67578.20","0.000"],["67579.00","0.006"],["67579.30","1.051"],["68259.70","0.000"],["89523.20","0.078"]],"b":[["11548.20","0.320"],["11755.20","0.240"],["11756.80","0.144"],["11758.00","0.064"],["11848.20","2.144"],["11955.20","0.112"],["11955.70","0.016"],["11956.80","0.064"],["11958.00","0.032"],["55849.60","0.000"],["55851.10","0.000"],["55852.20","0.002"],["56506.40","0.000"],["56535.30","0.589"],["58939.00","0.105"],["58953.90","0.000"],["59572.90","0.000"],["60815.70","0.003"],["61051.00","0.005"],["61052.10","0.004"],["61052.20","0.000"],["61055.20","0.276"],["61055.70","0.002"],["61058.00","0.018"],["61434.60","0.000"],["61435.10","0.000"],["61436.20","0.000"],["61437.40","0.000"],["61554.50","0.000"],["61561.40","0.369"],["61616.50","0.086"],["61623.50","0.030"],["61658.00","0.474"],["61685.40","0.254"],["61700.10","5.869"],["61737.50","0.012"],["61737.90","0.001"],["61738.00","0.989"],["61738.10","0.270"],["61802.70","0.036"],["61809.70","0.001"],["61823.50","0.171"],["61834.20","0.878"],["61847.20","0.002"],["61856.40","0.440"],["61863.90","0.032"],["61866.20","0.016"],["61867.00","0.018"],["61867.20","0.581"],["61869.80","0.677"],["61875.20","0.000"],["61887.30","1.362"],["61917.30","0.701"],["61917.50","0.781"],["61918.80","0.000"],["61925.70","0.000"],["61927.90","0.000"],["61928.20","1.655"],["61928.30","0.750"],["61929.40","0.000"],["61930.80","0.000"],["61931.50","0.125"],["61932.20","0.003"],["61935.90","0.031"],["61941.70","1.387"],["61943.10","0.020"],["61949.30","2.073"],["61950.20","0.008"],["61951.70","5.851"],["61952.50","2.170"],["61955.50","1.346"],["61955.70","0.000"],["61956.80","0.025"],["61957.20","0.002"],["61957.50","0.000"],["61963.10","16.971"],["61963.20","0.000"],["61963.70","3.279"],["61963.80","0.018"],["61965.00","0.022"],["61966.40","0.204"],["61966.90","0.021"],["61967.00","0.001"],["61967.90","3.926"],["61968.90","4.837"],["61969.00","1.444"],["61969.60","0.000"],["61970.60","0.026"],["61971.00","0.002"],["61971.50","0.813"],["61971.60","0.003"],["61972.80","0.000"],["61973.10","0.015"],["61975.10","1.226"],["61976.20","0.002"],["61976.80","1.819"],["61976.90","0.000"],["61977.20","0.000"],["61977.70","0.600"],["61978.00","0.000"],["61978.90","0.000"],["61979.70","0.181"],["61979.90","0.030"],["61981.60","0.002"],["61982.30","0.001"],["61983.70","19.204"],["61983.90","1.764"],["61984.30","3.917"],["61985.80","0.002"],["61986.30","0.003"],["61987.40","0.000"],["61988.20","0.000"],["61988.30","0.017"],["61989.10","0.048"],["61989.30","0.001"],["61989.90","0.002"],["61990.30","0.000"],["61990.80","0.106"],["61991.90","0.000"],["61992.00","0.118"],["61992.10","0.002"],["61992.20","0.634"],["61992.30","0.016"],["61992.40","0.000"],["61992.90","0.000"],["61994.30","0.100"],["61994.40","0.001"],["61995.00","0.025"],["61995.30","0.005"],["61995.70","0.001"],["61995.80","0.015"],["61996.30","0.101"],["61997.00","1.211"],["61997.40","0.285"],["61997.50","0.013"],["61998.00","0.349"],["61998.50","0.691"],["61998.80","0.004"],["61999.40","0.907"],["61999.70","0.210"],["62000.10","1.876"],["62000.30","0.458"],["62000.80","0.061"],["62001.70","0.000"],["62002.40","2.433"],["62002.50","0.831"],["62002.80","0.087"],["62002.90","0.448"],["62003.00","0.101"],["62003.10","0.085"],["62003.70","0.007"],["62003.80","0.245"],["62003.90","0.001"],["62004.00","0.001"],["62004.60","0.072"],["62005.10","0.000"],["62005.30","0.002"],["62005.50","0.001"],["62005.70","0.000"],["62005.90","0.010"],["62006.00","0.016"],["62006.20","0.016"],["62006.50","0.469"],["62006.60","0.004"],["62006.70","0.000"],["62006.90","0.708"],["62007.00","0.313"],["62007.10","0.158"],["62007.40","0.016"],["62007.50","0.001"],["62007.60","0.728"],["62007.80","0.000"],["62007.90","0.003"],["62008.00","0.062"],["62008.20","0.008"],["62008.30","0.001"],["62008.40","0.718"],["62008.50","0.000"],["62008.70","0.008"],["62009.10","0.037"],["62009.20","0.647"],["62009.30","0.029"],["62009.50","0.048"],["62009.60","0.008"],["62009.70","0.002"],["62009.80","0.692"],["62010.00","0.448"],["62010.10","0.064"],["62010.30","0.003"],["62010.70","0.004"],["62011.50","0.010"],["62011.80","0.060"],["62011.90","0.000"],["62012.00","0.001"],["62012.10","0.678"],["62012.20","0.001"],["62012.40","2.793"],["62012.60","1.954"],["62012.80","0.085"],["62012.90","0.470"],["62013.20","0.009"],["62013.40","0.000"],["62014.00","0.116"],["62015.20","1.423"],["62015.30","0.001"],["62016.00","0.005"],["62016.10","0.001"],["62016.40","0.019"],["62016.50","0.007"],["62016.60","0.002"],["62016.80","1.338"],["62017.70","0.125"],["62018.10","0.622"],["62018.20","0.000"],["62018.50","0.667"],["62018.90","0.312"],["62019.10","0.005"],["62019.20","0.017"],["62019.30","0.051"],["62019.50","0.026"],["62019.70","0.001"],["62019.90","0.009"],["62020.00","0.931"],["62020.10","0.040"],["62020.20","0.751"],["62020.30","0.003"],["62020.40","0.976"],["62020.50","0.020"],["62020.80","0.006"],["62021.30","0.002"],["62021.60","0.900"],["62022.00","0.001"],["62022.30","0.001"],["62022.80","0.001"],["62022.90","0.090"],["62023.00","0.255"],["62023.10","0.001"],["62023.20","0.530"],["62023.30","0.001"],["62023.40","0.082"],["62023.50","2.007"],["62024.30","0.001"],["62024.50","1.332"],["62024.70","0.416"],["62024.90","0.004"],["62025.10","0.003"],["62025.40","0.003"],["62025.50","0.003"],["62025.70","0.002"],["62025.80","0.326"],["62026.00","0.754"],["62026.20","0.002"],["62026.30","0.012"],["62026.40","0.172"],["62026.50","0.517"],["62026.70","0.002"],["62026.90","0.050"],["62027.00","0.003"],["62027.10","0.009"],["62027.20","0.053"],["62027.40","0.052"],["62027.50","0.004"],["62027.60","0.002"],["62028.10","1.312"],["62028.30","0.130"],["62028.80","0.351"],["62028.90","0.001"],["62029.00","0.040"],["62029.30","0.044"],["62029.50","0.121"],["62029.60","0.013"],["62029.70","0.000"],["62029.90","1.211"],["62030.30","0.003"],["62030.60","0.282"],["62030.70","0.000"],["62030.90","1.363"],["62031.00","0.011"],["62031.10","0.005"],["62031.20","0.297"],["62031.40","0.123"],["62031.60","0.049"],["62032.30","0.011"],["62032.50","0.063"],["62032.80","0.001"],["62033.00","0.001"],["62033.10","0.003"],["62033.30","0.003"],["62033.40","0.170"],["62033.50","0.006"],["62033.80","0.023"],["62033.90","0.340"],["62034.00","1.208"],["62034.10","0.006"],["62034.20","0.003"],["62034.80","0.000"],["62035.50","1.625"],["62035.60","0.060"],["62035.80","0.023"],["62036.10","2.204"],["62036.20","0.167"],["62036.30","1.816"],["62036.40","0.661"],["62036.50","0.002"],["62036.60","0.352"],["62036.70","1.560"],["62036.80","0.983"],["62036.90","0.254"],["62037.00","0.226"],["62037.30","0.050"],["62037.70","0.004"],["62037.90","0.003"],["62038.00","0.013"],["62038.10","0.384"],["62038.20","0.732"],["62038.40","0.306"],["62038.60","0.002"],["62038.90","0.022"],["62039.20","0.051"],["62039.30","0.005"],["62039.40","0.001"],["62039.70","1.513"],["62039.80","0.743"],["62039.90","0.045"],["62040.00","0.006"],["62040.10","0.002"],["62040.20","0.001"],["62040.60","0.065"],["62040.80","0.001"],["62041.00","0.885"],["62041.10","0.567"],["62041.20","0.574"],["62041.30","0.158"],["62041.40","0.020"],["62041.50","0.322"],["62041.80","0.007"],["62041.90","0.060"],["62042.10","0.443"],["62042.50","0.355"],["62042.60","1.055"],["62042.70","0.003"],["62042.80","0.126"],["62042.90","0.006"],["62043.00","0.785"],["62043.10","0.002"],["62043.20","0.003"],["62043.30","0.004"],["62043.90","0.084"],["62044.00","0.208"],["62044.20","0.040"],["62044.30","0.002"],["62044.70","0.002"],["62044.80","1.482"],["62044.90","0.083"],["62045.10","0.032"],["62045.20","1.569"],["62045.30","0.000"],["62045.60","0.156"],["62045.70","0.253"],["62045.90","0.233"],["62046.00","0.002"],["62046.10","0.000"],["62046.30","0.858"],["62046.40","0.008"],["62046.50","0.358"],["62046.60","0.000"],["62046.70","0.025"],["62046.80","0.040"],["62047.20","0.006"],["62047.30","1.363"],["62047.40","1.375"],["62047.50","0.508"],["62047.60","0.300"],["62048.00","0.015"],["62048.10","0.055"],["62048.20","0.031"],["62048.30","0.003"],["62048.40","0.033"],["62048.70","0.001"],["62048.90","0.126"],["62049.00","0.000"],["62049.20","0.000"],["62049.30","0.000"],["62049.40","0.021"],["62049.50","0.501"],["62049.80","0.233"],["62049.90","0.010"],["62050.20","0.004"],["62050.60","0.001"],["62050.70","0.325"],["62050.80","0.042"],["62051.20","0.001"],["62051.30","0.001"],["62051.40","0.000"],["62051.60","0.003"],["62051.70","0.000"],["62051.80","0.263"],["62052.10","0.035"],["62052.30","0.001"],["62052.40","0.224"],["62052.60","0.000"],["62052.80","0.000"],["62053.10","0.052"],["62053.60","0.284"],["62053.70","0.008"],["62054.00","0.001"],["62054.20","0.179"],["62054.30","0.004"],["62054.40","0.002"],["62054.70","0.001"],["62054.90","0.001"],["62055.00","0.327"],["62055.10","0.004"],["62055.20","0.006"],["62055.30","1.803"],["62055.40","0.441"],["62055.50","0.000"],["62055.60","0.080"],["62055.70","0.343"],["62055.80","1.803"],["62055.90","0.001"],["62056.00","0.000"],["62056.10","0.001"],["62056.20","0.004"],["62056.30","0.000"],["62056.40","0.000"],["62056.50","0.001"],["62056.60","0.000"],["62056.70","0.003"],["62056.80","0.086"],["62056.90","2.124"],["62057.00","0.000"],["62057.10","0.001"],["62057.30","0.000"],["62057.50","0.000"],["62057.60","0.000"],["62057.70","0.000"],["62057.80","0.000"],["62057.90","0.024"],["62058.00","14.627"]],"e":"depthUpdate","ps":"BTCUSDT","pu":10998400449791,"s":"BTCUSDT","st":1,"u":10998400482139}
{"E":1783504324898,"T":1783504324897,"U":10998400482442,"a":[["62058.10","4.860"],["62059.70","0.207"],["62061.00","0.004"],["62061.10","0.012"],["62061.60","0.001"],["62061.70","0.002"],["62062.10","0.000"],["62062.20","0.005"],["62062.30","0.903"],["62062.40","1.145"],["62062.50","0.023"],["62063.20","0.164"],["62063.30","0.431"],["62063.50","0.096"],["62063.90","0.514"],["62064.20","0.071"],["62064.60","0.000"],["62064.80","0.417"],["62065.00","0.052"],["62065.10","1.663"],["62065.20","1.364"],["62065.30","0.102"],["62065.40","0.790"],["62065.60","0.002"],["62065.80","0.120"],["62065.90","0.006"],["62066.50","0.001"],["62066.60","0.280"],["62067.20","0.004"],["62068.50","0.009"],["62069.40","0.000"],["62069.70","0.244"],["62069.80","0.164"],["62070.80","0.000"],["62070.90","1.380"],["62071.10","0.002"],["62071.60","0.354"],["62071.80","0.333"],["62071.90","0.630"],["62073.50","0.173"],["62074.60","0.001"],["62074.70","0.406"],["62074.90","0.165"],["62075.40","0.889"],["62076.20","0.294"],["62076.70","0.580"],["62077.80","3.178"],["62078.90","0.005"],["62081.30","0.944"],["62083.30","0.245"],["62083.60","1.316"],["62084.20","0.002"],["62085.30","0.040"],["62085.40","0.002"],["62085.70","0.002"],["62085.80","0.731"],["62086.40","0.001"],["62086.50","0.017"],["62087.50","0.001"],["62087.70","0.253"],["62088.00","0.289"],["62088.30","0.003"],["62089.70","0.879"],["62089.80","2.867"],["62090.20","0.052"],["62091.10","0.022"],["62092.00","0.017"],["62092.60","0.000"],["62093.30","0.306"],["62094.40","0.660"],["62095.00","0.302"],["62095.30","0.014"],["62095.60","0.027"],["62095.70","0.002"],["62096.20","0.001"],["62096.40","3.553"],["62098.80","0.000"],["62099.40","0.999"],["62099.50","1.385"],["62099.60","1.486"],["62100.60","0.082"],["62100.90","0.001"],["62102.60","0.025"],["62104.50","0.457"],["62108.20","1.953"],["62108.50","4.516"],["62110.00","3.569"],["62111.20","0.058"],["62111.90","0.000"],["62112.30","0.150"],["62112.50","0.161"],["62112.70","0.003"],["62113.30","0.003"],["62113.90","0.012"],["62114.00","0.103"],["62114.50","0.688"],["62114.60","0.116"],["62114.80","0.105"],["62115.60","0.027"],["62117.40","0.051"],["62117.70","1.355"],["62117.80","0.132"],["62118.10","0.667"],["62122.20","0.748"],["62124.10","0.154"],["62124.50","0.700"],["62134.20","0.332"],["62135.00","0.138"],["62135.70","0.090"],["62135.90","0.000"],["62136.30","0.076"],["62136.90","0.071"],["62138.40","0.000"],["62143.70","1.604"],["62143.80","6.595"],["62143.90","0.000"],["62145.80","4.846"],["62146.40","0.805"],["62146.70","0.125"],["62149.80","0.292"],["62151.00","0.001"],["62151.10","1.535"],["62154.60","0.008"],["62160.30","0.017"],["62162.80","0.040"],["62171.90","0.003"],["62172.00","1.530"],["62174.30","0.103"],["62181.10","0.001"],["62183.10","0.016"],["62186.80","0.031"],["62192.70","0.023"],["62192.80","1.559"],["62197.80","0.003"],["62199.90","0.050"],["62210.70","0.075"],["62252.30","0.296"],["62274.00","0.218"],["62316.30","0.440"],["62319.20","1.337"],["62644.10","0.022"],["62666.90","0.000"],["62675.70","0.797"],["62678.70","0.000"],["62770.50","0.000"],["62771.10","0.000"],["62772.20","21.307"],["62798.40","1.185"],["62802.60","1.814"],["62833.10","0.004"],["62834.20","8.672"],["62931.70","3.682"],["62988.70","0.000"],["63019.80","1.100"],["64600.00","20.470"],["65400.00","19.678"],["67579.30","0.445"],["67579.40","0.000"],["67579.70","0.000"],["67579.80","0.594"]],"b":[["1000.00","210.542"],["11548.20","0.176"],["11758.00","0.336"],["11848.20","1.872"],["11958.00","0.176"],["55852.20","0.002"],["58955.10","0.017"],["61155.30","7.906"],["61183.60","2.428"],["61279.30","5.401"],["61307.70","1.616"],["61437.40","0.000"],["61495.20","0.000"],["61793.10","0.683"],["61847.20","0.003"],["61859.70","0.032"],["61859.80","1.539"],["61859.90","0.584"],["61877.50","0.009"],["61885.20","0.001"],["61886.40","0.000"],["61889.40","0.001"],["61902.70","0.000"],["61904.30","0.000"],["61906.00","0.193"],["61907.40","0.000"],["61914.60","0.000"],["61924.60","0.000"],["61943.30","0.879"],["61943.80","0.029"],["61950.10","0.027"],["61957.10","0.014"],["61957.80","0.000"],["61963.60","6.334"],["61963.70","3.228"],["61963.80","0.069"],["61963.90","0.049"],["61964.00","0.824"],["61964.20","0.033"],["61967.80","0.000"],["61978.10","0.108"],["61978.20","0.026"],["61978.40","1.542"],["61978.90","0.242"],["61979.30","0.249"],["61980.80","0.222"],["61981.40","0.003"],["61982.90","0.000"],["61983.70","0.015"],["61983.80","0.173"],["61984.30","1.147"],["61984.40","0.000"],["61984.50","1.534"],["61985.30","0.052"],["61993.80","0.005"],["61995.80","0.000"],["61996.70","0.002"],["61998.40","23.719"],["61998.70","5.147"],["61999.70","0.000"],["61999.80","0.008"],["62000.00","9.035"],["62000.20","1.239"],["62000.30","0.454"],["62002.10","0.759"],["62002.40","2.437"],["62002.90","0.436"],["62003.00","0.139"],["62005.20","0.568"],["62005.30","1.531"],["62006.00","0.004"],["62006.60","0.214"],["62007.60","0.726"],["62008.40","0.719"],["62008.70","0.023"],["62009.00","0.046"],["62009.10","0.003"],["62009.20","0.637"],["62009.90","1.362"],["62010.00","0.446"],["62010.10","0.066"],["62010.40","0.006"],["62010.50","0.002"],["62010.90","0.013"],["62011.50","0.009"],["62011.70","0.001"],["62012.00","0.000"],["62012.10","0.653"],["62014.60","0.318"],["62015.20","1.363"],["62016.50","0.034"],["62017.00","0.680"],["62019.30","0.061"],["62020.60","0.004"],["62020.80","0.054"],["62021.20","0.025"],["62022.20","0.060"],["62023.90","0.044"],["62025.40","0.002"],["62026.00","0.756"],["62027.00","0.027"],["62030.10","0.052"],["62031.60","0.041"],["62032.50","2.064"],["62033.20","0.107"],["62034.00","1.529"],["62034.40","0.035"],["62035.50","1.565"],["62036.10","2.144"],["62036.20","0.047"],["62037.00","0.194"],["62037.40","0.001"],["62039.30","1.379"],["62039.50","0.407"],["62041.10","0.569"],["62041.80","0.733"],["62042.50","0.356"],["62042.60","1.020"],["62043.00","0.060"],["62044.40","0.124"],["62044.80","1.418"],["62045.00","0.062"],["62045.10","0.092"],["62045.60","0.190"],["62045.70","0.261"],["62045.90","0.234"],["62046.20","0.405"],["62046.40","0.004"],["62046.70","0.002"],["62046.80","0.072"],["62047.00","0.000"],["62047.20","0.002"],["62047.30","1.363"],["62047.60","0.292"],["62048.10","0.057"],["62048.50","0.002"],["62049.50","0.565"],["62050.50","0.024"],["62051.00","0.043"],["62051.10","0.001"],["62051.70","0.001"],["62051.80","0.267"],["62052.10","0.188"],["62053.60","0.279"],["62053.70","0.050"],["62054.00","0.002"],["62054.10","0.001"],["62054.90","0.012"],["62055.10","0.008"],["62055.70","0.343"],["62055.90","0.005"],["62056.70","0.001"],["62056.80","0.088"],["62057.20","0.002"],["62057.70","0.000"],["62057.90","0.022"],["62058.00","14.164"]],"e":"depthUpdate","ps":"BTCUSDT","pu":10998400482139,"s":"BTCUSDT","st":1,"u":10998400495527}
{"E":1783504325000,"T":1783504324997,"U":10998400495635,"a":[["62061.00","0.002"],["62062.20","0.567"],["62062.30","0.339"],["62063.50","0.094"],["62064.20","0.173"],["62064.30","0.322"],["62064.40","0.829"],["62064.70","0.012"],["62064.80","0.233"],["62065.00","0.344"],["62065.30","0.342"],["62065.50","0.457"],["62065.90","0.004"],["62067.20","0.002"],["62067.30","0.885"],["62068.40","0.002"],["62069.10","0.633"],["62069.70","0.242"],["62069.80","0.164"],["62070.60","0.007"],["62071.80","0.011"],["62075.60","1.379"],["62076.80","0.162"],["62076.90","0.332"],["62077.20","1.375"],["62078.40","0.074"],["62081.30","0.864"],["62084.80","1.416"],["62088.30","0.001"],["62096.80","0.002"],["62097.40","0.196"],["62098.00","0.001"],["62098.60","0.009"],["62104.90","0.003"],["62112.30","0.360"],["62117.10","1.854"],["62117.60","0.581"],["62117.80","0.031"],["62117.90","0.001"],["62118.00","6.848"],["62119.20","12.972"],["62133.00","1.607"],["62133.50","0.002"],["62133.70","0.139"],["62134.10","0.572"],["62134.30","0.243"],["62142.50","0.177"],["62145.40","0.004"],["62154.50","0.020"],["62217.00","0.812"],["62415.70","0.000"],["62418.70","0.017"],["62676.30","0.000"],["62678.70","0.000"],["62679.30","0.009"],["62852.30","0.012"],["63051.10","0.707"],["89523.20","0.084"]],"b":[["1000.00","210.542"],["11548.20","0.048"],["11758.00","0.608"],["11848.20","1.600"],["11958.00","0.304"],["49646.40","0.000"],["55852.20","0.002"],["58952.40","0.003"],["58955.10","0.017"],["59575.60","0.013"],["61154.70","6.205"],["61155.30","5.456"],["61186.40","4.856"],["61279.50","0.003"],["61310.70","9.869"],["61437.40","0.000"],["61706.80","0.010"],["61744.80","0.002"],["61795.60","0.000"],["61797.60","0.208"],["61799.20","0.077"],["61847.20","0.002"],["61958.80","0.000"],["61966.10","0.040"],["61982.70","0.001"],["61985.70","19.201"],["61986.00","0.063"],["61986.60","3.573"],["61988.90","1.346"],["61990.20","0.002"],["61994.60","0.472"],["61995.30","0.003"],["61995.60","0.262"],["61998.40","4.530"],["61998.70","1.899"],["62009.60","0.007"],["62010.10","0.064"],["62011.10","0.005"],["62012.60","1.953"],["62013.00","0.001"],["62013.60","0.678"],["62013.80","1.289"],["62014.20","0.009"],["62016.30","0.973"],["62017.50","0.000"],["62018.80","1.414"],["62020.00","0.929"],["62020.20","0.681"],["62020.70","9.350"],["62021.30","0.000"],["62021.60","2.195"],["62022.50","0.003"],["62023.80","0.001"],["62025.00","0.005"],["62027.40","0.122"],["62035.50","1.567"],["62035.60","0.000"],["62036.60","0.292"],["62036.80","0.981"],["62036.90","0.134"],["62037.00","0.894"],["62037.50","0.001"],["62038.10","0.324"],["62039.90","0.013"],["62040.50","0.032"],["62044.90","0.085"],["62045.00","0.122"],["62045.10","0.152"],["62045.20","1.629"],["62045.60","0.250"],["62046.30","0.919"],["62046.40","0.371"],["62047.50","0.509"],["62048.20","0.028"],["62049.60","0.002"],["62054.40","0.003"],["62055.20","0.001"],["62058.00","14.166"]],"e":"depthUpdate","ps":"BTCUSDT","pu":10998400495527,"s":"BTCUSDT","st":1,"u":10998400504924}
{"E":1783504325102,"T":1783504325101,"U":10998400505346,"a":[["62059.50","0.009"],["62059.70","0.206"],["62060.60","0.055"],["62060.90","0.000"],["62062.20","0.003"],["62062.40","0.792"],["62062.50","0.000"],["62063.20","0.187"],["62063.80","0.567"],["62064.20","0.237"],["62064.40","0.825"],["62064.70","0.102"],["62064.80","0.169"],["62069.60","0.003"],["62070.10","1.128"],["62070.50","0.257"],["62070.60","0.003"],["62071.90","0.066"],["62072.00","1.978"],["62072.20","0.345"],["62072.50","0.778"],["62073.10","0.364"],["62074.10","0.031"],["62075.60","1.363"],["62076.80","0.159"],["62079.10","0.004"],["62079.90","0.080"],["62080.00","1.104"],["62085.50","0.658"],["62089.60","0.210"],["62089.80","2.673"],["62092.80","0.150"],["62098.60","0.008"],["62105.00","0.154"],["62110.30","0.345"],["62114.90","2.431"],["62115.10","0.006"],["62117.70","1.367"],["62120.20","0.001"],["62122.10","0.000"],["62124.80","1.221"],["62126.70","0.077"],["62127.00","4.092"],["62134.20","0.224"],["62136.30","0.009"],["62151.10","0.007"],["62151.20","1.528"],["62152.10","0.000"],["62159.70","0.005"],["62162.60","0.028"],["62168.50","2.077"],["62168.60","7.487"],["62169.20","0.004"],["62192.80","0.031"],["62192.90","1.528"],["62226.40","0.000"],["62229.40","0.006"],["62368.40","0.002"],["62678.70","0.000"],["62878.70","0.794"],["63003.90","0.000"]],"b":[["11548.20","0.000"],["11758.00","0.880"],["11848.20","1.328"],["11858.00","0.096"],["11958.00","0.256"],["52000.00","155.386"],["52459.30","0.006"],["52922.70","0.006"],["53390.20","0.006"],["53861.80","0.006"],["54337.50","0.008"],["54817.50","0.006"],["55301.70","0.006"],["55790.20","0.006"],["55852.20","0.002"],["56283.10","0.006"],["56780.20","0.006"],["57281.80","0.006"],["57787.80","0.006"],["58298.20","0.006"],["58813.20","0.021"],["58955.10","0.017"],["59332.70","0.007"],["59575.60","0.010"],["59856.80","0.009"],["60385.60","0.006"],["60475.40","0.000"],["60919.00","0.006"],["61061.70","1.213"],["61080.10","0.018"],["61093.50","0.973"],["61155.00","6.793"],["61186.60","2.427"],["61207.30","3.194"],["61279.00","3.316"],["61279.30","3.772"],["61310.70","13.099"],["61437.40","0.000"],["61444.20","6.689"],["61457.10","0.095"],["61489.80","0.973"],["61549.70","0.000"],["61737.90","0.000"],["61738.00","0.979"],["61744.90","0.001"],["61827.00","0.002"],["61847.20","0.003"],["61859.80","0.003"],["61859.90","1.538"],["61860.00","0.795"],["61947.20","0.705"],["61950.20","0.011"],["61962.20","0.217"],["61962.50","6.867"],["61962.60","1.728"],["61978.90","0.000"],["61984.50","0.004"],["61984.60","1.539"],["61985.70","0.012"],["61986.20","0.003"],["61986.60","0.612"],["61990.00","19.198"],["61990.20","0.000"],["61990.70","3.510"],["61990.80","0.108"],["61990.90","0.245"],["61995.90","0.001"],["61996.70","0.005"],["62004.10","4.103"],["62005.30","0.002"],["62005.40","1.529"],["62006.10","1.710"],["62012.80","0.145"],["62014.80","0.000"],["62015.20","1.362"],["62020.70","9.410"],["62037.00","0.834"],["62039.00","0.121"],["62040.50","0.000"],["62041.20","1.179"],["62041.80","0.007"],["62042.10","0.383"],["62045.00","0.182"],["62045.30","0.120"],["62045.60","0.370"],["62045.70","0.321"],["62046.20","0.465"],["62051.70","0.002"],["62054.40","0.002"],["62055.70","0.279"],["62058.00","14.165"]],"e":"depthUpdate","ps":"BTCUSDT","pu":10998400504924,"s":"BTCUSDT","st":1,"u":10998400517704}
{"E":1783504325204,"T":1783504325203,"U":10998400517899,"a":[["62059.60","0.029"],["62059.70","0.089"],["62059.80","0.001"],["62060.80","0.002"],["62062.20","0.004"],["62062.30","0.688"],["62062.40","1.095"],["62062.90","0.091"],["62063.00","0.150"],["62063.10","0.424"],["62063.60","0.188"],["62063.80","0.193"],["62064.10","0.863"],["62067.90","0.263"],["62068.70","0.165"],["62069.70","0.001"],["62070.10","0.564"],["62070.80","0.000"],["62071.90","0.630"],["62072.50","0.053"],["62073.20","0.725"],["62073.50","0.174"],["62073.70","0.015"],["62074.10","0.015"],["62075.00","0.017"],["62076.80","0.079"],["62077.20","1.295"],["62077.80","3.194"],["62078.70","0.444"],["62079.60","0.438"],["62080.50","0.757"],["62080.90","0.005"],["62081.80","0.154"],["62086.40","0.002"],["62089.60","0.105"],["62089.70","0.774"],["62095.20","0.036"],["62096.10","0.000"],["62106.10","0.193"],["62107.70","0.353"],["62108.70","1.447"],["62109.90","2.284"],["62110.10","3.506"],["62111.10","0.002"],["62114.90","2.341"],["62116.00","0.101"],["62117.60","0.480"],["62118.00","6.875"],["62118.30","0.003"],["62119.00","0.003"],["62120.50","1.380"],["62120.60","0.025"],["62125.60","0.029"],["62127.20","0.011"],["62128.50","0.021"],["62133.00","1.505"],["62133.70","0.031"],["62134.00","0.000"],["62134.10","0.476"],["62134.20","0.122"],["62134.30","0.271"],["62135.70","0.000"],["62136.90","0.013"],["62137.20","0.009"],["62158.30","0.875"],["62168.30","0.011"],["62187.90","0.027"],["62190.30","0.029"],["62191.90","0.052"],["62200.00","12.056"],["62200.10","0.142"],["62213.30","0.070"],["62324.60","2.247"],["62538.30","4.629"],["62616.60","1.282"],["62678.70","0.000"],["62724.30","0.000"],["62910.30","0.000"],["67579.80","0.000"],["67580.00","0.598"],["89523.20","0.090"]],"b":[["1000.00","210.542"],["11758.00","1.152"],["11848.20","1.056"],["11858.00","0.224"],["11958.00","0.128"],["55852.20","0.002"],["58955.10","0.037"],["59575.60","0.013"],["60803.10","0.005"],["61095.90","0.016"],["61154.70","4.899"],["61155.10","0.000"],["61186.60","4.854"],["61198.90","0.815"],["61221.50","0.000"],["61278.70","1.793"],["61310.70","14.714"],["61437.40","0.000"],["61444.20","5.964"],["61735.90","0.001"],["61847.20","0.002"],["61938.20","0.678"],["61948.00","0.018"],["61969.20","0.101"],["61979.00","0.002"],["61986.80","0.016"],["62000.30","0.452"],["62001.30","0.001"],["62008.70","0.008"],["62010.10","0.002"],["62011.50","0.073"],["62017.90","0.062"],["62019.60","0.015"],["62019.80","0.008"],["62022.50","0.001"],["62023.50","1.307"],["62033.20","0.105"],["62038.50","0.702"],["62040.60","0.005"],["62041.00","0.898"],["62041.10","0.005"],["62042.10","0.323"],["62042.40","0.626"],["62042.50","0.296"],["62043.00","0.000"],["62043.80","0.063"],["62048.20","0.011"],["62051.00","0.042"],["62052.80","0.001"],["62053.60","0.281"],["62054.20","0.171"],["62055.40","0.442"],["62057.20","0.000"],["62057.50","0.002"],["62057.60","0.002"],["62058.00","14.131"]],"e":"depthUpdate","ps":"BTCUSDT","pu":10998400517704,"s":"BTCUSDT","st":1,"u":10998400528337}
{"E":1783504325306,"T":1783504325305,"U":10998400528370,"a":[["62061.80","0.004"],["62064.70","0.098"],["62068.50","0.007"],["62069.80","0.162"],["62073.20","0.000"],["62073.90","0.725"],["62076.90","0.333"],["62077.20","1.375"],["62078.70","0.364"],["62081.80","0.091"],["62082.20","0.007"],["62083.80","0.458"],["62087.20","0.002"],["62089.60","0.106"],["62094.00","1.758"],["62094.30","0.019"],["62100.00","0.745"],["62116.00","0.000"],["62118.30","0.001"],["62118.90","0.027"],["62121.40","0.020"],["62121.50","0.017"],["62123.20","0.012"],["62134.30","0.181"],["62136.50","0.670"],["62187.70","0.023"],["62355.60","0.152"],["62541.90","0.163"],["62678.20","0.002"],["62678.70","0.000"],["62728.20","0.150"],["62822.30","0.000"],["62914.50","0.150"],["63020.30","0.448"],["63024.80","14.898"],["63096.30","0.003"]],"b":[["1000.00","210.742"],["11758.00","1.424"],["11848.20","0.784"],["11858.00","0.368"],["11956.80","0.048"],["11958.00","0.000"],["49637.00","0.000"],["55852.20","0.002"],["58955.10","0.020"],["59575.60","0.010"],["61126.70","1.019"],["61154.80","2.646"],["61186.60","7.281"],["61437.40","0.000"],["61458.70","0.811"],["61736.00","0.309"],["61847.20","0.003"],["61871.90","0.018"],["61955.90","0.101"],["61987.80","0.279"],["61999.40","0.000"],["62009.10","0.064"],["62011.50","0.009"],["62012.40","2.808"],["62012.70","0.878"],["62017.20","0.089"],["62018.90","0.314"],["62019.60","0.000"],["62025.10","0.001"],["62035.80","0.003"],["62041.20","0.453"],["62041.60","0.021"],["62041.90","0.000"],["62042.40","0.566"],["62042.50","0.294"],["62042.60","1.746"],["62043.10","0.000"],["62043.70","0.001"],["62045.00","0.184"],["62052.70","0.002"],["62054.00","0.597"],["62055.60","0.000"],["62056.20","0.006"],["62056.80","0.087"],["62058.00","14.132"]],"e":"depthUpdate","ps":"BTCUSDT","pu":10998400528337,"s":"BTCUSDT","st":1,"u":10998400538390}
{"E":1783504325408,"T":1783504325405,"U":10998400538518,"a":[["62058.10","4.864"],["62062.30","0.771"],["62065.10","1.543"],["62067.90","0.022"],["62068.40","0.243"],["62069.80","0.324"],["62071.80","0.173"],["62072.10","2.273"],["62074.30","0.085"],["62075.30","0.163"],["62077.20","1.295"],["62077.70","0.213"],["62077.80","3.178"],["62080.10","0.001"],["62080.50","0.918"],["62081.50","0.009"],["62081.90","0.108"],["62082.70","0.017"],["62086.70","0.330"],["62089.00","0.194"],["62089.60","0.017"],["62089.70","0.685"],["62111.10","0.002"],["62125.70","0.000"],["62131.90","0.005"],["62133.00","1.403"],["62134.10","0.332"],["62134.70","0.018"],["62138.10","0.287"],["62140.90","0.059"],["62147.10","0.017"],["62678.70","0.000"],["62899.80","25.208"],["89523.20","0.096"]],"b":[["11758.00","1.696"],["11848.20","0.512"],["11858.00","0.496"],["11955.20","0.048"],["11955.70","0.000"],["11956.80","0.000"],["55852.20","0.002"],["58955.10","0.020"],["59500.00","56.018"],["60816.90","0.003"],["61154.80","0.196"],["61189.20","2.435"],["61421.40","0.001"],["61437.40","0.000"],["61456.00","1.273"],["61458.70","1.541"],["61551.80","0.325"],["61744.90","0.011"],["61847.20","0.003"],["61921.10","0.000"],["61955.90","0.468"],["61981.50","0.022"],["62000.00","8.935"],["62004.90","0.001"],["62012.40","2.793"],["62012.80","0.144"],["62014.20","0.024"],["62029.70","0.322"],["62030.20","0.303"],["62034.10","0.067"],["62034.70","0.011"],["62035.10","0.416"],["62035.50","1.565"],["62035.90","0.211"],["62036.30","1.806"],["62038.00","0.003"],["62038.90","0.002"],["62042.10","0.404"],["62044.10","0.013"],["62044.30","0.566"],["62045.20","1.065"],["62045.70","0.313"],["62047.20","0.022"],["62049.60","0.003"],["62052.10","0.187"],["62058.00","14.134"]],"e":"depthUpdate","ps":"BTCUSDT","pu":10998400538390,"s":"BTCUSDT","st":1,"u":10998400547684}
{"E":1783504325510,"T":1783504325509,"U":10998400548018,"a":[["62069.10","0.003"],["62071.90","0.066"],["62072.70","0.564"],["62073.90","0.000"],["62074.50","0.765"],["62076.90","0.349"],["62077.00","0.137"],["62078.50","0.131"],["62079.00","0.703"],["62080.50","0.218"],["62081.90","0.028"],["62082.70","0.001"],["62089.70","0.774"],["62091.20","0.002"],["62111.10","0.002"],["62115.80","0.706"],["62146.10","0.192"],["62162.50","0.001"],["62175.50","0.256"],["62678.70","0.000"],["63220.90","0.000"],["67580.00","0.002"],["67580.10","0.596"]],"b":[["1000.00","210.742"],["11658.00","0.112"],["11758.00","1.744"],["11848.20","0.352"],["11858.00","0.640"],["11952.10","0.048"],["11953.60","0.000"],["11954.20","0.000"],["11955.20","0.000"],["55852.20","0.002"],["58955.10","0.020"],["59575.60","0.013"],["61155.00","4.365"],["61179.50","2.124"],["61186.90","2.427"],["61210.50","0.759"],["61241.60","0.979"],["61437.40","0.000"],["61744.20","0.000"],["61744.90","2.436"],["61745.00","0.530"],["61847.20","0.002"],["62018.40","0.061"],["62020.00","0.931"],["62043.70","0.003"],["62048.10","0.054"],["62049.40","0.024"]],"e":"depthUpdate","ps":"BTCUSDT","pu":10998400547684,"s":"BTCUSDT","st":1,"u":10998400557494}
{"E":1783504325612,"T":1783504325611,"U":10998400557621,"a":[["62058.10","5.525"],["62061.40","0.016"],["62062.30","0.106"],["62062.40","1.012"],["62062.70","0.006"],["62062.80","0.098"],["62063.00","0.092"],["62063.10","0.323"],["62063.30","0.221"],["62063.40","0.001"],["62063.60","0.002"],["62063.80","0.656"],["62063.90","0.406"],["62064.10","0.695"],["62065.10","1.623"],["62067.50","0.492"],["62067.90","0.002"],["62068.20","1.222"],["62069.80","0.162"],["62070.90","1.360"],["62071.80","0.011"],["62071.90","0.066"],["62072.10","2.293"],["62072.30","0.084"],["62074.30","0.004"],["62074.50","0.040"],["62074.60","0.726"],["62075.00","0.007"],["62075.30","0.001"],["62076.40","0.053"],["62076.70","0.000"],["62076.90","0.333"],["62077.00","0.057"],["62077.70","0.051"],["62078.50","0.124"],["62078.60","0.583"],["62081.30","0.928"],["62083.80","0.399"],["62085.50","0.717"],["62087.00","0.424"],["62088.90","1.025"],["62090.20","0.055"],["62091.10","0.032"],["62094.00","0.851"],["62096.50","4.502"],["62100.60","3.236"],["62107.20","0.056"],["62109.60","0.130"],["62109.90","2.363"],["62110.00","0.415"],["62111.70","0.139"],["62113.00","0.022"],["62114.90","2.419"],["62115.40","0.102"],["62115.80","0.706"],["62116.00","0.000"],["62125.20","0.078"],["62127.40","0.003"],["62133.50","0.092"],["62160.50","0.673"],["62176.60","0.001"],["62180.00","1.290"],["62189.00","0.002"],["62189.10","2.910"],["62217.60","2.025"],["62480.00","0.810"],["62678.70","0.000"],["62784.50","0.000"],["63284.80","0.015"],["63361.30","0.317"],["89523.20","0.102"]],"b":[["1000.00","210.742"],["11658.00","0.256"],["11758.00","1.728"],["11848.20","0.224"],["11858.00","0.768"],["11948.20","0.832"],["11949.80","0.000"],["11951.00","0.000"],["11952.10","0.000"],["34000.00","13.622"],["55852.20","0.002"],["58955.10","0.023"],["59575.60","0.010"],["61005.80","0.633"],["61123.80","0.011"],["61149.60","3.955"],["61154.70","2.450"],["61158.20","1.133"],["61186.40","7.283"],["61189.20","4.862"],["61255.00","6.033"],["61276.40","0.411"],["61278.80","1.636"],["61279.00","1.700"],["61309.80","1.001"],["61310.50","1.616"],["61311.00","1.621"],["61344.30","0.968"],["61437.40","0.000"],["61738.00","0.972"],["61788.40","0.000"],["61793.10","0.000"],["61794.40","0.339"],["61847.20","0.003"],["61881.30","0.156"],["61899.20","3.530"],["61930.20","1.706"],["61931.20","0.000"],["61931.50","1.207"],["61977.60","0.001"],["61978.50","0.006"],["61983.70","19.204"],["61984.30","3.940"],["61988.20","0.016"],["61990.00","0.009"],["61990.70","0.764"],["61990.80","0.108"],["61994.40","0.017"],["61995.90","0.081"],["62003.70","0.023"],["62005.30","0.158"],["62014.40","0.016"],["62016.10","0.017"],["62028.50","0.891"],["62029.70","0.000"],["62031.60","0.057"],["62035.90","0.050"],["62036.90","0.002"],["62037.00","0.702"],["62040.90","1.311"],["62041.30","0.126"],["62042.10","0.323"],["62042.40","0.002"],["62042.60","1.020"],["62042.70","0.135"],["62043.50","0.727"],["62043.60","0.689"],["62045.20","1.065"],["62045.30","0.128"],["62047.70","0.132"],["62048.00","0.016"],["62050.80","0.002"],["62051.20","0.002"],["62054.10","0.002"],["62055.10","0.012"],["62055.40","0.474"],["62056.80","0.063"],["62057.40","0.072"],["62058.00","14.160"]],"e":"depthUpdate","ps":"BTCUSDT","pu":10998400557494,"s":"BTCUSDT","st":1,"u":10998400567148}
{"E":1783504325714,"T":1783504325713,"U":10998400567307,"a":[["62058.10","6.000"],["62061.40","0.000"],["62062.10","0.002"],["62062.30","0.090"],["62062.80","0.194"],["62063.10","0.001"],["62063.60","0.324"],["62063.70","0.074"],["62065.10","1.663"],["62065.90","0.001"],["62066.70","0.148"],["62067.40","0.111"],["62070.00","0.915"],["62071.20","0.003"],["62072.10","2.173"],["62074.00","0.028"],["62078.30","0.621"],["62078.80","0.080"],["62080.50","0.057"],["62081.50","0.009"],["62087.10","0.927"],["62087.30","0.121"],["62089.70","0.685"],["62093.30","1.232"],["62094.20","0.691"],["62099.50","2.311"],["62105.70","1.033"],["62107.20","0.019"],["62109.60","0.070"],["62110.30","0.249"],["62110.40","0.001"],["62114.30","0.001"],["62114.40","0.131"],["62114.70","0.154"],["62115.30","0.000"],["62115.70","0.000"],["62115.80","0.605"],["62126.70","0.017"],["62134.00","0.056"],["62135.90","0.083"],["62136.50","0.728"],["62398.80","0.034"],["62400.40","0.000"],["62678.70","0.000"],["62775.80","17.282"],["62796.50","0.954"],["62926.80","0.191"],["63220.00","0.814"]],"b":[["11658.00","0.384"],["11758.00","1.744"],["11848.20","0.080"],["11858.00","0.912"],["11948.20","0.688"],["55852.20","0.002"],["58955.10","0.023"],["59575.60","0.013"],["61149.60","1.527"],["61189.20","7.289"],["61248.30","1.090"],["61280.00","3.060"],["61437.40","0.000"],["61723.80","0.720"],["61744.90","2.426"],["61747.70","0.000"],["61847.20","0.002"],["61953.60","0.036"],["61962.20","0.213"],["61966.30","0.679"],["61978.20","0.051"],["61980.90","2.444"],["61983.70","0.015"],["61984.30","1.147"],["61984.90","0.056"],["61985.80","19.191"],["61986.60","3.579"],["62000.00","8.933"],["62000.30","0.016"],["62002.90","0.000"],["62004.20","0.437"],["62024.40","0.003"],["62032.50","2.015"],["62036.40","0.081"],["62038.50","1.282"],["62039.40","0.050"],["62040.10","0.000"],["62042.90","0.008"],["62043.40","0.005"],["62045.30","0.450"],["62045.70","0.635"],["62046.50","0.036"],["62054.30","0.008"],["62055.10","0.006"],["62055.70","0.201"],["62056.80","0.061"],["62057.90","0.024"],["62058.00","13.060"]],"e":"depthUpdate","ps":"BTCUSDT","pu":10998400567148,"s":"BTCUSDT","st":1,"u":10998400575539}
{"E":1783504325816,"T":1783504325815,"U":10998400575678,"a":[["62059.60","0.110"],["62061.90","0.001"],["62062.00","0.005"],["62062.10","0.002"],["62062.20","0.004"],["62062.30","0.090"],["62062.80","0.134"],["62063.60","0.002"],["62063.80","0.978"],["62064.30","0.449"],["62067.10","0.017"],["62068.00","0.081"],["62076.70","0.096"],["62078.30","0.605"],["62078.80","0.000"],["62087.70","0.416"],["62099.10","3.187"],["62099.40","1.505"],["62107.30","0.001"],["62107.70","0.102"],["62108.50","1.362"],["62114.40","0.100"],["62114.60","0.217"],["62114.70","0.255"],["62114.80","0.105"],["62115.40","0.001"],["62118.00","3.623"],["62120.00","0.198"],["62127.70","0.026"],["62127.90","5.096"],["62128.40","23.377"],["62135.70","0.022"],["62136.50","0.670"],["62367.20","0.100"],["62647.60","0.796"],["62678.70","0.000"],["62991.90","5.548"],["67176.30","0.002"],["89523.20","0.108"]],"b":[["1000.00","210.742"],["11658.00","0.576"],["11758.00","1.632"],["11848.20","0.000"],["11858.00","1.040"],["11948.20","0.560"],["55852.20","0.002"],["58939.00","0.103"],["58955.10","0.023"],["59575.60","0.010"],["60851.40","0.000"],["61056.50","0.736"],["61061.70","0.068"],["61093.30","1.134"],["61093.80","1.134"],["61120.10","0.000"],["61137.10","6.624"],["61217.50","0.815"],["61437.40","0.000"],["61772.50","0.000"],["61787.50","0.009"],["61847.20","0.003"],["61981.60","0.004"],["61985.80","0.002"],["61986.60","0.612"],["61987.90","19.427"],["61990.70","3.525"],["62002.80","0.005"],["62003.10","0.003"],["62012.40","1.998"],["62012.70","0.880"],["62021.90","0.083"],["62031.50","0.054"],["62031.60","0.059"],["62033.30","0.005"],["62037.00","0.002"],["62043.80","0.065"],["62055.60","0.002"],["62056.80","0.063"]],"e":"depthUpdate","ps":"BTCUSDT","pu":10998400575539,"s":"BTCUSDT","st":1,"u":10998400583044}
{"E":1783504325918,"T":1783504325917,"U":10998400583107,"a":[["62059.60","0.029"],["62059.70","0.090"],["62062.20","0.168"],["62062.80","0.194"],["62067.00","0.106"],["62067.60","0.303"],["62067.70","1.492"],["62068.00","0.267"],["62068.20","1.330"],["62088.40","0.687"],["62102.70","0.186"],["62114.10","0.135"],["62114.40","0.100"],["62114.60","0.116"],["62114.70","0.154"],["62115.10","0.090"],["62119.70","0.298"],["62122.00","4.064"],["62122.10","22.206"],["62122.20","0.000"],["62127.90","1.991"],["62128.40","1.171"],["62133.00","1.505"],["62133.50","0.002"],["62134.00","0.242"],["62134.20","0.230"],["62135.90","0.000"],["62183.80","0.000"],["62198.80","1.333"],["62678.70","0.000"],["62762.10","6.869"],["62793.10","5.067"],["62915.30","0.000"],["63175.10","0.379"],["63400.00","12.932"]],"b":[["1000.00","210.942"],["11658.00","0.848"],["11758.00","1.360"],["11858.00","1.184"],["11948.20","0.416"],["55852.20","0.002"],["58955.10","0.023"],["61175.00","0.007"],["61273.60","8.221"],["61437.40","0.000"],["61747.70","0.164"],["61847.20","0.002"],["61916.50","0.000"],["61927.40","0.576"],["61985.70","19.286"],["61986.60","3.600"],["61987.90","0.153"],["61990.70","0.764"],["61996.80","0.018"],["62022.10","0.821"],["62028.10","1.320"],["62033.30","0.003"],["62048.20","0.008"],["62048.30","0.034"],["62054.40","0.003"],["62058.00","13.071"]],"e":"depthUpdate","ps":"BTCUSDT","pu":10998400583044,"s":"BTCUSDT","st":1,"u":10998400589450}
{"E":1783504326020,"T":1783504326019,"U":10998400589622,"a":[["62062.20","0.005"],["62063.80","1.079"],["62064.40","0.829"],["62065.10","1.679"],["62067.10","0.001"],["62068.40","0.260"],["62069.80","0.324"],["62070.60","0.007"],["62071.90","0.228"],["62075.30","0.163"],["62076.80","0.083"],["62077.70","0.213"],["62081.00","0.334"],["62086.70","0.008"],["62088.20","0.046"],["62114.20","0.584"],["62114.40","0.201"],["62678.70","0.000"],["89523.20","0.114"]],"b":[["11658.00","1.120"],["11758.00","1.088"],["11858.00","1.312"],["11948.20","0.288"],["49644.20","0.000"],["55852.20","0.002"],["58955.10","0.023"],["59575.60","0.013"],["61061.90","1.556"],["61096.10","1.165"],["61117.50","0.010"],["61396.70","0.813"],["61437.40","0.002"],["61455.70","9.278"],["61747.70","0.174"],["61847.20","0.003"],["62022.20","0.142"],["62055.70","0.199"],["62056.80","0.065"],["62058.00","14.171"]],"e":"depthUpdate","ps":"BTCUSDT","pu":10998400589450,"s":"BTCUSDT","st":1,"u":10998400596157}
{"E":1783504326122,"T":1783504326121,"U":10998400596202,"a":[["62058.10","5.532"],["62060.00","0.017"],["62062.10","0.000"],["62062.20","0.004"],["62064.40","0.825"],["62065.00","0.424"],["62065.10","1.663"],["62065.50","0.090"],["62065.70","0.068"],["62068.00","0.187"],["62068.40","0.243"],["62070.00","1.282"],["62070.60","0.003"],["62076.80","0.079"],["62083.10","0.002"],["62089.00","0.194"],["62097.00","0.061"],["62114.60","0.217"],["62115.10","0.006"],["62134.00","0.158"],["62134.20","0.122"],["62167.60","0.022"],["62368.40","0.001"],["62398.80","0.016"],["62618.50","0.000"],["62678.70","0.000"],["62891.40","0.001"],["62970.30","1.272"],["63284.80","0.012"]],"b":[["1000.00","210.942"],["11658.00","1.392"],["11756.80","0.080"],["11758.00","0.880"],["11858.00","1.456"],["11948.20","0.144"],["55852.20","0.002"],["58955.10","0.023"],["59575.60","0.010"],["61100.10","0.287"],["61437.40","0.000"],["61537.60","6.684"],["61561.50","0.008"],["61847.20","0.002"],["61998.00","0.292"],["62014.30","0.282"],["62018.00","0.195"],["62018.10","0.620"],["62027.40","0.052"],["62030.40","0.005"],["62033.70","0.003"],["62034.10","0.065"],["62034.20","0.001"],["62034.50","0.072"],["62041.20","0.533"],["62042.40","0.004"],["62047.60","0.347"],["62049.40","0.021"],["62050.80","0.005"],["62058.00","14.159"]],"e":"depthUpdate","ps":"BTCUSDT","pu":10998400596157,"s":"BTCUSDT","st":1,"u":10998400606808}
{"E":1783504326224,"T":1783504326222,"U":10998400607078,"a":[["62058.10","5.535"],["62060.00","0.001"],["62062.80","0.098"],["62063.90","0.422"],["62064.30","0.353"],["62065.00","0.344"],["62068.40","0.323"],["62076.80","0.077"],["62114.60","0.219"],["62114.80","0.206"],["62133.00","1.403"],["62160.50","0.675"],["62396.00","0.030"],["62678.70","0.000"],["62802.80","1.598"],["62864.90","0.166"],["63284.80","0.009"],["89523.20","0.120"]],"b":[["1000.00","210.942"],["11658.00","1.664"],["11754.20","0.032"],["11755.20","0.128"],["11756.80","0.064"],["11758.00","0.752"],["11858.00","1.584"],["11948.20","0.016"],["55852.20","0.002"],["59575.60","0.013"],["61245.60","0.002"],["61437.40","0.000"],["61468.40","0.664"],["61747.70","0.175"],["61847.20","0.003"],["61985.70","0.012"],["61986.60","0.612"],["61987.80","19.553"],["61990.70","3.525"],["62026.90","0.052"],["62031.60","0.043"],["62058.00","14.161"]],"e":"depthUpdate","ps":"BTCUSDT","pu":10998400606808,"s":"BTCUSDT","st":1,"u":10998400618624}
{"E":1783504326326,"T":1783504326325,"U":10998400618775,"a":[["62058.10","5.523"],["62060.60","0.006"],["62060.90","0.001"],["62061.00","0.002"],["62062.20","0.167"],["62063.70","0.075"],["62063.90","0.406"],["62068.40","0.243"],["62069.80","0.162"],["62071.90","0.066"],["62074.50","0.000"],["62075.30","0.001"],["62076.00","0.019"],["62077.70","0.051"],["62078.10","0.955"],["62078.50","0.164"],["62081.00","1.218"],["62108.90","0.802"],["62111.20","0.030"],["62113.00","0.000"],["62114.40","0.100"],["62114.60","0.118"],["62114.80","0.105"],["62134.00","0.056"],["62678.70","0.001"],["62939.30","0.278"]],"b":[["11658.00","1.936"],["11752.10","0.000"],["11753.60","0.048"],["11754.20","0.016"],["11758.00","0.736"],["11858.00","1.472"],["11948.20","0.000"],["55852.20","0.002"],["58955.10","0.023"],["61061.90","0.000"],["61096.10","2.721"],["61176.80","0.286"],["61279.00","0.084"],["61313.30","1.615"],["61437.40","0.000"],["61550.00","8.935"],["61747.70","0.165"],["61847.20","0.002"],["61983.70","0.015"],["61984.30","1.147"],["61985.80","19.276"],["61986.60","3.600"],["61987.80","0.279"],["61990.70","0.764"],["61990.80","0.108"],["62031.10","0.000"],["62036.50","0.004"],["62037.60","0.037"],["62041.60","0.001"],["62042.50","0.296"],["62055.00","0.329"],["62055.60","0.004"]],"e":"depthUpdate","ps":"BTCUSDT","pu":10998400618624,"s":"BTCUSDT","st":1,"u":10998400628719}
{"E":1783504326428,"T":1783504326427,"U":10998400628822,"a":[["62058.10","0.000"],["62058.20","0.000"],["62058.30","0.000"],["62058.70","0.000"],["62058.80","0.000"],["62058.90","0.000"],["62059.00","0.000"],["62059.20","0.000"],["62059.50","0.000"],["62059.60","0.000"],["62059.70","5.456"],["62059.80","0.005"],["62059.90","0.001"],["62060.40","0.002"],["62060.60","0.000"],["62060.80","0.001"],["62060.90","0.056"],["62061.00","0.001"],["62061.20","0.002"],["62061.30","0.086"],["62061.70","0.002"],["62061.80","0.000"],["62061.90","0.001"],["62062.00","0.573"],["62062.10","0.000"],["62062.20","0.002"],["62062.30","0.001"],["62062.40","1.011"],["62062.60","0.002"],["62062.70","0.000"],["62062.80","0.098"],["62062.90","0.002"],["62063.00","0.005"],["62063.10","0.323"],["62063.20","0.002"],["62063.30","0.002"],["62063.40","0.001"],["62063.50","0.004"],["62063.70","0.019"],["62063.80","0.000"],["62063.90","0.404"],["62064.10","0.652"],["62064.20","0.002"],["62064.30","0.024"],["62064.40","0.000"],["62064.50","0.001"],["62064.60","0.222"],["62064.70","0.066"],["62064.80","0.061"],["62064.90","0.001"],["62065.00","0.344"],["62065.10","1.543"],["62065.20","0.002"],["62065.30","0.144"],["62065.40","0.247"],["62065.50","0.000"],["62065.60","0.001"],["62065.80","0.120"],["62066.00","0.004"],["62066.10","0.005"],["62066.30","1.082"],["62066.50","0.001"],["62066.60","0.002"],["62066.70","0.148"],["62067.20","0.485"],["62067.30","0.885"],["62067.40","0.061"],["62067.50","0.170"],["62067.60","1.610"],["62067.70","0.130"],["62067.80","0.003"],["62067.90","0.002"],["62068.10","0.010"],["62068.20","1.209"],["62068.40","0.002"],["62068.50","0.002"],["62068.60","0.000"],["62068.80","0.001"],["62069.00","0.443"],["62069.10","0.003"],["62069.40","0.442"],["62069.50","0.000"],["62069.70","0.453"],["62069.80","0.162"],["62070.00","1.150"],["62070.10","0.566"],["62070.30","0.003"],["62070.40","0.513"],["62070.50","0.001"],["62070.60","0.003"],["62070.80","1.295"],["62070.90","0.062"],["62071.10","0.003"],["62071.50","0.123"],["62071.90","0.381"],["62072.00","1.526"],["62072.10","2.424"],["62072.20","0.344"],["62072.70","0.000"],["62072.90","0.004"],["62073.00","0.174"],["62073.50","0.174"],["62073.60","2.602"],["62074.40","0.008"],["62074.50","0.000"],["62074.60","0.124"],["62074.80","0.003"],["62075.00","0.007"],["62075.20","0.218"],["62075.30","0.565"],["62075.50","0.354"],["62075.70","0.000"],["62075.90","0.726"],["62076.00","0.003"],["62076.10","0.413"],["62076.70","0.245"],["62076.90","0.003"],["62077.40","0.335"],["62077.50","0.010"],["62077.70","0.375"],["62077.90","0.108"],["62078.10","0.875"],["62078.20","1.692"],["62078.60","0.581"],["62078.90","0.000"],["62079.40","0.016"],["62079.70","0.001"],["62079.80","14.200"],["62079.90","0.000"],["62080.30","0.081"],["62080.60","0.026"],["62080.70","0.010"],["62080.80","0.092"],["62081.00","0.334"],["62081.30","0.866"],["62081.50","0.009"],["62082.20","0.087"],["62082.40","0.063"],["62083.30","0.125"],["62083.60","1.300"],["62084.10","0.000"],["62084.60","0.050"],["62085.50","0.709"],["62085.80","0.731"],["62085.90","0.806"],["62086.10","0.002"],["62086.20","0.375"],["62086.40","0.002"],["62086.70","0.008"],["62086.90","0.000"],["62087.00","0.335"],["62087.10","0.011"],["62087.30","0.001"],["62087.50","0.057"],["62087.70","0.416"],["62087.90","0.060"],["62089.00","0.194"],["62089.10","9.405"],["62089.30","0.000"],["62089.50","0.100"],["62089.60","0.017"],["62089.70","0.685"],["62089.80","2.673"],["62090.00","0.326"],["62090.20","0.055"],["62090.90","0.003"],["62091.30","0.455"],["62092.30","2.510"],["62092.40","0.008"],["62092.70","0.001"],["62093.90","0.429"],["62094.60","0.005"],["62094.80","0.008"],["62095.30","0.014"],["62095.60","0.019"],["62096.10","0.003"],["62096.40","1.098"],["62096.60","0.284"],["62096.90","0.049"],["62097.00","0.003"],["62097.60","0.454"],["62098.00","0.057"],["62098.30","0.030"],["62099.10","0.041"],["62099.20","0.027"],["62100.60","0.084"],["62100.80","0.004"],["62101.10","0.000"],["62101.80","0.044"],["62101.90","0.116"],["62102.10","0.000"],["62102.30","0.002"],["62102.60","0.028"],["62102.70","0.189"],["62103.00","0.003"],["62103.60","0.164"],["62103.70","0.455"],["62105.00","0.157"],["62108.20","1.943"],["62109.30","0.251"],["62109.60","0.016"],["62109.70","1.295"],["62109.90","3.289"],["62110.10","3.508"],["62110.80","0.572"],["62111.20","0.026"],["62112.00","0.007"],["62112.30","0.150"],["62112.50","0.015"],["62114.10","0.034"],["62114.20","0.483"],["62114.40","0.100"],["62116.00","0.101"],["62117.00","0.364"],["62117.10","1.967"],["62117.40","0.051"],["62117.50","1.200"],["62117.60","0.480"],["62117.90","0.001"],["62118.30","0.003"],["62118.40","0.001"],["62118.60","0.214"],["62119.20","12.974"],["62120.00","0.196"],["62120.30","0.008"],["62122.10","22.208"],["62122.30","0.292"],["62123.10","0.282"],["62126.40","0.017"],["62127.40","0.000"],["62133.80","0.006"],["62141.20","0.000"],["62154.80","0.603"],["62161.90","0.001"],["62162.60","0.029"],["62199.60","0.294"],["62207.50","0.018"],["62217.10","2.404"],["62236.20","0.001"],["62262.40","0.046"],["62287.50","2.691"],["62304.30","0.001"],["62340.80","0.004"],["62370.30","0.156"],["62678.70","0.001"],["62678.80","0.000"],["62679.40","0.000"],["62680.20","0.000"],["62680.30","0.000"],["62771.90","8.043"],["62772.20","13.739"],["62773.00","0.947"],["62773.50","6.622"],["62804.20","3.421"],["62834.20","3.944"],["62834.90","2.018"],["62835.10","0.788"],["62835.60","1.586"],["62835.90","1.576"],["62896.00","8.106"],["62897.20","0.000"],["62928.00","7.082"],["62928.30","4.724"],["62989.00","3.336"],["63020.60","1.217"],["63284.80","0.006"],["63300.70","0.064"],["63300.80","0.015"],["63335.30","1.894"],["67580.10","0.000"],["67580.20","0.000"],["67580.70","0.000"],["67581.10","0.588"],["89523.20","0.126"]],"b":[["1000.00","210.942"],["11658.00","2.160"],["11659.50","0.032"],["11659.60","0.016"],["11748.20","0.256"],["11749.80","0.000"],["11751.00","0.000"],["11758.00","0.704"],["11758.70","0.016"],["11759.60","0.016"],["11858.00","1.344"],["49646.00","0.000"],["55852.20","0.000"],["55853.60","0.005"],["58955.10","0.023"],["59575.60","0.010"],["60816.90","0.006"],["61054.20","0.000"],["61055.20","0.260"],["61055.70","0.000"],["61058.00","0.020"],["61058.70","0.023"],["61059.50","0.008"],["61059.60","0.018"],["61061.60","0.000"],["61096.10","4.989"],["61242.70","6.445"],["61278.80","0.006"],["61282.30","0.808"],["61313.30","3.230"],["61437.40","0.000"],["61438.10","1.626"],["61438.90","0.208"],["61439.00","0.313"],["61747.70","0.166"],["61847.20","0.003"],["61874.50","0.002"],["61875.80","2.413"],["61878.50","0.000"],["61882.00","0.002"],["61904.50","0.016"],["61930.80","0.001"],["61970.00","0.133"],["61975.30","19.275"],["61978.50","0.003"],["61980.90","2.442"],["61982.20","0.000"],["61983.60","0.670"],["61983.70","0.015"],["61984.20","0.532"],["61984.30","3.953"],["61985.00","0.873"],["61985.80","0.002"],["61986.60","0.612"],["61987.80","0.279"],["61988.20","0.000"],["61990.70","0.764"],["61990.80","0.106"],["61993.20","0.019"],["61994.30","0.000"],["61994.40","0.001"],["61994.50","1.370"],["61996.40","0.016"],["61996.80","0.017"],["61997.10","0.001"],["61998.80","0.004"],["61999.40","0.890"],["62000.00","8.933"],["62002.00","1.130"],["62002.20","0.221"],["62002.50","0.677"],["62002.80","0.441"],["62003.70","0.007"],["62005.30","0.156"],["62006.60","0.002"],["62006.80","2.063"],["62007.20","0.129"],["62007.50","0.226"],["62008.20","0.010"],["62009.10","0.003"],["62009.80","0.693"],["62010.30","0.001"],["62010.40","0.006"],["62010.50","0.002"],["62010.60","0.062"],["62010.70","0.001"],["62011.10","0.008"],["62011.50","0.011"],["62013.80","1.240"],["62014.20","0.009"],["62016.00","0.006"],["62016.10","0.001"],["62017.70","0.122"],["62018.60","0.030"],["62018.90","0.311"],["62019.10","0.001"],["62019.20","0.014"],["62019.30","0.064"],["62019.90","0.007"],["62020.40","0.979"],["62020.70","9.412"],["62021.20","0.000"],["62021.50","0.004"],["62021.90","0.083"],["62022.20","0.060"],["62022.60","0.004"],["62022.80","0.001"],["62023.00","0.252"],["62023.20","0.529"],["62023.60","0.004"],["62024.30","0.004"],["62025.00","0.005"],["62027.00","0.024"],["62027.10","0.001"],["62027.20","0.051"],["62027.70","0.004"],["62028.10","1.312"],["62028.40","1.375"],["62028.50","0.875"],["62028.60","1.256"],["62029.10","0.000"],["62029.30","0.044"],["62029.40","0.003"],["62029.50","0.001"],["62029.60","0.013"],["62029.90","0.326"],["62030.20","0.303"],["62030.50","0.009"],["62030.60","0.290"],["62030.70","0.000"],["62031.40","0.003"],["62031.90","0.122"],["62032.10","0.002"],["62032.20","0.001"],["62032.60","0.317"],["62033.50","0.004"],["62034.10","0.063"],["62034.50","0.002"],["62034.70","0.001"],["62035.10","1.301"],["62035.20","0.072"],["62036.10","2.146"],["62036.50","0.003"],["62036.60","0.302"],["62036.90","0.002"],["62037.00","0.004"],["62037.20","0.003"],["62037.30","0.098"],["62037.40","0.049"],["62037.70","0.052"],["62037.80","0.493"],["62038.20","0.069"],["62038.50","0.702"],["62039.00","0.000"],["62039.10","0.122"],["62039.30","1.958"],["62039.40","0.050"],["62039.80","0.735"],["62040.00","0.007"],["62040.10","0.663"],["62040.40","0.000"],["62040.80","0.001"],["62040.90","1.312"],["62041.10","0.003"],["62041.30","0.002"],["62041.60","0.001"],["62042.50","0.297"],["62042.70","0.143"],["62042.80","0.003"],["62043.10","0.000"],["62043.50","0.002"],["62043.60","0.125"],["62043.80","0.790"],["62044.10","0.009"],["62044.30","0.122"],["62044.40","0.002"],["62044.60","0.322"],["62044.90","0.085"],["62045.00","0.337"],["62045.20","0.065"],["62045.30","0.128"],["62045.60","0.216"],["62045.70","0.309"],["62045.80","0.565"],["62045.90","0.113"],["62046.40","0.495"],["62046.50","0.922"],["62046.70","1.002"],["62046.90","0.008"],["62047.40","1.377"],["62047.70","0.000"],["62047.80","0.000"],["62048.00","0.139"],["62049.50","0.746"],["62049.60","0.006"],["62049.90","1.366"],["62050.20","0.008"],["62050.50","0.024"],["62050.70","0.326"],["62050.80","0.001"],["62051.10","0.122"],["62051.60","0.154"],["62051.70","0.006"],["62051.80","0.004"],["62052.10","0.034"],["62052.20","0.003"],["62052.40","0.220"],["62052.50","0.001"],["62052.80","0.001"],["62053.10","0.003"],["62053.80","0.003"],["62054.20","0.177"],["62054.30","0.008"],["62054.50","0.001"],["62055.10","0.052"],["62055.30","0.003"],["62055.40","0.474"],["62055.60","0.004"],["62055.80","0.005"],["62055.90","0.005"],["62056.00","0.001"],["62056.20","0.002"],["62056.30","0.000"],["62056.40","0.000"],["62056.80","0.060"],["62056.90","0.000"],["62057.60","0.000"],["62057.80","0.000"],["62057.90","0.104"],["62058.00","0.869"],["62058.10","1.807"],["62058.20","0.004"],["62058.60","0.000"],["62058.70","0.199"],["62058.80","1.800"],["62058.90","0.001"],["62059.10","0.000"],["62059.20","0.323"],["62059.30","0.000"],["62059.40","0.000"],["62059.50","0.325"],["62059.60","12.898"]],"e":"depthUpdate","ps":"BTCUSDT","pu":10998400628719,"s":"BTCUSDT","st":1,"u":10998400649110}
{"E":1783504326530,"T":1783504326529,"U":10998400649316,"a":[["62059.70","5.361"],["62059.80","0.001"],["62060.90","0.000"],["62061.20","0.003"],["62062.00","0.005"],["62062.40","0.431"],["62063.00","0.001"],["62063.10","0.001"],["62063.70","0.002"],["62064.20","0.006"],["62064.50","0.005"],["62064.80","0.003"],["62064.90","0.887"],["62065.30","0.000"],["62066.00","0.008"],["62066.10","0.001"],["62066.20","0.065"],["62066.90","0.323"],["62067.00","0.207"],["62067.10","0.440"],["62067.20","0.163"],["62067.50","0.169"],["62067.60","1.609"],["62068.20","1.311"],["62068.30","0.004"],["62068.90","0.109"],["62069.10","0.093"],["62069.20","0.012"],["62069.30","0.096"],["62069.40","0.264"],["62069.50","0.090"],["62069.60","0.003"],["62070.10","0.570"],["62071.20","0.001"],["62071.30","0.005"],["62071.70","0.028"],["62072.00","1.151"],["62072.10","0.262"],["62072.40","0.002"],["62073.10","0.380"],["62073.50","0.738"],["62073.60","2.682"],["62075.00","0.732"],["62075.10","0.297"],["62075.20","0.218"],["62075.30","0.001"],["62075.50","0.354"],["62075.90","0.001"],["62076.40","0.073"],["62076.70","0.281"],["62076.80","0.137"],["62077.10","0.000"],["62077.30","0.000"],["62077.80","3.180"],["62077.90","0.106"],["62078.50","0.124"],["62078.60","0.001"],["62079.00","0.701"],["62079.40","0.000"],["62079.80","14.202"],["62080.50","0.101"],["62080.60","0.007"],["62080.80","0.012"],["62081.10","0.583"],["62081.30","1.242"],["62081.50","0.000"],["62082.40","0.001"],["62083.10","2.145"],["62084.90","0.082"],["62085.30","0.049"],["62085.50","0.650"],["62086.10","0.003"],["62087.10","0.001"],["62087.60","0.092"],["62089.70","0.879"],["62089.80","2.867"],["62090.20","0.160"],["62090.80","0.005"],["62093.90","0.283"],["62096.10","0.006"],["62098.00","0.001"],["62098.40","0.001"],["62099.00","0.044"],["62099.60","1.487"],["62107.70","0.138"],["62107.80","0.668"],["62109.30","0.000"],["62111.50","0.001"],["62111.70","0.043"],["62112.50","0.111"],["62114.80","0.101"],["62115.50","0.875"],["62115.60","0.117"],["62116.00","0.105"],["62117.40","0.152"],["62117.60","0.581"],["62117.80","0.241"],["62117.90","0.102"],["62118.60","0.004"],["62122.00","0.000"],["62122.10","0.002"],["62122.20","0.574"],["62123.40","0.001"],["62127.90","5.096"],["62128.40","23.377"],["62130.40","0.001"],["62130.50","0.000"],["62131.70","0.000"],["62133.00","1.505"],["62133.70","0.139"],["62134.10","0.572"],["62134.30","0.271"],["62134.90","0.159"],["62135.70","0.023"],["62142.00","7.512"],["62145.40","0.005"],["62153.40","0.004"],["62163.90","0.008"],["62172.00","0.002"],["62172.10","1.536"],["62176.00","0.128"],["62192.20","1.045"],["62192.90","0.000"],["62193.00","1.530"],["62194.70","0.002"],["62204.60","1.229"],["62204.70","4.036"],["62213.40","0.000"],["62235.40","5.175"],["62236.30","0.277"],["62239.40","0.141"],["62320.80","0.679"],["62459.90","0.244"],["62541.70","0.000"],["62579.60","0.116"],["62616.90","3.324"],["62623.10","0.000"],["62629.30","0.003"],["62647.80","0.000"],["62649.20","0.704"],["62655.40","0.700"],["62661.60","0.869"],["62678.90","0.000"],["62680.10","0.797"],["62680.30","0.000"],["62711.20","1.107"],["62771.90","3.312"],["62772.20","2.035"],["62773.00","0.001"],["62773.80","5.676"],["62773.90","2.841"],["62804.20","9.725"],["62804.30","1.582"],["62833.90","0.000"],["62834.20","0.004"],["62835.10","0.000"],["62835.40","0.237"],["62835.90","3.940"],["62836.00","2.364"],["62866.40","6.302"],["62896.00","1.023"],["62896.20","0.270"],["62896.30","0.000"],["62896.40","0.000"],["62927.00","0.692"],["62927.30","0.000"],["62928.30","11.804"],["62928.40","7.080"],["62959.40","1.101"],["62959.50","2.285"],["62989.00","0.036"],["63021.50","3.300"],["63268.20","0.000"],["63300.60","0.789"]],"b":[["1000.00","210.942"],["11659.60","0.288"],["11748.20","0.128"],["11758.00","0.560"],["11759.60","0.160"],["11858.00","1.200"],["55853.60","0.005"],["58956.60","0.000"],["59577.20","0.003"],["61220.20","0.914"],["61433.80","2.036"],["61439.00","0.313"],["61464.80","0.000"],["61465.70","3.224"],["61496.70","2.415"],["61847.20","0.002"],["61859.90","0.002"],["61860.00","1.748"],["61860.10","0.614"],["61869.70","0.000"],["61875.90","0.594"],["61882.50","0.181"],["61942.00","0.294"],["61942.50","0.699"],["61951.40","4.030"],["61952.50","3.171"],["61959.70","0.101"],["61966.50","0.001"],["61970.60","0.000"],["61975.30","0.001"],["61976.80","1.819"],["61977.60","0.003"],["61981.80","0.004"],["61982.70","0.002"],["61984.30","1.147"],["61985.70","19.286"],["61985.90","0.190"],["61987.30","0.009"],["61989.00","0.026"],["61990.00","0.009"],["61990.70","3.522"],["61991.40","0.027"],["61993.50","0.003"],["61995.20","0.706"],["61995.60","0.302"],["62000.20","1.213"],["62001.40","0.104"],["62002.40","2.433"],["62002.80","0.445"],["62006.20","0.008"],["62007.40","0.226"],["62007.50","0.001"],["62010.60","0.000"],["62011.10","0.006"],["62011.70","0.003"],["62014.40","0.016"],["62014.50","0.016"],["62015.50","0.008"],["62016.00","0.005"],["62016.10","0.000"],["62016.60","0.001"],["62017.20","0.088"],["62020.10","0.000"],["62026.50","0.516"],["62028.10","1.304"],["62029.00","0.000"],["62030.40","0.002"],["62030.80","1.655"],["62031.20","0.296"],["62031.60","0.003"],["62032.50","2.018"],["62034.00","1.569"],["62035.30","0.001"],["62036.90","0.134"],["62038.50","0.701"],["62038.70","0.000"],["62038.90","0.582"],["62039.30","1.378"],["62039.40","0.090"],["62040.40","0.000"],["62041.60","0.009"],["62041.80","0.010"],["62041.90","0.002"],["62042.30","2.049"],["62042.40","0.004"],["62042.50","1.670"],["62042.70","0.135"],["62042.90","0.129"],["62043.00","0.725"],["62043.10","0.564"],["62043.80","0.065"],["62043.90","0.084"],["62044.00","0.208"],["62044.10","0.001"],["62044.30","0.002"],["62044.90","0.085"],["62045.00","0.337"],["62045.10","0.152"],["62045.80","0.001"],["62046.10","0.000"],["62046.80","0.072"],["62047.00","0.001"],["62047.20","0.023"],["62047.30","1.364"],["62047.40","1.375"],["62047.50","0.509"],["62047.70","0.817"],["62047.80","0.008"],["62048.50","0.003"],["62049.50","1.084"],["62050.50","0.000"],["62051.20","0.002"],["62052.20","0.006"],["62052.30","0.007"],["62052.40","0.420"],["62053.50","0.001"],["62053.80","0.263"],["62054.00","0.598"],["62054.40","0.002"],["62055.10","0.050"],["62055.40","0.260"],["62055.50","0.001"],["62055.60","0.006"],["62055.70","0.048"],["62056.70","0.001"],["62056.90","0.001"],["62057.50","0.003"],["62057.90","0.102"],["62058.00","0.057"],["62058.10","1.806"],["62058.70","0.051"],["62059.30","0.002"],["62059.50","0.061"],["62059.60","11.732"]],"e":"depthUpdate","ps":"BTCUSDT","pu":10998400649110,"s":"BTCUSDT","st":1,"u":10998400666785}
{"E":1783504326632,"T":1783504326629,"U":10998400666982,"a":[["62059.70","7.287"],["62061.00","0.018"],["62061.10","0.028"],["62062.40","0.920"],["62063.60","0.456"],["62063.70","0.324"],["62063.80","0.017"],["62064.00","0.709"],["62064.10","0.732"],["62064.70","0.130"],["62064.80","0.909"],["62064.90","0.565"],["62065.00","1.706"],["62065.20","0.003"],["62066.20","0.001"],["62066.40","0.076"],["62067.00","0.106"],["62067.10","0.001"],["62067.30","0.325"],["62068.10","0.251"],["62068.30","0.003"],["62068.80","0.091"],["62069.20","0.013"],["62070.00","0.699"],["62070.90","0.060"],["62072.00","0.910"],["62072.50","0.058"],["62073.10","0.364"],["62073.60","2.602"],["62074.00","0.022"],["62076.60","0.580"],["62079.00","0.001"],["62079.70","0.164"],["62080.60","0.006"],["62080.90","0.125"],["62081.10","0.003"],["62084.40","1.570"],["62084.60","5.050"],["62084.90","0.062"],["62085.80","0.751"],["62085.90","0.686"],["62087.00","0.091"],["62087.70","0.163"],["62089.70","0.685"],["62089.80","2.673"],["62090.20","0.055"],["62091.70","0.026"],["62100.20","0.007"],["62100.80","0.004"],["62103.60","0.001"],["62103.70","0.292"],["62105.30","0.246"],["62111.00","0.438"],["62112.50","0.111"],["62114.80","0.202"],["62114.90","2.377"],["62115.00","0.291"],["62115.20","0.204"],["62116.00","0.004"],["62117.00","0.364"],["62117.40","0.051"],["62117.60","0.480"],["62117.90","0.001"],["62121.10","0.164"],["62128.10","0.709"],["62132.00","1.144"],["62133.70","0.031"],["62134.10","0.476"],["62135.80","0.010"],["62139.70","0.702"],["62146.80","0.012"],["62153.80","0.674"],["62239.40","0.140"],["62282.20","0.610"],["62283.80","0.061"],["62308.80","3.145"],["62311.70","0.000"],["62330.60","0.004"],["62418.70","0.009"],["62420.30","0.008"],["62618.10","1.937"],["62679.30","0.001"],["62680.30","0.000"],["62680.90","0.012"],["62873.30","0.074"],["62897.50","0.634"],["89523.20","0.132"]],"b":[["11559.60","0.016"],["11659.60","0.528"],["11748.20","0.000"],["11758.00","0.432"],["11759.60","0.288"],["11858.00","1.072"],["55853.60","0.005"],["58956.60","0.000"],["59577.20","0.000"],["61061.80","0.032"],["61096.20","1.134"],["61155.30","3.006"],["61158.80","2.450"],["61189.30","4.854"],["61242.70","4.053"],["61273.60","6.591"],["61282.40","2.639"],["61283.70","4.044"],["61313.40","3.232"],["61439.00","0.313"],["61513.20","0.000"],["61514.00","0.008"],["61530.00","0.160"],["61742.70","0.003"],["61743.50","0.008"],["61747.70","0.176"],["61790.00","0.077"],["61827.10","0.001"],["61847.20","0.003"],["61880.60","0.000"],["61939.40","0.241"],["61958.20","0.027"],["61985.70","0.012"],["61986.60","0.612"],["61990.00","0.009"],["61990.70","0.764"],["61992.10","19.276"],["61992.20","3.513"],["61994.00","0.018"],["62003.30","0.308"],["62004.30","0.134"],["62004.90","0.004"],["62007.10","0.240"],["62011.70","0.001"],["62012.40","2.000"],["62012.60","1.969"],["62026.20","0.000"],["62028.10","1.320"],["62028.40","1.368"],["62031.20","0.312"],["62034.80","0.002"],["62035.10","1.311"],["62036.10","2.144"],["62036.50","0.001"],["62036.60","0.292"],["62036.90","0.002"],["62037.10","0.107"],["62038.60","0.001"],["62039.30","0.004"],["62040.40","0.008"],["62041.00","1.019"],["62041.20","0.535"],["62041.60","0.001"],["62042.70","0.003"],["62042.90","0.008"],["62043.10","0.564"],["62043.60","0.141"],["62043.90","0.098"],["62044.90","0.085"],["62046.30","0.653"],["62047.20","0.024"],["62050.50","0.023"],["62052.30","0.009"],["62053.50","0.001"],["62055.60","0.004"],["62057.80","0.001"],["62058.00","0.056"],["62059.00","0.002"],["62059.20","0.000"],["62059.30","0.000"],["62059.40","0.000"],["62059.50","0.061"],["62059.60","9.865"]],"e":"depthUpdate","ps":"BTCUSDT","pu":10998400666785,"s":"BTCUSDT","st":1,"u":10998400681744}
{"E":1783504326734,"T":1783504326733,"U":10998400681981,"a":[["62059.70","7.367"],["62062.30","0.164"],["62063.50","0.568"],["62063.60","0.324"],["62064.10","0.675"],["62064.70","0.066"],["62064.90","0.001"],["62067.60","1.699"],["62068.10","0.010"],["62068.30","0.070"],["62068.60","0.241"],["62068.90","0.167"],["62074.00","0.020"],["62075.60","1.365"],["62079.70","0.065"],["62107.30","0.133"],["62114.90","2.287"],["62135.70","0.113"],["62136.30","0.076"],["62136.90","0.071"],["62680.30","0.000"],["62836.10","0.795"],["63083.70","1.661"]],"b":[["1000.00","210.942"],["11559.60","0.144"],["11659.60","0.544"],["11758.00","0.288"],["11759.60","0.432"],["11858.00","0.928"],["49648.00","0.000"],["55853.60","0.005"],["58956.60","0.003"],["59577.20","0.003"],["61066.60","6.870"],["61096.20","2.268"],["61155.00","1.937"],["61189.30","7.281"],["61200.00","36.767"],["61279.70","0.005"],["61313.40","4.847"],["61439.00","0.313"],["61847.20","0.002"],["61992.10","0.002"],["61992.20","0.634"],["61998.30","19.327"],["61998.70","5.157"],["62022.90","0.000"],["62028.00","1.468"],["62029.80","0.119"],["62042.90","0.006"],["62044.50","0.003"],["62047.60","0.347"],["62049.80","0.235"],["62052.30","0.007"],["62058.10","1.801"]],"e":"depthUpdate","ps":"BTCUSDT","pu":10998400681744,"s":"BTCUSDT","st":1,"u":10998400689899}
{"E":1783504326836,"T":1783504326835,"U":10998400690078,"a":[["62059.70","7.069"],["62059.80","0.017"],["62060.90","0.001"],["62061.10","0.012"],["62068.20","1.314"],["62069.40","0.366"],["62077.10","0.020"],["62085.80","0.731"],["62087.00","0.001"],["62100.80","2.459"],["62112.50","0.111"],["62114.10","0.135"],["62114.40","0.201"],["62114.80","0.101"],["62117.00","0.496"],["62134.20","0.224"],["62134.30","0.181"],["62152.70","0.002"],["62153.50","0.039"],["62153.70","0.434"],["62158.90","0.001"],["62159.90","0.200"],["62229.40","0.003"],["62230.40","0.157"],["62237.40","0.028"],["62425.80","0.117"],["62426.80","0.550"],["62680.30","0.002"],["62798.20","0.954"],["89523.20","0.138"]],"b":[["1000.00","210.942"],["11559.60","0.288"],["11659.50","0.016"],["11659.60","0.544"],["11756.80","0.000"],["11758.00","0.224"],["11759.60","0.560"],["11858.00","0.800"],["49648.00","0.000"],["55853.60","0.005"],["58939.00","0.102"],["58939.10","0.003"],["58956.60","0.003"],["60506.50","0.083"],["61066.60","5.735"],["61096.20","3.402"],["61126.50","0.000"],["61149.60","1.249"],["61154.70","0.000"],["61155.30","0.556"],["61158.30","1.133"],["61159.40","3.005"],["61189.20","9.716"],["61189.30","12.135"],["61252.60","0.814"],["61278.70","0.163"],["61279.30","2.142"],["61282.40","3.447"],["61313.30","4.845"],["61313.40","6.462"],["61432.00","0.285"],["61439.00","0.313"],["61462.30","1.090"],["61747.70","0.175"],["61787.50","0.001"],["61789.60","0.009"],["61847.20","0.003"],["61950.20","0.008"],["61951.20","0.006"],["61971.40","0.553"],["61972.40","0.645"],["61977.60","0.203"],["61978.60","0.005"],["61990.00","0.209"],["61991.00","0.941"],["62004.30","0.002"],["62012.60","1.953"],["62021.90","0.215"],["62024.70","0.402"],["62025.30","0.659"],["62025.40","0.004"],["62025.50","0.005"],["62031.60","0.017"],["62033.50","2.462"],["62041.40","0.022"],["62041.50","0.324"],["62041.60","0.003"],["62051.00","0.044"],["62052.30","0.005"],["62054.00","0.003"],["62055.10","0.051"],["62055.90","0.004"],["62058.00","0.047"],["62059.60","9.874"]],"e":"depthUpdate","ps":"BTCUSDT","pu":10998400689899,"s":"BTCUSDT","st":1,"u":10998400698412}
{"E":1783504326938,"T":1783504326937,"U":10998400698484,"a":[["62059.70","7.084"],["62059.80","0.001"],["62060.50","0.002"],["62061.80","0.000"],["62071.00","0.015"],["62076.60","0.000"],["62077.10","0.000"],["62077.80","3.760"],["62078.00","0.104"],["62079.00","0.701"],["62081.10","0.005"],["62112.50","0.015"],["62133.00","1.403"],["62134.10","0.332"],["62162.30","0.000"],["62197.60","0.590"],["62198.80","0.618"],["62201.90","0.343"],["62680.30","0.000"],["62842.20","0.795"],["62853.70","0.000"],["62864.90","0.484"]],"b":[["11559.60","0.416"],["11658.00","2.032"],["11659.60","0.688"],["11754.20","0.000"],["11755.20","0.000"],["11759.60","0.704"],["11858.00","0.656"],["55853.60","0.005"],["58956.60","0.003"],["59577.20","0.000"],["61136.70","0.003"],["61438.20","0.156"],["61439.00","0.313"],["61470.00","2.583"],["61500.80","0.166"],["61532.10","2.382"],["61747.70","0.165"],["61749.30","0.010"],["61847.20","0.002"],["61927.40","0.000"],["61928.70","0.565"],["61985.80","19.316"],["61986.60","3.638"],["61990.20","0.002"],["61998.30","0.013"],["61998.70","1.899"],["62002.50","0.675"],["62022.20","0.192"],["62040.00","0.009"],["62046.30","0.649"],["62050.90","0.024"],["62058.00","0.046"],["62059.00","0.000"],["62059.30","0.002"],["62059.40","0.002"],["62059.60","9.876"]],"e":"depthUpdate","ps":"BTCUSDT","pu":10998400698412,"s":"BTCUSDT","st":1,"u":10998400705695}
{"E":1783504327040,"T":1783504327037,"U":10998400705811,"a":[["62059.70","7.093"],["62062.20","0.006"],["62064.20","0.002"],["62066.00","0.012"],["62068.60","0.000"],["62069.00","0.443"],["62071.20","0.018"],["62072.00","0.595"],["62072.20","0.348"],["62073.60","0.027"],["62078.40","0.078"],["62081.10","0.003"],["62082.60","0.062"],["62096.60","0.374"],["62098.20","0.060"],["62112.50","0.015"],["62113.40","0.762"],["62114.00","0.103"],["62114.10","0.034"],["62114.40","0.100"],["62114.80","0.202"],["62117.10","1.966"],["62370.00","0.040"],["62377.70","0.301"],["62680.30","0.000"],["62804.20","8.149"],["62991.20","0.008"],["63256.30","1.565"],["89523.20","0.144"]],"b":[["1000.00","210.942"],["11559.60","0.640"],["11658.00","1.888"],["11659.60","0.656"],["11753.60","0.000"],["11759.60","0.832"],["11858.00","0.528"],["49647.70","0.000"],["55853.60","0.005"],["58956.60","0.003"],["59577.20","0.003"],["60803.10","0.002"],["61283.40","2.443"],["61314.90","1.615"],["61439.00","0.313"],["61749.30","0.011"],["61759.90","0.210"],["61797.00","0.008"],["61847.20","0.003"],["61985.80","0.002"],["61986.60","0.612"],["61990.20","0.000"],["61992.10","19.316"],["61992.20","3.491"],["61996.90","0.000"],["62011.50","0.075"],["62050.90","0.001"],["62055.90","0.008"],["62058.00","0.043"],["62058.20","0.000"],["62059.60","9.881"]],"e":"depthUpdate","ps":"BTCUSDT","pu":10998400705695,"s":"BTCUSDT","st":1,"u":10998400716097}
{"E":1783504327142,"T":1783504327141,"U":10998400716568,"a":[["62063.60","0.002"],["62064.10","0.679"],["62065.20","0.002"],["62066.00","0.004"],["62066.40","0.077"],["62066.90","0.327"],["62071.20","0.001"],["62072.20","0.344"],["62072.70","0.322"],["62078.40","0.074"],["62080.00","1.087"],["62081.30","1.259"],["62089.00","0.194"],["62089.80","2.663"],["62098.50","0.000"],["62099.60","1.476"],["62100.20","0.003"],["62101.60","0.000"],["62102.20","0.013"],["62112.50","0.015"],["62135.70","0.023"],["62136.30","0.009"],["62230.40","0.154"],["62230.50","0.003"],["62364.20","0.016"],["62396.00","0.012"],["62680.30","0.000"],["63286.90","0.000"]],"b":[["1000.00","210.942"],["11559.60","0.912"],["11658.00","1.760"],["11659.60","0.512"],["11759.60","0.976"],["11858.00","0.384"],["55853.60","0.005"],["59577.20","0.000"],["60804.80","0.003"],["60818.50","0.003"],["61065.90","0.026"],["61066.60","4.600"],["61097.70","2.268"],["61128.10","8.098"],["61159.60","2.428"],["61159.70","2.266"],["61188.70","0.407"],["61190.80","2.427"],["61439.00","0.313"],["61620.50","0.023"],["61747.70","0.164"],["61749.30","0.011"],["61847.20","0.002"],["61951.20","0.003"],["61951.30","0.003"],["62017.60","0.325"],["62039.80","0.856"],["62041.00","0.898"],["62043.80","0.063"],["62046.10","0.002"],["62049.00","0.002"],["62059.60","9.856"]],"e":"depthUpdate","ps":"BTCUSDT","pu":10998400716097,"s":"BTCUSDT","st":1,"u":10998400728631}
{"E":1783504327244,"T":1783504327243,"U":10998400728777,"a":[["62059.70","7.092"],["62060.80","0.009"],["62061.00","0.018"],["62062.30","0.001"],["62063.70","0.484"],["62063.80","0.339"],["62066.10","0.279"],["62072.70","0.000"],["62076.80","0.237"],["62077.60","0.164"],["62077.70","0.375"],["62080.00","1.069"],["62092.20","0.010"],["62114.40","0.000"],["62114.80","0.102"],["62134.20","0.122"],["62136.90","0.013"],["62160.00","0.545"],["62197.50","0.597"],["62197.60","0.000"],["62240.00","0.607"],["62320.00","0.543"],["62344.20","0.480"],["62370.00","0.041"],["62400.00","14.498"],["62680.30","0.000"],["62804.40","1.590"],["89523.20","0.150"]],"b":[["11559.60","1.184"],["11658.00","1.616"],["11659.60","0.384"],["11759.60","1.104"],["11858.00","0.256"],["55853.60","0.005"],["58956.60","0.003"],["59577.20","0.003"],["60804.80","0.000"],["60805.10","0.000"],["61127.80","0.048"],["61159.70","4.217"],["61439.00","0.313"],["61444.30","0.806"],["61680.00","1.099"],["61760.00","0.591"],["61840.00","0.447"],["61847.20","0.003"],["61920.00","0.504"],["61928.70","0.000"],["61928.80","0.565"],["61985.80","19.316"],["61986.60","3.638"],["61992.10","0.002"],["61992.20","0.636"],["62000.00","8.915"],["62026.80","0.012"],["62059.60","9.492"]],"e":"depthUpdate","ps":"BTCUSDT","pu":10998400728631,"s":"BTCUSDT","st":1,"u":10998400738492}
{"E":1783504327346,"T":1783504327345,"U":10998400738733,"a":[["62059.70","6.997"],["62061.60","0.081"],["62062.30","0.164"],["62064.70","0.082"],["62066.70","0.065"],["62067.00","0.004"],["62067.40","0.003"],["62067.50","0.001"],["62067.60","1.525"],["62067.70","0.004"],["62068.00","0.001"],["62068.20","1.104"],["62068.30","0.003"],["62068.80","0.001"],["62068.90","0.001"],["62069.10","0.003"],["62069.30","0.000"],["62069.40","0.120"],["62069.50","0.000"],["62077.60","0.001"],["62092.30","2.420"],["62092.50","0.875"],["62093.00","0.297"],["62093.20","0.003"],["62093.40","0.004"],["62093.50","0.000"],["62096.60","0.284"],["62102.70","0.063"],["62105.10","0.033"],["62105.20","0.253"],["62105.70","0.943"],["62105.80","0.001"],["62106.10","0.007"],["62106.30","1.162"],["62106.40","0.031"],["62112.50","0.015"],["62114.00","0.013"],["62114.20","0.400"],["62114.60","0.051"],["62114.90","2.151"],["62115.20","0.146"],["62115.60","0.027"],["62160.00","0.563"],["62197.50","0.002"],["62240.00","0.625"],["62320.00","0.561"],["62400.00","14.516"],["62480.00","0.828"],["62678.70","0.000"],["62680.30","0.000"],["62804.40","3.180"],["63236.40","4.265"]],"b":[["1000.00","210.942"],["11559.60","1.456"],["11658.00","1.488"],["11659.60","0.240"],["11759.60","1.248"],["11858.00","0.112"],["54000.00","158.842"],["55853.60","0.005"],["58956.60","0.003"],["60806.40","0.018"],["61066.60","3.465"],["61097.70","3.402"],["61149.60","0.971"],["61196.70","0.816"],["61200.00","36.787"],["61364.30","0.050"],["61395.60","1.374"],["61431.80","2.261"],["61439.00","0.313"],["61457.60","0.967"],["61680.00","1.117"],["61760.00","0.609"],["61840.00","0.465"],["61847.20","0.002"],["61920.00","0.522"],["61928.80","0.000"],["61929.80","0.177"],["61929.90","0.000"],["61963.60","6.302"],["61963.90","0.017"],["61964.20","0.001"],["61964.50","0.000"],["61964.80","1.346"],["61985.30","0.020"],["61985.50","0.006"],["61985.80","0.002"],["61985.90","0.158"],["61986.10","0.903"],["61986.40","0.004"],["61986.60","0.612"],["61990.00","19.523"],["61990.70","3.562"],["62000.00","8.933"],["62000.10","1.816"],["62000.20","1.033"],["62000.40","0.087"],["62000.80","0.001"],["62001.40","0.044"],["62006.90","0.648"],["62008.00","0.002"],["62008.40","0.659"],["62009.20","0.577"],["62012.80","0.084"],["62017.20","0.028"],["62017.90","0.002"],["62018.40","0.001"],["62020.70","9.352"],["62045.00","0.157"],["62045.10","0.032"],["62045.20","0.005"],["62045.30","0.008"],["62045.60","0.004"],["62045.70","0.129"],["62045.90","0.081"],["62046.20","0.373"],["62046.30","0.589"],["62046.50","0.890"],["62046.80","0.040"],["62055.60","0.599"],["62058.00","0.042"],["62059.60","9.493"]],"e":"depthUpdate","ps":"BTCUSDT","pu":10998400738492,"s":"BTCUSDT","st":1,"u":10998400749526}
{"E":1783504327448,"T":1783504327447,"U":10998400749757,"a":[["62059.70","7.092"],["62061.00","0.022"],["62061.10","0.014"],["62061.60","0.001"],["62062.30","0.164"],["62063.40","0.001"],["62063.50","0.004"],["62063.60","0.165"],["62063.70","0.162"],["62063.80","0.903"],["62064.70","0.066"],["62068.80","0.091"],["62069.20","0.097"],["62069.60","0.003"],["62070.80","1.300"],["62071.90","0.381"],["62072.50","0.053"],["62072.70","0.886"],["62073.50","0.174"],["62073.80","0.081"],["62077.30","0.002"],["62077.70","0.538"],["62080.00","1.230"],["62086.20","0.697"],["62096.60","0.374"],["62097.00","0.087"],["62112.50","0.015"],["62115.80","0.706"],["62116.00","0.004"],["62197.00","0.002"],["62197.50","0.594"],["62219.00","1.203"],["62392.60","0.021"],["62680.30","0.000"],["89523.20","0.156"]],"b":[["1000.00","210.942"],["11559.60","1.728"],["11658.00","1.344"],["11659.60","0.128"],["11759.60","1.344"],["11858.00","0.000"],["55853.60","0.005"],["58956.60","0.003"],["59577.20","0.000"],["61135.30","0.000"],["61283.00","0.614"],["61314.90","3.230"],["61376.20","3.229"],["61408.00","0.902"],["61439.00","0.313"],["61468.40","1.394"],["61749.30","0.011"],["61847.20","0.003"],["61886.80","0.000"],["61907.20","1.923"],["61928.80","0.565"],["61985.00","0.717"],["62000.60","0.157"],["62002.00","1.133"],["62002.80","0.009"],["62029.30","0.366"],["62035.50","1.726"],["62038.40","0.308"],["62041.70","0.082"],["62045.10","0.362"],["62045.20","0.005"],["62045.50","0.062"],["62045.90","0.141"],["62046.50","0.004"],["62047.80","0.000"],["62047.90","0.001"],["62048.00","0.703"],["62049.10","0.002"],["62057.90","0.100"],["62059.50","0.063"],["62059.60","9.494"]],"e":"depthUpdate","ps":"BTCUSDT","pu":10998400749526,"s":"BTCUSDT","st":1,"u":10998400757575}
{"E":1783504327550,"T":1783504327549,"U":10998400757717,"a":[["62059.70","7.197"],["62062.30","0.001"],["62063.60","0.002"],["62063.70","0.162"],["62065.20","0.003"],["62066.40","0.076"],["62067.60","1.615"],["62068.00","0.084"],["62068.30","0.172"],["62068.70","0.223"],["62068.80","0.175"],["62068.90","0.368"],["62069.20","0.199"],["62069.50","0.108"],["62072.60","0.325"],["62072.70","0.564"],["62077.60","0.001"],["62077.70","0.538"],["62082.60","0.000"],["62083.60","1.364"],["62089.30","0.090"],["62089.70","0.768"],["62090.00","0.393"],["62090.40","1.354"],["62090.50","0.095"],["62090.60","0.127"],["62096.10","0.108"],["62097.00","0.189"],["62097.30","0.805"],["62098.20","0.003"],["62112.50","0.015"],["62115.80","0.605"],["62117.10","1.906"],["62121.50","0.015"],["62142.10","0.223"],["62148.20","0.027"],["62680.30","0.000"],["62804.40","3.450"],["62948.20","0.013"]],"b":[["11559.60","2.000"],["11658.00","1.200"],["11659.50","0.000"],["11659.60","0.160"],["11759.60","1.200"],["49648.00","0.000"],["55853.60","0.005"],["58945.80","0.003"],["58945.90","0.003"],["58956.60","0.003"],["59577.20","0.003"],["61289.50","5.049"],["61314.40","0.031"],["61314.90","3.507"],["61345.90","0.968"],["61439.00","0.313"],["61847.20","0.002"],["62002.70","1.406"],["62003.10","0.035"],["62003.30","0.340"],["62003.60","0.035"],["62011.50","0.011"],["62013.70","0.293"],["62021.90","0.133"],["62038.40","0.306"],["62045.10","0.040"],["62045.20","0.065"],["62045.50","0.122"],["62045.80","0.121"],["62046.10","0.034"],["62046.40","0.587"],["62046.70","1.034"],["62047.00","0.033"],["62047.80","0.322"],["62058.70","0.053"]],"e":"depthUpdate","ps":"BTCUSDT","pu":10998400757575,"s":"BTCUSDT","st":1,"u":10998400764469}
{"E":1783504327652,"T":1783504327651,"U":10998400764605,"a":[["62059.70","7.181"],["62061.20","0.019"],["62062.30","0.164"],["62063.70","0.484"],["62065.20","0.002"],["62065.90","0.002"],["62068.80","0.343"],["62068.90","0.426"],["62069.40","0.222"],["62072.60","0.003"],["62077.60","0.001"],["62077.70","0.375"],["62080.50","0.061"],["62081.30","1.299"],["62083.60","1.300"],["62084.40","1.570"],["62090.60","0.185"],["62095.30","0.014"],["62096.60","0.542"],["62097.20","0.367"],["62112.50","0.111"],["62113.40","0.661"],["62136.80","0.727"],["62197.50","0.002"],["62680.30","0.000"],["62835.40","0.474"],["62928.50","0.290"],["89523.20","0.162"]],"b":[["1000.00","210.942"],["11559.60","2.272"],["11658.00","0.928"],["11659.60","0.288"],["11759.60","1.072"],["49648.00","0.000"],["55853.60","0.005"],["58956.60","0.003"],["59577.20","0.000"],["61004.50","1.462"],["61035.60","1.135"],["61066.60","2.330"],["61097.70","4.536"],["61128.40","3.267"],["61159.70","5.350"],["61178.40","0.285"],["61431.80","1.294"],["61439.00","0.313"],["61457.60","1.934"],["61820.00","0.377"],["61847.20","0.003"],["61928.80","0.000"],["61999.20","0.949"],["61999.40","0.000"],["62002.40","2.465"],["62004.30","0.084"],["62007.00","0.395"],["62007.10","0.158"],["62011.40","0.281"],["62013.70","0.230"],["62016.80","1.354"],["62037.90","0.583"],["62038.90","0.002"],["62039.90","0.015"],["62045.30","0.068"],["62045.80","0.153"],["62045.90","0.261"],["62052.20","0.003"],["62053.60","0.285"],["62058.00","0.025"],["62059.60","9.511"]],"e":"depthUpdate","ps":"BTCUSDT","pu":10998400764469,"s":"BTCUSDT","st":1,"u":10998400773651}
{"E":1783504327754,"T":1783504327753,"U":10998400773808,"a":[["62060.90","0.001"],["62061.20","0.003"],["62062.30","0.001"],["62064.00","0.725"],["62068.20","1.206"],["62068.90","0.534"],["62069.30","0.096"],["62069.40","0.366"],["62069.50","0.592"],["62073.20","0.630"],["62075.60","1.365"],["62077.60","0.001"],["62077.70","0.538"],["62096.10","0.210"],["62096.70","0.108"],["62097.20","0.607"],["62097.30","0.895"],["62097.40","0.286"],["62112.50","0.111"],["62114.80","0.001"],["62197.30","0.626"],["62680.30","0.000"],["62990.50","0.396"],["63289.20","0.036"],["63300.80","0.018"]],"b":[["1000.00","210.942"],["11559.60","2.544"],["11658.00","0.656"],["11659.60","0.432"],["11759.60","0.928"],["55853.60","0.005"],["58956.60","0.006"],["61066.10","0.730"],["61097.70","5.670"],["61127.10","0.481"],["61128.10","4.859"],["61128.60","4.211"],["61159.70","9.720"],["61283.20","1.848"],["61314.80","3.229"],["61314.90","11.622"],["61376.40","0.097"],["61408.00","3.288"],["61439.00","0.313"],["61747.70","0.174"],["61749.30","0.001"],["61847.20","0.002"],["61928.80","0.565"],["61992.20","0.634"],["62031.20","0.296"],["62035.50","1.742"],["62044.50","0.003"],["62044.90","0.085"],["62045.20","0.185"],["62045.30","0.128"],["62045.40","0.060"],["62045.80","0.213"],["62046.50","0.064"],["62047.80","0.322"],["62048.10","0.054"],["62059.60","9.512"]],"e":"depthUpdate","ps":"BTCUSDT","pu":10998400773651,"s":"BTCUSDT","st":1,"u":10998400782999}
{"E":1783504327856,"T":1783504327854,"U":10998400783488,"a":[["62059.70","6.001"],["62062.30","0.001"],["62063.60","0.002"],["62063.70","0.162"],["62064.00","0.709"],["62064.70","0.066"],["62065.00","0.052"],["62065.90","0.001"],["62066.00","0.010"],["62066.40","0.076"],["62066.90","0.323"],["62067.10","0.004"],["62067.40","0.004"],["62067.50","1.363"],["62067.60","0.253"],["62068.90","0.293"],["62069.40","0.366"],["62069.70","0.533"],["62072.70","0.322"],["62073.80","0.016"],["62074.90","0.729"],["62077.60","0.164"],["62077.70","0.538"],["62080.00","1.069"],["62084.40","0.760"],["62084.60","0.050"],["62086.20","0.375"],["62088.90","0.231"],["62089.00","0.194"],["62089.70","0.873"],["62089.80","2.752"],["62096.40","0.610"],["62096.50","0.002"],["62111.00","0.528"],["62111.40","0.776"],["62111.60","0.215"],["62112.00","0.065"],["62112.50","0.015"],["62112.60","0.378"],["62118.00","2.494"],["62118.20","0.002"],["62126.30","24.064"],["62127.90","1.991"],["62128.40","1.171"],["62135.30","0.744"],["62147.80","0.014"],["62149.10","0.335"],["62161.60","0.001"],["62178.20","0.000"],["62197.30","0.625"],["62198.80","0.619"],["62680.30","0.000"],["62807.90","0.000"],["62808.00","0.378"],["89523.20","0.168"]],"b":[["11559.60","2.720"],["11658.00","0.432"],["11659.60","0.560"],["11759.60","0.800"],["11959.60","0.048"],["55853.60","0.005"],["58939.00","0.100"],["58956.60","0.006"],["59577.20","0.003"],["60807.30","0.051"],["60814.10","0.501"],["61066.60","1.195"],["61097.70","6.804"],["61128.10","3.239"],["61252.20","0.814"],["61283.80","3.231"],["61314.20","0.104"],["61345.90","4.196"],["61376.20","0.003"],["61408.00","6.512"],["61439.00","0.313"],["61469.70","2.416"],["61501.00","1.960"],["61789.60","0.001"],["61790.10","0.011"],["61847.20","0.003"],["61880.10","0.027"],["61928.80","0.000"],["61928.90","0.566"],["61976.70","0.000"],["61976.80","0.621"],["61981.10","0.033"],["61981.40","0.035"],["61981.60","0.036"],["61982.00","0.630"],["61990.00","0.209"],["61990.70","0.764"],["61991.30","0.402"],["61992.10","19.316"],["61998.40","0.030"],["62005.30","0.000"],["62017.60","0.385"],["62018.00","0.255"],["62021.90","0.001"],["62022.10","0.016"],["62022.20","0.060"],["62043.10","0.000"],["62044.60","0.377"],["62044.90","0.649"],["62050.00","0.820"],["62051.00","0.042"],["62052.40","0.053"],["62052.50","1.363"],["62052.60","0.725"],["62056.90","0.004"],["62058.00","0.028"],["62058.90","0.003"]],"e":"depthUpdate","ps":"BTCUSDT","pu":10998400782999,"s":"BTCUSDT","st":1,"u":10998400798896}
{"E":1783504327958,"T":1783504327957,"U":10998400799242,"a":[["62059.70","5.217"],["62060.80","0.001"],["62061.70","0.004"],["62064.70","0.066"],["62064.80","0.820"],["62065.00","0.344"],["62066.90","0.001"],["62067.20","0.323"],["62067.40","0.230"],["62067.90","0.324"],["62069.30","0.258"],["62069.60","0.003"],["62069.70","0.453"],["62070.20","1.606"],["62070.80","1.295"],["62071.90","0.219"],["62072.50","0.058"],["62072.70","0.000"],["62073.10","0.928"],["62074.90","0.165"],["62075.20","0.056"],["62075.30","0.163"],["62077.40","0.415"],["62077.70","0.376"],["62078.00","0.084"],["62079.20","0.473"],["62079.70","0.163"],["62080.90","0.005"],["62082.10","0.130"],["62089.80","2.857"],["62089.90","0.853"],["62090.20","0.160"],["62099.90","0.716"],["62106.80","0.014"],["62107.20","0.182"],["62112.30","0.208"],["62122.10","22.602"],["62126.30","1.618"],["62149.30","0.011"],["62230.50","0.000"],["62230.60","1.674"],["62392.60","0.003"],["62680.30","0.000"],["62904.20","0.001"],["62991.90","4.279"],["63284.80","0.003"],["63286.80","0.001"],["63288.30","0.000"],["63289.20","0.024"]],"b":[["1000.00","210.942"],["11559.60","2.736"],["11658.00","0.288"],["11659.60","0.704"],["11759.60","0.656"],["11959.60","0.176"],["55853.60","0.005"],["58956.60","0.006"],["59577.20","0.000"],["60805.20","0.034"],["60807.30","0.039"],["61159.70","11.339"],["61439.00","0.313"],["61469.70","0.000"],["61501.10","2.415"],["61563.10","0.000"],["61847.20","0.002"],["61879.40","4.711"],["61910.40","8.085"],["61912.50","1.781"],["61941.30","8.107"],["61942.50","1.815"],["61945.70","0.000"],["61946.60","0.942"],["61951.30","0.000"],["61951.40","4.033"],["61956.80","4.063"],["61972.30","2.328"],["61980.80","0.254"],["62012.80","0.003"],["62017.40","0.061"],["62017.60","0.445"],["62018.60","0.090"],["62021.90","0.082"],["62024.10","0.119"],["62024.20","1.422"],["62029.30","0.044"],["62035.50","1.581"],["62036.90","0.134"],["62041.70","0.001"],["62042.70","0.135"],["62052.40","0.051"],["62052.50","1.365"],["62053.60","0.281"],["62053.70","0.050"],["62054.90","0.012"],["62055.00","0.333"],["62055.90","0.006"],["62057.50","0.006"],["62058.00","0.025"],["62058.20","0.000"],["62058.90","0.001"],["62059.20","0.323"],["62059.60","9.512"]],"e":"depthUpdate","ps":"BTCUSDT","pu":10998400798896,"s":"BTCUSDT","st":1,"u":10998400818270}
{"E":1783504328060,"T":1783504328059,"U":10998400818450,"a":[["62059.70","3.661"],["62064.40","0.001"],["62065.00","0.052"],["62066.00","0.013"],["62066.10","0.001"],["62067.40","0.229"],["62068.30","0.173"],["62069.20","0.190"],["62069.60","0.244"],["62070.20","1.365"],["62070.40","0.503"],["62070.70","0.016"],["62071.10","0.019"],["62071.20","0.017"],["62072.20","0.348"],["62073.80","0.000"],["62073.90","0.080"],["62075.20","0.116"],["62077.40","0.335"],["62078.40","0.078"],["62078.50","0.126"],["62079.00","0.001"],["62086.20","0.385"],["62089.00","0.982"],["62090.20","0.249"],["62091.70","0.001"],["62093.40","0.005"],["62098.30","0.086"],["62100.60","0.082"],["62100.80","2.461"],["62104.50","4.957"],["62108.20","0.002"],["62112.60","0.282"],["62112.70","0.099"],["62114.90","1.998"],["62126.20","8.001"],["62126.40","0.170"],["62129.00","0.002"],["62230.60","1.671"],["62230.70","0.677"],["62370.00","0.040"],["62407.80","0.220"],["62408.90","0.001"],["62680.30","0.000"],["63000.00","58.633"],["89523.20","0.174"]],"b":[["1000.00","210.942"],["11559.60","2.720"],["11658.00","0.160"],["11659.60","0.832"],["11759.60","0.528"],["11959.60","0.320"],["49647.70","0.000"],["55853.60","0.005"],["58956.60","0.016"],["59577.20","0.003"],["60807.30","0.033"],["60818.50","0.006"],["61159.60","0.000"],["61190.80","4.854"],["61432.50","0.000"],["61439.00","0.313"],["61460.30","0.001"],["61463.80","0.777"],["61747.70","0.164"],["61749.30","0.002"],["61847.20","0.003"],["61870.00","0.005"],["61883.10","0.071"],["61893.90","0.009"],["61902.00","0.001"],["61902.60","0.295"],["61935.40","0.000"],["61951.40","4.030"],["61951.50","0.003"],["61955.90","0.368"],["61966.00","0.292"],["61967.90","3.826"],["61977.60","0.269"],["61980.40","0.100"],["61985.80","19.447"],["61987.00","8.000"],["61987.10","0.436"],["61992.10","0.002"],["61995.60","0.040"],["62002.80","0.445"],["62003.30","0.324"],["62004.20","0.001"],["62006.80","2.053"],["62007.00","0.367"],["62007.90","0.017"],["62008.70","4.510"],["62017.40","0.121"],["62018.10","0.740"],["62024.20","2.222"],["62030.30","0.011"],["62034.10","0.095"],["62037.90","0.585"],["62039.10","0.121"],["62043.10","0.000"],["62044.90","0.649"],["62052.50","1.363"],["62052.60","1.017"],["62054.90","0.014"],["62056.60","0.001"],["62056.90","0.001"],["62058.00","0.032"],["62058.10","1.803"],["62058.50","0.000"],["62059.60","10.610"]],"e":"depthUpdate","ps":"BTCUSDT","pu":10998400818270,"s":"BTCUSDT","st":1,"u":10998400833567}
{"E":1783504328162,"T":1783504328161,"U":10998400833747,"a":[["62059.70","0.118"],["62060.40","0.001"],["62060.90","0.000"],["62061.00","0.001"],["62061.80","0.004"],["62062.20","0.002"],["62062.30","0.000"],["62062.40","0.002"],["62062.80","0.002"],["62063.40","0.065"],["62063.60","0.002"],["62063.70","0.001"],["62063.80","0.065"],["62063.90","0.251"],["62064.00","0.741"],["62064.10","0.656"],["62064.30","0.000"],["62064.50","0.001"],["62064.70","0.066"],["62064.80","0.003"],["62065.00","0.003"],["62065.10","0.325"],["62065.70","0.004"],["62065.80","0.000"],["62066.00","0.008"],["62066.30","0.001"],["62066.40","0.000"],["62066.50","0.003"],["62067.00","0.120"],["62067.10","0.580"],["62067.20","0.001"],["62067.30","0.002"],["62067.40","0.002"],["62067.50","0.001"],["62067.60","0.095"],["62067.70","0.001"],["62067.90","0.002"],["62068.00","0.084"],["62068.10","0.908"],["62068.20","0.852"],["62068.30","0.172"],["62068.50","0.000"],["62068.60","0.081"],["62068.70","0.226"],["62069.00","0.051"],["62069.10","0.003"],["62069.20","0.190"],["62069.30","0.096"],["62069.60","0.003"],["62069.70","0.001"],["62069.80","1.364"],["62069.90","0.575"],["62070.00","0.049"],["62070.10","0.006"],["62070.20","0.003"],["62070.40","0.067"],["62070.60","0.003"],["62070.70","0.008"],["62070.80","0.000"],["62070.90","0.001"],["62071.00","0.015"],["62071.10","0.003"],["62071.20","0.001"],["62071.30","0.327"],["62071.40","0.328"],["62071.90","0.671"],["62072.00","1.595"],["62072.10","0.508"],["62072.20","0.052"],["62072.50","0.001"],["62072.70","1.362"],["62072.80","0.001"],["62073.00","0.174"],["62073.10","0.360"],["62073.20","0.631"],["62073.30","0.323"],["62073.60","0.023"],["62073.70","0.002"],["62073.90","0.000"],["62074.10","0.345"],["62074.80","0.370"],["62074.90","0.572"],["62075.00","0.007"],["62075.20","1.164"],["62075.30","1.655"],["62075.40","0.789"],["62075.50","0.353"],["62075.60","0.003"],["62075.90","0.001"],["62076.20","0.002"],["62076.30","0.282"],["62076.70","0.036"],["62076.80","0.483"],["62076.90","0.006"],["62077.10","1.295"],["62077.20","0.725"],["62077.60","0.001"],["62077.70","0.051"],["62077.80","0.003"],["62077.90","0.006"],["62078.10","0.000"],["62078.40","0.074"],["62079.60","0.983"],["62079.70","0.876"],["62079.80","0.692"],["62080.00","1.055"],["62080.70","0.102"],["62081.00","0.628"],["62081.40","1.019"],["62081.70","0.027"],["62081.80","0.091"],["62082.10","0.010"],["62082.90","0.002"],["62083.00","2.490"],["62083.20","0.066"],["62083.30","0.150"],["62083.40","0.001"],["62083.50","0.146"],["62083.60","1.298"],["62083.70","0.083"],["62084.00","0.005"],["62084.10","13.510"],["62084.50","0.687"],["62084.60","0.352"],["62084.80","1.366"],["62085.00","0.476"],["62085.30","0.040"],["62085.80","0.665"],["62085.90","0.721"],["62086.20","0.302"],["62086.60","0.217"],["62086.70","0.120"],["62086.80","0.009"],["62087.00","0.001"],["62087.30","0.001"],["62087.60","0.059"],["62087.70","0.002"],["62087.90","0.003"],["62088.10","0.001"],["62088.20","0.044"],["62088.30","0.001"],["62088.60","0.000"],["62088.70","0.049"],["62088.90","0.233"],["62089.00","0.994"],["62089.70","0.768"],["62089.80","2.857"],["62089.90","0.853"],["62090.30","2.323"],["62090.60","0.290"],["62091.00","0.730"],["62091.10","0.011"],["62091.40","0.194"],["62091.60","0.000"],["62091.90","0.003"],["62092.20","0.053"],["62092.30","2.420"],["62092.40","0.005"],["62092.80","0.068"],["62093.80","0.005"],["62093.90","0.163"],["62094.20","0.765"],["62094.30","0.001"],["62095.80","0.328"],["62095.90","0.195"],["62096.00","1.560"],["62096.10","0.207"],["62096.20","0.001"],["62096.30","0.011"],["62096.60","0.647"],["62096.80","0.070"],["62096.90","0.098"],["62097.00","0.189"],["62097.20","0.343"],["62097.30","0.962"],["62098.30","0.028"],["62098.50","0.090"],["62098.60","0.000"],["62098.70","0.059"],["62099.00","0.101"],["62099.10","0.033"],["62099.20","0.134"],["62099.40","1.505"],["62100.20","0.011"],["62100.30","0.123"],["62100.40","0.001"],["62100.60","0.084"],["62101.80","0.104"],["62102.40","0.001"],["62102.60","0.025"],["62102.70","0.048"],["62102.90","0.657"],["62103.10","0.082"],["62103.40","0.007"],["62103.60","0.164"],["62103.70","0.455"],["62104.40","0.013"],["62104.50","4.959"],["62105.00","0.154"],["62105.80","0.004"],["62107.20","0.166"],["62107.30","0.001"],["62107.70","0.102"],["62107.80","0.577"],["62108.30","0.181"],["62108.70","1.446"],["62109.00","0.000"],["62109.10","0.263"],["62109.50","0.016"],["62110.10","3.511"],["62110.30","0.249"],["62110.40","0.011"],["62111.80","0.323"],["62112.70","0.003"],["62112.80","1.362"],["62113.50","0.665"],["62116.30","0.028"],["62116.50","0.032"],["62117.00","0.148"],["62117.10","1.642"],["62117.30","0.031"],["62118.80","0.000"],["62118.90","0.021"],["62121.70","0.006"],["62123.60","0.000"],["62123.80","0.324"],["62128.60","1.949"],["62128.70","0.078"],["62128.80","0.239"],["62137.40","1.395"],["62140.00","0.166"],["62140.70","0.190"],["62142.40","0.004"],["62149.80","0.424"],["62155.60","2.241"],["62157.30","11.683"],["62160.00","0.545"],["62211.80","0.678"],["62217.30","0.216"],["62220.20","0.000"],["62221.60","0.000"],["62236.10","0.077"],["62240.00","0.607"],["62320.00","0.543"],["62347.80","0.000"],["62377.40","0.035"],["62400.00","14.498"],["62491.30","0.005"],["62503.70","0.000"],["62680.30","0.002"],["63287.10","0.000"],["63289.20","0.006"],["63300.80","0.024"],["67581.10","0.000"]],"b":[["11559.60","2.736"],["11658.00","0.016"],["11659.60","0.976"],["11759.60","0.384"],["11959.60","0.448"],["49648.00","0.000"],["55853.60","0.005"],["58939.90","0.000"],["58956.60","0.006"],["59577.20","0.000"],["60807.30","0.012"],["60818.50","0.012"],["61066.60","0.060"],["61097.70","7.938"],["61128.40","2.124"],["61128.60","0.972"],["61159.40","0.556"],["61159.70","15.709"],["61190.80","7.281"],["61283.70","2.429"],["61314.90","13.237"],["61439.00","0.315"],["61680.00","1.099"],["61760.00","0.591"],["61788.50","0.025"],["61826.20","0.014"],["61834.80","0.000"],["61835.10","0.108"],["61840.00","0.447"],["61843.50","0.000"],["61847.20","0.002"],["61864.80","0.153"],["61877.20","0.000"],["61890.90","0.322"],["61898.50","0.015"],["61912.40","0.000"],["61912.50","1.819"],["61920.00","0.504"],["61923.00","0.010"],["61927.80","11.955"],["61927.90","0.024"],["61934.40","0.001"],["61935.10","0.647"],["61943.20","0.001"],["61946.30","0.028"],["61946.40","0.000"],["61948.60","1.374"],["61956.00","11.001"],["61957.30","0.017"],["61968.10","0.043"],["61969.10","0.003"],["61969.90","0.002"],["61971.50","1.088"],["61976.80","0.594"],["61976.90","0.166"],["61981.20","0.150"],["61981.90","1.372"],["61982.00","0.531"],["61985.80","19.447"],["61987.10","0.000"],["61987.90","0.140"],["61988.20","0.156"],["61990.00","0.209"],["61991.30","0.246"],["61991.70","0.001"],["61994.00","0.002"],["61995.60","0.040"],["61997.60","0.043"],["62000.00","8.915"],["62000.60","0.001"],["62002.10","0.703"],["62004.30","0.002"],["62006.40","0.017"],["62006.50","0.453"],["62006.60","0.267"],["62006.80","2.051"],["62007.00","0.275"],["62007.40","0.016"],["62007.60","0.728"],["62007.90","0.001"],["62008.20","0.008"],["62008.70","4.520"],["62008.80","0.452"],["62009.30","0.031"],["62010.20","0.000"],["62011.10","0.003"],["62011.50","0.003"],["62011.90","0.003"],["62012.20","0.001"],["62012.40","1.998"],["62013.00","0.003"],["62013.10","0.008"],["62013.20","0.001"],["62014.30","0.290"],["62014.90","0.010"],["62015.80","0.210"],["62016.80","1.338"],["62017.30","0.060"],["62017.40","0.241"],["62017.50","0.060"],["62017.80","0.015"],["62018.00","0.315"],["62018.60","0.125"],["62019.30","0.060"],["62019.90","0.001"],["62020.00","0.934"],["62020.30","0.003"],["62021.50","0.001"],["62021.70","0.781"],["62021.90","0.164"],["62022.20","0.000"],["62022.30","0.011"],["62022.40","0.106"],["62022.50","0.026"],["62022.70","0.007"],["62023.40","0.082"],["62024.00","0.687"],["62024.30","0.001"],["62024.90","0.100"],["62025.70","0.012"],["62026.30","0.000"],["62026.50","0.515"],["62026.80","0.002"],["62027.90","0.007"],["62028.00","1.480"],["62028.10","1.304"],["62028.30","0.130"],["62028.40","1.365"],["62028.90","0.071"],["62029.30","0.036"],["62029.60","0.013"],["62029.70","0.016"],["62029.80","0.029"],["62030.10","0.052"],["62030.30","0.101"],["62030.50","0.001"],["62030.60","0.282"],["62030.80","1.655"],["62031.10","0.000"],["62031.20","0.356"],["62031.40","0.000"],["62031.60","0.011"],["62031.70","0.009"],["62032.40","0.036"],["62032.70","0.494"],["62032.90","0.008"],["62034.40","0.000"],["62034.50","0.002"],["62034.80","0.000"],["62035.10","1.301"],["62035.20","0.002"],["62035.50","1.565"],["62035.70","0.000"],["62036.10","2.158"],["62036.80","0.852"],["62036.90","0.131"],["62037.90","0.007"],["62039.20","0.061"],["62039.80","0.735"],["62040.40","0.000"],["62041.00","1.474"],["62041.30","0.037"],["62041.40","0.002"],["62041.50","0.002"],["62042.70","0.003"],["62042.80","0.011"],["62042.90","0.022"],["62043.00","0.000"],["62043.60","0.125"],["62043.70","0.123"],["62044.00","0.208"],["62044.10","0.057"],["62044.80","1.418"],["62044.90","0.085"],["62045.00","0.157"],["62045.10","0.032"],["62045.20","0.201"],["62045.30","0.120"],["62046.10","0.759"],["62046.50","0.628"],["62047.20","0.028"],["62047.30","1.365"],["62047.60","0.427"],["62047.80","0.000"],["62047.90","0.021"],["62048.00","0.140"],["62048.10","0.698"],["62048.50","0.001"],["62048.60","0.822"],["62048.90","0.122"],["62049.80","0.237"],["62050.10","0.581"],["62050.30","0.000"],["62050.40","0.311"],["62050.80","0.819"],["62051.00","0.074"],["62051.90","0.004"],["62052.30","0.001"],["62052.50","1.363"],["62052.60","1.019"],["62052.70","0.862"],["62053.00","0.818"],["62053.20","0.001"],["62053.70","1.345"],["62053.80","0.715"],["62054.10","0.820"],["62054.60","0.207"],["62054.90","0.014"],["62055.00","0.329"],["62055.40","0.747"],["62055.50","0.005"],["62055.70","0.000"],["62055.90","0.002"],["62056.40","0.000"],["62056.60","0.050"],["62057.50","0.003"],["62057.60","0.004"],["62057.70","0.001"],["62058.10","1.803"],["62058.90","0.590"],["62059.00","0.152"],["62059.30","0.123"],["62059.60","10.776"]],"e":"depthUpdate","ps":"BTCUSDT","pu":10998400833567,"s":"BTCUSDT","st":1,"u":10998400870119}
