{"E":1783504313576,"T":1783504313573,"U":10998399093440,"a":[["62042.00","9.277"],["62042.40","0.276"],["62042.80","0.053"],["62043.50","0.000"],["62045.40","0.004"],["62045.50","0.000"],["62045.60","0.002"],["62046.50","0.005"],["62047.20","0.051"],["62048.20","0.243"],["62049.30","0.286"],["62058.00","0.087"],["62059.00","0.584"],["62060.60","0.132"],["62064.50","0.149"],["62066.80","0.128"],["62078.00","0.268"],["62078.10","1.322"],["62103.70","0.393"],["62104.00","0.078"],["62105.40","0.017"],["62107.50","18.721"],["62130.80","0.004"],["62167.30","0.000"],["62600.40","1.435"],["62662.40","0.001"],["63282.80","0.013"]],"b":[["1000.00","210.542"],["11641.90","0.208"],["11741.90","1.904"],["11834.00","0.272"],["11841.90","0.720"],["11937.80","0.496"],["55837.70","0.002"],["59560.20","0.022"],["61128.90","0.981"],["61154.70","8.654"],["61220.70","9.786"],["61221.40","1.396"],["61299.70","0.000"],["61421.50","0.000"],["61425.60","1.133"],["61834.40","0.001"],["61976.80","0.096"],["62035.40","0.000"],["62035.90","0.266"],["62036.70","0.045"],["62037.10","0.024"],["62037.40","0.001"],["62037.60","0.298"],["62040.70","0.002"],["62041.10","0.000"],["62041.90","11.037"]],"e":"depthUpdate","ps":"BTCUSDT","pu":10998399093359,"s":"BTCUSDT","st":1,"u":10998399100153}
{"E":1783504313678,"T":1783504313677,"U":10998399100454,"a":[["62042.00","9.285"],["62045.60","0.002"],["62045.70","0.000"],["62045.80","0.680"],["62050.60","0.002"],["62051.00","0.241"],["62058.00","0.071"],["62062.50","0.000"],["62064.50","0.069"],["62104.00","0.179"],["62173.20","1.312"],["62662.40","0.001"],["65763.20","0.000"]],"b":[["11641.90","0.336"],["11741.90","1.920"],["11834.00","0.128"],["11841.90","0.864"],["11937.80","0.352"],["55837.70","0.002"],["59560.20","0.019"],["61169.30","1.305"],["61261.60","1.138"],["61421.50","0.000"],["61727.70","0.000"],["61731.70","0.010"],["61834.40","0.002"],["61889.20","0.002"],["61906.40","0.213"],["61906.90","0.645"],["62037.70","0.001"]],"e":"depthUpdate","ps":"BTCUSDT","pu":10998399100153,"s":"BTCUSDT","st":1,"u":10998399107819}
{"E":1783504313780,"T":1783504313777,"U":10998399107916,"a":[["62042.00","9.105"],["62042.80","0.004"],["62045.80","0.680"],["62048.20","0.390"],["62051.00","0.000"],["62051.80","0.263"],["62052.60","0.001"],["62055.20","0.650"],["62059.60","0.124"],["62060.60","0.004"],["62060.90","0.131"],["62063.80","0.040"],["62067.10","0.162"],["62067.30","0.330"],["62073.30","0.444"],["62078.20","1.665"],["62104.00","0.179"],["62123.70","6.210"],["62160.90","0.216"],["62167.00","0.001"],["62173.20","1.318"],["62631.40","0.717"],["62662.40","0.001"]],"b":[["1000.00","210.542"],["11641.90","0.480"],["11741.90","1.904"],["11834.00","0.000"],["11841.90","0.992"],["11937.80","0.224"],["55837.70","0.002"],["58312.90","0.002"],["61044.20","0.000"],["61138.30","0.982"],["61160.90","4.528"],["61169.30","2.610"],["61227.60","3.272"],["61295.80","4.367"],["61357.30","5.366"],["61417.40","0.000"],["61421.50","0.000"],["61731.70","0.011"],["61768.20","0.000"],["61772.00","0.031"],["61834.40","0.001"],["61847.00","0.001"],["61902.40","0.004"],["61906.90","0.644"],["61977.90","0.003"],["61979.50","0.018"],["61979.90","0.084"],["62001.60","0.130"],["62002.90","0.157"],["62016.30","0.669"],["62022.50","0.163"],["62028.70","0.263"],["62029.50","0.034"],["62033.80","0.244"],["62041.70","0.050"]],"e":"depthUpdate","ps":"BTCUSDT","pu":10998399107819,"s":"BTCUSDT","st":1,"u":10998399115829}
{"E":1783504313882,"T":1783504313881,"U":10998399116016,"a":[["62042.00","9.094"],["62045.40","0.003"],["62045.60","0.553"],["62045.70","0.292"],["62045.80","0.128"],["62047.20","0.211"],["62048.20","0.390"],["62048.30","0.657"],["62060.60","0.132"],["62063.30","0.120"],["62065.30","0.000"],["62104.00","0.078"],["62105.40","18.452"],["62107.50","0.286"],["62173.20","1.318"],["62438.90","0.018"],["62443.80","0.000"],["62534.40","0.000"],["62662.40","0.001"],["62822.50","0.001"]],"b":[["1000.00","210.542"],["11641.90","0.752"],["11741.90","1.632"],["11841.90","1.136"],["11937.80","0.080"],["49633.50","0.000"],["55837.70","0.002"],["58932.20","0.013"],["59560.20","0.022"],["61421.50","0.000"],["61834.40","0.002"],["61906.90","0.002"],["61907.00","0.646"],["61979.50","0.002"],["62020.80","0.082"],["62022.10","0.123"],["62022.90","0.000"],["62028.70","0.182"],["62041.90","10.608"]],"e":"depthUpdate","ps":"BTCUSDT","pu":10998399115829,"s":"BTCUSDT","st":1,"u":10998399122921}
{"E":1783504313984,"T":1783504313983,"U":10998399123060,"a":[["62045.60","0.001"],["62047.70","0.296"],["62048.20","0.243"],["62055.00","0.405"],["62055.20","0.020"],["62058.20","0.016"],["62064.60","0.080"],["62066.80","0.000"],["62067.20","0.003"],["62069.90","0.543"],["62102.80","1.644"],["62104.00","0.179"],["62538.30","0.788"],["62662.40","0.003"],["62800.30","0.797"]],"b":[["11641.90","1.024"],["11741.90","1.360"],["11841.90","1.264"],["11934.00","0.336"],["11937.60","0.000"],["11937.80","0.000"],["55837.70","0.002"],["59560.20","0.019"],["61129.40","0.000"],["61365.60","1.627"],["61421.50","0.000"],["61731.70","0.011"],["61834.40","0.001"],["61982.00","0.156"],["62020.80","0.002"],["62037.10","0.000"]],"e":"depthUpdate","ps":"BTCUSDT","pu":10998399122921,"s":"BTCUSDT","st":1,"u":10998399127476}
{"E":1783504314086,"T":1783504314085,"U":10998399127555,"a":[["62045.60","0.001"],["62058.20","0.000"],["62059.80","0.021"],["62062.50","0.700"],["62064.60","0.000"],["62066.00","0.084"],["62103.80","0.424"],["62104.00","0.078"],["62105.40","0.017"],["62109.60","18.605"],["62400.00","14.516"],["62538.70","0.000"],["62662.40","0.001"],["63282.80","0.016"]],"b":[["1000.00","210.542"],["11641.90","1.296"],["11741.90","1.088"],["11841.90","1.408"],["11934.00","0.192"],["55837.70","0.002"],["59560.20","0.022"],["61147.40","0.237"],["61421.50","0.000"],["61731.70","0.012"],["61834.40","0.002"],["61980.80","0.249"],["61988.20","0.002"],["61988.30","1.065"],["62000.20","1.299"],["62000.30","0.217"],["62002.80","0.657"],["62002.90","0.239"],["62038.50","0.003"],["62039.60","0.008"],["62041.90","10.608"]],"e":"depthUpdate","ps":"BTCUSDT","pu":10998399127476,"s":"BTCUSDT","st":1,"u":10998399134511}
{"E":1783504314188,"T":1783504314187,"U":10998399134601,"a":[["62042.00","9.157"],["62042.70","0.051"],["62043.70","0.007"],["62044.60","0.323"],["62044.80","0.014"],["62045.30","0.825"],["62045.50","0.001"],["62045.60","0.012"],["62046.20","0.132"],["62046.40","0.831"],["62047.10","1.362"],["62047.20","1.032"],["62047.60","0.822"],["62049.00","1.464"],["62049.50","0.883"],["62050.70","0.838"],["62051.40","0.001"],["62051.80","0.022"],["62051.90","0.826"],["62052.00","0.324"],["62052.30","0.339"],["62052.90","0.984"],["62053.10","0.823"],["62053.30","0.665"],["62053.80","0.573"],["62057.10","0.635"],["62059.70","0.748"],["62059.80","0.005"],["62060.90","0.050"],["62066.00","0.004"],["62066.80","0.128"],["62067.10","0.001"],["62068.50","0.005"],["62069.80","0.294"],["62078.20","1.560"],["62083.10","2.460"],["62083.50","0.126"],["62097.50","0.096"],["62099.90","1.123"],["62104.00","0.078"],["62125.40","0.020"],["62173.20","1.316"],["62352.30","0.002"],["62537.00","0.021"],["62538.30","4.779"],["62662.40","0.003"],["62834.30","1.910"],["62892.20","8.038"],["62950.80","0.005"],["63020.30","0.435"],["63274.50","0.003"]],"b":[["1000.00","210.542"],["11641.90","1.568"],["11737.80","0.736"],["11739.40","0.000"],["11741.90","0.880"],["11841.90","1.536"],["11934.00","0.064"],["55837.70","0.002"],["58435.30","0.001"],["59560.20","0.019"],["60793.40","0.006"],["61421.50","0.000"],["61731.60","0.002"],["61834.40","0.001"],["61907.00","0.003"],["61907.10","0.685"],["61955.60","2.824"],["61964.30","0.062"],["61975.80","0.431"],["61981.00","0.000"],["61981.30","0.060"],["61981.50","0.001"],["61981.60","20.935"],["61982.00","0.592"],["61994.10","0.081"],["61998.90","0.002"],["62001.60","0.002"],["62002.80","0.575"],["62003.60","0.003"],["62003.70","0.007"],["62003.80","0.403"],["62006.20","0.017"],["62007.60","0.005"],["62007.70","0.006"],["62007.80","0.005"],["62012.40","2.608"],["62016.30","0.347"],["62017.10","0.130"],["62017.80","0.025"],["62018.00","0.197"],["62019.10","0.001"],["62019.30","0.064"],["62019.70","0.001"],["62019.80","0.008"],["62019.90","0.003"],["62021.70","0.910"],["62022.50","0.002"],["62023.30","0.019"],["62023.70","0.005"],["62023.80","0.003"],["62023.90","0.004"],["62024.60","0.616"],["62025.40","0.001"],["62029.30","0.115"],["62029.50","0.162"],["62033.80","0.268"],["62033.90","1.127"],["62034.40","0.000"],["62035.90","0.264"],["62036.60","0.004"],["62037.60","0.050"],["62037.90","1.832"],["62038.00","2.126"],["62038.10","0.004"],["62038.50","0.000"],["62038.60","0.007"],["62038.70","0.287"],["62039.40","0.003"],["62039.50","1.800"],["62039.60","0.003"],["62040.20","0.000"],["62041.70","0.001"],["62041.80","0.004"],["62041.90","5.175"]],"e":"depthUpdate","ps":"BTCUSDT","pu":10998399134511,"s":"BTCUSDT","st":1,"u":10998399143373}
{"E":1783504314290,"T":1783504314289,"U":10998399143404,"a":[["62042.00","9.208"],["62042.40","0.542"],["62044.10","0.011"],["62044.50","0.553"],["62045.20","0.000"],["62045.50","0.001"],["62045.60","0.002"],["62046.30","0.004"],["62046.60","1.378"],["62046.90","0.001"],["62047.60","0.001"],["62047.70","0.002"],["62049.10","0.426"],["62049.50","0.062"],["62049.60","0.840"],["62050.70","0.017"],["62051.90","0.005"],["62052.00","0.002"],["62052.30","0.323"],["62052.40","1.072"],["62052.60","0.081"],["62052.90","0.163"],["62053.10","0.002"],["62053.80","0.001"],["62054.10","0.003"],["62054.20","0.379"],["62055.40","0.452"],["62055.90","0.002"],["62059.40","0.758"],["62059.70","0.668"],["62062.80","0.076"],["62066.30","0.774"],["62067.40","0.649"],["62068.40","0.020"],["62075.30","0.554"],["62075.40","9.359"],["62075.50","1.112"],["62075.80","0.107"],["62076.00","0.121"],["62077.10","0.000"],["62078.00","0.163"],["62078.10","3.114"],["62100.70","0.205"],["62101.40","0.002"],["62102.20","0.053"],["62102.70","0.001"],["62102.90","4.096"],["62103.30","0.000"],["62103.70","0.292"],["62103.80","0.323"],["62109.50","4.382"],["62109.90","0.021"],["62131.40","0.747"],["62131.70","3.006"],["62662.40","0.001"],["62771.90","12.774"]],"b":[["11641.90","1.840"],["11737.80","0.608"],["11741.90","0.816"],["11841.90","1.520"],["11934.00","0.000"],["55837.70","0.002"],["58157.40","0.002"],["58932.20","0.010"],["61049.20","0.458"],["61107.20","0.412"],["61138.30","2.125"],["61200.00","36.751"],["61421.50","0.002"],["61731.70","0.012"],["61834.40","0.002"],["61958.20","0.023"],["61959.10","4.226"],["61979.50","0.000"],["61980.70","5.987"],["61984.20","5.819"],["61994.10","0.065"],["61995.70","0.018"],["62002.90","0.239"],["62003.40","0.003"],["62007.60","0.728"],["62007.90","0.019"],["62012.70","0.878"],["62014.30","0.298"],["62015.80","2.459"],["62016.90","0.533"],["62018.70","0.037"],["62020.20","0.809"],["62020.50","0.016"],["62021.00","0.121"],["62021.70","0.781"],["62022.10","0.002"],["62025.00","0.026"],["62027.70","0.846"],["62030.40","0.453"],["62033.80","0.244"],["62035.70","0.004"],["62038.60","0.004"],["62039.60","0.085"],["62041.90","4.734"]],"e":"depthUpdate","ps":"BTCUSDT","pu":10998399143373,"s":"BTCUSDT","st":1,"u":10998399153375}
{"E":1783504314392,"T":1783504314389,"U":10998399153515,"a":[["62042.70","0.055"],["62043.50","0.002"],["62044.10","0.013"],["62044.40","0.000"],["62044.50","0.001"],["62044.80","0.004"],["62044.90","0.001"],["62046.70","0.000"],["62047.10","1.362"],["62047.70","0.012"],["62047.80","1.001"],["62048.90","0.163"],["62051.00","0.080"],["62051.80","0.028"],["62052.60","0.017"],["62054.00","0.012"],["62054.20","0.363"],["62057.90","0.007"],["62060.50","0.008"],["62060.80","0.122"],["62062.80","0.068"],["62063.30","0.002"],["62063.40","1.617"],["62063.50","1.503"],["62066.90","0.833"],["62068.20","0.694"],["62068.30","5.002"],["62069.90","0.415"],["62075.20","0.099"],["62075.50","1.007"],["62075.80","0.002"],["62076.00","0.016"],["62076.40","0.053"],["62131.40","0.772"],["62184.30","1.161"],["62223.40","0.413"],["62251.20","0.506"],["62316.40","0.175"],["62436.40","0.019"],["62438.90","0.000"],["62508.10","0.179"],["62662.40","0.001"],["62736.90","0.650"],["62844.40","0.318"],["62910.60","2.381"],["63063.40","0.000"]],"b":[["1000.00","210.542"],["11641.90","2.112"],["11737.80","0.464"],["11741.90","0.816"],["11841.90","1.392"],["49634.00","0.000"],["55837.70","0.002"],["59560.20","0.022"],["59606.70","1.424"],["61262.30","2.510"],["61284.00","9.726"],["61421.50","0.000"],["61731.60","0.001"],["61783.00","0.682"],["61834.40","0.001"],["61943.90","0.003"],["61944.00","0.006"],["61969.40","0.670"],["61974.00","0.696"],["61977.20","0.460"],["61986.50","1.411"],["62012.80","0.004"],["62012.90","2.166"],["62014.00","0.265"],["62019.10","0.582"],["62019.70","0.122"],["62020.10","0.006"],["62021.00","0.000"],["62022.00","0.002"],["62026.80","0.000"],["62027.30","0.082"],["62029.00","0.040"],["62029.50","0.034"],["62030.30","0.165"],["62030.50","0.293"],["62031.50","0.052"],["62031.60","0.123"],["62033.90","1.125"],["62035.30","0.004"],["62036.70","0.042"],["62039.60","0.003"],["62041.90","4.632"]],"e":"depthUpdate","ps":"BTCUSDT","pu":10998399153375,"s":"BTCUSDT","st":1,"u":10998399162048}
{"E":1783504314494,"T":1783504314493,"U":10998399162442,"a":[["62042.00","9.289"],["62042.60","0.017"],["62043.50","0.002"],["62043.70","0.005"],["62044.50","0.001"],["62046.30","0.298"],["62047.10","1.362"],["62051.00","0.000"],["62052.60","0.001"],["62054.10","0.001"],["62054.80","0.729"],["62057.30","0.080"],["62057.50","0.128"],["62057.60","0.002"],["62057.90","0.009"],["62058.30","0.580"],["62059.00","0.004"],["62067.40","0.659"],["62068.40","0.012"],["62352.30","0.003"],["62662.40","0.001"],["62817.50","0.587"],["63259.10","0.708"]],"b":[["1000.00","210.542"],["11641.90","2.384"],["11737.80","0.336"],["11741.90","0.816"],["11841.90","1.248"],["55837.70","0.002"],["59560.20","0.019"],["60801.10","0.074"],["61031.20","0.247"],["61421.50","0.000"],["61834.40","0.002"],["61880.00","5.365"],["61986.50","1.395"],["62007.90","0.003"],["62020.20","0.681"],["62021.60","1.075"],["62023.10","0.021"],["62025.00","0.006"],["62025.70","0.018"],["62026.80","0.002"],["62029.20","0.186"],["62030.30","0.457"],["62030.50","0.001"],["62033.80","0.144"],["62040.80","0.002"]],"e":"depthUpdate","ps":"BTCUSDT","pu":10998399162048,"s":"BTCUSDT","st":1,"u":10998399169482}
{"E":1783504314596,"T":1783504314595,"U":10998399169596,"a":[["62042.00","9.291"],["62044.10","0.003"],["62044.50","0.001"],["62045.70","0.000"],["62046.20","0.424"],["62046.30","0.004"],["62047.00","0.001"],["62047.70","0.002"],["62054.80","0.004"],["62056.60","1.007"],["62058.30","0.000"],["62059.30","0.582"],["62060.10","0.000"],["62064.20","0.027"],["62066.80","0.000"],["62080.00","1.057"],["62090.80","0.000"],["62094.90","0.073"],["62126.10","0.157"],["62130.20","0.018"],["62160.00","0.546"],["62240.00","0.607"],["62320.00","0.543"],["62400.00","14.498"],["62662.40","0.001"],["62786.40","1.590"],["62910.50","2.382"],["63202.10","0.955"]],"b":[["11641.90","2.656"],["11737.80","0.192"],["11741.90","0.816"],["11841.90","1.120"],["49634.00","0.000"],["55837.70","0.002"],["59560.20","0.022"],["61222.30","1.385"],["61421.50","0.000"],["61499.60","0.001"],["61503.70","0.009"],["61680.00","1.099"],["61729.10","0.009"],["61731.70","0.012"],["61733.30","0.169"],["61760.00","0.591"],["61834.40","0.001"],["61840.00","0.431"],["61920.00","0.504"],["61982.80","0.001"],["61987.20","0.136"],["61995.90","0.323"],["62000.00","8.948"],["62005.30","0.004"],["62014.00","0.137"],["62014.70","0.353"],["62017.10","0.002"],["62017.50","0.784"],["62018.90","0.325"],["62029.50","0.162"],["62033.20","0.029"]],"e":"depthUpdate","ps":"BTCUSDT","pu":10998399169482,"s":"BTCUSDT","st":1,"u":10998399180860}
{"E":1783504314698,"T":1783504314697,"U":10998399181128,"a":[["62042.00","9.211"],["62042.60","0.001"],["62043.50","0.002"],["62044.90","0.003"],["62045.20","0.294"],["62045.80","0.422"],["62046.70","0.080"],["62047.10","1.362"],["62049.20","0.185"],["62060.80","0.002"],["62061.80","0.120"],["62067.40","0.649"],["62094.60","0.003"],["62100.90","0.029"],["62891.90","1.375"],["63039.70","1.471"],["64521.70","0.000"]],"b":[["1000.00","210.542"],["11541.90","0.096"],["11641.90","2.736"],["11737.80","0.160"],["11741.90","0.816"],["11841.90","0.976"],["49634.00","0.002"],["55837.70","0.002"],["58939.80","0.003"],["60983.20","0.823"],["61421.50","0.002"],["61834.40","0.002"],["61973.20","0.001"],["61980.10","0.002"],["61980.80","0.247"],["61981.60","21.481"],["61982.00","0.436"],["61982.10","0.008"],["61982.40","0.001"],["61983.00","0.832"],["61984.20","2.962"],["61989.40","0.236"],["61995.90","0.323"],["62004.60","0.019"],["62029.50","0.162"],["62039.60","0.085"]],"e":"depthUpdate","ps":"BTCUSDT","pu":10998399180860,"s":"BTCUSDT","st":1,"u":10998399191743}
{"E":1783504314800,"T":1783504314797,"U":10998399191826,"a":[["62043.50","0.004"],["62044.30","0.004"],["62045.10","0.296"],["62045.80","0.128"],["62046.00","0.003"],["62046.70","0.000"],["62049.20","0.169"],["62049.40","0.241"],["62052.90","0.243"],["62057.40","0.179"],["62060.60","0.004"],["62066.80","0.128"],["62069.80","0.296"],["62069.90","0.543"],["62662.40","0.001"],["62837.40","0.001"],["62893.40","0.793"],["62972.90","0.000"],["63278.60","0.036"]],"b":[["1000.00","210.542"],["11541.90","0.240"],["11641.90","2.720"],["11741.90","0.816"],["11841.90","0.848"],["49633.50","0.000"],["49634.00","0.000"],["55837.70","0.002"],["58932.20","0.012"],["59560.20","0.019"],["61097.40","0.752"],["61204.30","0.408"],["61310.50","0.001"],["61421.50","0.000"],["61772.00","0.023"],["61772.50","0.008"],["61834.40","0.001"],["61992.10","0.691"],["61995.90","0.309"],["62004.90","0.015"]],"e":"depthUpdate","ps":"BTCUSDT","pu":10998399191743,"s":"BTCUSDT","st":1,"u":10998399200274}
{"E":1783504314902,"T":1783504314901,"U":10998399200644,"a":[["62043.50","0.004"],["62045.80","0.275"],["62046.10","0.149"],["62046.30","0.004"],["62048.50","0.114"],["62048.90","0.001"],["62052.90","0.001"],["62054.90","0.213"],["62056.10","0.160"],["62057.40","0.163"],["62059.10","0.003"],["62060.60","0.132"],["62061.20","0.050"],["62063.30","0.000"],["62063.60","0.022"],["62064.20","0.088"],["62064.90","0.082"],["62066.80","0.000"],["62068.40","0.022"],["62069.80","0.134"],["62069.90","0.415"],["62071.20","0.220"],["62075.90","0.001"],["62077.10","0.000"],["62077.20","1.436"],["62084.90","0.001"],["62085.10","0.000"],["62085.20","0.065"],["62662.40","0.001"],["62879.50","0.746"],["63282.80","0.019"]],"b":[["11541.90","0.368"],["11641.90","2.736"],["11737.80","0.096"],["11741.80","0.000"],["11741.90","0.896"],["11841.90","0.704"],["55837.70","0.002"],["59560.20","0.022"],["61078.60","0.000"],["61107.20","1.148"],["61421.50","0.000"],["61727.70","0.010"],["61731.70","0.002"],["61834.40","0.002"],["61993.10","0.064"],["61993.80","9.372"],["61995.70","0.002"],["61995.90","0.309"],["61996.20","0.017"],["61996.40","0.001"],["62002.90","0.157"],["62004.60","0.019"],["62004.90","0.001"],["62011.50","0.058"],["62020.20","1.131"],["62020.60","0.047"],["62020.70","0.016"],["62026.40","0.334"],["62029.50","0.034"],["62032.60","0.400"],["62041.90","4.867"]],"e":"depthUpdate","ps":"BTCUSDT","pu":10998399200274,"s":"BTCUSDT","st":1,"u":10998399210113}
{"E":1783504315004,"T":1783504315003,"U":10998399210254,"a":[["62042.00","9.206"],["62042.70","0.006"],["62043.50","0.556"],["62045.10","0.002"],["62045.20","0.294"],["62045.50","0.000"],["62045.60","0.001"],["62045.80","0.422"],["62046.10","0.296"],["62046.30","0.004"],["62047.10","1.509"],["62048.50","0.091"],["62049.40","0.000"],["62049.70","0.341"],["62049.90","0.244"],["62052.70","0.020"],["62056.10","0.080"],["62057.50","0.000"],["62061.00","0.705"],["62061.20","0.034"],["62062.50","0.000"],["62063.40","1.615"],["62075.30","0.554"],["62086.60","0.200"],["62100.70","0.205"],["62662.40","0.001"],["62703.70","0.000"]],"b":[["1000.00","210.542"],["11541.90","0.544"],["11641.90","2.656"],["11737.80","0.000"],["11741.90","1.024"],["11841.90","0.576"],["49634.00","0.000"],["55837.70","0.002"],["59560.20","0.019"],["60489.70","0.015"],["61058.60","0.970"],["61289.20","1.976"],["61421.50","0.000"],["61834.40","0.001"],["61935.90","0.128"],["61973.20","21.478"],["61973.70","0.157"],["61981.00","0.436"],["61981.60","0.004"],["61995.10","0.003"],["61995.70","0.004"],["62002.80","0.139"],["62002.90","0.157"],["62003.30","0.343"],["62008.20","0.050"],["62026.40","0.173"],["62029.50","0.162"],["62031.60","0.014"],["62032.60","0.319"],["62035.30","0.001"],["62036.80","0.055"],["62038.40","0.185"],["62039.60","0.085"],["62039.70","0.000"],["62041.90","4.885"]],"e":"depthUpdate","ps":"BTCUSDT","pu":10998399210113,"s":"BTCUSDT","st":1,"u":10998399219538}
{"E":1783504315106,"T":1783504315105,"U":10998399220086,"a":[["62042.00","9.191"],["62043.50","0.003"],["62044.50","0.002"],["62045.10","0.296"],["62045.70","0.147"],["62045.80","0.128"],["62046.10","0.149"],["62046.70","0.002"],["62047.10","1.362"],["62047.20","0.211"],["62048.20","0.081"],["62049.00","1.302"],["62049.30","0.124"],["62052.00","0.164"],["62052.70","0.004"],["62055.20","0.036"],["62055.90","0.164"],["62057.50","0.128"],["62064.90","0.001"],["62068.10","0.100"],["62068.30","5.004"],["62069.70","0.003"],["62073.30","0.122"],["62434.70","0.177"],["62436.40","0.001"],["62662.40","0.001"],["62848.50","0.960"],["62947.80","4.488"]],"b":[["1000.00","210.542"],["11541.90","0.816"],["11641.90","2.384"],["11741.90","1.168"],["11841.90","0.432"],["55837.70","0.002"],["59560.20","0.022"],["60793.50","0.000"],["61278.70","3.423"],["61421.50","0.002"],["61834.40","0.002"],["61973.20","0.001"],["61979.50","21.479"],["61980.70","5.985"],["61996.20","0.003"],["62002.80","0.221"],["62005.20","0.582"],["62015.30","0.050"],["62017.50","0.084"],["62019.00","0.819"],["62021.90","0.001"],["62024.80","0.005"],["62028.80","0.080"],["62030.30","0.295"],["62034.20","1.510"],["62039.60","0.003"],["62041.50","0.049"],["62041.90","6.294"]],"e":"depthUpdate","ps":"BTCUSDT","pu":10998399219538,"s":"BTCUSDT","st":1,"u":10998399228840}
{"E":1783504315208,"T":1783504315205,"U":10998399228869,"a":[["62043.50","0.003"],["62045.10","0.002"],["62045.20","0.000"],["62045.70","0.000"],["62045.80","0.128"],["62046.60","0.963"],["62049.70","0.261"],["62053.40","0.367"],["62055.20","0.020"],["62059.80","0.021"],["62069.90","0.543"],["62071.20","0.059"],["62352.30","0.002"],["62662.40","0.001"],["62718.30","0.682"],["62884.60","0.000"]],"b":[["11541.90","1.088"],["11641.90","2.112"],["11741.90","1.296"],["11841.90","0.304"],["55837.70","0.002"],["60452.70","2.396"],["61030.60","0.247"],["61134.10","1.134"],["61199.30","0.221"],["61320.10","5.373"],["61421.50","0.000"],["61727.70","0.000"],["61731.70","0.012"],["61834.40","0.001"],["61982.00","0.000"],["61999.70","0.016"],["62020.20","0.809"],["62030.40","0.324"],["62030.70","0.170"],["62034.20","1.363"],["62041.90","5.277"]],"e":"depthUpdate","ps":"BTCUSDT","pu":10998399228840,"s":"BTCUSDT","st":1,"u":10998399235436}
{"E":1783504315310,"T":1783504315309,"U":10998399235653,"a":[["62044.50","0.554"],["62044.90","0.005"],["62045.20","0.294"],["62045.50","0.002"],["62045.80","0.275"],["62047.10","1.362"],["62048.00","0.001"],["62051.50","0.003"],["62051.60","0.000"],["62053.40","0.287"],["62056.50","0.080"],["62059.80","0.005"],["62063.30","0.016"],["62068.20","2.491"],["62068.40","0.012"],["62070.10","0.122"],["62071.00","0.074"],["62077.10","0.060"],["62085.20","0.005"],["62376.30","0.103"],["62413.40","0.173"],["62437.90","0.162"],["62511.10","0.003"],["62662.40","0.001"],["67559.10","0.606"]],"b":[["1000.00","210.542"],["11541.90","1.360"],["11641.90","1.840"],["11741.90","1.440"],["11841.90","0.160"],["55837.70","0.002"],["58936.00","0.002"],["59560.20","0.019"],["61304.00","0.981"],["61421.50","0.000"],["61731.60","0.002"],["61834.40","0.002"],["61976.20","1.013"],["61976.80","0.000"],["61980.70","9.012"],["61997.40","0.341"],["62005.30","0.000"],["62020.20","0.681"],["62022.30","0.002"],["62023.30","0.147"],["62024.30","0.001"],["62024.50","1.465"],["62027.30","0.122"],["62027.70","0.843"],["62028.10","0.240"],["62029.00","0.000"],["62029.50","0.162"],["62029.90","0.373"],["62031.50","0.054"],["62031.70","0.065"],["62033.20","0.006"],["62033.50","0.129"],["62041.50","0.000"]],"e":"depthUpdate","ps":"BTCUSDT","pu":10998399235436,"s":"BTCUSDT","st":1,"u":10998399241597}
{"E":1783504315412,"T":1783504315411,"U":10998399241710,"a":[["62044.50","0.002"],["62045.20","0.000"],["62045.80","0.275"],["62047.10","1.362"],["62048.50","0.001"],["62048.80","0.001"],["62049.10","0.324"],["62049.20","0.000"],["62049.50","0.004"],["62049.60","0.505"],["62049.70","0.003"],["62049.80","0.006"],["62050.10","0.001"],["62050.20","0.067"],["62050.30","0.013"],["62050.40","0.002"],["62051.00","0.090"],["62051.80","0.022"],["62052.00","0.002"],["62053.30","0.671"],["62054.90","0.051"],["62055.90","0.002"],["62056.50","0.000"],["62057.50","0.000"],["62057.90","0.007"],["62060.60","0.132"],["62061.50","0.081"],["62062.20","0.063"],["62063.30","0.000"],["62063.50","1.501"],["62069.90","0.415"],["62070.20","1.365"],["62070.50","0.000"],["62070.80","1.477"],["62071.20","0.001"],["62071.40","1.032"],["62071.50","0.707"],["62075.40","9.464"],["62075.50","1.112"],["62076.90","0.004"],["62077.00","0.049"],["62077.50","0.481"],["62077.60","0.000"],["62077.90","0.028"],["62078.00","0.061"],["62078.10","2.772"],["62078.20","1.362"],["62078.30","0.605"],["62078.80","0.107"],["62091.80","0.339"],["62092.20","0.041"],["62092.50","0.875"],["62092.80","0.017"],["62093.10","0.153"],["62352.30","0.001"],["62662.40","0.001"],["62785.10","0.000"],["62855.40","0.794"],["62892.20","8.027"],["63278.60","0.033"]],"b":[["1000.00","210.542"],["11541.90","1.632"],["11641.90","1.568"],["11741.90","1.568"],["11841.90","0.032"],["55837.70","0.002"],["59560.20","0.022"],["60797.10","0.013"],["60801.10","0.077"],["60983.30","1.231"],["61049.20","1.275"],["61204.30","0.978"],["61299.60","0.990"],["61421.50","0.000"],["61834.40","0.001"],["61952.50","2.170"],["61963.60","6.302"],["61963.90","0.017"],["61964.20","0.001"],["61964.50","0.011"],["61964.80","1.346"],["61971.80","0.042"],["61979.60","0.002"],["61980.10","0.000"],["61985.30","0.002"],["61985.60","0.003"],["61985.90","0.000"],["61986.20","0.002"],["61986.50","1.363"],["61989.90","0.115"],["61993.50","0.019"],["61997.40","0.281"],["61997.90","3.789"],["61998.80","0.029"],["61999.10","0.002"],["61999.20","0.052"],["62000.20","1.179"],["62000.30","0.097"],["62000.50","0.004"],["62000.80","0.002"],["62000.90","0.108"],["62001.40","0.067"],["62006.90","0.649"],["62007.00","0.275"],["62020.20","0.809"],["62020.80","0.004"],["62023.60","0.008"],["62026.60","0.040"],["62026.80","0.000"],["62027.80","0.060"],["62028.00","0.105"],["62028.10","0.000"],["62028.20","0.000"],["62028.30","1.417"],["62028.60","0.454"],["62028.70","0.002"],["62028.80","0.020"],["62028.90","0.565"],["62029.20","0.126"],["62029.30","0.023"],["62029.50","0.130"],["62029.80","0.001"],["62034.00","1.915"],["62041.90","5.089"]],"e":"depthUpdate","ps":"BTCUSDT","pu":10998399241597,"s":"BTCUSDT","st":1,"u":10998399247534}
{"E":1783504315514,"T":1783504315513,"U":10998399247606,"a":[["62042.00","9.233"],["62042.50","0.026"],["62042.80","0.053"],["62044.10","0.005"],["62044.50","0.002"],["62046.70","0.000"],["62047.00","0.001"],["62049.80","0.096"],["62050.10","0.084"],["62050.40","0.104"],["62050.80","0.380"],["62051.00","0.174"],["62051.10","0.532"],["62051.40","0.187"],["62051.60","0.108"],["62056.30","0.080"],["62057.90","0.009"],["62061.50","0.001"],["62062.80","0.084"],["62068.40","0.022"],["62071.40","1.122"],["62071.80","0.092"],["62072.40","0.086"],["62072.70","1.188"],["62074.80","0.163"],["62075.80","0.002"],["62078.30","0.707"],["62079.20","0.186"],["62079.50","0.110"],["62093.10","0.243"],["62093.40","0.086"],["62094.10","0.774"],["62101.20","0.030"],["62662.40","0.001"],["62798.40","1.961"],["62798.50","0.539"]],"b":[["11541.90","1.904"],["11641.90","1.408"],["11741.90","1.488"],["11841.90","0.000"],["49634.00","0.000"],["55837.70","0.002"],["59560.20","0.019"],["61138.30","3.105"],["61142.30","0.328"],["61211.50","0.286"],["61247.80","0.937"],["61294.90","0.000"],["61324.50","2.335"],["61421.50","0.000"],["61731.60","0.003"],["61731.70","0.012"],["61834.40","0.002"],["61984.70","0.033"],["61985.30","0.034"],["61985.60","0.035"],["61999.70","0.000"],["62002.80","0.139"],["62019.10","0.001"],["62019.90","0.584"],["62020.80","0.004"],["62026.80","0.002"],["62027.20","0.195"],["62027.40","0.210"],["62027.70","0.903"],["62027.80","0.120"],["62028.10","0.032"],["62028.40","0.061"],["62028.60","0.486"],["62028.90","0.597"],["62036.80","0.052"],["62038.00","2.129"],["62039.60","0.085"]],"e":"depthUpdate","ps":"BTCUSDT","pu":10998399247534,"s":"BTCUSDT","st":1,"u":10998399253907}
{"E":1783504315616,"T":1783504315614,"U":10998399253994,"a":[["62042.00","9.235"],["62042.80","0.004"],["62043.50","0.555"],["62045.10","0.296"],["62045.20","0.294"],["62045.70","0.000"],["62045.80","0.422"],["62046.10","0.296"],["62048.60","0.083"],["62049.60","0.696"],["62050.40","0.171"],["62050.90","0.141"],["62051.00","0.252"],["62051.10","0.590"],["62051.20","0.299"],["62051.60","0.210"],["62053.00","0.308"],["62053.30","0.665"],["62056.30","0.000"],["62057.50","0.128"],["62062.80","0.068"],["62070.90","2.041"],["62072.10","0.383"],["62072.70","1.246"],["62075.30","0.554"],["62075.50","1.007"],["62078.80","0.275"],["62079.40","0.102"],["62093.80","0.067"],["62094.40","0.713"],["62100.70","0.205"],["62662.40","0.001"]],"b":[["1000.00","210.542"],["11541.90","2.176"],["11641.90","1.264"],["11741.90","1.360"],["49634.00","0.000"],["55837.70","0.002"],["61421.50","0.000"],["61834.40","0.001"],["61976.20","0.917"],["61976.70","0.096"],["61984.40","0.033"],["61985.00","0.724"],["61997.40","0.277"],["62002.80","0.221"],["62004.20","0.005"],["62020.20","0.681"],["62027.20","0.255"],["62027.80","0.212"],["62027.90","0.432"],["62028.40","0.093"],["62029.50","0.130"],["62033.70","0.025"],["62034.00","1.892"],["62039.60","0.003"],["62041.80","0.016"]],"e":"depthUpdate","ps":"BTCUSDT","pu":10998399253907,"s":"BTCUSDT","st":1,"u":10998399260786}
{"E":1783504315718,"T":1783504315717,"U":10998399261139,"a":[["62042.00","9.237"],["62042.40","0.764"],["62042.80","0.053"],["62043.50","0.555"],["62044.90","0.299"],["62045.00","0.295"],["62045.80","0.275"],["62046.10","0.149"],["62048.60","0.003"],["62050.40","0.273"],["62051.10","0.698"],["62051.50","0.243"],["62051.60","0.300"],["62051.70","0.090"],["62053.00","0.292"],["62061.20","0.114"],["62078.20","1.464"],["62078.90","0.108"],["62079.30","0.124"],["62079.40","0.246"],["62079.50","0.290"],["62662.40","0.001"],["62751.50","0.240"],["62786.90","1.864"],["62886.40","0.003"]],"b":[["1000.00","210.542"],["11541.90","2.448"],["11641.90","1.136"],["11741.90","1.216"],["55837.70","0.002"],["59560.20","0.022"],["60900.00","38.628"],["61297.40","1.231"],["61300.00","88.646"],["61421.50","0.002"],["61834.40","0.002"],["62002.80","0.221"],["62023.30","0.147"],["62027.10","0.061"],["62027.20","0.375"],["62027.30","0.182"],["62027.80","0.272"],["62028.40","0.153"],["62039.60","0.003"],["62041.90","4.889"]],"e":"depthUpdate","ps":"BTCUSDT","pu":10998399260786,"s":"BTCUSDT","st":1,"u":10998399267977}
{"E":1783504315820,"T":1783504315817,"U":10998399268011,"a":[["62043.50","0.003"],["62044.90","0.005"],["62045.00","0.001"],["62045.10","0.002"],["62045.20","0.552"],["62045.50","0.004"],["62045.80","0.128"],["62047.40","0.173"],["62048.50","0.025"],["62058.70","0.082"],["62061.20","0.034"],["62068.40","0.012"],["62662.40","0.001"],["62853.40","0.318"],["63278.60","0.030"],["63559.50","0.000"],["65702.50","1.520"]],"b":[["11541.90","2.720"],["11641.90","0.992"],["11741.90","1.088"],["49633.50","0.000"],["55837.70","0.002"],["58932.20","0.010"],["59560.20","0.019"],["61264.80","0.000"],["61421.50","0.000"],["61731.70","0.012"],["61834.40","0.001"],["61963.00","0.065"],["61963.40","1.088"],["61963.60","6.334"],["61963.90","0.049"],["61984.50","0.035"],["62000.00","9.008"],["62023.30","0.131"],["62024.90","0.584"],["62033.20","0.030"],["62033.50","0.106"],["62033.70","0.001"],["62039.60","0.085"]],"e":"depthUpdate","ps":"BTCUSDT","pu":10998399267977,"s":"BTCUSDT","st":1,"u":10998399273471}
{"E":1783504315922,"T":1783504315921,"U":10998399273725,"a":[["62042.00","9.236"],["62044.50","0.002"],["62045.20","0.000"],["62057.50","0.128"],["62060.60","0.004"],["62061.10","0.535"],["62063.30","0.002"],["62064.20","0.027"],["62067.30","0.491"],["62068.40","0.012"],["62072.30","0.051"],["62073.50","0.486"],["62173.20","0.670"],["62187.30","0.014"],["62432.30","0.018"],["62434.70","0.159"],["62662.40","0.001"],["62892.00","6.233"]],"b":[["1000.00","210.542"],["11541.90","2.736"],["11641.90","0.992"],["11741.90","0.944"],["11941.90","0.128"],["55837.70","0.002"],["59560.20","0.022"],["61251.80","3.259"],["61421.50","0.000"],["61834.40","0.002"],["61879.30","0.060"],["61907.10","0.043"],["61962.80","0.680"],["61973.70","0.001"],["61994.10","0.055"],["61999.30","0.061"],["61999.60","0.120"],["62000.50","0.064"],["62002.80","0.139"],["62006.10","1.222"],["62016.10","0.324"],["62020.20","0.809"],["62022.30","0.163"],["62028.50","0.081"],["62029.50","0.130"],["62041.90","4.888"]],"e":"depthUpdate","ps":"BTCUSDT","pu":10998399273471,"s":"BTCUSDT","st":1,"u":10998399279033}
{"E":1783504316024,"T":1783504316021,"U":10998399279146,"a":[["62044.50","0.002"],["62045.80","0.128"],["62047.10","1.362"],["62048.50","0.001"],["62049.00","1.382"],["62054.50","0.472"],["62058.70","0.002"],["62060.60","0.132"],["62067.40","0.659"],["62173.30","0.649"],["62194.80","1.072"],["62662.40","0.001"],["62786.50","9.274"],["63034.70","0.444"]],"b":[["1000.00","210.542"],["11541.90","2.720"],["11641.90","0.992"],["11741.90","0.816"],["11941.90","0.272"],["49634.00","0.000"],["55837.70","0.002"],["59560.20","0.019"],["61421.50","0.000"],["61727.70","0.010"],["61731.70","0.002"],["61834.40","0.001"],["61886.00","1.052"],["61907.60","3.395"],["61999.40","0.061"],["62000.00","9.128"],["62033.70","0.025"],["62041.90","4.653"]],"e":"depthUpdate","ps":"BTCUSDT","pu":10998399279033,"s":"BTCUSDT","st":1,"u":10998399286957}
{"E":1783504316126,"T":1783504316125,"U":10998399287174,"a":[["62042.00","9.377"],["62043.00","0.085"],["62044.50","0.002"],["62045.20","0.000"],["62047.20","0.227"],["62049.00","1.302"],["62054.50","0.456"],["62066.80","0.128"],["62070.40","0.031"],["62080.90","0.021"],["62662.40","0.001"],["62662.50","0.002"],["62996.10","0.000"]],"b":[["11541.90","2.736"],["11641.90","0.992"],["11741.90","0.672"],["11941.90","0.400"],["55837.70","0.002"],["61071.60","0.080"],["61421.50","0.000"],["61834.40","0.002"],["61979.60","0.002"],["61996.10","0.014"],["61997.70","0.009"],["61999.30","0.121"],["61999.40","0.181"],["61999.50","0.061"],["61999.90","0.063"],["62000.60","0.078"],["62004.20","0.001"],["62005.20","0.568"],["62011.50","0.042"],["62015.90","0.016"],["62020.50","0.000"],["62020.80","0.002"],["62022.10","0.018"],["62041.90","4.653"]],"e":"depthUpdate","ps":"BTCUSDT","pu":10998399286957,"s":"BTCUSDT","st":1,"u":10998399293756}
{"E":1783504316228,"T":1783504316225,"U":10998399293895,"a":[["62045.20","0.000"],["62045.80","0.680"],["62057.50","0.000"],["62072.20","0.072"],["62662.40","0.001"],["62798.40","1.692"],["63278.60","0.027"]],"b":[["1000.00","210.542"],["11541.90","2.592"],["11641.90","1.056"],["11741.90","0.544"],["11941.90","0.608"],["49634.00","0.000"],["55837.70","0.002"],["59560.20","0.022"],["61080.10","0.031"],["61297.40","2.860"],["61304.00","0.004"],["61421.50","0.000"],["61834.40","0.001"],["61997.70","0.005"],["61998.20","0.000"],["62005.20","0.572"],["62023.30","0.131"]],"e":"depthUpdate","ps":"BTCUSDT","pu":10998399293756,"s":"BTCUSDT","st":1,"u":10998399301295}
{"E":1783504316330,"T":1783504316329,"U":10998399301618,"a":[["62043.00","0.005"],["62045.20","0.000"],["62045.80","0.128"],["62047.10","1.914"],["62047.20","0.211"],["62048.00","0.003"],["62049.10","0.404"],["62049.80","0.102"],["62051.20","0.293"],["62054.90","0.067"],["62057.50","0.128"],["62063.50","2.385"],["62066.80","0.000"],["62075.30","0.554"],["62100.70","0.205"],["62173.30","0.649"],["62662.40","0.001"],["63003.90","0.013"]],"b":[["1000.00","210.542"],["11541.90","2.320"],["11641.90","1.200"],["11741.90","0.400"],["11941.90","0.880"],["49634.00","0.004"],["55837.70","0.002"],["59560.20","0.019"],["61421.50","0.000"],["61727.70","0.010"],["61731.60","0.002"],["61834.40","0.002"],["61907.60","3.393"],["61988.20","0.060"],["61995.40","0.136"],["62003.50","0.075"],["62020.20","0.681"],["62026.60","0.000"],["62029.50","0.002"],["62040.20","0.037"],["62041.90","4.548"]],"e":"depthUpdate","ps":"BTCUSDT","pu":10998399301295,"s":"BTCUSDT","st":1,"u":10998399309344}
{"E":1783504316432,"T":1783504316429,"U":10998399309516,"a":[["62042.00","9.377"],["62042.80","0.061"],["62045.20","0.000"],["62045.80","0.680"],["62046.20","0.426"],["62047.10","1.362"],["62049.10","0.324"],["62054.70","0.080"],["62054.90","0.051"],["62062.10","0.042"],["62063.50","2.446"],["62112.20","1.231"],["62134.50","0.797"],["62254.60","0.160"],["62313.90","0.027"],["62352.30","0.002"],["62662.40","0.001"]],"b":[["11541.90","2.048"],["11641.90","1.328"],["11741.90","0.272"],["11941.90","1.152"],["49634.00","0.000"],["55837.70","0.002"],["59560.20","0.022"],["60177.30","0.000"],["61421.50","0.000"],["61731.70","0.001"],["61834.40","0.001"],["61975.10","1.226"],["61977.20","0.444"],["61978.80","0.686"],["62002.80","0.221"],["62007.60","0.726"],["62007.70","0.004"],["62007.80","0.003"],["62020.80","0.004"],["62023.70","0.003"],["62023.80","0.001"],["62023.90","0.002"],["62039.60","0.003"],["62041.90","4.569"]],"e":"depthUpdate","ps":"BTCUSDT","pu":10998399309344,"s":"BTCUSDT","st":1,"u":10998399316941}
{"E":1783504316534,"T":1783504316532,"U":10998399317179,"a":[["62045.80","0.128"],["62051.40","0.267"],["62054.70","0.000"],["62057.90","0.009"],["62058.00","0.087"],["62062.10","0.026"],["62067.40","0.659"],["62086.50","0.014"],["62662.40","0.001"],["62915.50","0.004"]],"b":[["1000.00","210.542"],["11541.90","1.776"],["11641.90","1.472"],["11741.90","0.128"],["11941.90","1.424"],["55837.70","0.002"],["59560.20","0.019"],["61421.50","0.000"],["61731.60","0.001"],["61834.40","0.002"],["61981.20","0.323"],["62023.30","0.003"],["62026.80","0.002"],["62033.20","0.006"]],"e":"depthUpdate","ps":"BTCUSDT","pu":10998399316941,"s":"BTCUSDT","st":1,"u":10998399323501}
{"E":1783504316636,"T":1783504316634,"U":10998399323575,"a":[["62045.00","0.081"],["62045.80","0.128"],["62050.50","0.064"],["62051.40","0.187"],["62058.00","0.071"],["62089.70","0.688"],["62136.90","0.013"],["62352.30","0.003"],["62731.50","0.000"],["62886.20","4.887"]],"b":[["1000.00","210.542"],["11541.90","1.504"],["11641.90","1.600"],["11741.90","0.000"],["11941.90","1.696"],["55837.70","0.002"],["60000.00","124.275"],["60149.20","2.409"],["61328.40","0.422"],["61421.50","0.000"],["61503.70","0.001"],["61507.70","0.009"],["61588.00","66.203"],["61727.70","0.010"],["61733.30","0.161"],["61737.30","0.016"],["61834.40","0.001"],["61955.60","0.249"],["61955.70","0.001"],["61985.30","0.037"],["61997.70","0.009"],["62005.20","0.568"],["62029.50","0.130"],["62039.60","0.085"]],"e":"depthUpdate","ps":"BTCUSDT","pu":10998399323501,"s":"BTCUSDT","st":1,"u":10998399329811}
{"E":1783504316738,"T":1783504316737,"U":10998399329883,"a":[["62045.00","0.001"],["62045.80","0.128"],["62046.50","0.005"],["62048.20","0.202"],["62049.70","0.125"],["62050.10","0.164"],["62050.50","0.048"],["62051.30","0.173"],["62052.10","0.453"],["62052.80","0.127"],["62056.80","0.018"],["62057.50","0.000"],["62065.80","0.052"],["62066.20","0.104"],["62132.30","2.619"],["62620.70","6.326"],["62662.40","0.001"],["62923.00","2.683"]],"b":[["11541.90","1.376"],["11641.90","1.456"],["11941.90","1.968"],["55837.70","0.002"],["59560.20","0.022"],["61297.40","4.489"],["61421.50","0.000"],["61834.40","0.002"],["61951.60","5.217"],["61997.70","0.005"]],"e":"depthUpdate","ps":"BTCUSDT","pu":10998399329811,"s":"BTCUSDT","st":1,"u":10998399336830}
{"E":1783504316840,"T":1783504316837,"U":10998399336942,"a":[["62047.10","1.362"],["62050.10","0.084"],["62054.10","0.081"],["62056.80","0.002"],["62057.50","0.128"],["62061.70","2.162"],["62633.10","0.005"],["62662.40","0.001"],["62667.30","1.195"],["62798.50","0.269"]],"b":[["1000.00","210.542"],["11541.90","1.232"],["11641.90","1.328"],["11941.90","2.240"],["49633.50","0.000"],["55837.70","0.002"],["58932.20","0.012"],["59560.20","0.019"],["61297.40","4.766"],["61421.50","0.000"],["61834.40","0.001"],["61967.00","0.052"],["61995.40","0.008"],["62002.80","0.139"],["62005.20","0.572"],["62023.30","0.131"]],"e":"depthUpdate","ps":"BTCUSDT","pu":10998399336830,"s":"BTCUSDT","st":1,"u":10998399342537}
{"E":1783504316942,"T":1783504316941,"U":10998399342751,"a":[["62047.00","0.553"],["62048.60","0.005"],["62051.00","0.332"],["62054.10","0.001"],["62058.00","0.087"],["62060.60","0.132"],["62061.70","2.146"],["63274.70","0.006"]],"b":[["1000.00","210.542"],["11541.90","1.104"],["11641.90","1.184"],["11941.90","2.512"],["55837.70","0.002"],["59560.20","0.022"],["60797.10","0.010"],["61421.50","0.000"],["61727.70","0.000"],["61731.70","0.011"],["61834.40","0.002"],["61979.60","0.002"],["61998.40","0.018"],["62002.80","0.139"],["62005.20","0.568"],["62029.50","0.002"],["62039.60","0.085"]],"e":"depthUpdate","ps":"BTCUSDT","pu":10998399342537,"s":"BTCUSDT","st":1,"u":10998399347721}
{"E":1783504317044,"T":1783504317043,"U":10998399347845,"a":[["62047.00","0.553"],["62047.40","0.175"],["62049.60","1.067"],["62050.60","0.324"],["62050.70","1.379"],["62052.40","0.750"],["62067.40","0.649"],["62075.30","0.554"],["62100.40","0.102"],["62100.60","0.101"],["62100.70","0.205"],["62173.30","0.637"],["62631.30","1.035"],["62662.40","0.003"]],"b":[["11541.90","0.992"],["11641.90","1.056"],["11841.90","0.032"],["11941.90","2.720"],["55837.70","0.002"],["58932.30","0.045"],["61314.50","0.822"],["61317.60","0.000"],["61421.50","0.000"],["61731.70","0.012"],["61834.40","0.001"],["61907.60","2.752"],["61907.80","0.755"],["61929.70","0.000"],["61995.40","0.136"],["62002.80","0.221"],["62033.90","1.149"],["62041.90","4.568"]],"e":"depthUpdate","ps":"BTCUSDT","pu":10998399347721,"s":"BTCUSDT","st":1,"u":10998399353361}
{"E":1783504317146,"T":1783504317145,"U":10998399353394,"a":[["62042.00","9.471"],["62045.20","0.000"],["62045.70","0.564"],["62045.80","0.128"],["62047.00","0.001"],["62047.80","1.017"],["62050.60","0.002"],["62051.00","0.252"],["62052.40","0.170"],["62052.60","0.339"],["62058.00","0.071"],["62067.40","0.659"],["62100.60","0.101"],["62100.70","0.104"],["62662.40","0.001"],["62662.50","0.001"],["62732.60","0.244"],["62817.50","0.824"],["62910.60","2.392"],["63274.70","0.000"],["63278.50","0.000"]],"b":[["1000.00","210.542"],["11541.90","0.992"],["11641.90","0.912"],["11841.90","0.160"],["11941.90","2.736"],["55837.70","0.002"],["58932.30","0.006"],["58939.80","0.003"],["59560.20","0.019"],["60801.10","0.080"],["61421.50","0.000"],["61834.40","0.002"],["61964.30","0.037"],["61995.40","0.008"],["62023.30","0.003"],["62029.50","0.130"],["62030.70","0.041"],["62033.50","0.004"],["62034.50","0.131"],["62039.50","0.000"],["62039.60","0.003"],["62041.00","0.104"],["62041.90","4.569"]],"e":"depthUpdate","ps":"BTCUSDT","pu":10998399353361,"s":"BTCUSDT","st":1,"u":10998399362605}
{"E":1783504317248,"T":1783504317247,"U":10998399362668,"a":[["62042.00","12.262"],["62042.10","0.006"],["62042.50","0.028"],["62042.70","0.006"],["62042.90","0.001"],["62043.00","0.054"],["62043.10","0.824"],["62043.50","0.005"],["62043.60","0.259"],["62044.10","1.363"],["62044.20","0.943"],["62044.30","0.004"],["62044.50","0.002"],["62045.10","0.324"],["62045.20","0.653"],["62045.30","0.821"],["62045.40","0.004"],["62045.60","0.060"],["62045.70","0.902"],["62045.80","0.258"],["62046.20","0.424"],["62046.40","0.833"],["62046.60","1.340"],["62046.80","0.059"],["62046.90","0.000"],["62047.00","0.826"],["62047.60","0.051"],["62047.70","0.012"],["62047.80","1.001"],["62048.10","0.025"],["62048.20","0.571"],["62048.30","0.657"],["62048.40","0.290"],["62048.50","0.025"],["62048.60","0.825"],["62048.70","0.000"],["62048.90","0.832"],["62049.30","0.128"],["62049.50","0.568"],["62049.80","0.096"],["62049.90","0.003"],["62050.20","0.003"],["62050.60","0.002"],["62050.70","1.375"],["62050.80","0.058"],["62050.90","0.866"],["62051.10","0.648"],["62051.50","0.241"],["62052.60","0.001"],["62052.70","0.004"],["62053.10","0.002"],["62053.30","0.661"],["62054.80","0.584"],["62055.10","0.002"],["62055.40","0.130"],["62055.50","0.035"],["62056.30","0.000"],["62056.60","0.282"],["62057.00","0.009"],["62057.20","0.011"],["62057.50","0.128"],["62057.80","0.122"],["62059.30","0.061"],["62060.50","0.000"],["62060.60","0.134"],["62061.10","0.454"],["62061.60","0.011"],["62061.80","0.000"],["62062.20","0.127"],["62062.30","1.844"],["62062.80","0.004"],["62063.50","2.448"],["62064.40","0.001"],["62067.30","0.330"],["62067.50","0.697"],["62067.80","0.011"],["62068.10","0.263"],["62068.20","2.475"],["62068.40","0.004"],["62069.00","0.049"],["62069.10","0.009"],["62069.60","0.020"],["62069.80","0.002"],["62069.90","0.283"],["62070.70","0.171"],["62072.60","0.246"],["62073.50","0.164"],["62074.00","0.030"],["62074.90","0.359"],["62075.00","5.772"],["62075.10","0.320"],["62075.20","0.010"],["62075.30","0.360"],["62075.40","9.353"],["62077.20","1.434"],["62079.60","0.342"],["62080.00","1.075"],["62080.70","0.299"],["62081.80","0.121"],["62082.70","0.092"],["62084.40","0.766"],["62087.70","0.001"],["62088.80","0.003"],["62089.30","0.000"],["62089.50","0.035"],["62096.70","0.000"],["62097.80","12.112"],["62099.40","0.101"],["62099.50","1.463"],["62099.80","0.606"],["62100.40","0.001"],["62100.60","0.000"],["62109.60","0.016"],["62115.80","19.557"],["62160.00","0.564"],["62198.50","0.000"],["62240.00","0.625"],["62320.00","0.561"],["62400.00","14.516"],["62428.80","0.018"],["62432.30","0.000"],["62644.00","0.013"],["62662.40","0.005"],["63278.60","0.015"]],"b":[["1000.00","210.542"],["11541.90","0.992"],["11641.90","0.784"],["11841.90","0.304"],["11941.90","2.720"],["55837.70","0.002"],["58381.40","1.711"],["58939.80","0.003"],["59560.20","0.022"],["60793.40","0.003"],["60801.10","0.095"],["60892.40","0.000"],["61134.00","9.111"],["61262.40","0.277"],["61352.90","0.019"],["61421.50","0.006"],["61603.50","0.011"],["61612.20","0.032"],["61612.30","0.000"],["61680.00","1.117"],["61731.70","0.002"],["61754.00","0.374"],["61760.00","0.609"],["61834.40","0.001"],["61840.00","0.449"],["61920.00","0.522"],["61933.50","0.001"],["61942.00","0.426"],["61942.60","0.270"],["61963.40","0.632"],["61964.30","0.193"],["61965.00","0.022"],["61967.00","0.001"],["61971.80","0.026"],["61976.30","0.682"],["61978.80","0.670"],["61979.60","0.000"],["61982.70","0.027"],["61983.00","0.832"],["61984.20","1.998"],["61988.20","0.002"],["61993.10","0.001"],["61993.20","0.326"],["61993.50","0.003"],["61994.80","0.096"],["61995.10","0.003"],["61996.20","0.001"],["61997.30","0.052"],["61997.70","0.002"],["61998.00","0.303"],["62000.00","9.259"],["62000.30","0.016"],["62002.80","0.089"],["62002.90","0.025"],["62003.00","0.091"],["62003.20","0.017"],["62003.30","0.353"],["62003.50","0.059"],["62005.10","0.000"],["62006.20","0.020"],["62007.20","0.127"],["62007.80","0.000"],["62008.90","0.136"],["62009.40","0.059"],["62009.90","1.389"],["62010.40","0.009"],["62011.00","0.006"],["62011.70","0.057"],["62012.00","0.001"],["62012.20","0.050"],["62012.60","1.299"],["62013.70","0.219"],["62014.00","0.137"],["62014.40","0.582"],["62015.00","0.006"],["62015.80","2.461"],["62015.90","0.000"],["62016.10","0.002"],["62016.20","0.001"],["62016.40","0.787"],["62016.50","0.178"],["62016.60","0.002"],["62016.70","0.005"],["62016.80","1.459"],["62016.90","0.543"],["62017.10","0.458"],["62017.80","0.015"],["62018.00","0.195"],["62018.10","0.008"],["62018.20","0.000"],["62019.00","1.545"],["62019.10","0.565"],["62019.40","0.011"],["62019.70","0.001"],["62019.80","0.009"],["62019.90","0.003"],["62020.20","0.681"],["62020.50","0.000"],["62020.70","0.014"],["62020.80","0.002"],["62021.20","0.000"],["62021.40","1.363"],["62021.60","1.073"],["62021.90","0.001"],["62022.10","0.725"],["62022.20","0.003"],["62022.30","0.042"],["62022.50","0.324"],["62023.30","0.003"],["62023.60","0.005"],["62023.70","0.023"],["62024.40","0.241"],["62024.50","1.467"],["62024.60","0.294"],["62024.70","0.901"],["62024.90","0.004"],["62025.80","0.323"],["62026.50","0.019"],["62026.60","0.040"],["62027.00","0.069"],["62027.50","0.002"],["62027.60","0.328"],["62027.70","0.689"],["62028.00","1.467"],["62028.30","0.122"],["62028.50","0.000"],["62028.60","0.492"],["62028.80","0.012"],["62028.90","0.033"],["62029.00","0.000"],["62029.10","0.032"],["62029.30","0.003"],["62029.40","0.011"],["62029.50","1.213"],["62029.90","0.636"],["62030.00","0.004"],["62030.10","0.006"],["62030.20","0.822"],["62030.30","0.003"],["62030.40","0.002"],["62030.50","0.001"],["62030.70","1.403"],["62030.80","0.000"],["62031.00","0.045"],["62031.10","0.000"],["62031.50","0.052"],["62031.60","0.012"],["62031.70","0.001"],["62031.90","0.004"],["62032.20","0.057"],["62032.30","0.000"],["62032.40","0.001"],["62032.50","0.010"],["62033.20","0.006"],["62033.40","0.051"],["62033.70","0.001"],["62033.80","0.027"],["62033.90","1.123"],["62034.00","1.811"],["62034.10","0.043"],["62034.20","0.005"],["62034.30","0.902"],["62034.40","0.001"],["62034.60","0.003"],["62035.00","0.005"],["62035.30","0.000"],["62035.70","0.004"],["62035.90","0.001"],["62036.00","0.000"],["62036.10","0.003"],["62036.40","0.002"],["62036.60","0.000"],["62036.70","0.091"],["62036.80","0.002"],["62036.90","0.004"],["62037.10","0.036"],["62037.30","0.000"],["62037.50","0.005"],["62037.60","0.001"],["62037.80","0.001"],["62037.90","0.000"],["62038.00","0.003"],["62038.10","0.001"],["62038.20","0.000"],["62038.60","0.001"],["62038.70","0.000"],["62038.80","0.002"],["62039.60","0.000"],["62040.20","0.000"],["62041.00","0.103"],["62041.80","0.015"],["62041.90","0.481"]],"e":"depthUpdate","ps":"BTCUSDT","pu":10998399362605,"s":"BTCUSDT","st":1,"u":10998399384257}
{"E":1783504317350,"T":1783504317349,"U":10998399384289,"a":[["62042.00","10.792"],["62042.10","0.006"],["62042.40","1.247"],["62042.60","0.003"],["62043.00","0.056"],["62043.50","0.003"],["62043.80","0.016"],["62043.90","0.004"],["62044.00","0.886"],["62045.10","0.002"],["62045.20","0.500"],["62045.70","0.153"],["62047.40","0.177"],["62047.70","0.012"],["62048.60","0.002"],["62048.90","0.001"],["62050.50","0.048"],["62050.60","0.002"],["62053.10","0.324"],["62053.30","0.741"],["62054.00","0.011"],["62061.60","0.075"],["62062.20","0.063"],["62063.00","0.354"],["62080.60","0.005"],["62097.70","2.004"],["62098.20","0.101"],["62098.50","0.009"],["62098.70","0.002"],["62099.00","0.026"],["62099.40","0.101"],["62099.50","1.463"],["62109.50","19.684"],["62115.80","0.282"],["62662.40","0.005"],["62748.60","0.251"],["62781.50","0.000"],["62817.50","1.093"],["63278.60","0.009"],["63282.80","0.028"]],"b":[["11541.90","0.992"],["11641.90","0.640"],["11841.90","0.432"],["11941.90","2.736"],["55837.70","0.002"],["58932.30","0.000"],["58939.80","0.006"],["59000.00","30.902"],["59560.20","0.019"],["60797.10","0.004"],["60801.10","0.104"],["61157.00","0.291"],["61421.50","0.002"],["61607.60","0.000"],["61731.70","0.003"],["61834.40","0.001"],["61860.40","0.000"],["61955.90","1.252"],["61976.30","0.778"],["61976.70","0.000"],["62013.00","0.022"],["62020.30","0.008"],["62022.60","0.002"],["62024.00","0.024"],["62025.40","0.713"],["62026.40","0.153"],["62027.40","0.212"],["62028.40","0.169"],["62028.60","0.490"],["62029.50","1.085"],["62029.60","0.305"],["62030.20","0.001"],["62030.30","0.026"],["62030.80","0.968"],["62034.40","0.005"],["62035.60","0.001"],["62035.70","0.004"]],"e":"depthUpdate","ps":"BTCUSDT","pu":10998399384257,"s":"BTCUSDT","st":1,"u":10998399404558}
{"E":1783504317452,"T":1783504317451,"U":10998399404599,"a":[["62042.00","10.727"],["62043.00","0.007"],["62043.50","0.022"],["62043.80","0.000"],["62044.00","0.902"],["62044.20","0.822"],["62044.50","0.026"],["62045.20","0.368"],["62045.80","0.126"],["62046.80","0.053"],["62047.60","0.051"],["62047.70","0.012"],["62048.10","0.001"],["62048.40","0.296"],["62048.50","0.001"],["62048.90","0.001"],["62049.30","0.130"],["62049.50","0.004"],["62050.40","0.273"],["62050.50","0.048"],["62050.60","0.566"],["62050.90","0.141"],["62052.00","0.727"],["62056.20","0.636"],["62057.10","0.005"],["62059.10","0.135"],["62061.60","0.207"],["62075.30","0.449"],["62107.50","0.286"],["62109.50","19.684"],["62191.30","0.000"],["62203.80","1.016"],["62352.30","0.002"],["62627.40","0.278"],["62662.40","0.005"],["62812.50","0.013"],["63278.60","0.003"],["63282.80","0.034"]],"b":[["1000.00","210.692"],["11541.90","1.088"],["11641.90","0.512"],["11841.90","0.672"],["11941.90","2.528"],["55837.70","0.002"],["58939.80","0.006"],["59560.20","0.022"],["60797.10","0.001"],["60801.10","0.110"],["60879.00","1.059"],["61138.40","1.147"],["61421.50","0.000"],["61731.60","0.002"],["61834.40","0.002"],["61975.60","0.177"],["61976.10","0.098"],["61976.20","0.917"],["61976.30","0.680"],["61981.10","0.027"],["62014.40","0.001"],["62016.40","1.368"],["62019.10","0.001"],["62020.30","0.572"],["62021.90","0.001"],["62022.50","0.002"],["62023.70","0.039"],["62024.50","1.465"],["62026.60","0.000"],["62027.50","0.004"],["62028.10","1.327"],["62028.20","0.747"],["62029.60","0.013"],["62030.90","0.323"],["62031.10","0.005"],["62033.00","0.017"],["62034.60","0.002"],["62036.10","0.019"],["62036.20","0.049"],["62036.40","0.005"],["62037.10","0.000"],["62037.50","0.003"],["62038.70","0.036"]],"e":"depthUpdate","ps":"BTCUSDT","pu":10998399404558,"s":"BTCUSDT","st":1,"u":10998399418273}
{"E":1783504317554,"T":1783504317553,"U":10998399418300,"a":[["62042.00","10.744"],["62043.50","0.006"],["62043.80","0.000"],["62043.90","0.004"],["62044.00","0.000"],["62045.70","0.000"],["62048.20","0.443"],["62048.90","0.001"],["62050.50","0.950"],["62052.00","0.002"],["62053.10","1.049"],["62054.80","0.004"],["62055.60","0.582"],["62057.90","0.009"],["62059.30","0.002"],["62062.00","0.084"],["62075.20","0.010"],["62075.30","0.554"],["62099.60","3.554"],["62662.40","0.005"],["62762.10","7.139"],["62783.10","0.000"],["63278.60","0.000"],["63282.80","0.040"]],"b":[["1000.00","210.542"],["11541.90","1.232"],["11641.90","0.368"],["11841.90","0.944"],["11941.90","2.256"],["49634.00","0.002"],["55837.70","0.002"],["58939.80","0.006"],["60801.10","0.113"],["61221.90","0.970"],["61316.00","0.759"],["61421.50","0.000"],["61731.70","0.014"],["61834.40","0.001"],["62019.00","0.819"],["62021.80","2.024"],["62026.80","0.002"],["62034.10","0.044"],["62038.80","0.001"],["62041.00","0.104"]],"e":"depthUpdate","ps":"BTCUSDT","pu":10998399418273,"s":"BTCUSDT","st":1,"u":10998399431081}
{"E":1783504317656,"T":1783504317655,"U":10998399431120,"a":[["62042.00","10.744"],["62046.70","0.241"],["62048.90","0.011"],["62050.70","1.875"],["62059.60","0.204"],["62060.60","0.132"],["62062.30","1.764"],["62063.50","2.450"],["62063.60","0.024"],["62066.10","0.002"],["62070.40","0.017"],["62075.30","0.449"],["62079.10","0.014"],["62282.40","0.000"],["62290.30","0.724"],["62352.30","0.001"],["62438.10","0.000"],["62446.10","0.150"],["62594.20","0.000"],["62602.20","0.030"],["62662.40","0.001"],["63282.80","0.049"],["63531.00","0.502"]],"b":[["11541.90","1.360"],["11641.90","0.240"],["11841.90","1.216"],["11941.90","1.984"],["49634.00","0.000"],["55837.70","0.004"],["58939.80","0.009"],["59560.20","0.019"],["60801.10","0.116"],["61235.40","0.979"],["61421.50","0.004"],["61478.80","0.092"],["61486.60","0.016"],["61632.50","0.000"],["61640.30","0.009"],["61834.40","0.002"],["61996.10","0.014"],["62005.20","0.568"],["62019.00","0.119"],["62029.60","0.305"],["62030.30","0.003"],["62030.70","0.041"],["62031.00","0.792"],["62031.40","0.000"],["62041.90","0.497"]],"e":"depthUpdate","ps":"BTCUSDT","pu":10998399431081,"s":"BTCUSDT","st":1,"u":10998399443883}
{"E":1783504317758,"T":1783504317757,"U":10998399443910,"a":[["62041.10","15.035"],["62041.20","0.002"],["62041.30","0.564"],["62041.40","1.629"],["62041.70","0.745"],["62041.80","1.803"],["62041.90","2.196"],["62042.00","0.432"],["62042.10","0.002"],["62042.20","0.000"],["62042.40","0.003"],["62042.60","0.004"],["62042.70","0.188"],["62042.80","0.053"],["62043.00","0.005"],["62043.10","0.003"],["62043.50","0.132"],["62043.60","0.001"],["62043.70","0.126"],["62043.90","0.002"],["62044.00","0.577"],["62044.20","0.001"],["62044.70","0.023"],["62045.10","0.000"],["62045.20","0.368"],["62045.30","0.000"],["62045.40","0.003"],["62045.60","0.060"],["62045.70","0.000"],["62045.80","0.731"],["62046.00","0.009"],["62046.10","0.471"],["62046.20","0.424"],["62046.40","0.012"],["62046.70","0.000"],["62047.00","0.005"],["62047.10","1.362"],["62047.70","0.002"],["62048.20","0.121"],["62048.40","0.290"],["62048.80","0.000"],["62048.90","0.903"],["62049.20","0.001"],["62049.40","0.725"],["62049.50","0.004"],["62049.60","1.069"],["62050.50","0.048"],["62050.60","0.002"],["62050.90","0.140"],["62052.10","0.606"],["62052.20","0.060"],["62052.70","0.004"],["62053.10","0.364"],["62053.20","0.649"],["62053.50","0.602"],["62054.20","0.343"],["62054.40","0.013"],["62054.90","0.171"],["62055.50","0.000"],["62055.60","0.002"],["62056.40","1.426"],["62057.00","0.001"],["62057.50","0.000"],["62057.80","0.002"],["62058.00","0.151"],["62058.60","0.156"],["62059.10","0.003"],["62059.40","0.757"],["62059.60","0.121"],["62059.80","0.016"],["62060.60","0.004"],["62060.70","0.013"],["62061.60","0.143"],["62062.20","0.168"],["62062.30","1.904"],["62063.80","0.000"],["62064.50","0.059"],["62064.90","0.246"],["62066.10","0.002"],["62066.60","0.298"],["62067.00","0.133"],["62067.40","0.649"],["62067.50","0.681"],["62067.80","0.003"],["62068.10","0.263"],["62068.30","5.012"],["62068.70","0.001"],["62069.10","0.001"],["62070.20","1.379"],["62070.70","0.171"],["62071.40","1.132"],["62072.00","0.001"],["62072.10","0.071"],["62072.60","0.277"],["62072.70","1.440"],["62073.00","0.245"],["62073.40","0.105"],["62073.50","0.269"],["62073.80","0.089"],["62074.30","0.001"],["62074.90","0.522"],["62075.00","5.578"],["62075.30","0.360"],["62076.00","0.006"],["62079.10","0.000"],["62079.80","0.687"],["62080.00","1.078"],["62080.70","0.299"],["62081.30","0.884"],["62082.20","0.000"],["62082.40","0.020"],["62082.70","0.088"],["62084.60","0.102"],["62084.70","0.573"],["62085.50","0.003"],["62088.80","0.006"],["62089.50","0.032"],["62089.70","0.688"],["62092.20","0.026"],["62093.50","0.003"],["62093.90","0.082"],["62094.10","0.779"],["62097.50","0.096"],["62097.70","2.004"],["62098.20","0.000"],["62098.90","0.035"],["62099.40","0.015"],["62099.50","1.362"],["62099.60","3.453"],["62109.50","0.000"],["62112.90","0.001"],["62115.80","0.282"],["62115.90","20.226"],["62117.90","0.001"],["62118.60","0.000"],["62121.80","0.101"],["62127.10","0.028"],["62128.00","4.779"],["62131.10","0.990"],["62135.00","2.757"],["62223.10","0.000"],["62223.20","0.006"],["62289.30","0.245"],["62294.60","0.138"],["62424.80","0.018"],["62428.80","0.000"],["62441.50","0.480"],["62661.50","0.004"],["62662.30","0.000"],["62662.40","0.001"],["62817.50","1.888"],["62980.70","0.072"],["63023.70","0.000"],["63025.50","0.003"],["63026.30","0.000"],["63041.90","0.006"],["63280.20","0.000"],["63281.90","0.007"],["63282.80","0.049"]],"b":[["1000.00","210.542"],["11541.00","0.064"],["11541.80","0.016"],["11541.90","1.424"],["11641.90","0.096"],["11841.00","0.128"],["11841.90","1.360"],["11941.90","1.712"],["55836.90","0.002"],["55837.70","0.000"],["58157.40","0.000"],["58938.90","0.000"],["59560.20","0.022"],["60800.20","0.003"],["60801.10","0.119"],["60841.60","0.000"],["61420.60","0.004"],["61421.40","0.894"],["61421.50","0.058"],["61607.50","0.002"],["61607.60","0.000"],["61731.60","0.003"],["61786.50","0.000"],["61794.40","0.541"],["61834.40","0.001"],["61857.00","0.001"],["61860.10","0.001"],["61880.10","1.389"],["61882.90","0.155"],["61889.20","0.000"],["61902.40","0.001"],["61941.00","0.016"],["61948.90","0.002"],["61965.80","0.000"],["61975.90","0.004"],["61981.40","0.045"],["61987.30","0.065"],["61987.90","0.151"],["61990.60","1.296"],["61990.90","0.002"],["61991.30","0.273"],["61993.20","0.325"],["61994.50","1.370"],["61994.80","0.033"],["61995.30","0.003"],["61995.40","0.071"],["61995.50","0.013"],["61997.00","1.203"],["61997.30","0.055"],["61998.00","0.300"],["61998.20","0.000"],["61998.80","0.004"],["62000.00","9.261"],["62003.80","0.403"],["62005.00","1.532"],["62006.70","0.000"],["62007.50","0.144"],["62008.20","0.053"],["62008.90","0.133"],["62009.60","0.016"],["62010.10","0.003"],["62010.40","0.001"],["62010.90","0.022"],["62011.30","0.002"],["62011.70","0.049"],["62013.80","1.410"],["62013.90","0.877"],["62014.00","0.097"],["62014.10","0.002"],["62014.80","0.013"],["62015.00","0.006"],["62015.10","0.404"],["62015.80","2.459"],["62016.30","0.350"],["62016.40","0.775"],["62016.60","0.010"],["62016.80","1.338"],["62016.90","0.540"],["62018.10","0.000"],["62018.20","0.726"],["62018.90","0.889"],["62019.30","0.064"],["62020.30","0.008"],["62020.50","0.020"],["62020.70","0.034"],["62021.80","1.298"],["62021.90","0.323"],["62022.10","0.018"],["62023.10","0.001"],["62023.70","0.023"],["62024.00","0.004"],["62024.10","0.061"],["62024.40","0.243"],["62024.70","0.820"],["62025.20","0.031"],["62026.20","0.122"],["62026.50","0.017"],["62026.70","0.004"],["62027.30","0.062"],["62027.50","0.002"],["62028.00","1.469"],["62028.10","0.034"],["62028.60","1.079"],["62028.70","0.002"],["62029.40","0.257"],["62029.50","0.002"],["62029.60","0.013"],["62029.90","0.660"],["62030.10","0.002"],["62030.30","0.003"],["62030.70","0.002"],["62030.80","0.712"],["62030.90","0.001"],["62031.10","0.343"],["62031.20","0.648"],["62031.40","0.000"],["62032.80","0.002"],["62033.80","0.023"],["62033.90","0.323"],["62034.00","0.689"],["62034.10","0.047"],["62034.30","0.000"],["62034.40","0.157"],["62034.60","0.000"],["62035.90","0.050"],["62036.20","0.036"],["62036.40","0.000"],["62036.50","0.001"],["62036.70","0.042"],["62038.70","0.000"],["62039.20","0.001"],["62039.40","0.001"],["62040.00","0.001"],["62040.10","0.008"],["62040.90","0.003"],["62041.00","0.214"],["62041.30","0.000"],["62041.70","0.000"],["62041.80","0.000"],["62041.90","0.000"]],"e":"depthUpdate","ps":"BTCUSDT","pu":10998399443883,"s":"BTCUSDT","st":1,"u":10998399465878}
{"E":1783504317860,"T":1783504317859,"U":10998399465917,"a":[["62041.10","13.271"],["62041.20","0.002"],["62041.30","0.001"],["62041.40","1.456"],["62041.70","0.530"],["62041.80","1.803"],["62041.90","2.075"],["62042.00","0.392"],["62044.00","0.581"],["62044.60","0.323"],["62045.10","0.241"],["62046.10","0.149"],["62047.00","0.005"],["62047.10","1.684"],["62047.70","0.002"],["62048.80","0.564"],["62048.90","0.581"],["62049.40","0.000"],["62049.60","1.067"],["62049.90","0.001"],["62050.10","0.406"],["62050.50","0.048"],["62051.60","1.025"],["62053.50","0.022"],["62054.40","0.585"],["62054.90","0.051"],["62055.60","0.010"],["62056.00","1.420"],["62056.40","1.362"],["62058.00","0.071"],["62059.10","0.133"],["62059.60","0.201"],["62061.00","0.769"],["62061.60","0.143"],["62062.00","0.064"],["62062.20","0.063"],["62062.30","1.799"],["62064.90","0.001"],["62066.90","0.853"],["62070.10","0.120"],["62073.80","0.091"],["62074.80","0.252"],["62074.90","0.522"],["62081.80","0.125"],["62083.70","0.083"],["62084.30","0.001"],["62085.60","0.012"],["62096.80","0.001"],["62097.80","12.213"],["62098.20","0.000"],["62099.00","0.127"],["62099.40","0.015"],["62107.60","0.693"],["62109.60","20.231"],["62115.90","0.011"],["62119.90","0.007"],["62661.50","0.008"],["63281.90","0.019"]],"b":[["11541.00","0.160"],["11541.90","1.392"],["11641.90","0.000"],["11841.00","0.400"],["11941.00","0.032"],["11941.90","1.440"],["49632.80","0.000"],["55836.90","0.002"],["58932.20","0.010"],["59560.20","0.019"],["60800.20","0.009"],["61281.70","0.000"],["61420.60","0.004"],["61421.50","0.059"],["61730.80","0.001"],["61731.70","0.014"],["61779.90","0.743"],["61834.40","0.002"],["61857.00","0.000"],["61953.30","0.000"],["61964.00","0.091"],["61967.40","0.013"],["61971.10","0.030"],["61972.50","0.585"],["61975.60","0.273"],["61976.10","0.002"],["61978.40","1.466"],["61979.50","20.709"],["61979.90","0.083"],["61980.70","5.985"],["61981.00","0.436"],["61987.30","0.009"],["61989.10","0.001"],["61994.40","0.034"],["61995.40","0.008"],["61998.70","1.959"],["62003.80","0.403"],["62007.10","0.169"],["62014.00","0.137"],["62014.70","0.351"],["62021.30","2.146"],["62021.90","0.323"],["62022.30","0.002"],["62024.00","0.008"],["62028.60","1.079"],["62028.70","0.002"],["62028.80","0.008"],["62028.90","0.853"],["62029.40","0.011"],["62031.10","0.005"],["62031.20","0.003"],["62031.30","0.908"],["62031.40","0.097"],["62032.70","0.486"],["62032.80","0.296"],["62032.90","0.000"],["62034.00","1.012"],["62034.10","0.194"],["62034.50","0.002"],["62034.60","0.886"],["62034.70","0.130"],["62035.50","0.051"],["62041.00","0.214"]],"e":"depthUpdate","ps":"BTCUSDT","pu":10998399465878,"s":"BTCUSDT","st":1,"u":10998399487834}
{"E":1783504317962,"T":1783504317961,"U":10998399487862,"a":[["62041.10","13.339"],["62041.60","0.000"],["62041.80","1.862"],["62042.00","0.391"],["62042.20","0.002"],["62042.90","0.003"],["62044.00","0.577"],["62047.00","0.015"],["62047.70","0.012"],["62048.90","0.017"],["62050.60","0.566"],["62053.60","0.326"],["62056.00","1.300"],["62057.10","0.125"],["62080.00","1.060"],["62084.60","0.001"],["62085.00","0.552"],["62092.30","0.016"],["62098.20","0.000"],["62099.00","0.127"],["62099.40","0.000"],["62099.50","1.362"],["62160.00","0.546"],["62240.00","0.607"],["62320.00","0.543"],["62400.00","14.498"],["62661.50","0.006"],["63281.90","0.028"]],"b":[["11541.90","1.248"],["11841.00","0.672"],["11941.00","0.176"],["11941.90","1.168"],["55836.90","0.002"],["58938.90","0.000"],["58939.80","0.006"],["58939.90","0.003"],["59559.30","0.003"],["60800.20","0.021"],["60882.40","0.703"],["61264.70","0.016"],["61299.60","1.967"],["61420.60","0.006"],["61421.50","0.001"],["61544.70","0.000"],["61680.00","1.099"],["61760.00","0.591"],["61834.40","0.001"],["61840.00","0.431"],["61920.00","0.504"],["61975.20","0.392"],["61975.60","0.177"],["61978.10","0.085"],["61984.50","0.020"],["61985.00","0.739"],["62000.00","9.243"],["62016.40","0.733"],["62018.20","0.000"],["62018.90","0.325"],["62020.20","0.716"],["62020.30","0.572"],["62021.00","0.726"],["62021.50","0.002"],["62024.80","0.086"],["62025.20","0.003"],["62026.20","0.124"],["62026.50","0.040"],["62028.70","0.000"],["62028.80","0.006"],["62029.40","0.011"],["62030.60","0.325"],["62031.40","0.016"],["62032.30","0.004"],["62032.70","0.633"],["62032.90","0.147"],["62033.30","0.004"],["62034.00","1.159"],["62034.10","0.194"],["62034.20","0.327"],["62034.60","0.564"],["62035.70","0.002"],["62036.80","0.030"],["62040.70","0.004"],["62041.00","0.216"]],"e":"depthUpdate","ps":"BTCUSDT","pu":10998399487834,"s":"BTCUSDT","st":1,"u":10998399503822}
{"E":1783504318064,"T":1783504318063,"U":10998399503849,"a":[["62041.10","14.622"],["62041.20","0.295"],["62041.30","0.629"],["62041.50","0.000"],["62041.70","0.001"],["62041.80","1.803"],["62041.90","2.077"],["62042.00","0.390"],["62042.10","0.002"],["62042.20","0.000"],["62042.70","0.180"],["62056.50","0.700"],["62074.20","0.089"],["62074.80","0.163"],["62074.90","0.522"],["62084.70","0.472"],["62085.40","0.035"],["62092.30","0.001"],["62098.20","0.000"],["62099.00","0.026"],["62099.40","0.000"],["62192.50","0.000"],["62192.60","1.528"],["62223.20","0.003"],["62223.40","0.416"],["62542.20","0.002"],["62661.50","0.006"],["62817.40","0.269"],["62996.80","0.282"],["63281.90","0.040"]],"b":[["1000.00","210.542"],["11541.90","1.120"],["11841.00","0.944"],["11941.00","0.304"],["11941.90","0.896"],["55836.90","0.002"],["58938.90","0.000"],["60800.20","0.024"],["61154.80","5.096"],["61241.10","0.003"],["61283.20","8.310"],["61420.60","0.008"],["61730.80","0.002"],["61834.40","0.002"],["61944.00","0.003"],["61944.20","0.005"],["62032.70","0.486"],["62032.90","0.000"],["62034.00","1.012"],["62034.10","0.044"],["62035.40","0.003"],["62040.00","0.003"]],"e":"depthUpdate","ps":"BTCUSDT","pu":10998399503822,"s":"BTCUSDT","st":1,"u":10998399517007}
{"E":1783504318166,"T":1783504318165,"U":10998399517023,"a":[["62041.10","14.163"],["62041.30","0.629"],["62041.40","1.456"],["62041.50","0.000"],["62041.60","0.000"],["62041.70","0.001"],["62041.80","1.803"],["62041.90","2.077"],["62042.70","0.131"],["62044.30","0.028"],["62045.10","0.000"],["62045.60","0.301"],["62045.70","0.153"],["62045.80","0.578"],["62047.70","0.002"],["62056.50","0.000"],["62059.60","0.265"],["62061.00","0.705"],["62080.00","1.078"],["62160.00","0.564"],["62240.00","0.625"],["62320.00","0.561"],["62400.00","14.516"],["62661.50","0.004"],["63281.90","0.052"]],"b":[["11541.90","0.976"],["11841.00","1.216"],["11941.00","0.448"],["11941.90","0.624"],["49633.00","0.000"],["55836.90","0.002"],["58938.90","0.000"],["59239.90","0.000"],["59559.30","0.000"],["60800.20","0.027"],["61420.60","0.002"],["61680.00","1.117"],["61731.70","0.014"],["61736.70","0.009"],["61737.30","0.008"],["61760.00","0.609"],["61834.40","0.001"],["61840.00","0.449"],["61860.00","0.212"],["61920.00","0.522"],["61942.00","0.294"],["61942.60","0.138"],["61963.80","0.142"],["61975.90","0.002"],["61981.00","0.568"],["62000.00","9.261"],["62003.30","0.306"],["62008.20","0.006"],["62014.60","0.290"],["62020.60","0.000"],["62029.90","0.613"],["62030.10","0.025"],["62030.40","0.004"],["62032.90","0.297"],["62033.00","0.314"],["62034.00","1.012"],["62034.10","0.341"],["62037.50","0.001"],["62041.00","0.367"]],"e":"depthUpdate","ps":"BTCUSDT","pu":10998399517007,"s":"BTCUSDT","st":1,"u":10998399530005}
{"E":1783504318268,"T":1783504318266,"U":10998399530059,"a":[["62041.10","10.773"],["62041.40","1.453"],["62041.50","0.000"],["62041.70","0.001"],["62041.80","1.803"],["62041.90","2.013"],["62042.00","0.373"],["62042.10","0.001"],["62043.70","0.005"],["62044.10","1.365"],["62044.30","0.004"],["62045.00","0.017"],["62046.00","0.003"],["62046.60","0.963"],["62047.00","0.005"],["62047.70","0.002"],["62048.30","0.663"],["62048.80","0.000"],["62049.20","0.000"],["62050.30","0.577"],["62050.60","0.002"],["62051.60","0.300"],["62052.00","0.002"],["62053.00","0.292"],["62053.10","0.928"],["62053.20","0.650"],["62054.00","0.011"],["62054.20","1.068"],["62054.40","0.005"],["62055.60","0.002"],["62055.90","0.582"],["62057.10","0.005"],["62057.60","0.010"],["62058.30","0.120"],["62060.20","0.278"],["62063.50","2.448"],["62063.60","0.022"],["62066.40","1.456"],["62070.20","1.365"],["62075.00","5.772"],["62078.50","0.145"],["62085.40","0.020"],["62093.80","0.082"],["62107.50","20.501"],["62109.60","0.016"],["62661.50","0.000"],["62755.20","3.091"],["62755.90","12.319"],["62922.60","0.000"],["63281.90","0.055"]],"b":[["11541.90","0.848"],["11741.00","0.064"],["11841.00","1.424"],["11841.90","1.296"],["11941.00","0.576"],["11941.90","0.416"],["55836.90","0.002"],["58005.70","0.000"],["58938.90","0.000"],["59559.30","0.003"],["60474.00","0.000"],["60800.20","0.039"],["61203.40","5.783"],["61252.20","4.047"],["61300.00","88.693"],["61420.60","0.000"],["61834.40","0.002"],["61946.40","0.166"],["61958.70","0.000"],["61964.30","0.037"],["61968.10","0.047"],["61971.10","0.030"],["61982.10","0.164"],["61987.00","0.056"],["61994.80","0.049"],["61995.10","0.064"],["61996.10","0.000"],["61998.70","1.960"],["62002.80","0.007"],["62003.80","0.417"],["62004.20","0.017"],["62007.30","0.047"],["62008.70","0.327"],["62012.50","1.180"],["62013.80","1.289"],["62013.90","0.296"],["62014.90","0.344"],["62016.60","0.026"],["62016.90","0.661"],["62017.10","1.039"],["62019.70","0.048"],["62020.30","0.008"],["62021.10","0.001"],["62021.90","0.001"],["62023.60","0.569"],["62023.70","0.023"],["62024.40","0.241"],["62024.90","1.004"],["62027.50","0.004"],["62027.70","0.909"],["62028.10","1.329"],["62029.00","0.000"],["62029.10","0.032"],["62030.80","1.144"],["62031.40","0.404"],["62032.00","0.050"],["62032.20","0.877"],["62032.80","0.002"],["62032.90","0.000"],["62033.00","0.017"],["62033.10","0.157"],["62034.10","0.126"],["62034.20","0.907"],["62034.40","0.004"],["62034.60","0.000"],["62035.40","0.000"],["62036.20","0.000"],["62037.30","0.003"],["62038.50","0.034"],["62038.80","0.002"],["62039.50","0.001"],["62039.80","0.000"],["62040.00","0.052"],["62040.40","0.001"],["62040.90","0.004"],["62041.00","2.717"]],"e":"depthUpdate","ps":"BTCUSDT","pu":10998399530005,"s":"BTCUSDT","st":1,"u":10998399540155}
{"E":1783504318370,"T":1783504318369,"U":10998399540453,"a":[["62041.10","10.632"],["62041.20","0.003"],["62041.30","0.631"],["62041.40","0.091"],["62041.90","2.012"],["62042.00","0.292"],["62042.10","0.000"],["62042.20","0.000"],["62042.40","0.052"],["62042.80","0.004"],["62043.30","0.000"],["62043.80","0.001"],["62043.90","1.364"],["62044.00","0.433"],["62044.10","0.003"],["62045.00","0.001"],["62045.60","0.060"],["62046.10","0.149"],["62046.50","0.085"],["62047.10","1.362"],["62047.60","0.051"],["62048.10","0.323"],["62055.90","0.002"],["62057.50","0.580"],["62058.30","0.000"],["62059.10","0.001"],["62059.80","0.006"],["62060.20","0.398"],["62060.30","0.018"],["62061.50","0.011"],["62061.60","0.011"],["62062.00","0.005"],["62063.30","0.000"],["62064.80","1.189"],["62066.90","0.833"],["62068.20","1.638"],["62068.30","0.012"],["62072.60","0.172"],["62072.70","1.335"],["62073.00","0.140"],["62073.40","0.000"],["62073.50","0.164"],["62074.80","0.295"],["62075.10","0.340"],["62075.30","0.471"],["62094.50","0.000"],["62095.20","0.057"],["62095.30","0.000"],["62096.20","0.002"],["62097.50","0.228"],["62097.70","1.903"],["62107.30","3.689"],["62124.80","0.582"],["62538.90","0.000"],["62661.50","0.002"],["62755.20","4.038"],["62755.90","11.372"]],"b":[["1000.00","210.542"],["11541.90","0.704"],["11741.00","0.192"],["11841.00","1.568"],["11841.90","1.168"],["11941.00","0.720"],["11941.90","0.272"],["55836.90","0.002"],["58622.80","0.000"],["58932.20","0.007"],["59559.30","0.000"],["59857.00","0.000"],["61242.60","1.829"],["61295.80","3.552"],["61420.60","0.002"],["61444.30","1.531"],["61506.80","0.008"],["61507.70","0.001"],["61730.80","0.003"],["61834.40","0.001"],["61963.80","0.010"],["61968.10","0.000"],["61980.70","8.896"],["61981.00","0.436"],["61981.10","0.159"],["62002.80","0.088"],["62008.70","0.005"],["62021.00","0.000"],["62023.90","0.728"],["62024.80","0.005"],["62024.90","0.004"],["62026.40","1.153"],["62027.60","0.328"],["62029.00","0.047"],["62029.10","0.032"],["62030.10","0.002"],["62030.20","0.024"],["62030.90","1.363"],["62031.40","0.322"],["62033.40","0.172"],["62034.10","0.044"],["62034.20","0.005"],["62034.30","0.000"],["62034.40","0.342"],["62034.50","0.566"],["62034.80","0.082"],["62038.00","0.003"],["62041.00","3.391"]],"e":"depthUpdate","ps":"BTCUSDT","pu":10998399540155,"s":"BTCUSDT","st":1,"u":10998399548163}
{"E":1783504318472,"T":1783504318469,"U":10998399548212,"a":[["62041.10","10.626"],["62041.30","0.629"],["62041.70","0.003"],["62041.90","2.008"],["62042.00","0.277"],["62042.30","0.003"],["62042.40","0.003"],["62042.70","0.179"],["62044.10","0.002"],["62044.50","0.002"],["62044.70","0.003"],["62045.00","0.024"],["62046.50","0.005"],["62047.00","0.005"],["62048.00","0.244"],["62049.60","1.087"],["62050.30","0.013"],["62053.20","0.649"],["62053.40","0.367"],["62058.00","0.091"],["62060.30","0.002"],["62063.00","0.370"],["62073.80","0.089"],["62074.90","0.417"],["62075.10","0.320"],["62075.20","0.009"],["62094.50","0.000"],["62094.60","0.099"],["62095.20","0.018"],["62095.30","0.039"],["62097.80","12.112"],["62105.40","20.232"],["62107.30","0.770"],["62107.50","0.286"],["62643.80","0.704"],["62661.50","0.000"],["62755.20","4.985"],["62755.90","10.425"]],"b":[["11541.90","0.576"],["11741.00","0.336"],["11841.00","1.696"],["11841.90","1.024"],["11941.00","0.848"],["11941.90","0.144"],["49634.00","0.000"],["55836.90","0.002"],["58938.90","0.000"],["58939.00","0.106"],["59559.30","0.003"],["60801.10","0.116"],["61420.60","0.000"],["61730.80","0.003"],["61731.60","0.002"],["61731.70","0.004"],["61834.40","0.002"],["61981.00","0.436"],["61981.10","0.027"],["61982.50","0.016"],["62014.00","0.097"],["62018.40","0.021"],["62018.60","0.373"],["62020.50","0.000"],["62020.70","0.014"],["62025.30","0.003"],["62025.80","0.363"],["62026.40","1.153"],["62027.90","0.065"],["62029.90","0.589"],["62030.60","0.348"],["62031.50","0.068"],["62031.80","0.020"],["62033.30","0.824"],["62034.10","0.608"],["62034.40","0.824"],["62034.50","0.538"],["62034.60","0.000"],["62041.00","3.815"]],"e":"depthUpdate","ps":"BTCUSDT","pu":10998399548163,"s":"BTCUSDT","st":1,"u":10998399555577}
{"E":1783504318574,"T":1783504318573,"U":10998399555793,"a":[["62041.10","3.251"],["62041.20","0.005"],["62041.30","0.076"],["62041.40","0.000"],["62041.70","0.000"],["62041.80","0.002"],["62041.90","0.048"],["62042.30","0.001"],["62042.50","0.026"],["62042.60","0.002"],["62042.70","0.130"],["62042.90","0.001"],["62043.00","0.101"],["62043.40","0.004"],["62043.50","0.129"],["62043.80","0.001"],["62043.90","0.002"],["62044.00","0.425"],["62044.10","0.002"],["62044.50","0.003"],["62044.60","0.005"],["62045.00","0.003"],["62045.20","0.000"],["62045.30","0.000"],["62045.50","0.068"],["62045.60","0.583"],["62045.70","0.774"],["62045.80","0.126"],["62046.00","0.003"],["62046.10","0.151"],["62046.20","0.132"],["62046.30","0.068"],["62046.50","0.005"],["62046.60","0.963"],["62046.70","0.001"],["62047.10","0.000"],["62047.20","0.051"],["62047.30","0.657"],["62047.40","0.175"],["62048.00","1.365"],["62048.10","0.001"],["62048.30","0.657"],["62048.60","0.025"],["62048.80","0.000"],["62048.90","0.001"],["62049.00","0.007"],["62049.10","0.324"],["62049.60","1.067"],["62049.70","0.127"],["62050.00","0.323"],["62050.10","0.084"],["62050.20","0.005"],["62050.50","1.410"],["62050.60","0.004"],["62050.70","0.513"],["62050.90","0.160"],["62051.20","0.060"],["62051.80","0.028"],["62052.00","0.155"],["62052.10","0.453"],["62052.20","0.001"],["62052.50","0.609"],["62053.00","1.654"],["62053.10","0.002"],["62053.30","0.661"],["62053.40","0.287"],["62053.80","0.293"],["62053.90","0.001"],["62054.00","0.011"],["62054.20","0.343"],["62055.70","0.581"],["62055.80","0.004"],["62055.90","2.981"],["62056.00","0.005"],["62056.40","0.000"],["62057.00","0.003"],["62057.50","0.000"],["62057.60","0.002"],["62057.70","0.325"],["62057.80","0.003"],["62057.90","0.007"],["62058.00","0.851"],["62058.40","0.734"],["62058.50","1.706"],["62059.10","0.001"],["62059.20","0.002"],["62059.30","0.002"],["62059.60","0.201"],["62060.20","0.278"],["62060.50","0.040"],["62061.00","0.593"],["62061.10","0.425"],["62061.20","0.035"],["62061.50","0.001"],["62061.60","2.246"],["62062.40","1.299"],["62062.70","0.004"],["62063.00","0.354"],["62063.80","0.010"],["62063.90","0.404"],["62064.80","1.130"],["62065.70","0.121"],["62066.00","1.010"],["62066.60","0.282"],["62066.90","0.531"],["62067.00","0.141"],["62067.80","0.003"],["62068.00","0.171"],["62068.10","0.108"],["62068.20","1.077"],["62068.30","0.004"],["62068.50","0.005"],["62069.00","0.049"],["62069.40","0.008"],["62069.70","0.003"],["62069.80","0.002"],["62071.10","0.002"],["62071.40","0.418"],["62071.50","0.002"],["62072.10","0.383"],["62073.40","0.010"],["62073.70","0.010"],["62074.80","0.163"],["62075.40","9.458"],["62076.20","0.140"],["62076.40","0.158"],["62077.10","0.165"],["62077.40","0.162"],["62077.70","0.163"],["62078.00","0.063"],["62078.40","0.779"],["62079.20","0.186"],["62079.60","0.342"],["62079.80","0.690"],["62079.90","0.000"],["62080.00","1.075"],["62080.30","0.053"],["62080.50","0.014"],["62080.60","0.006"],["62080.70","0.296"],["62081.80","0.125"],["62082.10","0.002"],["62082.20","0.002"],["62082.40","0.018"],["62087.60","0.002"],["62087.70","0.001"],["62088.30","0.015"],["62088.50","3.780"],["62088.70","0.000"],["62088.80","0.001"],["62092.90","0.317"],["62093.20","0.022"],["62093.40","0.089"],["62093.50","0.000"],["62094.10","0.771"],["62094.20","0.699"],["62094.30","0.041"],["62094.40","0.713"],["62094.60","0.003"],["62094.90","0.169"],["62096.60","0.290"],["62097.80","12.109"],["62099.00","0.026"],["62105.40","0.017"],["62141.00","0.134"],["62198.50","0.213"],["62351.40","0.004"],["62537.40","0.319"],["62661.50","0.000"],["62707.50","4.533"],["62816.60","0.271"],["62817.20","1.583"],["62817.90","8.386"],["62848.50","1.119"],["63281.90","0.058"]],"b":[["11541.90","0.432"],["11741.00","0.464"],["11841.00","1.840"],["11841.90","0.896"],["11941.00","0.992"],["11941.90","0.000"],["55836.90","0.002"],["58938.90","0.000"],["60800.20","0.042"],["61056.60","0.001"],["61289.70","1.792"],["61420.60","0.000"],["61451.70","0.655"],["61606.70","0.248"],["61834.40","0.001"],["61836.80","0.001"],["61839.30","0.000"],["61935.90","0.028"],["61971.10","20.737"],["61979.50","0.002"],["61980.70","5.985"],["61981.40","0.070"],["61990.30","0.000"],["61990.60","1.296"],["61990.70","0.796"],["61990.90","0.000"],["61995.50","0.005"],["61995.60","0.009"],["61995.70","0.004"],["61995.80","0.951"],["61996.10","0.002"],["61996.80","0.002"],["61997.00","1.206"],["61997.20","0.444"],["61997.30","0.050"],["62002.80","0.170"],["62003.80","0.662"],["62005.00","1.535"],["62006.20","0.017"],["62007.40","0.002"],["62007.80","0.000"],["62008.00","0.018"],["62008.20","0.003"],["62009.40","0.000"],["62009.60","0.008"],["62010.40","0.001"],["62010.70","0.079"],["62010.90","0.014"],["62011.10","0.010"],["62011.60","0.011"],["62012.00","0.009"],["62012.30","0.683"],["62012.40","2.608"],["62012.50","1.182"],["62013.10","0.008"],["62013.60","0.679"],["62013.70","0.217"],["62014.80","0.001"],["62015.60","0.050"],["62015.90","0.000"],["62016.10","0.005"],["62016.30","0.347"],["62016.40","0.749"],["62016.60","0.018"],["62016.90","0.540"],["62017.10","0.460"],["62018.10","0.059"],["62018.90","0.335"],["62019.80","0.008"],["62020.00","0.319"],["62020.30","0.005"],["62020.70","0.014"],["62020.80","0.583"],["62021.50","0.010"],["62021.80","1.378"],["62022.50","0.002"],["62022.80","0.122"],["62023.60","0.006"],["62023.90","0.002"],["62024.10","0.059"],["62024.60","0.858"],["62024.70","0.000"],["62024.80","0.005"],["62025.40","0.081"],["62025.50","0.325"],["62025.80","1.049"],["62025.90","0.004"],["62026.40","0.173"],["62026.70","0.002"],["62026.80","0.000"],["62027.20","0.295"],["62027.30","0.062"],["62027.40","0.210"],["62027.50","0.002"],["62027.60","0.328"],["62027.70","0.689"],["62027.80","0.272"],["62028.00","1.467"],["62028.10","1.327"],["62028.20","1.000"],["62028.60","0.589"],["62028.90","0.033"],["62029.60","0.015"],["62029.70","0.003"],["62029.90","0.326"],["62030.10","0.004"],["62030.20","0.001"],["62030.40","0.007"],["62030.50","0.001"],["62030.60","0.325"],["62030.80","0.712"],["62031.00","0.297"],["62031.10","0.028"],["62031.40","0.000"],["62031.50","0.052"],["62031.80","0.000"],["62032.20","0.821"],["62032.80","0.002"],["62033.30","0.004"],["62033.40","0.174"],["62033.50","1.366"],["62033.90","0.325"],["62034.00","1.821"],["62034.10","0.607"],["62034.30","0.000"],["62034.40","0.820"],["62034.50","0.456"],["62034.60","1.295"],["62034.80","0.000"],["62034.90","0.584"],["62035.20","0.264"],["62035.30","0.001"],["62035.50","0.871"],["62035.60","0.799"],["62035.70","0.018"],["62035.80","0.003"],["62036.00","0.207"],["62036.30","0.005"],["62036.60","0.820"],["62037.30","0.000"],["62037.60","0.043"],["62037.70","0.821"],["62037.80","0.288"],["62038.10","0.324"],["62038.20","0.056"],["62038.50","0.000"],["62038.80","0.796"],["62040.70","0.002"],["62040.80","0.005"],["62041.00","6.332"]],"e":"depthUpdate","ps":"BTCUSDT","pu":10998399555577,"s":"BTCUSDT","st":1,"u":10998399569383}
{"E":1783504318676,"T":1783504318672,"U":10998399569483,"a":[["62041.10","6.052"],["62041.80","0.000"],["62042.40","0.008"],["62042.80","0.053"],["62042.90","0.003"],["62043.80","0.000"],["62043.90","0.003"],["62044.00","0.781"],["62044.60","0.000"],["62044.70","0.561"],["62044.80","0.327"],["62044.90","0.004"],["62045.40","0.069"],["62045.50","2.111"],["62045.60","0.581"],["62046.40","0.010"],["62046.60","0.963"],["62047.70","0.741"],["62047.80","0.001"],["62048.00","2.365"],["62048.90","0.001"],["62049.50","1.299"],["62051.00","0.252"],["62051.10","0.889"],["62051.40","0.193"],["62051.80","0.022"],["62052.50","0.368"],["62053.10","0.566"],["62053.70","0.000"],["62054.00","0.012"],["62055.10","0.000"],["62055.30","0.727"],["62055.70","0.097"],["62055.90","2.983"],["62057.40","0.179"],["62058.00","0.151"],["62058.40","0.009"],["62058.70","0.582"],["62061.00","0.013"],["62061.10","0.405"],["62062.10","0.046"],["62062.20","0.183"],["62065.60","0.001"],["62065.70","0.001"],["62066.60","0.322"],["62070.70","0.008"],["62074.90","0.549"],["62088.20","0.014"],["62093.80","0.067"],["62093.90","0.097"],["62094.90","0.073"],["62095.00","0.397"],["62103.30","0.000"],["62109.60","20.231"],["62141.00","0.002"],["62300.00","8.489"],["62422.40","0.018"],["62424.80","0.000"],["62661.50","0.000"],["62834.30","1.592"],["63163.90","0.002"],["63281.90","0.061"]],"b":[["1000.00","210.542"],["11541.90","0.304"],["11741.00","0.736"],["11841.90","0.624"],["11941.00","1.120"],["49633.00","0.000"],["55836.90","0.002"],["58938.90","0.000"],["59559.30","0.000"],["60947.90","3.330"],["61166.20","2.611"],["61224.30","0.000"],["61420.60","0.000"],["61834.40","0.002"],["61971.10","0.030"],["61979.50","20.707"],["61980.70","5.987"],["61997.00","1.205"],["62002.80","0.302"],["62003.00","0.001"],["62007.50","0.104"],["62009.90","1.479"],["62014.90","0.344"],["62015.30","0.109"],["62016.40","0.733"],["62017.40","0.101"],["62018.10","0.000"],["62018.90","0.325"],["62019.50","0.100"],["62019.60","1.784"],["62019.80","0.591"],["62020.80","0.002"],["62021.50","0.131"],["62021.90","0.001"],["62022.80","0.001"],["62023.60","0.005"],["62024.60","1.584"],["62025.40","0.001"],["62025.80","0.326"],["62028.30","1.024"],["62029.60","0.013"],["62030.10","0.002"],["62030.90","1.365"],["62031.10","0.005"],["62031.20","0.005"],["62032.10","0.002"],["62032.20","0.001"],["62032.30","0.000"],["62032.60","0.319"],["62032.70","0.490"],["62033.30","0.001"],["62033.40","0.196"],["62033.90","0.323"],["62034.10","0.043"],["62034.20","0.001"],["62034.50","0.006"],["62034.60","0.000"],["62034.90","0.452"],["62035.00","0.007"],["62035.30","0.005"],["62035.50","0.873"],["62035.60","0.389"],["62035.70","0.002"],["62036.90","0.007"],["62037.60","0.041"],["62037.90","0.001"],["62038.20","0.057"],["62038.50","0.003"],["62038.90","0.000"],["62040.80","0.002"],["62041.00","3.313"]],"e":"depthUpdate","ps":"BTCUSDT","pu":10998399569383,"s":"BTCUSDT","st":1,"u":10998399577927}
{"E":1783504318778,"T":1783504318777,"U":10998399578068,"a":[["62041.10","6.046"],["62043.40","0.006"],["62043.90","0.559"],["62044.60","0.001"],["62044.70","0.005"],["62045.40","0.067"],["62047.20","0.348"],["62047.80","0.002"],["62050.60","0.003"],["62055.70","0.017"],["62057.10","0.085"],["62057.40","0.163"],["62058.90","0.020"],["62068.10","5.108"],["62074.80","0.326"],["62077.80","1.439"],["62078.00","0.061"],["62351.40","0.005"],["62661.50","0.000"],["62717.40","0.785"],["62780.90","0.000"],["62817.20","2.371"],["62817.90","7.598"],["63928.10","0.000"]],"b":[["11541.90","0.160"],["11741.00","1.008"],["11841.90","0.352"],["11941.00","1.264"],["55836.90","0.002"],["58932.20","0.009"],["58938.90","0.000"],["59559.30","0.003"],["61135.00","0.384"],["61420.60","0.000"],["61730.80","0.003"],["61731.60","0.001"],["61834.40","0.001"],["61835.00","0.377"],["61972.50","0.149"],["61979.50","20.709"],["61980.70","5.985"],["61998.40","0.014"],["62004.70","0.013"],["62013.70","0.257"],["62017.40","0.061"],["62020.20","0.837"],["62021.50","0.010"],["62027.10","1.061"],["62027.70","0.829"],["62028.20","0.000"],["62032.70","0.514"],["62033.40","0.172"],["62040.40","0.000"],["62040.80","0.001"],["62041.00","3.233"]],"e":"depthUpdate","ps":"BTCUSDT","pu":10998399577927,"s":"BTCUSDT","st":1,"u":10998399584714}
{"E":1783504318880,"T":1783504318878,"U":10998399584779,"a":[["62041.10","6.056"],["62041.30","0.076"],["62041.90","0.048"],["62042.00","0.290"],["62043.80","0.000"],["62043.90","0.559"],["62046.30","0.435"],["62046.50","0.005"],["62047.20","0.051"],["62048.10","0.001"],["62048.20","0.124"],["62052.50","0.001"],["62057.10","0.005"],["62058.90","0.004"],["62061.60","2.326"],["62075.50","1.112"],["62076.20","0.035"],["62076.40","0.053"],["62077.10","0.060"],["62077.40","0.057"],["62077.70","0.058"],["62077.80","1.437"],["62080.00","0.898"],["62084.40","0.767"],["62088.20","0.013"],["62160.00","0.387"],["62173.30","0.003"],["62240.00","0.448"],["62320.00","0.384"],["62400.00","14.339"],["62661.50","0.000"],["62755.20","5.932"],["62755.90","9.478"],["63141.60","0.791"]],"b":[["1000.00","210.542"],["11541.90","0.032"],["11741.00","1.280"],["11841.90","0.080"],["11941.00","1.392"],["49632.80","0.000"],["55836.90","0.002"],["58938.90","0.000"],["59559.30","0.000"],["60955.30","1.311"],["61420.60","0.000"],["61680.00","0.940"],["61760.00","0.432"],["61834.40","0.002"],["61837.50","0.207"],["61840.00","0.272"],["61907.80","0.113"],["61920.00","0.345"],["62000.00","9.084"],["62036.00","0.000"],["62037.00","0.002"],["62040.00","0.052"],["62041.00","3.639"]],"e":"depthUpdate","ps":"BTCUSDT","pu":10998399584714,"s":"BTCUSDT","st":1,"u":10998399590885}
{"E":1783504318982,"T":1783504318981,"U":10998399591083,"a":[["62041.10","5.793"],["62043.90","0.559"],["62044.60","0.000"],["62045.40","0.230"],["62059.60","0.281"],["62061.60","2.246"],["62064.10","0.068"],["62075.00","5.667"],["62075.80","0.107"],["62080.00","1.075"],["62097.50","0.228"],["62160.00","0.564"],["62172.70","0.670"],["62240.00","0.625"],["62320.00","0.561"],["62400.00","14.516"],["62661.50","0.000"],["62755.20","6.879"],["62755.90","8.531"],["62817.20","3.947"],["62817.90","6.022"],["62848.50","1.437"],["62900.20","0.002"],["63281.90","0.064"],["63282.80","0.046"],["63903.30","2.266"]],"b":[["1000.00","210.542"],["11541.00","0.064"],["11541.80","0.000"],["11541.90","0.000"],["11741.00","1.552"],["11841.00","1.648"],["11841.90","0.000"],["11941.00","1.536"],["55836.90","0.002"],["58938.90","0.000"],["59559.30","0.003"],["61420.60","0.000"],["61680.00","1.117"],["61760.00","0.609"],["61779.90","0.063"],["61834.40","0.001"],["61840.00","0.449"],["61908.50","0.027"],["61920.00","0.522"],["61981.00","0.568"],["62000.00","9.261"],["62022.00","0.702"],["62037.90","0.003"],["62039.90","0.001"],["62040.00","0.003"],["62040.80","0.050"],["62041.00","3.496"]],"e":"depthUpdate","ps":"BTCUSDT","pu":10998399590885,"s":"BTCUSDT","st":1,"u":10998399595821}
{"E":1783504319084,"T":1783504319082,"U":10998399595914,"a":[["62041.10","5.735"],["62041.80","0.002"],["62042.30","0.001"],["62042.40","0.003"],["62042.60","0.002"],["62042.80","0.053"],["62042.90","0.001"],["62043.30","0.002"],["62043.80","0.006"],["62043.90","0.559"],["62044.70","0.003"],["62045.40","0.364"],["62045.60","0.583"],["62046.20","0.134"],["62047.20","0.200"],["62051.40","0.187"],["62052.80","0.133"],["62055.10","0.080"],["62057.90","0.023"],["62059.60","0.201"],["62062.50","0.700"],["62064.10","0.052"],["62066.60","0.282"],["62067.90","0.010"],["62068.10","0.110"],["62068.30","0.002"],["62068.70","0.041"],["62069.20","0.003"],["62074.90","0.417"],["62075.30","0.366"],["62075.80","0.002"],["62077.40","0.162"],["62077.70","0.163"],["62131.60","0.002"],["62194.80","0.023"],["62661.50","0.000"],["62793.10","5.574"],["62798.50","0.000"],["63282.80","0.043"]],"b":[["11541.00","0.000"],["11741.00","1.824"],["11841.00","1.440"],["11941.00","1.536"],["55836.90","0.002"],["58938.90","0.000"],["61110.40","0.373"],["61420.60","0.000"],["61546.20","0.000"],["61730.80","0.003"],["61834.40","0.002"],["61886.00","0.001"],["61944.20","0.002"],["61944.30","0.682"],["61981.00","0.436"],["62002.80","0.738"],["62002.90","0.107"],["62015.30","0.238"],["62022.10","0.150"],["62027.10","0.061"],["62028.20","1.000"],["62030.90","1.363"],["62033.40","0.174"],["62034.70","0.001"],["62038.50","0.000"],["62039.90","0.004"],["62040.60","0.050"],["62040.80","0.001"],["62041.00","6.057"]],"e":"depthUpdate","ps":"BTCUSDT","pu":10998399595821,"s":"BTCUSDT","st":1,"u":10998399603176}
{"E":1783504319186,"T":1783504319185,"U":10998399603274,"a":[["62041.10","0.000"],["62041.20","0.000"],["62041.30","0.000"],["62041.80","0.000"],["62041.90","0.000"],["62042.00","0.000"],["62042.30","0.000"],["62042.40","0.000"],["62042.50","0.000"],["62042.60","0.000"],["62042.70","0.000"],["62042.80","0.000"],["62042.90","0.000"],["62043.00","0.000"],["62043.10","0.000"],["62043.20","0.000"],["62043.30","0.000"],["62043.40","0.000"],["62043.50","0.000"],["62043.60","0.000"],["62043.70","0.000"],["62043.80","0.000"],["62043.90","0.000"],["62044.00","6.236"],["62044.10","0.006"],["62044.20","0.001"],["62044.50","0.002"],["62044.80","0.003"],["62045.00","0.001"],["62045.20","0.002"],["62045.30","0.005"],["62045.40","0.209"],["62045.50","0.004"],["62045.60","0.099"],["62045.70","0.000"],["62045.80","0.121"],["62046.00","0.002"],["62046.10","0.004"],["62046.20","0.132"],["62046.30","0.369"],["62046.50","0.004"],["62046.60","0.414"],["62046.70","0.000"],["62046.80","0.004"],["62046.90","0.049"],["62047.00","0.001"],["62047.20","0.002"],["62047.30","0.576"],["62047.40","0.124"],["62047.50","0.000"],["62047.60","0.003"],["62047.70","0.002"],["62047.80","0.001"],["62047.90","0.002"],["62048.00","0.003"],["62048.20","0.000"],["62048.30","0.657"],["62048.40","0.099"],["62048.60","0.002"],["62049.00","0.154"],["62049.10","0.324"],["62049.20","0.003"],["62049.30","0.011"],["62049.50","0.057"],["62049.60","0.765"],["62049.70","0.003"],["62050.00","0.082"],["62050.20","0.003"],["62050.40","0.273"],["62050.50","0.002"],["62050.60","1.050"],["62050.70","1.875"],["62050.80","0.059"],["62050.90","0.140"],["62051.00","1.256"],["62051.10","0.648"],["62051.20","0.001"],["62051.30","0.050"],["62051.40","0.251"],["62051.50","0.243"],["62051.80","0.072"],["62052.00","0.002"],["62052.10","0.001"],["62052.40","0.166"],["62052.80","0.049"],["62052.90","0.184"],["62053.00","0.355"],["62053.10","0.002"],["62053.20","2.011"],["62053.30","0.983"],["62053.40","0.289"],["62053.50","0.023"],["62053.80","0.001"],["62054.20","0.001"],["62055.10","0.153"],["62055.20","0.020"],["62055.30","0.002"],["62055.40","0.130"],["62055.50","0.008"],["62055.60","0.010"],["62055.70","0.179"],["62055.80","1.366"],["62055.90","0.004"],["62056.10","0.080"],["62056.50","0.000"],["62057.00","0.002"],["62057.10","0.011"],["62057.20","0.005"],["62057.90","0.007"],["62058.20","0.452"],["62058.30","0.342"],["62058.40","0.171"],["62058.50","0.344"],["62058.60","0.003"],["62058.70","0.566"],["62058.80","0.738"],["62059.20","0.164"],["62059.30","1.619"],["62059.50","0.688"],["62059.60","0.121"],["62059.70","0.005"],["62060.50","0.041"],["62061.00","0.005"],["62061.30","0.177"],["62061.50","1.678"],["62061.60","0.884"],["62061.80","0.000"],["62062.20","0.063"],["62062.30","1.844"],["62062.40","0.004"],["62062.60","0.664"],["62062.90","0.001"],["62063.10","0.324"],["62063.50","2.387"],["62063.80","0.000"],["62064.10","0.352"],["62064.60","0.580"],["62065.10","0.563"],["62065.40","0.040"],["62065.80","0.052"],["62065.90","1.365"],["62066.00","1.020"],["62066.30","0.001"],["62066.40","0.084"],["62067.00","0.125"],["62067.90","0.001"],["62068.00","0.122"],["62068.10","0.102"],["62068.80","0.121"],["62068.90","0.003"],["62069.00","1.411"],["62069.20","0.003"],["62069.40","0.000"],["62069.50","0.000"],["62069.80","0.164"],["62070.10","0.000"],["62070.20","0.003"],["62070.40","0.097"],["62070.50","0.050"],["62070.70","0.170"],["62071.30","0.365"],["62071.40","0.508"],["62071.50","0.002"],["62071.90","0.016"],["62072.20","0.002"],["62072.30","0.051"],["62072.50","0.013"],["62073.20","0.010"],["62073.40","0.000"],["62073.50","0.195"],["62074.50","0.023"],["62074.80","0.458"],["62074.90","0.549"],["62075.00","5.668"],["62075.20","0.058"],["62075.40","9.353"],["62075.50","1.007"],["62076.50","0.712"],["62076.60","0.000"],["62076.70","0.000"],["62077.10","0.000"],["62077.20","1.554"],["62077.30","0.010"],["62077.70","0.155"],["62077.80","1.545"],["62078.20","1.569"],["62078.40","0.779"],["62078.50","0.131"],["62078.60","0.106"],["62078.90","0.213"],["62079.00","4.503"],["62079.10","0.000"],["62079.70","0.071"],["62079.80","0.687"],["62080.50","0.060"],["62081.00","0.346"],["62081.30","0.884"],["62081.40","0.690"],["62082.20","0.003"],["62082.30","1.389"],["62082.90","0.947"],["62083.30","0.149"],["62083.40","0.712"],["62083.70","0.085"],["62083.90","0.002"],["62084.10","0.000"],["62084.20","0.098"],["62084.30","0.161"],["62084.40","0.755"],["62084.50","0.820"],["62084.80","1.367"],["62085.50","0.000"],["62086.50","0.074"],["62086.60","0.200"],["62087.30","0.000"],["62087.60","0.012"],["62088.50","3.777"],["62088.70","0.003"],["62089.30","0.002"],["62090.00","0.314"],["62090.20","0.000"],["62090.60","0.025"],["62090.70","0.006"],["62090.90","0.020"],["62091.70","0.042"],["62092.90","0.333"],["62093.40","0.096"],["62093.70","0.004"],["62093.90","0.082"],["62094.20","0.691"],["62094.90","0.283"],["62095.00","0.301"],["62095.90","1.101"],["62096.30","0.001"],["62096.60","0.287"],["62096.70","0.096"],["62097.10","0.001"],["62097.20","0.009"],["62097.50","0.096"],["62098.00","0.003"],["62098.20","0.028"],["62098.90","0.031"],["62099.90","1.117"],["62100.00","0.640"],["62100.10","0.009"],["62100.90","0.004"],["62101.10","0.004"],["62101.70","0.002"],["62101.80","0.016"],["62102.00","0.001"],["62102.60","0.000"],["62105.00","0.125"],["62105.10","0.022"],["62110.30","0.003"],["62112.20","1.231"],["62118.60","0.001"],["62120.50","1.363"],["62126.50","0.000"],["62127.00","0.000"],["62131.60","0.002"],["62135.60","0.003"],["62137.00","0.122"],["62148.20","0.026"],["62163.70","0.020"],["62172.60","1.524"],["62183.60","0.027"],["62194.20","2.370"],["62195.80","0.677"],["62421.00","0.503"],["62422.40","0.000"],["62511.10","0.001"],["62542.20","0.000"],["62661.50","0.000"],["62664.40","0.000"],["62755.20","2.144"],["62755.90","0.008"],["62758.00","13.244"],["62771.90","11.197"],["62817.20","0.795"],["62817.90","0.506"],["62820.10","10.179"],["63284.80","0.006"],["67559.10","0.000"],["67798.30","0.000"],["67953.80","0.001"],["68109.30","0.000"]],"b":[["1000.00","210.542"],["11741.00","2.000"],["11743.90","0.096"],["11841.00","1.264"],["11843.90","0.048"],["11941.00","1.392"],["55836.90","0.000"],["55839.50","0.002"],["58941.20","0.034"],["58941.70","0.000"],["59559.30","0.000"],["60500.00","311.980"],["61165.10","2.704"],["61420.60","0.000"],["61423.50","0.000"],["61606.70","0.003"],["61793.70","0.003"],["61834.40","0.001"],["61835.00","0.170"],["61835.40","0.331"],["61837.50","0.000"],["61881.50","0.025"],["61882.90","0.152"],["61886.90","1.043"],["61901.70","0.003"],["61908.50","0.664"],["61932.20","0.003"],["61939.00","0.008"],["61940.40","1.435"],["61940.90","1.131"],["61946.70","0.014"],["61946.90","0.001"],["61955.60","0.248"],["61957.00","0.001"],["61957.10","0.290"],["61960.30","0.031"],["61962.20","0.871"],["61963.80","0.013"],["61964.70","0.025"],["61971.00","20.352"],["61975.30","0.003"],["61975.50","0.688"],["61977.20","0.121"],["61978.60","0.233"],["61979.50","0.002"],["61979.90","0.083"],["61980.80","0.272"],["61981.00","0.568"],["61981.10","0.159"],["61981.70","0.016"],["61981.90","1.541"],["61982.30","0.001"],["61982.50","0.000"],["61982.60","0.003"],["61985.00","0.724"],["61987.90","0.361"],["61988.50","0.001"],["61989.30","0.044"],["61989.40","0.001"],["61989.90","0.099"],["61990.70","0.794"],["61991.30","0.246"],["61991.60","0.002"],["61991.70","0.027"],["61992.20","0.138"],["61992.60","0.000"],["61992.70","0.002"],["61993.30","0.002"],["61994.00","0.029"],["61994.40","0.024"],["61994.50","1.367"],["61995.20","0.778"],["61995.30","0.003"],["61995.40","0.000"],["61995.60","0.001"],["61996.10","0.002"],["61996.80","0.016"],["61997.00","1.202"],["61997.30","0.001"],["61997.70","0.004"],["61998.30","0.021"],["61998.50","0.691"],["61998.60","0.693"],["61998.70","1.960"],["61999.10","0.005"],["61999.40","0.181"],["61999.50","0.061"],["62000.20","1.033"],["62001.20","0.329"],["62002.40","2.458"],["62002.80","0.524"],["62002.90","0.107"],["62003.20","0.003"],["62003.30","0.296"],["62003.40","0.003"],["62003.60","0.013"],["62003.80","0.648"],["62003.90","0.001"],["62004.20","0.001"],["62005.00","1.530"],["62005.30","0.003"],["62006.30","0.806"],["62006.70","0.102"],["62007.30","0.047"],["62007.50","0.194"],["62008.00","0.003"],["62008.50","0.010"],["62008.60","0.292"],["62008.90","0.027"],["62009.30","0.005"],["62009.50","0.049"],["62009.80","0.690"],["62009.90","1.389"],["62010.40","0.004"],["62010.70","0.001"],["62010.90","0.084"],["62011.20","0.034"],["62011.50","0.042"],["62011.60","0.008"],["62011.70","0.001"],["62012.00","0.001"],["62012.10","0.655"],["62012.20","0.018"],["62012.50","1.172"],["62013.00","0.006"],["62013.30","0.012"],["62013.90","0.307"],["62014.10","0.002"],["62014.30","0.282"],["62014.50","0.033"],["62014.70","0.350"],["62014.90","0.352"],["62015.00","0.746"],["62015.10","0.412"],["62015.20","1.365"],["62015.30","0.109"],["62015.50","0.012"],["62015.60","0.001"],["62016.10","0.002"],["62016.40","0.685"],["62016.70","0.005"],["62016.90","0.530"],["62017.10","0.458"],["62017.20","1.014"],["62017.40","0.001"],["62017.60","0.335"],["62017.90","0.003"],["62018.50","0.976"],["62018.70","0.002"],["62019.00","0.119"],["62019.10","0.051"],["62019.50","0.148"],["62019.60","1.784"],["62019.70","0.050"],["62019.80","0.010"],["62019.90","0.099"],["62020.10","0.003"],["62020.20","0.716"],["62021.00","0.010"],["62021.10","0.003"],["62021.40","1.363"],["62021.50","0.002"],["62021.60","1.121"],["62021.70","0.780"],["62021.80","1.298"],["62022.00","0.701"],["62022.10","0.018"],["62022.20","0.013"],["62022.40","0.004"],["62022.90","0.146"],["62023.20","0.001"],["62023.30","0.052"],["62023.40","0.083"],["62023.50","1.881"],["62023.60","1.381"],["62023.70","0.058"],["62024.00","0.684"],["62024.20","1.362"],["62024.30","0.664"],["62024.50","1.341"],["62024.60","0.310"],["62024.70","0.121"],["62024.80","0.013"],["62025.20","0.004"],["62025.50","0.003"],["62025.90","0.004"],["62026.10","0.003"],["62026.40","0.176"],["62026.50","0.024"],["62027.00","0.001"],["62027.60","0.206"],["62027.70","0.687"],["62027.80","0.272"],["62028.20","0.000"],["62028.30","0.864"],["62028.40","1.914"],["62028.60","0.610"],["62028.70","0.000"],["62028.90","0.037"],["62029.20","0.005"],["62029.30","0.003"],["62029.60","0.013"],["62029.70","0.001"],["62029.90","0.648"],["62030.10","0.689"],["62030.60","0.324"],["62030.80","1.186"],["62030.90","1.367"],["62031.00","0.297"],["62031.10","1.005"],["62031.20","0.825"],["62031.30","0.088"],["62031.40","0.064"],["62031.50","0.054"],["62031.70","0.123"],["62032.20","0.003"],["62032.50","0.014"],["62033.00","0.001"],["62033.20","0.186"],["62033.40","0.204"],["62033.60","0.016"],["62034.10","0.037"],["62034.40","0.002"],["62034.50","1.297"],["62034.60","0.000"],["62035.20","0.002"],["62035.30","0.001"],["62035.50","0.051"],["62035.60","0.248"],["62035.70","0.129"],["62035.80","0.001"],["62036.10","0.003"],["62036.30","0.001"],["62036.60","0.000"],["62036.70","0.000"],["62037.00","0.001"],["62037.50","0.051"],["62037.60","0.001"],["62037.70","0.001"],["62037.80","0.289"],["62037.90","0.298"],["62038.00","0.003"],["62038.10","0.331"],["62038.20","0.041"],["62038.40","0.306"],["62038.50","0.001"],["62038.70","0.002"],["62038.80","0.033"],["62038.90","0.164"],["62039.60","0.042"],["62039.80","0.001"],["62039.90","0.001"],["62040.00","0.031"],["62040.60","0.102"],["62040.90","0.000"],["62041.00","0.006"],["62041.10","1.833"],["62041.20","0.001"],["62041.40","0.003"],["62041.70","0.000"],["62041.80","0.002"],["62041.90","0.000"],["62042.00","0.000"],["62042.40","0.002"],["62042.50","0.000"],["62042.60","0.001"],["62042.70","0.001"],["62042.80","0.000"],["62042.90","0.287"],["62043.00","0.000"],["62043.30","0.000"],["62043.40","0.002"],["62043.50","0.001"],["62043.60","0.002"],["62043.70","0.000"],["62043.80","0.003"],["62043.90","9.400"]],"e":"depthUpdate","ps":"BTCUSDT","pu":10998399603176,"s":"BTCUSDT","st":1,"u":10998399624495}
{"E":1783504319288,"T":1783504319287,"U":10998399624761,"a":[["62044.00","6.270"],["62044.10","0.002"],["62044.50","0.000"],["62044.70","0.007"],["62044.80","0.067"],["62045.40","0.241"],["62045.80","0.677"],["62046.10","0.002"],["62046.20","0.133"],["62046.60","0.570"],["62047.20","0.002"],["62047.90","0.324"],["62048.00","0.567"],["62048.10","0.339"],["62048.20","1.362"],["62048.40","0.005"],["62048.70","0.024"],["62049.50","0.057"],["62049.60","1.215"],["62049.70","0.013"],["62050.20","0.003"],["62050.30","0.335"],["62050.50","0.832"],["62050.60","0.164"],["62050.90","0.592"],["62052.70","0.296"],["62052.80","1.344"],["62052.90","0.164"],["62053.10","0.003"],["62053.30","0.661"],["62053.40","0.290"],["62054.00","0.253"],["62054.10","0.021"],["62054.40","0.005"],["62054.80","0.004"],["62055.50","0.000"],["62055.60","0.002"],["62055.70","0.179"],["62056.10","0.080"],["62057.60","0.566"],["62057.70","0.617"],["62058.10","0.820"],["62058.70","0.002"],["62059.30","1.297"],["62059.50","0.004"],["62060.50","0.001"],["62061.00","0.005"],["62061.90","0.053"],["62062.10","0.026"],["62062.50","0.000"],["62063.70","0.027"],["62063.90","0.444"],["62064.90","0.050"],["62065.80","0.050"],["62066.10","0.247"],["62067.20","0.067"],["62067.40","0.649"],["62067.70","0.763"],["62068.10","0.102"],["62068.80","0.433"],["62068.90","0.164"],["62069.20","13.515"],["62070.40","0.033"],["62070.90","2.131"],["62071.00","0.082"],["62071.30","0.357"],["62071.40","0.418"],["62072.00","0.009"],["62072.10","0.071"],["62072.50","0.005"],["62073.20","0.012"],["62075.00","5.672"],["62075.20","0.009"],["62075.30","0.471"],["62075.50","1.012"],["62077.40","0.057"],["62077.70","0.050"],["62077.80","1.440"],["62078.20","1.464"],["62078.40","0.779"],["62078.60","0.001"],["62078.90","0.108"],["62082.20","0.000"],["62082.40","0.021"],["62084.80","1.365"],["62084.90","0.003"],["62085.10","0.001"],["62085.70","0.018"],["62086.30","0.002"],["62086.90","0.001"],["62090.70","0.003"],["62090.80","0.000"],["62091.00","0.032"],["62096.70","0.000"],["62097.00","0.099"],["62097.60","0.650"],["62098.20","0.003"],["62099.80","0.610"],["62099.90","1.116"],["62105.90","0.002"],["62106.80","0.025"],["62109.60","0.016"],["62115.90","20.870"],["62134.40","0.665"],["62150.80","0.005"],["62150.90","1.528"],["62171.70","0.028"],["62171.80","1.528"],["62215.50","0.000"],["62664.40","0.000"],["62726.40","3.899"],["62755.20","0.250"],["62758.00","15.136"],["62877.50","0.278"]],"b":[["1000.00","210.542"],["11743.90","0.368"],["11841.00","0.992"],["11843.90","0.176"],["11941.00","1.264"],["55839.50","0.002"],["58157.40","0.002"],["58941.70","0.000"],["59562.10","0.003"],["60803.10","0.005"],["61420.60","0.014"],["61423.50","0.000"],["61455.70","9.922"],["61779.00","0.684"],["61834.40","0.002"],["61859.50","0.000"],["61859.60","1.537"],["61859.70","0.609"],["61860.10","0.000"],["61863.50","0.000"],["61946.60","2.148"],["61949.30","0.997"],["61971.00","0.002"],["61972.50","0.305"],["61973.40","0.000"],["61975.30","0.001"],["61975.80","0.430"],["61979.40","20.387"],["61981.00","0.668"],["61983.00","0.676"],["61984.20","0.468"],["61984.30","1.531"],["61986.60","0.616"],["61993.30","0.000"],["61993.40","0.002"],["61995.70","0.002"],["61996.80","0.002"],["61997.10","0.033"],["61998.70","1.959"],["61999.10","0.002"],["61999.30","0.121"],["61999.40","0.183"],["62000.00","9.260"],["62000.60","0.077"],["62002.40","2.433"],["62003.70","0.021"],["62003.80","0.664"],["62004.10","0.028"],["62004.40","0.001"],["62005.00","0.001"],["62005.10","1.529"],["62007.50","0.204"],["62008.50","0.000"],["62009.60","0.010"],["62009.70","0.054"],["62009.80","0.692"],["62010.30","0.001"],["62010.40","0.001"],["62010.50","0.055"],["62011.80","0.006"],["62012.40","2.346"],["62013.40","0.128"],["62013.90","0.299"],["62014.80","0.009"],["62015.10","0.404"],["62016.50","0.178"],["62019.10","0.063"],["62019.60","0.406"],["62020.10","0.013"],["62020.20","0.718"],["62021.00","0.000"],["62021.10","0.001"],["62022.20","0.003"],["62022.70","0.004"],["62025.70","0.020"],["62025.80","0.328"],["62025.90","0.006"],["62026.30","0.322"],["62026.50","0.034"],["62027.10","0.787"],["62028.30","0.138"],["62028.40","0.717"],["62028.50","0.875"],["62028.70","0.000"],["62028.80","0.006"],["62029.10","0.354"],["62029.90","0.326"],["62030.60","0.309"],["62031.00","0.005"],["62031.20","1.117"],["62031.30","0.088"],["62032.20","0.001"],["62032.70","0.510"],["62033.10","0.181"],["62033.50","0.004"],["62033.60","1.378"],["62034.00","1.763"],["62034.50","0.002"],["62034.60","2.115"],["62035.00","0.089"],["62035.10","0.723"],["62035.20","0.006"],["62035.60","0.381"],["62036.80","0.030"],["62038.20","0.001"],["62038.80","0.001"],["62039.40","0.041"],["62039.60","0.046"],["62040.00","0.064"],["62040.70","0.003"],["62040.80","0.008"],["62041.10","1.801"],["62042.10","0.323"],["62042.80","0.002"],["62043.80","0.002"],["62043.90","7.724"]],"e":"depthUpdate","ps":"BTCUSDT","pu":10998399624495,"s":"BTCUSDT","st":1,"u":10998399633494}
{"E":1783504319390,"T":1783504319389,"U":10998399633562,"a":[["62044.00","6.255"],["62045.80","0.121"],["62047.20","0.162"],["62047.90","0.002"],["62048.00","0.003"],["62048.10","0.339"],["62048.60","0.005"],["62049.40","0.000"],["62049.50","0.379"],["62050.20","0.567"],["62053.20","2.013"],["62055.70","0.022"],["62057.20","0.005"],["62059.20","0.002"],["62061.30","0.015"],["62063.70","0.007"],["62070.40","0.053"],["62070.70","0.008"],["62072.80","1.432"],["62075.40","9.458"],["62075.50","1.007"],["62078.50","0.122"],["62078.80","0.258"],["62079.70","0.001"],["62086.90","0.000"],["62088.60","0.008"],["62088.80","0.018"],["62097.00","0.003"],["62097.20","0.105"],["62111.70","0.043"],["62113.80","20.859"],["62115.90","0.011"],["62167.00","0.000"],["62248.10","1.509"],["62249.40","0.000"],["62402.50","0.000"],["62404.50","0.090"],["62663.10","0.000"],["62664.40","0.002"],["62665.10","0.008"],["62788.50","2.544"],["66076.80","0.036"]],"b":[["11743.90","0.640"],["11841.00","0.720"],["11843.90","0.320"],["11941.00","1.120"],["55839.50","0.002"],["59562.10","0.000"],["61423.50","0.000"],["61544.70","0.324"],["61730.80","0.003"],["61795.70","0.121"],["61834.40","0.001"],["61855.30","0.210"],["61881.30","0.153"],["61882.90","0.000"],["61979.40","0.037"],["61981.60","20.354"],["61982.20","3.427"],["61982.70","0.029"],["61987.90","0.151"],["61994.80","0.259"],["62001.20","0.328"],["62011.10","0.003"],["62015.00","0.126"],["62019.00","0.082"],["62019.60","0.413"],["62021.50","0.001"],["62027.30","0.142"],["62030.30","0.004"],["62032.70","0.486"],["62033.40","0.124"],["62033.50","0.038"],["62034.00","1.721"],["62035.00","0.007"],["62037.80","0.293"],["62041.00","0.006"],["62042.00","0.500"],["62042.80","0.000"],["62042.90","0.000"],["62043.90","6.987"]],"e":"depthUpdate","ps":"BTCUSDT","pu":10998399633494,"s":"BTCUSDT","st":1,"u":10998399641668}
{"E":1783504319492,"T":1783504319489,"U":10998399641703,"a":[["62044.00","6.340"],["62045.80","0.121"],["62048.00","0.325"],["62048.10","0.017"],["62049.00","0.154"],["62049.20","0.005"],["62049.40","0.000"],["62050.70","1.375"],["62052.60","0.001"],["62053.20","2.254"],["62053.30","0.101"],["62054.00","0.012"],["62056.50","0.000"],["62060.60","0.024"],["62062.40","0.084"],["62067.70","0.683"],["62068.80","0.485"],["62070.40","0.033"],["62075.50","1.112"],["62111.70","0.043"],["62113.80","20.859"],["62116.90","0.000"],["62351.40","0.004"],["62664.40","0.000"],["62943.90","0.000"],["63575.20","0.673"],["63586.10","0.001"]],"b":[["1000.00","210.542"],["11643.90","0.096"],["11743.90","0.720"],["11841.00","0.544"],["11843.90","0.448"],["11941.00","0.992"],["55839.50","0.002"],["59562.10","0.003"],["60801.10","0.113"],["61400.00","34.239"],["61423.50","0.000"],["61730.80","0.000"],["61731.70","0.000"],["61834.40","0.002"],["61934.20","1.375"],["61937.50","0.004"],["61973.40","0.016"],["61997.20","0.454"],["61999.80","0.196"],["62012.20","0.002"],["62017.60","0.325"],["62018.60","0.006"],["62021.50","0.581"],["62022.30","0.123"],["62022.90","0.000"],["62023.50","1.301"],["62024.60","0.858"],["62024.70","0.000"],["62025.50","0.729"],["62027.10","0.428"],["62027.80","0.272"],["62028.40","0.153"],["62028.70","0.564"],["62030.10","0.125"],["62033.50","0.061"],["62033.80","0.019"],["62034.00","1.697"],["62035.20","0.008"],["62041.00","0.005"],["62041.10","1.800"],["62043.90","6.516"]],"e":"depthUpdate","ps":"BTCUSDT","pu":10998399641668,"s":"BTCUSDT","st":1,"u":10998399647965}
{"E":1783504319594,"T":1783504319592,"U":10998399648193,"a":[["62044.00","6.339"],["62046.90","0.051"],["62047.10","0.292"],["62047.20","0.162"],["62047.60","0.005"],["62048.50","0.003"],["62049.40","0.000"],["62049.60","1.217"],["62049.70","0.003"],["62050.50","0.822"],["62052.50","0.001"],["62053.00","0.596"],["62053.20","2.013"],["62053.60","0.326"],["62054.80","0.002"],["62056.00","0.003"],["62057.00","0.000"],["62059.70","0.585"],["62059.90","0.002"],["62060.10","0.080"],["62062.30","0.096"],["62062.40","0.004"],["62063.50","2.507"],["62064.20","0.013"],["62064.60","0.000"],["62066.10","0.261"],["62068.80","0.365"],["62074.90","0.386"],["62094.90","0.269"],["62096.60","0.301"],["62111.70","0.043"],["62113.80","0.000"],["62115.80","21.141"],["62130.20","0.004"],["62131.70","3.020"],["62136.30","0.073"],["62664.40","0.000"]],"b":[["1000.00","210.542"],["11643.90","0.224"],["11743.90","0.736"],["11841.00","0.400"],["11843.90","0.592"],["11941.00","0.848"],["55839.50","0.002"],["61423.50","0.000"],["61733.60","0.001"],["61733.70","0.004"],["61779.00","0.000"],["61779.10","0.494"],["61834.40","0.001"],["61987.20","0.122"],["61989.50","0.014"],["62004.10","0.003"],["62010.10","0.001"],["62011.30","0.000"],["62012.60","1.324"],["62018.90","0.311"],["62021.00","0.014"],["62023.40","0.091"],["62024.70","0.322"],["62024.80","0.005"],["62025.90","0.004"],["62026.30","0.000"],["62028.80","0.008"],["62030.00","0.006"],["62036.90","0.004"],["62038.80","0.005"],["62040.20","0.003"],["62041.20","0.006"]],"e":"depthUpdate","ps":"BTCUSDT","pu":10998399647965,"s":"BTCUSDT","st":1,"u":10998399654919}
{"E":1783504319696,"T":1783504319694,"U":10998399655169,"a":[["62044.00","7.147"],["62044.10","0.107"],["62044.30","0.002"],["62045.30","0.000"],["62045.80","0.121"],["62046.60","0.876"],["62047.00","0.082"],["62047.10","0.341"],["62047.30","0.635"],["62048.00","0.647"],["62048.10","0.837"],["62049.40","0.820"],["62049.50","0.057"],["62050.00","0.001"],["62050.10","0.094"],["62053.00","0.355"],["62053.60","0.324"],["62053.80","0.242"],["62054.90","0.049"],["62055.20","0.060"],["62055.50","0.566"],["62055.70","0.022"],["62056.00","0.633"],["62056.10","0.078"],["62057.10","0.005"],["62058.10","0.000"],["62059.70","0.005"],["62060.10","0.000"],["62060.50","0.001"],["62061.30","0.595"],["62061.40","0.132"],["62062.90","0.009"],["62063.50","2.387"],["62063.90","0.404"],["62064.10","0.344"],["62064.20","0.074"],["62064.60","0.000"],["62065.70","0.121"],["62068.50","0.085"],["62068.80","0.465"],["62068.90","0.296"],["62069.00","2.031"],["62074.80","0.326"],["62074.90","0.254"],["62075.50","1.007"],["62076.00","0.006"],["62076.40","0.053"],["62082.10","0.058"],["62111.70","0.043"],["62115.80","21.573"],["62121.80","0.001"],["62128.70","0.000"],["62131.10","0.678"],["62136.30","0.009"],["62137.10","0.002"],["62223.40","0.413"],["62224.10","0.024"],["62664.40","0.000"]],"b":[["11643.90","0.368"],["11743.90","0.720"],["11841.00","0.272"],["11843.90","0.720"],["11941.00","0.720"],["55839.50","0.002"],["59562.10","0.000"],["61423.50","0.000"],["61730.80","0.000"],["61834.40","0.002"],["61889.20","0.002"],["61937.90","0.924"],["61944.30","0.679"],["61944.90","0.003"],["61950.80","0.003"],["61969.10","0.003"],["61973.00","0.000"],["61984.50","0.004"],["62003.30","0.343"],["62003.80","0.648"],["62004.60","0.044"],["62006.70","0.003"],["62012.60","1.299"],["62019.70","0.048"],["62021.30","2.162"],["62022.30","0.002"],["62022.40","0.012"],["62023.40","0.083"],["62024.60","0.415"],["62026.40","0.192"],["62028.20","0.564"],["62028.30","0.122"],["62028.70","0.000"],["62029.10","0.032"],["62030.10","0.125"],["62030.70","0.000"],["62031.50","0.153"],["62032.00","0.003"],["62032.50","0.016"],["62034.40","0.000"],["62035.20","0.346"],["62035.30","0.565"],["62035.60","0.596"],["62036.20","0.820"],["62036.30","0.002"],["62038.40","0.185"],["62038.60","0.005"],["62039.30","0.003"],["62040.10","0.000"],["62040.60","0.053"],["62040.70","0.006"],["62041.00","0.003"],["62041.20","0.001"],["62041.40","0.000"],["62042.10","0.000"],["62043.10","0.002"],["62043.80","0.004"],["62043.90","3.603"]],"e":"depthUpdate","ps":"BTCUSDT","pu":10998399654919,"s":"BTCUSDT","st":1,"u":10998399663062}
{"E":1783504319798,"T":1783504319797,"U":10998399663330,"a":[["62044.00","7.148"],["62045.20","0.010"],["62045.90","0.647"],["62048.40","0.003"],["62049.20","0.003"],["62050.10","0.084"],["62053.20","2.011"],["62060.60","0.004"],["62061.60","0.904"],["62074.80","0.163"],["62111.70","21.334"],["62113.80","0.000"],["62115.80","0.282"],["62172.60","0.877"],["62175.40","0.647"],["62351.40","0.003"],["62664.40","0.000"]],"b":[["1000.00","210.542"],["11643.90","0.528"],["11741.00","1.872"],["11743.90","0.800"],["11841.00","0.160"],["11843.90","0.864"],["11941.00","0.576"],["55839.50","0.002"],["58752.90","0.040"],["58932.20","0.007"],["59562.10","0.003"],["61135.00","0.016"],["61298.00","1.414"],["61423.50","0.002"],["61834.40","0.001"],["61907.90","0.690"],["61908.50","0.027"],["62021.30","2.146"],["62022.80","0.017"],["62025.60","0.566"],["62028.20","0.000"],["62028.70","0.902"],["62032.90","0.004"],["62034.00","1.653"],["62035.20","0.002"],["62035.30","0.001"],["62043.90","3.608"]],"e":"depthUpdate","ps":"BTCUSDT","pu":10998399663062,"s":"BTCUSDT","st":1,"u":10998399670852}
{"E":1783504319900,"T":1783504319897,"U":10998399670916,"a":[["62052.40","0.407"],["62053.80","0.001"],["62055.50","0.567"],["62071.20","5.001"],["62073.50","0.164"],["62111.70","0.043"],["62115.90","21.302"],["62664.40","0.000"],["63148.80","0.000"],["63284.80","0.009"]],"b":[["1000.00","210.542"],["11643.90","0.800"],["11741.00","1.728"],["11743.90","0.672"],["11843.90","0.992"],["11941.00","0.448"],["49635.10","0.000"],["55839.50","0.002"],["58001.90","0.012"],["59562.10","0.000"],["61110.40","0.741"],["61172.40","0.011"],["61296.50","1.961"],["61423.50","0.000"],["61733.60","0.002"],["61834.40","0.002"],["62003.30","0.296"],["62023.70","0.179"],["62024.60","0.294"],["62034.00","1.633"],["62034.90","0.499"]],"e":"depthUpdate","ps":"BTCUSDT","pu":10998399670852,"s":"BTCUSDT","st":1,"u":10998399675381}
{"E":1783504320002,"T":1783504320001,"U":10998399675624,"a":[["62044.00","6.344"],["62045.80","1.007"],["62047.00","0.082"],["62048.00","0.325"],["62050.20","0.003"],["62050.50","0.002"],["62051.90","0.246"],["62052.40","0.166"],["62052.60","0.163"],["62055.20","0.020"],["62057.40","0.325"],["62059.10","0.081"],["62061.20","0.197"],["62061.30","0.015"],["62061.40","0.172"],["62062.80","0.584"],["62064.20","0.013"],["62068.50","0.005"],["62068.70","0.203"],["62070.90","2.129"],["62071.20","5.003"],["62075.30","0.471"],["62082.10","0.002"],["62113.80","21.291"],["62115.90","0.011"],["62127.30","0.025"],["62175.40","0.000"],["62176.20","0.654"],["62601.00","0.008"],["62664.40","0.000"]],"b":[["11643.90","1.072"],["11741.00","1.600"],["11743.90","0.528"],["11843.90","1.136"],["11941.00","0.304"],["55839.50","0.002"],["61423.50","0.000"],["61730.80","0.000"],["61733.70","0.005"],["61834.40","0.001"],["61907.90","0.025"],["61908.00","1.690"],["61973.40","0.000"],["61978.60","0.217"],["61981.00","0.232"],["62016.60","0.002"],["62020.50","0.016"],["62022.80","0.001"],["62025.50","0.003"],["62025.60","0.002"],["62025.70","0.584"],["62026.30","0.726"],["62028.00","1.466"],["62028.40","0.153"],["62028.80","0.008"],["62031.80","0.820"],["62035.60","0.003"],["62035.70","0.000"],["62036.30","1.364"],["62036.40","0.899"],["62036.50","0.130"],["62037.30","0.820"],["62038.40","1.005"],["62043.90","3.609"]],"e":"depthUpdate","ps":"BTCUSDT","pu":10998399675381,"s":"BTCUSDT","st":1,"u":10998399682015}
{"E":1783504320104,"T":1783504320103,"U":10998399682591,"a":[["62044.00","6.308"],["62045.10","0.718"],["62045.20","0.010"],["62045.30","0.016"],["62045.40","0.034"],["62045.60","0.099"],["62045.70","0.000"],["62045.80","0.121"],["62046.00","0.003"],["62047.00","0.001"],["62047.10","0.049"],["62047.70","0.566"],["62047.80","0.001"],["62047.90","0.083"],["62048.00","0.003"],["62048.10","0.821"],["62049.20","0.002"],["62049.70","0.004"],["62050.80","0.058"],["62051.90","0.244"],["62052.60","0.001"],["62052.90","1.161"],["62053.20","1.364"],["62054.00","0.018"],["62055.40","0.130"],["62055.50","0.561"],["62055.60","0.324"],["62055.70","0.586"],["62056.40","0.002"],["62057.00","0.080"],["62057.40","0.163"],["62057.50","0.000"],["62057.60","0.002"],["62058.10","0.725"],["62058.80","0.013"],["62059.10","0.001"],["62060.80","0.004"],["62061.20","0.035"],["62062.50","0.000"],["62068.20","1.018"],["62068.50","0.064"],["62068.70","0.204"],["62068.80","0.593"],["62073.70","0.002"],["62077.90","0.012"],["62078.00","0.077"],["62081.80","0.109"],["62081.90","0.020"],["62085.70","0.002"],["62085.80","0.666"],["62099.50","1.387"],["62099.70","0.927"],["62099.80","0.711"],["62099.90","1.217"],["62100.20","0.029"],["62100.40","0.102"],["62105.00","0.121"],["62105.50","0.004"],["62106.80","0.000"],["62111.70","21.334"],["62113.80","0.000"],["62127.30","0.000"],["62421.00","0.485"],["62664.40","0.000"],["62903.90","0.000"]],"b":[["1000.00","210.542"],["11643.90","1.344"],["11741.00","1.456"],["11743.90","0.400"],["11843.90","1.264"],["11941.00","0.176"],["55839.50","0.002"],["59562.10","0.003"],["60578.60","0.000"],["60803.10","0.008"],["60947.90","2.599"],["61265.50","0.277"],["61423.50","0.000"],["61738.50","0.024"],["61742.60","0.112"],["61834.40","0.002"],["61944.90","0.000"],["61945.00","0.006"],["61966.30","0.869"],["61980.80","0.274"],["61982.30","0.437"],["62002.80","0.170"],["62003.30","0.292"],["62007.70","0.000"],["62007.80","0.004"],["62012.30","0.687"],["62015.30","0.050"],["62018.80","1.507"],["62020.50","0.000"],["62022.70","0.125"],["62023.50","1.298"],["62023.70","0.058"],["62025.30","0.131"],["62025.70","0.020"],["62026.20","0.124"],["62026.30","0.000"],["62026.40","0.756"],["62026.80","0.726"],["62027.00","0.001"],["62028.40","0.281"],["62028.70","0.904"],["62030.40","0.005"],["62032.50","0.014"],["62033.90","0.325"],["62039.50","0.003"],["62040.30","0.050"],["62040.60","0.004"],["62043.90","3.576"]],"e":"depthUpdate","ps":"BTCUSDT","pu":10998399682015,"s":"BTCUSDT","st":1,"u":10998399693253}
{"E":1783504320206,"T":1783504320205,"U":10998399693334,"a":[["62045.10","0.209"],["62045.20","0.002"],["62045.30","0.000"],["62045.80","1.023"],["62047.20","0.162"],["62047.70","0.294"],["62047.80","0.562"],["62047.90","0.405"],["62048.00","0.003"],["62049.00","0.155"],["62055.60","0.002"],["62056.40","0.000"],["62057.20","0.730"],["62058.10","0.000"],["62068.10","0.118"],["62080.00","1.057"],["62100.60","0.101"],["62131.00","0.001"],["62160.00","0.546"],["62240.00","0.607"],["62320.00","0.543"],["62400.00","14.498"],["62418.60","0.021"],["62602.40","1.127"],["62664.40","0.000"],["62767.50","5.005"]],"b":[["1000.00","210.542"],["11643.90","1.616"],["11741.00","1.328"],["11743.90","0.256"],["11843.90","1.408"],["11941.00","0.032"],["55839.50","0.055"],["59562.10","0.000"],["61423.50","0.000"],["61680.00","1.099"],["61760.00","0.591"],["61834.40","0.001"],["61840.00","0.431"],["61920.00","0.504"],["61972.50","0.149"],["61981.90","1.697"],["62000.00","9.242"],["62002.80","0.606"],["62014.90","0.360"],["62022.80","0.003"],["62026.10","0.729"],["62026.20","0.688"],["62026.40","0.192"],["62026.80","0.000"],["62026.90","0.003"],["62027.10","0.428"],["62031.40","0.066"],["62041.00","0.006"],["62041.20","0.002"],["62041.90","0.002"],["62042.50","0.002"],["62043.90","3.577"]],"e":"depthUpdate","ps":"BTCUSDT","pu":10998399693253,"s":"BTCUSDT","st":1,"u":10998399701932}
{"E":1783504320308,"T":1783504320305,"U":10998399702092,"a":[["62044.00","7.142"],["62045.10","0.316"],["62045.60","0.985"],["62045.70","0.000"],["62045.80","0.137"],["62047.20","0.162"],["62047.80","0.001"],["62047.90","0.236"],["62048.00","0.003"],["62049.20","0.002"],["62049.50","0.058"],["62049.70","0.003"],["62051.20","0.242"],["62051.90","0.003"],["62055.60","0.324"],["62059.70","0.585"],["62061.10","0.405"],["62062.80","0.004"],["62067.30","0.491"],["62068.10","0.102"],["62068.90","0.296"],["62073.50","0.486"],["62100.40","0.001"],["62100.60","0.000"],["62608.60","0.020"],["62664.40","0.000"],["62905.80","4.722"]],"b":[["11643.90","1.888"],["11741.00","1.184"],["11743.90","0.224"],["11843.90","1.344"],["11941.00","0.000"],["55839.50","0.055"],["59562.10","0.003"],["61134.00","8.139"],["61211.20","1.617"],["61423.50","0.000"],["61730.80","0.010"],["61834.40","0.002"],["61975.20","0.296"],["61977.80","0.109"],["61986.50","1.363"],["61997.10","0.031"],["61997.70","0.006"],["62008.20","0.003"],["62014.40","0.017"],["62016.00","0.007"],["62016.20","0.060"],["62016.30","0.396"],["62018.80","1.448"],["62022.20","0.003"],["62023.30","0.003"],["62023.80","0.017"],["62025.30","0.003"],["62025.60","0.728"],["62025.70","0.584"],["62026.10","0.003"],["62026.20","0.124"],["62028.40","0.281"],["62028.70","0.904"],["62028.80","0.010"],["62029.90","1.326"],["62031.10","0.005"],["62031.20","0.297"],["62031.80","0.000"],["62034.00","1.399"],["62036.50","0.130"],["62037.30","0.824"],["62040.20","0.000"],["62040.40","0.002"],["62040.70","0.003"],["62043.90","2.713"]],"e":"depthUpdate","ps":"BTCUSDT","pu":10998399701932,"s":"BTCUSDT","st":1,"u":10998399713699}
{"E":1783504320410,"T":1783504320409,"U":10998399714054,"a":[["62045.10","0.209"],["62045.40","0.034"],["62045.50","0.004"],["62045.60","0.099"],["62045.80","0.121"],["62047.20","0.162"],["62047.80","0.323"],["62048.00","0.905"],["62049.10","0.325"],["62049.50","0.057"],["62055.50","0.641"],["62055.60","0.002"],["62055.90","0.006"],["62056.00","0.003"],["62057.00","0.000"],["62664.40","0.000"]],"b":[["1000.00","210.542"],["11643.90","2.160"],["11741.00","1.040"],["11743.90","0.240"],["11843.90","1.200"],["55839.50","0.055"],["57846.40","0.002"],["58941.70","0.020"],["59562.10","0.000"],["60500.00","312.585"],["60942.70","0.003"],["60955.30","2.048"],["60998.70","0.572"],["61423.50","0.000"],["61834.40","0.001"],["61994.80","0.243"],["62011.60","0.024"],["62023.50","1.998"],["62031.40","0.064"],["62043.90","2.712"]],"e":"depthUpdate","ps":"BTCUSDT","pu":10998399713699,"s":"BTCUSDT","st":1,"u":10998399727181}
{"E":1783504320512,"T":1783504320511,"U":10998399727635,"a":[["62044.00","7.088"],["62047.20","0.162"],["62049.10","0.324"],["62049.50","0.058"],["62053.50","0.103"],["62055.50","0.561"],["62056.00","0.003"],["62056.20","0.421"],["62056.80","0.727"],["62057.20","0.005"],["62062.50","0.700"],["62062.90","1.131"],["62063.50","1.570"],["62064.60","0.061"],["62065.70","0.249"],["62067.70","0.699"],["62068.80","0.593"],["62079.00","0.003"],["62082.50","0.100"],["62099.60","1.598"],["62099.80","0.610"],["62099.90","1.116"],["62100.70","0.205"],["62100.80","0.006"],["62102.70","0.102"],["62111.60","4.081"],["62112.20","0.539"],["62175.40","0.647"],["62176.20","0.006"],["62616.90","4.029"],["62623.60","0.239"],["62664.40","0.000"],["62788.40","5.130"],["62873.00","0.473"],["62893.30","0.000"],["62953.50","0.714"]],"b":[["1000.00","210.542"],["11643.90","2.432"],["11741.00","0.768"],["11743.90","0.368"],["11843.90","1.072"],["49635.00","0.000"],["55839.50","0.055"],["58939.80","0.003"],["58939.90","0.006"],["58941.70","0.000"],["61144.30","0.980"],["61169.10","0.815"],["61294.40","2.735"],["61423.50","0.002"],["61650.00","21.417"],["61733.60","0.001"],["61834.40","0.002"],["61908.00","1.039"],["61908.20","0.658"],["61959.00","0.002"],["61959.10","0.666"],["61966.30","0.741"],["61972.10","2.265"],["61980.70","1.485"],["61999.20","0.068"],["62006.30","0.022"],["62020.10","0.594"],["62021.50","0.001"],["62022.80","0.001"],["62024.90","0.730"],["62025.00","0.570"],["62025.30","0.131"],["62025.60","0.002"],["62025.70","0.020"],["62027.70","0.845"],["62031.50","0.281"],["62039.70","0.049"],["62043.90","2.921"]],"e":"depthUpdate","ps":"BTCUSDT","pu":10998399727181,"s":"BTCUSDT","st":1,"u":10998399747742}
{"E":1783504320614,"T":1783504320613,"U":10998399748125,"a":[["62044.00","6.880"],["62044.10","0.102"],["62045.10","0.333"],["62045.80","1.023"],["62046.50","0.084"],["62047.20","0.162"],["62047.60","0.566"],["62047.80","0.001"],["62048.00","0.003"],["62053.50","0.023"],["62055.60","0.324"],["62055.70","0.602"],["62059.90","0.002"],["62061.80","0.008"],["62062.90","1.123"],["62063.00","0.354"],["62063.30","0.120"],["62065.70","0.129"],["62067.70","0.683"],["62079.30","0.184"],["62086.50","0.014"],["62095.30","0.000"],["62095.40","0.016"],["62095.50","0.012"],["62095.90","1.101"],["62096.40","0.066"],["62102.80","1.745"],["62109.60","21.307"],["62111.60","0.123"],["62111.70","0.043"],["62131.80","0.001"],["62224.10","0.021"],["62224.20","0.003"],["62250.00","18.271"],["62354.30","0.001"],["62418.60","0.003"],["62664.40","0.004"],["62782.20","1.112"],["62895.50","0.794"],["62936.20","1.654"],["62958.40","0.357"],["62974.60","0.395"]],"b":[["11643.90","2.704"],["11741.00","0.496"],["11743.90","0.512"],["11843.90","0.928"],["49635.00","0.000"],["55839.50","0.055"],["58941.70","0.000"],["59562.10","0.003"],["60941.80","0.835"],["61416.80","0.006"],["61423.50","0.000"],["61682.50","0.002"],["61683.70","0.137"],["61730.80","0.000"],["61733.70","0.015"],["61834.40","0.001"],["61928.10","0.019"],["62007.70","0.004"],["62007.80","0.000"],["62016.70","0.003"],["62020.10","0.013"],["62020.80","0.583"],["62021.90","0.122"],["62022.40","0.004"],["62022.70","0.004"],["62023.10","0.009"],["62023.80","0.019"],["62023.90","0.004"],["62024.70","0.000"],["62025.10","0.325"],["62027.70","0.523"],["62028.40","0.281"],["62028.80","0.010"],["62029.40","0.333"],["62031.50","0.281"],["62033.10","0.157"],["62033.50","0.038"],["62033.80","0.042"],["62038.50","0.420"],["62038.90","0.000"],["62043.80","0.007"],["62043.90","3.075"]],"e":"depthUpdate","ps":"BTCUSDT","pu":10998399747742,"s":"BTCUSDT","st":1,"u":10998399767866}
{"E":1783504320716,"T":1783504320713,"U":10998399768025,"a":[["62044.10","0.103"],["62045.10","0.209"],["62045.50","0.004"],["62045.60","0.099"],["62045.70","0.000"],["62045.80","0.121"],["62046.50","0.004"],["62047.60","0.005"],["62047.70","0.002"],["62047.80","0.323"],["62048.00","0.905"],["62048.10","0.821"],["62055.40","0.130"],["62055.60","0.002"],["62055.70","0.586"],["62055.90","0.004"],["62056.40","0.000"],["62056.50","0.000"],["62058.00","0.231"],["62065.50","0.002"],["62071.00","0.868"],["62075.30","0.471"],["62079.30","0.124"],["62084.40","1.346"],["62086.50","4.514"],["62087.40","0.060"],["62096.10","0.000"],["62096.30","0.001"],["62096.40","0.066"],["62099.50","1.362"],["62099.80","0.711"],["62099.90","1.217"],["62100.70","0.104"],["62102.70","0.001"],["62102.80","1.644"],["62108.10","0.025"],["62108.20","9.941"],["62131.70","1.769"],["62139.30","11.000"],["62145.80","0.036"],["62417.20","0.018"],["62633.40","1.353"],["62664.40","0.000"],["62819.60","0.269"],["63023.30","0.013"]],"b":[["1000.00","210.542"],["11543.90","0.128"],["11643.90","2.720"],["11741.00","0.352"],["11743.90","0.640"],["11843.90","0.800"],["55839.50","0.055"],["58932.20","0.004"],["58941.70","0.000"],["59562.10","0.000"],["61305.60","0.981"],["61350.00","24.458"],["61420.60","0.000"],["61423.50","0.000"],["61834.40","0.002"],["61928.20","3.061"],["61969.10","8.003"],["61980.80","0.272"],["61981.00","0.234"],["61990.80","5.161"],["61992.10","1.228"],["62006.30","0.821"],["62020.00","0.279"],["62020.20","0.681"],["62025.30","0.003"],["62025.80","0.368"],["62026.50","0.001"],["62030.60","0.282"],["62032.30","0.002"],["62034.50","0.025"],["62036.80","0.002"]],"e":"depthUpdate","ps":"BTCUSDT","pu":10998399767866,"s":"BTCUSDT","st":1,"u":10998399781827}
{"E":1783504320818,"T":1783504320817,"U":10998399782366,"a":[["62046.30","0.002"],["62047.20","0.484"],["62047.70","0.294"],["62048.00","0.585"],["62051.20","0.001"],["62052.00","0.243"],["62055.20","0.387"],["62065.50","0.000"],["62080.00","0.880"],["62099.70","0.826"],["62135.90","0.027"],["62160.00","0.369"],["62175.40","0.000"],["62240.00","0.430"],["62242.90","0.002"],["62320.00","0.366"],["62400.00","14.321"],["62608.70","1.201"],["62664.40","0.000"],["62798.40","1.423"],["62819.50","0.269"],["62847.60","0.318"],["62874.50","2.174"],["62958.30","1.092"]],"b":[["1000.00","210.542"],["11543.90","0.256"],["11643.90","2.736"],["11741.00","0.208"],["11743.90","0.784"],["11843.90","0.656"],["55839.50","0.055"],["58932.20","0.006"],["58941.70","0.000"],["59562.10","0.003"],["61423.50","0.000"],["61680.00","0.922"],["61760.00","0.414"],["61834.40","0.001"],["61840.00","0.254"],["61880.10","1.401"],["61908.20","0.005"],["61920.00","0.327"],["61938.20","11.678"],["61964.00","0.040"],["62000.00","9.065"],["62025.30","0.131"],["62033.80","0.019"],["62034.40","0.024"],["62034.50","0.002"],["62040.00","0.066"],["62043.90","3.077"]],"e":"depthUpdate","ps":"BTCUSDT","pu":10998399781827,"s":"BTCUSDT","st":1,"u":10998399795218}
{"E":1783504320920,"T":1783504320919,"U":10998399795367,"a":[["62046.40","0.332"],["62046.50","0.020"],["62047.10","0.049"],["62047.20","0.723"],["62048.00","0.569"],["62053.10","0.563"],["62058.00","0.151"],["62059.90","0.082"],["62062.60","0.661"],["62063.60","0.032"],["62065.70","0.001"],["62066.00","1.010"],["62073.50","0.488"],["62074.90","0.264"],["62077.30","0.000"],["62138.40","0.025"],["62175.40","0.647"],["62194.20","1.378"],["62197.00","1.058"],["62484.50","0.000"],["62664.40","0.000"],["62881.50","0.793"],["62915.00","0.096"],["62974.70","0.714"]],"b":[["11543.90","0.400"],["11643.90","2.720"],["11741.00","0.080"],["11743.90","0.912"],["11843.90","0.528"],["49635.10","0.000"],["55839.50","0.055"],["58941.70","0.000"],["59562.10","0.000"],["61423.50","0.000"],["61451.60","0.718"],["61609.60","0.492"],["61733.60","0.000"],["61733.70","0.015"],["61834.40","0.002"],["61886.80","1.086"],["61886.90","0.000"],["61908.30","0.785"],["62006.40","0.012"],["62007.50","0.194"],["62018.80","1.460"],["62019.10","0.051"],["62024.30","0.661"],["62028.40","0.153"],["62031.50","0.281"]],"e":"depthUpdate","ps":"BTCUSDT","pu":10998399795218,"s":"BTCUSDT","st":1,"u":10998399804693}
{"E":1783504321022,"T":1783504321021,"U":10998399804782,"a":[["62044.10","0.003"],["62046.40","0.010"],["62046.50","0.568"],["62047.10","0.387"],["62047.20","0.162"],["62048.00","0.005"],["62049.50","0.057"],["62049.60","1.218"],["62052.20","0.081"],["62056.80","0.002"],["62057.00","0.725"],["62059.90","0.002"],["62063.70","0.023"],["62066.60","0.341"],["62068.50","0.005"],["62110.10","0.000"],["62112.30","0.798"],["62184.50","0.000"],["62184.70","4.032"],["62354.30","0.002"],["62664.40","0.000"],["62894.00","1.849"],["62907.30","0.781"],["63000.50","0.358"],["63001.40","0.277"],["63284.80","0.012"]],"b":[["1000.00","210.542"],["11543.90","0.592"],["11643.90","2.608"],["11741.00","0.000"],["11743.90","1.056"],["11843.90","0.384"],["55839.50","0.055"],["57690.90","0.002"],["58941.70","0.000"],["61097.40","0.016"],["61175.30","2.449"],["61229.80","0.000"],["61237.30","0.979"],["61423.50","0.000"],["61702.60","0.618"],["61705.10","0.229"],["61834.40","0.001"],["61932.60","4.030"],["61933.10","0.130"],["61973.50","0.139"],["61975.70","1.410"],["61982.30","0.001"],["61993.40","0.018"],["62020.30","0.586"],["62020.80","0.002"],["62023.50","1.298"],["62024.90","0.004"],["62025.80","1.094"]],"e":"depthUpdate","ps":"BTCUSDT","pu":10998399804693,"s":"BTCUSDT","st":1,"u":10998399816766}
{"E":1783504321124,"T":1783504321121,"U":10998399817187,"a":[["62046.20","0.132"],["62046.40","0.026"],["62047.10","0.371"],["62048.40","0.083"],["62049.00","0.522"],["62052.20","0.001"],["62055.20","0.020"],["62056.30","0.002"],["62059.20","0.018"],["62062.60","0.664"],["62063.70","0.007"],["62068.70","0.041"],["62069.00","1.411"],["62080.00","1.057"],["62160.00","0.546"],["62240.00","0.607"],["62320.00","0.543"],["62400.00","14.498"],["62415.90","0.019"],["62417.20","0.000"],["62499.50","0.121"],["62626.40","0.240"],["62664.40","0.000"],["62968.70","0.792"],["63000.50","0.001"],["63282.80","0.040"]],"b":[["1000.00","210.542"],["11543.90","0.864"],["11643.90","2.336"],["11743.90","1.184"],["11843.90","0.256"],["55839.50","0.055"],["58941.70","0.000"],["59562.10","0.003"],["61423.50","0.000"],["61680.00","1.099"],["61760.00","0.591"],["61834.40","0.002"],["61840.00","0.431"],["61870.10","0.005"],["61920.00","0.504"],["62000.00","9.242"],["62002.80","0.524"],["62009.60","0.008"],["62009.70","0.052"],["62009.80","0.690"],["62025.00","0.006"],["62025.30","0.134"],["62025.70","0.744"],["62025.80","0.366"],["62025.90","0.002"],["62026.00","0.050"],["62026.10","0.003"],["62026.20","0.688"],["62026.80","0.002"],["62032.30","0.000"],["62043.90","3.074"]],"e":"depthUpdate","ps":"BTCUSDT","pu":10998399816766,"s":"BTCUSDT","st":1,"u":10998399826986}
{"E":1783504321226,"T":1783504321225,"U":10998399827299,"a":[["62044.00","6.965"],["62044.90","0.005"],["62046.40","0.027"],["62047.70","0.002"],["62048.40","0.003"],["62050.50","0.018"],["62056.70","0.897"],["62057.00","0.000"],["62059.20","0.002"],["62062.50","0.000"],["62062.60","0.792"],["62068.70","0.204"],["62068.80","0.465"],["62099.60","1.497"],["62100.20","0.029"],["62100.60","0.101"],["62175.40","0.605"],["62212.90","0.001"],["62664.40","0.000"],["62813.10","0.022"],["62853.90","2.425"],["63116.50","0.000"],["63284.80","0.015"]],"b":[["11543.90","1.136"],["11643.90","2.064"],["11743.90","1.328"],["11843.90","0.112"],["55839.50","0.055"],["58939.90","0.003"],["58941.70","0.000"],["59562.10","0.000"],["60474.00","0.300"],["60801.10","0.110"],["61113.20","0.740"],["61221.40","1.070"],["61421.50","0.000"],["61423.40","0.003"],["61423.50","0.000"],["61733.70","0.016"],["61834.40","0.000"],["61908.30","0.125"],["61908.40","0.607"],["61981.90","1.698"],["62004.60","0.019"],["62005.30","0.028"],["62011.60","0.024"],["62022.50","0.004"],["62025.30","0.006"],["62025.80","0.930"],["62026.20","0.124"],["62028.40","0.281"],["62031.50","0.153"],["62032.00","0.002"],["62043.90","2.975"]],"e":"depthUpdate","ps":"BTCUSDT","pu":10998399826986,"s":"BTCUSDT","st":1,"u":10998399837572}
{"E":1783504321328,"T":1783504321327,"U":10998399837766,"a":[["62044.00","6.885"],["62046.10","0.004"],["62047.00","0.081"],["62047.70","0.294"],["62047.80","0.001"],["62048.60","0.007"],["62049.50","0.159"],["62049.60","0.766"],["62049.80","0.006"],["62049.90","0.003"],["62050.10","0.001"],["62050.40","0.002"],["62050.50","0.002"],["62050.80","0.090"],["62050.90","0.502"],["62051.00","1.004"],["62051.10","0.356"],["62051.40","0.065"],["62051.50","0.003"],["62051.60","0.000"],["62051.70","0.000"],["62055.60","0.324"],["62057.00","0.016"],["62059.50","0.132"],["62062.70","0.085"],["62068.80","0.593"],["62071.40","0.328"],["62071.80","0.009"],["62072.10","0.004"],["62072.40","0.028"],["62072.70","1.067"],["62074.90","0.254"],["62075.20","0.019"],["62077.30","0.102"],["62078.10","0.875"],["62078.20","1.362"],["62078.30","0.605"],["62078.60","0.091"],["62078.80","0.000"],["62078.90","0.000"],["62079.20","0.000"],["62079.30","0.028"],["62079.40","0.000"],["62079.50","0.002"],["62093.10","0.153"],["62093.40","0.013"],["62093.80","0.000"],["62094.10","0.713"],["62094.40","0.655"],["62099.80","0.610"],["62099.90","1.116"],["62100.40","0.102"],["62100.60","0.000"],["62101.20","0.055"],["62102.80","1.745"],["62108.10","0.000"],["62664.40","0.000"],["62850.60","2.445"],["62918.80","1.238"],["62974.70","1.071"]],"b":[["1000.00","210.542"],["11543.90","1.408"],["11643.90","1.792"],["11743.90","1.456"],["11841.00","0.144"],["11843.90","0.000"],["55839.50","0.055"],["58941.70","0.000"],["59239.90","2.000"],["59562.10","0.003"],["59857.00","1.000"],["61423.50","0.000"],["61834.40","0.001"],["61962.80","0.648"],["61963.00","0.033"],["61963.40","0.600"],["61963.60","6.302"],["61963.90","0.017"],["61978.10","0.101"],["61984.30","1.547"],["61984.40","0.001"],["61984.70","0.001"],["61985.00","0.692"],["61985.30","0.005"],["61985.60","0.003"],["61997.70","0.010"],["61999.30","0.001"],["61999.40","0.003"],["61999.50","0.001"],["61999.60","0.000"],["61999.90","0.003"],["62000.00","9.062"],["62000.50","0.004"],["62000.60","0.017"],["62004.70","0.009"],["62006.10","1.102"],["62017.10","0.780"],["62018.80","1.458"],["62019.00","0.702"],["62019.10","0.053"],["62022.60","0.004"],["62023.30","0.164"],["62027.10","0.368"],["62027.20","0.055"],["62027.30","0.082"],["62027.40","0.090"],["62027.70","0.463"],["62027.80","0.000"],["62027.90","0.065"],["62028.10","1.295"],["62028.40","0.129"],["62028.60","0.578"],["62028.90","0.005"],["62029.20","0.065"],["62029.50","0.083"],["62037.30","0.820"],["62040.50","0.003"]],"e":"depthUpdate","ps":"BTCUSDT","pu":10998399837572,"s":"BTCUSDT","st":1,"u":10998399847494}
{"E":1783504321430,"T":1783504321429,"U":10998399847666,"a":[["62044.00","6.886"],["62046.40","0.011"],["62046.50","0.004"],["62047.00","0.001"],["62047.10","0.049"],["62048.00","0.907"],["62049.50","0.160"],["62049.60","0.765"],["62049.70","0.003"],["62050.00","0.091"],["62050.50","0.086"],["62052.60","0.001"],["62056.30","0.000"],["62056.50","0.725"],["62056.70","0.172"],["62057.00","0.000"],["62057.50","0.000"],["62058.20","0.532"],["62074.80","0.165"],["62075.30","0.471"],["62077.90","0.102"],["62078.30","0.689"],["62138.40","0.050"],["62664.40","0.000"],["62974.70","1.428"],["63129.80","1.356"],["63284.80","0.018"]],"b":[["1000.00","210.542"],["11543.90","1.680"],["11643.90","1.520"],["11743.90","1.600"],["11841.00","0.000"],["49635.00","0.000"],["55839.50","0.055"],["57000.00","63.225"],["58000.00","105.391"],["58005.70","4.000"],["58622.80","3.000"],["58941.70","0.010"],["61423.50","0.000"],["61730.90","1.108"],["61733.70","0.006"],["61834.40","0.001"],["61854.70","0.001"],["61980.80","0.274"],["61981.00","0.232"],["61997.70","0.006"],["61999.20","0.052"],["62004.70","0.013"],["62018.80","1.460"],["62019.10","0.051"],["62022.20","0.011"],["62023.10","0.001"],["62023.50","1.998"],["62024.60","0.858"],["62025.40","0.727"],["62025.70","0.018"],["62025.80","0.366"],["62026.30","0.000"],["62028.20","0.060"],["62028.70","0.964"],["62043.90","2.973"]],"e":"depthUpdate","ps":"BTCUSDT","pu":10998399847494,"s":"BTCUSDT","st":1,"u":10998399857960}
{"E":1783504321532,"T":1783504321530,"U":10998399857991,"a":[["62044.00","6.921"],["62046.40","0.010"],["62046.50","0.005"],["62047.10","0.057"],["62047.20","0.734"],["62047.80","0.323"],["62048.00","0.327"],["62049.00","0.612"],["62049.20","0.085"],["62049.50","0.262"],["62049.60","0.832"],["62049.80","0.064"],["62050.10","0.211"],["62050.50","0.188"],["62050.60","0.002"],["62050.70","1.483"],["62055.00","0.485"],["62055.60","0.002"],["62058.20","0.452"],["62065.10","0.579"],["62067.30","0.522"],["62068.10","0.265"],["62068.20","3.927"],["62068.90","0.133"],["62070.60","0.092"],["62070.90","2.212"],["62071.30","0.424"],["62071.50","0.060"],["62071.80","0.219"],["62077.40","0.159"],["62078.30","0.791"],["62078.50","0.230"],["62100.00","0.645"],["62101.20","0.156"],["62102.70","0.001"],["62102.80","1.644"],["62354.30","0.001"],["62664.40","0.000"]],"b":[["11543.90","1.952"],["11643.90","1.376"],["11743.90","1.472"],["55839.50","0.055"],["57535.40","0.002"],["58941.70","0.000"],["59562.10","0.000"],["60947.90","1.300"],["61237.30","1.305"],["61423.50","0.000"],["61506.80","0.000"],["61509.70","0.303"],["61733.70","0.016"],["61834.40","0.000"],["61950.70","0.337"],["61963.10","12.093"],["61972.10","3.344"],["61972.40","1.242"],["61975.40","0.285"],["61985.50","0.032"],["61985.90","0.032"],["61986.10","0.907"],["61986.40","0.036"],["62003.00","0.017"],["62007.30","0.000"],["62010.20","0.057"],["62019.00","0.082"],["62019.70","0.001"],["62022.60","0.049"],["62023.80","0.003"],["62024.60","0.294"],["62025.30","0.134"],["62025.50","0.567"],["62028.00","1.542"],["62028.20","0.120"],["62028.40","0.001"],["62028.60","0.698"],["62028.90","0.037"],["62029.00","0.000"],["62029.20","0.157"],["62029.50","0.034"],["62029.80","0.033"],["62031.50","0.281"],["62034.90","0.499"],["62043.90","2.972"]],"e":"depthUpdate","ps":"BTCUSDT","pu":10998399857960,"s":"BTCUSDT","st":1,"u":10998399867800}
{"E":1783504321634,"T":1783504321633,"U":10998399868044,"a":[["62044.00","6.920"],["62044.70","0.087"],["62046.50","0.891"],["62047.10","0.379"],["62047.20","0.170"],["62047.80","0.001"],["62048.00","0.005"],["62050.00","0.259"],["62050.20","0.061"],["62050.70","1.585"],["62052.90","0.999"],["62053.90","0.017"],["62055.00","0.405"],["62058.40","0.009"],["62059.30","1.877"],["62059.50","0.004"],["62059.70","0.005"],["62059.90","0.002"],["62061.50","1.516"],["62062.50","0.700"],["62062.80","0.124"],["62063.30","0.000"],["62065.10","0.563"],["62069.80","0.002"],["62071.80","0.277"],["62075.10","0.328"],["62077.90","0.270"],["62078.50","0.332"],["62096.40","0.027"],["62097.90","0.040"],["62101.20","0.055"],["62664.40","0.000"],["62732.60","0.005"],["62879.60","0.000"]],"b":[["1000.00","210.542"],["11543.90","2.224"],["11643.90","1.248"],["11743.90","1.328"],["55839.50","0.055"],["58939.00","0.103"],["58939.10","0.003"],["58941.70","0.000"],["59562.10","0.003"],["61733.60","0.001"],["61736.70","0.001"],["61739.30","0.008"],["61834.40","0.001"],["61929.80","0.138"],["61929.90","0.039"],["61972.40","1.195"],["61985.30","0.037"],["62022.20","0.003"],["62023.10","0.009"],["62025.10","0.003"],["62025.60","0.324"],["62028.10","1.355"],["62028.60","0.730"],["62028.70","1.084"],["62028.80","0.010"],["62031.90","0.051"]],"e":"depthUpdate","ps":"BTCUSDT","pu":10998399867800,"s":"BTCUSDT","st":1,"u":10998399883040}
{"E":1783504321736,"T":1783504321735,"U":10998399883293,"a":[["62044.00","6.921"],["62044.10","0.103"],["62044.70","0.007"],["62045.10","0.216"],["62045.80","1.007"],["62046.30","0.010"],["62046.40","0.018"],["62046.50","0.005"],["62047.10","0.049"],["62047.20","0.162"],["62048.00","0.566"],["62049.30","0.011"],["62049.50","0.262"],["62050.20","0.169"],["62050.30","0.013"],["62050.60","0.242"],["62050.70","1.675"],["62050.80","0.412"],["62053.10","0.563"],["62053.90","0.001"],["62055.40","0.130"],["62055.60","0.002"],["62056.40","0.000"],["62056.50","0.000"],["62056.80","0.082"],["62057.00","0.322"],["62057.10","0.730"],["62059.30","1.297"],["62059.90","0.582"],["62061.40","0.040"],["62062.60","0.792"],["62062.70","0.004"],["62062.80","0.004"],["62063.10","0.444"],["62063.60","0.022"],["62064.10","0.354"],["62064.60","0.077"],["62065.70","0.129"],["62067.30","0.361"],["62068.10","0.263"],["62068.20","3.929"],["62068.80","0.465"],["62068.90","0.001"],["62071.20","0.003"],["62073.40","0.002"],["62073.50","0.166"],["62075.20","0.009"],["62075.60","1.372"],["62078.00","0.185"],["62078.40","0.875"],["62078.50","0.476"],["62078.60","0.181"],["62097.50","0.228"],["62102.80","1.745"],["62108.10","0.132"],["62137.10","0.314"],["62167.10","0.002"],["62224.20","0.000"],["62224.30","0.003"],["62233.20","0.001"],["62414.40","0.066"],["62415.90","0.001"],["62664.40","0.000"],["62864.40","0.794"],["63098.80","0.553"],["63306.70","0.000"]],"b":[["1000.00","210.542"],["11543.90","2.496"],["11643.90","1.104"],["11743.90","1.200"],["55839.50","0.055"],["58941.70","0.000"],["59562.10","0.000"],["60938.20","0.157"],["60947.90","0.001"],["61149.60","6.405"],["61423.50","0.000"],["61733.70","0.016"],["61834.40","0.000"],["61840.00","0.447"],["61945.00","0.003"],["61945.10","1.365"],["61980.80","0.272"],["61981.00","0.100"],["61981.10","0.027"],["61981.20","0.323"],["61981.40","0.072"],["61990.50","0.000"],["61990.80","5.163"],["62000.10","1.876"],["62001.40","0.127"],["62002.90","0.239"],["62006.40","0.002"],["62007.00","0.275"],["62018.80","1.448"],["62019.40","0.011"],["62020.30","0.005"],["62021.10","0.582"],["62025.30","0.134"],["62028.00","1.662"],["62028.20","0.180"],["62028.60","0.790"],["62028.70","0.762"],["62028.80","0.332"],["62029.20","0.157"],["62029.90","0.326"],["62031.10","1.005"],["62033.90","0.323"],["62034.50","0.004"],["62035.60","0.001"],["62038.40","1.007"],["62039.30","0.000"],["62041.10","1.803"],["62043.90","5.322"]],"e":"depthUpdate","ps":"BTCUSDT","pu":10998399883040,"s":"BTCUSDT","st":1,"u":10998399895462}
{"E":1783504321838,"T":1783504321837,"U":10998399895536,"a":[["62045.50","0.004"],["62045.60","0.099"],["62045.70","0.000"],["62045.80","0.121"],["62046.30","0.002"],["62046.40","0.010"],["62047.20","0.162"],["62047.80","0.562"],["62048.00","0.907"],["62056.80","0.002"],["62057.10","0.005"],["62057.50","0.725"],["62059.90","0.002"],["62060.60","0.584"],["62061.80","0.000"],["62062.50","0.708"],["62063.10","0.324"],["62064.10","0.474"],["62064.60","0.000"],["62065.10","0.627"],["62067.90","0.081"],["62092.30","0.091"],["62092.50","0.958"],["62093.00","0.071"],["62093.20","0.080"],["62664.40","0.000"],["62754.00","0.239"],["62834.30","1.274"],["62925.00","0.376"],["62958.40","0.000"],["62972.70","2.945"]],"b":[["11543.90","2.736"],["11643.90","0.992"],["11743.90","1.056"],["11943.90","0.016"],["55839.50","0.055"],["58932.20","0.004"],["58941.70","0.020"],["59562.10","0.003"],["60554.80","0.412"],["60889.90","0.820"],["60958.10","3.071"],["61423.50","0.000"],["61834.40","0.001"],["61963.90","0.049"],["61964.20","0.033"],["61964.50","0.043"],["61964.80","1.378"],["61981.40","0.070"],["61995.10","0.003"],["61997.10","0.094"],["62000.40","0.147"],["62000.80","0.062"],["62006.70","0.013"],["62019.20","0.024"],["62019.50","0.150"],["62020.50","0.581"],["62021.10","0.001"],["62025.40","0.001"],["62025.50","0.003"],["62026.60","0.726"],["62026.70","0.566"],["62043.90","5.320"]],"e":"depthUpdate","ps":"BTCUSDT","pu":10998399895462,"s":"BTCUSDT","st":1,"u":10998399909207}
{"E":1783504321940,"T":1783504321938,"U":10998399909288,"a":[["62044.00","6.922"],["62047.60","0.327"],["62047.80","0.001"],["62049.20","0.085"],["62049.50","0.262"],["62050.50","0.190"],["62057.00","0.000"],["62060.30","0.082"],["62067.90","0.001"],["62068.10","0.395"],["62093.50","0.058"],["62100.40","0.001"],["62108.10","0.000"],["62175.40","0.000"],["62664.40","0.000"],["62834.20","0.004"],["63295.90","0.678"]],"b":[["1000.00","210.542"],["11543.90","2.720"],["11643.90","0.992"],["11743.90","0.928"],["11943.90","0.160"],["49635.10","0.000"],["55839.50","0.055"],["61423.50","0.000"],["61783.00","0.002"],["61834.40","0.000"],["61908.40","0.000"],["61963.60","6.334"],["61981.70","0.018"],["61989.30","0.029"],["61999.10","0.017"],["62000.20","1.093"],["62000.40","0.207"],["62001.30","0.061"],["62006.90","0.769"],["62011.60","0.008"],["62016.00","0.023"],["62018.10","0.620"],["62022.50","0.006"],["62031.50","0.153"],["62037.00","0.002"],["62043.90","5.315"]],"e":"depthUpdate","ps":"BTCUSDT","pu":10998399909207,"s":"BTCUSDT","st":1,"u":10998399920417}
{"E":1783504322042,"T":1783504322041,"U":10998399920831,"a":[["62044.00","0.000"],["62044.10","1.635"],["62044.20","0.009"],["62044.70","0.003"],["62044.80","0.001"],["62044.90","0.004"],["62045.10","0.000"],["62045.40","0.026"],["62045.60","0.007"],["62045.80","0.121"],["62045.90","0.645"],["62046.00","0.074"],["62046.10","0.000"],["62046.20","0.131"],["62046.40","0.010"],["62046.50","0.004"],["62046.60","0.003"],["62046.80","0.004"],["62046.90","0.002"],["62047.10","0.000"],["62047.20","0.002"],["62047.30","0.000"],["62047.40","0.008"],["62047.60","0.003"],["62047.70","0.007"],["62047.90","0.002"],["62048.00","0.005"],["62048.10","0.001"],["62048.20","0.000"],["62048.30","0.665"],["62048.40","0.003"],["62048.60","0.004"],["62048.90","0.001"],["62049.00","0.241"],["62049.10","0.001"],["62049.40","0.628"],["62049.50","0.261"],["62049.60","0.081"],["62049.70","0.003"],["62049.80","0.061"],["62050.20","0.289"],["62050.30","0.014"],["62050.50","0.198"],["62050.60","0.818"],["62050.70","0.313"],["62050.80","0.090"],["62050.90","0.001"],["62051.00","0.004"],["62051.10","0.014"],["62051.20","0.082"],["62051.50","0.001"],["62051.60","1.000"],["62051.80","0.018"],["62052.00","0.002"],["62052.30","0.001"],["62052.60","0.001"],["62052.70","0.004"],["62052.80","0.051"],["62053.00","0.276"],["62053.10","0.563"],["62053.20","0.002"],["62053.40","0.008"],["62053.50","0.042"],["62054.00","0.379"],["62054.10","0.001"],["62054.20","0.323"],["62054.30","0.001"],["62054.40","0.327"],["62055.60","0.053"],["62055.70","0.022"],["62055.80","0.004"],["62056.40","0.342"],["62056.50","0.008"],["62056.60","0.286"],["62056.70","0.574"],["62057.30","0.322"],["62057.40","0.163"],["62057.50","0.000"],["62057.60","0.022"],["62057.70","0.331"],["62058.00","0.071"],["62058.10","0.000"],["62058.30","0.342"],["62058.70","0.005"],["62058.90","0.004"],["62059.20","0.566"],["62059.40","0.757"],["62059.50","0.004"],["62060.30","0.002"],["62060.50","0.001"],["62060.60","0.004"],["62061.20","0.034"],["62061.30","0.001"],["62061.40","0.820"],["62061.60","0.754"],["62061.80","0.000"],["62062.10","0.026"],["62062.50","0.000"],["62062.60","0.792"],["62062.70","0.132"],["62062.80","0.879"],["62062.90","1.203"],["62063.50","1.578"],["62064.10","0.172"],["62064.60","0.580"],["62064.90","0.001"],["62065.40","0.005"],["62065.60","0.001"],["62065.70","0.002"],["62066.10","0.261"],["62066.60","0.282"],["62067.20","0.003"],["62067.30","0.361"],["62067.50","0.681"],["62068.10","0.263"],["62068.60","0.003"],["62068.80","0.101"],["62069.10","0.121"],["62069.80","0.061"],["62070.90","2.122"],["62071.00","0.860"],["62071.40","0.328"],["62071.50","0.060"],["62071.90","0.016"],["62072.00","0.001"],["62072.20","0.010"],["62072.40","0.028"],["62072.80","1.397"],["62073.10","0.280"],["62073.40","0.010"],["62074.80","0.003"],["62075.30","0.366"],["62075.40","9.458"],["62075.50","1.112"],["62075.60","1.362"],["62076.20","0.033"],["62077.40","0.133"],["62077.80","1.486"],["62078.20","1.467"],["62078.30","0.791"],["62078.60","0.181"],["62078.70","3.600"],["62078.90","0.003"],["62079.90","0.070"],["62080.00","1.039"],["62081.90","0.023"],["62082.10","0.002"],["62082.40","0.018"],["62083.30","0.141"],["62083.60","1.295"],["62084.00","0.034"],["62084.20","0.084"],["62084.80","1.367"],["62084.90","0.050"],["62085.30","0.266"],["62086.50","4.516"],["62087.40","0.000"],["62087.70","0.001"],["62088.00","0.364"],["62089.80","0.001"],["62090.30","1.621"],["62090.40","1.298"],["62090.70","0.003"],["62091.00","0.029"],["62091.60","0.067"],["62094.60","0.003"],["62094.90","0.059"],["62097.00","0.003"],["62097.20","0.260"],["62097.30","0.688"],["62097.50","0.096"],["62101.20","0.030"],["62102.20","0.023"],["62103.30","0.101"],["62103.40","0.365"],["62103.70","0.292"],["62103.80","0.424"],["62104.10","1.592"],["62104.20","0.758"],["62107.10","0.011"],["62107.60","0.745"],["62107.80","0.340"],["62108.10","0.233"],["62108.20","9.943"],["62109.60","21.332"],["62125.00","0.160"],["62126.80","0.001"],["62137.10","0.002"],["62137.20","0.319"],["62143.80","0.132"],["62144.50","0.696"],["62160.00","0.528"],["62175.50","0.634"],["62240.00","0.589"],["62320.00","0.525"],["62354.30","0.000"],["62355.10","0.000"],["62360.50","2.673"],["62400.00","14.480"],["62664.40","0.002"],["62775.80","18.859"],["62957.20","0.803"],["63284.80","0.021"]],"b":[["1000.00","210.542"],["11543.90","2.736"],["11643.90","0.976"],["11743.90","0.800"],["11943.90","0.288"],["55839.50","0.053"],["55839.60","0.002"],["56523.70","0.597"],["58941.20","0.018"],["59562.10","0.000"],["60803.10","0.011"],["60958.10","4.382"],["61423.50","0.006"],["61423.60","0.007"],["61609.70","0.492"],["61680.00","1.081"],["61733.60","0.002"],["61733.70","0.016"],["61760.00","0.573"],["61834.40","0.001"],["61840.00","0.429"],["61869.90","6.177"],["61883.50","0.038"],["61895.90","0.001"],["61908.30","0.126"],["61908.80","0.659"],["61920.00","0.486"],["61940.90","1.031"],["61949.20","4.115"],["61953.20","0.522"],["61955.40","0.001"],["61963.80","0.010"],["61966.60","0.124"],["61967.20","0.017"],["61967.90","0.100"],["61969.20","0.101"],["61971.80","0.000"],["61974.00","0.679"],["61976.90","0.004"],["61978.10","0.085"],["61981.60","0.004"],["61981.90","1.542"],["61982.10","0.008"],["61983.80","0.017"],["61984.30","1.531"],["61992.90","0.010"],["61993.20","0.327"],["61993.40","0.000"],["61994.00","0.004"],["61994.80","0.000"],["61995.00","0.674"],["61997.00","1.202"],["61998.60","0.685"],["61998.70","1.907"],["61998.80","0.007"],["61998.90","0.002"],["61999.20","0.052"],["61999.40","0.000"],["62000.00","9.044"],["62000.20","1.153"],["62000.80","0.182"],["62001.10","0.015"],["62001.40","0.078"],["62002.80","0.086"],["62002.90","0.543"],["62003.00","0.001"],["62003.50","0.059"],["62003.60","0.169"],["62003.70","0.163"],["62004.00","0.001"],["62004.70","0.046"],["62005.30","0.238"],["62006.00","0.029"],["62006.70","0.003"],["62008.90","0.087"],["62009.00","0.001"],["62009.90","1.389"],["62010.10","0.004"],["62010.30","0.001"],["62010.50","0.052"],["62012.00","0.001"],["62013.10","0.033"],["62013.40","0.120"],["62013.80","1.289"],["62013.90","0.296"],["62014.10","0.010"],["62014.80","0.001"],["62014.90","0.352"],["62015.00","0.129"],["62015.20","1.365"],["62015.40","0.000"],["62015.50","0.020"],["62015.70","0.000"],["62016.00","0.031"],["62016.20","0.001"],["62016.30","0.347"],["62017.10","0.458"],["62017.30","0.000"],["62018.90","0.370"],["62019.10","0.017"],["62019.20","0.014"],["62019.50","0.148"],["62019.90","0.099"],["62020.00","0.319"],["62020.10","0.003"],["62020.50","0.000"],["62021.10","0.001"],["62021.40","1.363"],["62021.90","0.049"],["62022.50","0.006"],["62022.60","0.049"],["62023.30","0.003"],["62023.50","2.594"],["62023.70","0.058"],["62024.40","0.290"],["62024.60","0.294"],["62024.70","0.000"],["62025.20","0.003"],["62025.30","0.007"],["62025.40","0.122"],["62025.60","0.002"],["62025.70","0.018"],["62025.80","0.323"],["62026.10","0.083"],["62026.20","0.004"],["62026.30","0.050"],["62026.60","0.000"],["62026.70","0.002"],["62027.00","0.001"],["62027.70","0.305"],["62028.00","1.646"],["62028.10","1.484"],["62028.20","0.180"],["62028.70","0.182"],["62028.80","0.010"],["62028.90","0.359"],["62029.30","0.003"],["62029.50","0.034"],["62029.60","0.013"],["62030.50","0.727"],["62030.90","1.363"],["62031.00","0.569"],["62031.30","0.426"],["62031.40","0.064"],["62031.50","0.279"],["62031.80","0.000"],["62032.00","0.566"],["62032.50","0.010"],["62032.80","0.004"],["62032.90","0.120"],["62033.60","1.380"],["62034.00","2.039"],["62034.50","0.006"],["62034.60","1.319"],["62035.10","0.002"],["62035.80","0.007"],["62036.10","0.007"],["62036.20","0.000"],["62036.30","1.364"],["62036.50","0.001"],["62036.60","0.292"],["62037.20","0.003"],["62037.30","0.000"],["62037.50","0.001"],["62037.70","0.001"],["62038.40","0.306"],["62038.60","0.005"],["62038.80","0.006"],["62039.40","0.001"],["62039.50","0.003"],["62039.60","0.195"],["62040.00","0.050"],["62040.40","0.052"],["62040.60","0.060"],["62041.10","1.800"],["62041.20","0.002"],["62041.30","0.032"],["62041.70","0.000"],["62042.10","0.787"],["62042.60","0.002"],["62042.80","0.000"],["62043.60","0.123"],["62043.80","0.056"],["62043.90","1.630"],["62044.00","31.777"]],"e":"depthUpdate","ps":"BTCUSDT","pu":10998399920417,"s":"BTCUSDT","st":1,"u":10998399968018}
{"E":1783504322144,"T":1783504322143,"U":10998399968032,"a":[["62044.10","0.000"],["62044.20","0.000"],["62044.30","0.000"],["62044.40","0.000"],["62044.70","0.000"],["62044.80","0.000"],["62044.90","0.000"],["62045.00","0.000"],["62045.20","0.000"],["62045.40","0.000"],["62045.50","0.000"],["62045.60","0.000"],["62045.70","0.000"],["62045.80","0.000"],["62045.90","0.000"],["62046.00","0.000"],["62046.10","0.651"],["62046.20","0.131"],["62046.30","0.001"],["62046.40","0.001"],["62046.50","0.001"],["62046.60","0.002"],["62046.90","0.000"],["62047.20","0.121"],["62047.30","0.000"],["62047.40","0.004"],["62047.50","0.000"],["62047.60","0.001"],["62047.70","0.094"],["62047.80","0.000"],["62047.90","0.000"],["62048.10","0.000"],["62048.20","0.006"],["62048.30","0.656"],["62048.40","0.001"],["62048.50","0.000"],["62048.70","0.000"],["62049.00","0.001"],["62049.10","0.001"],["62049.20","0.002"],["62049.30","0.009"],["62049.40","0.000"],["62049.50","0.008"],["62049.60","0.016"],["62049.80","0.003"],["62050.00","0.001"],["62050.10","0.570"],["62050.20","0.043"],["62050.30","0.013"],["62050.40","0.002"],["62050.50","0.003"],["62050.60","0.002"],["62050.70","0.026"],["62050.80","0.203"],["62050.90","0.001"],["62051.00","0.104"],["62051.10","0.003"],["62051.20","0.001"],["62051.30","0.646"],["62051.40","0.001"],["62051.60","0.000"],["62052.10","0.061"],["62052.20","0.090"],["62052.30","0.065"],["62052.40","0.359"],["62052.50","1.015"],["62052.60","0.903"],["62052.70","0.580"],["62052.80","0.003"],["62052.90","0.957"],["62053.00","0.174"],["62053.10","0.563"],["62053.30","0.001"],["62053.40","0.004"],["62053.50","0.327"],["62053.60","0.000"],["62053.90","0.001"],["62054.00","0.425"],["62054.10","0.097"],["62054.20","0.001"],["62054.30","0.091"],["62054.40","0.005"],["62054.50","0.003"],["62054.60","0.081"],["62054.70","0.820"],["62054.90","0.049"],["62055.00","0.003"],["62055.10","0.000"],["62055.20","0.654"],["62055.30","1.605"],["62055.40","0.871"],["62055.60","0.002"],["62055.70","0.021"],["62056.00","0.389"],["62056.20","0.000"],["62056.30","0.000"],["62056.40","0.000"],["62056.50","0.000"],["62056.60","0.034"],["62056.70","0.042"],["62056.80","1.002"],["62056.90","0.943"],["62057.00","0.002"],["62057.10","0.002"],["62057.20","0.005"],["62057.30","0.000"],["62057.50","0.324"],["62057.70","0.325"],["62057.80","1.415"],["62057.90","0.007"],["62058.00","0.002"],["62058.10","0.000"],["62058.20","0.458"],["62058.30","0.453"],["62058.40","0.132"],["62058.60","0.004"],["62058.80","0.007"],["62058.90","0.004"],["62059.00","0.004"],["62059.10","0.293"],["62059.20","0.232"],["62059.30","1.297"],["62059.40","0.881"],["62059.80","0.005"],["62060.00","0.174"],["62060.10","0.406"],["62060.50","0.005"],["62060.60","0.000"],["62060.70","0.013"],["62060.80","0.006"],["62061.00","0.246"],["62061.10","0.003"],["62061.20","0.599"],["62061.30","0.007"],["62061.40","0.162"],["62061.50","1.520"],["62061.60","0.009"],["62061.80","0.342"],["62061.90","0.027"],["62062.20","0.063"],["62062.30","0.016"],["62062.40","0.014"],["62062.50","0.000"],["62062.60","0.001"],["62062.70","0.014"],["62062.80","0.879"],["62063.00","1.080"],["62063.20","0.526"],["62063.40","0.960"],["62063.50","0.686"],["62063.70","0.005"],["62063.80","0.000"],["62064.10","0.130"],["62064.20","0.102"],["62064.40","0.664"],["62064.60","0.000"],["62064.70","0.306"],["62065.00","0.212"],["62065.10","0.563"],["62065.30","0.402"],["62065.40","0.006"],["62065.70","0.002"],["62065.80","0.002"],["62066.00","0.004"],["62066.10","0.016"],["62066.20","0.009"],["62066.60","0.862"],["62066.90","0.531"],["62067.10","0.246"],["62067.20","0.066"],["62067.30","0.327"],["62067.50","0.683"],["62067.60","0.069"],["62067.90","0.009"],["62068.10","0.100"],["62068.20","1.020"],["62068.30","0.003"],["62068.50","0.005"],["62068.70","0.044"],["62068.80","0.081"],["62069.00","1.411"],["62069.10","0.002"],["62069.20","0.415"],["62069.40","0.010"],["62069.80","0.002"],["62070.00","0.314"],["62070.20","0.003"],["62070.40","0.017"],["62070.50","0.000"],["62070.60","0.146"],["62070.70","0.089"],["62071.30","0.072"],["62071.80","0.277"],["62072.00","0.121"],["62072.20","0.061"],["62072.40","0.028"],["62072.60","0.083"],["62072.70","0.978"],["62072.90","0.012"],["62073.00","0.051"],["62073.20","0.028"],["62073.30","0.122"],["62073.40","0.002"],["62073.60","2.588"],["62073.90","0.661"],["62074.00","0.036"],["62074.20","0.089"],["62074.30","0.001"],["62074.60","0.001"],["62074.70","0.010"],["62075.00","5.668"],["62075.10","0.348"],["62075.40","9.353"],["62075.70","0.008"],["62075.80","0.004"],["62076.00","0.006"],["62076.10","0.590"],["62076.80","0.080"],["62077.40","0.104"],["62077.50","0.481"],["62078.20","1.467"],["62078.30","0.791"],["62078.60","0.286"],["62078.90","0.000"],["62079.00","0.006"],["62079.20","0.000"],["62079.30","0.028"],["62079.90","0.000"],["62080.00","1.057"],["62080.10","0.000"],["62080.20","0.017"],["62080.40","0.000"],["62080.60","0.006"],["62081.00","0.346"],["62081.50","0.000"],["62081.70","0.027"],["62081.90","0.020"],["62082.50","0.043"],["62082.70","0.090"],["62082.80","0.000"],["62082.90","0.944"],["62083.10","0.708"],["62083.40","0.713"],["62083.50","0.231"],["62083.70","0.086"],["62083.80","0.504"],["62084.00","0.034"],["62084.30","0.161"],["62084.40","1.435"],["62084.50","0.820"],["62084.60","0.109"],["62084.70","0.472"],["62084.80","1.365"],["62085.10","0.057"],["62085.90","0.756"],["62086.30","0.002"],["62086.50","4.518"],["62086.80","0.022"],["62086.90","0.000"],["62087.00","0.275"],["62087.10","0.659"],["62087.60","0.000"],["62088.00","0.304"],["62088.20","0.010"],["62088.50","3.789"],["62088.70","0.000"],["62089.30","0.000"],["62090.40","1.295"],["62090.60","0.000"],["62091.40","0.002"],["62091.50","1.365"],["62091.60","0.053"],["62091.80","0.342"],["62091.90","0.000"],["62092.00","0.011"],["62092.50","0.960"],["62092.90","0.317"],["62093.10","0.156"],["62093.40","0.003"],["62093.60","0.000"],["62093.90","0.003"],["62094.30","0.051"],["62095.20","0.034"],["62095.40","0.076"],["62095.70","0.002"],["62095.80","0.324"],["62095.90","0.784"],["62096.00","1.366"],["62096.40","0.028"],["62097.20","0.164"],["62097.50","0.163"],["62097.60","0.536"],["62097.70","1.902"],["62098.20","0.000"],["62098.70","0.041"],["62099.30","0.029"],["62099.70","0.671"],["62099.80","0.606"],["62100.10","0.001"],["62100.20","0.006"],["62100.40","0.004"],["62100.70","0.028"],["62101.10","0.000"],["62102.30","0.026"],["62102.70","0.038"],["62102.80","0.004"],["62102.90","0.003"],["62105.10","0.109"],["62105.50","0.000"],["62106.30","0.096"],["62106.40","0.118"],["62107.30","0.774"],["62107.60","0.693"],["62107.80","0.692"],["62107.90","0.099"],["62108.00","0.604"],["62108.10","0.429"],["62108.50","1.386"],["62109.60","0.018"],["62109.70","1.295"],["62110.80","0.673"],["62111.00","0.529"],["62111.50","0.001"],["62111.80","0.424"],["62111.90","0.154"],["62112.20","0.539"],["62112.30","0.821"],["62113.00","0.113"],["62114.00","0.107"],["62114.10","0.034"],["62114.60","0.067"],["62115.20","0.000"],["62115.80","0.282"],["62116.80","0.001"],["62117.00","0.016"],["62117.20","0.294"],["62117.30","0.031"],["62117.40","0.000"],["62117.90","0.001"],["62118.80","0.030"],["62118.90","0.038"],["62119.00","0.088"],["62120.10","22.087"],["62122.40","0.001"],["62123.70","6.207"],["62125.60","0.014"],["62127.20","0.000"],["62127.80","0.002"],["62128.00","4.528"],["62128.10","0.707"],["62128.60","0.075"],["62128.70","0.015"],["62128.90","0.044"],["62129.60","0.290"],["62129.70","0.043"],["62137.20","0.007"],["62137.60","0.017"],["62138.00","0.684"],["62139.20","0.013"],["62139.90","3.180"],["62144.80","0.292"],["62148.50","0.000"],["62150.00","102.272"],["62153.70","0.531"],["62160.00","0.546"],["62162.50","0.256"],["62184.40","0.000"],["62195.80","0.676"],["62197.80","0.074"],["62207.50","0.018"],["62215.40","0.001"],["62218.50","0.003"],["62223.00","0.044"],["62240.00","0.607"],["62240.50","0.028"],["62277.90","0.278"],["62306.50","0.683"],["62306.90","0.654"],["62307.00","1.721"],["62320.00","0.543"],["62361.30","0.000"],["62368.10","0.001"],["62371.30","0.001"],["62373.10","0.180"],["62400.00","14.498"],["62443.90","0.289"],["62664.40","0.000"],["62664.50","0.001"],["62664.70","0.010"],["62666.30","0.569"],["62666.40","0.000"],["62666.50","0.000"],["62666.60","0.633"],["62758.00","2.838"],["62759.50","10.406"],["62759.70","1.896"],["62820.10","2.299"],["62821.60","8.675"],["62850.60","3.081"],["62958.20","0.025"],["62974.70","1.785"],["62995.90","0.000"],["63286.80","0.004"],["63286.90","0.003"],["67642.80","0.010"]],"b":[["11543.90","2.592"],["11544.20","0.016"],["11545.70","0.016"],["11545.80","0.048"],["11545.90","0.032"],["11546.00","0.016"],["11643.90","0.848"],["11644.00","0.016"],["11645.70","0.032"],["11645.80","0.048"],["11645.90","0.016"],["11646.00","0.032"],["11743.90","0.656"],["11944.20","0.016"],["11945.70","0.016"],["11945.80","0.064"],["11945.90","0.016"],["11946.00","0.032"],["49635.00","0.000"],["55839.60","0.000"],["55841.10","0.000"],["55841.20","0.000"],["55841.30","0.061"],["55841.40","0.002"],["59563.90","0.003"],["60804.80","0.006"],["60805.10","0.003"],["61035.60","0.004"],["61037.60","0.002"],["61037.70","0.493"],["61037.80","0.013"],["61039.40","1.985"],["61045.70","0.012"],["61045.80","0.011"],["61046.00","0.046"],["61072.30","0.723"],["61082.00","0.009"],["61291.90","1.615"],["61423.50","0.000"],["61423.60","0.003"],["61423.80","0.000"],["61425.20","0.000"],["61425.30","0.002"],["61425.40","0.000"],["61425.50","0.002"],["61541.50","0.000"],["61547.80","0.001"],["61603.50","0.010"],["61609.90","0.003"],["61622.30","0.245"],["61680.00","1.099"],["61710.30","0.022"],["61720.50","0.104"],["61760.00","0.591"],["61789.60","0.001"],["61795.70","0.000"],["61796.00","0.001"],["61825.10","0.004"],["61834.40","0.000"],["61838.20","0.959"],["61840.00","0.447"],["61855.90","0.008"],["61857.20","0.275"],["61863.70","0.000"],["61869.70","0.072"],["61870.00","0.076"],["61870.10","0.003"],["61877.20","0.315"],["61883.50","0.000"],["61898.50","0.053"],["61917.50","0.000"],["61919.20","0.001"],["61919.30","0.022"],["61920.00","0.504"],["61921.10","0.367"],["61921.30","2.500"],["61931.50","0.145"],["61932.20","0.032"],["61935.40","0.615"],["61939.00","0.005"],["61941.30","0.028"],["61941.40","0.000"],["61943.40","0.000"],["61948.50","0.000"],["61949.30","0.989"],["61951.70","0.008"],["61952.10","1.404"],["61952.50","2.213"],["61953.80","0.000"],["61954.10","0.001"],["61955.30","0.000"],["61955.50","1.539"],["61955.60","0.000"],["61956.50","0.000"],["61957.10","0.340"],["61958.80","0.255"],["61963.70","3.278"],["61964.00","0.015"],["61965.00","0.122"],["61966.40","0.038"],["61966.90","19.398"],["61967.00","0.077"],["61967.80","0.248"],["61967.90","0.253"],["61968.50","0.001"],["61969.50","0.203"],["61970.20","0.000"],["61971.10","0.030"],["61975.50","0.672"],["61976.00","0.000"],["61976.20","0.944"],["61977.10","0.097"],["61978.00","0.001"],["61979.90","0.003"],["61980.00","0.845"],["61980.70","0.000"],["61981.40","0.040"],["61981.70","0.016"],["61981.90","1.297"],["61982.00","0.598"],["61982.20","0.121"],["61983.10","0.000"],["61983.70","0.085"],["61984.80","0.262"],["61985.40","0.412"],["61985.90","0.152"],["61986.30","0.011"],["61986.60","0.612"],["61989.00","0.010"],["61990.90","0.002"],["61991.00","1.141"],["61991.70","0.017"],["61992.20","0.122"],["61992.60","0.010"],["61992.70","0.000"],["61993.20","0.325"],["61993.90","1.346"],["61994.10","0.265"],["61994.50","1.383"],["61995.00","0.660"],["61995.20","0.679"],["61995.80","0.000"],["61995.90","0.309"],["61996.00","0.002"],["61996.10","0.000"],["61997.10","0.031"],["61997.20","0.444"],["61997.70","0.004"],["61997.90","3.791"],["61998.30","0.013"],["61998.80","0.004"],["61999.10","0.015"],["61999.80","0.050"],["61999.90","0.005"],["62000.00","9.062"],["62000.20","1.299"],["62000.30","0.079"],["62000.40","0.207"],["62000.50","0.004"],["62000.80","0.241"],["62000.90","0.198"],["62001.10","0.001"],["62001.50","0.032"],["62001.80","0.680"],["62002.10","4.155"],["62002.30","1.296"],["62002.40","2.433"],["62002.60","0.025"],["62002.80","0.522"],["62002.90","0.461"],["62003.00","0.083"],["62003.10","0.003"],["62003.80","0.246"],["62004.60","0.047"],["62004.70","0.039"],["62005.20","0.634"],["62005.30","0.025"],["62005.60","0.051"],["62006.10","1.135"],["62006.60","0.112"],["62006.70","0.000"],["62007.00","1.249"],["62007.10","0.158"],["62007.40","0.000"],["62007.50","0.003"],["62008.10","0.004"],["62008.20","0.003"],["62008.50","0.004"],["62008.60","0.292"],["62008.80","0.003"],["62008.90","0.027"],["62009.30","0.004"],["62009.70","0.055"],["62009.90","1.388"],["62010.00","0.142"],["62010.10","0.001"],["62010.20","0.057"],["62010.60","0.000"],["62010.90","0.014"],["62011.00","0.004"],["62011.20","0.022"],["62011.40","0.281"],["62011.50","0.042"],["62011.60","0.000"],["62011.70","0.001"],["62011.90","0.003"],["62012.00","0.001"],["62012.10","0.667"],["62012.20","0.002"],["62012.40","2.004"],["62012.60","1.309"],["62012.70","0.892"],["62012.90","0.455"],["62013.00","0.002"],["62013.10","0.008"],["62013.30","0.012"],["62013.70","0.217"],["62014.10","0.002"],["62014.50","0.091"],["62014.70","0.001"],["62014.80","0.001"],["62014.90","0.010"],["62015.00","0.134"],["62015.20","1.363"],["62015.60","0.001"],["62015.80","0.000"],["62015.90","0.120"],["62016.00","0.007"],["62016.30","0.347"],["62016.50","0.009"],["62016.60","0.002"],["62016.90","0.530"],["62017.00","0.681"],["62017.10","0.010"],["62017.20","1.014"],["62017.50","0.002"],["62017.70","0.122"],["62017.90","0.002"],["62018.00","0.195"],["62018.40","0.001"],["62018.50","0.973"],["62018.60","0.084"],["62018.80","1.416"],["62018.90","0.311"],["62019.00","0.001"],["62019.30","0.052"],["62019.40","0.006"],["62019.50","0.048"],["62019.60","0.015"],["62019.80","0.018"],["62020.00","0.933"],["62020.20","0.684"],["62020.30","0.008"],["62020.40","1.640"],["62020.50","0.010"],["62020.60","0.059"],["62020.80","0.042"],["62020.90","0.001"],["62021.10","0.002"],["62022.10","0.016"],["62022.20","0.000"],["62022.30","0.001"],["62022.40","0.004"],["62022.50","0.007"],["62022.70","0.001"],["62023.00","0.252"],["62023.10","0.005"],["62023.20","0.008"],["62023.30","0.001"],["62023.40","0.083"],["62023.50","1.998"],["62023.60","0.005"],["62023.70","0.003"],["62023.90","0.002"],["62024.00","0.684"],["62024.10","0.059"],["62024.20","1.362"],["62024.30","0.001"],["62024.40","0.033"],["62024.50","1.341"],["62024.60","0.423"],["62024.70","0.414"],["62024.80","0.005"],["62024.90","0.004"],["62025.00","0.006"],["62025.20","0.003"],["62025.30","0.084"],["62025.40","0.081"],["62025.50","0.004"],["62025.60","0.003"],["62025.70","0.164"],["62025.80","0.324"],["62025.90","0.037"],["62026.10","0.601"],["62026.40","0.172"],["62026.50","0.041"],["62026.80","0.002"],["62026.90","0.003"],["62027.00","0.661"],["62027.10","0.371"],["62027.20","0.051"],["62027.30","0.003"],["62027.40","0.089"],["62027.70","0.421"],["62028.00","2.008"],["62028.10","1.357"],["62028.40","2.054"],["62028.60","0.666"],["62028.80","0.352"],["62028.90","0.357"],["62029.40","0.322"],["62029.50","0.044"],["62029.60","0.026"],["62029.80","0.133"],["62029.90","0.326"],["62030.00","0.007"],["62030.10","0.728"],["62030.30","0.326"],["62030.50","0.003"],["62030.70","0.000"],["62030.80","1.187"],["62030.90","1.363"],["62031.00","0.005"],["62031.10","0.569"],["62031.20","0.295"],["62031.30","0.137"],["62031.40","0.000"],["62031.50","0.052"],["62031.70","0.001"],["62032.00","0.126"],["62032.10","0.022"],["62032.50","1.012"],["62032.60","0.319"],["62032.80","0.022"],["62033.00","0.021"],["62033.10","1.715"],["62033.20","0.065"],["62033.30","0.001"],["62033.50","0.161"],["62033.70","0.008"],["62033.80","0.023"],["62034.00","2.039"],["62034.10","0.762"],["62034.20","0.009"],["62034.40","0.000"],["62034.50","0.086"],["62034.60","1.637"],["62034.70","0.001"],["62034.80","0.080"],["62035.00","0.347"],["62035.10","0.124"],["62035.50","0.075"],["62035.60","0.012"],["62035.70","0.000"],["62035.80","0.065"],["62036.40","0.642"],["62036.60","0.413"],["62036.80","0.173"],["62037.20","0.001"],["62037.50","0.003"],["62037.80","0.289"],["62037.90","0.035"],["62038.20","0.000"],["62038.50","0.147"],["62038.60","0.001"],["62038.70","0.006"],["62038.80","0.004"],["62039.00","0.002"],["62039.10","0.001"],["62039.50","0.405"],["62039.60","0.000"],["62039.70","0.049"],["62039.80","0.001"],["62039.90","0.003"],["62040.00","0.010"],["62040.20","0.000"],["62040.30","0.051"],["62040.40","0.002"],["62040.60","0.004"],["62040.90","0.153"],["62041.00","0.006"],["62041.10","0.002"],["62041.20","0.042"],["62041.50","0.042"],["62041.60","0.001"],["62041.70","0.001"],["62041.80","0.034"],["62041.90","0.002"],["62042.10","0.323"],["62042.20","0.267"],["62042.30","0.001"],["62042.40","0.026"],["62042.60","0.003"],["62043.10","0.002"],["62043.60","0.121"],["62043.70","0.001"],["62043.80","0.058"],["62043.90","0.384"],["62044.00","0.214"],["62044.10","0.001"],["62044.20","0.040"],["62044.30","0.002"],["62044.40","0.008"],["62044.50","0.001"],["62044.60","0.000"],["62044.70","0.000"],["62044.80","0.001"],["62044.90","0.000"],["62045.00","0.000"],["62045.10","0.000"],["62045.30","0.000"],["62045.40","0.000"],["62045.50","0.279"],["62045.60","0.003"],["62045.70","0.199"],["62045.80","1.800"],["62045.90","3.082"],["62046.00","19.086"]],"e":"depthUpdate","ps":"BTCUSDT","pu":10998399968018,"s":"BTCUSDT","st":1,"u":10998400021644}
{"E":1783504322246,"T":1783504322245,"U":10998400021780,"a":[["62046.10","0.000"],["62046.20","0.000"],["62046.30","0.000"],["62046.40","0.000"],["62046.50","0.000"],["62046.60","0.000"],["62046.80","0.000"],["62047.00","0.000"],["62047.20","0.000"],["62047.40","4.768"],["62047.50","0.003"],["62047.60","0.001"],["62047.70","0.001"],["62047.80","0.000"],["62048.20","0.105"],["62048.50","0.005"],["62049.00","0.093"],["62049.20","0.000"],["62049.50","0.004"],["62049.60","0.011"],["62050.10","0.570"],["62050.40","0.001"],["62050.60","0.001"],["62050.70","0.003"],["62050.80","0.056"],["62050.90","0.050"],["62051.00","0.000"],["62051.30","0.650"],["62051.70","0.002"],["62052.10","0.001"],["62052.20","0.001"],["62052.30","0.065"],["62052.40","0.466"],["62052.50","0.821"],["62052.60","0.905"],["62052.70","0.004"],["62052.90","0.981"],["62053.00","0.174"],["62053.10","0.003"],["62053.50","0.327"],["62053.60","0.224"],["62053.70","0.058"],["62053.80","0.293"],["62053.90","0.577"],["62054.00","0.463"],["62054.10","1.097"],["62054.20","0.000"],["62054.50","0.001"],["62054.60","0.243"],["62055.10","0.000"],["62055.20","0.046"],["62055.40","0.872"],["62055.50","0.001"],["62055.70","0.008"],["62056.00","0.067"],["62056.20","0.701"],["62056.70","0.164"],["62056.80","0.002"],["62057.00","0.001"],["62057.20","0.003"],["62057.70","0.325"],["62057.90","0.008"],["62058.00","0.042"],["62058.10","0.322"],["62058.20","0.454"],["62058.30","0.473"],["62058.50","0.342"],["62059.00","0.002"],["62059.30","1.417"],["62059.60","0.122"],["62060.10","0.402"],["62060.50","0.004"],["62060.70","0.013"],["62061.00","0.005"],["62061.20","0.003"],["62061.30","0.001"],["62061.40","0.484"],["62061.50","1.520"],["62061.60","0.008"],["62061.80","0.382"],["62062.30","0.009"],["62062.70","0.578"],["62062.80","0.877"],["62062.90","0.209"],["62063.00","0.349"],["62063.20","0.526"],["62063.40","0.276"],["62063.50","0.087"],["62064.10","0.855"],["62064.40","0.001"],["62064.80","1.129"],["62064.90","0.005"],["62065.00","0.213"],["62065.60","0.003"],["62065.80","0.015"],["62066.00","0.668"],["62066.50","0.163"],["62067.00","0.109"],["62067.20","0.003"],["62067.40","0.649"],["62067.50","0.684"],["62068.00","0.250"],["62068.20","1.021"],["62068.30","0.065"],["62068.70","0.004"],["62069.10","0.038"],["62069.20","0.003"],["62069.40","0.088"],["62069.50","0.060"],["62069.70","0.164"],["62070.00","0.476"],["62070.10","0.325"],["62070.20","2.703"],["62070.30","10.403"],["62070.60","0.146"],["62070.70","0.098"],["62070.80","1.487"],["62071.00","0.074"],["62071.10","0.009"],["62071.40","0.328"],["62072.30","0.083"],["62072.40","0.059"],["62072.50","0.005"],["62072.60","0.091"],["62073.20","0.052"],["62073.50","0.077"],["62073.80","0.000"],["62074.10","0.034"],["62074.20","0.016"],["62074.70","0.004"],["62074.90","0.165"],["62075.00","5.579"],["62075.20","0.017"],["62075.30","0.360"],["62075.50","1.007"],["62075.70","0.000"],["62075.90","0.323"],["62076.40","0.061"],["62076.80","0.076"],["62077.00","0.057"],["62077.80","1.437"],["62078.40","0.879"],["62078.60","0.375"],["62079.00","0.076"],["62079.60","0.323"],["62079.70","0.195"],["62079.80","0.881"],["62079.90","0.194"],["62080.00","1.058"],["62080.20","0.014"],["62080.90","0.021"],["62081.00","0.336"],["62081.20","0.001"],["62081.30","0.884"],["62081.40","0.690"],["62081.60","0.004"],["62082.00","0.001"],["62082.10","0.012"],["62082.80","0.000"],["62083.40","1.015"],["62083.50","0.121"],["62083.70","0.083"],["62083.80","0.399"],["62084.40","0.755"],["62084.60","0.053"],["62084.70","0.472"],["62085.00","0.552"],["62085.10","0.004"],["62085.40","0.020"],["62085.70","0.002"],["62085.80","0.666"],["62085.90","0.686"],["62086.00","0.090"],["62086.20","0.000"],["62086.50","0.016"],["62086.60","0.201"],["62087.10","0.657"],["62087.20","2.458"],["62087.80","1.357"],["62088.30","0.016"],["62088.40","0.681"],["62088.50","3.777"],["62088.90","0.213"],["62089.50","0.051"],["62091.40","0.000"],["62091.50","1.362"],["62091.60","0.065"],["62091.80","0.353"],["62092.60","0.002"],["62092.90","0.320"],["62093.10","0.159"],["62094.00","0.856"],["62094.30","0.041"],["62095.40","0.077"],["62096.00","1.392"],["62097.30","0.680"],["62097.40","0.205"],["62097.50","0.295"],["62098.00","0.000"],["62098.70","0.027"],["62098.80","0.016"],["62098.90","0.031"],["62100.40","0.001"],["62100.70","0.036"],["62101.50","0.006"],["62102.70","0.034"],["62103.80","0.428"],["62104.30","0.535"],["62105.10","0.103"],["62105.20","0.253"],["62105.70","0.107"],["62106.10","0.489"],["62106.70","0.061"],["62107.30","0.770"],["62107.90","0.135"],["62108.10","0.201"],["62108.20","2.044"],["62108.30","0.162"],["62108.60","0.000"],["62108.70","0.000"],["62109.00","0.004"],["62109.60","0.018"],["62110.80","0.572"],["62111.00","0.428"],["62111.80","0.424"],["62112.20","0.539"],["62115.00","4.383"],["62115.20","0.058"],["62115.80","0.282"],["62118.00","0.499"],["62118.80","0.066"],["62118.90","0.002"],["62119.00","0.000"],["62119.10","0.053"],["62120.00","22.284"],["62120.10","0.001"],["62123.40","0.027"],["62133.90","0.004"],["62136.20","0.312"],["62137.40","1.677"],["62143.80","0.000"],["62161.30","0.001"],["62263.70","0.000"],["62282.00","1.165"],["62413.10","0.019"],["62413.40","0.172"],["62414.40","0.048"],["62419.70","0.001"],["62537.50","0.001"],["62543.80","0.001"],["62666.60","0.633"],["62666.70","0.001"],["62667.90","0.028"],["62758.00","0.000"],["62759.50","0.000"],["62759.70","4.734"],["62760.10","10.406"],["62820.10","1.511"],["62822.00","0.812"],["62843.80","12.604"],["62974.70","2.142"],["63005.80","0.009"],["63287.10","0.003"],["63288.30","0.003"],["63700.00","9.995"],["64987.70","0.000"],["64994.20","0.102"],["67487.30","0.000"],["67566.00","0.053"],["67566.40","0.611"]],"b":[["1000.00","210.542"],["11543.90","2.464"],["11545.90","0.000"],["11546.00","0.000"],["11546.10","0.000"],["11643.90","0.800"],["11646.10","0.096"],["11647.30","0.048"],["11743.90","0.512"],["11946.10","0.160"],["11947.30","0.064"],["55841.40","0.000"],["55842.50","0.002"],["59563.90","0.000"],["60801.10","0.098"],["60805.20","0.037"],["61039.40","1.979"],["61045.80","0.009"],["61046.00","0.056"],["61046.10","0.004"],["61358.50","3.264"],["61423.40","0.002"],["61425.50","0.000"],["61425.60","1.133"],["61426.80","0.000"],["61458.90","0.172"],["61497.50","0.113"],["61650.60","0.004"],["61677.20","0.369"],["61805.70","0.000"],["61829.10","0.696"],["61847.20","0.003"],["61880.10","1.389"],["61881.50","0.000"],["61882.00","0.054"],["61884.40","3.370"],["61885.50","0.275"],["61886.90","0.000"],["61889.40","0.052"],["61900.60","0.127"],["61904.30","0.064"],["61923.00","0.010"],["61923.10","0.000"],["61933.80","0.000"],["61934.40","0.029"],["61944.70","0.003"],["61953.60","0.033"],["61954.40","0.000"],["61956.50","0.029"],["61959.70","0.102"],["61966.00","0.358"],["61966.90","0.021"],["61969.10","0.003"],["61972.00","1.297"],["61972.10","2.265"],["61973.20","19.378"],["61975.20","0.296"],["61977.10","0.094"],["61978.60","0.205"],["61979.40","0.012"],["61981.20","0.000"],["61984.40","0.000"],["61985.30","0.057"],["61987.00","0.000"],["61987.30","0.034"],["61987.40","0.008"],["61988.30","1.077"],["61990.80","0.663"],["61991.60","0.000"],["61992.10","4.794"],["61992.60","0.000"],["61993.50","0.030"],["61993.80","9.354"],["61994.40","0.005"],["61995.00","0.683"],["61995.70","0.012"],["61996.00","0.000"],["61996.30","0.019"],["61997.40","0.279"],["61997.80","0.001"],["61998.60","0.675"],["61998.70","1.899"],["61999.00","0.140"],["61999.60","0.128"],["61999.90","0.003"],["62000.30","0.076"],["62000.90","0.092"],["62001.00","0.016"],["62001.60","0.005"],["62002.00","0.010"],["62002.30","1.295"],["62002.70","1.374"],["62002.90","0.592"],["62003.00","0.215"],["62003.20","0.002"],["62003.70","0.182"],["62004.10","0.043"],["62004.60","0.066"],["62005.20","0.780"],["62006.30","0.016"],["62006.40","0.016"],["62007.00","1.377"],["62008.10","0.001"],["62008.80","0.000"],["62009.20","0.587"],["62009.50","0.058"],["62010.00","0.143"],["62011.20","0.018"],["62011.50","0.002"],["62011.90","0.000"],["62012.10","0.655"],["62012.40","2.005"],["62012.60","1.297"],["62012.70","0.878"],["62013.00","0.012"],["62013.20","0.129"],["62013.30","0.015"],["62013.40","0.000"],["62013.80","1.287"],["62013.90","0.296"],["62014.00","0.097"],["62014.30","0.282"],["62014.90","0.002"],["62015.00","0.006"],["62015.10","0.415"],["62016.30","0.344"],["62016.40","0.019"],["62016.50","0.007"],["62017.10","0.002"],["62017.70","0.127"],["62017.80","0.023"],["62018.10","0.942"],["62018.60","0.076"],["62019.00","0.009"],["62019.50","0.052"],["62019.60","0.013"],["62019.90","2.559"],["62020.10","0.043"],["62020.40","0.976"],["62020.70","0.001"],["62020.80","0.002"],["62021.30","2.274"],["62022.40","0.124"],["62022.50","0.087"],["62023.30","0.033"],["62024.30","0.162"],["62024.40","0.161"],["62024.60","0.294"],["62024.70","0.402"],["62024.80","0.004"],["62025.00","0.055"],["62025.10","0.005"],["62025.30","0.094"],["62025.50","0.132"],["62025.60","0.003"],["62025.70","0.018"],["62025.80","0.324"],["62026.00","0.050"],["62026.10","0.591"],["62026.20","0.004"],["62026.40","0.182"],["62026.50","0.041"],["62026.70","0.002"],["62026.80","0.002"],["62026.90","0.003"],["62027.00","0.001"],["62027.10","0.368"],["62027.30","0.002"],["62027.40","0.089"],["62027.50","0.002"],["62027.60","0.002"],["62027.70","0.441"],["62027.80","0.000"],["62028.20","0.120"],["62028.50","0.875"],["62028.60","1.296"],["62028.70","0.185"],["62028.90","0.035"],["62029.20","0.176"],["62030.10","0.002"],["62030.30","0.004"],["62030.50","0.084"],["62030.80","1.189"],["62031.00","0.009"],["62031.10","0.005"],["62031.20","0.298"],["62031.30","0.088"],["62031.40","0.013"],["62032.40","0.017"],["62032.50","0.012"],["62032.70","1.212"],["62032.80","0.002"],["62033.00","0.023"],["62033.10","1.714"],["62033.70","0.572"],["62034.10","0.037"],["62034.20","0.001"],["62034.50","1.006"],["62034.70","0.323"],["62035.10","0.124"],["62035.30","0.004"],["62035.50","0.051"],["62035.60","0.584"],["62035.70","0.008"],["62035.80","0.125"],["62036.10","0.039"],["62036.20","0.060"],["62036.40","0.907"],["62036.50","0.323"],["62036.70","0.000"],["62037.80","0.466"],["62038.10","0.325"],["62038.50","0.001"],["62038.70","0.004"],["62039.60","0.231"],["62040.30","0.110"],["62040.60","0.005"],["62040.90","0.000"],["62041.20","0.264"],["62041.80","0.002"],["62042.00","0.506"],["62042.10","0.325"],["62042.20","0.207"],["62042.40","0.002"],["62042.70","0.002"],["62042.80","0.001"],["62043.30","0.001"],["62043.90","0.383"],["62044.30","0.002"],["62044.40","0.001"],["62044.60","0.003"],["62044.80","0.041"],["62045.00","0.002"],["62045.50","0.001"],["62045.70","0.195"],["62045.80","0.000"],["62045.90","0.011"],["62046.00","1.833"],["62046.10","2.278"],["62046.20","2.124"],["62046.30","0.000"],["62046.40","0.000"],["62046.50","0.001"],["62046.70","0.000"],["62046.90","0.000"],["62047.10","0.001"],["62047.20","0.083"],["62047.30","9.510"]],"e":"depthUpdate","ps":"BTCUSDT","pu":10998400021644,"s":"BTCUSDT","st":1,"u":10998400054476}
{"E":1783504322348,"T":1783504322346,"U":10998400054712,"a":[["62047.40","4.007"],["62048.20","0.104"],["62049.30","0.008"],["62050.00","0.002"],["62051.20","0.002"],["62051.70","0.000"],["62053.10","0.105"],["62053.60","0.180"],["62053.70","0.184"],["62053.80","0.001"],["62054.00","0.565"],["62054.20","0.108"],["62063.50","0.006"],["62065.90","1.400"],["62069.70","0.003"],["62069.90","0.283"],["62070.30","10.813"],["62072.80","1.362"],["62075.90","0.001"],["62079.90","0.194"],["62080.00","1.076"],["62084.90","0.064"],["62087.30","0.001"],["62088.30","0.015"],["62088.90","0.212"],["62091.80","0.339"],["62093.40","0.087"],["62093.50","0.184"],["62105.20","0.355"],["62106.10","0.489"],["62106.40","0.136"],["62112.20","0.640"],["62114.90","0.820"],["62115.90","22.097"],["62117.30","0.203"],["62120.00","0.198"],["62139.20","0.005"],["62141.90","0.009"],["62146.70","0.015"],["62150.90","0.000"],["62151.00","1.529"],["62159.70","0.001"],["62160.00","0.564"],["62172.20","2.559"],["62174.60","0.287"],["62192.60","0.000"],["62192.70","1.551"],["62240.00","0.625"],["62302.10","0.310"],["62320.00","0.561"],["62325.50","0.004"],["62400.00","14.516"],["62667.90","0.028"],["62759.70","0.004"],["62760.10","0.000"],["62761.40","15.145"],["62791.80","1.591"],["62821.60","0.795"],["62822.00","0.024"],["62822.30","0.002"],["62823.40","8.669"],["62902.20","0.000"],["63282.80","0.037"],["63421.60","0.473"],["89523.20","0.006"]],"b":[["1000.00","210.542"],["11543.90","2.272"],["11544.20","0.000"],["11545.70","0.000"],["11545.80","0.000"],["11647.30","0.176"],["11743.90","0.384"],["11947.30","0.336"],["49637.00","0.002"],["55842.50","0.002"],["59565.40","0.003"],["60709.80","0.000"],["60801.10","0.092"],["60806.40","0.021"],["61028.30","4.560"],["61425.30","0.003"],["61426.80","0.000"],["61680.00","1.117"],["61733.70","0.016"],["61760.00","0.609"],["61840.00","0.465"],["61847.20","0.002"],["61859.60","0.001"],["61859.70","1.568"],["61859.80","0.584"],["61882.10","0.003"],["61920.00","0.522"],["61951.70","0.000"],["61954.40","0.008"],["61971.90","0.876"],["61973.20","0.001"],["61978.40","1.708"],["61979.50","0.002"],["61981.60","19.381"],["61981.90","1.296"],["61989.00","0.006"],["61991.10","0.080"],["61997.70","0.002"],["61999.60","0.000"],["62000.00","9.080"],["62000.40","0.147"],["62001.10","0.003"],["62002.90","0.460"],["62003.00","0.083"],["62003.20","0.001"],["62003.80","0.245"],["62003.90","0.129"],["62004.40","0.000"],["62005.00","0.000"],["62006.60","0.052"],["62008.90","0.013"],["62013.20","0.001"],["62015.90","0.000"],["62017.60","0.339"],["62018.10","0.620"],["62019.60","0.073"],["62021.30","2.146"],["62021.80","1.962"],["62022.00","0.001"],["62022.50","0.007"],["62022.80","0.121"],["62024.30","0.001"],["62027.30","0.000"],["62028.00","2.710"],["62028.60","1.297"],["62028.70","0.125"],["62030.50","0.003"],["62031.00","0.009"],["62031.60","0.738"],["62032.70","0.486"],["62033.70","0.008"],["62034.10","0.601"],["62034.80","0.080"],["62034.90","0.627"],["62035.50","0.111"],["62035.70","0.000"],["62035.80","0.185"],["62036.10","0.099"],["62036.20","0.120"],["62036.70","0.881"],["62036.80","0.181"],["62037.20","0.004"],["62037.40","0.790"],["62039.30","0.004"],["62039.40","0.003"],["62041.40","0.002"],["62041.90","0.002"],["62042.10","0.326"],["62042.30","0.000"],["62043.20","0.001"],["62043.50","0.001"],["62043.80","0.056"],["62043.90","0.108"],["62044.00","0.208"],["62044.30","0.001"],["62045.20","0.001"],["62045.60","0.001"],["62045.70","0.194"],["62045.80","0.001"],["62046.00","1.829"],["62047.20","0.084"],["62047.30","7.929"]],"e":"depthUpdate","ps":"BTCUSDT","pu":10998400054476,"s":"BTCUSDT","st":1,"u":10998400075808}
{"E":1783504322450,"T":1783504322449,"U":10998400076199,"a":[["62047.40","0.000"],["62047.50","0.000"],["62047.60","0.000"],["62047.70","0.000"],["62048.00","0.000"],["62048.20","0.000"],["62048.30","0.996"],["62049.30","0.010"],["62049.50","0.003"],["62050.10","0.340"],["62050.90","0.001"],["62051.20","0.006"],["62052.40","0.396"],["62052.50","0.001"],["62052.70","0.087"],["62053.40","0.062"],["62053.50","0.000"],["62053.60","0.342"],["62053.80","0.566"],["62054.00","0.198"],["62054.10","0.097"],["62054.20","0.210"],["62054.60","0.081"],["62054.70","0.000"],["62054.90","0.000"],["62055.30","0.243"],["62055.40","0.051"],["62055.90","0.004"],["62056.10","0.078"],["62056.60","0.004"],["62056.70","0.002"],["62056.90","0.123"],["62057.50","0.322"],["62057.80","0.053"],["62057.90","0.005"],["62058.00","0.002"],["62058.20","0.002"],["62058.40","0.123"],["62059.10","0.001"],["62059.30","0.122"],["62059.60","0.001"],["62059.80","0.004"],["62060.00","0.214"],["62060.40","0.009"],["62060.70","0.013"],["62061.30","2.552"],["62061.40","0.000"],["62061.50","0.158"],["62061.60","0.002"],["62062.80","0.002"],["62062.90","0.202"],["62063.00","0.348"],["62064.70","0.014"],["62065.90","1.365"],["62066.00","0.796"],["62066.50","0.001"],["62066.90","0.002"],["62067.00","0.110"],["62067.10","0.001"],["62067.50","0.682"],["62068.00","0.122"],["62068.20","2.988"],["62068.30","0.003"],["62068.90","0.017"],["62070.00","0.314"],["62070.10","0.162"],["62070.20","0.003"],["62070.30","0.413"],["62070.80","1.477"],["62073.30","0.157"],["62075.20","0.009"],["62075.60","1.370"],["62076.40","0.053"],["62076.80","0.084"],["62078.40","0.174"],["62080.20","0.014"],["62080.60","0.200"],["62081.20","0.001"],["62081.40","0.795"],["62082.10","0.002"],["62084.00","0.026"],["62084.60","0.050"],["62084.90","0.050"],["62085.00","0.555"],["62085.10","0.001"],["62085.80","0.669"],["62086.00","0.032"],["62091.60","0.053"],["62091.70","0.054"],["62093.00","0.074"],["62093.10","0.156"],["62093.60","0.014"],["62095.20","0.018"],["62097.40","0.195"],["62097.50","0.179"],["62097.60","0.543"],["62098.90","0.031"],["62099.70","0.674"],["62103.30","0.000"],["62103.80","1.306"],["62104.10","1.491"],["62105.10","0.001"],["62105.70","0.185"],["62106.30","0.198"],["62108.70","0.001"],["62109.50","0.001"],["62112.20","0.640"],["62113.80","22.086"],["62114.10","0.035"],["62114.20","0.083"],["62114.90","0.878"],["62115.90","0.011"],["62122.20","1.878"],["62136.20","0.000"],["62137.40","1.365"],["62139.30","0.000"],["62141.40","0.979"],["62146.80","0.144"],["62152.90","0.003"],["62167.20","0.003"],["62197.30","0.006"],["62199.70","2.800"],["62216.70","0.004"],["62224.80","0.015"],["62237.10","0.000"],["62258.50","0.002"],["62295.70","0.001"],["62360.50","2.513"],["62404.50","0.082"],["62407.70","0.008"],["62665.10","0.000"],["62667.90","0.036"],["62668.30","0.008"],["62668.70","0.002"],["62668.80","0.007"],["62942.20","0.000"],["63282.80","0.031"],["67566.40","0.000"],["67566.70","0.000"]],"b":[["11543.90","2.016"],["11647.30","0.304"],["11743.90","0.256"],["11947.30","0.592"],["49637.00","0.000"],["55842.50","0.002"],["60801.10","0.089"],["61045.70","0.006"],["61299.40","1.628"],["61426.80","0.002"],["61427.70","0.002"],["61472.40","2.348"],["61738.00","0.003"],["61825.10","0.000"],["61826.20","0.000"],["61826.30","1.240"],["61835.40","0.124"],["61844.40","0.696"],["61847.20","0.003"],["61848.90","0.000"],["61854.40","2.735"],["61855.30","0.003"],["61864.90","0.185"],["61886.20","0.002"],["61917.10","0.715"],["61923.00","0.034"],["61938.20","0.678"],["61950.30","0.000"],["61956.50","0.000"],["61958.80","0.002"],["61973.20","0.001"],["61975.50","0.674"],["61981.00","0.000"],["61981.60","0.004"],["61983.70","0.085"],["61988.50","0.101"],["61990.20","0.000"],["61990.90","0.000"],["61994.10","0.055"],["61994.50","1.367"],["61995.70","0.002"],["61995.80","0.010"],["61996.80","0.018"],["61999.00","0.076"],["62000.80","0.181"],["62001.50","0.035"],["62001.60","0.002"],["62001.90","0.210"],["62002.00","0.002"],["62002.20","0.129"],["62003.00","0.001"],["62004.70","0.035"],["62005.60","0.002"],["62011.70","0.005"],["62012.40","2.004"],["62013.00","0.002"],["62013.20","0.004"],["62013.30","0.012"],["62015.10","0.403"],["62015.30","0.062"],["62015.50","0.012"],["62016.90","0.001"],["62017.50","0.005"],["62017.70","0.124"],["62017.80","0.015"],["62018.70","0.010"],["62020.20","0.681"],["62021.50","0.004"],["62022.50","0.005"],["62023.70","0.013"],["62025.10","0.003"],["62025.30","0.084"],["62025.70","0.018"],["62026.40","0.172"],["62027.70","0.421"],["62028.00","2.650"],["62028.20","0.060"],["62028.60","1.176"],["62028.70","0.005"],["62028.90","0.003"],["62029.20","0.116"],["62029.40","0.323"],["62029.50","0.013"],["62031.00","0.005"],["62031.30","0.086"],["62031.70","0.565"],["62031.90","0.049"],["62032.60","0.317"],["62033.20","0.063"],["62034.00","1.929"],["62034.10","0.037"],["62035.10","0.856"],["62035.60","0.644"],["62035.80","0.205"],["62036.20","0.240"],["62036.40","0.939"],["62036.70","0.913"],["62036.80","0.313"],["62037.00","0.034"],["62037.30","0.032"],["62037.50","0.005"],["62037.80","0.442"],["62038.50","0.761"],["62039.60","0.323"],["62039.70","2.232"],["62039.90","0.001"],["62040.70","0.824"],["62041.00","0.007"],["62041.50","0.000"],["62041.80","0.002"],["62042.20","0.157"],["62042.30","1.362"],["62042.90","0.000"],["62044.90","0.001"],["62046.00","0.024"],["62046.10","2.080"],["62046.30","0.821"],["62047.20","0.003"],["62047.30","4.090"],["62047.40","0.222"],["62047.50","0.000"],["62047.60","0.027"],["62047.90","0.209"],["62048.10","3.737"],["62048.20","20.550"]],"e":"depthUpdate","ps":"BTCUSDT","pu":10998400075808,"s":"BTCUSDT","st":1,"u":10998400103773}
