{"E":1783504305008,"T":1783504305007,"U":10998398087911,"a":[["62036.80","0.002"],["62037.40","0.004"],["62040.20","0.648"],["62050.20","0.083"],["62054.00","0.011"],["62060.60","5.020"],["62064.90","1.257"],["62072.30","0.049"],["62072.40","0.214"],["62072.50","0.097"],["62072.70","0.424"],["62075.30","0.175"],["62099.10","0.061"],["62103.20","18.518"],["62167.30","0.001"],["62654.20","3.928"],["62778.30","2.543"],["62809.90","0.798"]],"b":[["11533.80","1.008"],["11633.80","1.104"],["11933.80","2.688"],["55830.40","0.002"],["59552.40","0.003"],["60793.20","0.034"],["61288.20","14.634"],["61413.50","0.009"],["61536.30","0.328"],["61775.40","0.000"],["61834.40","0.001"],["61999.80","0.217"],["62011.40","0.290"],["62015.40","0.016"],["62019.30","0.062"],["62022.70","0.084"],["62031.50","0.076"]],"e":"depthUpdate","ps":"BTCUSDT","pu":10998398087853,"s":"BTCUSDT","st":1,"u":10998398095988}
{"E":1783504305110,"T":1783504305109,"U":10998398096213,"a":[["62040.20","0.092"],["62041.20","0.152"],["62049.80","0.009"],["62062.40","0.013"],["62065.80","0.002"],["62073.40","0.006"],["62073.80","0.003"],["62074.20","0.000"],["62075.30","0.070"],["62076.80","0.007"],["62080.60","0.005"],["62102.20","0.154"],["62165.40","0.635"],["62654.20","3.928"],["62871.90","0.000"],["62914.80","1.470"]],"b":[["1000.00","210.542"],["11533.80","0.992"],["11633.80","0.960"],["11833.80","0.112"],["11933.80","2.736"],["55830.40","0.002"],["59552.40","0.000"],["61413.50","0.009"],["61475.50","1.266"],["61834.40","0.002"],["61903.10","0.591"],["61970.30","0.026"],["61973.30","0.148"],["61988.20","0.018"],["61988.30","1.049"],["62000.20","0.339"],["62000.30","0.000"],["62010.20","0.146"],["62015.30","0.181"],["62015.40","0.000"],["62016.60","0.102"],["62017.30","0.000"],["62018.70","1.364"],["62022.70","0.004"]],"e":"depthUpdate","ps":"BTCUSDT","pu":10998398095988,"s":"BTCUSDT","st":1,"u":10998398103689}
{"E":1783504305212,"T":1783504305209,"U":10998398103928,"a":[["62040.20","0.092"],["62041.20","0.003"],["62049.80","0.011"],["62059.40","1.394"],["62063.60","0.091"],["62070.50","0.000"],["62075.00","2.927"],["62090.20","0.004"],["62090.30","1.621"],["62099.10","18.576"],["62102.20","0.053"],["62103.20","0.003"],["62165.40","0.635"],["62654.20","3.928"]],"b":[["1000.00","210.542"],["11533.80","0.992"],["11633.80","0.832"],["11833.80","0.256"],["11933.80","2.720"],["55830.40","0.002"],["59552.40","0.003"],["61182.50","0.818"],["61413.50","0.009"],["61723.60","0.175"],["61821.20","4.700"],["61834.40","0.001"],["61841.70","0.388"],["61866.00","1.043"],["61884.50","0.829"],["61903.10","0.602"],["61912.50","0.616"],["61931.20","2.254"],["61958.20","2.253"],["61970.30","0.024"],["61972.20","0.125"],["61977.50","4.224"],["61977.60","0.005"],["62006.10","1.104"],["62016.60","0.022"],["62017.90","0.082"],["62018.70","1.366"],["62021.60","0.048"],["62033.70","0.015"]],"e":"depthUpdate","ps":"BTCUSDT","pu":10998398103689,"s":"BTCUSDT","st":1,"u":10998398113031}
{"E":1783504305314,"T":1783504305313,"U":10998398113233,"a":[["62033.90","5.795"],["62035.90","0.004"],["62037.50","0.005"],["62040.20","0.092"],["62042.40","0.007"],["62071.00","0.074"],["62080.00","1.089"],["62097.50","0.228"],["62131.20","0.001"],["62165.40","0.635"],["62654.20","3.928"],["62816.30","4.742"]],"b":[["11533.80","0.992"],["11633.80","0.688"],["11833.80","0.384"],["11933.80","2.736"],["55830.40","0.002"],["58932.10","0.046"],["60793.30","0.006"],["61413.50","0.009"],["61834.40","0.002"],["61903.10","0.602"],["61943.90","0.006"],["61944.00","0.003"],["62010.20","0.130"],["62012.40","0.410"],["62014.00","0.107"],["62015.00","0.007"],["62015.10","1.078"],["62015.30","0.171"],["62017.00","0.684"],["62017.90","0.002"],["62020.00","0.142"],["62021.20","0.000"],["62021.40","0.129"],["62023.60","0.907"],["62024.30","0.081"],["62026.00","0.050"],["62027.60","0.155"],["62028.40","0.001"],["62029.10","0.000"],["62032.00","0.005"],["62033.50","0.102"],["62033.80","7.009"]],"e":"depthUpdate","ps":"BTCUSDT","pu":10998398113031,"s":"BTCUSDT","st":1,"u":10998398120828}
{"E":1783504305416,"T":1783504305415,"U":10998398121018,"a":[["62033.90","5.796"],["62040.20","0.092"],["62041.20","0.003"],["62043.20","0.129"],["62045.70","0.322"],["62046.70","0.564"],["62047.80","0.001"],["62049.50","0.005"],["62052.40","0.587"],["62054.80","0.012"],["62055.00","0.003"],["62056.90","0.168"],["62057.00","0.001"],["62060.10","0.000"],["62067.90","0.001"],["62068.20","0.054"],["62073.00","0.154"],["62080.00","1.075"],["62654.20","3.930"],["63091.00","0.014"]],"b":[["1000.00","210.542"],["11533.80","1.040"],["11633.80","0.560"],["11833.80","0.576"],["11933.80","2.624"],["55830.40","0.002"],["59552.40","0.000"],["61196.30","2.756"],["61305.00","0.345"],["61413.50","0.009"],["61834.40","0.001"],["61865.10","0.005"],["61965.60","0.157"],["61971.10","0.030"],["61973.20","0.326"],["61974.90","0.003"],["61975.30","18.579"],["61975.80","0.434"],["61977.40","0.002"],["61977.50","0.681"],["61977.60","0.001"],["61982.00","0.436"],["62000.20","0.471"],["62000.30","0.082"],["62014.80","1.410"],["62020.00","0.126"],["62021.60","0.001"],["62022.70","0.020"],["62024.60","0.324"],["62026.20","0.006"],["62026.60","0.002"],["62027.30","0.058"],["62033.80","7.012"]],"e":"depthUpdate","ps":"BTCUSDT","pu":10998398120828,"s":"BTCUSDT","st":1,"u":10998398129422}
{"E":1783504305518,"T":1783504305517,"U":10998398129454,"a":[["62033.90","5.804"],["62041.20","0.561"],["62046.70","0.000"],["62048.20","0.564"],["62056.90","0.249"],["62059.40","0.000"],["62060.60","0.020"],["62063.10","0.485"],["62067.00","0.004"],["62069.30","0.325"],["62069.40","0.010"],["62071.80","0.009"],["62075.30","0.175"],["62135.80","0.001"],["62165.40","0.003"],["62187.00","0.094"],["62654.20","3.928"],["62873.70","0.000"],["63091.00","0.000"]],"b":[["1000.00","210.542"],["11533.80","1.184"],["11633.80","0.416"],["11833.80","0.848"],["11933.80","2.352"],["55830.40","0.002"],["59552.40","0.003"],["61413.50","0.009"],["61723.60","0.175"],["61834.40","0.002"],["61881.60","0.730"],["61903.10","0.000"],["61967.00","0.001"],["61984.20","0.854"],["61993.80","9.372"],["62000.20","0.471"],["62012.80","1.587"],["62013.70","0.297"],["62019.00","0.166"],["62022.70","0.004"],["62024.30","0.001"],["62024.80","0.052"],["62025.20","2.742"]],"e":"depthUpdate","ps":"BTCUSDT","pu":10998398129422,"s":"BTCUSDT","st":1,"u":10998398135857}
{"E":1783504305620,"T":1783504305617,"U":10998398135973,"a":[["62041.20","0.561"],["62069.40","0.000"],["62099.00","0.127"],["62165.40","0.639"],["62186.90","1.111"],["62654.20","3.928"]],"b":[["11533.80","1.312"],["11633.80","0.288"],["11833.80","1.120"],["11933.80","2.080"],["49627.00","0.000"],["55830.40","0.002"],["59552.40","0.000"],["61413.50","0.009"],["61834.40","0.001"],["61881.60","1.577"],["61903.10","0.602"],["62012.40","0.370"],["62013.70","0.217"],["62016.90","0.081"],["62019.20","0.058"]],"e":"depthUpdate","ps":"BTCUSDT","pu":10998398135857,"s":"BTCUSDT","st":1,"u":10998398141455}
{"E":1783504305722,"T":1783504305721,"U":10998398141662,"a":[["62033.90","6.608"],["62035.60","0.005"],["62037.20","0.017"],["62038.40","0.003"],["62040.20","0.028"],["62040.90","0.001"],["62041.20","0.005"],["62042.40","0.071"],["62056.90","0.168"],["62100.20","0.031"],["62159.60","0.001"],["62159.70","2.419"],["62223.00","0.047"],["62223.10","0.000"],["62344.10","0.074"],["62388.90","0.003"],["62461.80","0.018"],["62464.00","0.060"],["62654.20","3.930"],["62809.30","0.271"],["63091.00","0.016"],["63274.50","0.024"]],"b":[["1000.00","210.542"],["11533.80","1.456"],["11633.80","0.144"],["11833.80","1.392"],["11933.80","1.808"],["49627.00","0.000"],["55830.40","0.002"],["59552.40","0.003"],["60725.10","0.000"],["61011.50","0.000"],["61413.50","0.009"],["61723.60","0.174"],["61834.40","0.002"],["61945.10","1.362"],["61945.40","2.420"],["61982.10","0.140"],["62012.80","1.265"],["62015.00","0.047"],["62015.20","0.002"],["62016.90","0.001"],["62019.00","0.005"],["62019.20","0.018"],["62021.40","0.129"],["62023.20","0.016"],["62025.20","2.661"],["62027.30","0.034"],["62028.80","0.086"],["62030.70","1.385"],["62031.60","0.068"],["62032.20","0.001"],["62033.80","6.948"]],"e":"depthUpdate","ps":"BTCUSDT","pu":10998398141455,"s":"BTCUSDT","st":1,"u":10998398147486}
{"E":1783504305824,"T":1783504305821,"U":10998398147536,"a":[["62036.90","0.003"],["62038.20","0.001"],["62038.30","0.002"],["62039.20","0.002"],["62040.20","0.028"],["62040.30","1.010"],["62040.80","0.324"],["62042.40","0.068"],["62043.00","0.500"],["62067.20","0.009"],["62075.00","2.822"],["62098.80","0.016"],["62161.80","0.120"],["62654.20","3.928"]],"b":[["1000.00","210.542"],["11533.80","1.584"],["11633.80","0.016"],["11833.80","1.664"],["11933.80","1.536"],["49627.00","0.000"],["55830.40","0.002"],["58932.30","0.000"],["58943.80","0.000"],["61040.10","1.637"],["61168.70","0.000"],["61318.00","1.117"],["61400.00","34.218"],["61413.50","0.009"],["61723.60","0.174"],["61764.90","0.008"],["61765.00","0.000"],["61834.40","0.001"],["61911.80","0.080"],["61974.90","0.019"],["62006.40","0.010"],["62020.40","0.650"],["62023.20","0.000"],["62025.70","0.098"],["62028.80","0.006"],["62029.40","0.004"],["62031.70","0.006"],["62032.90","0.001"]],"e":"depthUpdate","ps":"BTCUSDT","pu":10998398147486,"s":"BTCUSDT","st":1,"u":10998398153911}
{"E":1783504305926,"T":1783504305925,"U":10998398154108,"a":[["62035.50","0.359"],["62654.20","3.928"],["63962.70","0.000"]],"b":[["11533.80","1.472"],["11633.80","0.000"],["11833.80","1.936"],["11933.80","1.392"],["55830.40","0.002"],["59552.40","0.000"],["60198.70","0.019"],["60900.00","39.223"],["60979.20","5.647"],["61152.90","0.326"],["61413.50","0.009"],["61723.60","0.173"],["61781.00","0.112"],["61825.80","0.000"],["61834.40","0.002"],["61970.60","0.002"],["61972.20","0.123"],["62020.40","0.634"],["62025.30","0.140"],["62025.70","0.018"],["62029.60","0.093"]],"e":"depthUpdate","ps":"BTCUSDT","pu":10998398153911,"s":"BTCUSDT","st":1,"u":10998398160216}
{"E":1783504306028,"T":1783504306027,"U":10998398160297,"a":[["62038.70","0.003"],["62040.20","1.390"],["62041.80","0.006"],["62042.90","1.297"],["62074.90","0.165"],["62344.10","0.075"],["62654.20","3.928"],["62654.30","0.001"],["62722.10","0.000"]],"b":[["1000.00","210.542"],["11533.80","1.344"],["11833.80","2.208"],["11933.80","1.248"],["55830.40","0.002"],["59552.40","0.003"],["61289.40","0.762"],["61413.50","0.011"],["61834.40","0.001"],["62009.00","0.382"],["62019.90","0.019"],["62021.40","0.001"],["62025.30","0.124"],["62025.40","0.081"],["62029.60","0.013"]],"e":"depthUpdate","ps":"BTCUSDT","pu":10998398160216,"s":"BTCUSDT","st":1,"u":10998398165023}
{"E":1783504306130,"T":1783504306129,"U":10998398165045,"a":[["62033.90","6.609"],["62037.50","0.168"],["62037.60","0.792"],["62040.10","0.129"],["62040.60","0.005"],["62042.80","0.053"],["62043.20","0.129"],["62046.40","0.812"],["62059.00","0.006"],["62060.20","0.620"],["62074.90","0.270"],["62075.00","2.927"],["62075.30","0.070"],["62654.20","3.928"],["63274.60","2.148"]],"b":[["1000.00","210.542"],["11533.80","1.200"],["11833.80","2.480"],["11933.80","1.120"],["49627.00","0.000"],["55830.40","0.002"],["59552.40","0.000"],["60140.10","2.408"],["61289.40","2.716"],["61313.60","0.815"],["61413.50","0.009"],["61442.10","0.000"],["61537.50","1.297"],["61723.60","0.173"],["61834.40","0.002"],["62010.80","0.079"],["62012.60","0.036"],["62016.30","0.424"],["62019.60","0.082"],["62019.90","0.003"],["62024.30","0.010"],["62025.40","0.001"],["62031.10","0.003"],["62031.70","0.003"]],"e":"depthUpdate","ps":"BTCUSDT","pu":10998398165023,"s":"BTCUSDT","st":1,"u":10998398173100}
{"E":1783504306232,"T":1783504306229,"U":10998398173327,"a":[["62040.10","0.001"],["62040.60","0.004"],["62041.40","0.002"],["62049.80","0.011"],["62050.40","1.196"],["62075.00","5.683"],["62075.30","0.070"],["62107.30","0.770"],["62124.80","1.295"],["62146.90","2.807"],["62150.00","102.271"],["62658.70","1.354"],["62778.30","3.178"],["62932.20","10.951"],["63025.20","1.037"],["63908.00","2.266"],["65135.50","0.003"]],"b":[["11533.80","1.072"],["11733.80","0.016"],["11833.80","2.720"],["11933.80","0.992"],["55830.40","0.002"],["59552.40","0.003"],["60793.30","0.003"],["61257.70","0.576"],["61413.50","0.009"],["61450.00","11.522"],["61537.50","1.622"],["61609.10","1.055"],["61633.60","0.187"],["61650.10","3.243"],["61673.30","0.811"],["61695.10","0.716"],["61727.10","0.477"],["61748.10","1.241"],["61766.90","1.056"],["61785.60","0.848"],["61803.60","1.439"],["61826.30","1.723"],["61834.40","0.001"],["61850.60","1.211"],["61871.00","1.244"],["61897.70","0.713"],["61917.30","2.329"],["61937.70","1.755"],["61955.70","1.493"],["61975.60","3.137"],["62002.40","2.433"],["62010.80","0.063"],["62015.60","0.204"],["62016.30","0.344"],["62018.70","1.366"],["62020.10","0.688"],["62029.50","0.040"]],"e":"depthUpdate","ps":"BTCUSDT","pu":10998398173100,"s":"BTCUSDT","st":1,"u":10998398179822}
{"E":1783504306334,"T":1783504306333,"U":10998398179983,"a":[["62038.50","0.002"],["62040.10","0.129"],["62043.80","0.241"],["62044.10","1.655"],["62048.30","1.217"],["62074.90","0.433"],["62099.00","0.127"],["62654.20","3.928"],["63274.50","0.027"],["65135.50","0.001"]],"b":[["1000.00","210.542"],["11533.80","0.928"],["11733.80","0.144"],["11833.80","2.736"],["11933.80","0.992"],["55830.40","0.002"],["61004.00","1.461"],["61413.50","0.009"],["61444.50","0.698"],["61834.40","0.002"],["61899.80","0.002"],["61970.60","0.000"],["61971.00","0.002"],["61971.10","0.030"],["61971.80","0.386"],["61972.10","1.364"],["61972.50","0.440"],["61973.20","18.902"],["61975.30","0.005"],["61975.60","0.177"],["62015.60","0.188"],["62018.40","2.704"],["62020.10","0.608"],["62027.20","0.069"],["62027.90","0.117"]],"e":"depthUpdate","ps":"BTCUSDT","pu":10998398179822,"s":"BTCUSDT","st":1,"u":10998398186479}
{"E":1783504306436,"T":1783504306433,"U":10998398186654,"a":[["62040.10","0.685"],["62043.20","0.129"],["62096.10","0.000"],["62169.20","0.960"],["62183.10","0.008"],["62277.00","0.394"],["62836.00","0.000"]],"b":[["1000.00","210.542"],["11533.80","0.800"],["11733.80","0.288"],["11833.80","2.720"],["11933.80","0.992"],["49627.00","0.000"],["55830.40","0.002"],["59552.40","0.000"],["61216.30","0.980"],["61413.50","0.009"],["61723.60","0.163"],["61768.00","0.000"],["61834.40","0.001"],["61973.30","0.584"],["61982.00","0.000"],["62000.30","0.000"],["62002.70","0.094"],["62012.40","0.410"],["62015.00","0.007"],["62027.20","0.053"],["62027.90","0.037"],["62032.80","0.534"],["62033.20","0.022"],["62033.80","6.947"]],"e":"depthUpdate","ps":"BTCUSDT","pu":10998398186479,"s":"BTCUSDT","st":1,"u":10998398193431}
{"E":1783504306538,"T":1783504306537,"U":10998398193746,"a":[["62033.90","6.652"],["62040.10","0.685"],["62056.40","0.081"],["62186.80","0.793"],["62211.60","3.238"],["62230.60","1.671"],["62260.90","0.849"],["62654.20","3.928"],["63274.60","2.145"]],"b":[["11533.80","0.656"],["11733.80","0.416"],["11833.80","2.736"],["11933.80","0.992"],["55830.40","0.002"],["59552.40","0.003"],["61134.30","1.143"],["61413.50","0.009"],["61834.40","0.002"],["62009.00","0.382"],["62012.00","0.323"],["62013.20","0.662"],["62018.20","0.161"],["62022.80","0.003"],["62024.40","0.082"],["62024.80","0.052"],["62032.80","0.454"],["62033.20","0.006"],["62033.70","0.004"]],"e":"depthUpdate","ps":"BTCUSDT","pu":10998398193431,"s":"BTCUSDT","st":1,"u":10998398204126}
{"E":1783504306640,"T":1783504306637,"U":10998398204222,"a":[["62034.00","0.104"],["62035.60","0.004"],["62037.10","0.002"],["62039.80","0.556"],["62039.90","0.002"],["62040.00","0.005"],["62040.10","0.001"],["62042.40","0.070"],["62042.50","0.042"],["62042.60","0.890"],["62061.40","0.000"],["62063.70","0.045"],["62083.80","0.499"],["62280.80","0.752"],["62299.90","1.235"],["62319.90","0.224"],["62339.60","0.494"],["62357.90","0.115"],["62379.90","1.293"],["62399.90","2.244"],["62422.70","0.453"],["62654.20","3.928"],["62707.50","5.243"],["62931.70","5.061"]],"b":[["1000.00","210.542"],["11533.80","0.528"],["11733.80","0.640"],["11833.80","2.560"],["11933.80","1.072"],["55830.40","0.002"],["59552.40","0.000"],["61010.20","0.777"],["61413.50","0.009"],["61581.80","0.026"],["61834.40","0.001"],["61972.60","0.000"],["61981.70","0.015"],["62013.20","0.582"],["62013.30","0.014"],["62014.50","0.072"],["62026.50","0.139"],["62028.10","1.443"]],"e":"depthUpdate","ps":"BTCUSDT","pu":10998398204126,"s":"BTCUSDT","st":1,"u":10998398212208}
{"E":1783504306742,"T":1783504306741,"U":10998398212419,"a":[["62034.00","0.329"],["62036.40","0.041"],["62037.00","0.057"],["62039.80","0.000"],["62040.10","0.129"],["62344.10","0.074"],["62461.80","0.000"],["62654.20","3.928"]],"b":[["1000.00","210.542"],["11533.80","0.384"],["11733.80","0.912"],["11833.80","2.288"],["11933.80","1.216"],["49627.00","0.000"],["55830.40","0.002"],["61142.30","0.613"],["61171.50","2.581"],["61288.20","13.983"],["61289.40","3.530"],["61413.50","0.009"],["61537.50","1.946"],["61723.60","0.174"],["61834.40","0.002"],["61972.90","0.015"],["61981.70","0.000"],["62000.00","8.868"],["62000.20","0.471"],["62032.60","0.319"],["62033.70","0.015"],["62033.80","6.939"]],"e":"depthUpdate","ps":"BTCUSDT","pu":10998398212208,"s":"BTCUSDT","st":1,"u":10998398219841}
{"E":1783504306844,"T":1783504306841,"U":10998398219975,"a":[["62033.90","5.537"],["62034.00","0.327"],["62036.90","0.001"],["62037.20","0.001"],["62037.50","0.005"],["62037.60","0.547"],["62038.70","0.019"],["62040.10","0.001"],["62040.20","0.028"],["62040.30","1.013"],["62041.40","0.001"],["62042.70","0.796"],["62043.20","0.001"],["62056.40","0.000"],["62058.70","0.130"],["62063.10","0.324"],["62069.30","0.003"],["62074.90","0.433"],["62075.00","5.683"],["62126.90","0.163"],["62127.00","0.122"],["62200.00","12.027"],["62282.20","0.110"],["62282.30","1.305"],["62437.90","0.008"],["62438.00","0.568"],["62459.10","0.018"],["62529.00","1.079"],["62530.20","0.958"],["62594.00","0.066"],["62594.10","0.000"],["62654.20","3.928"],["62710.10","0.716"]],"b":[["11533.80","0.256"],["11733.80","1.184"],["11833.80","2.016"],["11933.80","1.344"],["55830.40","0.002"],["58943.80","0.002"],["59552.40","0.003"],["60300.00","11.738"],["61413.50","0.009"],["61478.60","0.016"],["61478.70","0.008"],["61632.30","0.008"],["61632.40","0.040"],["61786.30","0.004"],["61786.40","0.022"],["61834.40","0.001"],["61940.80","4.378"],["61940.90","4.837"],["61964.30","0.026"],["61965.60","0.001"],["61972.90","0.000"],["61974.90","0.175"],["61981.70","0.015"],["61982.10","0.008"],["62000.00","8.968"],["62009.00","0.254"],["62018.90","0.135"],["62021.40","0.129"],["62026.50","0.123"],["62028.10","1.363"],["62033.80","7.095"]],"e":"depthUpdate","ps":"BTCUSDT","pu":10998398219841,"s":"BTCUSDT","st":1,"u":10998398228084}
{"E":1783504306946,"T":1783504306945,"U":10998398228272,"a":[["62037.80","0.001"],["62043.20","0.001"],["62097.00","18.515"],["62097.70","0.119"],["62099.00","0.026"],["62099.10","0.061"],["62654.20","3.928"],["63274.50","0.030"]],"b":[["1000.00","210.542"],["11533.80","0.112"],["11733.80","1.456"],["11833.80","1.744"],["11933.80","1.488"],["55830.40","0.002"],["59552.40","0.000"],["61288.20","13.169"],["61413.50","0.009"],["61536.30","0.003"],["61834.40","0.002"],["61972.10","1.362"],["61972.30","0.313"],["61975.00","3.509"],["61975.30","0.003"],["62009.00","0.382"],["62029.40","0.000"],["62029.50","0.044"],["62031.60","0.177"],["62032.50","0.002"],["62033.80","7.784"]],"e":"depthUpdate","ps":"BTCUSDT","pu":10998398228084,"s":"BTCUSDT","st":1,"u":10998398236560}
{"E":1783504307048,"T":1783504307045,"U":10998398236743,"a":[["62037.10","0.001"],["62037.50","0.005"],["62038.00","0.003"],["62052.40","0.007"],["62053.20","0.582"],["62097.00","0.003"],["62098.90","0.132"],["62099.00","18.384"],["62344.10","0.073"],["62654.20","3.928"],["62654.30","0.000"]],"b":[["11533.80","0.000"],["11733.80","1.728"],["11833.80","1.488"],["11933.80","1.584"],["55830.40","0.002"],["59552.40","0.003"],["61295.20","6.757"],["61357.30","6.173"],["61413.50","0.009"],["61723.60","0.174"],["61834.40","0.001"],["61900.00","3.748"],["62012.40","0.370"],["62019.20","0.058"],["62024.70","0.016"],["62029.30","0.082"],["62033.80","7.689"]],"e":"depthUpdate","ps":"BTCUSDT","pu":10998398236560,"s":"BTCUSDT","st":1,"u":10998398244504}
{"E":1783504307150,"T":1783504307149,"U":10998398244771,"a":[["62036.80","0.004"],["62041.20","0.005"],["62056.90","0.048"],["62058.30","0.120"],["62074.20","0.128"],["62083.80","0.399"],["62654.20","3.928"],["63005.50","0.017"]],"b":[["11733.80","2.000"],["11833.80","1.360"],["11933.80","1.440"],["55830.40","0.002"],["58932.20","0.013"],["58932.30","0.003"],["59552.40","0.000"],["61062.30","0.000"],["61071.60","0.102"],["61413.50","0.009"],["61723.60","0.175"],["61834.40","0.002"],["62013.20","0.001"],["62013.80","0.632"],["62015.00","0.047"],["62019.20","0.018"],["62024.70","0.000"],["62029.30","0.002"],["62031.90","0.019"],["62033.80","7.762"]],"e":"depthUpdate","ps":"BTCUSDT","pu":10998398244504,"s":"BTCUSDT","st":1,"u":10998398253309}
{"E":1783504307252,"T":1783504307249,"U":10998398253481,"a":[["62040.20","0.028"],["62041.20","0.005"],["62049.80","0.011"],["62056.20","0.912"],["62058.70","0.130"],["62084.40","0.754"],["62093.50","0.000"],["62095.00","0.340"],["62654.20","3.928"],["62712.90","0.001"],["62809.30","0.390"],["62996.10","0.022"]],"b":[["1000.00","210.542"],["11733.80","2.272"],["11833.80","1.216"],["11933.80","1.312"],["55830.40","0.002"],["61289.40","5.160"],["61357.60","1.671"],["61413.50","0.009"],["61834.40","0.001"],["61937.70","1.753"],["61971.80","0.230"],["61972.50","0.004"],["61982.00","0.436"],["62009.00","0.254"],["62018.70","1.366"],["62024.80","0.005"],["62031.90","0.003"],["62033.80","7.778"]],"e":"depthUpdate","ps":"BTCUSDT","pu":10998398253309,"s":"BTCUSDT","st":1,"u":10998398261423}
{"E":1783504307354,"T":1783504307353,"U":10998398261792,"a":[["62033.90","5.538"],["62039.70","0.129"],["62040.20","0.028"],["62041.20","0.005"],["62042.90","0.002"],["62043.30","0.409"],["62044.00","0.181"],["62074.40","0.003"],["62081.60","0.061"],["62654.20","3.928"]],"b":[["11733.80","2.544"],["11833.80","1.088"],["11933.80","1.168"],["49627.00","0.000"],["55830.40","0.002"],["59552.40","0.003"],["61256.20","0.000"],["61413.50","0.009"],["61474.30","0.446"],["61723.60","0.175"],["61834.40","0.002"],["61965.60","0.157"],["61972.30","0.311"],["61972.50","0.006"],["61980.00","4.981"],["61992.90","0.509"],["61994.10","0.080"],["61997.80","0.001"],["61999.20","0.112"],["62000.20","0.339"],["62000.60","0.019"],["62005.50","0.001"],["62022.60","0.154"],["62027.60","0.152"],["62028.80","0.009"],["62029.50","0.040"],["62029.60","0.017"],["62031.20","0.003"],["62032.50","0.002"],["62033.80","9.236"]],"e":"depthUpdate","ps":"BTCUSDT","pu":10998398261423,"s":"BTCUSDT","st":1,"u":10998398270788}
{"E":1783504307456,"T":1783504307455,"U":10998398270901,"a":[["62033.90","5.540"],["62040.20","0.028"],["62041.20","0.005"],["62102.80","1.641"],["62344.10","0.233"],["62654.20","3.928"],["62853.60","0.807"]],"b":[["11633.80","0.048"],["11733.80","2.720"],["11833.80","0.992"],["11933.80","1.040"],["55830.40","0.002"],["59552.40","0.000"],["60793.30","0.000"],["61413.50","0.011"],["61723.60","0.174"],["61834.40","0.001"],["61973.30","0.148"],["62031.30","0.184"],["62033.80","9.239"]],"e":"depthUpdate","ps":"BTCUSDT","pu":10998398270788,"s":"BTCUSDT","st":1,"u":10998398278379}
{"E":1783504307558,"T":1783504307557,"U":10998398278428,"a":[["62041.20","1.367"],["62044.60","0.190"],["62055.80","0.086"],["62058.70","0.130"],["62062.00","0.174"],["62068.20","0.376"],["62074.90","0.328"],["62075.00","5.683"],["62075.20","0.295"],["62654.20","3.928"]],"b":[["1000.00","210.542"],["11633.80","0.176"],["11733.80","2.736"],["11833.80","0.992"],["11933.80","0.896"],["55830.40","0.002"],["59552.40","0.003"],["61041.30","1.178"],["61165.30","0.770"],["61413.50","0.009"],["61475.50","1.510"],["61834.40","0.002"],["61990.50","0.062"],["61999.20","0.052"],["62018.20","0.177"],["62024.70","0.080"],["62029.60","0.013"],["62031.30","0.168"],["62032.50","0.004"],["62033.80","9.163"]],"e":"depthUpdate","ps":"BTCUSDT","pu":10998398278379,"s":"BTCUSDT","st":1,"u":10998398290219}
{"E":1783504307660,"T":1783504307657,"U":10998398290511,"a":[["62034.00","0.326"],["62037.80","0.557"],["62054.80","0.004"],["62055.60","0.010"],["62057.60","0.002"],["62074.20","0.000"],["62080.00","1.057"],["62097.70","0.018"],["62160.00","0.546"],["62240.00","0.607"],["62320.00","0.543"],["62400.00","14.418"],["62654.20","3.928"],["62816.20","0.795"],["67255.00","4.786"]],"b":[["11633.80","0.320"],["11733.80","2.720"],["11833.80","0.992"],["11933.80","0.768"],["55830.40","0.002"],["60731.10","0.329"],["61306.50","0.819"],["61326.70","0.005"],["61413.50","0.009"],["61680.00","1.099"],["61723.60","0.174"],["61760.00","0.591"],["61834.40","0.001"],["61840.00","0.431"],["61855.20","2.969"],["61857.60","0.025"],["61920.00","0.504"],["62000.00","8.950"],["62002.70","0.094"],["62012.00","0.001"],["62018.20","0.000"],["62024.40","0.001"],["62024.70","0.000"],["62029.60","0.017"],["62030.50","0.019"],["62031.30","0.191"],["62032.50","0.002"],["62033.60","0.096"],["62033.80","8.064"]],"e":"depthUpdate","ps":"BTCUSDT","pu":10998398290219,"s":"BTCUSDT","st":1,"u":10998398300499}
{"E":1783504307762,"T":1783504307761,"U":10998398300813,"a":[["62033.90","5.525"],["62034.00","0.324"],["62035.90","0.000"],["62037.20","0.005"],["62037.80","0.001"],["62038.70","0.021"],["62040.00","0.947"],["62040.10","0.001"],["62040.20","0.028"],["62042.40","0.006"],["62042.60","0.004"],["62043.20","0.565"],["62055.80","0.005"],["62098.90","0.132"],["62456.40","0.018"],["62459.10","0.000"],["62654.20","3.928"],["62777.10","17.063"],["63274.60","2.139"]],"b":[["11633.80","0.448"],["11733.80","2.736"],["11833.80","0.992"],["11933.80","0.624"],["49627.00","0.000"],["55830.40","0.002"],["59552.40","0.000"],["61413.50","0.009"],["61723.60","0.174"],["61800.00","7.675"],["61834.40","0.002"],["62000.20","0.257"],["62015.30","0.050"],["62017.60","0.462"],["62029.20","0.017"],["62029.60","0.013"],["62030.50","0.003"],["62032.00","0.002"],["62032.10","0.082"],["62032.50","0.004"],["62033.40","0.004"],["62033.60","0.016"],["62033.80","8.067"]],"e":"depthUpdate","ps":"BTCUSDT","pu":10998398300499,"s":"BTCUSDT","st":1,"u":10998398308858}
{"E":1783504307864,"T":1783504307861,"U":10998398308984,"a":[["62040.00","0.069"],["62040.10","0.887"],["62040.20","0.028"],["62042.60","0.004"],["62043.20","0.001"],["62048.20","0.000"],["62050.30","0.577"],["62050.50","0.001"],["62051.90","0.727"],["62053.20","0.002"],["62053.50","1.304"],["62055.50","0.035"],["62058.30","0.000"],["62060.70","0.133"],["62068.00","0.122"],["62068.10","0.102"],["62068.20","0.374"],["62073.00","0.140"],["62074.20","0.128"],["62080.00","1.075"],["62083.00","0.014"],["62160.00","0.564"],["62240.00","0.625"],["62320.00","0.561"],["62344.10","0.234"],["62400.00","14.436"],["62575.10","0.334"],["62654.20","3.928"]],"b":[["1000.00","210.542"],["11633.80","0.704"],["11733.80","2.496"],["11833.80","1.104"],["11933.80","0.496"],["55830.40","0.002"],["58943.80","0.000"],["59552.40","0.003"],["60916.10","0.008"],["61413.50","0.009"],["61680.00","1.117"],["61760.00","0.609"],["61764.90","0.000"],["61765.00","0.008"],["61834.40","0.001"],["61840.00","0.449"],["61920.00","0.522"],["61974.90","0.019"],["62000.00","8.968"],["62013.80","0.051"],["62014.90","2.245"],["62016.90","0.001"],["62018.80","1.070"],["62020.20","0.564"],["62021.20","0.000"],["62024.80","0.052"],["62029.20","0.001"],["62029.50","0.044"],["62031.80","0.016"],["62032.10","0.002"],["62032.50","0.002"],["62033.80","8.147"]],"e":"depthUpdate","ps":"BTCUSDT","pu":10998398308858,"s":"BTCUSDT","st":1,"u":10998398316210}
{"E":1783504307966,"T":1783504307965,"U":10998398316454,"a":[["62039.60","0.066"],["62039.80","0.000"],["62039.90","0.002"],["62040.00","0.005"],["62040.10","0.001"],["62043.20","0.887"],["62058.70","0.130"],["62654.20","3.928"]],"b":[["11633.80","0.976"],["11733.80","2.224"],["11833.80","1.248"],["11933.80","0.352"],["55830.40","0.002"],["58932.10","0.052"],["59552.40","0.000"],["61258.40","0.296"],["61413.50","0.009"],["61537.50","1.946"],["61723.60","0.174"],["61781.00","0.000"],["61821.70","0.112"],["61834.40","0.002"],["62018.90","0.699"],["62020.20","0.000"],["62021.10","1.182"],["62026.10","0.083"],["62031.80","0.000"],["62033.70","0.004"],["62033.80","8.067"]],"e":"depthUpdate","ps":"BTCUSDT","pu":10998398316210,"s":"BTCUSDT","st":1,"u":10998398322952}
{"E":1783504308068,"T":1783504308066,"U":10998398323099,"a":[["62033.90","3.841"],["62040.10","0.557"],["62040.20","0.890"],["62043.20","0.001"],["62057.50","0.160"],["62060.70","0.013"],["62062.00","0.013"],["62068.20","0.052"],["62075.30","0.175"],["62167.20","0.000"],["62654.20","3.928"],["62778.30","3.655"],["62933.40","3.729"],["63026.40","2.218"]],"b":[["1000.00","210.692"],["11633.80","1.248"],["11733.80","1.952"],["11833.80","1.376"],["11933.80","0.224"],["55830.40","0.002"],["59552.40","0.003"],["60901.90","0.000"],["61216.30","0.002"],["61293.10","14.962"],["61413.50","0.009"],["61834.40","0.001"],["61972.20","0.125"],["61972.50","0.004"],["62012.70","0.036"],["62013.90","0.585"],["62014.90","1.664"],["62019.20","0.034"],["62019.40","0.011"],["62021.10","1.166"],["62024.60","0.404"],["62026.10","0.003"],["62028.50","0.123"],["62029.50","0.040"],["62030.70","1.362"],["62032.50","0.004"]],"e":"depthUpdate","ps":"BTCUSDT","pu":10998398322952,"s":"BTCUSDT","st":1,"u":10998398331507}
{"E":1783504308170,"T":1783504308169,"U":10998398331645,"a":[["62033.90","0.327"],["62034.00","0.098"],["62035.50","0.352"],["62036.40","0.000"],["62037.00","0.001"],["62037.20","0.001"],["62037.50","0.000"],["62037.60","0.000"],["62037.90","2.446"],["62038.00","0.002"],["62038.30","0.000"],["62038.50","0.001"],["62038.60","0.004"],["62038.70","0.005"],["62038.80","0.001"],["62038.90","0.001"],["62039.40","0.005"],["62039.70","0.003"],["62040.00","0.003"],["62040.10","0.001"],["62040.20","0.002"],["62040.30","0.010"],["62040.40","0.002"],["62040.50","0.016"],["62040.80","0.001"],["62041.10","0.303"],["62041.20","0.625"],["62041.60","0.002"],["62041.70","0.001"],["62041.80","0.038"],["62041.90","0.002"],["62042.10","0.000"],["62042.60","0.375"],["62042.70","0.795"],["62042.80","0.004"],["62043.00","0.460"],["62043.20","0.001"],["62043.30","1.087"],["62043.80","0.000"],["62043.90","0.066"],["62044.00","0.060"],["62044.10","0.001"],["62044.20","0.343"],["62044.30","0.437"],["62044.60","0.186"],["62044.70","1.277"],["62044.80","0.663"],["62044.90","0.199"],["62045.40","0.123"],["62045.70","0.000"],["62045.80","0.122"],["62045.90","0.645"],["62046.00","0.005"],["62046.20","0.931"],["62046.80","0.925"],["62047.30","0.000"],["62048.90","0.125"],["62049.10","0.449"],["62049.20","1.658"],["62049.30","0.325"],["62049.60","0.019"],["62050.20","0.324"],["62050.30","0.013"],["62050.40","0.775"],["62051.80","0.753"],["62051.90","0.002"],["62052.30","0.156"],["62052.60","0.665"],["62052.90","0.726"],["62053.40","0.818"],["62053.50","0.724"],["62054.10","0.323"],["62054.60","0.000"],["62055.10","1.126"],["62055.40","0.130"],["62055.60","0.002"],["62056.10","1.442"],["62056.50","0.000"],["62056.80","0.582"],["62056.90","0.111"],["62057.30","0.768"],["62057.50","0.040"],["62058.70","0.002"],["62059.20","0.862"],["62059.30","1.535"],["62059.40","0.000"],["62060.60","0.004"],["62061.00","0.005"],["62061.30","0.015"],["62061.60","0.487"],["62061.80","0.000"],["62062.00","0.005"],["62062.40","0.013"],["62062.80","0.004"],["62062.90","0.001"],["62063.00","0.012"],["62063.10","0.324"],["62063.40","0.284"],["62063.60","0.021"],["62063.80","0.923"],["62064.10","0.052"],["62064.50","0.059"],["62064.60","0.028"],["62065.00","1.084"],["62067.30","0.328"],["62067.70","0.683"],["62068.00","0.122"],["62068.10","0.152"],["62068.20","0.058"],["62068.30","0.002"],["62069.20","0.093"],["62069.30","0.123"],["62069.40","0.049"],["62071.00","0.074"],["62072.80","1.365"],["62072.90","0.001"],["62073.00","0.140"],["62073.20","0.000"],["62073.50","0.078"],["62073.80","0.000"],["62074.20","0.440"],["62075.00","5.580"],["62075.20","0.295"],["62075.30","0.173"],["62077.00","0.049"],["62077.10","0.105"],["62078.20","1.432"],["62081.80","0.111"],["62081.90","0.019"],["62082.10","0.002"],["62082.30","1.389"],["62082.60","0.014"],["62083.00","0.000"],["62086.30","0.094"],["62086.50","0.017"],["62088.00","0.304"],["62089.30","0.000"],["62089.40","0.014"],["62093.50","0.000"],["62095.90","1.412"],["62096.70","0.025"],["62099.00","18.386"],["62099.80","0.707"],["62100.40","0.001"],["62100.60","0.015"],["62102.90","4.094"],["62115.40","1.135"],["62126.50","0.008"],["62133.30","0.054"],["62136.40","0.706"],["62136.80","2.002"],["62155.90","3.972"],["62175.10","4.708"],["62192.20","1.586"],["62214.20","2.929"],["62239.10","0.771"],["62266.90","0.735"],["62292.30","0.485"],["62310.70","0.789"],["62332.90","0.655"],["62344.10","0.235"],["62359.90","0.636"],["62392.10","1.502"],["62409.90","0.091"],["62428.40","0.241"],["62654.20","3.930"],["63274.50","0.036"],["63274.60","2.133"]],"b":[["1000.00","210.542"],["11633.80","1.520"],["11733.80","1.680"],["11833.80","1.520"],["11933.80","0.080"],["55830.40","0.002"],["60793.20","0.037"],["61169.20","0.571"],["61413.50","0.011"],["61574.70","0.000"],["61723.60","0.335"],["61789.70","0.003"],["61834.40","0.002"],["61882.40","0.000"],["61957.20","0.602"],["61965.60","0.001"],["61967.10","0.546"],["61972.20","0.123"],["61972.40","1.195"],["61973.30","0.098"],["61974.90","0.175"],["61975.10","0.000"],["61975.30","0.003"],["61976.40","0.097"],["61980.40","0.000"],["61981.70","0.000"],["61982.00","0.000"],["61982.60","0.003"],["61983.50","0.316"],["61983.70","0.019"],["61983.80","1.530"],["61987.40","0.000"],["61987.70","0.000"],["61988.30","1.057"],["61988.40","0.101"],["61990.20","0.004"],["61990.40","0.000"],["61990.50","0.002"],["61990.60","1.296"],["61990.80","0.661"],["61991.10","0.076"],["61996.70","0.054"],["61997.10","0.244"],["61998.80","0.185"],["61999.10","0.065"],["61999.70","0.000"],["62000.20","0.255"],["62001.00","0.019"],["62001.20","0.329"],["62001.40","0.065"],["62002.50","0.673"],["62004.00","0.041"],["62004.80","0.003"],["62005.40","0.061"],["62005.90","0.010"],["62006.00","0.037"],["62006.20","0.029"],["62006.30","0.016"],["62006.50","0.453"],["62006.60","0.122"],["62006.70","0.000"],["62007.00","0.275"],["62007.20","0.135"],["62007.40","0.016"],["62009.10","0.053"],["62009.40","0.000"],["62012.70","0.001"],["62012.90","0.455"],["62013.30","0.012"],["62013.50","0.345"],["62013.80","0.051"],["62013.90","0.004"],["62014.10","0.037"],["62014.40","0.130"],["62015.20","0.130"],["62016.10","0.002"],["62016.20","0.001"],["62016.40","0.069"],["62016.50","0.007"],["62017.60","0.341"],["62017.90","0.583"],["62018.70","1.374"],["62018.80","0.344"],["62018.90","0.003"],["62019.20","0.018"],["62020.30","0.005"],["62020.50","0.000"],["62020.70","0.360"],["62020.90","0.426"],["62021.20","0.564"],["62021.40","0.855"],["62021.90","0.122"],["62022.60","0.022"],["62023.00","0.299"],["62023.60","0.021"],["62024.60","0.324"],["62024.80","0.005"],["62024.90","0.016"],["62025.30","0.124"],["62025.40","0.437"],["62025.50","0.123"],["62025.70","0.582"],["62025.90","0.324"],["62026.10","0.003"],["62026.20","0.002"],["62026.50","0.121"],["62027.10","0.995"],["62027.40","0.205"],["62028.10","1.363"],["62028.20","0.852"],["62028.40","0.133"],["62028.50","0.123"],["62028.80","0.008"],["62030.00","0.026"],["62030.30","0.003"],["62030.70","1.365"],["62030.90","0.133"],["62031.00","0.005"],["62031.10","0.000"],["62031.30","0.240"],["62031.60","0.121"],["62031.70","0.026"],["62032.00","0.061"],["62032.50","0.002"],["62032.70","0.485"],["62032.90","0.276"],["62033.40","0.001"],["62033.80","14.866"]],"e":"depthUpdate","ps":"BTCUSDT","pu":10998398331507,"s":"BTCUSDT","st":1,"u":10998398385872}
{"E":1783504308272,"T":1783504308271,"U":10998398386303,"a":[["62033.90","0.000"],["62034.00","0.000"],["62034.10","1.529"],["62034.20","0.002"],["62035.50","0.001"],["62035.70","0.351"],["62036.30","0.001"],["62036.80","0.002"],["62037.40","0.002"],["62038.60","0.000"],["62038.70","0.003"],["62039.30","0.002"],["62039.40","0.001"],["62039.60","0.002"],["62040.40","0.006"],["62040.50","0.001"],["62041.00","0.068"],["62041.10","0.006"],["62041.20","0.502"],["62041.70","0.000"],["62042.40","0.021"],["62042.50","0.026"],["62042.60","0.051"],["62043.00","0.372"],["62043.20","1.005"],["62043.30","0.004"],["62043.40","0.712"],["62043.60","0.001"],["62043.70","0.001"],["62043.90","0.401"],["62044.00","0.002"],["62044.20","0.001"],["62044.30","0.145"],["62044.40","0.000"],["62044.60","0.000"],["62044.70","0.003"],["62044.80","0.377"],["62044.90","0.001"],["62045.20","0.000"],["62045.80","0.666"],["62046.10","0.002"],["62046.20","0.130"],["62046.30","0.077"],["62046.40","0.017"],["62046.50","0.005"],["62046.70","0.901"],["62046.80","1.290"],["62046.90","0.454"],["62047.00","0.001"],["62047.10","0.000"],["62048.00","0.887"],["62048.10","0.821"],["62048.20","0.322"],["62048.40","0.003"],["62048.80","0.002"],["62048.90","0.208"],["62049.00","0.821"],["62049.10","0.449"],["62049.20","1.654"],["62049.30","0.428"],["62049.40","0.287"],["62049.60","0.977"],["62049.80","0.093"],["62049.90","0.131"],["62050.00","0.003"],["62050.20","0.185"],["62050.40","0.109"],["62051.30","0.050"],["62051.40","0.021"],["62051.50","0.001"],["62051.80","0.018"],["62051.90","0.006"],["62052.30","0.003"],["62052.90","0.001"],["62053.30","0.101"],["62053.40","0.660"],["62053.50","0.024"],["62053.60","0.332"],["62054.20","0.001"],["62055.00","0.567"],["62055.50","0.004"],["62055.80","0.006"],["62055.90","0.822"],["62056.00","0.006"],["62056.20","0.913"],["62056.50","0.725"],["62056.80","0.404"],["62056.90","0.048"],["62057.30","0.760"],["62057.40","0.174"],["62057.70","0.387"],["62057.80","0.003"],["62058.00","0.070"],["62058.60","0.487"],["62058.90","1.365"],["62059.00","0.086"],["62059.30","0.529"],["62059.40","0.000"],["62059.50","1.340"],["62061.40","0.171"],["62061.60","0.367"],["62061.80","0.043"],["62062.00","0.585"],["62062.40","0.011"],["62063.80","0.864"],["62064.60","0.008"],["62064.80","1.130"],["62064.90","1.168"],["62065.20","0.004"],["62065.80","0.002"],["62068.00","0.122"],["62068.20","0.186"],["62068.70","0.062"],["62069.80","0.120"],["62070.20","1.474"],["62071.30","1.335"],["62071.50","0.104"],["62073.30","0.132"],["62074.20","0.312"],["62074.40","0.003"],["62074.50","0.000"],["62074.70","0.304"],["62074.80","0.003"],["62075.20","0.296"],["62075.50","1.064"],["62076.50","0.722"],["62077.70","0.050"],["62078.00","0.165"],["62078.10","2.890"],["62078.20","1.521"],["62078.60","0.001"],["62080.90","0.081"],["62081.60","0.001"],["62082.40","0.032"],["62084.40","0.755"],["62087.60","0.142"],["62087.80","1.356"],["62088.00","0.304"],["62089.40","0.000"],["62093.90","0.149"],["62094.10","0.713"],["62097.70","0.019"],["62098.90","0.031"],["62099.00","0.026"],["62099.30","0.102"],["62099.60","3.480"],["62100.00","0.639"],["62100.20","0.133"],["62100.40","0.016"],["62100.50","0.799"],["62100.60","0.000"],["62101.30","0.864"],["62101.50","0.003"],["62102.30","8.002"],["62103.10","0.101"],["62103.20","0.003"],["62104.60","0.350"],["62106.90","0.001"],["62107.30","0.770"],["62108.20","1.989"],["62108.30","0.239"],["62109.00","0.058"],["62109.60","18.447"],["62133.60","0.000"],["62144.80","0.332"],["62179.20","0.001"],["62294.40","0.014"],["62455.10","0.018"],["62456.40","0.000"],["62654.20","3.928"],["62654.40","1.910"],["62655.60","14.243"],["62809.30","0.787"],["63274.50","0.039"]],"b":[["11633.80","1.568"],["11634.00","0.224"],["11733.80","1.408"],["11734.00","0.048"],["11833.80","1.536"],["11834.00","0.016"],["11933.80","0.000"],["55830.40","0.000"],["55830.60","0.002"],["58932.20","0.029"],["59552.40","0.000"],["60793.20","0.031"],["60793.40","0.009"],["61034.00","0.018"],["61043.50","0.000"],["61043.60","0.001"],["61043.90","0.587"],["61165.30","3.219"],["61184.30","0.000"],["61248.70","1.157"],["61413.50","0.009"],["61413.70","0.010"],["61612.10","0.492"],["61619.40","1.216"],["61646.00","0.589"],["61665.20","0.281"],["61692.00","0.533"],["61711.20","0.000"],["61714.10","0.096"],["61723.60","0.335"],["61730.70","0.420"],["61751.00","1.007"],["61768.70","0.755"],["61785.80","0.000"],["61785.90","1.048"],["61788.90","0.697"],["61807.60","0.407"],["61834.40","0.001"],["61835.50","0.245"],["61844.90","0.675"],["61855.30","0.003"],["61857.60","0.000"],["61867.20","0.784"],["61870.20","0.766"],["61880.10","1.453"],["61887.60","0.763"],["61913.90","0.843"],["61929.70","0.051"],["61934.30","1.486"],["61940.90","0.009"],["61941.00","0.016"],["61944.80","0.000"],["61951.90","5.518"],["61952.50","1.591"],["61964.20","0.053"],["61964.80","1.346"],["61964.90","0.000"],["61965.80","0.052"],["61965.90","0.027"],["61966.90","0.021"],["61967.00","0.103"],["61967.30","0.139"],["61968.90","0.158"],["61969.00","0.004"],["61969.20","0.013"],["61971.00","18.948"],["61971.50","0.261"],["61972.00","1.474"],["61973.20","0.324"],["61973.30","0.150"],["61974.90","0.019"],["61975.10","0.000"],["61975.80","0.432"],["61976.20","0.887"],["61976.70","0.000"],["61978.40","1.488"],["61980.90","1.528"],["61981.70","0.210"],["61982.00","0.436"],["61983.70","0.004"],["61984.30","0.016"],["61984.40","0.254"],["61987.50","0.087"],["61989.00","0.006"],["61989.30","0.110"],["61989.50","0.008"],["61990.70","1.086"],["61990.90","0.000"],["61991.50","0.112"],["61993.40","0.001"],["61994.10","0.055"],["61994.20","0.291"],["61997.10","0.034"],["61997.80","0.061"],["61998.70","1.961"],["61998.80","0.125"],["62000.20","0.174"],["62000.60","0.018"],["62000.70","0.370"],["62001.00","0.017"],["62002.80","0.059"],["62003.00","0.129"],["62004.00","0.001"],["62004.50","0.259"],["62005.00","0.003"],["62007.30","0.002"],["62007.40","0.002"],["62008.40","0.667"],["62008.90","2.859"],["62009.00","0.001"],["62009.20","0.468"],["62012.40","0.370"],["62013.50","0.325"],["62013.70","0.257"],["62014.00","0.097"],["62014.40","0.001"],["62014.70","1.382"],["62015.10","1.068"],["62015.20","0.001"],["62015.30","0.051"],["62015.60","0.247"],["62016.40","0.067"],["62016.50","0.007"],["62016.60","0.024"],["62016.90","0.001"],["62017.40","0.011"],["62017.70","0.132"],["62017.90","0.002"],["62018.70","1.501"],["62018.90","0.005"],["62019.00","0.005"],["62019.20","0.014"],["62020.50","0.581"],["62020.90","0.442"],["62021.20","0.132"],["62021.30","0.005"],["62021.40","0.001"],["62021.70","0.329"],["62021.90","0.001"],["62022.60","0.007"],["62023.10","0.002"],["62023.20","0.000"],["62023.90","0.373"],["62024.10","0.292"],["62024.30","0.736"],["62024.40","0.871"],["62024.60","0.324"],["62025.20","2.660"],["62025.30","0.688"],["62025.40","0.000"],["62025.60","0.124"],["62025.80","0.327"],["62026.60","0.022"],["62026.70","0.126"],["62026.80","0.004"],["62027.00","0.215"],["62027.20","0.053"],["62027.40","0.136"],["62027.70","0.002"],["62028.00","0.215"],["62028.20","0.164"],["62028.30","0.218"],["62028.40","0.001"],["62028.50","0.127"],["62028.60","0.002"],["62028.70","0.000"],["62028.80","0.008"],["62029.40","0.011"],["62029.80","0.001"],["62030.00","0.006"],["62030.10","0.000"],["62030.50","0.053"],["62030.70","1.362"],["62030.90","0.005"],["62031.30","0.219"],["62031.70","0.003"],["62031.90","0.003"],["62032.00","0.084"],["62032.40","0.001"],["62032.50","0.004"],["62032.60","0.322"],["62032.70","0.483"],["62032.90","0.001"],["62033.70","0.000"],["62033.80","1.519"],["62033.90","4.114"],["62034.00","25.833"]],"e":"depthUpdate","ps":"BTCUSDT","pu":10998398385872,"s":"BTCUSDT","st":1,"u":10998398414627}
{"E":1783504308374,"T":1783504308373,"U":10998398414685,"a":[["62035.60","0.005"],["62039.20","0.000"],["62041.10","0.006"],["62041.20","0.625"],["62043.10","0.004"],["62043.90","0.066"],["62045.50","0.485"],["62045.60","0.887"],["62045.70","0.820"],["62046.40","0.015"],["62046.60","0.019"],["62048.00","0.001"],["62048.60","0.092"],["62049.20","0.067"],["62049.60","0.977"],["62049.70","1.893"],["62049.80","0.171"],["62049.90","0.189"],["62051.20","0.242"],["62051.40","0.005"],["62051.50","0.154"],["62052.50","1.018"],["62054.00","0.047"],["62054.70","0.004"],["62055.00","0.003"],["62058.90","1.365"],["62059.50","1.360"],["62059.70","0.297"],["62061.80","0.008"],["62062.50","0.049"],["62063.40","0.276"],["62063.60","0.029"],["62064.70","0.306"],["62064.90","0.876"],["62065.30","0.000"],["62065.60","0.001"],["62065.90","0.003"],["62068.40","0.002"],["62069.40","0.000"],["62070.00","0.309"],["62070.20","1.454"],["62071.30","1.518"],["62071.50","0.002"],["62072.00","0.091"],["62072.40","0.112"],["62075.20","0.004"],["62075.30","0.465"],["62076.50","0.712"],["62077.60","0.001"],["62077.70","0.155"],["62078.00","0.060"],["62078.10","2.979"],["62078.20","1.556"],["62080.60","0.006"],["62082.40","0.018"],["62086.90","0.037"],["62088.20","0.010"],["62099.80","0.875"],["62100.20","0.031"],["62100.40","0.001"],["62103.20","0.104"],["62103.30","18.431"],["62104.40","0.001"],["62104.60","0.249"],["62108.00","0.090"],["62108.30","0.156"],["62108.70","0.067"],["62109.30","0.058"],["62109.60","0.016"],["62120.70","0.000"],["62654.40","1.910"],["62871.60","0.556"]],"b":[["1000.00","210.542"],["11634.00","0.496"],["11733.80","1.136"],["11734.00","0.192"],["11833.80","1.408"],["11834.00","0.000"],["49627.00","0.000"],["55830.60","0.002"],["58932.10","0.049"],["58932.20","0.032"],["59552.60","0.003"],["60793.20","0.028"],["60793.40","0.012"],["60872.60","1.632"],["61171.50","3.560"],["61178.80","0.323"],["61413.70","0.010"],["61537.50","2.270"],["61834.40","0.002"],["61930.90","0.000"],["61971.00","0.002"],["61975.80","0.430"],["61981.20","0.328"],["61981.60","20.099"],["61990.60","1.296"],["61997.80","0.001"],["61998.40","0.077"],["62007.20","0.127"],["62007.50","0.112"],["62010.20","0.170"],["62013.70","0.217"],["62014.70","0.010"],["62015.40","0.128"],["62016.60","0.004"],["62018.80","1.719"],["62021.60","0.129"],["62022.30","0.122"],["62022.60","0.571"],["62024.90","0.036"],["62025.30","0.124"],["62025.60","0.003"],["62028.30","0.154"],["62030.90","0.297"],["62033.80","1.232"],["62033.90","3.950"],["62034.00","25.481"]],"e":"depthUpdate","ps":"BTCUSDT","pu":10998398414627,"s":"BTCUSDT","st":1,"u":10998398430516}
{"E":1783504308476,"T":1783504308473,"U":10998398430683,"a":[["62034.10","1.531"],["62041.00","0.068"],["62041.10","0.006"],["62041.20","0.696"],["62042.50","0.323"],["62042.60","0.348"],["62045.40","1.009"],["62045.50","0.353"],["62045.60","0.001"],["62046.40","0.014"],["62046.60","0.311"],["62047.00","0.002"],["62047.70","0.005"],["62048.30","0.657"],["62048.40","0.004"],["62049.10","0.690"],["62049.30","0.427"],["62049.90","0.297"],["62050.30","0.253"],["62050.40","0.301"],["62051.20","0.001"],["62052.40","0.299"],["62053.60","1.694"],["62055.80","0.006"],["62055.90","0.002"],["62057.30","1.340"],["62059.20","0.002"],["62059.60","0.132"],["62061.20","0.094"],["62061.80","0.000"],["62062.00","0.005"],["62062.40","0.002"],["62063.60","0.149"],["62065.00","1.001"],["62065.90","0.012"],["62066.00","0.004"],["62068.10","0.102"],["62069.80","0.000"],["62072.10","0.004"],["62072.60","0.185"],["62072.70","0.316"],["62077.60","0.000"],["62078.00","0.165"],["62078.20","1.362"],["62099.90","1.204"],["62100.40","0.343"],["62100.50","0.889"],["62150.50","1.668"],["62150.60","1.602"],["62524.10","0.006"],["62654.40","1.910"],["63274.50","0.036"]],"b":[["1000.00","210.542"],["11634.00","0.768"],["11733.80","0.864"],["11734.00","0.320"],["11833.80","1.280"],["55830.60","0.002"],["59552.60","0.000"],["61289.40","5.811"],["61413.70","0.010"],["61834.40","0.001"],["61859.10","0.000"],["61859.20","1.537"],["61983.80","0.000"],["61983.90","2.952"],["62006.20","0.015"],["62014.90","1.678"],["62018.70","1.945"],["62018.80","1.848"],["62020.50","0.000"],["62020.90","1.002"],["62021.00","1.008"],["62021.80","0.003"],["62033.80","1.231"],["62033.90","3.949"],["62034.00","25.489"]],"e":"depthUpdate","ps":"BTCUSDT","pu":10998398430516,"s":"BTCUSDT","st":1,"u":10998398444783}
{"E":1783504308578,"T":1783504308577,"U":10998398445159,"a":[["62034.10","1.535"],["62041.10","0.006"],["62041.20","0.696"],["62042.30","0.304"],["62042.40","0.318"],["62045.20","0.552"],["62045.30","0.000"],["62045.50","0.000"],["62048.90","1.570"],["62049.00","0.001"],["62049.20","0.169"],["62050.50","0.091"],["62054.10","0.001"],["62054.80","0.326"],["62057.30","1.421"],["62063.50","0.845"],["62068.20","0.058"],["62069.70","0.323"],["62071.40","0.328"],["62072.60","0.083"],["62072.70","0.136"],["62078.00","0.060"],["62078.10","2.874"],["62078.20","1.362"],["62089.80","0.050"],["62096.70","0.000"],["62099.30","0.204"],["62100.60","0.090"],["62108.30","0.239"],["62165.40","0.003"],["62654.40","1.910"],["63274.50","0.033"]],"b":[["11634.00","1.040"],["11733.80","0.592"],["11734.00","0.464"],["11833.80","1.136"],["49627.00","0.000"],["55830.60","0.002"],["61124.70","0.972"],["61258.40","1.111"],["61413.70","0.010"],["61577.50","0.005"],["61723.60","0.335"],["61834.40","0.002"],["61903.10","0.000"],["62012.90","0.777"],["62018.90","0.137"],["62019.10","0.242"],["62022.00","0.702"],["62025.30","0.205"],["62028.20","0.032"],["62029.90","0.341"],["62033.80","1.215"],["62033.90","3.944"],["62034.00","25.491"]],"e":"depthUpdate","ps":"BTCUSDT","pu":10998398444783,"s":"BTCUSDT","st":1,"u":10998398458011}
{"E":1783504308680,"T":1783504308679,"U":10998398458278,"a":[["62041.10","0.006"],["62042.20","0.149"],["62042.50","0.026"],["62042.60","0.051"],["62044.80","0.381"],["62045.10","0.564"],["62045.40","0.445"],["62048.80","0.002"],["62049.70","1.983"],["62050.20","0.269"],["62068.20","0.186"],["62071.30","1.518"],["62071.50","0.128"],["62072.50","0.001"],["62077.40","0.056"],["62078.00","0.356"],["62086.90","0.022"],["62090.60","0.003"],["62095.00","0.355"],["62099.10","18.492"],["62099.80","0.875"],["62099.90","1.305"],["62100.30","0.085"],["62100.40","0.348"],["62103.10","0.000"],["62103.20","0.003"],["62103.30","0.000"],["62169.20","1.602"],["62186.90","0.000"],["62190.70","1.168"],["62530.40","0.391"],["62654.40","1.910"],["63188.60","0.789"],["63226.00","0.002"]],"b":[["1000.00","210.542"],["11534.00","0.080"],["11634.00","1.152"],["11733.80","0.400"],["11734.00","0.592"],["11833.80","1.008"],["49627.00","0.002"],["55830.60","0.002"],["58932.10","0.027"],["59552.60","0.003"],["60932.20","0.818"],["61134.30","2.123"],["61155.00","9.221"],["61289.40","6.625"],["61413.70","0.010"],["61537.50","2.595"],["61834.40","0.001"],["61881.60","0.730"],["61881.80","1.035"],["61901.00","0.002"],["61903.40","0.670"],["61950.70","0.337"],["62019.60","0.002"],["62025.90","0.404"],["62029.90","0.325"],["62033.70","0.011"],["62033.80","1.213"],["62034.00","25.655"]],"e":"depthUpdate","ps":"BTCUSDT","pu":10998398458011,"s":"BTCUSDT","st":1,"u":10998398470269}
{"E":1783504308782,"T":1783504308781,"U":10998398470274,"a":[["62034.10","1.536"],["62035.60","0.003"],["62036.20","0.004"],["62041.10","0.562"],["62042.20","0.000"],["62042.30","0.007"],["62042.40","0.021"],["62042.60","0.348"],["62044.80","0.383"],["62062.50","0.749"],["62075.30","0.360"],["62080.00","0.898"],["62085.00","0.552"],["62090.60","0.003"],["62160.00","0.387"],["62240.00","0.448"],["62320.00","0.384"],["62344.10","0.234"],["62400.00","14.259"],["62654.40","1.910"]],"b":[["1000.00","210.542"],["11534.00","0.208"],["11634.00","1.168"],["11733.80","0.256"],["11734.00","0.736"],["11833.80","0.864"],["49627.00","0.000"],["55830.60","0.002"],["58932.10","0.009"],["58932.30","0.043"],["58943.80","0.002"],["59552.60","0.000"],["61413.70","0.010"],["61680.00","0.940"],["61723.80","0.883"],["61760.00","0.432"],["61834.40","0.002"],["61840.00","0.272"],["61920.00","0.345"],["61940.90","0.109"],["61981.20","0.326"],["61981.60","20.101"],["62000.00","8.791"],["62031.60","0.123"],["62033.80","1.230"],["62034.00","26.044"]],"e":"depthUpdate","ps":"BTCUSDT","pu":10998398470269,"s":"BTCUSDT","st":1,"u":10998398484459}
{"E":1783504308884,"T":1783504308883,"U":10998398484801,"a":[["62034.10","0.000"],["62034.20","0.000"],["62034.30","0.000"],["62034.40","0.000"],["62034.80","0.000"],["62035.00","0.000"],["62035.10","0.000"],["62035.50","0.000"],["62035.60","0.000"],["62035.70","0.000"],["62036.10","0.000"],["62036.20","0.000"],["62036.30","0.000"],["62036.70","0.000"],["62036.80","0.000"],["62036.90","0.000"],["62037.00","0.000"],["62037.10","0.000"],["62037.20","0.000"],["62037.30","0.000"],["62037.40","0.000"],["62037.70","0.000"],["62037.80","0.000"],["62037.90","1.872"],["62038.00","0.006"],["62038.20","0.000"],["62038.50","0.000"],["62038.90","0.000"],["62039.50","0.270"],["62039.60","0.000"],["62040.00","0.002"],["62040.20","0.000"],["62040.30","0.005"],["62040.40","0.005"],["62040.70","0.001"],["62041.00","0.003"],["62041.10","0.007"],["62041.20","0.005"],["62041.30","0.000"],["62041.80","0.006"],["62041.90","0.000"],["62042.00","0.000"],["62042.20","0.000"],["62042.30","0.007"],["62042.40","0.036"],["62042.50","0.075"],["62042.60","0.002"],["62042.70","0.001"],["62042.80","0.004"],["62042.90","0.149"],["62043.00","0.005"],["62043.10","0.004"],["62043.20","0.001"],["62043.30","0.004"],["62043.40","0.004"],["62043.90","0.002"],["62044.00","0.000"],["62044.10","0.129"],["62044.20","0.129"],["62044.30","0.000"],["62044.40","0.561"],["62044.50","0.868"],["62044.70","0.003"],["62044.80","0.038"],["62045.00","0.974"],["62045.10","0.493"],["62045.20","0.000"],["62045.30","0.000"],["62045.40","0.302"],["62045.50","1.395"],["62045.60","0.773"],["62045.70","0.000"],["62045.80","0.649"],["62046.00","0.005"],["62046.10","0.007"],["62046.30","0.077"],["62046.40","0.313"],["62046.50","0.813"],["62046.60","0.751"],["62046.70","0.000"],["62046.80","0.053"],["62046.90","0.000"],["62047.00","0.001"],["62047.20","0.051"],["62047.30","0.001"],["62047.40","0.120"],["62047.70","0.048"],["62047.80","0.821"],["62047.90","0.004"],["62048.10","0.082"],["62048.20","0.000"],["62048.40","0.003"],["62048.60","0.414"],["62048.70","1.000"],["62048.80","0.000"],["62048.90","0.904"],["62049.10","0.328"],["62049.30","0.169"],["62049.40","0.024"],["62049.50","0.824"],["62049.60","1.348"],["62049.70","0.233"],["62049.80","0.170"],["62050.10","0.001"],["62050.20","0.189"],["62050.30","0.253"],["62050.40","0.755"],["62050.70","0.305"],["62050.80","0.323"],["62050.90","0.050"],["62051.10","0.834"],["62051.30","0.050"],["62051.50","2.183"],["62051.70","0.002"],["62052.00","0.002"],["62052.30","0.156"],["62052.40","0.167"],["62052.50","0.453"],["62052.60","0.324"],["62052.70","0.004"],["62053.00","0.292"],["62053.20","0.586"],["62053.30","0.101"],["62053.40","0.283"],["62053.50","0.024"],["62053.60","0.329"],["62053.70","0.000"],["62053.80","0.001"],["62054.00","0.012"],["62054.10","0.001"],["62054.40","0.005"],["62054.50","0.023"],["62054.80","0.004"],["62054.90","0.110"],["62055.00","0.567"],["62055.10","1.127"],["62055.70","0.309"],["62055.80","0.004"],["62056.00","1.301"],["62056.10","0.080"],["62056.20","0.912"],["62056.30","0.000"],["62056.40","1.362"],["62056.50","1.388"],["62056.60","0.283"],["62056.80","0.002"],["62057.30","0.760"],["62057.40","0.163"],["62057.70","0.325"],["62058.00","0.071"],["62058.30","0.000"],["62058.90","0.004"],["62059.00","0.006"],["62059.50","1.340"],["62059.60","0.126"],["62059.70","0.005"],["62059.90","0.982"],["62060.20","0.620"],["62060.60","0.004"],["62061.00","0.297"],["62061.20","0.084"],["62061.50","0.036"],["62061.60","0.351"],["62061.80","0.000"],["62062.10","0.026"],["62062.30","0.096"],["62062.40","3.536"],["62062.50","0.049"],["62062.60","0.001"],["62062.70","0.005"],["62063.30","0.008"],["62063.40","1.625"],["62063.50","0.684"],["62063.60","0.021"],["62063.70","0.005"],["62063.90","0.002"],["62064.40","0.405"],["62064.60","0.000"],["62064.70","0.014"],["62064.80","1.130"],["62064.90","0.001"],["62065.10","0.558"],["62065.20","0.000"],["62065.50","0.000"],["62065.70","0.001"],["62065.90","0.003"],["62066.00","0.020"],["62066.20","0.019"],["62066.40","1.494"],["62066.50","0.057"],["62066.70","0.064"],["62067.00","0.105"],["62067.10","0.001"],["62067.20","0.001"],["62067.70","0.691"],["62068.20","0.058"],["62068.30","0.022"],["62068.60","0.123"],["62068.70","0.062"],["62068.90","0.011"],["62069.20","0.012"],["62069.30","0.120"],["62069.70","0.001"],["62069.80","0.000"],["62070.00","0.312"],["62070.10","0.042"],["62070.20","1.365"],["62070.60","0.002"],["62070.70","0.008"],["62070.80","1.477"],["62071.00","0.074"],["62071.30","1.376"],["62072.00","0.403"],["62072.30","0.049"],["62072.80","1.365"],["62073.00","0.286"],["62073.30","0.122"],["62073.50","0.075"],["62073.60","2.588"],["62074.20","0.003"],["62074.40","0.003"],["62074.90","0.336"],["62075.00","5.578"],["62075.10","0.067"],["62075.20","0.002"],["62075.30","0.363"],["62075.50","1.007"],["62075.60","1.372"],["62075.70","0.090"],["62076.00","0.006"],["62076.90","0.004"],["62077.10","0.000"],["62077.20","1.435"],["62077.70","0.050"],["62077.80","1.438"],["62077.90","0.133"],["62078.00","0.356"],["62078.10","2.970"],["62078.40","0.074"],["62078.80","0.019"],["62079.00","0.001"],["62079.10","0.002"],["62080.00","1.075"],["62080.50","4.513"],["62081.70","0.001"],["62081.80","0.112"],["62082.20","0.014"],["62082.60","0.014"],["62083.00","0.000"],["62083.20","0.004"],["62083.90","0.014"],["62084.10","0.003"],["62084.50","0.673"],["62084.70","0.632"],["62085.60","0.014"],["62086.30","0.091"],["62086.90","0.014"],["62087.10","0.657"],["62088.10","0.016"],["62088.20","0.010"],["62088.80","0.004"],["62090.20","0.000"],["62090.60","0.000"],["62091.10","0.030"],["62091.20","0.000"],["62091.40","0.000"],["62092.20","0.029"],["62093.90","0.003"],["62094.60","0.011"],["62094.90","0.063"],["62095.60","0.000"],["62095.80","0.427"],["62095.90","1.100"],["62096.90","0.000"],["62099.10","0.061"],["62099.40","0.004"],["62099.60","3.480"],["62099.80","0.774"],["62100.00","0.642"],["62100.10","0.007"],["62100.40","0.348"],["62100.60","0.191"],["62103.20","0.003"],["62103.80","0.323"],["62107.50","0.387"],["62107.80","0.118"],["62108.60","0.101"],["62110.80","0.572"],["62113.80","18.284"],["62114.80","0.001"],["62120.00","0.198"],["62122.20","0.014"],["62122.60","0.000"],["62124.90","1.295"],["62126.80","0.001"],["62127.90","0.001"],["62129.20","0.048"],["62133.30","0.040"],["62134.90","0.123"],["62136.50","5.506"],["62142.80","0.011"],["62145.70","0.041"],["62160.00","0.564"],["62205.20","0.020"],["62208.30","0.001"],["62222.90","0.003"],["62223.00","0.044"],["62240.00","0.625"],["62320.00","0.561"],["62352.50","0.021"],["62354.60","0.144"],["62363.90","0.001"],["62400.00","14.436"],["62453.60","0.018"],["62455.10","0.000"],["62635.50","0.001"],["62654.40","1.910"],["62655.10","0.000"],["62656.10","0.000"],["62658.30","0.001"],["62748.00","0.006"],["62748.80","1.198"],["62749.60","3.479"],["62749.70","0.947"],["62751.90","1.894"],["62752.00","11.410"],["62809.90","0.003"],["62810.00","0.159"],["62811.70","1.577"],["62814.00","7.092"],["62853.70","0.794"],["63274.50","0.030"],["67559.20","0.000"]],"b":[["11534.00","0.224"],["11537.80","0.128"],["11634.00","1.024"],["11635.60","0.016"],["11637.80","0.112"],["11733.80","0.128"],["11735.60","0.016"],["11737.80","0.112"],["11833.80","0.736"],["55830.60","0.000"],["55832.00","0.000"],["55834.00","0.003"],["55877.70","0.001"],["58932.20","0.013"],["58932.30","0.046"],["58935.90","0.003"],["59556.20","0.010"],["60793.20","0.025"],["60797.10","0.004"],["60873.80","0.989"],["61035.60","0.014"],["61037.80","0.019"],["61043.90","0.585"],["61045.30","0.002"],["61045.50","0.016"],["61413.70","0.010"],["61415.20","0.001"],["61417.40","0.000"],["61680.00","1.117"],["61723.60","0.325"],["61723.80","0.894"],["61760.00","0.609"],["61772.80","0.684"],["61785.90","0.720"],["61787.50","0.001"],["61788.20","0.000"],["61834.40","0.001"],["61837.70","0.000"],["61840.00","0.449"],["61850.50","2.752"],["61854.20","3.778"],["61857.20","0.346"],["61861.60","0.052"],["61861.70","0.000"],["61869.20","0.001"],["61870.20","0.702"],["61879.70","0.003"],["61904.00","1.000"],["61904.20","0.000"],["61920.00","0.522"],["61933.50","0.052"],["61939.50","0.028"],["61940.90","0.101"],["61941.30","0.071"],["61941.80","0.283"],["61943.80","0.003"],["61943.90","0.003"],["61948.50","0.001"],["61948.60","0.763"],["61957.10","0.168"],["61959.00","0.002"],["61960.90","1.363"],["61962.70","0.003"],["61963.80","0.446"],["61964.00","0.028"],["61964.20","0.001"],["61964.90","0.248"],["61965.70","0.035"],["61965.80","0.051"],["61966.50","0.195"],["61966.90","0.021"],["61967.10","0.453"],["61967.30","0.138"],["61968.50","0.002"],["61968.90","0.002"],["61969.00","0.004"],["61971.10","19.600"],["61971.70","0.000"],["61972.00","1.317"],["61972.70","0.304"],["61973.30","0.002"],["61974.90","0.003"],["61975.60","0.193"],["61975.80","0.431"],["61976.40","0.001"],["61976.60","0.000"],["61978.40","1.468"],["61978.50","0.017"],["61978.70","0.001"],["61980.00","4.980"],["61981.50","4.503"],["61981.60","1.153"],["61981.70","0.000"],["61982.00","0.440"],["61982.70","0.027"],["61983.10","0.238"],["61983.20","0.003"],["61983.50","0.314"],["61983.90","2.954"],["61984.20","0.852"],["61984.30","0.001"],["61984.50","0.052"],["61984.90","0.000"],["61985.10","0.129"],["61985.90","0.002"],["61987.30","0.011"],["61987.40","0.016"],["61988.10","0.032"],["61988.20","0.018"],["61988.30","1.049"],["61988.80","0.008"],["61988.90","1.346"],["61989.30","0.029"],["61989.40","0.001"],["61989.50","0.000"],["61989.60","0.000"],["61989.90","0.099"],["61990.10","0.214"],["61990.20","0.001"],["61991.00","1.225"],["61991.10","0.076"],["61991.20","0.016"],["61991.50","0.102"],["61991.60","0.002"],["61991.70","0.019"],["61992.20","0.122"],["61992.40","0.030"],["61992.50","0.008"],["61992.80","0.000"],["61992.90","0.517"],["61993.20","0.325"],["61993.30","0.000"],["61993.40","0.000"],["61994.00","0.083"],["61994.20","0.287"],["61994.40","0.024"],["61994.60","1.862"],["61995.10","0.017"],["61996.70","0.050"],["61997.10","0.031"],["61998.20","0.001"],["61998.80","0.125"],["61999.10","0.062"],["62000.00","8.966"],["62000.50","0.006"],["62000.60","0.155"],["62000.70","0.361"],["62001.00","0.014"],["62001.30","0.007"],["62001.40","0.067"],["62001.80","0.681"],["62002.30","2.465"],["62002.70","0.226"],["62002.80","0.007"],["62003.00","0.001"],["62003.30","0.000"],["62003.50","0.062"],["62004.60","0.019"],["62004.90","0.045"],["62005.20","0.568"],["62005.30","0.060"],["62005.40","0.060"],["62005.70","0.025"],["62006.00","0.029"],["62006.10","1.102"],["62006.20","0.019"],["62006.40","0.002"],["62006.50","0.461"],["62006.70","0.000"],["62007.10","0.018"],["62007.20","0.141"],["62007.40","0.002"],["62007.50","0.104"],["62007.60","0.635"],["62007.80","1.656"],["62008.10","0.003"],["62008.20","0.003"],["62008.30","0.001"],["62008.40","0.003"],["62008.50","0.000"],["62008.60","0.004"],["62008.80","0.534"],["62008.90","1.308"],["62009.10","0.058"],["62009.20","0.324"],["62009.30","0.004"],["62009.40","0.002"],["62009.80","0.690"],["62009.90","0.027"],["62010.20","0.260"],["62010.30","0.009"],["62011.50","0.003"],["62011.60","0.011"],["62012.30","1.855"],["62012.40","0.369"],["62012.90","0.455"],["62014.10","0.002"],["62014.30","0.282"],["62014.50","0.072"],["62014.90","1.663"],["62015.00","0.046"],["62015.10","0.405"],["62015.30","0.050"],["62015.40","0.000"],["62015.50","0.009"],["62015.60","0.076"],["62015.70","0.885"],["62015.90","0.000"],["62016.00","0.007"],["62016.10","0.004"],["62016.20","0.001"],["62016.60","0.004"],["62016.70","0.005"],["62016.80","1.340"],["62016.90","0.001"],["62017.10","0.037"],["62017.20","0.130"],["62017.40","0.001"],["62017.50","0.004"],["62017.60","0.325"],["62018.50","1.147"],["62018.60","1.304"],["62018.80","1.719"],["62018.90","0.005"],["62019.10","0.083"],["62019.20","0.677"],["62019.60","0.012"],["62019.70","0.001"],["62019.80","0.012"],["62020.10","0.624"],["62020.70","0.236"],["62020.90","0.986"],["62021.00","0.008"],["62021.20","0.000"],["62021.60","0.001"],["62022.20","0.149"],["62022.30","0.001"],["62022.60","0.007"],["62022.70","0.004"],["62022.80","0.001"],["62022.90","0.000"],["62023.10","1.008"],["62023.60","0.005"],["62023.80","0.000"],["62023.90","0.002"],["62024.20","0.133"],["62024.50","0.288"],["62024.60","0.002"],["62024.90","0.020"],["62025.00","1.128"],["62025.30","0.688"],["62025.40","0.323"],["62025.70","0.018"],["62025.90","0.082"],["62026.00","0.052"],["62026.50","0.244"],["62026.60","0.002"],["62026.70","0.122"],["62027.00","0.214"],["62027.90","0.359"],["62028.00","0.199"],["62028.10","1.485"],["62028.50","0.125"],["62028.80","0.006"],["62029.10","0.753"],["62029.20","0.002"],["62029.50","0.000"],["62029.60","0.134"],["62029.90","0.325"],["62030.00","0.005"],["62030.50","0.003"],["62030.60","0.283"],["62030.80","0.766"],["62030.90","0.297"],["62031.30","0.217"],["62031.70","0.006"],["62032.00","0.061"],["62032.10","0.002"],["62032.60","0.321"],["62032.70","0.485"],["62032.90","0.020"],["62033.00","0.078"],["62033.20","0.006"],["62033.30","0.001"],["62033.50","0.221"],["62033.60","0.020"],["62033.80","0.272"],["62033.90","3.267"],["62034.00","1.149"],["62034.10","2.731"],["62034.20","0.000"],["62034.30","1.296"],["62034.40","0.002"],["62034.50","0.052"],["62034.60","0.352"],["62034.70","2.292"],["62034.80","0.002"],["62034.90","1.296"],["62035.00","0.228"],["62035.10","0.565"],["62035.40","0.306"],["62035.50","0.050"],["62035.60","0.372"],["62035.70","3.552"],["62036.00","0.000"],["62036.10","0.355"],["62036.20","0.000"],["62036.30","0.001"],["62036.50","0.001"],["62036.60","0.001"],["62036.70","0.000"],["62036.80","0.000"],["62036.90","0.000"],["62037.00","0.000"],["62037.10","0.001"],["62037.20","0.001"],["62037.30","0.198"],["62037.60","0.004"],["62037.70","0.039"],["62037.80","17.432"]],"e":"depthUpdate","ps":"BTCUSDT","pu":10998398484459,"s":"BTCUSDT","st":1,"u":10998398528761}
{"E":1783504308986,"T":1783504308985,"U":10998398529060,"a":[["62042.50","0.026"],["62042.80","0.004"],["62043.90","0.066"],["62044.00","0.755"],["62044.10","0.635"],["62044.20","0.065"],["62044.30","0.516"],["62044.40","0.791"],["62045.00","0.007"],["62045.10","0.000"],["62045.30","0.299"],["62045.50","0.879"],["62045.70","0.000"],["62045.80","0.000"],["62046.40","0.014"],["62047.70","0.624"],["62048.60","0.092"],["62048.70","1.367"],["62049.10","0.324"],["62050.70","0.013"],["62051.00","0.002"],["62051.10","0.014"],["62051.50","1.363"],["62053.20","0.432"],["62055.70","0.017"],["62055.90","0.324"],["62057.70","0.617"],["62061.00","0.005"],["62061.80","0.020"],["62062.90","0.293"],["62068.30","0.002"],["62068.80","0.105"],["62068.90","0.007"],["62072.00","0.091"],["62075.70","0.000"],["62077.30","0.004"],["62077.90","0.028"],["62079.60","0.344"],["62080.20","0.014"],["62080.90","0.021"],["62089.50","0.092"],["62089.80","0.025"],["62092.90","0.317"],["62096.10","0.025"],["62108.60","0.101"],["62109.50","0.000"],["62109.60","18.300"],["62113.80","0.000"],["62129.20","0.040"],["62131.30","2.452"],["62171.40","0.000"],["62171.50","2.333"],["62658.30","0.001"],["62749.60","2.532"],["62749.70","0.000"],["62752.00","13.304"],["62811.70","0.001"],["62814.00","8.668"],["62827.00","0.796"],["63621.00","1.316"]],"b":[["1000.00","210.542"],["11537.80","0.272"],["11634.00","0.896"],["11637.80","0.224"],["11733.80","0.000"],["11737.80","0.256"],["11833.80","0.592"],["55834.00","0.003"],["59556.20","0.007"],["61258.40","1.517"],["61417.40","0.002"],["61778.90","0.001"],["61789.60","0.123"],["61834.40","0.002"],["61836.80","0.208"],["61861.60","0.001"],["61871.50","0.040"],["61971.10","0.030"],["61972.70","0.148"],["61981.50","4.501"],["61981.60","20.725"],["61982.00","0.648"],["61983.10","0.028"],["61983.90","1.424"],["61984.00","1.530"],["61989.50","0.000"],["61989.80","0.002"],["61989.90","0.309"],["61990.70","1.086"],["61991.70","0.021"],["61994.60","1.861"],["61996.60","0.076"],["61996.80","0.002"],["61997.00","1.204"],["61997.30","0.050"],["61997.60","0.017"],["61998.40","0.017"],["62002.70","0.094"],["62004.70","0.002"],["62004.80","1.532"],["62008.10","0.003"],["62008.60","0.000"],["62009.00","0.001"],["62016.50","0.007"],["62018.90","0.137"],["62020.70","0.014"],["62024.40","1.111"],["62027.00","0.213"],["62027.20","0.057"],["62027.40","0.152"],["62028.60","0.340"],["62028.70","0.564"],["62029.20","0.001"],["62029.70","0.021"],["62032.70","0.486"],["62032.90","0.000"],["62034.00","0.858"],["62034.10","2.714"],["62034.60","0.070"],["62034.70","2.291"],["62034.80","0.001"],["62035.00","0.229"],["62035.10","0.001"],["62035.70","3.230"],["62035.80","0.000"],["62037.80","21.870"]],"e":"depthUpdate","ps":"BTCUSDT","pu":10998398528761,"s":"BTCUSDT","st":1,"u":10998398546669}
{"E":1783504309088,"T":1783504309085,"U":10998398546716,"a":[["62040.80","0.000"],["62043.90","0.821"],["62044.10","0.323"],["62044.70","0.001"],["62045.20","0.000"],["62045.30","0.000"],["62045.40","0.003"],["62045.50","0.580"],["62046.40","0.306"],["62048.60","0.090"],["62049.90","0.295"],["62051.40","0.297"],["62052.10","0.124"],["62054.70","0.006"],["62056.50","0.663"],["62057.60","0.727"],["62064.00","1.046"],["62072.00","0.403"],["62073.00","0.140"],["62074.90","0.336"],["62075.30","0.377"],["62080.40","0.105"],["62082.20","0.000"],["62082.60","0.074"],["62089.50","0.032"],["62093.80","0.146"],["62095.90","1.099"],["62097.20","0.296"],["62103.20","0.104"],["62103.30","0.000"],["62107.50","0.286"],["62107.80","0.017"],["62108.60","0.000"],["62109.50","0.000"],["62109.60","18.300"],["62394.40","0.001"],["62398.30","0.008"],["62655.00","0.020"],["62658.30","0.001"],["62658.90","2.139"]],"b":[["1000.00","210.542"],["11537.80","0.544"],["11633.80","1.520"],["11634.00","0.800"],["11637.80","0.096"],["11737.80","0.384"],["11833.80","0.464"],["55834.00","0.003"],["61417.40","0.000"],["61734.60","0.007"],["61738.50","0.136"],["61834.40","0.001"],["61861.60","0.001"],["61923.70","0.000"],["61933.00","4.121"],["61971.80","0.229"],["61994.30","0.011"],["61996.90","0.028"],["61999.40","0.147"],["62005.70","0.000"],["62010.20","0.140"],["62015.70","0.875"],["62016.50","0.127"],["62020.70","0.693"],["62022.20","0.003"],["62022.80","0.017"],["62023.50","0.707"],["62025.10","0.003"],["62025.50","0.255"],["62027.40","0.136"],["62034.60","0.065"],["62035.30","0.001"]],"e":"depthUpdate","ps":"BTCUSDT","pu":10998398546669,"s":"BTCUSDT","st":1,"u":10998398557465}
{"E":1783504309190,"T":1783504309189,"U":10998398557842,"a":[["62041.00","0.002"],["62041.10","0.006"],["62042.50","0.026"],["62042.70","0.050"],["62043.70","0.065"],["62043.80","1.317"],["62043.90","0.002"],["62044.00","0.000"],["62044.10","0.002"],["62044.30","0.000"],["62044.40","0.000"],["62045.30","0.564"],["62045.40","0.302"],["62045.50","0.315"],["62045.80","0.000"],["62046.30","0.077"],["62047.70","1.624"],["62048.50","0.001"],["62048.70","0.000"],["62048.80","0.001"],["62049.10","0.328"],["62049.80","0.168"],["62050.80","0.322"],["62051.70","0.111"],["62052.20","0.242"],["62054.20","0.036"],["62056.90","0.415"],["62061.50","0.001"],["62062.30","1.844"],["62065.80","0.002"],["62068.90","0.135"],["62072.00","0.531"],["62078.00","0.251"],["62078.90","0.105"],["62079.00","2.562"],["62079.80","0.775"],["62080.40","0.000"],["62093.60","0.000"],["62095.00","0.340"],["62096.30","0.001"],["62097.70","1.903"],["62099.90","1.204"],["62100.30","0.001"],["62101.60","0.027"],["62107.50","0.387"],["62108.10","0.101"],["62108.60","0.000"],["62119.10","0.053"],["62127.90","1.991"],["62134.20","0.125"],["62344.10","0.233"],["62658.30","0.001"]],"b":[["11537.80","0.816"],["11633.80","1.392"],["11634.00","0.768"],["11635.60","0.000"],["11637.80","0.000"],["11737.80","0.528"],["11833.80","0.320"],["55834.00","0.003"],["59556.20","0.010"],["61212.20","0.000"],["61417.40","0.002"],["61512.50","0.000"],["61723.80","0.894"],["61834.40","0.001"],["61839.30","0.207"],["61861.60","0.001"],["61871.60","0.028"],["61886.10","0.003"],["61981.60","20.727"],["61994.60","1.859"],["62006.30","0.811"],["62011.70","2.508"],["62017.80","0.031"],["62018.40","2.144"],["62020.80","0.002"],["62022.80","0.001"],["62025.00","1.130"],["62029.10","1.120"],["62029.30","0.003"],["62031.50","0.077"],["62035.40","0.282"],["62035.70","2.696"],["62036.30","0.025"],["62036.90","0.002"],["62037.80","21.869"]],"e":"depthUpdate","ps":"BTCUSDT","pu":10998398557465,"s":"BTCUSDT","st":1,"u":10998398572393}
{"E":1783504309292,"T":1783504309289,"U":10998398572452,"a":[["62040.60","0.002"],["62041.20","0.003"],["62041.80","0.004"],["62042.70","0.001"],["62043.40","0.068"],["62043.60","0.667"],["62043.70","0.656"],["62043.80","0.753"],["62045.20","0.150"],["62045.30","0.621"],["62045.50","0.404"],["62045.80","0.299"],["62046.30","0.077"],["62046.40","0.306"],["62047.20","0.051"],["62048.80","0.000"],["62049.40","0.001"],["62049.70","0.234"],["62050.00","0.001"],["62051.90","0.247"],["62052.20","0.001"],["62053.10","0.002"],["62053.80","0.003"],["62067.80","0.003"],["62068.90","0.135"],["62072.00","0.403"],["62075.10","0.320"],["62078.90","0.105"],["62079.00","2.457"],["62079.80","0.686"],["62093.60","0.000"],["62105.40","0.118"],["62106.00","0.129"],["62106.20","0.101"],["62107.50","0.286"],["62108.10","0.000"],["62114.10","0.004"],["62153.60","1.600"],["62176.80","1.477"],["62195.50","2.863"],["62220.20","0.518"],["62241.90","0.603"],["62271.10","0.299"],["62289.10","0.358"],["62307.00","1.042"],["62329.90","0.339"],["62349.90","1.348"],["62372.00","0.290"],["62393.90","0.254"],["62425.70","0.194"],["62658.30","0.001"],["63278.60","0.003"]],"b":[["1000.00","210.542"],["11537.80","1.088"],["11633.80","1.248"],["11634.00","0.640"],["11737.80","0.656"],["11833.80","0.192"],["55834.00","0.003"],["58779.40","0.051"],["58932.20","0.010"],["58932.30","0.049"],["59556.20","0.007"],["60000.00","124.402"],["61417.40","0.000"],["61444.20","7.495"],["61614.40","0.393"],["61640.10","0.151"],["61657.70","1.853"],["61677.10","0.553"],["61699.10","0.683"],["61720.80","0.340"],["61727.60","0.008"],["61744.20","0.144"],["61762.50","0.478"],["61782.10","0.331"],["61810.80","0.309"],["61827.90","1.235"],["61834.40","0.002"],["61848.10","2.311"],["61875.90","0.799"],["61894.60","0.798"],["61922.10","1.219"],["61940.90","1.131"],["61951.40","0.003"],["61961.00","1.895"],["61982.00","0.208"],["61982.10","4.065"],["61982.20","0.571"],["61985.10","0.001"],["61995.10","0.001"],["62000.60","0.155"],["62009.00","1.134"],["62018.90","0.135"],["62019.20","0.805"],["62022.70","0.006"],["62029.20","0.293"],["62030.90","0.005"],["62034.00","0.853"],["62035.40","0.000"],["62037.80","21.874"]],"e":"depthUpdate","ps":"BTCUSDT","pu":10998398572393,"s":"BTCUSDT","st":1,"u":10998398584230}
{"E":1783504309394,"T":1783504309392,"U":10998398584647,"a":[["62043.50","0.000"],["62043.60","0.195"],["62043.70","1.217"],["62043.80","0.089"],["62044.10","0.130"],["62044.40","0.000"],["62045.00","0.306"],["62045.10","0.564"],["62045.70","0.000"],["62045.80","0.000"],["62046.30","0.077"],["62049.90","0.318"],["62051.70","0.002"],["62060.60","0.067"],["62078.50","0.188"],["62078.60","0.106"],["62078.90","0.000"],["62081.80","0.108"],["62093.60","0.000"],["62100.40","0.247"],["62100.60","0.090"],["62104.40","0.102"],["62105.10","0.001"],["62105.40","0.017"],["62106.00","0.028"],["62106.20","0.000"],["62292.80","0.002"],["62311.70","0.004"],["62529.00","0.760"],["62658.30","0.001"],["63278.60","0.006"]],"b":[["1000.00","210.542"],["11537.80","1.360"],["11633.80","1.120"],["11634.00","0.496"],["11737.80","0.800"],["11833.80","0.048"],["49630.00","0.172"],["55834.00","0.003"],["59556.20","0.010"],["61241.10","0.900"],["61417.40","0.000"],["61470.70","1.141"],["61834.40","0.001"],["61920.60","0.000"],["61939.40","0.004"],["61985.10","0.129"],["61990.30","0.062"],["61995.10","0.003"],["62000.60","0.027"],["62015.00","0.006"],["62017.80","0.015"],["62020.90","0.966"],["62023.90","0.562"],["62026.50","0.284"],["62027.20","0.077"],["62030.30","0.174"],["62034.00","0.851"],["62035.00","0.245"],["62035.60","0.201"],["62037.80","21.877"]],"e":"depthUpdate","ps":"BTCUSDT","pu":10998398584230,"s":"BTCUSDT","st":1,"u":10998398596787}
{"E":1783504309496,"T":1783504309493,"U":10998398597009,"a":[["62037.90","1.874"],["62043.60","0.090"],["62043.70","1.112"],["62044.10","0.002"],["62044.40","0.322"],["62045.30","0.000"],["62045.40","0.003"],["62045.50","0.105"],["62048.60","0.000"],["62048.80","0.083"],["62048.90","0.821"],["62049.20","0.102"],["62049.30","0.067"],["62049.50","0.882"],["62049.60","0.919"],["62049.70","0.054"],["62049.80","0.216"],["62049.90","0.026"],["62050.10","0.103"],["62050.20","0.003"],["62050.30","0.013"],["62050.40","0.563"],["62050.50","0.001"],["62065.30","0.120"],["62068.60","0.003"],["62068.90","0.007"],["62070.50","0.083"],["62071.20","0.059"],["62071.40","0.412"],["62071.50","0.128"],["62072.00","0.313"],["62072.40","0.028"],["62077.00","0.151"],["62078.00","0.251"],["62078.10","2.874"],["62078.20","1.470"],["62078.90","0.105"],["62079.00","2.562"],["62086.30","0.001"],["62086.70","0.023"],["62087.00","0.274"],["62087.30","0.000"],["62087.60","0.000"],["62092.20","0.112"],["62092.80","0.075"],["62099.30","0.000"],["62099.80","0.606"],["62099.90","1.096"],["62100.40","0.001"],["62100.50","0.691"],["62100.60","0.000"],["62104.60","0.350"],["62107.40","0.788"],["62107.50","0.387"],["62107.80","0.118"],["62108.00","0.000"],["62108.30","0.156"],["62108.70","0.000"],["62109.00","0.000"],["62109.30","0.000"],["62169.20","0.960"],["62176.00","0.571"],["62658.30","0.001"],["62777.10","16.269"],["63274.50","0.027"],["63958.40","0.001"]],"b":[["11537.80","1.632"],["11633.80","0.976"],["11634.00","0.368"],["11637.80","0.080"],["11737.80","0.768"],["11833.80","0.000"],["49630.00","0.170"],["55834.00","0.003"],["61196.30","3.572"],["61417.40","0.000"],["61444.80","2.019"],["61723.80","0.884"],["61727.60","0.018"],["61834.40","0.002"],["61903.40","0.000"],["61907.20","1.411"],["61962.00","0.077"],["61962.30","0.000"],["61962.60","0.000"],["61962.90","0.001"],["61963.20","0.000"],["61983.60","0.670"],["61983.90","1.392"],["61984.20","0.820"],["61984.50","0.020"],["61984.80","0.263"],["61985.60","0.035"],["61986.20","0.034"],["61998.50","0.691"],["61998.60","0.734"],["61998.70","1.901"],["61998.80","0.005"],["61999.10","0.002"],["61999.30","0.001"],["61999.80","0.097"],["62005.30","0.000"],["62005.40","0.000"],["62017.00","0.683"],["62018.70","1.364"],["62019.20","0.717"],["62020.50","0.581"],["62021.00","0.000"],["62023.10","1.016"],["62024.10","0.413"],["62025.30","0.567"],["62025.90","0.098"],["62026.40","0.452"],["62026.50","0.124"],["62026.70","0.002"],["62027.00","0.001"],["62027.10","0.815"],["62027.30","0.002"],["62027.60","0.000"],["62027.90","0.327"],["62028.10","1.545"],["62028.20","0.000"],["62028.30","0.214"],["62028.60","0.400"],["62028.70","0.624"],["62028.90","0.033"],["62029.20","0.353"],["62029.30","0.003"],["62029.50","0.032"],["62030.70","1.364"],["62032.00","0.062"],["62032.50","0.002"],["62033.80","0.270"],["62033.90","3.265"],["62035.00","0.229"],["62035.70","1.806"],["62035.80","1.360"],["62036.50","0.025"],["62037.60","0.006"],["62037.70","0.041"],["62037.80","21.878"]],"e":"depthUpdate","ps":"BTCUSDT","pu":10998398596787,"s":"BTCUSDT","st":1,"u":10998398606374}
{"E":1783504309598,"T":1783504309597,"U":10998398606605,"a":[["62037.90","1.921"],["62042.80","0.053"],["62043.60","0.195"],["62043.70","0.843"],["62044.90","0.300"],["62045.20","0.000"],["62045.50","0.404"],["62045.80","0.000"],["62046.30","0.077"],["62046.40","0.306"],["62048.50","0.091"],["62049.00","1.363"],["62049.20","0.169"],["62049.70","0.222"],["62049.80","0.274"],["62050.30","0.115"],["62056.20","0.898"],["62060.10","0.014"],["62060.80","0.083"],["62062.50","0.749"],["62064.00","0.346"],["62067.00","0.266"],["62070.20","1.455"],["62070.80","1.544"],["62071.50","0.186"],["62073.20","0.322"],["62077.50","0.649"],["62078.10","2.976"],["62078.90","0.000"],["62079.00","2.457"],["62079.70","0.001"],["62086.90","0.000"],["62090.80","0.014"],["62091.80","0.429"],["62092.50","0.942"],["62093.10","0.211"],["62107.40","0.687"],["62107.50","0.286"],["62107.80","0.017"],["62108.10","0.000"],["62122.20","0.000"],["62126.10","0.171"],["62176.00","0.000"],["62534.20","0.319"],["62658.30","0.001"],["62869.50","0.009"],["62930.00","0.177"]],"b":[["1000.00","210.542"],["11537.80","1.904"],["11633.80","0.848"],["11634.00","0.224"],["11637.80","0.224"],["11737.80","0.624"],["55834.00","0.003"],["58932.20","0.007"],["58932.30","0.052"],["59556.20","0.007"],["60793.20","0.022"],["61069.40","0.000"],["61417.40","0.000"],["61772.80","0.000"],["61790.60","0.000"],["61805.50","1.121"],["61834.40","0.001"],["61907.20","0.783"],["61978.50","0.003"],["61982.80","0.015"],["61985.30","0.034"],["61985.90","0.034"],["61986.50","1.395"],["61999.80","0.050"],["62010.80","0.000"],["62012.20","0.052"],["62014.70","0.024"],["62014.80","1.363"],["62015.00","0.046"],["62017.00","1.005"],["62017.70","0.181"],["62019.20","0.677"],["62019.40","0.027"],["62023.00","0.252"],["62023.20","0.161"],["62025.90","0.082"],["62028.10","1.605"],["62028.60","0.432"],["62028.70","0.744"],["62029.30","0.036"],["62029.40","0.092"],["62029.80","0.033"],["62037.80","21.878"]],"e":"depthUpdate","ps":"BTCUSDT","pu":10998398606374,"s":"BTCUSDT","st":1,"u":10998398616484}
{"E":1783504309700,"T":1783504309697,"U":10998398617091,"a":[["62043.60","0.756"],["62044.90","0.001"],["62045.00","0.007"],["62045.30","0.150"],["62045.40","0.302"],["62045.80","0.299"],["62046.30","0.376"],["62049.10","0.430"],["62049.80","0.382"],["62050.20","0.099"],["62050.30","0.259"],["62050.40","0.743"],["62067.20","0.003"],["62076.90","0.106"],["62077.60","0.108"],["62078.10","3.216"],["62078.20","1.560"],["62078.30","0.695"],["62103.20","0.003"],["62105.40","0.017"],["62176.00","0.634"],["62658.30","0.001"],["63155.60","0.000"],["63278.60","0.009"],["63941.40","0.851"]],"b":[["1000.00","210.542"],["11537.80","2.176"],["11633.80","0.704"],["11634.00","0.096"],["11637.80","0.352"],["11737.80","0.496"],["55834.00","0.003"],["59556.20","0.010"],["61417.40","0.000"],["61834.40","0.002"],["61907.20","1.411"],["62015.00","0.006"],["62019.40","0.011"],["62023.90","0.564"],["62025.80","0.343"],["62026.50","0.164"],["62028.00","0.259"],["62028.10","1.725"],["62028.20","0.060"],["62028.60","0.492"],["62029.30","0.095"],["62030.80","1.082"],["62037.80","21.879"]],"e":"depthUpdate","ps":"BTCUSDT","pu":10998398616484,"s":"BTCUSDT","st":1,"u":10998398627258}
{"E":1783504309802,"T":1783504309801,"U":10998398627693,"a":[["62037.90","2.339"],["62039.90","0.004"],["62042.40","0.056"],["62043.10","0.053"],["62043.40","0.629"],["62043.50","0.756"],["62043.60","0.196"],["62043.80","0.000"],["62044.30","0.002"],["62044.40","0.322"],["62045.00","0.306"],["62045.80","0.000"],["62046.30","0.077"],["62048.90","0.942"],["62049.70","0.312"],["62051.50","1.363"],["62051.90","0.006"],["62052.00","0.243"],["62060.60","0.004"],["62061.10","0.413"],["62063.30","0.000"],["62077.50","0.739"],["62078.60","0.106"],["62093.60","0.000"],["62104.10","1.594"],["62104.20","0.758"],["62104.40","0.001"],["62104.60","0.249"],["62658.30","0.001"],["62736.40","0.000"],["62808.60","3.154"],["62812.80","0.000"]],"b":[["11537.80","2.448"],["11633.80","0.528"],["11634.00","0.000"],["11637.80","0.496"],["11737.80","0.352"],["49630.20","0.000"],["55834.00","0.003"],["58943.80","0.000"],["59556.20","0.007"],["60793.20","0.019"],["61289.60","3.541"],["61417.40","0.000"],["61600.00","50.188"],["61723.80","0.883"],["61727.60","0.018"],["61765.00","0.000"],["61768.20","0.008"],["61834.40","0.001"],["61940.90","1.031"],["61963.80","0.010"],["61963.90","0.032"],["61964.50","0.043"],["61964.80","1.378"],["62002.70","0.226"],["62015.50","0.025"],["62023.20","0.000"],["62024.10","0.121"],["62025.50","0.123"],["62025.80","0.327"],["62028.80","0.066"],["62028.90","0.325"],["62029.20","0.061"],["62029.30","0.096"],["62029.40","0.011"],["62037.80","21.878"]],"e":"depthUpdate","ps":"BTCUSDT","pu":10998398627258,"s":"BTCUSDT","st":1,"u":10998398641465}
{"E":1783504309904,"T":1783504309903,"U":10998398641623,"a":[["62037.90","4.736"],["62042.40","0.060"],["62043.30","0.068"],["62043.40","0.004"],["62043.50","0.331"],["62043.60","0.571"],["62043.70","0.754"],["62044.00","0.000"],["62044.10","1.002"],["62044.40","0.000"],["62044.50","0.869"],["62045.00","0.007"],["62045.10","0.000"],["62045.30","0.000"],["62045.40","0.153"],["62045.50","0.863"],["62046.40","0.306"],["62046.60","1.049"],["62047.50","0.285"],["62047.70","0.624"],["62048.80","0.083"],["62049.40","0.000"],["62050.10","0.187"],["62050.70","0.013"],["62051.10","0.255"],["62052.00","0.002"],["62057.90","0.007"],["62058.90","0.584"],["62059.90","0.402"],["62060.80","0.002"],["62061.80","0.000"],["62063.40","1.745"],["62065.30","0.000"],["62066.80","0.020"],["62067.00","0.105"],["62077.90","0.112"],["62078.00","0.356"],["62078.10","3.321"],["62078.20","1.649"],["62078.60","0.001"],["62093.60","0.000"],["62095.00","0.301"],["62095.30","0.039"],["62097.20","0.133"],["62103.80","0.424"],["62104.00","0.077"],["62104.10","1.493"],["62104.20","0.657"],["62194.20","1.378"],["62348.10","0.255"],["62643.30","0.000"],["62658.30","0.001"],["62712.20","0.000"],["62781.20","0.001"],["62850.10","0.794"],["62919.00","0.287"],["62987.90","0.000"],["63056.80","0.000"],["63125.70","0.001"],["63194.60","0.000"],["63263.60","0.001"]],"b":[["1000.00","210.542"],["11537.80","2.496"],["11633.80","0.368"],["11637.80","0.624"],["11737.80","0.224"],["11937.80","0.112"],["55834.00","0.003"],["59556.20","0.010"],["60782.60","0.000"],["60851.60","0.002"],["60920.50","0.007"],["60989.40","0.025"],["61058.30","0.000"],["61078.50","0.295"],["61127.20","0.005"],["61196.10","0.007"],["61265.00","0.008"],["61334.00","0.114"],["61402.90","0.000"],["61417.40","0.000"],["61834.40","0.002"],["61963.60","6.334"],["61964.20","0.033"],["61966.50","0.039"],["61968.60","0.016"],["61971.70","0.016"],["61977.90","0.019"],["61993.40","0.016"],["61999.60","0.016"],["62000.20","0.366"],["62000.50","0.066"],["62001.40","0.127"],["62006.90","0.709"],["62007.00","0.335"],["62008.90","1.324"],["62011.30","0.002"],["62011.70","2.510"],["62015.50","0.009"],["62017.00","0.683"],["62018.20","0.016"],["62018.40","2.154"],["62018.50","1.163"],["62018.90","0.003"],["62019.30","0.643"],["62019.60","0.002"],["62020.30","0.008"],["62020.50","0.000"],["62020.90","0.986"],["62022.10","0.010"],["62022.70","0.127"],["62023.10","1.008"],["62024.10","0.000"],["62027.20","0.057"],["62028.30","0.274"],["62033.50","0.244"],["62033.70","0.000"],["62033.80","0.253"],["62034.70","2.132"],["62035.20","0.005"],["62036.30","0.001"],["62036.50","0.001"],["62037.60","0.002"],["62037.80","21.815"]],"e":"depthUpdate","ps":"BTCUSDT","pu":10998398641465,"s":"BTCUSDT","st":1,"u":10998398652053}
{"E":1783504310006,"T":1783504310005,"U":10998398652124,"a":[["62037.90","10.706"],["62038.00","0.007"],["62038.70","0.056"],["62038.80","0.050"],["62038.90","0.001"],["62039.00","0.824"],["62039.40","0.044"],["62040.10","0.824"],["62040.40","0.001"],["62040.70","0.324"],["62040.80","0.120"],["62041.20","0.826"],["62041.30","0.171"],["62041.70","0.001"],["62042.30","0.830"],["62042.40","0.141"],["62042.60","0.004"],["62042.80","1.415"],["62042.90","0.601"],["62043.20","0.001"],["62043.30","0.152"],["62043.40","0.948"],["62043.50","0.694"],["62043.60","0.155"],["62044.00","1.326"],["62044.10","0.129"],["62044.30","0.284"],["62044.40","0.004"],["62044.50","0.868"],["62045.00","0.376"],["62045.10","0.000"],["62045.30","1.362"],["62045.40","0.023"],["62045.50","0.000"],["62045.80","1.354"],["62046.10","0.002"],["62046.40","0.304"],["62046.50","1.135"],["62046.60","1.051"],["62047.10","0.000"],["62047.40","0.160"],["62047.50","0.289"],["62047.60","0.017"],["62048.00","0.005"],["62048.10","0.001"],["62048.20","0.322"],["62048.40","0.005"],["62048.80","1.293"],["62049.00","1.363"],["62049.40","0.564"],["62049.50","1.757"],["62049.70","0.261"],["62050.50","0.005"],["62050.80","0.000"],["62051.00","0.825"],["62051.10","0.014"],["62051.30","0.767"],["62051.40","1.018"],["62051.70","0.000"],["62051.90","0.002"],["62052.10","0.121"],["62052.60","0.002"],["62054.00","0.011"],["62054.20","0.001"],["62054.40","0.828"],["62054.50","0.003"],["62054.90","1.095"],["62055.00","0.003"],["62055.10","1.126"],["62055.50","0.000"],["62055.80","0.736"],["62055.90","0.002"],["62056.50","1.243"],["62057.60","0.002"],["62057.80","0.002"],["62058.60","0.407"],["62058.90","0.004"],["62059.80","0.014"],["62060.50","0.120"],["62061.40","0.000"],["62062.20","0.225"],["62062.80","1.011"],["62063.40","1.615"],["62063.50","0.692"],["62063.80","0.934"],["62064.80","1.138"],["62065.20","0.000"],["62066.00","0.004"],["62066.50","0.049"],["62067.70","0.683"],["62067.90","0.036"],["62068.60","0.013"],["62068.80","0.015"],["62069.00","0.109"],["62069.50","0.002"],["62070.50","0.119"],["62071.10","0.012"],["62071.30","0.602"],["62071.70","0.001"],["62074.20","0.000"],["62074.70","0.002"],["62074.80","0.166"],["62074.90","0.173"],["62075.00","5.578"],["62075.10","0.320"],["62075.30","0.360"],["62075.60","1.362"],["62077.20","1.438"],["62077.40","0.250"],["62077.60","0.116"],["62077.70","0.139"],["62077.80","1.441"],["62078.00","0.162"],["62078.10","3.127"],["62078.20","1.560"],["62078.80","0.017"],["62079.40","0.002"],["62080.00","1.057"],["62080.60","0.005"],["62081.70","0.015"],["62082.60","0.014"],["62083.20","0.002"],["62083.90","0.011"],["62084.40","0.754"],["62085.70","0.035"],["62086.50","0.020"],["62087.80","1.354"],["62088.10","0.000"],["62088.20","0.035"],["62088.80","0.001"],["62089.40","0.090"],["62090.50","0.014"],["62090.90","0.028"],["62091.10","0.022"],["62092.20","0.109"],["62093.60","0.000"],["62093.70","0.019"],["62094.60","0.014"],["62096.10","0.000"],["62096.50","0.048"],["62097.20","0.001"],["62097.50","0.096"],["62101.60","0.012"],["62102.70","0.102"],["62102.80","1.742"],["62103.60","0.000"],["62103.70","0.292"],["62103.80","0.323"],["62104.00","0.077"],["62108.20","1.941"],["62109.60","0.016"],["62115.80","18.566"],["62137.80","0.000"],["62160.00","0.546"],["62240.00","0.607"],["62320.00","0.543"],["62400.00","14.418"],["62658.30","0.007"],["63274.50","0.024"],["67559.00","0.614"]],"b":[["1000.00","210.542"],["11537.80","2.512"],["11633.80","0.224"],["11637.80","0.752"],["11737.80","0.096"],["11937.80","0.240"],["49630.00","0.170"],["55834.00","0.003"],["61153.20","0.285"],["61417.40","0.012"],["61680.00","1.099"],["61727.60","0.019"],["61760.00","0.591"],["61834.40","0.001"],["61840.00","0.431"],["61920.00","0.504"],["61921.90","4.707"],["61931.50","0.125"],["61933.00","0.091"],["61938.00","0.137"],["61946.40","0.166"],["61946.70","0.015"],["61947.10","0.004"],["61954.60","0.029"],["61960.20","0.052"],["61961.00","1.885"],["61963.00","0.031"],["61966.50","0.117"],["61966.90","0.021"],["61971.50","0.213"],["61971.60","0.172"],["61980.30","0.004"],["61981.60","1.155"],["61983.20","0.213"],["61984.10","0.162"],["61985.00","0.708"],["61985.10","0.001"],["61987.30","0.009"],["61987.40","0.000"],["61987.50","0.177"],["61987.60","0.017"],["61987.90","0.153"],["61989.90","0.099"],["61991.70","0.019"],["61992.30","0.024"],["61992.40","0.027"],["61992.50","0.000"],["61993.20","0.326"],["61994.20","0.289"],["61995.00","0.661"],["61996.60","0.051"],["61997.90","3.793"],["61999.60","0.000"],["62000.00","8.948"],["62000.10","1.816"],["62000.20","1.401"],["62000.30","0.060"],["62000.60","0.024"],["62000.90","0.228"],["62002.10","4.123"],["62002.30","1.298"],["62002.60","0.049"],["62002.70","1.456"],["62003.10","0.006"],["62003.50","0.059"],["62003.70","0.007"],["62004.50","0.249"],["62005.40","0.003"],["62006.10","1.110"],["62006.30","0.016"],["62006.40","0.294"],["62006.50","0.453"],["62006.80","2.189"],["62007.40","0.010"],["62007.60","0.001"],["62007.80","0.002"],["62008.10","0.001"],["62008.30","0.001"],["62008.90","0.029"],["62009.00","1.183"],["62009.10","0.050"],["62009.30","0.044"],["62009.40","0.000"],["62010.20","0.010"],["62010.30","0.001"],["62010.40","0.003"],["62011.60","0.008"],["62011.90","0.002"],["62012.10","0.703"],["62012.20","0.050"],["62012.40","1.769"],["62012.60","1.331"],["62012.90","2.166"],["62013.00","0.112"],["62013.10","0.021"],["62013.20","0.001"],["62013.50","0.328"],["62013.90","0.296"],["62014.00","0.097"],["62014.30","0.282"],["62014.60","0.290"],["62014.80","0.001"],["62014.90","1.834"],["62015.00","0.006"],["62015.20","0.001"],["62015.70","0.000"],["62015.80","0.000"],["62016.20","0.001"],["62016.90","0.201"],["62017.10","0.002"],["62017.70","0.122"],["62017.90","0.583"],["62018.00","0.259"],["62018.40","2.144"],["62018.50","1.161"],["62018.60","0.009"],["62018.70","0.002"],["62018.80","1.427"],["62018.90","0.295"],["62019.30","0.062"],["62019.50","0.221"],["62019.70","1.363"],["62019.80","0.009"],["62019.90","0.405"],["62020.10","0.003"],["62020.80","0.010"],["62020.90","0.426"],["62021.00","0.931"],["62021.70","0.345"],["62022.00","0.002"],["62022.10","0.002"],["62022.30","0.001"],["62022.40","0.004"],["62022.50","0.034"],["62022.70","0.006"],["62022.80","0.021"],["62023.10","0.001"],["62023.20","0.338"],["62023.50","0.007"],["62023.90","0.004"],["62024.20","0.129"],["62024.30","0.010"],["62024.90","0.000"],["62025.20","0.003"],["62025.30","0.003"],["62025.40","0.001"],["62025.50","0.003"],["62025.90","0.002"],["62026.20","0.006"],["62026.40","0.000"],["62026.70","0.006"],["62026.90","0.002"],["62027.10","0.001"],["62027.40","0.133"],["62027.90","0.005"],["62028.00","0.064"],["62028.10","0.363"],["62028.30","0.121"],["62028.40","0.001"],["62028.50","0.123"],["62028.60","0.154"],["62028.70","0.180"],["62028.90","0.032"],["62029.10","0.049"],["62029.70","0.001"],["62029.90","0.349"],["62030.30","0.003"],["62030.70","0.000"],["62030.80","0.050"],["62030.90","0.001"],["62031.20","0.002"],["62031.40","0.049"],["62031.60","0.121"],["62031.70","0.004"],["62032.00","0.003"],["62032.10","0.001"],["62032.50","0.000"],["62032.70","0.484"],["62032.80","0.002"],["62033.50","0.221"],["62033.60","0.016"],["62033.80","0.124"],["62033.90","0.071"],["62034.00","0.525"],["62034.10","0.006"],["62034.30","0.001"],["62034.40","0.000"],["62034.50","0.002"],["62034.60","0.001"],["62034.70","0.000"],["62034.90","0.001"],["62035.00","0.004"],["62035.30","0.000"],["62035.50","0.001"],["62035.60","0.012"],["62035.70","0.006"],["62035.80","0.000"],["62035.90","0.000"],["62036.10","0.000"],["62037.30","0.000"],["62037.60","0.000"],["62037.70","0.005"],["62037.80","3.453"]],"e":"depthUpdate","ps":"BTCUSDT","pu":10998398652053,"s":"BTCUSDT","st":1,"u":10998398671055}
{"E":1783504310108,"T":1783504310107,"U":10998398671232,"a":[["62034.10","14.599"],["62034.20","2.197"],["62034.30","0.002"],["62034.40","0.000"],["62034.60","0.000"],["62034.70","0.001"],["62035.00","0.001"],["62035.10","0.000"],["62035.20","0.000"],["62035.30","0.001"],["62035.40","0.000"],["62035.50","0.001"],["62035.60","0.003"],["62035.70","0.312"],["62035.80","0.000"],["62036.20","0.002"],["62036.30","0.002"],["62036.40","0.001"],["62036.50","0.324"],["62036.60","0.452"],["62036.70","0.132"],["62036.80","0.001"],["62036.90","1.805"],["62037.00","1.626"],["62037.10","0.003"],["62037.20","0.001"],["62037.30","0.000"],["62037.40","0.001"],["62037.70","0.083"],["62037.80","3.483"],["62037.90","2.229"],["62038.00","0.004"],["62038.20","0.050"],["62038.30","0.000"],["62038.50","0.001"],["62038.60","0.000"],["62038.70","0.052"],["62038.80","0.953"],["62038.90","0.001"],["62039.00","0.001"],["62039.20","0.147"],["62039.40","1.877"],["62039.50","0.274"],["62039.70","0.007"],["62039.80","0.004"],["62039.90","0.063"],["62040.00","1.768"],["62040.10","0.323"],["62040.20","0.342"],["62040.30","1.327"],["62040.40","0.002"],["62040.50","0.002"],["62040.60","0.002"],["62041.00","0.553"],["62041.10","0.300"],["62041.20","0.004"],["62041.50","0.006"],["62041.60","0.002"],["62042.20","0.160"],["62042.30","0.007"],["62042.40","0.006"],["62042.50","0.028"],["62042.70","0.001"],["62042.80","1.536"],["62042.90","0.454"],["62043.10","0.051"],["62043.20","0.001"],["62043.30","0.084"],["62043.40","0.225"],["62043.50","0.000"],["62043.60","0.001"],["62043.70","0.754"],["62044.00","0.002"],["62044.10","0.001"],["62044.20","0.167"],["62044.30","0.284"],["62044.40","0.126"],["62044.50","0.001"],["62044.80","0.326"],["62044.90","0.065"],["62045.00","0.326"],["62045.20","0.564"],["62045.60","1.128"],["62045.70","0.153"],["62045.90","0.768"],["62046.50","0.005"],["62046.60","0.737"],["62047.10","0.004"],["62047.40","0.502"],["62047.50","0.409"],["62047.60","0.001"],["62047.70","0.002"],["62047.80","0.001"],["62047.90","0.003"],["62048.00","0.001"],["62048.20","0.000"],["62048.40","0.003"],["62048.80","0.083"],["62048.90","0.186"],["62049.30","0.003"],["62049.40","0.000"],["62049.50","0.937"],["62049.60","0.925"],["62049.70","0.261"],["62049.90","0.083"],["62050.20","0.098"],["62050.30","0.839"],["62050.50","0.001"],["62051.00","0.122"],["62051.30","0.050"],["62051.40","0.293"],["62051.50","1.363"],["62052.00","0.002"],["62052.10","0.001"],["62052.40","0.168"],["62052.50","0.453"],["62052.70","0.014"],["62052.80","0.666"],["62052.90","0.002"],["62053.30","0.001"],["62053.40","0.318"],["62053.50","0.026"],["62053.60","0.325"],["62053.90","0.059"],["62054.40","0.005"],["62054.90","0.110"],["62055.10","1.126"],["62055.40","0.130"],["62055.60","0.061"],["62055.70","0.017"],["62055.80","0.004"],["62055.90","0.004"],["62056.10","0.080"],["62056.20","0.909"],["62056.40","1.362"],["62056.50","0.000"],["62056.60","0.282"],["62057.40","0.166"],["62057.90","0.007"],["62058.00","0.070"],["62058.10","0.884"],["62058.40","0.029"],["62058.90","0.003"],["62059.30","0.543"],["62059.50","1.342"],["62059.60","0.140"],["62059.80","0.004"],["62059.90","0.000"],["62060.20","0.278"],["62060.30","0.002"],["62060.40","0.051"],["62060.50","0.000"],["62060.70","0.076"],["62060.80","0.050"],["62060.90","0.098"],["62061.10","0.405"],["62061.20","0.034"],["62061.40","0.049"],["62061.60","0.009"],["62061.90","0.173"],["62062.00","0.013"],["62062.20","0.195"],["62062.30","1.764"],["62062.40","3.626"],["62062.50","0.700"],["62062.70","0.004"],["62062.80","1.715"],["62063.00","0.012"],["62063.20","0.021"],["62063.50","0.684"],["62063.60","0.021"],["62063.70","0.055"],["62063.80","0.010"],["62064.00","0.004"],["62064.20","0.002"],["62064.30","0.001"],["62064.40","0.003"],["62064.60","0.070"],["62064.80","1.130"],["62065.90","0.003"],["62066.10","0.002"],["62066.30","0.015"],["62066.40","1.446"],["62066.50","0.001"],["62067.60","0.291"],["62067.90","0.001"],["62068.20","0.180"],["62068.60","0.003"],["62068.70","0.001"],["62068.80","0.005"],["62069.00","0.049"],["62069.10","0.004"],["62069.30","0.000"],["62069.50","0.000"],["62070.00","0.309"],["62070.10","0.002"],["62070.50","0.083"],["62070.70","0.008"],["62071.10","0.002"],["62071.30","0.485"],["62071.60","0.010"],["62072.00","0.001"],["62072.70","0.047"],["62072.80","1.362"],["62073.00","0.051"],["62073.20","0.089"],["62073.40","0.089"],["62073.50","0.272"],["62073.60","2.677"],["62073.80","0.194"],["62074.10","0.037"],["62074.50","0.000"],["62074.70","0.002"],["62074.80","0.003"],["62074.90","0.494"],["62075.00","5.578"],["62075.10","0.320"],["62075.20","0.002"],["62075.30","0.385"],["62075.40","9.355"],["62075.70","0.002"],["62077.00","0.102"],["62077.20","1.435"],["62077.30","0.000"],["62077.40","0.056"],["62077.70","0.050"],["62077.80","1.438"],["62079.00","0.000"],["62079.10","0.000"],["62079.40","0.000"],["62079.60","0.343"],["62080.00","1.075"],["62080.20","0.013"],["62080.40","0.104"],["62080.70","0.299"],["62081.70","0.001"],["62081.90","0.019"],["62082.00","0.005"],["62082.20","0.000"],["62083.50","0.153"],["62084.00","0.026"],["62084.10","0.000"],["62084.50","0.819"],["62084.70","0.472"],["62084.80","1.365"],["62084.90","0.211"],["62085.70","0.036"],["62086.50","0.017"],["62086.80","0.006"],["62087.20","0.010"],["62088.20","0.010"],["62089.30","0.015"],["62089.40","0.000"],["62089.90","0.678"],["62090.20","0.004"],["62090.50","0.011"],["62090.90","0.023"],["62091.20","0.000"],["62091.30","0.462"],["62092.00","0.001"],["62092.20","0.109"],["62092.90","0.317"],["62093.70","0.004"],["62093.80","0.000"],["62094.60","0.003"],["62095.80","0.423"],["62096.30","0.000"],["62097.10","0.007"],["62097.40","0.195"],["62097.70","2.004"],["62098.20","0.101"],["62099.00","0.127"],["62099.40","0.105"],["62099.50","1.463"],["62099.60","3.480"],["62099.70","0.826"],["62100.00","0.639"],["62100.10","0.001"],["62100.40","0.001"],["62102.40","0.001"],["62102.70","0.001"],["62102.80","1.641"],["62103.80","0.000"],["62109.50","18.311"],["62110.80","5.408"],["62113.80","0.000"],["62114.80","0.000"],["62115.80","0.282"],["62116.80","0.041"],["62118.20","4.836"],["62120.00","0.077"],["62124.80","0.001"],["62125.60","0.050"],["62125.70","0.000"],["62126.80","0.000"],["62127.20","0.312"],["62127.30","0.050"],["62127.40","0.000"],["62127.90","1.999"],["62131.00","0.364"],["62131.30","2.444"],["62136.30","0.124"],["62136.50","0.670"],["62142.80","0.010"],["62144.50","0.700"],["62160.00","0.564"],["62163.80","0.027"],["62182.50","0.004"],["62183.60","0.024"],["62240.00","0.625"],["62294.60","0.383"],["62320.00","0.561"],["62354.60","0.143"],["62400.00","14.436"],["62447.70","0.018"],["62450.40","0.000"],["62453.60","0.000"],["62654.40","1.910"],["62654.50","0.000"],["62657.40","0.000"],["62658.30","0.001"],["62751.90","6.629"],["62752.00","8.569"],["62813.90","3.155"],["62814.00","5.516"],["63027.80","0.000"],["63034.20","0.008"],["63274.50","0.021"],["63278.60","0.012"],["64000.00","108.260"],["67552.20","0.800"]],"b":[["11534.00","0.304"],["11536.90","0.016"],["11537.80","2.400"],["11633.80","0.096"],["11634.00","0.080"],["11634.10","0.016"],["11637.80","0.800"],["11734.00","0.704"],["11735.60","0.000"],["11737.80","0.000"],["11934.00","0.096"],["11937.80","0.288"],["55830.60","0.002"],["55834.00","0.001"],["56517.90","0.000"],["59556.20","0.007"],["60793.20","0.016"],["60793.50","0.003"],["60797.10","0.007"],["61134.30","2.246"],["61413.70","0.014"],["61413.80","0.083"],["61416.50","0.075"],["61416.70","0.001"],["61417.40","0.000"],["61602.60","0.010"],["61603.50","0.257"],["61612.00","0.445"],["61612.10","0.000"],["61612.20","0.523"],["61612.30","0.492"],["61680.00","1.117"],["61727.60","0.019"],["61760.00","0.609"],["61772.90","1.589"],["61773.00","1.416"],["61776.70","0.680"],["61834.40","0.002"],["61835.50","0.000"],["61840.00","0.449"],["61850.70","0.001"],["61853.80","0.078"],["61860.20","0.003"],["61861.90","0.000"],["61869.20","0.214"],["61875.70","0.000"],["61879.70","0.000"],["61894.60","0.783"],["61920.00","0.522"],["61931.40","1.539"],["61937.80","0.000"],["61938.00","0.005"],["61939.50","0.029"],["61939.60","20.243"],["61940.90","1.039"],["61941.00","0.018"],["61941.30","0.072"],["61941.80","0.275"],["61942.00","0.294"],["61948.50","0.002"],["61948.60","0.764"],["61951.40","0.001"],["61951.90","0.682"],["61958.90","0.001"],["61963.80","0.578"],["61963.90","0.164"],["61964.10","0.000"],["61964.20","0.126"],["61964.30","0.026"],["61964.90","0.196"],["61965.50","0.002"],["61965.80","0.066"],["61966.40","0.156"],["61966.50","0.195"],["61970.40","0.013"],["61971.80","0.026"],["61972.00","1.815"],["61972.10","1.363"],["61972.70","0.096"],["61972.90","0.000"],["61973.40","0.100"],["61974.10","0.371"],["61975.60","0.177"],["61975.80","0.430"],["61978.40","1.472"],["61980.00","4.981"],["61980.50","0.018"],["61980.90","1.503"],["61981.40","0.033"],["61981.50","4.503"],["61981.60","0.002"],["61982.00","0.000"],["61982.10","0.008"],["61982.20","0.131"],["61983.20","0.003"],["61984.10","0.102"],["61984.20","0.470"],["61984.40","0.003"],["61984.60","0.034"],["61987.50","0.087"],["61987.60","0.003"],["61987.90","0.151"],["61988.10","0.030"],["61988.60","0.008"],["61989.10","0.028"],["61989.60","0.008"],["61989.70","0.066"],["61989.90","0.125"],["61990.10","0.304"],["61990.30","0.000"],["61990.40","0.000"],["61990.50","0.004"],["61990.60","1.296"],["61991.20","0.001"],["61991.40","0.072"],["61992.30","0.016"],["61992.90","0.510"],["61993.40","0.000"],["61993.50","0.004"],["61993.80","9.376"],["61994.00","0.002"],["61994.10","0.055"],["61994.20","0.291"],["61994.40","0.024"],["61994.70","0.001"],["61994.80","0.034"],["61994.90","0.002"],["61995.00","0.658"],["61995.10","0.073"],["61995.70","0.294"],["61996.60","0.016"],["61996.80","0.006"],["61996.90","0.003"],["61997.00","1.207"],["61997.80","0.003"],["61998.10","0.004"],["61998.20","0.041"],["61998.30","0.019"],["61998.80","0.065"],["61999.10","0.062"],["61999.20","0.126"],["61999.40","0.150"],["61999.80","0.050"],["62000.00","8.968"],["62000.20","1.251"],["62000.30","0.201"],["62000.60","0.020"],["62000.70","0.358"],["62000.80","0.062"],["62001.30","0.001"],["62001.70","0.015"],["62001.80","0.801"],["62002.00","0.002"],["62002.10","4.174"],["62002.30","1.296"],["62002.40","2.513"],["62002.50","0.677"],["62002.70","1.433"],["62002.80","0.089"],["62002.90","0.392"],["62003.00","0.005"],["62003.10","0.004"],["62003.40","0.012"],["62003.70","0.007"],["62003.80","0.403"],["62004.10","0.043"],["62004.60","0.027"],["62004.90","0.045"],["62005.10","0.000"],["62005.20","0.571"],["62005.30","0.120"],["62005.40","0.001"],["62005.70","0.035"],["62005.80","0.010"],["62006.00","0.079"],["62006.10","1.102"],["62006.20","2.740"],["62006.40","0.002"],["62006.50","0.453"],["62006.60","0.173"],["62006.70","0.002"],["62006.80","2.061"],["62006.90","0.709"],["62007.10","0.171"],["62007.20","0.127"],["62007.30","0.000"],["62007.40","0.002"],["62007.50","0.104"],["62008.00","0.003"],["62008.30","0.002"],["62008.40","0.003"],["62008.60","1.381"],["62008.80","0.531"],["62008.90","0.013"],["62009.00","0.001"],["62009.10","0.058"],["62009.30","0.005"],["62009.40","0.000"],["62009.80","0.693"],["62009.90","0.001"],["62010.20","0.010"],["62010.40","0.001"],["62010.50","0.068"],["62010.60","0.000"],["62011.30","0.002"],["62011.40","0.290"],["62011.50","0.002"],["62011.70","0.051"],["62011.80","0.052"],["62011.90","0.000"],["62012.10","0.783"],["62012.20","0.050"],["62012.30","1.857"],["62012.40","1.710"],["62012.70","2.253"],["62013.00","0.168"],["62013.10","0.011"],["62013.50","0.325"],["62013.60","1.405"],["62013.80","1.631"],["62013.90","0.056"],["62014.00","0.101"],["62014.60","0.290"],["62014.70","0.366"],["62014.90","0.344"],["62015.00","0.014"],["62015.30","0.050"],["62015.40","0.001"],["62015.50","0.669"],["62015.60","0.565"],["62015.70","0.020"],["62015.80","0.000"],["62016.10","0.002"],["62016.20","0.005"],["62016.40","0.067"],["62016.50","0.178"],["62016.60","0.008"],["62016.70","0.005"],["62016.80","1.340"],["62016.90","0.121"],["62017.20","0.117"],["62017.50","0.004"],["62017.80","0.337"],["62017.90","0.006"],["62018.20","0.000"],["62018.40","0.001"],["62018.50","0.705"],["62018.70","0.002"],["62018.80","1.752"],["62018.90","0.003"],["62019.00","0.009"],["62019.10","0.002"],["62019.20","0.014"],["62019.30","0.094"],["62019.50","0.100"],["62019.60","0.406"],["62019.70","0.001"],["62019.80","0.832"],["62019.90","0.003"],["62020.00","0.441"],["62020.30","0.007"],["62020.40","0.292"],["62020.70","0.014"],["62020.80","0.002"],["62020.90","0.004"],["62021.00","1.000"],["62021.10","0.001"],["62021.20","0.000"],["62021.30","0.828"],["62021.40","1.374"],["62021.50","0.164"],["62021.60","1.756"],["62021.70","0.381"],["62021.80","1.298"],["62021.90","0.565"],["62022.10","0.265"],["62022.20","0.003"],["62022.30","0.053"],["62022.40","0.767"],["62022.50","0.033"],["62022.60","0.171"],["62022.90","0.002"],["62023.10","0.001"],["62023.20","0.052"],["62023.50","0.769"],["62023.60","0.696"],["62023.70","0.001"],["62023.80","0.000"],["62024.00","0.054"],["62024.10","0.752"],["62024.20","0.000"],["62024.30","0.001"],["62024.40","0.241"],["62024.50","0.288"],["62024.70","0.128"],["62025.00","0.006"],["62025.10","0.003"],["62025.20","0.003"],["62025.30","0.003"],["62025.40","0.000"],["62025.70","0.840"],["62025.80","0.323"],["62025.90","0.325"],["62026.00","0.054"],["62026.20","0.002"],["62026.50","0.001"],["62026.60","0.000"],["62026.70","0.002"],["62026.80","0.000"],["62027.00","0.005"],["62027.10","0.005"],["62027.20","0.053"],["62027.40","0.053"],["62027.60","0.023"],["62027.80","0.000"],["62028.00","0.064"],["62028.10","0.241"],["62028.20","0.063"],["62028.50","0.000"],["62028.60","0.154"],["62028.90","0.034"],["62029.00","0.003"],["62029.30","0.096"],["62029.40","0.000"],["62029.60","0.013"],["62029.70","0.003"],["62029.80","0.075"],["62029.90","0.324"],["62030.50","0.001"],["62030.60","0.283"],["62030.80","0.000"],["62030.90","0.003"],["62031.00","0.045"],["62031.20","0.004"],["62031.30","0.167"],["62031.40","0.000"],["62031.50","0.125"],["62031.70","0.001"],["62032.20","0.057"],["62032.60","0.319"],["62032.70","0.483"],["62032.80","0.003"],["62033.00","0.001"],["62033.30","0.000"],["62033.50","0.102"],["62033.90","0.004"],["62034.00","6.841"],["62034.10","0.000"],["62034.30","0.000"],["62034.50","0.000"],["62034.60","0.000"],["62034.80","0.000"],["62034.90","0.000"],["62035.00","0.000"],["62035.10","0.000"],["62035.20","0.000"],["62035.50","0.000"],["62035.60","0.000"],["62035.70","0.000"],["62036.30","0.000"],["62036.50","0.000"],["62036.60","0.000"],["62036.90","0.000"],["62037.10","0.000"],["62037.20","0.000"],["62037.30","0.000"],["62037.70","0.000"],["62037.80","0.000"]],"e":"depthUpdate","ps":"BTCUSDT","pu":10998398671055,"s":"BTCUSDT","st":1,"u":10998398721001}
{"E":1783504310210,"T":1783504310209,"U":10998398721049,"a":[["62034.10","14.345"],["62034.20","0.835"],["62034.30","0.001"],["62035.60","0.001"],["62035.80","0.004"],["62036.30","0.000"],["62036.40","0.001"],["62036.50","0.001"],["62036.80","0.557"],["62037.00","1.627"],["62037.70","1.526"],["62037.80","1.802"],["62037.90","1.973"],["62038.00","0.005"],["62038.20","0.000"],["62038.50","0.002"],["62038.80","0.051"],["62039.10","0.082"],["62039.40","0.582"],["62039.70","0.007"],["62039.90","0.225"],["62040.00","1.366"],["62040.10","0.001"],["62040.20","1.342"],["62040.30","0.005"],["62040.50","0.002"],["62041.00","0.555"],["62041.30","0.221"],["62041.60","0.026"],["62042.10","0.322"],["62042.80","1.536"],["62043.20","0.323"],["62043.70","1.059"],["62044.20","1.053"],["62044.30","0.300"],["62044.70","0.163"],["62044.80","0.004"],["62044.90","0.227"],["62045.00","0.324"],["62045.10","0.402"],["62045.60","0.403"],["62046.10","0.369"],["62047.00","0.726"],["62047.10","0.326"],["62047.50","0.491"],["62047.70","0.344"],["62048.50","0.093"],["62048.90","0.284"],["62050.50","0.021"],["62050.60","0.018"],["62052.70","0.004"],["62054.50","0.052"],["62054.80","0.014"],["62055.00","0.067"],["62055.90","0.166"],["62056.90","0.048"],["62058.40","0.009"],["62059.00","0.008"],["62059.20","0.004"],["62059.30","0.545"],["62061.40","0.000"],["62062.20","0.063"],["62063.80","0.000"],["62064.40","0.623"],["62066.20","0.029"],["62067.20","0.001"],["62067.60","0.231"],["62075.20","2.458"],["62076.30","0.341"],["62076.50","0.737"],["62077.20","1.434"],["62077.80","1.437"],["62078.40","0.073"],["62080.40","0.003"],["62083.50","0.128"],["62085.00","0.452"],["62091.80","0.525"],["62097.50","0.228"],["62103.30","0.000"],["62109.50","0.000"],["62109.60","18.327"],["62131.20","0.001"],["62148.50","0.255"],["62150.60","0.074"],["62150.70","1.551"],["62161.70","0.142"],["62184.40","0.071"],["62192.30","3.614"],["62192.40","1.529"],["62197.20","0.001"],["62202.00","0.000"],["62205.20","0.019"],["62654.40","1.910"],["62819.10","0.015"],["63274.70","0.003"]],"b":[["1000.00","210.542"],["11534.00","0.400"],["11537.80","2.224"],["11633.80","0.000"],["11634.00","0.224"],["11734.00","0.560"],["11934.00","0.272"],["49627.00","0.000"],["55830.60","0.002"],["59552.60","0.003"],["61413.70","0.010"],["61727.60","0.018"],["61834.40","0.001"],["61859.20","0.001"],["61859.30","2.210"],["61938.70","4.836"],["61939.60","0.019"],["61957.10","0.169"],["61963.80","0.446"],["61963.90","0.032"],["61964.80","1.378"],["61966.90","0.021"],["61967.00","0.539"],["61969.00","20.228"],["61974.10","0.161"],["61980.50","0.004"],["61981.00","0.210"],["61984.60","0.009"],["61987.40","0.014"],["61990.70","0.794"],["61991.70","0.020"],["61992.00","0.111"],["61992.30","0.017"],["61992.50","0.292"],["61993.80","9.378"],["61995.10","0.003"],["61995.70","0.002"],["61996.30","0.027"],["61997.90","3.853"],["61998.00","0.300"],["62000.70","0.358"],["62002.10","4.125"],["62002.70","1.503"],["62003.30","0.292"],["62005.80","0.008"],["62006.20","2.742"],["62006.30","0.016"],["62007.80","0.000"],["62007.90","2.462"],["62008.60","0.296"],["62008.70","0.017"],["62009.20","0.527"],["62009.30","0.054"],["62009.80","0.703"],["62013.60","0.679"],["62013.90","0.480"],["62015.30","0.051"],["62015.50","0.673"],["62016.20","0.727"],["62017.90","0.002"],["62019.80","0.009"],["62020.20","0.002"],["62020.30","0.005"],["62020.40","0.301"],["62020.80","0.003"],["62021.00","0.000"],["62021.30","1.828"],["62021.60","1.553"],["62021.70","0.833"],["62022.10","0.006"],["62023.40","0.085"],["62023.60","0.824"],["62023.70","0.133"],["62024.00","0.004"],["62025.00","0.004"],["62025.90","0.196"],["62026.30","0.823"],["62026.40","0.491"],["62027.00","0.001"],["62027.10","0.055"],["62028.20","0.326"],["62028.30","0.242"],["62029.30","0.094"],["62029.50","0.036"],["62029.90","0.326"],["62034.00","6.851"]],"e":"depthUpdate","ps":"BTCUSDT","pu":10998398721001,"s":"BTCUSDT","st":1,"u":10998398733883}
{"E":1783504310312,"T":1783504310311,"U":10998398733945,"a":[["62034.40","0.060"],["62035.70","0.293"],["62036.80","0.001"],["62037.90","1.972"],["62040.40","0.066"],["62044.90","0.163"],["62045.20","0.000"],["62046.50","0.569"],["62046.70","0.377"],["62047.00","0.001"],["62047.50","0.411"],["62048.00","0.726"],["62048.60","0.002"],["62049.50","1.017"],["62050.00","0.003"],["62050.60","0.002"],["62051.00","0.002"],["62053.80","0.001"],["62054.20","0.141"],["62054.80","0.078"],["62055.00","0.003"],["62055.60","0.002"],["62055.70","0.033"],["62058.30","0.059"],["62059.00","0.006"],["62059.30","0.543"],["62059.40","0.414"],["62063.60","5.021"],["62066.80","0.000"],["62071.30","0.357"],["62073.80","0.000"],["62074.80","0.166"],["62074.90","0.300"],["62094.00","0.851"],["62098.20","0.000"],["62099.00","0.026"],["62099.40","0.004"],["62099.50","1.362"],["62103.20","18.314"],["62109.60","0.016"],["62122.20","1.321"],["62143.90","1.029"],["62344.30","0.111"],["62654.40","1.912"],["62751.80","3.788"],["62751.90","2.841"],["62813.80","3.152"],["62813.90","0.003"]],"b":[["1000.00","210.542"],["11537.80","1.952"],["11634.00","0.352"],["11734.00","0.432"],["11934.00","0.544"],["49627.00","0.000"],["55830.60","0.002"],["59552.60","0.000"],["61299.00","10.636"],["61413.70","0.010"],["61727.60","0.008"],["61834.40","0.002"],["61862.70","1.175"],["61891.20","0.326"],["61909.10","0.976"],["61949.30","0.989"],["61969.00","0.004"],["61971.10","20.254"],["61972.00","1.816"],["61980.70","1.485"],["61990.10","0.214"],["61990.50","0.004"],["61991.10","0.077"],["61991.40","0.012"],["61997.00","1.297"],["61997.40","0.337"],["61998.30","0.079"],["62003.40","0.003"],["62006.00","0.029"],["62008.00","1.400"],["62009.20","0.780"],["62013.00","0.218"],["62018.00","0.195"],["62018.90","0.297"],["62019.00","0.005"],["62021.30","1.006"],["62021.40","1.377"],["62021.60","1.300"],["62022.30","0.062"],["62022.60","0.235"],["62022.70","0.004"],["62023.90","0.002"],["62024.70","0.132"],["62025.10","0.001"],["62025.70","0.841"],["62026.00","0.054"],["62030.70","0.003"],["62034.00","6.641"]],"e":"depthUpdate","ps":"BTCUSDT","pu":10998398733883,"s":"BTCUSDT","st":1,"u":10998398743961}
{"E":1783504310414,"T":1783504310413,"U":10998398743984,"a":[["62036.50","0.003"],["62036.80","0.001"],["62037.70","0.935"],["62037.80","2.083"],["62038.80","0.053"],["62039.40","0.582"],["62040.00","1.365"],["62046.50","0.005"],["62046.60","1.028"],["62047.90","0.567"],["62048.00","0.001"],["62049.00","2.088"],["62054.10","0.065"],["62054.80","0.014"],["62062.00","0.141"],["62065.00","0.210"],["62068.20","0.052"],["62069.00","0.109"],["62076.30","0.281"],["62078.10","1.229"],["62080.50","0.013"],["62092.70","0.003"],["62099.40","0.105"],["62099.60","1.499"],["62102.30","0.002"],["62131.30","0.001"],["62131.40","0.709"],["62635.50","0.003"],["62654.40","1.910"],["62655.60","14.240"]],"b":[["11537.80","1.680"],["11634.00","0.496"],["11734.00","0.288"],["11934.00","0.816"],["34000.00","13.622"],["49627.00","0.000"],["55830.60","0.002"],["61247.80","1.214"],["61323.40","0.000"],["61413.70","0.010"],["61723.60","0.324"],["61723.80","0.882"],["61727.60","0.017"],["61736.00","0.816"],["61757.10","0.052"],["61776.80","0.206"],["61794.40","0.537"],["61813.30","0.237"],["61832.30","0.469"],["61834.40","0.001"],["61928.80","0.000"],["61931.20","0.604"],["61952.20","0.674"],["61955.50","1.346"],["61959.80","0.000"],["61961.00","0.307"],["61965.80","0.051"],["61969.20","0.001"],["61972.80","0.016"],["61980.30","0.002"],["61980.40","0.000"],["61981.50","0.003"],["61990.70","0.819"],["61992.00","0.086"],["62008.70","0.015"],["62010.90","0.016"],["62015.60","0.001"],["62018.60","0.573"],["62021.60","1.172"],["62022.50","0.034"],["62026.00","0.050"],["62032.80","0.002"],["62033.80","0.126"],["62034.00","6.646"]],"e":"depthUpdate","ps":"BTCUSDT","pu":10998398743961,"s":"BTCUSDT","st":1,"u":10998398751823}
{"E":1783504310516,"T":1783504310513,"U":10998398751921,"a":[["62034.10","14.334"],["62034.20","0.836"],["62036.80","0.002"],["62036.90","1.804"],["62037.00","1.626"],["62037.10","0.003"],["62037.80","2.082"],["62037.90","1.971"],["62038.00","0.004"],["62039.80","0.004"],["62040.30","0.246"],["62041.20","0.003"],["62043.20","0.001"],["62044.20","1.053"],["62045.20","0.322"],["62045.80","1.434"],["62045.90","0.769"],["62046.60","1.027"],["62047.10","0.004"],["62048.20","0.322"],["62049.50","0.937"],["62049.60","0.941"],["62050.30","0.259"],["62052.20","0.581"],["62053.50","0.090"],["62054.10","0.001"],["62054.20","0.021"],["62055.00","0.123"],["62055.70","0.017"],["62099.50","1.463"],["62654.40","1.910"],["62748.00","1.900"],["62748.10","0.948"],["62751.80","0.947"],["62799.20","2.364"],["62805.60","0.557"],["62810.00","0.947"],["62810.10","2.365"],["62813.80","0.000"]],"b":[["1000.00","210.542"],["11537.80","1.408"],["11634.00","0.624"],["11734.00","0.160"],["11934.00","1.088"],["55830.60","0.002"],["59552.60","0.003"],["61413.70","0.010"],["61732.80","0.022"],["61834.40","0.002"],["61895.60","0.015"],["61963.90","0.049"],["61964.70","0.022"],["61967.60","0.027"],["61971.10","0.030"],["61973.10","20.238"],["61973.20","0.456"],["62000.50","0.064"],["62000.60","0.018"],["62000.70","0.356"],["62002.70","1.444"],["62006.20","2.161"],["62006.60","0.052"],["62008.50","0.700"],["62009.70","0.052"],["62009.80","0.762"],["62013.20","0.582"],["62013.70","0.338"],["62013.80","1.309"],["62016.60","0.006"],["62016.70","0.003"],["62016.80","1.338"],["62017.30","0.322"],["62017.80","0.015"],["62018.80","1.430"],["62021.50","0.486"],["62022.00","0.324"],["62023.70","0.001"],["62027.60","0.000"],["62030.00","0.006"],["62031.20","0.001"],["62032.50","0.003"],["62034.00","6.647"]],"e":"depthUpdate","ps":"BTCUSDT","pu":10998398751823,"s":"BTCUSDT","st":1,"u":10998398758324}
{"E":1783504310618,"T":1783504310617,"U":10998398758508,"a":[["62034.10","14.335"],["62039.80","0.560"],["62040.20","1.422"],["62042.70","0.017"],["62045.80","1.354"],["62049.60","0.925"],["62053.40","0.382"],["62053.50","0.726"],["62059.20","0.002"],["62063.50","1.501"],["62064.30","0.082"],["62070.50","0.244"],["62073.10","0.385"],["62073.40","0.194"],["62073.50","0.167"],["62073.60","2.588"],["62076.70","0.322"],["62079.00","4.500"],["62080.00","0.898"],["62097.50","0.228"],["62099.40","0.004"],["62099.50","1.362"],["62100.80","8.004"],["62160.00","0.387"],["62176.00","0.000"],["62240.00","0.448"],["62320.00","0.384"],["62400.00","14.259"],["62654.40","1.910"],["63274.70","0.006"]],"b":[["1000.00","210.542"],["11537.80","1.136"],["11634.00","0.768"],["11734.00","0.016"],["11934.00","1.360"],["55830.60","0.002"],["59552.60","0.000"],["61165.50","7.461"],["61413.70","0.010"],["61680.00","0.940"],["61723.80","0.893"],["61727.60","0.007"],["61760.00","0.432"],["61834.40","0.001"],["61840.00","0.272"],["61907.20","0.783"],["61920.00","0.345"],["61959.00","8.002"],["61966.40","0.171"],["61968.30","0.281"],["61971.10","20.254"],["61972.00","1.563"],["61972.10","1.365"],["61973.10","0.014"],["61980.70","5.985"],["61996.20","0.797"],["62000.00","8.791"],["62004.10","0.003"],["62012.40","1.750"],["62019.90","0.325"],["62023.60","0.695"],["62023.70","0.130"],["62024.80","0.009"],["62026.10","0.164"],["62032.30","0.081"],["62034.00","6.931"]],"e":"depthUpdate","ps":"BTCUSDT","pu":10998398758324,"s":"BTCUSDT","st":1,"u":10998398767212}
{"E":1783504310720,"T":1783504310717,"U":10998398767413,"a":[["62039.80","0.004"],["62040.20","1.342"],["62042.70","0.001"],["62045.50","0.080"],["62049.80","0.384"],["62051.70","0.016"],["62073.00","0.245"],["62073.20","0.000"],["62073.40","0.089"],["62073.50","0.183"],["62083.80","0.499"],["62131.80","11.001"],["62165.70","0.647"],["62187.30","1.149"],["62190.70","0.000"],["62262.00","0.042"],["62654.40","1.910"],["62748.10","0.001"],["62752.00","9.516"],["62805.60","0.000"],["62810.10","0.789"],["62814.00","7.092"],["62991.90","6.817"],["63015.50","0.238"],["63274.50","0.018"],["68237.50","0.002"]],"b":[["11534.00","0.512"],["11537.80","0.864"],["11634.00","0.784"],["11637.80","0.688"],["11734.00","0.000"],["11934.00","1.632"],["55830.60","0.002"],["58740.30","0.000"],["58943.90","0.000"],["59552.60","0.003"],["61413.70","0.010"],["61834.40","0.002"],["61879.30","1.141"],["61881.80","0.003"],["61900.80","0.636"],["61925.90","0.109"],["61928.10","12.437"],["62012.50","1.172"],["62012.80","0.004"],["62026.10","0.003"],["62032.30","0.000"],["62034.00","6.706"]],"e":"depthUpdate","ps":"BTCUSDT","pu":10998398767212,"s":"BTCUSDT","st":1,"u":10998398775609}
{"E":1783504310822,"T":1783504310821,"U":10998398776128,"a":[["62034.10","14.275"],["62045.50","0.000"],["62049.80","0.464"],["62049.90","0.085"],["62051.70","0.000"],["62057.20","0.021"],["62062.00","0.013"],["62068.20","0.180"],["62073.40","0.194"],["62080.00","1.075"],["62095.20","0.057"],["62095.30","0.000"],["62097.50","0.096"],["62097.70","2.004"],["62160.00","0.564"],["62165.70","0.605"],["62240.00","0.625"],["62320.00","0.561"],["62400.00","14.436"],["62447.70","0.000"],["62654.40","1.910"],["62748.00","0.953"],["62752.00","10.463"],["62763.70","0.557"],["62777.10","15.634"],["68237.50","0.000"]],"b":[["1000.00","210.542"],["11534.00","0.656"],["11537.80","0.592"],["11637.80","0.544"],["11934.00","1.904"],["49627.20","0.000"],["55830.60","0.002"],["58932.20","0.009"],["59552.60","0.000"],["60964.00","0.014"],["61413.70","0.010"],["61680.00","1.117"],["61723.80","0.894"],["61760.00","0.609"],["61764.40","0.011"],["61768.20","0.000"],["61834.40","0.001"],["61840.00","0.449"],["61900.80","0.005"],["61901.20","0.573"],["61920.00","0.522"],["61943.70","0.005"],["61943.80","0.000"],["61978.10","0.085"],["61982.80","0.031"],["61991.70","0.023"],["61995.30","0.019"],["62000.00","8.968"],["62002.90","0.025"],["62004.60","0.043"],["62012.40","1.752"],["62012.80","0.006"],["62012.90","2.168"],["62013.90","0.496"],["62015.00","0.381"],["62015.10","0.408"],["62028.70","0.204"],["62030.10","0.002"],["62034.00","6.335"]],"e":"depthUpdate","ps":"BTCUSDT","pu":10998398775609,"s":"BTCUSDT","st":1,"u":10998398784303}
{"E":1783504310924,"T":1783504310923,"U":10998398784378,"a":[["62034.10","14.060"],["62034.30","0.003"],["62035.70","0.001"],["62036.50","0.166"],["62037.00","1.623"],["62039.10","0.001"],["62040.10","0.082"],["62040.20","1.000"],["62041.60","0.002"],["62042.10","0.000"],["62043.00","0.327"],["62045.30","1.704"],["62048.20","0.000"],["62048.90","0.606"],["62049.80","0.384"],["62053.50","0.724"],["62054.80","0.004"],["62055.50","0.080"],["62056.70","0.011"],["62057.20","0.005"],["62062.00","0.141"],["62062.90","0.295"],["62069.00","0.049"],["62073.50","0.272"],["62074.80","0.003"],["62074.90","0.137"],["62077.40","0.116"],["62097.50","0.228"],["62113.90","0.012"],["62348.10","0.254"],["62445.70","0.021"],["62654.40","1.912"],["62763.70","1.114"],["62777.10","15.157"],["62806.80","11.554"],["62810.00","0.159"],["62814.00","7.880"],["63026.60","0.791"]],"b":[["1000.00","210.542"],["11534.00","0.688"],["11537.80","0.416"],["11637.80","0.416"],["11934.00","2.176"],["55830.60","0.002"],["56518.00","1.719"],["61128.10","10.366"],["61221.30","0.652"],["61248.50","0.407"],["61413.70","0.010"],["61723.80","0.884"],["61727.60","0.017"],["61772.90","0.909"],["61834.40","0.002"],["61901.30","0.017"],["61940.60","0.001"],["61953.00","0.000"],["61953.20","0.549"],["61961.40","0.012"],["61962.30","0.047"],["61965.30","0.000"],["61973.20","0.324"],["61982.80","0.015"],["61987.40","0.000"],["61996.80","0.020"],["62000.20","1.169"],["62000.30","0.248"],["62002.80","0.221"],["62008.10","0.001"],["62009.90","1.363"],["62012.70","2.300"],["62014.00","0.101"],["62017.30","0.000"],["62021.60","1.425"],["62022.00","0.324"],["62022.10","0.328"],["62022.50","0.034"],["62023.60","0.005"],["62023.70","0.001"],["62024.20","1.654"],["62024.30","1.235"],["62025.00","0.051"],["62033.90","0.015"],["62034.00","6.336"]],"e":"depthUpdate","ps":"BTCUSDT","pu":10998398784303,"s":"BTCUSDT","st":1,"u":10998398794534}
{"E":1783504311026,"T":1783504311025,"U":10998398794539,"a":[["62034.10","10.682"],["62034.20","0.399"],["62035.90","0.004"],["62036.50","0.001"],["62036.90","0.004"],["62037.00","1.622"],["62037.80","2.083"],["62039.70","0.009"],["62039.80","0.000"],["62039.90","0.004"],["62040.30","0.005"],["62041.10","0.008"],["62041.30","0.050"],["62041.50","0.002"],["62041.90","0.000"],["62042.00","0.023"],["62042.60","0.004"],["62042.70","0.404"],["62044.20","0.735"],["62045.30","2.026"],["62046.40","0.479"],["62049.00","1.363"],["62049.60","0.980"],["62049.90","0.005"],["62050.10","0.912"],["62052.20","0.001"],["62052.90","0.662"],["62053.90","0.051"],["62054.80","0.012"],["62055.00","0.003"],["62055.50","0.000"],["62055.80","0.004"],["62056.80","0.122"],["62059.60","0.124"],["62060.00","0.070"],["62063.60","5.076"],["62064.30","0.001"],["62066.20","0.019"],["62068.20","0.052"],["62068.30","0.012"],["62070.50","0.083"],["62071.30","0.485"],["62073.80","0.194"],["62074.20","0.105"],["62074.80","0.166"],["62074.90","0.494"],["62076.50","0.712"],["62076.70","0.000"],["62083.00","0.025"],["62099.40","0.105"],["62099.50","1.463"],["62654.40","1.910"],["62781.70","2.889"],["62853.60","0.013"],["62949.90","0.555"],["63274.70","0.009"],["67552.20","0.192"]],"b":[["11534.00","0.704"],["11537.80","0.272"],["11637.80","0.272"],["11934.00","2.448"],["55830.60","0.002"],["59552.60","0.003"],["60934.40","0.820"],["61189.60","0.816"],["61227.40","1.429"],["61288.20","12.680"],["61413.70","0.010"],["61723.80","0.885"],["61834.40","0.001"],["61903.20","0.019"],["61904.50","0.017"],["61908.50","0.027"],["61925.90","0.009"],["61962.30","0.000"],["61963.80","0.010"],["61964.20","0.033"],["61964.90","0.100"],["61966.50","0.039"],["61981.00","0.646"],["61998.20","0.001"],["62003.10","0.003"],["62004.60","0.027"],["62005.20","0.611"],["62005.70","0.000"],["62008.70","0.005"],["62011.90","0.010"],["62012.10","0.703"],["62013.50","0.360"],["62013.80","1.402"],["62014.00","0.183"],["62016.20","0.001"],["62018.80","2.140"],["62021.70","0.913"],["62021.90","0.001"],["62022.00","0.049"],["62022.10","0.006"],["62024.10","0.811"],["62024.30","1.557"],["62024.50","0.288"],["62024.60","0.340"],["62024.70","0.792"],["62024.80","0.139"],["62026.40","0.153"],["62026.50","0.001"],["62027.40","0.876"],["62027.50","0.535"],["62028.70","0.180"],["62028.90","0.035"],["62033.90","0.338"],["62034.00","6.618"]],"e":"depthUpdate","ps":"BTCUSDT","pu":10998398794534,"s":"BTCUSDT","st":1,"u":10998398810058}
{"E":1783504311128,"T":1783504311125,"U":10998398810264,"a":[["62034.10","10.673"],["62035.80","0.000"],["62036.10","0.004"],["62036.80","0.001"],["62036.90","0.005"],["62037.40","0.001"],["62041.40","0.293"],["62041.60","0.243"],["62042.20","0.160"],["62042.70","0.163"],["62044.70","0.165"],["62045.90","0.768"],["62049.00","1.364"],["62054.70","0.004"],["62062.00","0.013"],["62063.60","0.076"],["62064.40","0.003"],["62074.40","0.131"],["62075.10","0.409"],["62075.20","2.547"],["62075.30","0.490"],["62081.80","0.124"],["62081.90","0.003"],["62083.80","0.399"],["62095.20","0.018"],["62095.30","0.039"],["62099.00","0.127"],["62099.10","18.538"],["62099.40","0.004"],["62099.50","1.362"],["62100.70","0.104"],["62103.20","0.003"],["62355.10","0.112"],["62356.40","0.964"],["62529.00","0.441"],["62534.20","0.638"],["62648.00","0.188"],["62654.40","1.910"],["62716.90","0.187"],["62782.40","0.635"],["62785.80","0.189"],["62854.70","0.187"],["62923.70","0.187"],["62992.60","0.189"],["63061.50","0.187"],["63130.40","0.662"],["63199.30","0.187"],["63268.30","0.187"]],"b":[["1000.00","210.542"],["11534.00","0.832"],["11537.80","0.144"],["11637.80","0.144"],["11834.00","0.144"],["11934.00","2.576"],["11937.80","0.144"],["55830.60","0.002"],["59552.60","0.000"],["60547.40","0.000"],["60787.10","0.187"],["60856.10","0.203"],["60925.00","0.999"],["60993.90","0.187"],["61062.80","4.601"],["61131.70","0.187"],["61200.70","0.220"],["61269.60","0.189"],["61300.00","88.051"],["61338.50","0.187"],["61407.40","1.477"],["61413.60","0.523"],["61413.70","0.010"],["61834.40","0.002"],["61966.40","0.015"],["61971.10","0.030"],["61972.00","1.719"],["61972.10","1.363"],["61973.10","20.372"],["61973.20","0.326"],["61974.00","0.712"],["61981.30","0.156"],["61986.40","0.004"],["61997.00","1.207"],["61999.70","0.002"],["61999.80","0.052"],["61999.90","0.005"],["62002.60","0.089"],["62003.90","0.091"],["62005.20","0.571"],["62008.20","0.019"],["62015.80","0.002"],["62015.90","0.002"],["62016.00","0.009"],["62023.50","0.007"],["62024.10","0.059"],["62027.10","0.051"],["62028.20","0.323"],["62028.60","0.178"],["62031.10","0.003"],["62031.70","0.003"],["62033.90","0.015"],["62034.00","6.475"]],"e":"depthUpdate","ps":"BTCUSDT","pu":10998398810058,"s":"BTCUSDT","st":1,"u":10998398820123}
{"E":1783504311230,"T":1783504311229,"U":10998398820456,"a":[["62034.10","8.279"],["62034.20","0.395"],["62036.50","0.001"],["62037.00","1.626"],["62037.10","0.002"],["62037.80","2.082"],["62039.30","0.003"],["62040.10","0.002"],["62041.20","0.084"],["62041.40","0.001"],["62041.60","0.002"],["62042.70","0.404"],["62049.40","0.630"],["62066.30","0.001"],["62071.30","0.357"],["62072.70","0.978"],["62072.80","1.376"],["62073.00","0.140"],["62073.10","0.280"],["62074.80","0.003"],["62074.90","0.494"],["62075.20","2.652"],["62075.30","0.579"],["62079.00","4.502"],["62080.50","0.011"],["62344.30","0.110"],["62484.00","0.000"],["62654.40","1.910"],["63274.70","0.012"]],"b":[["1000.00","210.542"],["11534.00","0.976"],["11537.80","0.000"],["11637.80","0.000"],["11834.00","0.272"],["11934.00","2.720"],["11937.80","0.016"],["55830.60","0.002"],["58932.10","0.006"],["58932.20","0.012"],["59552.60","0.003"],["60150.20","0.000"],["60930.70","0.001"],["61134.60","1.160"],["61413.70","0.010"],["61727.60","0.017"],["61834.40","0.001"],["61935.40","0.000"],["61947.70","0.104"],["61957.10","0.216"],["61960.10","0.022"],["61967.00","0.103"],["61973.10","20.374"],["61973.30","0.000"],["61981.10","0.479"],["61995.30","0.003"],["62000.30","0.248"],["62002.80","0.139"],["62004.90","0.001"],["62010.90","0.096"],["62011.00","0.050"],["62011.70","0.049"],["62012.40","1.753"],["62012.70","2.302"],["62013.00","0.918"],["62016.90","0.201"],["62018.50","0.666"],["62018.80","2.700"],["62018.90","0.297"],["62021.70","0.833"],["62021.90","0.903"],["62022.00","0.324"],["62024.30","1.235"],["62024.60","0.776"],["62024.70","0.192"],["62025.00","0.051"],["62025.30","0.042"],["62029.10","0.000"],["62034.00","7.369"]],"e":"depthUpdate","ps":"BTCUSDT","pu":10998398820123,"s":"BTCUSDT","st":1,"u":10998398830524}
{"E":1783504311332,"T":1783504311331,"U":10998398830684,"a":[["62034.10","7.473"],["62034.20","0.394"],["62036.70","0.133"],["62039.90","0.004"],["62050.00","0.003"],["62071.30","0.485"],["62073.40","0.089"],["62073.50","0.167"],["62074.40","0.003"],["62074.80","0.166"],["62097.70","4.536"],["62118.10","1.757"],["62165.00","0.702"],["62184.30","0.642"],["62204.60","1.152"],["62227.50","1.225"],["62245.90","0.554"],["62276.30","0.401"],["62302.00","0.209"],["62336.00","0.576"],["62654.40","1.912"],["62748.10","0.948"],["62752.00","9.516"],["62778.50","0.794"],["62782.40","2.226"],["62820.20","0.795"]],"b":[["11534.00","0.992"],["11536.90","0.000"],["11634.00","0.672"],["11634.10","0.000"],["11834.00","0.416"],["11934.00","2.720"],["11937.80","0.000"],["55830.60","0.002"],["59552.60","0.000"],["61195.30","0.000"],["61413.70","0.010"],["61604.70","0.277"],["61626.20","0.549"],["61655.10","0.661"],["61683.70","0.229"],["61716.70","0.093"],["61723.80","0.886"],["61834.40","0.002"],["61957.10","0.169"],["62010.90","0.016"],["62012.30","1.353"],["62012.40","2.648"],["62014.10","0.082"],["62018.90","0.297"],["62022.00","0.371"],["62028.80","0.090"],["62034.00","7.692"]],"e":"depthUpdate","ps":"BTCUSDT","pu":10998398830524,"s":"BTCUSDT","st":1,"u":10998398842089}
{"E":1783504311434,"T":1783504311433,"U":10998398842143,"a":[["62035.00","0.003"],["62036.10","0.000"],["62037.10","0.000"],["62037.50","0.004"],["62037.60","0.292"],["62038.50","0.003"],["62039.90","0.004"],["62040.80","0.122"],["62041.00","0.556"],["62043.00","0.005"],["62044.10","0.323"],["62067.40","0.657"],["62354.50","0.270"],["62385.80","0.253"],["62404.40","0.270"],["62432.90","0.082"],["62497.80","0.120"],["62654.40","1.910"],["62748.10","1.895"],["62752.00","8.569"],["62810.10","3.153"],["62814.00","5.516"],["63092.50","0.632"]],"b":[["1000.00","210.542"],["11534.00","1.072"],["11634.00","0.528"],["11834.00","0.624"],["11934.00","2.576"],["49627.00","0.000"],["55830.60","0.002"],["60886.40","1.065"],["61203.70","0.286"],["61413.70","0.010"],["61834.40","0.001"],["61975.30","0.019"],["62002.80","0.221"],["62006.80","2.069"],["62008.60","0.916"],["62009.80","0.752"],["62010.50","0.052"],["62012.10","0.719"],["62012.20","0.066"],["62013.50","0.370"],["62013.80","1.382"],["62014.10","0.002"],["62019.00","0.085"],["62020.30","0.025"],["62029.00","0.000"],["62029.10","0.032"],["62032.30","0.002"],["62033.20","0.007"],["62034.00","7.700"]],"e":"depthUpdate","ps":"BTCUSDT","pu":10998398842089,"s":"BTCUSDT","st":1,"u":10998398853417}
{"E":1783504311536,"T":1783504311533,"U":10998398853629,"a":[["62035.00","0.005"],["62036.50","0.164"],["62036.90","0.561"],["62042.30","0.248"],["62042.70","0.163"],["62049.90","0.005"],["62052.90","0.582"],["62057.70","0.617"],["62058.00","0.150"],["62060.70","0.013"],["62097.70","4.435"],["62134.90","0.121"],["62165.70","0.009"],["62171.20","0.621"],["62222.80","0.003"],["62222.90","0.000"],["62654.40","1.910"],["62748.10","3.789"],["62751.90","1.894"],["62752.00","7.622"],["62777.10","14.442"],["62809.50","0.407"],["62810.10","3.941"],["62813.40","1.192"],["62814.00","4.728"],["62950.80","1.113"],["63274.50","0.015"]],"b":[["1000.00","210.542"],["11534.00","1.200"],["11634.00","0.400"],["11834.00","0.896"],["11934.00","2.304"],["55830.60","0.002"],["58932.20","0.009"],["59552.60","0.003"],["60137.70","0.713"],["61413.70","0.010"],["61723.80","0.896"],["61727.60","0.007"],["61834.40","0.002"],["61901.20","0.000"],["61903.40","0.636"],["61972.80","0.001"],["61976.20","0.002"],["61981.30","0.192"],["61981.50","0.018"],["61989.10","0.092"],["61989.70","0.002"],["61994.10","0.065"],["62002.70","1.374"],["62009.80","0.822"],["62012.20","0.050"],["62013.70","0.217"],["62014.80","0.122"],["62015.60","0.001"],["62016.10","0.082"],["62019.00","0.005"],["62019.90","0.003"],["62024.70","0.132"],["62030.00","0.304"],["62031.30","0.038"],["62034.00","6.844"]],"e":"depthUpdate","ps":"BTCUSDT","pu":10998398853417,"s":"BTCUSDT","st":1,"u":10998398865030}
{"E":1783504311638,"T":1783504311637,"U":10998398865202,"a":[["62034.10","7.475"],["62036.40","0.133"],["62036.50","0.164"],["62036.90","0.005"],["62039.90","0.004"],["62059.70","0.086"],["62062.00","0.141"],["62065.90","0.164"],["62072.10","0.326"],["62073.80","0.089"],["62074.20","0.000"],["62074.80","0.003"],["62074.90","0.226"],["62097.50","0.096"],["62529.00","0.122"],["62654.40","1.910"],["62748.10","5.683"],["62752.00","5.728"],["62876.30","0.793"]],"b":[["11534.00","1.344"],["11634.00","0.256"],["11834.00","1.168"],["11934.00","2.032"],["55830.60","0.002"],["59552.60","0.000"],["61413.70","0.010"],["61834.40","0.001"],["62009.80","0.902"],["62011.20","0.022"],["62015.10","0.408"],["62016.10","0.002"],["62021.30","1.006"],["62027.50","0.535"],["62028.60","0.154"],["62028.70","0.204"],["62028.80","0.066"],["62034.00","6.148"]],"e":"depthUpdate","ps":"BTCUSDT","pu":10998398865030,"s":"BTCUSDT","st":1,"u":10998398878280}
{"E":1783504311740,"T":1783504311738,"U":10998398878293,"a":[["62034.60","0.049"],["62036.30","0.000"],["62036.40","0.001"],["62038.00","0.002"],["62039.90","0.560"],["62041.30","0.291"],["62042.30","0.007"],["62046.00","0.003"],["62047.50","0.409"],["62171.10","0.634"],["62171.20","0.003"],["62654.40","1.910"],["62747.50","0.397"],["62810.10","4.729"],["62814.00","3.940"],["62918.20","0.013"]],"b":[["1000.00","210.542"],["11534.00","1.472"],["11634.00","0.128"],["11834.00","1.440"],["11934.00","1.760"],["55830.60","0.002"],["59552.60","0.003"],["61098.40","0.000"],["61413.70","0.010"],["61834.40","0.002"],["61837.70","0.001"],["61903.40","0.620"],["61981.30","0.252"],["62003.50","0.129"],["62008.50","0.000"],["62009.80","0.752"],["62012.10","0.703"],["62013.10","0.011"],["62014.00","0.183"],["62016.30","0.364"],["62018.90","0.005"],["62020.30","0.005"],["62022.00","0.049"],["62022.10","0.328"],["62024.20","1.362"],["62034.00","6.240"]],"e":"depthUpdate","ps":"BTCUSDT","pu":10998398878280,"s":"BTCUSDT","st":1,"u":10998398887263}
{"E":1783504311842,"T":1783504311841,"U":10998398887585,"a":[["62034.10","7.470"],["62034.60","0.000"],["62036.30","0.000"],["62036.40","0.001"],["62037.90","1.987"],["62039.90","0.004"],["62071.30","0.485"],["62074.90","0.389"],["62075.30","0.579"],["62080.00","1.057"],["62099.00","0.127"],["62145.70","0.003"],["62160.00","0.546"],["62240.00","0.607"],["62320.00","0.543"],["62400.00","14.418"],["62443.80","0.018"],["62445.70","0.003"],["62654.40","1.910"],["62656.40","0.000"],["62810.10","5.517"],["62814.00","3.152"]],"b":[["1000.00","210.542"],["11534.00","1.584"],["11634.00","0.000"],["11834.00","1.712"],["11934.00","1.504"],["49627.00","0.000"],["49630.20","0.000"],["55830.60","0.002"],["58932.20","0.007"],["61413.70","0.010"],["61680.00","1.099"],["61723.80","0.886"],["61727.60","0.007"],["61760.00","0.591"],["61764.40","0.003"],["61764.90","0.008"],["61834.40","0.001"],["61840.00","0.431"],["61920.00","0.504"],["61973.20","0.324"],["61993.80","9.376"],["62000.00","8.950"],["62011.10","0.090"],["62012.40","2.651"],["62018.90","0.297"],["62020.20","0.000"],["62021.30","1.005"],["62021.40","1.374"],["62022.00","0.371"],["62022.10","0.006"],["62024.20","1.366"],["62024.30","0.904"],["62024.70","0.424"],["62034.00","6.239"]],"e":"depthUpdate","ps":"BTCUSDT","pu":10998398887263,"s":"BTCUSDT","st":1,"u":10998398896286}
{"E":1783504311944,"T":1783504311943,"U":10998398896482,"a":[["62035.60","0.003"],["62043.70","1.061"],["62055.20","0.016"],["62062.00","0.013"],["62074.40","0.131"],["62075.20","2.652"],["62080.00","1.075"],["62160.00","0.564"],["62240.00","0.625"],["62271.40","0.702"],["62320.00","0.561"],["62400.00","14.436"],["62654.40","1.910"],["62780.10","0.000"]],"b":[["11534.00","1.456"],["11834.00","1.984"],["11934.00","1.360"],["55830.60","0.002"],["59552.60","0.000"],["60000.00","124.611"],["61041.50","0.245"],["61140.60","0.001"],["61413.70","0.010"],["61680.00","1.117"],["61723.80","0.885"],["61760.00","0.609"],["61834.40","0.002"],["61840.00","0.449"],["61920.00","0.522"],["61941.00","0.016"],["61973.20","0.326"],["62000.00","8.968"],["62011.10","0.010"],["62014.00","0.101"]],"e":"depthUpdate","ps":"BTCUSDT","pu":10998398896286,"s":"BTCUSDT","st":1,"u":10998398903705}
{"E":1783504312046,"T":1783504312045,"U":10998398903817,"a":[["62036.50","0.001"],["62036.60","0.000"],["62036.80","0.003"],["62037.00","0.264"],["62043.30","0.004"],["62047.50","0.489"],["62053.70","0.016"],["62055.20","0.000"],["62056.90","0.110"],["62059.00","0.626"],["62059.30","5.543"],["62071.30","0.357"],["62133.30","0.015"],["62344.30","0.111"],["62654.40","1.910"],["62748.10","6.630"],["62752.00","4.781"],["62770.90","3.837"]],"b":[["1000.00","210.692"],["11534.00","1.312"],["11834.00","2.256"],["11934.00","1.232"],["55830.60","0.002"],["58935.90","0.000"],["58936.00","0.005"],["59552.60","0.003"],["60688.00","4.517"],["61294.40","3.713"],["61413.60","0.522"],["61413.70","0.010"],["61834.40","0.001"],["61966.20","0.137"],["61971.70","0.000"],["61972.00","1.563"],["61975.60","0.193"],["61976.20","0.917"],["61994.10","0.081"],["62002.40","2.433"],["62003.40","0.019"],["62008.60","0.296"],["62013.30","0.092"],["62015.80","0.018"],["62034.00","6.270"]],"e":"depthUpdate","ps":"BTCUSDT","pu":10998398903705,"s":"BTCUSDT","st":1,"u":10998398909721}
{"E":1783504312148,"T":1783504312147,"U":10998398909768,"a":[["62034.10","0.000"],["62034.20","0.000"],["62034.30","0.000"],["62034.40","0.000"],["62034.70","0.000"],["62035.00","0.000"],["62035.30","0.000"],["62035.50","0.000"],["62035.60","0.000"],["62035.70","0.000"],["62035.90","0.000"],["62036.20","0.000"],["62036.40","0.000"],["62036.50","0.000"],["62036.60","0.000"],["62036.70","0.000"],["62036.80","0.000"],["62036.90","0.000"],["62037.00","0.000"],["62037.20","0.000"],["62037.30","0.000"],["62037.40","0.000"],["62037.50","0.000"],["62037.60","0.000"],["62037.70","0.000"],["62037.80","0.000"],["62037.90","0.429"],["62038.00","0.007"],["62038.10","0.004"],["62038.50","0.001"],["62038.70","0.003"],["62038.80","0.001"],["62038.90","0.000"],["62039.20","0.000"],["62039.30","0.002"],["62039.40","0.002"],["62039.50","0.270"],["62039.70","0.003"],["62039.80","0.001"],["62039.90","0.004"],["62040.00","0.002"],["62040.10","0.003"],["62040.20","0.000"],["62040.40","0.001"],["62040.50","0.001"],["62040.60","0.066"],["62040.70","0.001"],["62040.80","0.000"],["62040.90","0.001"],["62041.00","0.131"],["62041.10","0.012"],["62041.20","0.039"],["62041.30","0.000"],["62041.40","0.001"],["62041.50","0.000"],["62041.60","0.002"],["62041.70","0.000"],["62041.80","0.008"],["62042.00","0.000"],["62042.20","0.049"],["62042.30","0.009"],["62042.40","0.006"],["62042.50","0.026"],["62042.60","0.003"],["62042.70","0.001"],["62042.80","0.004"],["62042.90","0.151"],["62043.00","0.005"],["62043.10","0.002"],["62043.30","0.004"],["62043.40","0.068"],["62043.50","0.105"],["62043.60","0.106"],["62043.70","0.756"],["62043.80","0.000"],["62043.90","0.002"],["62044.00","0.000"],["62044.10","0.061"],["62044.20","0.125"],["62044.30","0.014"],["62044.40","0.000"],["62044.60","0.894"],["62044.80","0.325"],["62044.90","0.163"],["62045.00","0.001"],["62045.10","0.370"],["62045.20","0.000"],["62045.30","0.000"],["62045.40","0.165"],["62045.70","0.064"],["62045.80","0.000"],["62045.90","1.221"],["62046.00","1.365"],["62046.20","0.133"],["62046.40","0.304"],["62046.50","0.005"],["62047.10","0.000"],["62047.20","0.051"],["62047.30","0.002"],["62047.40","0.280"],["62047.50","0.003"],["62047.70","0.002"],["62047.90","0.004"],["62048.20","0.081"],["62048.30","0.703"],["62048.40","1.003"],["62048.50","0.143"],["62048.70","1.362"],["62048.80","0.083"],["62048.90","0.163"],["62049.00","0.001"],["62049.20","0.174"],["62049.30","0.003"],["62049.50","0.062"],["62049.60","0.974"],["62049.80","0.386"],["62049.90","0.407"],["62050.00","0.003"],["62050.10","0.187"],["62050.20","0.099"],["62050.70","0.017"],["62050.80","0.322"],["62051.00","0.002"],["62051.10","0.356"],["62051.20","0.001"],["62051.30","0.203"],["62051.40","1.655"],["62051.50","0.001"],["62051.80","0.022"],["62052.00","0.173"],["62052.30","0.345"],["62052.60","0.002"],["62052.80","0.003"],["62052.90","0.001"],["62053.20","0.686"],["62053.30","0.101"],["62053.40","0.287"],["62053.70","0.000"],["62053.90","0.001"],["62054.00","0.012"],["62054.20","0.343"],["62054.40","0.005"],["62054.50","0.003"],["62054.80","0.004"],["62055.00","0.889"],["62055.80","0.729"],["62055.90","0.164"],["62056.20","0.898"],["62056.30","0.663"],["62056.40","1.363"],["62056.70","0.001"],["62056.80","0.002"],["62056.90","0.048"],["62057.30","0.760"],["62057.40","0.163"],["62058.00","0.071"],["62058.10","0.000"],["62058.30","0.000"],["62058.40","0.009"],["62058.60","0.487"],["62058.90","0.004"],["62059.00","0.004"],["62059.20","1.944"],["62059.30","0.602"],["62059.40","0.417"],["62059.50","1.340"],["62059.60","0.124"],["62059.70","0.005"],["62060.00","0.054"],["62060.40","0.003"],["62060.70","0.013"],["62060.80","0.002"],["62060.90","0.050"],["62061.10","0.460"],["62061.20","0.083"],["62061.90","0.053"],["62062.00","0.005"],["62062.30","1.844"],["62062.40","3.536"],["62062.70","0.004"],["62062.80","0.306"],["62062.90","0.303"],["62063.00","0.354"],["62063.20","0.013"],["62063.50","1.501"],["62063.90","0.002"],["62064.20","0.013"],["62064.40","0.003"],["62064.50","0.118"],["62064.60","0.016"],["62064.90","0.001"],["62065.00","0.330"],["62065.20","0.008"],["62065.80","0.004"],["62065.90","0.003"],["62066.20","0.016"],["62067.40","0.649"],["62068.20","0.054"],["62068.30","0.002"],["62068.50","0.053"],["62068.80","0.005"],["62068.90","0.145"],["62069.10","0.001"],["62070.00","0.312"],["62070.40","0.017"],["62070.90","2.042"],["62071.40","1.116"],["62071.50","0.891"],["62071.80","0.137"],["62072.00","0.129"],["62072.10","0.004"],["62072.20","0.070"],["62072.80","1.362"],["62073.20","0.000"],["62073.50","0.164"],["62073.70","0.009"],["62073.90","0.661"],["62074.10","0.034"],["62074.20","0.010"],["62074.40","0.315"],["62074.60","0.091"],["62074.80","0.166"],["62074.90","0.362"],["62075.00","5.683"],["62075.10","0.409"],["62075.20","0.091"],["62075.30","0.554"],["62075.40","9.353"],["62075.70","0.000"],["62076.30","0.284"],["62076.70","0.003"],["62077.00","0.151"],["62077.10","0.002"],["62077.20","1.434"],["62077.40","0.162"],["62077.60","0.236"],["62077.70","0.050"],["62078.00","0.163"],["62078.10","1.334"],["62078.20","1.566"],["62078.60","0.106"],["62079.10","0.002"],["62079.70","0.015"],["62080.40","0.000"],["62080.70","0.296"],["62081.80","0.128"],["62082.00","0.003"],["62082.10","0.005"],["62082.20","0.000"],["62082.30","1.389"],["62083.00","0.000"],["62083.20","0.002"],["62083.70","0.108"],["62084.00","0.026"],["62084.90","0.061"],["62085.00","0.454"],["62085.70","0.036"],["62086.50","0.017"],["62086.80","0.003"],["62087.20","0.002"],["62089.10","0.007"],["62089.30","0.000"],["62090.70","0.003"],["62090.90","0.028"],["62091.30","0.454"],["62091.70","0.252"],["62092.20","0.109"],["62092.80","0.077"],["62093.90","0.006"],["62094.00","0.876"],["62094.50","0.008"],["62096.10","0.312"],["62096.70","0.015"],["62097.00","0.003"],["62097.10","0.001"],["62097.60","0.751"],["62097.70","1.903"],["62098.90","0.132"],["62099.00","0.026"],["62099.10","0.061"],["62099.60","1.497"],["62099.80","0.707"],["62099.90","1.102"],["62100.70","0.205"],["62100.80","8.006"],["62102.80","1.644"],["62103.20","0.104"],["62103.30","18.504"],["62103.80","0.323"],["62106.20","0.011"],["62110.80","0.572"],["62114.80","0.001"],["62116.80","0.025"],["62116.90","0.052"],["62118.20","0.000"],["62120.00","0.198"],["62123.70","6.207"],["62126.80","0.017"],["62127.20","0.000"],["62131.00","0.052"],["62131.70","0.132"],["62131.90","4.837"],["62137.80","0.132"],["62142.80","0.011"],["62195.80","0.676"],["62200.00","12.028"],["62202.90","0.002"],["62206.00","0.016"],["62354.60","0.144"],["62604.40","0.001"],["62635.50","0.001"],["62654.40","1.910"],["62658.10","0.003"],["62658.20","0.561"],["62658.30","0.003"],["62743.40","0.240"],["62748.00","0.006"],["62748.10","1.895"],["62751.50","1.895"],["62751.80","4.735"],["62810.10","2.365"],["62811.60","1.576"],["62811.70","1.577"],["62996.10","0.013"],["63274.50","0.012"],["63278.50","0.003"],["63278.60","0.015"]],"b":[["1000.00","210.542"],["11534.00","1.184"],["11834.00","2.416"],["11837.60","0.032"],["11837.70","0.016"],["11837.80","0.064"],["11934.00","1.040"],["11937.60","0.016"],["11937.80","0.032"],["49627.00","0.000"],["55830.60","0.000"],["55833.80","0.000"],["55834.00","0.003"],["58935.70","0.016"],["59552.60","0.000"],["60793.40","0.015"],["61034.00","0.012"],["61035.60","0.012"],["61037.60","0.010"],["61037.70","0.505"],["61045.50","0.000"],["61071.60","0.093"],["61072.30","0.732"],["61336.30","0.005"],["61413.70","0.010"],["61417.20","6.448"],["61417.30","0.000"],["61417.40","0.002"],["61723.80","0.885"],["61834.40","0.002"],["61837.70","0.000"],["61850.70","0.000"],["61853.80","0.077"],["61855.00","0.405"],["61857.30","0.011"],["61857.80","0.000"],["61858.10","0.003"],["61860.20","0.000"],["61871.30","0.051"],["61879.50","0.672"],["61931.40","1.523"],["61938.70","0.000"],["61939.50","0.028"],["61941.30","0.071"],["61941.40","0.016"],["61943.60","0.218"],["61943.70","0.002"],["61948.50","0.001"],["61948.60","0.763"],["61950.10","20.829"],["61957.10","0.168"],["61962.70","0.003"],["61963.40","1.056"],["61963.80","0.446"],["61964.80","1.378"],["61964.90","0.052"],["61966.50","0.195"],["61966.90","0.021"],["61968.60","0.000"],["61970.40","0.002"],["61971.10","0.030"],["61971.60","1.351"],["61972.00","1.317"],["61972.10","1.362"],["61972.50","0.405"],["61972.60","0.052"],["61972.70","0.148"],["61973.00","0.015"],["61973.10","0.016"],["61973.20","0.324"],["61974.60","0.324"],["61975.30","0.003"],["61975.60","0.178"],["61975.80","0.529"],["61979.50","0.000"],["61980.00","4.980"],["61981.00","0.000"],["61981.10","0.043"],["61981.20","0.326"],["61981.30","0.096"],["61983.90","1.392"],["61984.20","0.468"],["61984.40","0.001"],["61985.70","0.012"],["61986.10","0.879"],["61987.60","0.005"],["61988.60","0.000"],["61989.10","0.067"],["61989.60","0.000"],["61989.70","0.002"],["61989.90","0.124"],["61990.50","0.002"],["61990.60","1.296"],["61990.70","0.794"],["61990.80","0.661"],["61991.20","0.001"],["61991.70","0.045"],["61991.90","0.000"],["61992.10","0.691"],["61992.30","0.025"],["61992.50","0.292"],["61992.70","0.008"],["61993.20","0.325"],["61993.40","0.002"],["61993.80","9.372"],["61993.90","1.348"],["61994.10","0.065"],["61994.20","0.291"],["61994.90","0.000"],["61996.10","0.000"],["61996.30","0.017"],["61996.60","0.030"],["61996.80","0.002"],["61997.00","1.204"],["61997.30","0.050"],["61997.80","0.001"],["61998.30","0.223"],["61998.70","1.904"],["61999.20","0.112"],["61999.40","0.001"],["61999.60","0.000"],["62000.00","8.966"],["62000.40","0.091"],["62000.70","0.356"],["62001.10","0.001"],["62001.20","0.335"],["62001.40","0.127"],["62001.60","0.002"],["62001.70","0.012"],["62001.80","0.681"],["62001.90","0.000"],["62002.40","2.436"],["62002.80","0.525"],["62002.90","0.107"],["62003.00","0.001"],["62003.20","0.003"],["62003.40","0.003"],["62003.50","0.059"],["62003.80","0.473"],["62003.90","0.001"],["62004.20","0.091"],["62004.40","0.004"],["62004.60","0.019"],["62004.90","0.064"],["62005.20","0.568"],["62005.30","0.120"],["62005.40","0.000"],["62005.80","0.011"],["62006.10","1.112"],["62006.20","2.161"],["62006.50","0.453"],["62006.70","0.000"],["62006.80","2.061"],["62007.00","0.338"],["62007.20","0.127"],["62007.50","0.112"],["62007.70","0.000"],["62007.90","0.003"],["62008.00","0.003"],["62008.20","0.003"],["62008.30","0.001"],["62008.40","0.003"],["62008.60","0.296"],["62008.70","0.005"],["62009.00","0.009"],["62009.20","0.697"],["62009.30","0.005"],["62009.40","0.000"],["62009.80","0.751"],["62009.90","1.491"],["62010.80","0.000"],["62010.90","0.014"],["62011.50","0.003"],["62011.90","0.003"],["62012.00","0.015"],["62012.30","0.683"],["62012.40","2.648"],["62012.80","0.006"],["62013.00","0.884"],["62013.20","0.001"],["62013.50","0.325"],["62013.60","0.679"],["62013.80","1.289"],["62013.90","0.296"],["62014.00","0.097"],["62014.30","0.317"],["62014.40","0.130"],["62014.50","0.033"],["62014.80","0.001"],["62015.00","0.373"],["62015.10","0.405"],["62015.20","1.363"],["62015.30","0.183"],["62015.40","0.000"],["62015.50","0.009"],["62015.80","0.002"],["62015.90","0.181"],["62016.30","0.344"],["62016.60","0.002"],["62016.80","1.340"],["62016.90","0.081"],["62017.20","0.129"],["62017.30","0.000"],["62017.60","0.325"],["62017.70","0.122"],["62017.80","0.031"],["62018.50","0.676"],["62018.60","0.009"],["62018.70","0.583"],["62018.80","1.976"],["62018.90","0.298"],["62019.00","0.668"],["62019.30","0.062"],["62019.40","0.157"],["62019.60","0.404"],["62019.70","0.050"],["62019.80","0.008"],["62020.00","0.279"],["62020.10","0.006"],["62020.40","0.297"],["62020.50","0.008"],["62021.00","0.000"],["62021.30","0.005"],["62021.40","1.363"],["62021.50","0.002"],["62021.60","1.073"],["62021.70","0.902"],["62021.80","1.298"],["62021.90","0.001"],["62022.10","0.002"],["62022.30","0.010"],["62022.40","0.004"],["62022.60","0.007"],["62022.90","0.000"],["62023.10","0.001"],["62023.20","0.000"],["62023.30","0.729"],["62023.40","0.083"],["62023.70","0.003"],["62024.20","1.362"],["62024.40","0.805"],["62024.50","0.854"],["62024.60","0.002"],["62024.70","1.292"],["62024.80","0.005"],["62024.90","0.004"],["62025.70","0.018"],["62025.90","0.034"],["62026.10","0.126"],["62026.20","0.004"],["62026.30","0.002"],["62026.50","0.001"],["62026.80","0.000"],["62027.10","0.001"],["62027.20","0.057"],["62027.30","0.066"],["62027.40","0.053"],["62027.50","0.000"],["62027.60","1.484"],["62027.70","0.326"],["62028.20","0.060"],["62028.30","1.537"],["62028.40","0.903"],["62028.50","0.000"],["62028.60","0.626"],["62028.70","0.180"],["62028.80","0.070"],["62028.90","0.033"],["62029.00","0.024"],["62029.10","0.032"],["62029.20","0.182"],["62029.30","0.096"],["62029.40","0.011"],["62029.50","0.056"],["62029.60","0.013"],["62029.70","0.293"],["62029.80","0.033"],["62029.90","0.328"],["62030.00","0.706"],["62030.10","1.366"],["62030.40","0.002"],["62030.60","0.285"],["62030.70","0.003"],["62030.80","0.000"],["62030.90","0.001"],["62031.10","0.059"],["62031.20","0.003"],["62031.30","0.088"],["62031.50","0.126"],["62031.70","0.001"],["62031.80","0.000"],["62032.10","0.002"],["62032.40","0.003"],["62032.50","0.010"],["62032.60","0.319"],["62032.70","0.485"],["62032.80","0.155"],["62032.90","0.000"],["62033.20","0.006"],["62033.30","0.042"],["62033.40","0.001"],["62033.70","0.000"],["62033.80","0.247"],["62033.90","0.020"],["62034.00","2.000"],["62034.10","2.560"],["62034.20","0.570"],["62034.30","0.000"],["62034.40","0.004"],["62034.50","0.002"],["62034.60","0.000"],["62034.90","0.000"],["62035.00","0.002"],["62035.10","0.002"],["62035.40","0.000"],["62035.50","0.002"],["62035.60","0.000"],["62035.80","0.000"],["62035.90","0.001"],["62036.10","0.050"],["62036.30","0.001"],["62036.40","0.000"],["62036.50","0.000"],["62036.60","0.000"],["62036.70","0.000"],["62036.80","0.000"],["62036.90","0.001"],["62037.00","0.002"],["62037.10","0.000"],["62037.20","0.004"],["62037.30","0.000"],["62037.40","0.000"],["62037.50","0.003"],["62037.60","0.299"],["62037.70","2.181"],["62037.80","17.565"]],"e":"depthUpdate","ps":"BTCUSDT","pu":10998398909721,"s":"BTCUSDT","st":1,"u":10998398951393}
{"E":1783504312250,"T":1783504312249,"U":10998398951432,"a":[["62037.90","0.427"],["62038.00","0.003"],["62040.10","0.001"],["62040.60","0.002"],["62041.00","0.267"],["62041.10","0.006"],["62041.20","0.067"],["62041.80","0.040"],["62042.20","0.000"],["62042.30","0.007"],["62042.60","0.051"],["62042.80","0.109"],["62043.00","0.110"],["62043.30","0.624"],["62043.40","0.827"],["62043.50","0.000"],["62043.60","0.001"],["62044.10","0.001"],["62044.20","0.001"],["62044.30","0.010"],["62044.40","0.004"],["62044.50","0.824"],["62044.60","0.896"],["62044.80","0.004"],["62044.90","0.163"],["62045.00","0.003"],["62045.30","0.299"],["62045.40","0.314"],["62045.50","1.120"],["62045.70","0.000"],["62045.80","0.120"],["62046.00","0.004"],["62046.10","0.002"],["62046.40","0.012"],["62046.60","0.510"],["62046.70","0.377"],["62047.80","0.024"],["62048.20","0.081"],["62048.40","0.003"],["62048.70","0.000"],["62048.90","0.325"],["62049.00","0.001"],["62049.10","0.426"],["62049.20","0.170"],["62049.30","0.165"],["62049.50","1.424"],["62049.60","1.329"],["62049.70","0.261"],["62049.80","0.384"],["62049.90","0.005"],["62050.00","1.003"],["62050.20","0.163"],["62050.80","0.324"],["62050.90","0.417"],["62051.00","0.008"],["62051.10","0.356"],["62051.30","0.050"],["62051.40","0.001"],["62051.60","2.143"],["62052.00","0.002"],["62052.30","0.325"],["62052.70","0.004"],["62053.00","0.292"],["62053.10","0.002"],["62053.20","0.432"],["62053.30","0.105"],["62053.50","0.024"],["62054.20","0.363"],["62054.90","0.213"],["62055.00","0.405"],["62055.70","0.339"],["62055.80","0.004"],["62056.70","0.172"],["62057.20","0.569"],["62059.10","0.748"],["62059.20","1.364"],["62059.30","0.531"],["62061.10","0.440"],["62061.20","0.034"],["62061.80","0.588"],["62062.20","0.225"],["62062.80","0.004"],["62062.90","0.293"],["62063.70","0.015"],["62064.50","0.069"],["62064.60","0.000"],["62065.00","0.210"],["62065.20","0.000"],["62065.30","0.016"],["62065.60","0.041"],["62065.90","0.003"],["62066.20","0.008"],["62066.30","0.009"],["62067.10","0.001"],["62067.30","0.448"],["62067.50","0.008"],["62068.10","0.151"],["62068.20","0.058"],["62068.90","0.135"],["62069.00","0.108"],["62070.10","0.862"],["62070.70","0.128"],["62071.80","0.009"],["62072.00","0.441"],["62074.00","0.036"],["62074.40","0.003"],["62074.80","0.186"],["62075.20","0.393"],["62076.30","0.281"],["62076.40","0.076"],["62076.60","0.000"],["62076.70","0.000"],["62077.00","0.165"],["62077.20","1.437"],["62077.60","0.108"],["62077.70","0.058"],["62078.40","0.074"],["62078.90","0.002"],["62079.00","4.505"],["62079.10","0.000"],["62079.50","0.002"],["62079.70","0.001"],["62080.10","0.001"],["62080.60","0.006"],["62080.90","0.035"],["62085.20","0.008"],["62085.40","0.020"],["62085.70","0.017"],["62087.80","1.354"],["62088.00","0.320"],["62089.10","0.004"],["62090.10","0.008"],["62090.20","0.000"],["62090.90","0.020"],["62091.10","0.030"],["62091.80","0.429"],["62092.50","0.942"],["62092.60","0.000"],["62092.70","0.003"],["62092.80","0.077"],["62093.00","0.004"],["62094.00","0.851"],["62095.80","0.427"],["62096.10","0.000"],["62096.50","0.000"],["62096.70","0.000"],["62097.20","0.164"],["62098.50","0.024"],["62100.20","0.056"],["62103.30","0.000"],["62103.40","0.203"],["62105.50","0.000"],["62107.10","0.013"],["62108.40","0.112"],["62108.60","0.101"],["62109.50","0.000"],["62109.60","18.520"],["62118.10","0.667"],["62126.90","0.161"],["62127.10","0.030"],["62127.90","1.991"],["62131.70","0.140"],["62171.50","0.805"],["62171.60","1.531"],["62175.40","0.000"],["62184.50","4.030"],["62198.50","0.213"],["62282.20","0.106"],["62282.40","0.004"],["62348.10","0.255"],["62437.90","0.000"],["62438.10","0.008"],["62594.00","0.050"],["62594.20","0.016"],["62658.30","0.322"],["62748.10","0.001"],["62751.50","2.842"],["62751.90","2.841"],["62772.20","6.171"],["62810.10","0.001"],["62811.60","0.000"],["62811.70","0.001"],["62813.30","0.270"],["62813.80","2.364"],["62813.90","2.367"],["62814.00","3.940"],["62901.60","3.935"],["62995.90","0.009"],["63278.60","0.024"],["67559.00","0.000"]],"b":[["11534.00","1.040"],["11737.80","0.032"],["11837.80","0.272"],["11934.00","0.800"],["11937.80","0.176"],["55834.00","0.003"],["59556.20","0.010"],["61120.70","4.084"],["61258.60","4.292"],["61283.50","1.580"],["61417.40","0.004"],["61478.60","0.000"],["61478.80","0.108"],["61531.60","0.001"],["61632.30","0.000"],["61632.50","0.008"],["61723.80","0.884"],["61773.00","0.759"],["61786.30","0.000"],["61786.40","0.000"],["61786.50","0.004"],["61834.40","0.001"],["61855.00","0.404"],["61859.30","0.674"],["61859.40","1.536"],["61869.20","0.001"],["61871.30","0.000"],["61871.50","0.051"],["61921.90","0.677"],["61933.10","4.160"],["61940.80","4.376"],["61940.90","1.031"],["61941.00","0.018"],["61941.80","0.283"],["61950.10","0.030"],["61951.30","4.836"],["61960.20","0.004"],["61963.80","0.010"],["61964.70","0.026"],["61966.70","0.094"],["61966.90","0.021"],["61968.00","0.008"],["61971.10","0.030"],["61973.20","21.123"],["61973.30","0.000"],["61974.10","0.163"],["61978.40","1.468"],["61981.50","0.003"],["61982.00","0.004"],["61982.50","0.210"],["61984.00","0.000"],["61984.10","1.632"],["61985.00","0.692"],["61987.40","0.018"],["61987.60","0.003"],["61989.20","0.323"],["61991.10","0.076"],["61991.70","0.044"],["61992.30","0.016"],["61992.40","0.042"],["61992.50","0.300"],["61992.90","0.509"],["61993.50","0.003"],["61993.70","0.006"],["61993.90","1.346"],["61994.20","0.287"],["61994.30","0.001"],["61994.80","0.033"],["61996.60","0.016"],["61998.30","0.013"],["62002.60","0.049"],["62003.70","0.135"],["62004.60","0.022"],["62004.80","0.017"],["62004.90","1.590"],["62005.30","0.000"],["62007.50","0.104"],["62008.50","0.000"],["62008.70","0.054"],["62008.90","0.021"],["62009.00","0.001"],["62009.10","0.090"],["62009.30","0.013"],["62009.70","0.052"],["62009.80","0.692"],["62009.90","1.517"],["62010.10","0.011"],["62011.90","0.000"],["62012.30","1.352"],["62012.40","2.650"],["62012.90","2.171"],["62013.00","0.834"],["62013.40","0.201"],["62014.10","0.012"],["62014.30","0.282"],["62014.40","0.001"],["62015.10","0.405"],["62015.30","0.051"],["62015.50","0.138"],["62015.90","0.132"],["62016.90","0.001"],["62017.80","0.015"],["62018.70","0.002"],["62019.10","0.134"],["62019.30","0.121"],["62019.60","1.782"],["62019.90","0.053"],["62020.20","0.681"],["62021.70","0.781"],["62022.60","0.042"],["62023.10","0.581"],["62023.30","0.003"],["62023.60","0.004"],["62024.40","0.241"],["62024.80","0.137"],["62025.40","0.001"],["62026.30","0.000"],["62027.70","0.450"],["62028.00","0.790"],["62028.70","0.744"],["62029.00","0.000"],["62029.20","0.186"],["62029.30","0.094"],["62029.50","0.032"],["62029.70","0.001"],["62029.90","0.326"],["62030.00","0.007"],["62030.20","1.443"],["62030.80","0.004"],["62030.90","0.003"],["62031.00","0.007"],["62032.20","0.003"],["62032.40","0.007"],["62032.70","0.486"],["62033.30","0.043"],["62033.40","0.081"],["62033.90","0.010"],["62034.00","1.915"],["62034.10","2.563"],["62034.20","1.795"],["62034.30","0.001"],["62034.40","0.000"],["62035.00","0.004"],["62035.80","0.040"],["62036.40","0.056"],["62036.50","0.000"],["62036.70","0.000"],["62037.30","0.016"],["62037.70","2.182"],["62037.80","17.728"]],"e":"depthUpdate","ps":"BTCUSDT","pu":10998398951393,"s":"BTCUSDT","st":1,"u":10998398982876}
{"E":1783504312352,"T":1783504312351,"U":10998398982923,"a":[["62037.90","0.429"],["62041.00","0.000"],["62041.20","0.003"],["62041.80","0.057"],["62042.60","0.002"],["62042.70","0.222"],["62042.80","0.109"],["62042.90","0.151"],["62043.30","0.004"],["62043.60","0.041"],["62044.20","0.057"],["62044.30","0.486"],["62044.40","0.004"],["62044.50","0.824"],["62044.60","0.002"],["62044.70","0.003"],["62044.90","0.024"],["62045.00","0.003"],["62045.30","0.002"],["62045.40","0.003"],["62045.50","0.823"],["62045.90","0.645"],["62046.60","0.730"],["62046.70","0.000"],["62047.30","0.578"],["62047.80","0.001"],["62048.90","0.581"],["62049.00","0.325"],["62049.20","0.169"],["62049.30","0.619"],["62049.40","0.000"],["62050.00","1.001"],["62050.10","0.188"],["62050.50","0.001"],["62050.80","0.322"],["62051.60","2.145"],["62051.70","0.000"],["62051.80","0.263"],["62052.20","0.001"],["62052.60","0.022"],["62053.80","0.003"],["62054.90","0.375"],["62055.90","0.002"],["62060.70","0.013"],["62061.10","0.489"],["62062.20","0.387"],["62062.40","3.556"],["62062.50","0.000"],["62065.80","0.004"],["62066.30","0.001"],["62066.70","0.072"],["62067.30","0.328"],["62067.50","0.000"],["62067.90","0.009"],["62068.10","0.102"],["62068.30","0.016"],["62068.90","0.007"],["62070.40","0.137"],["62070.90","2.039"],["62072.00","0.313"],["62072.70","0.981"],["62074.20","0.000"],["62074.80","0.166"],["62074.90","0.257"],["62075.00","5.578"],["62075.30","0.449"],["62076.00","0.016"],["62077.00","0.151"],["62078.50","0.131"],["62078.90","0.105"],["62079.00","6.961"],["62080.10","0.000"],["62089.90","0.655"],["62093.40","0.003"],["62096.30","0.001"],["62103.30","18.504"],["62107.40","0.687"],["62107.50","0.286"],["62107.80","0.017"],["62108.10","0.000"],["62108.20","1.941"],["62108.40","0.011"],["62108.60","0.000"],["62109.60","0.016"],["62658.30","0.322"],["62699.70","0.003"],["62776.20","0.958"],["62782.40","2.703"],["63278.60","0.030"],["66059.70","0.051"]],"b":[["1000.00","210.542"],["11534.00","0.912"],["11737.80","0.176"],["11834.00","2.400"],["11837.60","0.016"],["11837.70","0.000"],["11837.80","0.304"],["11934.00","0.672"],["11937.80","0.304"],["55834.00","0.003"],["60797.10","0.013"],["61289.70","0.977"],["61295.80","3.390"],["61306.80","1.969"],["61417.40","0.006"],["61537.80","0.648"],["61624.40","0.252"],["61642.30","0.216"],["61685.70","0.198"],["61708.10","0.306"],["61727.60","0.008"],["61737.50","0.132"],["61797.60","0.309"],["61834.40","0.002"],["61859.50","0.577"],["61906.60","0.652"],["61928.10","11.019"],["61928.20","4.703"],["61962.20","0.992"],["61973.20","0.324"],["61974.10","0.161"],["61975.10","0.000"],["61975.20","0.296"],["61975.30","0.005"],["61979.50","20.799"],["61981.40","0.033"],["61982.40","0.016"],["61984.20","1.432"],["61985.20","0.351"],["61991.70","0.019"],["61992.40","0.027"],["61998.40","0.031"],["61998.60","0.794"],["62004.80","0.003"],["62004.90","1.530"],["62007.00","0.335"],["62008.70","1.025"],["62008.80","0.534"],["62008.90","0.013"],["62009.10","0.050"],["62009.30","0.021"],["62010.10","0.003"],["62010.50","0.060"],["62011.70","2.508"],["62012.70","0.925"],["62014.00","0.137"],["62015.10","0.440"],["62015.30","0.212"],["62015.40","0.000"],["62015.50","0.009"],["62015.70","0.000"],["62016.50","0.178"],["62016.90","0.130"],["62017.80","0.027"],["62018.50","0.666"],["62018.60","0.007"],["62018.90","0.296"],["62019.10","0.002"],["62020.80","0.584"],["62021.90","0.295"],["62022.60","0.007"],["62022.70","0.006"],["62023.10","0.001"],["62023.60","0.005"],["62024.50","0.734"],["62024.80","0.299"],["62026.00","0.776"],["62026.10","0.690"],["62026.40","0.173"],["62027.30","0.002"],["62027.70","0.602"],["62028.00","0.064"],["62028.60","0.606"],["62028.70","0.180"],["62028.80","0.232"],["62030.20","1.420"],["62030.30","0.165"],["62030.40","0.002"],["62030.70","0.002"],["62030.90","0.001"],["62031.30","0.108"],["62031.50","0.247"],["62031.70","0.067"],["62033.20","0.006"],["62033.40","0.001"],["62033.70","0.000"],["62034.10","2.558"],["62034.20","1.796"],["62034.50","0.026"],["62035.00","0.004"],["62035.80","0.000"],["62036.00","0.000"],["62036.40","0.000"],["62037.80","17.904"]],"e":"depthUpdate","ps":"BTCUSDT","pu":10998398982876,"s":"BTCUSDT","st":1,"u":10998398998832}
{"E":1783504312454,"T":1783504312453,"U":10998398998851,"a":[["62037.90","0.849"],["62039.70","0.002"],["62039.80","0.000"],["62040.10","0.000"],["62042.30","0.007"],["62042.50","0.195"],["62042.60","0.269"],["62042.70","0.158"],["62042.80","0.004"],["62043.00","0.110"],["62043.20","0.002"],["62043.30","0.004"],["62043.70","0.556"],["62044.10","0.129"],["62044.30","1.066"],["62044.40","0.004"],["62044.90","0.000"],["62045.30","0.025"],["62045.40","0.165"],["62045.50","0.823"],["62045.80","0.120"],["62047.20","0.051"],["62048.20","0.081"],["62048.50","0.141"],["62048.70","0.121"],["62048.80","1.083"],["62048.90","0.001"],["62049.00","0.325"],["62049.60","0.914"],["62049.80","0.382"],["62050.00","0.001"],["62068.90","0.007"],["62077.40","0.057"],["62091.60","0.068"],["62092.70","0.000"],["62093.70","0.004"],["62098.50","0.009"],["62192.40","0.001"],["62192.50","1.528"],["62209.50","0.005"],["62212.60","0.006"],["62631.60","1.685"],["62656.90","0.003"],["62658.30","0.324"],["62992.90","4.410"],["63278.60","0.036"]],"b":[["11534.00","0.768"],["11737.80","0.304"],["11834.00","2.272"],["11837.80","0.448"],["11934.00","0.528"],["11937.80","0.448"],["55834.00","0.003"],["59556.20","0.007"],["60797.10","0.016"],["61075.00","0.037"],["61243.30","0.843"],["61417.40","0.001"],["61723.80","0.894"],["61834.40","0.001"],["61966.20","0.121"],["61972.50","0.249"],["61975.30","0.003"],["61975.60","0.177"],["61975.80","0.430"],["61979.60","0.002"],["61981.00","0.436"],["61982.00","0.160"],["61994.10","0.055"],["61996.20","0.001"],["61997.00","1.203"],["61998.10","0.000"],["61998.90","0.012"],["61999.60","0.146"],["62004.20","0.001"],["62005.30","0.004"],["62009.90","1.389"],["62011.10","0.100"],["62013.00","0.933"],["62013.30","0.012"],["62015.30","0.374"],["62015.90","0.004"],["62016.60","0.061"],["62019.30","0.062"],["62019.40","0.011"],["62021.70","0.797"],["62022.10","0.164"],["62024.90","0.166"],["62025.00","0.174"],["62027.20","0.137"],["62027.70","0.481"],["62031.10","0.075"],["62034.00","1.901"],["62034.20","1.414"],["62034.30","0.329"],["62034.50","0.002"],["62035.00","0.005"],["62035.30","0.081"],["62035.70","0.000"],["62036.40","0.024"],["62037.30","0.000"],["62037.70","2.193"],["62037.80","17.841"]],"e":"depthUpdate","ps":"BTCUSDT","pu":10998398998832,"s":"BTCUSDT","st":1,"u":10998399008995}
{"E":1783504312556,"T":1783504312555,"U":10998399009009,"a":[["62037.90","2.448"],["62038.00","0.004"],["62038.50","0.000"],["62039.10","0.000"],["62039.40","0.002"],["62041.80","0.008"],["62042.40","0.004"],["62042.50","0.139"],["62042.60","0.164"],["62043.00","0.005"],["62043.30","0.560"],["62044.10","0.001"],["62044.20","0.057"],["62044.30","0.164"],["62044.40","0.342"],["62045.00","0.003"],["62045.30","0.589"],["62045.40","0.165"],["62045.50","0.823"],["62046.50","0.302"],["62046.80","1.053"],["62047.20","0.051"],["62047.30","0.577"],["62048.60","0.000"],["62048.70","0.121"],["62048.80","0.083"],["62049.90","0.003"],["62050.10","0.191"],["62050.30","0.387"],["62050.90","0.418"],["62052.20","0.154"],["62053.10","0.566"],["62053.20","0.618"],["62053.40","0.287"],["62055.60","0.727"],["62057.20","0.005"],["62057.80","0.582"],["62059.10","0.023"],["62059.50","1.340"],["62061.50","0.051"],["62061.80","0.008"],["62064.10","0.172"],["62066.10","0.002"],["62067.70","0.773"],["62068.50","0.003"],["62068.90","0.135"],["62070.40","0.017"],["62074.60","0.001"],["62078.10","1.229"],["62078.60","0.106"],["62078.90","0.000"],["62080.20","0.014"],["62080.80","0.001"],["62081.40","0.691"],["62093.70","0.004"],["62097.50","0.228"],["62131.70","0.008"],["62137.80","0.000"],["62212.60","0.005"],["62658.30","0.320"],["62718.60","0.000"],["62906.40","2.381"],["62910.60","0.000"],["63116.90","2.528"],["63278.60","0.039"],["63289.80","0.000"]],"b":[["11534.00","0.640"],["11737.80","0.448"],["11834.00","2.128"],["11837.80","0.576"],["11934.00","0.400"],["11937.80","0.576"],["49630.00","0.170"],["55834.00","0.003"],["59556.20","0.010"],["61035.40","0.000"],["61220.70","8.970"],["61417.40","0.001"],["61834.40","0.002"],["61975.60","0.192"],["61982.40","0.001"],["62002.90","0.239"],["62003.70","0.135"],["62006.20","0.017"],["62006.70","0.002"],["62006.80","2.189"],["62008.60","0.292"],["62008.70","0.054"],["62013.00","0.805"],["62015.00","0.006"],["62016.80","1.338"],["62016.90","0.001"],["62017.50","0.084"],["62018.10","0.016"],["62018.60","0.136"],["62018.80","1.416"],["62019.70","0.631"],["62020.50","0.000"],["62020.80","0.003"],["62021.30","2.149"],["62022.00","0.749"],["62022.20","0.011"],["62022.90","0.121"],["62023.10","0.001"],["62023.80","0.000"],["62024.30","0.669"],["62024.50","1.138"],["62024.80","0.731"],["62024.90","0.328"],["62025.00","0.053"],["62025.10","0.003"],["62025.40","0.323"],["62025.90","0.036"],["62026.00","0.050"],["62026.10","0.126"],["62027.40","0.090"],["62027.90","0.372"],["62029.40","0.333"],["62029.80","0.053"],["62030.00","0.005"],["62030.60","0.283"],["62031.10","0.059"],["62031.30","0.088"],["62033.50","0.106"],["62033.90","0.323"],["62035.30","0.001"],["62036.90","0.026"],["62037.50","0.005"],["62037.60","0.301"],["62037.70","2.014"],["62037.80","17.424"]],"e":"depthUpdate","ps":"BTCUSDT","pu":10998399008995,"s":"BTCUSDT","st":1,"u":10998399017177}
{"E":1783504312658,"T":1783504312657,"U":10998399017301,"a":[["62037.90","2.283"],["62042.70","0.228"],["62043.30","0.110"],["62043.60","0.041"],["62043.90","0.002"],["62044.00","0.000"],["62044.10","0.001"],["62044.20","0.057"],["62044.40","0.020"],["62045.00","0.003"],["62045.30","0.911"],["62046.50","0.005"],["62048.90","0.001"],["62050.30","0.259"],["62054.20","0.398"],["62061.10","0.454"],["62062.50","0.700"],["62077.20","1.439"],["62078.90","0.000"],["62081.40","0.690"],["62092.80","0.075"],["62093.30","0.317"],["62097.60","0.650"],["62099.10","18.565"],["62100.20","0.031"],["62103.20","0.003"],["62103.30","0.000"],["62131.70","0.140"],["62658.30","0.320"],["62782.40","3.498"],["62999.50","0.951"],["63247.60","0.474"]],"b":[["1000.00","210.542"],["11534.00","0.496"],["11737.80","0.688"],["11834.00","2.000"],["11837.80","0.496"],["11934.00","0.368"],["11937.80","0.720"],["55834.00","0.003"],["58623.90","0.002"],["58932.10","0.003"],["58932.20","0.010"],["58932.30","0.049"],["59556.20","0.007"],["60001.00","1.127"],["61248.50","0.000"],["61258.60","4.535"],["61417.40","0.001"],["61773.00","0.074"],["61834.40","0.001"],["61951.40","0.003"],["61979.50","20.801"],["61980.00","4.978"],["61988.90","1.348"],["62000.30","0.201"],["62006.30","0.800"],["62012.70","0.878"],["62018.10","0.000"],["62022.00","0.702"],["62025.00","0.006"],["62028.50","0.016"],["62030.40","0.164"],["62036.40","0.000"]],"e":"depthUpdate","ps":"BTCUSDT","pu":10998399017177,"s":"BTCUSDT","st":1,"u":10998399024074}
{"E":1783504312760,"T":1783504312757,"U":10998399024163,"a":[["62037.90","0.000"],["62038.00","0.000"],["62038.10","0.000"],["62038.40","0.000"],["62038.70","0.000"],["62038.80","0.000"],["62039.00","0.000"],["62039.30","0.000"],["62039.40","0.000"],["62039.50","0.000"],["62039.70","0.000"],["62039.90","0.000"],["62040.00","0.000"],["62040.30","0.000"],["62040.40","0.000"],["62040.50","0.000"],["62040.60","0.000"],["62040.70","0.000"],["62040.90","0.000"],["62041.10","0.000"],["62041.20","0.000"],["62041.40","0.000"],["62041.60","0.000"],["62041.80","0.000"],["62042.00","9.516"],["62042.10","0.006"],["62042.20","0.001"],["62042.30","0.001"],["62042.40","0.423"],["62042.50","0.026"],["62042.60","0.001"],["62042.70","0.051"],["62042.90","0.001"],["62043.00","0.005"],["62043.10","0.003"],["62043.20","0.001"],["62043.30","0.001"],["62043.40","0.004"],["62043.60","0.300"],["62043.70","0.005"],["62044.10","0.001"],["62044.30","0.002"],["62044.40","0.004"],["62044.50","0.001"],["62044.60","0.000"],["62044.80","0.004"],["62045.00","0.003"],["62045.10","0.323"],["62045.20","0.000"],["62045.30","0.004"],["62045.40","0.003"],["62045.50","0.000"],["62045.60","0.001"],["62045.80","0.126"],["62046.00","0.003"],["62046.10","0.149"],["62046.20","0.130"],["62046.30","0.003"],["62046.40","0.011"],["62046.80","0.053"],["62047.30","0.576"],["62047.40","0.171"],["62047.70","0.299"],["62047.80","1.001"],["62048.20","0.243"],["62048.30","0.653"],["62048.40","0.003"],["62048.50","0.091"],["62048.70","0.023"],["62048.80","0.083"],["62048.90","0.001"],["62049.00","0.167"],["62049.10","0.427"],["62049.30","0.165"],["62049.50","0.062"],["62049.60","0.505"],["62050.10","0.187"],["62050.40","0.290"],["62050.50","0.048"],["62050.90","0.051"],["62051.00","0.002"],["62051.10","0.406"],["62051.20","0.293"],["62051.50","0.001"],["62051.60","0.002"],["62051.80","0.022"],["62051.90","0.246"],["62052.20","0.154"],["62052.50","0.001"],["62052.60","0.021"],["62052.70","0.004"],["62053.10","0.164"],["62053.20","0.937"],["62053.40","0.293"],["62053.60","0.326"],["62053.80","0.897"],["62053.90","1.363"],["62054.10","0.009"],["62054.20","0.363"],["62054.50","0.456"],["62054.60","0.000"],["62054.70","0.000"],["62054.90","0.375"],["62055.50","0.599"],["62055.60","0.002"],["62055.70","0.017"],["62056.00","1.300"],["62056.30","0.000"],["62056.40","1.362"],["62056.90","0.001"],["62057.20","0.327"],["62057.30","0.080"],["62057.60","0.727"],["62057.80","0.003"],["62058.10","0.000"],["62058.60","0.407"],["62058.70","0.002"],["62059.10","0.165"],["62059.30","0.002"],["62059.40","0.415"],["62059.70","0.668"],["62059.80","0.005"],["62060.60","0.584"],["62061.00","0.005"],["62061.50","0.001"],["62061.70","2.146"],["62061.80","0.000"],["62062.10","0.026"],["62062.20","0.225"],["62062.40","3.536"],["62062.60","0.001"],["62062.80","0.012"],["62063.00","0.434"],["62063.10","0.374"],["62063.70","0.017"],["62063.90","0.404"],["62064.10","0.052"],["62065.10","0.562"],["62065.30","0.120"],["62065.80","0.004"],["62066.10","0.002"],["62066.30","0.001"],["62066.70","0.064"],["62066.90","0.531"],["62067.00","0.125"],["62067.20","0.065"],["62067.30","0.328"],["62067.50","0.681"],["62067.60","0.231"],["62067.70","0.683"],["62067.90","0.001"],["62068.20","0.074"],["62068.30","0.022"],["62068.40","0.010"],["62068.50","0.003"],["62068.80","0.005"],["62068.90","0.225"],["62069.00","0.236"],["62069.60","0.028"],["62069.80","0.294"],["62069.90","0.415"],["62070.00","0.310"],["62070.10","0.982"],["62070.70","0.008"],["62071.00","0.072"],["62072.10","0.316"],["62072.70","0.978"],["62073.00","0.268"],["62074.30","0.101"],["62074.90","0.417"],["62075.00","5.578"],["62075.50","1.011"],["62076.40","0.158"],["62076.50","0.714"],["62076.60","0.014"],["62076.70","0.003"],["62077.10","0.111"],["62077.20","1.436"],["62077.40","0.057"],["62078.00","0.163"],["62078.10","1.217"],["62078.20","1.665"],["62078.60","0.001"],["62078.70","3.510"],["62078.80","0.017"],["62078.90","0.000"],["62079.00","4.503"],["62079.60","0.345"],["62080.60","0.006"],["62080.70","0.296"],["62080.80","0.001"],["62081.30","0.887"],["62081.80","0.125"],["62081.90","0.004"],["62082.10","0.002"],["62082.20","0.002"],["62082.30","1.391"],["62083.70","0.083"],["62083.90","0.001"],["62084.00","0.026"],["62084.40","0.766"],["62085.00","0.452"],["62085.20","0.005"],["62085.70","0.017"],["62086.10","0.002"],["62086.80","0.003"],["62087.30","0.003"],["62087.60","0.000"],["62087.70","0.003"],["62088.00","0.304"],["62088.20","0.013"],["62088.60","0.000"],["62089.10","0.005"],["62089.30","0.003"],["62090.10","0.005"],["62090.20","0.010"],["62090.60","0.016"],["62091.10","0.022"],["62091.60","0.053"],["62091.70","0.252"],["62092.20","0.124"],["62093.30","0.292"],["62093.70","0.029"],["62093.90","0.090"],["62094.10","0.716"],["62094.50","0.000"],["62094.60","0.028"],["62094.90","0.059"],["62095.10","0.001"],["62095.80","0.423"],["62095.90","1.098"],["62096.00","1.492"],["62096.70","0.003"],["62097.10","0.009"],["62097.50","0.096"],["62097.60","0.654"],["62098.00","0.000"],["62098.90","0.035"],["62099.10","0.061"],["62099.40","0.101"],["62099.50","1.463"],["62099.70","0.826"],["62099.80","0.606"],["62099.90","1.122"],["62100.40","0.001"],["62100.60","0.000"],["62100.70","0.104"],["62100.80","8.006"],["62101.50","0.003"],["62102.60","0.004"],["62102.90","4.096"],["62103.20","0.001"],["62103.30","0.000"],["62104.00","0.078"],["62104.10","1.491"],["62105.10","0.102"],["62105.40","0.118"],["62109.50","18.435"],["62116.70","0.001"],["62118.60","0.001"],["62131.70","0.008"],["62140.50","0.000"],["62144.60","0.703"],["62146.40","0.738"],["62153.60","1.599"],["62158.00","0.153"],["62161.20","0.283"],["62165.30","0.001"],["62212.40","0.022"],["62215.50","0.001"],["62220.00","3.331"],["62227.30","0.001"],["62282.10","0.000"],["62289.40","0.001"],["62302.70","0.685"],["62302.80","0.657"],["62303.10","0.682"],["62344.10","0.232"],["62351.40","0.003"],["62406.10","0.003"],["62413.40","0.003"],["62468.20","0.800"],["62475.50","0.001"],["62511.10","0.001"],["62530.20","0.957"],["62537.50","0.002"],["62542.20","0.000"],["62573.30","0.017"],["62658.30","0.320"],["62658.40","0.000"],["62659.90","1.323"],["62661.50","0.000"],["62662.40","0.001"],["62751.50","0.001"],["62751.80","0.000"],["62751.90","0.000"],["62752.00","0.046"],["62753.40","1.894"],["62755.90","13.266"],["62798.50","0.808"],["62813.80","0.000"],["62813.90","0.003"],["62814.00","0.000"],["62814.80","0.269"],["62815.40","1.583"],["62817.90","8.386"],["63127.50","1.275"],["63280.20","0.003"],["63282.80","0.010"]],"b":[["11534.00","0.368"],["11737.80","0.784"],["11739.40","0.016"],["11741.80","0.016"],["11741.90","0.144"],["11834.00","1.856"],["11837.80","0.368"],["11937.80","0.752"],["11939.40","0.016"],["11941.90","0.080"],["55834.00","0.001"],["55835.40","0.000"],["55837.70","0.002"],["58935.70","0.000"],["59560.20","0.022"],["61034.00","0.000"],["61035.60","0.008"],["61037.80","0.017"],["61039.40","1.993"],["61079.30","0.288"],["61289.60","4.356"],["61417.40","0.001"],["61417.50","0.009"],["61419.00","0.001"],["61420.60","0.000"],["61421.50","0.000"],["61537.70","0.327"],["61662.90","0.005"],["61669.50","0.006"],["61686.30","0.011"],["61695.20","0.000"],["61698.30","0.000"],["61701.30","0.040"],["61704.50","0.001"],["61723.80","0.884"],["61724.90","1.825"],["61727.60","0.018"],["61731.60","0.001"],["61754.00","0.619"],["61789.60","0.002"],["61791.20","0.001"],["61834.40","0.002"],["61849.00","0.000"],["61855.70","0.650"],["61858.10","0.002"],["61871.50","0.000"],["61879.50","0.669"],["61911.00","0.005"],["61914.50","0.031"],["61917.70","0.002"],["61922.70","0.016"],["61941.90","0.000"],["61943.10","0.000"],["61944.90","0.000"],["61947.30","0.002"],["61951.40","0.002"],["61960.90","1.362"],["61962.10","1.317"],["61962.80","0.648"],["61963.80","0.142"],["61964.00","0.079"],["61965.00","0.121"],["61966.50","0.039"],["61966.90","20.952"],["61967.00","0.235"],["61968.10","0.000"],["61968.80","0.161"],["61971.90","1.118"],["61973.10","0.015"],["61973.20","0.001"],["61974.60","0.000"],["61974.80","0.000"],["61975.30","0.003"],["61975.60","0.177"],["61978.20","0.001"],["61979.50","0.000"],["61979.60","0.000"],["61979.80","0.005"],["61979.90","0.083"],["61980.70","5.987"],["61980.80","0.247"],["61981.00","0.000"],["61981.50","0.003"],["61982.00","0.592"],["61982.10","0.164"],["61982.20","0.121"],["61982.40","0.026"],["61984.30","0.005"],["61984.50","0.035"],["61985.20","0.326"],["61986.10","0.875"],["61987.40","0.000"],["61988.50","0.011"],["61989.00","0.006"],["61989.10","0.003"],["61989.70","0.002"],["61989.90","0.140"],["61990.60","1.298"],["61991.10","0.078"],["61991.30","0.248"],["61991.60","0.004"],["61991.80","1.874"],["61992.50","0.292"],["61992.70","0.000"],["61993.40","0.000"],["61993.70","0.003"],["61994.60","1.859"],["61995.30","0.011"],["61995.40","0.008"],["61996.10","0.000"],["61996.20","0.003"],["61997.70","0.005"],["61997.90","3.849"],["61998.40","0.028"],["61998.60","0.685"],["61998.70","1.901"],["61999.60","0.000"],["61999.70","0.000"],["61999.80","0.050"],["61999.90","0.003"],["62001.70","0.000"],["62001.80","0.681"],["62002.00","0.002"],["62002.30","1.296"],["62002.40","2.433"],["62002.50","0.673"],["62002.80","0.443"],["62002.90","0.107"],["62003.30","0.296"],["62003.50","0.059"],["62003.60","0.005"],["62003.70","0.009"],["62003.80","0.475"],["62003.90","0.004"],["62004.10","0.003"],["62004.40","0.003"],["62004.60","0.019"],["62004.70","0.005"],["62005.00","0.001"],["62005.10","0.003"],["62006.10","1.102"],["62006.20","0.637"],["62006.80","2.061"],["62007.20","0.137"],["62007.40","0.002"],["62007.70","0.004"],["62007.80","0.131"],["62008.00","0.015"],["62008.40","0.003"],["62008.80","0.002"],["62008.90","0.133"],["62009.20","0.577"],["62009.30","0.013"],["62009.80","0.690"],["62009.90","1.479"],["62010.30","0.001"],["62010.40","0.001"],["62010.50","0.052"],["62010.90","0.142"],["62011.00","0.058"],["62011.10","0.010"],["62011.40","0.290"],["62011.50","0.042"],["62011.60","0.011"],["62011.70","0.049"],["62011.80","0.004"],["62012.20","0.058"],["62012.30","0.683"],["62012.40","2.610"],["62012.60","1.301"],["62012.90","2.168"],["62013.00","0.722"],["62013.40","0.120"],["62014.00","0.265"],["62014.50","0.033"],["62014.60","0.290"],["62014.70","0.367"],["62015.10","0.404"],["62015.80","0.000"],["62015.90","0.000"],["62016.00","0.007"],["62016.30","0.347"],["62016.90","0.004"],["62017.00","0.718"],["62017.30","0.048"],["62017.40","0.051"],["62017.70","0.122"],["62017.80","0.015"],["62018.10","0.000"],["62018.20","0.010"],["62018.60","0.006"],["62018.80","1.448"],["62018.90","0.311"],["62019.00","0.086"],["62019.10","0.011"],["62019.20","0.014"],["62019.30","0.066"],["62019.60","1.782"],["62019.70","0.042"],["62019.80","0.010"],["62019.90","0.005"],["62020.10","0.587"],["62020.40","0.296"],["62020.70","0.014"],["62020.80","0.002"],["62021.10","0.001"],["62021.50","0.002"],["62021.70","0.926"],["62021.90","0.163"],["62022.30","0.011"],["62022.40","0.667"],["62022.50","0.002"],["62022.80","0.001"],["62023.20","0.002"],["62023.70","0.149"],["62023.80","0.001"],["62024.30","0.669"],["62024.50","0.412"],["62024.70","0.292"],["62024.80","0.167"],["62024.90","0.892"],["62025.00","0.026"],["62025.60","0.002"],["62025.70","0.020"],["62025.80","0.363"],["62025.90","0.002"],["62026.10","0.852"],["62026.20","0.002"],["62026.70","0.002"],["62026.80","0.000"],["62026.90","0.003"],["62027.00","0.001"],["62027.20","0.135"],["62027.70","0.803"],["62028.00","0.064"],["62028.10","0.240"],["62028.40","0.001"],["62028.50","0.000"],["62028.60","0.686"],["62028.80","0.240"],["62028.90","0.919"],["62029.10","1.032"],["62029.20","0.188"],["62029.30","0.644"],["62029.40","0.019"],["62029.50","0.033"],["62029.80","0.033"],["62030.00","0.006"],["62030.20","1.414"],["62030.50","0.001"],["62031.50","0.246"],["62032.30","0.004"],["62032.40","0.005"],["62032.80","0.155"],["62033.10","0.004"],["62033.30","0.001"],["62033.70","0.001"],["62033.90","1.123"],["62034.00","1.893"],["62034.10","0.764"],["62034.20","1.364"],["62034.30","0.001"],["62034.70","0.001"],["62035.20","0.001"],["62035.40","0.003"],["62035.60","0.003"],["62035.80","0.003"],["62035.90","0.264"],["62036.00","0.253"],["62036.10","0.052"],["62036.70","0.065"],["62036.80","0.050"],["62036.90","0.003"],["62037.00","0.000"],["62037.20","0.001"],["62037.50","0.003"],["62037.60","0.301"],["62037.70","0.012"],["62037.80","0.086"],["62037.90","1.881"],["62038.00","2.575"],["62038.10","0.001"],["62038.20","0.040"],["62038.30","0.000"],["62038.40","0.001"],["62038.60","0.001"],["62038.70","0.000"],["62038.80","0.056"],["62038.90","0.000"],["62039.00","0.000"],["62039.10","0.000"],["62039.20","0.002"],["62039.30","0.000"],["62039.40","0.003"],["62039.50","1.953"],["62039.60","0.002"],["62039.80","0.001"],["62039.90","0.000"],["62040.00","0.003"],["62040.20","0.000"],["62040.30","0.001"],["62040.40","0.002"],["62040.50","0.000"],["62040.60","0.001"],["62040.80","0.001"],["62040.90","0.000"],["62041.00","0.001"],["62041.10","0.032"],["62041.30","0.000"],["62041.50","0.000"],["62041.70","0.001"],["62041.80","0.006"],["62041.90","11.117"]],"e":"depthUpdate","ps":"BTCUSDT","pu":10998399024074,"s":"BTCUSDT","st":1,"u":10998399035152}
{"E":1783504312862,"T":1783504312861,"U":10998399035334,"a":[["62042.00","9.518"],["62042.10","0.002"],["62042.40","0.457"],["62042.70","0.002"],["62043.50","0.000"],["62045.00","0.001"],["62045.70","0.297"],["62045.80","0.423"],["62046.00","0.005"],["62047.20","0.051"],["62047.70","0.002"],["62048.20","0.243"],["62048.60","0.003"],["62049.00","0.169"],["62051.10","0.408"],["62051.90","0.005"],["62052.10","0.453"],["62052.20","0.213"],["62052.40","0.409"],["62052.50","0.368"],["62052.90","0.323"],["62053.10","0.002"],["62054.80","0.004"],["62054.90","0.213"],["62055.00","0.965"],["62055.20","0.630"],["62057.20","0.005"],["62059.10","0.003"],["62062.00","0.025"],["62062.50","0.000"],["62066.30","0.065"],["62066.70","0.064"],["62067.20","0.001"],["62068.30","0.002"],["62069.80","0.132"],["62078.00","0.268"],["62078.10","1.322"],["62078.20","1.560"],["62082.50","0.043"],["62083.10","0.002"],["62083.70","0.084"],["62084.30","0.002"],["62085.00","0.552"],["62102.90","4.094"],["62103.20","0.102"],["62103.30","18.437"],["62103.40","0.155"],["62105.10","0.001"],["62105.40","0.017"],["62106.20","0.011"],["62109.50","0.000"],["62110.10","0.048"],["62131.70","0.000"],["62138.00","0.692"],["62662.40","0.001"],["62699.60","0.000"],["62753.40","0.000"],["62755.90","15.160"],["62815.40","0.795"],["62817.90","9.174"],["64500.00","53.075"]],"b":[["11534.00","0.224"],["11741.90","0.416"],["11834.00","1.728"],["11837.80","0.224"],["11941.90","0.224"],["49630.30","0.000"],["55837.70","0.002"],["58932.20","0.012"],["60483.10","5.493"],["61421.50","0.000"],["61764.90","0.000"],["61768.20","0.008"],["61834.40","0.001"],["61902.10","1.377"],["61917.10","0.739"],["61940.90","1.131"],["61941.80","0.275"],["61946.60","2.156"],["61966.70","0.046"],["61966.90","0.021"],["61973.50","0.187"],["61979.50","0.002"],["61980.70","5.985"],["61982.50","0.000"],["61983.60","21.601"],["61989.40","0.211"],["61991.70","0.017"],["61995.10","0.005"],["61995.20","0.778"],["61995.80","0.951"],["61996.40","0.001"],["61997.00","1.202"],["61997.60","0.016"],["61998.20","0.000"],["62000.40","0.087"],["62004.70","0.009"],["62008.70","0.005"],["62010.90","0.014"],["62015.30","0.212"],["62015.60","0.050"],["62016.40","0.733"],["62022.00","0.782"],["62022.10","0.002"],["62023.50","1.301"],["62024.90","0.568"],["62026.90","0.425"],["62027.70","1.022"],["62028.60","0.606"],["62030.00","0.004"],["62030.40","0.002"],["62035.00","0.007"],["62036.80","0.051"],["62036.90","0.004"],["62037.40","0.001"],["62037.80","0.079"],["62037.90","1.839"],["62038.00","2.578"],["62038.80","0.057"],["62040.20","0.080"],["62041.80","0.055"],["62041.90","11.120"]],"e":"depthUpdate","ps":"BTCUSDT","pu":10998399035152,"s":"BTCUSDT","st":1,"u":10998399046069}
{"E":1783504312964,"T":1783504312961,"U":10998399046371,"a":[["62042.00","9.526"],["62042.40","0.276"],["62043.30","0.000"],["62043.60","0.299"],["62045.10","0.000"],["62045.70","0.292"],["62045.80","0.682"],["62046.40","0.010"],["62047.70","0.002"],["62048.90","0.163"],["62049.50","0.062"],["62051.00","0.000"],["62052.30","0.323"],["62052.90","0.163"],["62053.50","0.022"],["62054.40","0.133"],["62054.90","0.697"],["62059.10","0.165"],["62063.60","0.022"],["62067.60","0.069"],["62068.90","0.097"],["62069.00","0.108"],["62069.80","0.294"],["62073.00","0.140"],["62074.80","0.328"],["62078.20","1.665"],["62083.10","2.458"],["62084.40","0.767"],["62100.90","0.004"],["62102.50","0.003"],["62103.30","0.002"],["62104.60","0.350"],["62105.20","0.425"],["62105.30","18.438"],["62150.70","0.023"],["62150.80","1.533"],["62171.10","0.001"],["62171.60","0.003"],["62171.70","1.556"],["62398.30","0.000"],["62402.50","0.008"],["62538.10","0.319"],["62656.90","0.000"],["62658.90","2.131"],["62662.40","0.001"],["62663.10","0.008"],["62886.90","0.793"],["62950.80","0.559"]],"b":[["1000.00","210.542"],["11534.00","0.096"],["11741.90","0.688"],["11834.00","1.584"],["11837.80","0.096"],["11941.90","0.352"],["55837.70","0.002"],["59560.20","0.019"],["61421.50","0.000"],["61545.60","0.000"],["61731.70","0.001"],["61776.70","0.000"],["61776.80","0.105"],["61778.40","0.003"],["61782.00","0.012"],["61782.10","0.002"],["61793.70","0.124"],["61834.40","0.002"],["61859.40","0.000"],["61859.50","1.536"],["61903.40","0.000"],["61984.10","0.102"],["61984.20","2.962"],["61991.80","1.814"],["61998.70","1.961"],["61998.80","0.064"],["62000.20","1.315"],["62004.90","0.001"],["62005.00","1.530"],["62008.80","0.000"],["62011.00","0.014"],["62015.80","2.459"],["62016.40","0.777"],["62018.90","0.295"],["62019.00","0.119"],["62019.70","0.003"],["62021.30","2.148"],["62022.00","0.702"],["62023.70","0.003"],["62025.20","0.042"],["62025.30","0.003"],["62028.70","0.182"],["62029.50","0.034"],["62030.70","0.041"],["62031.50","0.172"],["62037.80","0.013"],["62037.90","1.839"],["62038.40","0.076"],["62041.60","0.049"],["62041.80","0.006"],["62041.90","11.270"]],"e":"depthUpdate","ps":"BTCUSDT","pu":10998399046069,"s":"BTCUSDT","st":1,"u":10998399056627}
{"E":1783504313066,"T":1783504313065,"U":10998399056905,"a":[["62042.00","9.532"],["62042.40","0.441"],["62043.50","0.000"],["62045.50","0.297"],["62045.60","0.002"],["62045.70","0.293"],["62045.80","0.126"],["62046.50","0.154"],["62047.70","0.002"],["62048.20","0.243"],["62052.40","0.413"],["62060.70","0.014"],["62063.70","0.007"],["62068.40","0.020"],["62074.80","0.165"],["62075.50","1.007"],["62078.20","1.560"],["62096.00","1.492"],["62104.00","0.179"],["62104.10","1.592"],["62104.20","0.657"],["62104.60","0.249"],["62173.20","1.280"],["62344.30","0.110"],["62635.80","1.355"],["62662.40","0.001"]],"b":[["11534.00","0.000"],["11741.90","0.960"],["11834.00","1.424"],["11837.60","0.000"],["11837.80","0.000"],["11841.90","0.048"],["11941.90","0.400"],["55837.70","0.002"],["59560.20","0.022"],["61421.50","0.000"],["61727.60","0.018"],["61834.40","0.001"],["61906.40","0.857"],["61943.50","0.080"],["61944.70","0.103"],["61948.80","0.000"],["61975.30","20.934"],["61975.40","0.287"],["61981.60","0.002"],["61983.60","0.670"],["61991.10","0.076"],["61994.10","0.071"],["62003.40","0.019"],["62012.70","0.894"],["62014.00","0.137"],["62015.80","2.475"],["62018.90","0.311"],["62026.90","0.003"],["62034.00","1.892"],["62034.20","1.363"],["62037.40","0.024"],["62037.60","0.300"],["62037.90","1.834"],["62041.30","0.004"],["62041.90","11.272"]],"e":"depthUpdate","ps":"BTCUSDT","pu":10998399056627,"s":"BTCUSDT","st":1,"u":10998399065139}
{"E":1783504313168,"T":1783504313166,"U":10998399065212,"a":[["62042.00","9.540"],["62042.40","0.323"],["62045.50","0.000"],["62045.70","0.293"],["62045.80","0.126"],["62046.50","0.005"],["62047.70","0.151"],["62049.50","0.062"],["62050.60","0.243"],["62051.10","0.406"],["62052.00","0.008"],["62052.40","0.170"],["62053.40","0.287"],["62053.60","0.324"],["62054.10","0.011"],["62058.80","0.459"],["62078.20","1.665"],["62082.00","0.001"],["62089.90","0.657"],["62096.20","0.098"],["62097.20","0.001"],["62098.90","0.038"],["62104.20","0.758"],["62104.60","0.249"],["62113.10","0.001"],["62121.00","0.003"],["62135.70","0.000"],["62144.20","0.092"],["62152.10","0.031"],["62222.80","0.000"],["62223.10","0.003"],["62662.40","0.001"],["62896.00","17.550"],["62931.70","4.316"]],"b":[["11741.90","1.232"],["11834.00","1.152"],["11841.90","0.176"],["11941.90","0.272"],["55821.30","0.000"],["55837.70","0.002"],["59560.20","0.019"],["61421.50","0.000"],["61525.00","5.097"],["61731.60","0.002"],["61834.40","0.001"],["61920.30","0.002"],["61923.90","1.368"],["61932.00","0.123"],["61939.40","0.245"],["61943.60","0.215"],["61943.90","0.006"],["61954.90","0.000"],["61963.00","0.033"],["61963.80","0.010"],["61967.00","0.103"],["61969.40","0.686"],["61975.30","0.003"],["61975.40","0.285"],["61975.60","0.193"],["61979.50","20.933"],["61979.60","0.002"],["61981.00","0.436"],["61985.90","0.032"],["61994.00","0.004"],["62002.80","0.221"],["62002.90","0.239"],["62014.10","0.015"],["62017.00","0.716"],["62017.10","0.130"],["62028.80","0.242"],["62030.20","1.122"],["62030.30","0.457"],["62034.10","0.765"],["62034.30","0.000"],["62036.70","0.042"],["62036.80","0.052"],["62037.00","0.001"],["62037.50","0.005"],["62038.10","0.002"],["62039.60","0.003"],["62041.60","0.000"],["62041.90","11.257"]],"e":"depthUpdate","ps":"BTCUSDT","pu":10998399065139,"s":"BTCUSDT","st":1,"u":10998399074853}
{"E":1783504313270,"T":1783504313269,"U":10998399074949,"a":[["62042.00","9.539"],["62042.40","0.274"],["62045.60","0.554"],["62045.80","0.420"],["62046.50","0.152"],["62047.70","0.149"],["62052.00","0.002"],["62054.00","0.018"],["62057.50","0.000"],["62059.60","0.164"],["62062.50","0.700"],["62063.60","0.085"],["62066.30","0.838"],["62066.60","0.295"],["62081.40","0.746"],["62099.60","3.453"],["62105.30","0.003"],["62107.50","18.721"],["62109.60","0.016"],["62118.00","0.499"],["62161.40","0.623"],["62189.20","0.811"],["62209.50","0.251"],["62236.20","0.360"],["62258.00","0.449"],["62282.20","1.039"],["62302.00","0.485"],["62344.10","0.523"],["62348.10","0.254"],["62606.60","0.008"],["62662.40","0.001"],["62786.50","3.788"],["62817.50","0.318"],["62892.00","5.678"],["63274.50","0.009"]],"b":[["1000.00","210.542"],["11741.90","1.504"],["11834.00","0.880"],["11841.90","0.320"],["11941.90","0.128"],["49627.00","0.000"],["55837.70","0.002"],["58468.40","0.002"],["60793.20","0.013"],["60793.40","0.012"],["61243.30","0.028"],["61289.60","4.845"],["61421.50","0.000"],["61834.40","0.002"],["61984.50","0.092"],["61992.10","0.752"],["61998.40","0.014"],["62001.60","0.130"],["62003.80","0.405"],["62005.30","0.018"],["62007.60","0.003"],["62007.80","0.131"],["62010.70","0.071"],["62037.80","0.005"],["62041.90","11.265"]],"e":"depthUpdate","ps":"BTCUSDT","pu":10998399074853,"s":"BTCUSDT","st":1,"u":10998399081291}
{"E":1783504313372,"T":1783504313371,"U":10998399081348,"a":[["62042.40","0.274"],["62045.10","0.002"],["62045.60","0.554"],["62045.80","0.128"],["62046.30","0.004"],["62046.50","0.005"],["62046.70","0.002"],["62047.70","0.002"],["62047.80","1.003"],["62048.80","0.084"],["62053.80","0.895"],["62057.90","0.009"],["62066.60","0.279"],["62068.40","0.010"],["62075.20","0.401"],["62076.40","0.053"],["62077.10","0.006"],["62078.20","1.560"],["62099.40","0.000"],["62099.50","1.362"],["62102.80","1.745"],["62103.20","0.001"],["62103.80","0.424"],["62104.00","0.078"],["62104.10","1.491"],["62104.20","0.657"],["62130.70","0.001"],["62363.90","0.339"],["62381.40","0.278"],["62407.80","0.575"],["62434.80","0.999"],["62538.30","0.469"],["62662.40","0.001"],["62786.50","4.503"],["62910.50","3.175"]],"b":[["11741.90","1.776"],["11834.00","0.608"],["11841.90","0.448"],["11941.90","0.000"],["55837.70","0.002"],["58932.10","0.000"],["58932.20","0.015"],["59560.20","0.022"],["60801.10","0.071"],["61421.50","0.000"],["61670.50","0.139"],["61705.10","0.157"],["61727.60","0.008"],["61727.70","0.010"],["61731.60","0.003"],["61781.60","0.213"],["61834.40","0.001"],["61859.60","0.578"],["61968.30","0.850"],["61979.50","0.002"],["61979.60","0.000"],["61980.80","0.249"],["61981.60","20.933"],["61983.20","0.019"],["61986.60","0.612"],["62014.60","0.298"],["62018.50","0.973"],["62022.70","0.004"],["62024.70","0.000"],["62026.80","0.002"],["62027.60","1.688"],["62029.50","0.162"],["62030.30","0.165"],["62032.30","0.002"],["62036.90","0.008"],["62038.50","0.006"],["62039.60","0.005"],["62041.00","0.002"]],"e":"depthUpdate","ps":"BTCUSDT","pu":10998399081291,"s":"BTCUSDT","st":1,"u":10998399086530}
{"E":1783504313474,"T":1783504313473,"U":10998399086617,"a":[["62042.00","9.073"],["62045.50","0.000"],["62045.60","0.002"],["62045.70","0.292"],["62054.40","0.005"],["62054.90","0.375"],["62055.10","0.002"],["62055.90","0.324"],["62060.60","0.712"],["62067.40","0.659"],["62069.80","0.162"],["62069.90","0.543"],["62097.50","0.228"],["62104.00","0.078"],["62146.30","0.012"],["62620.70","7.354"],["62634.20","1.375"],["62662.40","0.001"],["62695.80","0.003"],["63274.50","0.006"]],"b":[["1000.00","210.542"],["11641.90","0.064"],["11741.90","1.920"],["11834.00","0.400"],["11841.90","0.592"],["11937.80","0.624"],["11939.40","0.000"],["55837.70","0.002"],["59560.20","0.019"],["60793.40","0.009"],["61154.80","5.107"],["61221.30","0.326"],["61400.00","34.219"],["61421.50","0.000"],["61723.80","0.882"],["61727.60","0.007"],["61731.70","0.000"],["61834.40","0.002"],["61940.90","1.031"],["61969.70","0.028"],["61972.50","0.149"],["62003.10","0.103"],["62007.80","0.003"],["62017.00","0.681"],["62017.10","0.002"],["62024.40","0.967"],["62024.60","0.294"],["62025.00","0.061"],["62026.10","0.126"],["62027.50","0.002"],["62028.90","0.597"],["62030.30","0.457"],["62030.40","0.324"],["62041.60","0.000"],["62041.90","11.267"]],"e":"depthUpdate","ps":"BTCUSDT","pu":10998399086530,"s":"BTCUSDT","st":1,"u":10998399093359}
