{"E":1783504328264,"T":1783504328263,"U":10998400870239,"a":[["62059.70","0.000"],["62059.80","0.000"],["62059.90","0.000"],["62060.00","0.000"],["62060.30","0.000"],["62060.40","0.000"],["62060.50","0.000"],["62060.60","0.000"],["62060.70","0.000"],["62060.80","0.000"],["62061.00","0.000"],["62061.10","0.000"],["62061.20","0.000"],["62061.30","0.000"],["62061.50","0.000"],["62061.60","0.000"],["62061.70","0.000"],["62061.80","0.000"],["62061.90","0.000"],["62062.00","0.000"],["62062.20","0.000"],["62062.40","0.000"],["62062.60","0.000"],["62062.80","0.000"],["62062.90","0.000"],["62063.00","0.000"],["62063.10","0.000"],["62063.20","0.000"],["62063.30","0.000"],["62063.40","0.000"],["62063.50","0.000"],["62063.60","0.000"],["62063.70","0.000"],["62063.80","7.788"],["62063.90","0.008"],["62064.00","0.002"],["62064.10","0.004"],["62064.20","0.001"],["62064.40","0.000"],["62064.50","0.001"],["62064.60","0.000"],["62064.70","0.008"],["62064.80","0.001"],["62064.90","0.001"],["62065.00","0.004"],["62065.10","0.008"],["62065.40","0.006"],["62065.60","0.001"],["62065.70","0.001"],["62065.90","0.001"],["62066.00","0.002"],["62066.10","0.000"],["62066.20","0.001"],["62066.30","0.003"],["62066.50","0.000"],["62066.60","0.004"],["62066.70","0.068"],["62066.80","0.024"],["62067.00","0.056"],["62067.10","0.005"],["62067.20","0.164"],["62067.30","0.321"],["62067.40","0.327"],["62067.50","0.001"],["62067.60","0.131"],["62067.70","0.000"],["62067.80","0.003"],["62067.90","0.002"],["62068.00","0.244"],["62068.10","0.006"],["62068.20","1.757"],["62068.40","0.002"],["62068.50","0.000"],["62068.60","0.000"],["62068.70","0.642"],["62068.80","0.633"],["62069.00","0.051"],["62069.10","0.002"],["62069.20","0.190"],["62069.30","0.096"],["62069.40","0.246"],["62069.70","0.001"],["62069.80","1.362"],["62069.90","1.005"],["62070.00","0.050"],["62070.10","0.002"],["62070.20","0.007"],["62070.30","0.002"],["62070.40","0.068"],["62070.60","0.083"],["62070.80","0.000"],["62070.90","0.001"],["62071.00","0.016"],["62071.10","0.698"],["62071.20","0.163"],["62071.30","0.005"],["62071.40","0.328"],["62071.50","0.123"],["62071.60","0.349"],["62071.70","0.000"],["62071.80","0.011"],["62071.90","0.026"],["62072.00","0.555"],["62072.10","0.011"],["62072.20","0.002"],["62072.30","0.061"],["62072.40","0.050"],["62072.50","0.244"],["62072.60","1.687"],["62072.70","0.000"],["62072.90","0.005"],["62073.00","0.174"],["62073.10","0.401"],["62073.20","0.630"],["62073.40","0.004"],["62073.50","0.003"],["62073.70","0.002"],["62074.50","0.902"],["62074.60","0.286"],["62074.70","0.004"],["62074.80","0.699"],["62074.90","0.407"],["62075.00","0.007"],["62075.10","0.008"],["62075.20","0.472"],["62075.30","0.122"],["62075.40","0.084"],["62075.60","0.022"],["62075.70","0.251"],["62075.80","0.001"],["62075.90","0.126"],["62076.00","0.005"],["62076.10","0.405"],["62076.40","0.073"],["62076.50","0.002"],["62076.70","0.000"],["62076.80","0.423"],["62077.00","1.352"],["62077.10","0.011"],["62077.20","0.002"],["62077.40","0.002"],["62077.50","0.008"],["62077.70","0.001"],["62077.90","0.567"],["62078.00","1.011"],["62078.10","0.000"],["62078.20","0.000"],["62078.30","0.171"],["62078.60","0.859"],["62078.70","0.344"],["62078.90","0.725"],["62079.00","0.403"],["62079.10","0.005"],["62079.20","0.097"],["62079.30","0.313"],["62079.40","0.000"],["62079.50","1.526"],["62079.60","0.323"],["62079.70","0.001"],["62079.90","0.875"],["62080.00","1.073"],["62080.20","0.014"],["62080.50","0.057"],["62080.60","0.026"],["62080.80","0.073"],["62080.90","0.105"],["62081.00","0.579"],["62081.10","0.005"],["62081.30","1.297"],["62081.40","0.707"],["62081.90","0.108"],["62082.00","0.034"],["62082.10","0.172"],["62082.20","0.350"],["62082.30","1.451"],["62082.40","1.344"],["62082.60","0.003"],["62082.80","0.028"],["62082.90","0.164"],["62083.00","2.440"],["62083.10","2.194"],["62083.30","0.151"],["62083.70","0.084"],["62083.80","0.801"],["62083.90","0.007"],["62084.00","0.149"],["62084.10","13.512"],["62085.00","0.014"],["62085.20","0.004"],["62085.30","0.000"],["62085.40","0.455"],["62085.50","0.652"],["62085.60","0.121"],["62085.90","0.686"],["62086.00","0.061"],["62086.60","0.209"],["62086.70","0.000"],["62086.80","0.017"],["62087.10","0.011"],["62087.50","0.057"],["62087.60","0.000"],["62087.80","3.133"],["62088.00","0.364"],["62088.20","0.011"],["62088.30","0.121"],["62088.40","0.749"],["62088.60","0.049"],["62088.80","0.010"],["62088.90","0.231"],["62089.00","0.898"],["62089.10","9.405"],["62089.30","0.093"],["62089.60","0.076"],["62089.80","2.679"],["62089.90","0.659"],["62090.00","0.323"],["62090.20","0.003"],["62090.30","2.226"],["62090.60","0.185"],["62090.70","0.009"],["62091.00","0.026"],["62091.10","0.011"],["62091.20","0.107"],["62091.30","0.649"],["62091.40","0.196"],["62091.50","1.362"],["62091.60","0.000"],["62091.70","0.195"],["62091.80","0.531"],["62091.90","0.008"],["62092.00","0.003"],["62092.20","0.000"],["62092.50","0.965"],["62092.90","0.049"],["62093.00","0.297"],["62093.20","0.003"],["62093.30","1.218"],["62093.40","0.005"],["62093.90","0.252"],["62094.00","0.956"],["62094.10","0.686"],["62094.20","0.765"],["62094.30","0.001"],["62094.40","0.661"],["62094.60","0.004"],["62094.70","0.122"],["62094.80","0.021"],["62094.90","0.179"],["62095.00","0.302"],["62095.20","0.022"],["62095.40","0.016"],["62095.50","0.013"],["62095.80","0.325"],["62095.90","0.001"],["62096.00","1.367"],["62096.20","0.002"],["62096.30","0.001"],["62096.40","0.583"],["62096.60","0.542"],["62096.80","0.067"],["62097.40","0.091"],["62097.60","0.649"],["62097.80","0.722"],["62098.00","0.015"],["62098.20","0.000"],["62098.30","0.028"],["62098.40","0.011"],["62098.50","0.000"],["62098.70","0.035"],["62099.00","0.027"],["62099.20","0.165"],["62099.30","0.031"],["62099.50","2.288"],["62099.70","0.658"],["62099.90","0.722"],["62100.00","0.745"],["62100.20","0.003"],["62100.30","0.001"],["62100.70","0.033"],["62100.80","0.006"],["62101.00","0.076"],["62101.10","0.529"],["62101.30","0.001"],["62101.60","0.000"],["62101.80","0.018"],["62102.30","0.016"],["62102.60","0.000"],["62102.70","0.048"],["62103.00","0.001"],["62103.10","0.082"],["62103.30","0.011"],["62103.40","0.001"],["62103.60","0.001"],["62103.70","0.452"],["62104.20","0.657"],["62104.30","0.294"],["62104.40","0.003"],["62105.00","0.154"],["62105.10","0.001"],["62105.20","0.258"],["62105.30","0.246"],["62105.80","0.001"],["62106.00","0.031"],["62106.30","0.000"],["62106.50","0.001"],["62106.60","0.664"],["62106.80","0.012"],["62106.90","0.048"],["62107.20","0.004"],["62107.50","0.349"],["62108.90","0.805"],["62109.30","0.032"],["62109.50","0.000"],["62109.60","0.033"],["62109.70","1.295"],["62109.90","3.210"],["62110.10","3.508"],["62110.20","0.282"],["62110.30","0.004"],["62110.40","0.001"],["62110.80","0.573"],["62110.90","6.302"],["62111.00","0.518"],["62111.20","0.056"],["62112.00","0.062"],["62112.10","0.018"],["62112.90","0.011"],["62113.20","0.013"],["62113.50","0.657"],["62114.00","0.013"],["62114.10","0.029"],["62114.50","0.688"],["62115.10","0.002"],["62115.60","0.110"],["62115.90","0.011"],["62116.00","0.008"],["62117.00","0.152"],["62117.10","1.321"],["62117.50","1.200"],["62117.60","0.455"],["62117.80","0.031"],["62118.00","2.496"],["62118.20","0.000"],["62119.40","0.016"],["62119.80","0.327"],["62120.00","0.406"],["62120.30","0.004"],["62122.10","0.002"],["62122.60","0.001"],["62122.90","0.698"],["62124.20","0.002"],["62125.00","0.175"],["62125.30","0.004"],["62125.40","0.524"],["62125.60","0.014"],["62125.90","0.002"],["62126.20","8.003"],["62126.30","1.616"],["62126.70","0.047"],["62127.40","0.000"],["62128.40","23.771"],["62128.70","0.077"],["62128.80","0.173"],["62129.90","0.247"],["62130.50","0.000"],["62132.60","0.000"],["62133.00","1.370"],["62134.50","0.000"],["62135.00","0.124"],["62136.40","0.707"],["62137.60","0.002"],["62139.50","0.018"],["62141.30","0.019"],["62141.40","0.667"],["62141.90","0.453"],["62142.30","0.875"],["62142.60","0.015"],["62145.60","1.302"],["62145.90","0.008"],["62146.60","0.072"],["62146.70","0.003"],["62148.30","0.001"],["62149.80","0.292"],["62150.40","4.863"],["62153.60","0.001"],["62154.60","0.041"],["62154.70","0.010"],["62156.80","0.131"],["62160.00","0.563"],["62160.50","0.672"],["62160.60","0.014"],["62160.90","0.213"],["62164.40","0.707"],["62165.00","0.702"],["62165.20","8.456"],["62167.10","0.005"],["62173.50","0.000"],["62174.20","0.000"],["62174.60","0.000"],["62177.90","0.000"],["62179.50","0.413"],["62179.80","3.043"],["62181.20","12.186"],["62183.30","0.103"],["62184.60","0.003"],["62188.50","0.959"],["62198.60","0.014"],["62202.60","0.000"],["62202.90","0.002"],["62211.90","0.086"],["62215.50","0.071"],["62218.90","0.015"],["62227.90","0.240"],["62230.10","0.001"],["62230.60","1.110"],["62231.50","0.001"],["62236.10","0.078"],["62236.40","2.751"],["62237.40","0.031"],["62238.60","1.693"],["62239.90","0.000"],["62240.00","0.625"],["62240.40","0.001"],["62242.30","0.001"],["62243.50","0.877"],["62246.70","0.301"],["62252.70","0.010"],["62260.80","1.455"],["62260.90","4.021"],["62262.30","0.003"],["62265.20","0.000"],["62290.70","0.594"],["62302.00","0.485"],["62306.30","0.000"],["62308.10","0.001"],["62308.70","0.001"],["62320.00","0.561"],["62324.50","0.683"],["62324.60","2.899"],["62324.80","0.678"],["62325.50","0.000"],["62335.10","1.552"],["62335.20","6.287"],["62336.00","0.002"],["62344.30","0.114"],["62364.00","1.602"],["62370.00","0.039"],["62370.80","0.013"],["62372.00","0.291"],["62377.30","0.004"],["62379.40","0.001"],["62380.50","0.204"],["62388.70","0.001"],["62400.00","14.516"],["62426.00","0.162"],["62432.30","0.001"],["62463.90","0.165"],["62488.10","0.000"],["62492.90","0.000"],["62493.20","0.000"],["62494.50","0.493"],["62494.90","0.500"],["62495.00","0.265"],["62495.50","0.108"],["62496.30","0.001"],["62497.20","0.249"],["62550.10","0.000"],["62556.40","0.001"],["62569.70","0.002"],["62606.50","4.791"],["62607.10","0.128"],["62638.80","0.088"],["62653.20","0.714"],["62665.60","0.953"],["62680.30","0.000"],["62681.10","0.012"],["62681.20","0.000"],["62683.40","0.107"],["62684.00","0.008"],["62684.40","2.339"],["62715.30","0.792"],["62773.50","0.000"],["62773.80","0.000"],["62773.90","0.003"],["62774.60","3.784"],["62774.70","3.787"],["62775.40","0.000"],["62775.80","8.580"],["62776.00","1.010"],["62777.10","6.487"],["62778.00","6.622"],["62808.40","18.155"],["62835.60","0.010"],["62835.90","0.000"],["62836.00","0.000"],["62836.10","0.000"],["62836.70","0.248"],["62836.80","5.516"],["62837.80","37.683"],["62840.00","4.676"],["62853.10","0.014"],["62867.10","0.238"],["62870.40","7.085"],["62899.40","0.018"],["62899.80","7.873"],["62900.40","1.031"],["62901.00","0.770"],["62901.20","1.481"],["62930.40","1.652"],["62930.90","9.027"],["62931.30","2.360"],["62932.20","5.396"],["62932.50","26.747"],["62948.40","0.000"],["62963.50","13.054"],["62972.00","1.269"],["62992.90","3.300"],["62994.20","4.440"],["63025.60","6.442"],["63056.00","0.000"],["63056.20","1.111"],["63087.60","2.229"],["63289.20","0.003"],["89523.20","0.180"]],"b":[["1000.00","210.942"],["11559.60","2.496"],["11560.50","0.000"],["11658.00","0.000"],["11660.50","0.048"],["11663.70","0.080"],["11759.60","0.256"],["11959.60","0.464"],["11960.50","0.064"],["11962.10","0.016"],["11963.70","0.160"],["49648.00","0.000"],["55853.60","0.003"],["55854.40","0.000"],["55856.30","0.010"],["55857.30","0.002"],["56512.20","0.000"],["56541.10","0.611"],["58957.40","0.000"],["60819.30","0.003"],["60822.50","0.003"],["61040.70","0.003"],["61058.00","0.002"],["61060.40","0.002"],["61060.50","0.026"],["61439.00","0.313"],["61439.80","0.000"],["61439.90","0.012"],["61441.50","0.000"],["61442.10","0.000"],["61442.20","0.244"],["61443.10","0.000"],["61640.60","0.047"],["61680.00","1.117"],["61682.90","0.000"],["61689.70","0.001"],["61713.90","0.000"],["61742.10","0.035"],["61744.90","2.425"],["61748.00","0.147"],["61748.10","0.005"],["61748.90","0.310"],["61750.10","0.001"],["61751.80","0.121"],["61752.00","0.072"],["61760.00","0.609"],["61776.70","7.896"],["61776.80","1.275"],["61781.50","0.000"],["61838.10","0.000"],["61840.00","0.465"],["61847.20","0.003"],["61848.20","0.000"],["61855.00","1.411"],["61869.00","0.000"],["61869.90","0.030"],["61871.00","0.282"],["61875.90","0.595"],["61881.30","0.153"],["61882.30","0.026"],["61884.00","23.539"],["61901.80","4.969"],["61902.30","0.003"],["61920.00","0.522"],["61924.30","0.000"],["61931.10","2.081"],["61935.00","0.003"],["61935.90","0.028"],["61938.00","0.006"],["61943.50","0.081"],["61959.30","0.455"],["61959.70","0.001"],["61960.50","0.153"],["61961.10","0.000"],["61966.80","0.014"],["61975.10","1.326"],["61975.90","0.124"],["61977.00","0.000"],["61977.30","0.045"],["61979.50","19.447"],["61979.90","0.001"],["61982.10","0.037"],["61983.70","0.013"],["61985.30","0.000"],["61985.60","0.001"],["61985.80","0.002"],["61986.10","0.875"],["61986.20","0.002"],["61986.70","0.041"],["61988.30","0.045"],["61988.70","0.001"],["61989.00","0.157"],["61991.20","0.000"],["61993.10","0.001"],["61993.20","0.002"],["61993.70","0.002"],["61994.50","1.367"],["61995.00","0.065"],["61995.10","0.001"],["61995.20","0.679"],["61995.60","0.000"],["61995.90","0.001"],["61996.20","0.000"],["61996.30","0.001"],["61996.80","0.001"],["61997.80","0.014"],["61998.50","0.710"],["61998.70","1.898"],["61999.20","0.922"],["61999.90","0.002"],["62000.00","9.014"],["62000.60","0.000"],["62001.20","0.327"],["62001.40","0.018"],["62002.50","0.675"],["62002.70","1.418"],["62002.80","0.105"],["62003.00","0.139"],["62003.40","0.003"],["62003.70","0.006"],["62004.00","0.000"],["62004.20","0.441"],["62004.90","0.001"],["62005.40","1.529"],["62006.20","0.006"],["62007.60","0.726"],["62007.90","0.026"],["62008.40","0.659"],["62008.70","4.509"],["62008.80","0.436"],["62008.90","0.013"],["62009.30","0.004"],["62009.80","0.691"],["62010.00","0.446"],["62010.10","0.002"],["62011.10","0.038"],["62011.20","0.017"],["62011.40","0.297"],["62011.50","0.001"],["62011.70","0.003"],["62011.90","0.210"],["62012.10","0.653"],["62012.60","1.968"],["62013.00","0.001"],["62013.40","0.002"],["62013.50","0.325"],["62013.60","0.680"],["62013.70","0.215"],["62013.80","1.240"],["62014.00","0.116"],["62014.10","0.029"],["62014.20","0.009"],["62014.40","0.018"],["62014.50","0.001"],["62014.60","0.343"],["62014.90","0.002"],["62015.10","0.003"],["62015.30","0.064"],["62015.40","0.003"],["62015.80","0.000"],["62016.20","0.000"],["62016.50","0.034"],["62016.60","0.001"],["62016.90","0.001"],["62017.20","0.028"],["62017.30","0.068"],["62017.60","0.443"],["62017.80","0.014"],["62017.90","0.001"],["62018.10","0.120"],["62018.30","0.025"],["62018.60","0.124"],["62018.70","0.002"],["62018.90","0.310"],["62019.00","0.000"],["62019.30","0.011"],["62020.00","0.931"],["62020.30","0.002"],["62020.40","1.002"],["62020.50","0.010"],["62020.80","0.054"],["62021.70","0.779"],["62021.90","0.296"],["62022.10","0.030"],["62022.40","0.103"],["62022.50","0.001"],["62022.80","0.000"],["62023.40","0.082"],["62023.70","0.001"],["62024.00","0.687"],["62024.10","0.122"],["62024.20","2.224"],["62024.30","0.000"],["62024.90","0.004"],["62025.00","0.003"],["62025.20","0.003"],["62025.50","0.018"],["62025.70","0.011"],["62025.80","0.386"],["62026.50","0.515"],["62027.70","0.000"],["62027.90","0.004"],["62028.00","1.467"],["62028.10","1.303"],["62028.40","1.363"],["62028.80","0.350"],["62028.90","0.001"],["62029.50","0.000"],["62029.80","0.015"],["62030.10","0.066"],["62030.20","0.001"],["62030.30","0.003"],["62030.40","0.014"],["62030.50","0.000"],["62030.80","1.231"],["62031.00","0.013"],["62031.20","0.296"],["62031.30","0.174"],["62031.60","0.003"],["62031.70","0.001"],["62031.80","0.009"],["62031.90","0.002"],["62032.00","0.684"],["62032.10","0.008"],["62032.30","0.010"],["62032.40","0.033"],["62032.50","2.015"],["62032.80","0.001"],["62032.90","0.003"],["62033.00","0.000"],["62033.10","0.003"],["62033.20","0.105"],["62033.30","0.011"],["62033.40","0.122"],["62033.50","0.004"],["62033.70","0.003"],["62033.90","0.339"],["62034.10","0.036"],["62034.50","0.010"],["62035.00","0.347"],["62035.10","1.291"],["62035.50","1.463"],["62035.80","0.009"],["62036.20","0.000"],["62036.40","0.000"],["62036.70","1.526"],["62036.90","0.134"],["62037.00","0.002"],["62037.10","0.108"],["62037.30","0.048"],["62037.60","0.698"],["62037.70","0.049"],["62037.80","1.808"],["62037.90","0.003"],["62038.00","0.075"],["62038.20","0.072"],["62038.50","0.001"],["62038.60","0.049"],["62038.70","0.002"],["62038.80","0.315"],["62039.00","0.010"],["62039.20","0.051"],["62039.30","0.133"],["62039.40","0.041"],["62039.70","1.513"],["62039.80","0.794"],["62040.00","0.008"],["62040.10","0.000"],["62040.30","0.114"],["62040.40","0.002"],["62040.50","0.035"],["62040.90","1.295"],["62041.00","0.894"],["62041.20","0.537"],["62041.30","0.002"],["62041.40","0.233"],["62041.60","0.084"],["62041.70","0.001"],["62041.80","0.011"],["62041.90","0.000"],["62042.30","2.081"],["62042.90","0.019"],["62043.00","0.750"],["62043.30","0.002"],["62043.40","0.005"],["62043.50","0.002"],["62043.70","0.003"],["62043.90","0.678"],["62044.00","0.208"],["62044.10","0.077"],["62044.50","0.003"],["62044.70","0.003"],["62044.90","0.005"],["62045.00","0.159"],["62045.10","0.663"],["62045.20","0.181"],["62045.50","0.384"],["62045.80","2.231"],["62045.90","0.181"],["62046.10","0.034"],["62046.40","0.554"],["62046.70","0.034"],["62046.90","0.177"],["62047.00","0.001"],["62047.20","0.026"],["62047.30","1.367"],["62047.60","0.347"],["62047.70","0.820"],["62047.80","0.000"],["62048.00","0.865"],["62048.10","0.053"],["62048.60","0.004"],["62048.70","0.001"],["62049.30","0.000"],["62049.50","1.144"],["62049.80","0.265"],["62049.90","1.414"],["62050.00","0.062"],["62050.30","0.017"],["62050.60","0.000"],["62050.70","0.672"],["62050.80","0.001"],["62050.90","1.001"],["62051.00","0.891"],["62051.20","0.002"],["62051.30","0.001"],["62051.40","0.003"],["62051.70","0.008"],["62051.80","0.004"],["62051.90","0.000"],["62052.40","0.049"],["62052.50","1.365"],["62052.70","0.005"],["62052.80","0.081"],["62053.00","0.000"],["62053.20","0.002"],["62053.30","0.055"],["62053.40","0.080"],["62053.70","1.305"],["62053.80","0.452"],["62053.90","0.001"],["62054.10","0.002"],["62054.20","0.171"],["62054.30","0.006"],["62054.60","0.004"],["62054.70","0.001"],["62054.80","0.004"],["62054.90","0.012"],["62055.10","0.000"],["62055.40","0.471"],["62055.50","0.006"],["62055.60","0.600"],["62056.10","0.001"],["62056.60","0.049"],["62056.80","0.061"],["62056.90","0.004"],["62057.10","0.002"],["62057.30","0.278"],["62057.40","0.002"],["62057.60","0.001"],["62057.70","0.000"],["62057.80","0.265"],["62058.00","0.056"],["62058.10","0.006"],["62058.40","0.006"],["62058.60","0.000"],["62058.80","0.000"],["62058.90","0.111"],["62059.00","0.002"],["62059.10","0.003"],["62059.20","0.324"],["62059.40","0.000"],["62059.50","0.001"],["62059.60","0.044"],["62059.70","1.800"],["62059.80","0.033"],["62059.90","0.000"],["62060.00","0.002"],["62060.20","0.001"],["62060.30","0.001"],["62060.40","0.069"],["62060.50","0.002"],["62060.60","1.808"],["62060.70","0.278"],["62060.90","0.000"],["62061.00","0.154"],["62061.40","0.001"],["62061.60","0.097"],["62061.70","0.000"],["62061.80","0.000"],["62061.90","0.001"],["62062.00","0.001"],["62062.10","0.001"],["62062.20","0.001"],["62062.30","0.000"],["62062.50","0.000"],["62062.60","0.001"],["62062.70","0.048"],["62062.80","1.800"],["62062.90","0.049"],["62063.10","0.000"],["62063.30","0.010"],["62063.40","0.002"],["62063.60","0.005"],["62063.70","9.682"]],"e":"depthUpdate","ps":"BTCUSDT","pu":10998400870119,"s":"BTCUSDT","st":1,"u":10998400895978}
{"E":1783504328366,"T":1783504328365,"U":10998400896005,"a":[["62063.80","0.000"],["62063.90","0.000"],["62064.00","0.000"],["62064.10","0.000"],["62064.20","0.000"],["62064.50","0.000"],["62064.70","0.000"],["62064.80","0.000"],["62064.90","0.000"],["62065.00","0.000"],["62065.10","0.000"],["62065.20","0.000"],["62065.40","0.000"],["62065.60","0.000"],["62065.70","0.000"],["62065.90","0.000"],["62066.00","0.000"],["62066.20","0.000"],["62066.30","0.000"],["62066.50","0.000"],["62066.60","0.000"],["62066.70","8.537"],["62066.80","0.005"],["62066.90","0.001"],["62067.10","0.005"],["62067.20","0.001"],["62067.30","0.321"],["62067.40","0.002"],["62067.50","0.000"],["62067.80","0.002"],["62067.90","0.003"],["62068.00","0.084"],["62068.10","0.000"],["62068.20","0.752"],["62068.70","0.061"],["62068.80","0.392"],["62068.90","0.296"],["62069.00","0.000"],["62069.20","0.188"],["62069.40","0.286"],["62069.50","0.288"],["62069.70","0.001"],["62069.80","0.004"],["62069.90","0.004"],["62070.00","0.023"],["62070.10","0.000"],["62070.20","0.007"],["62070.60","0.002"],["62070.70","0.031"],["62071.00","0.018"],["62071.10","0.246"],["62071.30","0.005"],["62071.40","0.005"],["62071.50","0.300"],["62071.60","0.002"],["62071.70","0.088"],["62071.80","0.001"],["62071.90","0.753"],["62072.00","0.565"],["62072.10","0.006"],["62072.30","0.051"],["62072.40","0.000"],["62072.50","0.242"],["62072.60","0.003"],["62072.70","0.160"],["62072.80","1.001"],["62072.90","0.006"],["62073.00","0.056"],["62073.10","0.284"],["62073.20","0.001"],["62073.30","0.001"],["62073.40","0.006"],["62073.50","0.003"],["62073.60","0.013"],["62073.90","0.323"],["62074.10","1.364"],["62074.20","0.367"],["62074.40","0.009"],["62074.50","0.322"],["62074.60","0.163"],["62074.80","0.507"],["62074.90","0.005"],["62075.20","0.002"],["62075.30","0.062"],["62075.40","0.005"],["62075.50","0.030"],["62075.60","0.000"],["62075.70","0.000"],["62075.80","0.051"],["62075.90","0.121"],["62076.10","0.001"],["62076.20","0.294"],["62076.30","0.281"],["62076.40","0.053"],["62076.50","0.002"],["62076.70","0.322"],["62076.80","0.402"],["62076.90","2.663"],["62077.00","0.059"],["62077.10","0.015"],["62077.30","0.002"],["62077.40","0.332"],["62077.70","0.009"],["62077.80","0.455"],["62077.90","0.067"],["62078.00","0.244"],["62078.10","0.020"],["62078.20","0.744"],["62078.30","0.000"],["62078.40","0.557"],["62078.50","0.003"],["62078.80","0.000"],["62078.90","0.000"],["62079.00","0.001"],["62079.10","1.450"],["62079.20","0.096"],["62079.30","0.006"],["62079.40","1.046"],["62079.60","0.476"],["62079.70","0.001"],["62079.80","0.006"],["62079.90","0.000"],["62080.00","0.422"],["62080.20","0.001"],["62080.30","0.001"],["62080.60","0.086"],["62080.70","0.002"],["62080.80","0.062"],["62080.90","0.005"],["62081.00","0.334"],["62081.20","0.858"],["62081.30","1.639"],["62081.40","0.029"],["62081.50","0.402"],["62081.60","0.768"],["62081.70","0.111"],["62081.80","0.101"],["62082.00","0.039"],["62082.10","0.172"],["62082.20","0.234"],["62082.30","1.456"],["62082.40","0.012"],["62082.50","0.288"],["62082.60","0.012"],["62082.70","0.041"],["62083.10","2.145"],["62083.20","0.058"],["62083.30","0.200"],["62083.90","0.587"],["62084.00","2.970"],["62084.10","0.000"],["62084.30","0.613"],["62084.40","0.008"],["62084.60","0.050"],["62084.90","0.149"],["62085.00","0.049"],["62085.10","0.667"],["62085.40","0.458"],["62085.60","13.631"],["62085.70","0.002"],["62086.00","0.000"],["62086.40","0.010"],["62086.80","0.018"],["62087.00","0.081"],["62087.10","0.081"],["62087.40","0.002"],["62087.50","0.061"],["62087.70","0.082"],["62087.80","3.083"],["62087.90","0.003"],["62088.00","0.289"],["62088.20","0.074"],["62088.30","0.051"],["62088.40","0.681"],["62088.60","0.013"],["62088.80","0.000"],["62089.00","0.889"],["62089.20","0.002"],["62089.40","0.001"],["62089.50","0.052"],["62089.60","0.116"],["62089.80","2.663"],["62090.00","0.327"],["62090.10","0.016"],["62090.30","1.917"],["62090.40","1.355"],["62090.70","0.005"],["62090.80","0.001"],["62090.90","0.001"],["62091.00","0.046"],["62091.20","0.119"],["62091.40","0.498"],["62091.50","1.372"],["62091.70","0.211"],["62091.80","1.415"],["62091.90","0.000"],["62092.30","2.420"],["62092.40","0.125"],["62092.50","0.965"],["62092.70","0.001"],["62092.90","0.050"],["62093.30","0.292"],["62093.50","0.000"],["62093.60","0.000"],["62093.80","0.013"],["62094.10","0.775"],["62094.20","0.959"],["62094.40","0.661"],["62094.80","0.009"],["62094.90","0.059"],["62095.00","0.399"],["62095.20","0.005"],["62095.40","0.017"],["62095.60","0.017"],["62095.70","0.015"],["62095.80","0.436"],["62095.90","0.001"],["62096.00","1.364"],["62096.60","0.542"],["62096.90","0.099"],["62097.10","0.001"],["62097.20","0.352"],["62097.30","0.944"],["62097.60","0.455"],["62097.80","0.018"],["62097.90","0.161"],["62098.00","0.001"],["62098.30","0.001"],["62098.50","0.003"],["62098.60","0.003"],["62098.80","0.000"],["62098.90","0.001"],["62099.00","0.027"],["62099.10","0.014"],["62099.30","0.029"],["62099.50","2.290"],["62099.60","1.451"],["62099.90","0.696"],["62100.10","0.003"],["62100.20","0.003"],["62100.40","0.002"],["62100.60","0.365"],["62100.70","0.005"],["62100.80","0.053"],["62101.00","0.076"],["62101.10","0.529"],["62101.60","0.014"],["62101.70","0.012"],["62101.80","0.018"],["62101.90","0.117"],["62102.30","0.002"],["62102.50","0.007"],["62102.60","0.000"],["62102.80","0.006"],["62102.90","0.658"],["62103.30","0.009"],["62103.40","0.003"],["62103.50","0.044"],["62103.60","0.003"],["62103.70","0.615"],["62104.00","0.056"],["62104.40","0.001"],["62104.60","0.015"],["62104.70","0.000"],["62105.20","0.005"],["62105.50","0.486"],["62105.60","0.903"],["62105.70","1.252"],["62105.90","0.004"],["62106.00","0.028"],["62106.50","0.011"],["62106.60","0.662"],["62106.80","0.000"],["62107.10","0.011"],["62107.20","0.007"],["62107.50","0.304"],["62107.70","0.003"],["62107.90","0.000"],["62108.00","0.253"],["62108.30","0.241"],["62108.40","0.174"],["62108.80","2.221"],["62109.10","0.265"],["62109.30","0.032"],["62109.40","0.003"],["62109.60","0.196"],["62109.90","0.947"],["62110.10","3.511"],["62110.90","0.002"],["62111.10","0.014"],["62112.10","0.002"],["62112.90","0.001"],["62113.20","0.025"],["62113.40","0.661"],["62114.10","0.004"],["62114.20","0.000"],["62114.50","0.704"],["62115.30","0.000"],["62115.60","0.107"],["62116.00","0.002"],["62116.20","0.704"],["62116.30","0.020"],["62116.50","0.958"],["62116.90","0.003"],["62117.00","0.016"],["62117.10","1.296"],["62117.20","0.304"],["62118.10","0.670"],["62119.20","12.974"],["62119.70","0.299"],["62119.80","0.343"],["62120.00","0.196"],["62120.30","0.014"],["62120.40","0.404"],["62121.00","0.210"],["62121.70","0.000"],["62122.10","0.010"],["62123.30","0.007"],["62123.60","0.004"],["62124.80","2.509"],["62125.00","0.185"],["62125.90","0.002"],["62126.10","0.283"],["62126.60","0.001"],["62126.90","0.167"],["62127.80","0.325"],["62128.00","0.155"],["62128.30","0.015"],["62128.40","1.169"],["62128.60","2.654"],["62131.60","0.002"],["62131.80","0.324"],["62131.90","0.002"],["62132.50","0.000"],["62132.60","0.000"],["62134.30","0.675"],["62134.70","0.018"],["62134.80","0.104"],["62136.80","1.570"],["62137.40","7.695"],["62139.60","0.296"],["62140.20","0.709"],["62141.00","0.004"],["62141.20","0.312"],["62141.80","0.023"],["62143.30","0.001"],["62143.60","0.139"],["62145.00","0.187"],["62145.20","0.322"],["62146.10","0.189"],["62146.50","0.014"],["62147.00","11.179"],["62147.30","22.600"],["62147.50","0.009"],["62148.00","0.005"],["62151.20","0.000"],["62151.30","1.533"],["62151.50","0.218"],["62152.20","0.640"],["62154.60","0.033"],["62156.50","0.012"],["62157.20","0.009"],["62159.60","0.002"],["62161.80","10.503"],["62163.80","0.107"],["62165.00","1.763"],["62166.20","0.001"],["62168.00","0.490"],["62168.20","0.122"],["62171.40","0.000"],["62172.10","0.008"],["62172.20","1.669"],["62179.80","3.042"],["62182.30","0.417"],["62182.50","0.043"],["62183.40","1.298"],["62183.50","3.424"],["62184.30","0.000"],["62185.90","0.876"],["62190.70","0.001"],["62192.80","0.001"],["62216.20","0.030"],["62220.20","0.368"],["62235.60","2.043"],["62243.10","0.029"],["62246.20","0.001"],["62248.10","1.357"],["62261.20","0.008"],["62269.50","0.001"],["62269.70","1.579"],["62296.90","0.008"],["62308.70","0.000"],["62315.00","0.017"],["62318.50","0.275"],["62327.80","0.685"],["62344.90","0.344"],["62345.80","0.352"],["62349.70","0.000"],["62350.40","0.007"],["62377.00","0.042"],["62379.70","0.292"],["62379.80","0.069"],["62382.50","0.000"],["62390.20","0.019"],["62392.40","0.100"],["62432.30","0.000"],["62438.70","0.032"],["62465.90","0.666"],["62475.40","0.000"],["62494.90","0.499"],["62501.20","0.001"],["62507.60","0.048"],["62556.40","0.000"],["62558.70","0.001"],["62562.80","0.001"],["62591.10","3.700"],["62597.90","0.000"],["62612.30","0.738"],["62620.60","0.002"],["62631.70","0.055"],["62634.40","0.000"],["62638.90","0.040"],["62642.60","0.000"],["62653.20","3.053"],["62656.10","1.422"],["62668.20","1.056"],["62668.50","0.948"],["62671.80","1.057"],["62682.70","0.000"],["62684.40","2.337"],["62687.20","0.013"],["62687.40","0.005"],["62699.20","1.476"],["62713.70","1.605"],["62715.30","3.949"],["62742.70","1.026"],["62743.00","0.712"],["62746.30","3.156"],["62746.60","0.006"],["62774.60","0.000"],["62774.70","0.003"],["62775.80","3.848"],["62776.00","0.064"],["62777.10","4.896"],["62777.50","1.585"],["62777.60","0.000"],["62778.00","0.000"],["62778.10","0.948"],["62778.40","3.961"],["62779.20","3.154"],["62780.60","6.622"],["62780.90","7.568"],["62806.80","6.888"],["62808.40","24.459"],["62811.00","4.747"],["62811.10","1.576"],["62811.30","7.106"],["62836.80","0.000"],["62837.80","11.687"],["62839.40","4.664"],["62839.50","4.884"],["62839.60","9.453"],["62840.00","1.524"],["62842.60","1.576"],["62843.00","7.092"],["62870.40","28.341"],["62870.50","7.085"],["62872.00","3.156"],["62873.10","3.149"],["62873.40","12.918"],["62899.80","3.938"],["62901.60","0.787"],["62902.50","2.925"],["62930.80","0.000"],["62930.90","6.825"],["62932.20","0.952"],["62932.50","29.107"],["62932.60","4.563"],["62933.40","0.396"],["62933.50","2.620"],["62935.40","13.375"],["62963.50","20.761"],["62966.20","6.606"],["62966.50","6.606"],["62992.50","0.000"],["62992.90","0.000"],["62994.20","0.000"],["62994.60","2.201"],["62995.50","1.114"],["63025.60","14.142"],["63025.70","2.203"],["63026.40","0.000"],["63026.50","2.200"],["63028.20","3.300"],["63028.50","4.401"],["63056.20","0.002"],["63057.60","0.003"],["63059.30","1.103"],["63059.60","3.297"],["63087.60","3.327"],["63090.60","1.102"],["63307.80","0.008"]],"b":[["11559.60","2.224"],["11663.70","0.144"],["11666.40","0.016"],["11666.60","0.064"],["11759.60","0.112"],["11963.70","0.304"],["11966.60","0.128"],["49648.00","0.000"],["55857.30","0.000"],["55859.90","0.002"],["57501.00","2.227"],["58956.60","0.009"],["58960.50","0.000"],["59581.10","0.004"],["60807.30","0.009"],["61058.00","0.000"],["61058.70","0.011"],["61059.50","0.004"],["61066.40","0.041"],["61066.60","0.064"],["61443.10","0.000"],["61445.70","0.005"],["61445.90","0.000"],["61494.40","0.081"],["61556.90","2.028"],["61561.40","0.368"],["61569.80","0.001"],["61623.50","0.029"],["61631.80","0.002"],["61711.10","0.396"],["61714.60","0.000"],["61720.00","0.741"],["61723.10","0.000"],["61726.10","0.000"],["61729.30","0.047"],["61730.50","0.000"],["61740.40","0.100"],["61743.00","0.034"],["61749.30","0.012"],["61784.70","0.156"],["61785.60","0.608"],["61799.10","0.000"],["61809.70","0.000"],["61817.60","0.021"],["61818.00","0.981"],["61835.30","1.554"],["61847.20","0.002"],["61852.50","0.003"],["61860.00","0.212"],["61860.10","1.536"],["61860.20","0.614"],["61877.50","0.086"],["61887.10","0.000"],["61887.30","0.000"],["61887.60","0.436"],["61890.20","0.000"],["61895.20","0.454"],["61900.60","0.002"],["61901.60","0.021"],["61903.40","1.630"],["61907.60","0.000"],["61910.20","1.362"],["61914.90","0.133"],["61917.10","1.129"],["61917.60","0.000"],["61923.20","0.258"],["61928.30","2.448"],["61931.90","0.290"],["61940.80","0.000"],["61940.90","0.409"],["61941.70","1.385"],["61943.70","2.753"],["61946.50","0.038"],["61946.60","0.484"],["61946.90","0.000"],["61949.20","1.364"],["61949.60","0.000"],["61953.60","0.033"],["61954.00","0.002"],["61956.30","2.091"],["61956.60","0.000"],["61961.90","0.003"],["61962.90","0.000"],["61963.10","12.136"],["61963.60","0.002"],["61963.70","1.917"],["61963.80","0.061"],["61964.00","0.821"],["61964.70","0.024"],["61965.60","0.000"],["61968.00","0.068"],["61969.00","1.452"],["61972.90","0.066"],["61973.20","0.001"],["61973.70","0.001"],["61974.50","4.378"],["61974.60","4.834"],["61975.10","2.903"],["61975.60","2.928"],["61975.90","0.122"],["61976.80","0.000"],["61977.10","0.093"],["61977.40","19.447"],["61977.50","4.651"],["61977.70","0.000"],["61979.50","0.002"],["61980.10","4.384"],["61981.80","0.000"],["61983.00","0.677"],["61984.60","0.009"],["61984.70","1.531"],["61985.50","0.053"],["61986.60","0.000"],["61987.00","8.003"],["61987.10","1.982"],["61987.20","0.001"],["61987.50","0.086"],["61987.90","0.140"],["61988.20","0.000"],["61989.00","0.001"],["61990.10","6.513"],["61990.70","1.618"],["61991.80","1.815"],["61994.20","0.287"],["61994.60","0.472"],["61995.00","0.040"],["61997.20","0.121"],["61997.60","0.043"],["61998.40","0.030"],["61998.70","1.898"],["62001.30","0.000"],["62002.00","1.075"],["62002.10","0.673"],["62003.00","0.138"],["62003.90","0.001"],["62004.20","0.437"],["62004.30","0.411"],["62004.50","0.406"],["62005.20","0.566"],["62005.40","0.000"],["62005.50","1.530"],["62005.80","0.068"],["62006.30","0.018"],["62006.90","0.652"],["62007.60","0.003"],["62008.70","4.507"],["62008.80","1.860"],["62008.90","0.013"],["62009.70","0.212"],["62010.00","0.137"],["62010.40","0.009"],["62011.10","0.003"],["62011.20","0.003"],["62011.40","0.281"],["62011.60","0.000"],["62011.70","0.001"],["62011.90","0.000"],["62012.20","0.001"],["62012.50","0.231"],["62012.60","1.953"],["62013.40","0.000"],["62013.60","0.678"],["62013.80","0.018"],["62014.30","0.001"],["62014.40","0.016"],["62014.50","0.003"],["62014.70","1.041"],["62014.90","0.000"],["62015.10","0.001"],["62015.20","1.387"],["62015.30","0.003"],["62015.40","0.010"],["62016.00","0.007"],["62016.20","0.002"],["62016.30","0.000"],["62016.50","0.034"],["62016.70","0.067"],["62017.10","0.017"],["62017.30","0.060"],["62017.60","0.385"],["62017.90","0.004"],["62018.00","0.315"],["62018.10","0.120"],["62018.30","0.000"],["62018.50","0.666"],["62018.80","1.365"],["62019.10","0.000"],["62019.50","0.026"],["62019.80","0.007"],["62020.10","0.008"],["62020.50","0.000"],["62020.80","0.050"],["62021.40","1.368"],["62021.60","2.203"],["62021.80","1.295"],["62021.90","0.164"],["62022.00","0.083"],["62022.10","0.016"],["62022.50","0.000"],["62022.60","0.000"],["62022.70","0.001"],["62023.10","0.001"],["62024.00","0.684"],["62024.10","0.119"],["62024.20","2.224"],["62024.50","1.346"],["62024.60","0.294"],["62024.70","0.000"],["62025.30","0.657"],["62025.40","0.311"],["62025.50","0.016"],["62025.80","0.326"],["62026.10","0.974"],["62026.30","0.002"],["62026.50","0.536"],["62026.70","0.005"],["62027.80","0.006"],["62028.00","1.527"],["62028.10","1.295"],["62028.30","0.122"],["62028.60","1.254"],["62028.80","0.007"],["62028.90","0.001"],["62029.30","0.016"],["62029.50","0.000"],["62030.00","0.004"],["62030.10","0.052"],["62030.30","0.007"],["62030.40","0.002"],["62030.50","0.025"],["62030.60","0.285"],["62030.80","1.231"],["62031.30","0.084"],["62031.80","0.002"],["62031.90","0.002"],["62032.00","0.681"],["62032.10","0.006"],["62032.20","0.091"],["62032.40","0.001"],["62032.50","1.351"],["62032.60","0.318"],["62033.30","0.001"],["62033.80","0.023"],["62034.30","0.001"],["62034.50","0.002"],["62034.60","1.298"],["62034.70","0.015"],["62034.80","0.000"],["62034.90","0.454"],["62035.10","1.291"],["62035.30","0.001"],["62035.40","0.120"],["62035.50","1.340"],["62036.20","0.005"],["62036.40","0.301"],["62036.60","0.292"],["62036.80","0.681"],["62036.90","0.134"],["62037.10","0.107"],["62037.40","0.001"],["62037.60","0.724"],["62037.80","1.142"],["62038.00","0.005"],["62038.20","0.069"],["62038.30","0.000"],["62038.60","0.001"],["62038.70","0.072"],["62038.80","0.305"],["62038.90","0.010"],["62039.10","0.121"],["62039.20","0.051"],["62039.30","0.004"],["62039.50","0.005"],["62039.60","0.001"],["62039.70","1.413"],["62039.80","0.791"],["62040.30","0.115"],["62040.40","0.010"],["62040.50","0.000"],["62040.60","0.005"],["62040.90","1.298"],["62041.10","0.684"],["62041.20","0.535"],["62041.30","0.004"],["62041.40","0.231"],["62041.50","0.016"],["62041.60","0.082"],["62041.70","0.032"],["62041.80","0.009"],["62041.90","0.007"],["62042.10","0.358"],["62042.30","2.083"],["62042.40","0.019"],["62042.50","0.297"],["62042.60","1.100"],["62042.70","0.013"],["62042.80","0.003"],["62043.00","0.000"],["62043.10","0.050"],["62043.30","0.001"],["62043.40","0.004"],["62044.30","0.050"],["62044.50","0.403"],["62044.60","0.425"],["62044.90","0.007"],["62045.00","0.500"],["62045.10","0.000"],["62045.40","0.062"],["62045.80","2.239"],["62045.90","0.121"],["62046.00","0.051"],["62046.30","1.085"],["62046.40","0.430"],["62046.50","0.064"],["62046.80","0.000"],["62046.90","0.008"],["62047.30","1.365"],["62047.40","1.375"],["62047.50","1.649"],["62047.60","0.476"],["62047.70","0.663"],["62047.90","0.022"],["62048.00","0.006"],["62048.30","0.034"],["62048.40","0.033"],["62048.90","0.123"],["62049.00","0.680"],["62049.10","0.727"],["62049.30","0.060"],["62049.50","1.476"],["62049.60","0.008"],["62049.70","0.101"],["62049.80","0.325"],["62049.90","1.472"],["62050.00","0.194"],["62050.10","0.017"],["62050.20","0.008"],["62050.30","0.027"],["62050.40","0.314"],["62050.50","0.060"],["62050.70","0.648"],["62050.80","0.566"],["62050.90","0.001"],["62051.00","0.072"],["62051.10","0.125"],["62051.30","0.003"],["62051.40","0.003"],["62051.50","0.002"],["62051.60","0.154"],["62051.70","0.009"],["62051.80","0.000"],["62052.30","0.002"],["62052.40","0.049"],["62052.50","1.365"],["62052.60","1.140"],["62052.70","0.569"],["62053.10","0.002"],["62053.40","0.082"],["62053.60","1.281"],["62053.70","1.345"],["62053.80","0.502"],["62053.90","0.065"],["62054.00","0.006"],["62054.10","0.005"],["62054.20","0.293"],["62054.80","0.000"],["62054.90","0.012"],["62055.00","2.033"],["62055.30","0.012"],["62055.40","0.796"],["62055.50","0.004"],["62055.60","0.005"],["62055.70","0.125"],["62055.80","0.005"],["62056.00","0.002"],["62056.40","0.000"],["62056.80","0.232"],["62057.00","0.003"],["62057.10","0.002"],["62057.40","0.000"],["62057.70","0.000"],["62057.80","0.003"],["62058.00","0.006"],["62058.20","0.000"],["62058.40","0.006"],["62058.90","0.111"],["62059.10","0.001"],["62059.40","0.000"],["62059.60","0.028"],["62059.70","0.000"],["62059.80","0.033"],["62060.10","0.009"],["62060.30","0.002"],["62060.40","0.070"],["62060.50","0.002"],["62060.60","2.067"],["62060.80","0.000"],["62061.00","0.155"],["62061.10","0.051"],["62061.50","0.050"],["62062.20","0.003"],["62062.70","0.000"],["62062.80","1.806"],["62063.20","0.002"],["62063.30","0.001"],["62063.40","0.000"],["62063.60","0.001"],["62063.70","0.359"],["62063.80","2.080"],["62063.90","0.000"],["62064.00","0.000"],["62064.20","0.000"],["62064.40","0.000"],["62064.60","0.002"],["62064.70","0.003"],["62064.80","0.000"],["62064.90","0.000"],["62065.00","0.002"],["62065.10","0.002"],["62065.30","0.000"],["62065.40","0.000"],["62065.50","0.000"],["62065.60","0.001"],["62066.10","0.000"],["62066.20","0.000"],["62066.30","0.002"],["62066.40","0.446"],["62066.50","0.005"],["62066.60","10.663"]],"e":"depthUpdate","ps":"BTCUSDT","pu":10998400895978,"s":"BTCUSDT","st":1,"u":10998400913384}
{"E":1783504328468,"T":1783504328466,"U":10998400913404,"a":[["62066.70","8.532"],["62066.80","0.001"],["62066.90","0.000"],["62067.00","0.001"],["62067.10","0.001"],["62067.30","0.107"],["62067.60","0.001"],["62068.00","0.001"],["62068.20","0.650"],["62068.30","0.003"],["62068.70","0.003"],["62068.80","0.001"],["62068.90","0.004"],["62069.00","0.000"],["62069.20","0.010"],["62069.30","0.000"],["62069.40","0.040"],["62069.50","0.000"],["62069.80","0.002"],["62070.00","0.019"],["62070.10","0.002"],["62070.20","0.003"],["62070.70","0.008"],["62070.90","0.003"],["62071.40","0.006"],["62071.80","0.025"],["62071.90","0.739"],["62072.40","0.040"],["62072.60","0.013"],["62072.90","0.002"],["62073.10","0.280"],["62073.20","0.000"],["62073.70","0.012"],["62073.80","0.081"],["62074.00","0.312"],["62074.20","0.457"],["62074.70","0.005"],["62074.80","0.766"],["62074.90","0.072"],["62075.10","0.249"],["62075.40","0.095"],["62075.60","0.000"],["62076.00","0.107"],["62076.10","0.091"],["62076.20","0.002"],["62076.80","0.966"],["62077.10","0.095"],["62077.70","0.025"],["62078.40","0.537"],["62079.00","0.293"],["62079.10","1.450"],["62079.30","0.570"],["62079.90","0.020"],["62080.00","0.583"],["62080.50","0.050"],["62081.10","0.005"],["62081.20","0.002"],["62081.60","0.043"],["62082.00","0.764"],["62082.10","0.010"],["62082.70","0.041"],["62083.50","0.146"],["62083.90","0.007"],["62084.10","0.000"],["62084.80","1.367"],["62085.30","0.292"],["62085.40","0.459"],["62085.60","13.633"],["62086.20","0.332"],["62086.30","0.582"],["62086.50","0.015"],["62087.80","1.356"],["62088.20","0.011"],["62088.50","1.366"],["62088.60","0.000"],["62089.10","0.054"],["62089.30","0.155"],["62089.60","0.057"],["62089.80","2.665"],["62091.20","0.014"],["62091.30","0.544"],["62091.40","0.393"],["62091.50","1.419"],["62091.70","0.106"],["62091.80","1.310"],["62092.70","0.060"],["62094.60","0.028"],["62095.80","0.430"],["62096.00","1.363"],["62096.60","0.452"],["62097.70","0.013"],["62097.80","0.022"],["62099.50","2.296"],["62099.60","1.453"],["62100.30","0.026"],["62100.40","0.107"],["62100.80","0.075"],["62101.00","0.049"],["62102.30","3.057"],["62102.40","9.350"],["62103.50","0.021"],["62103.80","0.323"],["62103.90","1.396"],["62104.00","0.000"],["62104.20","0.658"],["62104.80","0.001"],["62105.10","0.058"],["62105.40","0.041"],["62106.00","0.029"],["62107.80","3.032"],["62110.10","3.513"],["62111.30","0.168"],["62111.70","0.015"],["62113.40","0.660"],["62114.40","0.001"],["62114.60","0.028"],["62116.40","0.753"],["62117.30","0.003"],["62120.40","0.400"],["62123.60","0.008"],["62124.50","0.700"],["62125.10","0.192"],["62125.70","0.100"],["62125.80","0.000"],["62128.70","0.477"],["62129.00","0.004"],["62130.50","22.600"],["62132.60","0.090"],["62133.30","0.082"],["62134.30","0.723"],["62135.00","0.133"],["62135.30","0.000"],["62141.20","1.158"],["62143.80","3.844"],["62145.40","0.002"],["62145.70","5.968"],["62145.80","0.011"],["62147.30","0.000"],["62152.20","0.969"],["62152.60","2.752"],["62157.20","0.001"],["62158.60","1.714"],["62159.80","4.834"],["62161.70","0.150"],["62164.40","1.451"],["62202.50","0.675"],["62217.80","8.305"],["62232.60","0.001"],["62296.70","0.455"],["62308.10","0.005"],["62326.60","0.261"],["62327.80","1.337"],["62344.20","0.320"],["62420.30","0.000"],["62427.10","0.008"],["62452.40","0.000"],["62463.90","0.173"],["62495.00","0.019"],["62497.20","0.003"],["62547.50","0.000"],["62563.20","0.008"],["62608.50","0.024"],["62612.30","0.021"],["62620.00","0.029"],["62656.10","2.133"],["62680.90","0.004"],["62684.40","0.000"],["62687.40","0.005"],["62687.80","0.008"],["62699.20","0.049"],["62699.30","0.000"],["62718.20","2.336"],["62743.00","2.763"],["62777.50","0.797"],["62778.10","0.002"],["62780.90","8.514"],["62808.60","0.002"],["62811.30","7.894"],["62839.50","0.945"],["62839.60","3.151"],["62842.30","3.151"],["62873.40","23.152"],["62901.60","0.000"],["62932.60","2.675"],["62933.50","0.398"],["62935.40","14.162"],["62966.50","10.695"],["62994.60","0.001"],["62994.70","0.234"],["62995.50","0.004"],["63028.50","8.801"],["63057.50","0.000"],["63090.60","2.200"],["63289.20","0.000"],["89523.20","0.186"]],"b":[["11559.60","1.952"],["11666.60","0.192"],["11758.70","0.000"],["11759.60","0.000"],["11966.60","0.400"],["55859.90","0.002"],["58963.20","0.003"],["59581.10","0.001"],["60825.30","0.013"],["61158.80","0.000"],["61190.80","9.708"],["61259.70","0.653"],["61284.10","0.277"],["61315.40","1.796"],["61315.60","1.615"],["61346.60","2.525"],["61445.90","0.000"],["61469.30","0.053"],["61492.80","0.000"],["61501.10","4.830"],["61504.20","0.016"],["61646.60","0.004"],["61657.90","0.012"],["61723.70","0.324"],["61795.90","0.002"],["61800.70","0.279"],["61812.10","0.004"],["61823.30","0.208"],["61834.10","0.001"],["61834.60","5.752"],["61862.30","39.447"],["61862.70","6.942"],["61863.50","0.001"],["61909.10","0.642"],["61927.90","0.000"],["61941.40","0.024"],["61959.20","0.678"],["61968.00","0.076"],["61968.90","0.002"],["61969.00","1.444"],["61974.20","2.569"],["61977.40","0.002"],["61977.50","1.749"],["61980.90","2.980"],["61981.90","6.206"],["61982.40","0.000"],["61984.30","1.803"],["61987.50","0.006"],["61989.10","0.000"],["61990.00","0.209"],["61990.20","1.455"],["61990.70","0.000"],["61992.20","1.234"],["61996.00","0.000"],["61996.30","0.049"],["61998.40","19.475"],["61998.70","4.462"],["62000.00","8.934"],["62002.80","0.104"],["62004.60","0.472"],["62006.00","0.104"],["62006.90","0.648"],["62010.00","0.141"],["62012.50","0.147"],["62016.00","0.005"],["62016.70","0.003"],["62017.00","0.682"],["62017.40","0.322"],["62018.10","0.124"],["62019.20","0.013"],["62019.70","0.000"],["62020.30","0.001"],["62020.90","0.000"],["62021.50","0.000"],["62022.20","0.082"],["62022.40","0.133"],["62023.20","0.531"],["62029.40","0.005"],["62029.60","0.335"],["62032.30","0.012"],["62032.40","0.003"],["62032.50","1.353"],["62035.80","0.170"],["62039.80","0.791"],["62040.50","2.458"],["62040.90","1.298"],["62041.10","1.999"],["62041.20","0.664"],["62042.00","0.631"],["62042.60","1.020"],["62045.20","0.121"],["62045.50","0.324"],["62045.80","2.119"],["62045.90","0.001"],["62046.10","0.002"],["62046.40","0.003"],["62046.70","0.002"],["62046.90","0.006"],["62047.60","0.347"],["62047.90","0.023"],["62048.40","0.035"],["62048.50","0.003"],["62048.60","0.006"],["62049.10","0.002"],["62049.30","1.431"],["62050.10","0.001"],["62050.30","0.028"],["62050.70","0.326"],["62050.80","0.727"],["62050.90","0.565"],["62051.30","0.123"],["62051.50","0.002"],["62052.00","0.121"],["62052.10","0.066"],["62052.70","0.037"],["62052.80","0.081"],["62052.90","0.000"],["62053.90","0.882"],["62054.50","0.024"],["62054.60","0.000"],["62055.10","0.817"],["62055.40","1.132"],["62055.50","0.005"],["62055.60","0.791"],["62055.70","1.027"],["62056.00","0.404"],["62056.70","0.368"],["62056.80","0.233"],["62057.10","0.008"],["62057.70","0.001"],["62058.90","0.156"],["62059.60","0.021"],["62059.70","0.004"],["62060.40","0.065"],["62060.50","0.004"],["62061.60","0.098"],["62062.30","0.042"],["62062.40","0.001"],["62062.70","0.001"],["62063.50","0.001"],["62064.50","0.001"],["62064.60","0.000"],["62064.70","0.001"],["62065.10","0.003"],["62066.50","0.006"],["62066.60","10.612"]],"e":"depthUpdate","ps":"BTCUSDT","pu":10998400913384,"s":"BTCUSDT","st":1,"u":10998400923147}
{"E":1783504328570,"T":1783504328569,"U":10998400923559,"a":[["62066.70","0.000"],["62066.80","0.000"],["62067.00","0.000"],["62067.10","0.000"],["62067.20","0.000"],["62067.30","0.000"],["62067.40","0.000"],["62067.50","0.000"],["62067.60","0.000"],["62067.80","0.000"],["62067.90","0.000"],["62068.00","0.000"],["62068.20","0.000"],["62068.30","0.000"],["62068.40","0.000"],["62068.70","0.000"],["62068.80","0.000"],["62068.90","0.000"],["62069.10","0.000"],["62069.20","0.000"],["62069.40","0.000"],["62069.50","0.000"],["62069.60","0.000"],["62069.70","0.000"],["62069.80","0.000"],["62069.90","0.000"],["62070.00","0.000"],["62070.10","0.000"],["62070.20","2.674"],["62070.30","0.008"],["62070.40","0.001"],["62070.50","0.000"],["62070.60","0.002"],["62070.80","0.000"],["62070.90","0.000"],["62071.00","0.014"],["62071.10","0.001"],["62071.20","0.001"],["62071.40","0.006"],["62071.50","0.002"],["62071.70","0.000"],["62071.80","0.026"],["62071.90","0.001"],["62072.00","0.001"],["62072.10","0.125"],["62072.20","0.646"],["62072.30","0.002"],["62072.50","0.001"],["62072.60","0.003"],["62072.70","0.000"],["62072.80","0.000"],["62072.90","0.001"],["62073.00","0.001"],["62073.10","0.002"],["62073.20","0.000"],["62073.40","0.004"],["62073.50","0.007"],["62073.60","0.003"],["62073.70","0.002"],["62073.80","0.000"],["62073.90","0.000"],["62074.00","0.017"],["62074.10","0.002"],["62074.20","0.000"],["62074.30","0.001"],["62074.40","0.004"],["62074.50","0.000"],["62074.60","0.310"],["62074.70","0.004"],["62074.80","0.326"],["62074.90","0.002"],["62075.10","0.014"],["62075.20","0.002"],["62075.30","0.002"],["62075.40","0.008"],["62075.50","0.018"],["62075.70","0.000"],["62075.80","0.005"],["62075.90","0.001"],["62076.00","0.005"],["62076.10","0.001"],["62076.20","0.002"],["62076.30","0.002"],["62076.40","0.117"],["62076.50","0.169"],["62076.60","0.004"],["62076.70","0.000"],["62076.80","0.007"],["62076.90","0.003"],["62077.10","0.013"],["62077.20","0.052"],["62077.40","0.196"],["62077.50","0.454"],["62077.60","0.120"],["62077.70","0.017"],["62077.80","2.199"],["62077.90","2.158"],["62078.00","0.761"],["62078.10","0.756"],["62078.20","0.003"],["62078.30","0.001"],["62078.40","0.416"],["62078.50","0.003"],["62078.60","0.001"],["62078.70","0.344"],["62079.00","0.001"],["62079.10","0.001"],["62079.20","0.000"],["62079.30","0.003"],["62079.40","1.362"],["62079.50","1.164"],["62079.60","0.324"],["62079.70","0.001"],["62079.80","0.004"],["62079.90","0.322"],["62080.00","0.418"],["62080.10","0.122"],["62080.40","0.002"],["62080.50","0.050"],["62080.60","0.047"],["62080.80","0.242"],["62081.10","0.003"],["62081.20","0.164"],["62081.30","1.327"],["62081.50","0.367"],["62081.60","0.002"],["62081.70","0.233"],["62081.80","0.095"],["62081.90","0.020"],["62082.00","0.007"],["62082.10","0.050"],["62082.20","1.362"],["62082.30","0.025"],["62082.40","0.013"],["62082.50","0.043"],["62082.60","0.509"],["62082.90","0.326"],["62083.00","0.000"],["62083.20","0.181"],["62083.30","0.151"],["62083.50","0.488"],["62083.80","1.203"],["62083.90","0.087"],["62084.00","1.015"],["62084.20","0.566"],["62084.40","0.143"],["62084.50","0.015"],["62084.60","0.221"],["62084.80","1.494"],["62084.90","0.049"],["62085.00","0.014"],["62085.10","0.003"],["62085.20","0.006"],["62085.40","0.002"],["62085.60","0.103"],["62085.70","0.344"],["62085.80","0.056"],["62085.90","0.007"],["62086.10","0.016"],["62086.20","0.013"],["62086.30","0.002"],["62086.40","0.002"],["62086.70","0.406"],["62086.80","0.018"],["62086.90","0.001"],["62087.00","0.806"],["62087.10","0.001"],["62087.30","0.081"],["62087.50","0.057"],["62087.70","0.002"],["62087.90","0.003"],["62088.20","0.670"],["62088.30","0.001"],["62088.40","0.679"],["62088.80","0.006"],["62088.90","0.229"],["62089.00","0.889"],["62089.10","0.006"],["62089.20","0.247"],["62089.30","0.093"],["62089.50","0.004"],["62089.60","0.017"],["62089.70","0.768"],["62089.80","0.002"],["62089.90","0.766"],["62090.00","2.718"],["62090.10","0.016"],["62090.20","0.583"],["62090.30","0.805"],["62090.50","0.144"],["62091.00","0.025"],["62091.10","0.013"],["62091.20","0.016"],["62091.30","0.538"],["62091.40","0.309"],["62091.60","0.000"],["62091.70","0.088"],["62091.80","1.221"],["62092.00","0.011"],["62092.10","0.000"],["62092.20","0.461"],["62092.30","15.930"],["62092.40","0.005"],["62092.50","0.883"],["62092.60","0.069"],["62092.70","0.001"],["62092.80","0.128"],["62092.90","0.052"],["62093.00","0.296"],["62093.20","0.044"],["62093.40","0.003"],["62093.50","0.070"],["62093.80","0.005"],["62093.90","0.163"],["62094.00","0.851"],["62094.10","0.686"],["62094.20","0.765"],["62094.40","0.657"],["62094.50","0.026"],["62094.60","0.013"],["62094.70","0.123"],["62094.80","0.009"],["62095.00","0.302"],["62095.10","0.051"],["62095.20","0.007"],["62095.40","0.017"],["62095.50","0.072"],["62095.80","0.325"],["62095.90","0.001"],["62096.00","1.363"],["62096.30","0.002"],["62096.40","0.556"],["62096.70","0.000"],["62097.10","0.001"],["62097.20","0.208"],["62097.40","0.001"],["62097.50","0.000"],["62097.60","0.455"],["62097.70","0.082"],["62097.80","0.073"],["62097.90","0.045"],["62098.00","0.121"],["62098.10","0.298"],["62098.20","0.048"],["62098.30","0.001"],["62098.40","0.001"],["62098.50","0.003"],["62098.60","0.000"],["62098.70","0.035"],["62098.80","0.008"],["62098.90","0.001"],["62099.00","0.030"],["62099.10","0.016"],["62099.20","0.313"],["62099.30","0.000"],["62099.40","1.486"],["62099.50","2.290"],["62099.60","1.451"],["62099.70","0.659"],["62099.80","0.639"],["62099.90","0.696"],["62100.00","0.746"],["62100.10","0.001"],["62100.40","0.003"],["62100.60","0.363"],["62100.80","0.053"],["62100.90","0.001"],["62101.10","0.001"],["62101.20","0.312"],["62101.40","0.002"],["62101.50","0.006"],["62101.60","0.000"],["62101.70","0.175"],["62101.80","2.777"],["62101.90","0.061"],["62102.00","0.032"],["62102.20","0.338"],["62102.30","3.055"],["62102.40","9.355"],["62102.50","0.004"],["62102.80","0.001"],["62102.90","0.002"],["62103.30","0.000"],["62103.50","0.006"],["62103.60","0.003"],["62103.70","0.452"],["62103.80","0.324"],["62103.90","1.396"],["62104.30","0.286"],["62104.40","0.090"],["62104.50","4.954"],["62104.60","0.015"],["62104.70","0.000"],["62104.80","0.050"],["62105.00","0.213"],["62105.10","0.180"],["62105.20","0.010"],["62105.40","0.018"],["62105.50","0.773"],["62105.60","1.008"],["62105.70","1.252"],["62105.80","0.001"],["62105.90","0.002"],["62106.00","0.029"],["62106.20","0.011"],["62106.50","0.014"],["62106.60","0.007"],["62107.00","0.003"],["62107.20","0.006"],["62107.30","0.001"],["62107.40","0.776"],["62107.50","0.393"],["62107.70","0.003"],["62107.80","0.579"],["62108.00","0.254"],["62108.10","0.003"],["62108.20","0.000"],["62108.30","0.181"],["62108.40","0.011"],["62108.60","0.000"],["62108.70","1.446"],["62108.90","0.008"],["62109.00","0.056"],["62109.10","0.265"],["62109.20","0.001"],["62109.30","0.032"],["62109.40","0.000"],["62109.50","0.018"],["62109.60","0.033"],["62109.80","0.000"],["62110.00","0.429"],["62110.10","3.540"],["62110.30","0.004"],["62110.40","0.001"],["62110.50","0.003"],["62110.60","0.686"],["62111.00","0.519"],["62111.10","0.002"],["62111.30","0.006"],["62111.40","0.778"],["62111.50","0.001"],["62111.60","2.344"],["62111.70","3.105"],["62111.90","0.003"],["62112.00","0.062"],["62112.20","3.693"],["62112.40","0.000"],["62112.60","0.282"],["62112.80","1.365"],["62113.20","0.000"],["62113.30","0.003"],["62113.80","3.154"],["62113.90","0.001"],["62114.50","0.688"],["62114.80","0.061"],["62114.90","2.007"],["62115.10","0.014"],["62115.30","0.005"],["62115.40","0.004"],["62115.60","0.000"],["62116.00","0.165"],["62116.20","0.000"],["62116.40","0.753"],["62116.60","0.015"],["62116.80","0.002"],["62116.90","0.000"],["62117.00","1.118"],["62117.10","1.395"],["62117.20","0.294"],["62117.30","0.003"],["62117.50","1.200"],["62117.80","0.003"],["62117.90","0.030"],["62118.10","0.667"],["62118.70","0.001"],["62119.20","12.092"],["62119.30","0.016"],["62119.50","0.001"],["62119.70","0.283"],["62119.90","0.536"],["62120.00","0.199"],["62120.20","0.000"],["62120.30","0.006"],["62120.40","0.403"],["62120.50","1.436"],["62120.60","0.025"],["62120.70","0.037"],["62121.00","0.000"],["62121.10","0.820"],["62121.20","0.011"],["62122.10","0.002"],["62122.60","0.000"],["62122.90","0.703"],["62123.40","0.001"],["62123.90","0.555"],["62124.00","0.005"],["62124.10","0.000"],["62124.20","0.000"],["62124.30","0.025"],["62124.50","0.679"],["62124.60","0.114"],["62124.70","0.100"],["62124.80","3.167"],["62125.00","0.281"],["62125.10","0.344"],["62125.20","0.093"],["62125.30","0.000"],["62125.40","0.273"],["62125.60","0.074"],["62125.70","0.100"],["62126.30","1.616"],["62126.90","0.161"],["62127.00","0.002"],["62127.20","0.043"],["62127.30","0.001"],["62127.90","0.001"],["62128.00","0.153"],["62128.30","0.000"],["62128.40","1.379"],["62128.80","0.177"],["62129.10","0.003"],["62129.30","0.000"],["62130.00","0.872"],["62130.20","0.029"],["62130.40","1.501"],["62130.50","0.002"],["62130.80","0.002"],["62131.60","0.000"],["62132.00","0.001"],["62132.30","3.326"],["62132.60","0.090"],["62133.30","0.015"],["62133.90","0.062"],["62134.30","3.924"],["62134.70","22.618"],["62135.80","0.001"],["62136.20","0.015"],["62136.40","0.734"],["62136.50","0.825"],["62136.70","0.025"],["62136.90","0.089"],["62139.90","0.000"],["62140.00","0.157"],["62140.10","0.000"],["62140.90","0.016"],["62141.20","0.846"],["62141.30","0.017"],["62141.40","0.668"],["62143.50","0.010"],["62144.10","0.001"],["62145.70","2.795"],["62145.90","0.000"],["62146.00","0.712"],["62147.10","0.018"],["62147.50","0.006"],["62148.80","0.291"],["62149.20","0.000"],["62149.60","0.000"],["62151.00","0.044"],["62151.60","0.011"],["62152.00","0.714"],["62152.70","0.004"],["62153.10","0.047"],["62160.30","0.033"],["62160.80","0.004"],["62161.30","0.002"],["62161.40","2.623"],["62161.80","10.423"],["62162.20","4.371"],["62162.80","0.000"],["62168.40","0.059"],["62169.80","0.700"],["62170.20","0.010"],["62174.30","0.073"],["62183.10","0.008"],["62183.20","0.257"],["62183.30","0.100"],["62184.60","0.002"],["62190.10","0.128"],["62191.10","0.002"],["62194.20","1.363"],["62195.10","0.002"],["62197.20","0.031"],["62202.40","0.570"],["62203.30","0.000"],["62204.30","0.000"],["62217.10","3.495"],["62218.60","0.059"],["62219.00","1.218"],["62219.60","0.017"],["62219.70","0.015"],["62226.70","0.489"],["62230.40","0.002"],["62230.70","0.674"],["62234.80","0.003"],["62237.80","0.001"],["62246.70","0.300"],["62250.20","0.000"],["62250.30","0.041"],["62253.20","0.004"],["62253.60","0.152"],["62265.00","0.000"],["62268.20","0.003"],["62293.40","0.002"],["62293.90","0.288"],["62297.10","0.278"],["62303.90","7.137"],["62305.20","4.348"],["62309.60","0.002"],["62315.20","0.000"],["62324.90","0.024"],["62331.00","0.679"],["62331.30","0.683"],["62345.30","0.069"],["62355.40","0.000"],["62370.80","0.012"],["62377.30","0.008"],["62379.70","0.035"],["62386.50","0.040"],["62407.10","0.252"],["62468.10","0.371"],["62488.80","0.324"],["62613.10","0.000"],["62657.60","0.711"],["62687.40","0.005"],["62687.60","0.000"],["62688.00","0.460"],["62688.90","0.000"],["62690.00","0.010"],["62690.10","0.000"],["62690.90","0.002"],["62699.80","0.017"],["62744.40","0.710"],["62780.60","0.000"],["62780.90","0.000"],["62781.50","5.676"],["62781.80","5.229"],["62782.30","3.786"],["62783.50","0.946"],["62783.60","2.838"],["62783.80","0.946"],["62842.60","0.000"],["62843.00","0.000"],["62843.60","1.581"],["62844.40","6.622"],["62846.40","0.789"],["62874.50","1.072"],["62887.50","0.279"],["62904.60","0.795"],["62905.50","1.574"],["62905.80","1.102"],["62906.40","0.000"],["62936.00","2.998"],["62936.80","0.002"],["62936.90","4.720"],["62938.90","7.077"],["62967.90","1.102"],["62998.60","0.001"],["63030.00","1.475"],["63308.60","0.003"],["63311.60","0.083"],["67590.00","0.035"],["67590.10","0.000"],["67591.90","0.000"],["67592.50","0.000"],["67592.80","0.026"],["67593.00","0.601"],["67603.70","0.589"],["67617.30","0.596"],["67630.90","0.608"]],"b":[["1000.00","210.942"],["11559.60","1.680"],["11666.60","0.224"],["11667.20","0.016"],["11668.10","0.016"],["11669.30","0.016"],["11670.10","0.064"],["11758.00","0.080"],["11966.60","0.448"],["11967.20","0.064"],["11968.10","0.016"],["11969.20","0.016"],["11970.10","0.128"],["55859.90","0.000"],["55860.40","0.000"],["55862.30","0.000"],["55863.00","0.005"],["58966.50","0.000"],["59587.20","0.003"],["60807.30","0.006"],["61059.60","0.000"],["61060.40","0.000"],["61060.50","0.010"],["61066.40","0.029"],["61066.60","0.062"],["61067.20","0.032"],["61068.10","0.006"],["61070.10","0.022"],["61128.10","0.000"],["61159.70","18.946"],["61166.60","1.441"],["61314.70","0.000"],["61345.90","5.164"],["61445.90","0.000"],["61446.20","0.000"],["61446.50","0.002"],["61447.40","0.000"],["61448.60","0.000"],["61449.40","0.004"],["61537.60","5.710"],["61689.70","0.000"],["61696.80","0.002"],["61700.10","6.733"],["61716.60","0.008"],["61743.70","0.000"],["61745.10","0.084"],["61747.70","0.162"],["61749.30","0.011"],["61751.80","0.120"],["61757.80","0.000"],["61758.90","0.015"],["61771.90","0.069"],["61799.00","0.000"],["61803.10","0.000"],["61803.40","0.002"],["61821.60","0.138"],["61834.20","0.014"],["61846.60","0.001"],["61847.40","0.000"],["61862.40","0.219"],["61863.50","0.000"],["61864.10","0.000"],["61867.40","0.005"],["61867.50","0.152"],["61875.90","0.594"],["61881.40","0.000"],["61883.00","0.007"],["61887.80","0.000"],["61889.00","0.284"],["61891.80","0.000"],["61894.60","0.501"],["61898.90","0.000"],["61899.40","0.669"],["61901.80","4.939"],["61902.10","1.362"],["61902.30","0.000"],["61902.60","0.003"],["61903.50","0.000"],["61905.20","0.002"],["61905.90","0.000"],["61906.80","0.003"],["61907.30","0.001"],["61910.50","0.003"],["61912.60","0.003"],["61917.80","0.289"],["61920.20","0.111"],["61920.40","0.154"],["61921.60","0.016"],["61922.40","0.001"],["61923.70","0.001"],["61924.20","0.963"],["61924.90","0.047"],["61927.10","0.000"],["61928.30","2.420"],["61929.00","0.045"],["61937.60","0.007"],["61937.70","1.183"],["61938.00","0.005"],["61943.10","0.000"],["61943.50","0.080"],["61943.80","0.000"],["61943.90","0.001"],["61945.10","1.363"],["61945.90","0.000"],["61946.50","0.036"],["61950.10","0.028"],["61951.50","0.000"],["61953.60","0.000"],["61955.20","0.000"],["61955.50","1.366"],["61955.60","0.032"],["61961.90","0.000"],["61962.00","0.077"],["61962.30","3.360"],["61963.10","12.093"],["61963.30","0.000"],["61966.40","0.015"],["61966.50","0.000"],["61966.60","0.126"],["61973.80","0.071"],["61974.80","0.016"],["61975.00","3.510"],["61975.10","2.936"],["61977.80","0.206"],["61978.10","0.085"],["61978.40","1.466"],["61979.30","0.001"],["61979.70","0.028"],["61980.20","0.292"],["61982.00","0.280"],["61985.50","0.000"],["61985.80","0.002"],["61987.10","1.982"],["61989.20","0.047"],["61989.40","0.000"],["61990.00","0.209"],["61990.10","6.612"],["61990.20","4.171"],["61990.90","0.496"],["61991.30","0.006"],["61992.20","1.113"],["61992.70","0.155"],["61994.00","0.000"],["61994.10","19.500"],["61995.00","0.000"],["61995.30","0.003"],["61995.90","0.000"],["61997.00","1.202"],["61997.40","0.277"],["61997.50","0.001"],["61998.40","0.030"],["61998.70","1.898"],["62000.00","8.933"],["62000.40","0.011"],["62001.20","0.004"],["62001.30","0.006"],["62001.50","0.000"],["62001.70","0.040"],["62002.00","0.004"],["62002.20","0.121"],["62002.70","1.417"],["62003.20","0.000"],["62003.40","0.002"],["62004.10","0.002"],["62004.50","0.157"],["62004.60","0.444"],["62004.70","0.000"],["62004.80","0.121"],["62005.10","0.006"],["62005.30","0.000"],["62005.50","1.529"],["62005.80","0.000"],["62006.20","0.005"],["62007.10","0.159"],["62007.20","0.129"],["62007.50","0.021"],["62007.60","0.003"],["62007.80","0.100"],["62008.00","0.012"],["62009.10","0.001"],["62009.70","0.002"],["62010.00","0.140"],["62010.60","0.055"],["62011.00","0.240"],["62012.90","0.452"],["62013.80","0.002"],["62014.00","0.097"],["62014.20","0.001"],["62014.30","0.001"],["62014.50","0.001"],["62014.60","0.335"],["62015.10","1.072"],["62015.30","0.001"],["62015.40","0.000"],["62015.80","0.000"],["62016.10","0.000"],["62016.20","0.000"],["62016.70","0.213"],["62017.00","0.727"],["62017.60","0.385"],["62017.70","0.122"],["62017.80","0.014"],["62017.90","0.001"],["62018.10","0.060"],["62018.30","0.000"],["62018.40","0.003"],["62018.50","0.665"],["62018.60","0.142"],["62018.70","0.002"],["62018.80","1.365"],["62018.90","0.310"],["62019.20","0.013"],["62019.30","0.001"],["62019.40","0.011"],["62019.50","0.003"],["62019.60","0.000"],["62019.80","0.009"],["62020.00","0.932"],["62020.10","0.000"],["62020.40","1.005"],["62020.50","0.000"],["62020.80","0.050"],["62020.90","0.000"],["62021.60","2.195"],["62021.90","0.082"],["62022.00","0.018"],["62022.40","0.132"],["62023.00","0.202"],["62023.10","0.009"],["62023.40","0.032"],["62023.50","0.013"],["62023.60","0.002"],["62023.70","0.020"],["62024.20","2.222"],["62024.40","0.064"],["62024.50","1.332"],["62024.70","0.000"],["62024.90","0.086"],["62025.20","0.035"],["62025.30","0.655"],["62025.50","0.003"],["62025.60","0.011"],["62025.70","0.010"],["62025.80","0.328"],["62026.40","0.172"],["62026.50","0.529"],["62026.70","0.002"],["62026.80","0.000"],["62026.90","0.005"],["62027.50","0.002"],["62027.70","0.000"],["62027.80","0.000"],["62027.90","0.004"],["62028.30","0.150"],["62028.60","1.108"],["62028.70","0.710"],["62028.80","0.092"],["62028.90","0.001"],["62029.20","0.005"],["62029.40","0.008"],["62029.60","0.013"],["62029.90","0.326"],["62030.00","0.008"],["62030.10","0.055"],["62030.60","0.282"],["62030.80","1.237"],["62031.00","0.007"],["62031.10","0.010"],["62031.30","0.086"],["62031.40","0.014"],["62031.50","0.052"],["62031.60","0.001"],["62032.00","0.685"],["62032.20","0.011"],["62032.50","1.351"],["62032.80","0.249"],["62032.90","0.000"],["62033.00","0.090"],["62033.20","0.105"],["62033.70","0.006"],["62033.80","0.021"],["62034.00","1.529"],["62034.30","0.000"],["62034.40","0.000"],["62034.60","1.295"],["62034.70","0.001"],["62034.80","0.000"],["62035.00","0.004"],["62035.10","0.004"],["62035.20","0.005"],["62035.40","0.000"],["62035.80","0.001"],["62035.90","0.050"],["62036.10","2.205"],["62036.30","1.464"],["62036.40","0.293"],["62036.60","0.912"],["62036.70","1.537"],["62036.80","0.681"],["62036.90","0.002"],["62037.00","0.004"],["62037.10","0.000"],["62037.20","0.003"],["62037.30","0.000"],["62037.50","0.004"],["62037.60","0.702"],["62037.70","0.003"],["62037.80","1.094"],["62038.00","0.005"],["62038.30","0.000"],["62038.50","0.001"],["62038.60","0.041"],["62038.70","0.084"],["62038.80","0.003"],["62038.90","0.008"],["62039.00","0.000"],["62039.20","0.001"],["62039.30","0.004"],["62039.50","0.005"],["62039.60","0.001"],["62039.70","1.413"],["62039.80","0.791"],["62040.00","0.008"],["62040.20","0.001"],["62040.30","0.112"],["62040.40","0.018"],["62040.50","0.002"],["62040.60","0.003"],["62040.80","0.001"],["62040.90","1.295"],["62041.00","0.881"],["62041.10","1.344"],["62041.20","0.535"],["62041.30","0.004"],["62041.40","0.000"],["62041.50","0.016"],["62041.60","0.001"],["62041.70","0.032"],["62041.80","0.010"],["62042.00","0.550"],["62042.10","0.326"],["62042.20","0.000"],["62042.30","2.049"],["62042.40","0.139"],["62042.60","1.555"],["62042.70","0.135"],["62043.00","0.885"],["62043.20","0.003"],["62043.50","0.003"],["62043.90","0.098"],["62044.30","0.054"],["62044.50","0.406"],["62044.60","1.106"],["62044.70","0.003"],["62044.80","1.417"],["62044.90","0.005"],["62045.00","0.500"],["62045.10","0.000"],["62045.20","0.061"],["62045.30","0.108"],["62045.50","0.002"],["62045.60","0.052"],["62045.70","0.177"],["62045.80","0.679"],["62046.00","0.050"],["62046.20","0.326"],["62046.30","0.830"],["62046.40","0.208"],["62046.50","0.063"],["62046.80","0.081"],["62047.00","0.000"],["62047.20","0.005"],["62047.40","1.295"],["62047.60","0.361"],["62047.70","0.000"],["62047.80","0.000"],["62047.90","0.001"],["62048.00","0.073"],["62048.10","0.053"],["62048.20","0.008"],["62048.40","0.151"],["62048.50","0.070"],["62048.60","0.003"],["62048.70","0.009"],["62048.90","0.123"],["62049.10","0.004"],["62049.40","0.001"],["62049.50","1.356"],["62049.60","0.024"],["62049.90","2.005"],["62050.00","0.062"],["62050.20","0.003"],["62050.30","0.024"],["62050.40","0.311"],["62050.50","0.060"],["62050.60","0.000"],["62050.80","0.002"],["62050.90","0.001"],["62051.10","0.001"],["62051.30","0.123"],["62051.40","0.004"],["62051.50","0.667"],["62051.70","0.005"],["62052.10","0.066"],["62052.30","0.003"],["62052.60","1.097"],["62052.70","0.359"],["62052.80","0.001"],["62053.40","0.001"],["62053.60","0.281"],["62053.70","1.338"],["62053.80","1.359"],["62053.90","0.029"],["62054.00","0.335"],["62054.10","0.569"],["62054.20","0.956"],["62054.30","0.190"],["62054.50","0.001"],["62054.70","0.021"],["62054.80","0.060"],["62054.90","0.354"],["62055.10","0.402"],["62055.30","0.012"],["62055.40","1.136"],["62055.50","0.005"],["62055.60","0.004"],["62055.70","0.000"],["62055.80","0.068"],["62055.90","0.185"],["62056.10","0.001"],["62056.20","1.560"],["62056.30","0.003"],["62056.50","1.001"],["62056.60","0.070"],["62056.80","1.051"],["62056.90","0.122"],["62057.10","0.002"],["62057.40","0.222"],["62057.50","1.667"],["62057.60","0.293"],["62057.70","1.201"],["62057.80","0.003"],["62058.00","0.823"],["62058.40","0.064"],["62058.50","0.001"],["62058.60","0.572"],["62058.70","0.206"],["62058.90","1.020"],["62059.00","0.123"],["62059.10","0.082"],["62059.20","0.383"],["62059.30","0.946"],["62059.50","0.001"],["62059.60","0.020"],["62059.70","0.002"],["62059.80","0.033"],["62060.10","0.055"],["62060.30","0.004"],["62060.50","0.006"],["62060.60","0.003"],["62060.70","0.282"],["62060.80","1.297"],["62060.90","0.366"],["62061.00","0.819"],["62061.10","0.049"],["62061.20","0.080"],["62061.30","0.817"],["62061.50","0.000"],["62061.60","0.100"],["62062.00","0.005"],["62062.10","0.005"],["62062.30","0.000"],["62062.70","0.002"],["62062.80","0.008"],["62062.90","0.051"],["62063.00","0.032"],["62063.10","0.001"],["62063.50","0.008"],["62063.70","0.354"],["62063.80","0.282"],["62063.90","0.374"],["62064.00","0.003"],["62064.40","0.121"],["62064.50","0.001"],["62064.60","0.002"],["62065.00","0.044"],["62065.20","0.049"],["62065.40","0.002"],["62065.50","0.000"],["62066.00","0.001"],["62066.20","0.007"],["62066.30","0.002"],["62066.40","0.000"],["62066.50","0.002"],["62066.60","0.029"],["62066.70","0.003"],["62066.80","0.005"],["62066.90","0.004"],["62067.00","0.000"],["62067.10","0.001"],["62067.20","0.129"],["62067.30","1.800"],["62067.40","0.305"],["62067.50","0.000"],["62067.70","0.323"],["62067.80","0.050"],["62067.90","0.000"],["62068.00","0.002"],["62068.10","0.007"],["62068.20","1.801"],["62068.30","0.000"],["62068.50","0.000"],["62068.60","0.001"],["62068.70","0.000"],["62069.00","0.000"],["62069.10","0.001"],["62069.20","0.000"],["62069.30","0.454"],["62069.40","1.800"],["62069.50","0.317"],["62069.60","0.000"],["62069.70","0.000"],["62069.80","0.000"],["62069.90","0.002"],["62070.00","0.003"],["62070.10","8.857"]],"e":"depthUpdate","ps":"BTCUSDT","pu":10998400923147,"s":"BTCUSDT","st":1,"u":10998400963404}
{"E":1783504328672,"T":1783504328671,"U":10998400963454,"a":[["62070.20","2.967"],["62070.30","0.004"],["62072.30","0.000"],["62073.50","0.001"],["62074.50","0.004"],["62074.80","0.734"],["62075.00","0.009"],["62075.60","0.031"],["62075.70","0.816"],["62075.80","0.001"],["62076.00","0.004"],["62076.20","0.091"],["62076.30","0.760"],["62076.40","0.113"],["62076.50","0.169"],["62076.60","0.064"],["62076.70","1.362"],["62076.80","0.823"],["62077.30","0.000"],["62077.50","0.514"],["62077.60","0.000"],["62077.70","0.001"],["62077.80","2.135"],["62077.90","1.108"],["62078.40","0.194"],["62078.50","1.001"],["62079.50","0.165"],["62080.80","0.001"],["62081.00","0.392"],["62081.20","0.254"],["62081.60","0.327"],["62082.20","1.362"],["62082.30","0.005"],["62082.40","0.012"],["62082.60","1.000"],["62083.50","0.463"],["62083.60","1.303"],["62084.00","1.019"],["62084.60","0.563"],["62084.80","1.514"],["62085.30","0.524"],["62085.50","0.656"],["62085.90","0.002"],["62087.10","0.005"],["62087.30","0.001"],["62088.20","0.671"],["62088.90","0.230"],["62089.00","0.101"],["62089.60","0.069"],["62089.90","0.862"],["62091.30","0.536"],["62091.50","1.363"],["62092.30","15.932"],["62092.60","0.034"],["62092.90","0.053"],["62093.60","0.062"],["62094.10","0.687"],["62094.60","0.001"],["62097.00","0.105"],["62097.70","0.070"],["62099.00","0.065"],["62099.10","0.016"],["62099.20","0.261"],["62100.00","0.646"],["62101.20","0.000"],["62101.70","0.175"],["62102.00","0.001"],["62102.20","0.175"],["62102.40","9.359"],["62103.90","1.372"],["62104.00","0.105"],["62104.40","0.001"],["62105.00","0.124"],["62105.50","0.579"],["62105.60","0.903"],["62107.40","0.687"],["62107.50","0.304"],["62108.30","0.182"],["62108.90","0.009"],["62109.00","0.000"],["62109.50","0.019"],["62109.60","0.058"],["62110.10","3.541"],["62110.90","0.000"],["62112.20","3.695"],["62113.10","0.003"],["62113.70","0.003"],["62113.80","3.156"],["62114.50","0.685"],["62116.00","0.002"],["62121.30","0.677"],["62122.20","0.574"],["62123.60","0.004"],["62123.90","0.578"],["62124.50","0.769"],["62124.90","1.379"],["62125.00","0.256"],["62126.10","0.287"],["62128.10","1.837"],["62130.40","0.001"],["62130.90","0.004"],["62131.70","0.899"],["62132.30","0.708"],["62133.40","0.001"],["62133.70","0.061"],["62134.30","3.910"],["62134.50","0.025"],["62134.70","22.486"],["62136.00","0.004"],["62136.20","0.000"],["62136.70","2.236"],["62136.80","0.002"],["62138.50","1.608"],["62138.90","0.022"],["62139.10","0.018"],["62144.70","0.312"],["62146.00","0.727"],["62149.30","0.001"],["62151.30","0.005"],["62151.40","2.233"],["62152.60","2.760"],["62161.70","0.142"],["62162.60","0.001"],["62164.90","3.100"],["62165.00","8.332"],["62171.40","0.040"],["62173.10","0.028"],["62175.50","0.000"],["62178.40","0.010"],["62193.00","0.002"],["62193.10","1.529"],["62201.90","0.029"],["62207.20","0.065"],["62210.70","0.003"],["62216.00","0.322"],["62329.90","0.599"],["62331.30","1.335"],["62472.30","0.425"],["62494.50","0.002"],["62494.90","0.008"],["62688.40","0.003"],["62688.70","0.006"],["62690.90","0.000"],["62700.00","7.524"],["62721.60","0.947"],["62721.70","2.345"],["62746.60","0.637"],["62781.50","0.000"],["62781.70","0.517"],["62781.80","4.283"],["62782.30","0.002"],["62782.40","1.907"],["62783.50","0.000"],["62783.60","0.000"],["62783.80","0.000"],["62784.30","3.786"],["62784.40","11.352"],["62814.70","1.576"],["62814.80","1.845"],["62843.60","0.005"],["62843.80","0.000"],["62844.40","0.318"],["62846.40","1.577"],["62846.50","7.092"],["62876.80","3.338"],["62876.90","10.241"],["62999.50","0.000"],["63032.10","0.942"],["63620.40","0.000"],["67593.00","0.000"],["67593.10","0.602"],["89523.20","0.192"]],"b":[["11559.60","1.408"],["11570.10","0.048"],["11670.10","0.096"],["11758.00","0.000"],["11970.10","0.400"],["50000.00","293.684"],["55863.00","0.005"],["58966.50","0.000"],["59587.20","0.000"],["61070.10","0.024"],["61128.40","0.980"],["61166.70","1.950"],["61197.80","0.277"],["61242.60","1.146"],["61252.80","0.326"],["61319.20","0.001"],["61341.90","2.260"],["61352.90","0.987"],["61390.20","0.730"],["61411.80","0.028"],["61434.40","1.898"],["61446.80","0.199"],["61449.40","0.004"],["61477.10","0.731"],["61514.00","0.000"],["61525.30","0.008"],["61566.90","0.959"],["61601.90","0.404"],["61624.30","0.005"],["61743.50","0.000"],["61749.30","0.011"],["61754.90","0.016"],["61785.30","0.000"],["61822.80","0.047"],["61829.10","0.692"],["61850.80","0.004"],["61863.50","0.001"],["61894.40","0.271"],["61894.50","0.002"],["61894.60","0.028"],["61898.20","0.003"],["61900.10","4.907"],["61925.20","0.000"],["61933.10","0.120"],["61944.50","0.000"],["61962.10","1.327"],["61968.00","0.068"],["61975.10","2.944"],["61980.80","0.222"],["61983.70","0.002"],["61983.80","0.000"],["61984.70","0.001"],["61984.80","1.530"],["61987.20","0.000"],["61989.20","0.000"],["61990.20","1.455"],["61994.10","0.055"],["61994.60","0.472"],["61995.20","0.850"],["61996.30","0.001"],["61996.50","0.000"],["61998.40","0.030"],["62002.40","0.032"],["62002.60","19.252"],["62002.70","6.628"],["62002.80","0.004"],["62003.10","0.046"],["62005.50","0.000"],["62005.60","1.564"],["62006.10","1.299"],["62006.40","0.016"],["62006.60","0.002"],["62006.80","2.171"],["62007.80","0.000"],["62008.00","0.263"],["62008.20","0.003"],["62008.60","0.392"],["62008.80","1.860"],["62010.00","0.136"],["62010.60","0.000"],["62012.70","0.884"],["62014.00","0.197"],["62017.00","0.680"],["62017.10","0.002"],["62017.50","0.000"],["62018.40","0.001"],["62020.60","0.000"],["62021.20","0.000"],["62021.60","2.197"],["62024.00","0.698"],["62024.60","0.293"],["62025.00","0.002"],["62025.30","0.654"],["62025.40","0.457"],["62026.60","0.000"],["62027.30","0.005"],["62027.60","0.000"],["62028.80","0.090"],["62030.10","0.053"],["62030.80","1.241"],["62032.60","0.316"],["62033.00","0.000"],["62033.80","0.019"],["62035.10","0.002"],["62036.10","2.205"],["62039.10","0.001"],["62039.90","0.105"],["62040.70","0.026"],["62042.60","1.028"],["62042.70","0.003"],["62043.90","0.096"],["62044.10","0.057"],["62044.60","2.423"],["62045.20","0.001"],["62045.30","0.048"],["62045.40","0.002"],["62046.30","1.201"],["62046.40","0.079"],["62046.50","0.003"],["62047.50","1.776"],["62048.10","0.051"],["62048.40","0.005"],["62048.50","0.070"],["62049.50","1.296"],["62049.80","0.293"],["62050.00","0.078"],["62050.90","0.121"],["62051.40","0.005"],["62052.60","2.341"],["62052.70","1.284"],["62053.80","1.479"],["62054.00","0.005"],["62055.00","2.031"],["62055.30","0.001"],["62055.60","0.002"],["62056.20","1.538"],["62056.80","0.232"],["62056.90","0.002"],["62057.00","0.001"],["62057.30","0.298"],["62057.40","0.226"],["62057.50","1.427"],["62057.70","0.133"],["62057.90","0.047"],["62058.00","0.066"],["62058.20","0.032"],["62058.60","0.008"],["62058.70","0.210"],["62058.90","1.414"],["62059.30","0.966"],["62059.60","0.017"],["62060.40","0.066"],["62060.90","0.047"],["62061.00","0.821"],["62061.40","1.947"],["62061.50","2.460"],["62061.60","0.111"],["62062.80","0.006"],["62063.80","0.282"],["62063.90","0.265"],["62064.00","1.365"],["62064.10","0.317"],["62064.50","0.081"],["62065.00","0.197"],["62065.60","0.003"],["62066.60","0.024"],["62067.10","0.004"],["62067.20","0.129"],["62067.30","1.801"],["62067.40","0.306"],["62068.10","0.005"],["62068.50","0.004"],["62069.60","0.000"],["62069.90","0.002"],["62070.00","0.005"],["62070.10","8.336"]],"e":"depthUpdate","ps":"BTCUSDT","pu":10998400963404,"s":"BTCUSDT","st":1,"u":10998400980094}
{"E":1783504328774,"T":1783504328773,"U":10998400980314,"a":[["62070.20","4.068"],["62071.40","0.005"],["62071.80","0.025"],["62072.20","0.644"],["62072.90","0.050"],["62073.40","0.002"],["62074.00","0.001"],["62074.50","0.820"],["62074.70","0.002"],["62075.60","0.547"],["62076.20","0.413"],["62076.50","0.165"],["62076.80","0.824"],["62077.10","1.013"],["62077.40","0.091"],["62077.50","0.409"],["62077.70","0.293"],["62077.90","0.464"],["62078.50","0.001"],["62078.80","0.050"],["62079.30","0.062"],["62079.70","0.002"],["62079.90","0.325"],["62080.00","0.508"],["62080.30","0.005"],["62080.40","0.085"],["62080.70","0.171"],["62081.10","0.165"],["62081.30","1.497"],["62081.60","0.429"],["62081.90","0.128"],["62082.00","0.329"],["62082.10","0.162"],["62083.40","0.041"],["62087.40","0.582"],["62087.70","0.164"],["62087.90","0.004"],["62089.60","0.053"],["62089.70","0.784"],["62090.20","0.003"],["62091.00","0.005"],["62092.10","0.197"],["62093.70","0.030"],["62094.10","0.807"],["62095.20","0.002"],["62095.90","0.021"],["62096.60","0.362"],["62098.00","0.001"],["62098.50","0.093"],["62099.00","0.030"],["62099.20","0.225"],["62101.90","0.062"],["62102.30","3.160"],["62102.60","0.000"],["62103.80","0.324"],["62104.00","0.000"],["62105.00","0.121"],["62105.50","0.489"],["62110.70","0.061"],["62111.30","2.462"],["62112.20","3.779"],["62114.30","0.006"],["62121.80","0.011"],["62123.60","0.000"],["62124.00","0.107"],["62124.50","0.679"],["62124.90","1.481"],["62125.10","0.452"],["62125.70","0.125"],["62126.10","0.290"],["62127.00","0.000"],["62127.20","0.047"],["62128.60","2.656"],["62128.80","0.173"],["62131.70","0.903"],["62132.30","0.954"],["62133.10","0.106"],["62133.30","0.082"],["62133.70","0.003"],["62134.50","0.000"],["62139.10","4.109"],["62143.60","0.007"],["62163.90","0.000"],["62174.40","0.008"],["62188.70","0.257"],["62190.10","0.120"],["62191.40","0.026"],["62196.10","0.008"],["62216.70","0.000"],["62223.80","0.072"],["62238.00","0.032"],["62410.70","0.050"],["62427.10","0.000"],["62430.60","0.008"],["62687.80","0.000"],["62690.90","0.000"],["62691.50","0.008"],["62703.20","0.000"],["62746.80","0.711"]],"b":[["11559.60","1.136"],["11570.10","0.192"],["11667.20","0.000"],["11668.10","0.000"],["11669.30","0.000"],["11670.10","0.000"],["11970.10","0.672"],["55863.00","0.005"],["58945.80","0.000"],["58945.90","0.006"],["58966.50","0.000"],["61147.30","1.389"],["61276.50","0.000"],["61449.40","0.004"],["61624.40","0.000"],["61656.10","0.895"],["61687.20","0.408"],["61822.80","0.000"],["61844.40","0.692"],["61863.50","0.000"],["61865.60","0.662"],["61975.80","0.000"],["61981.10","0.001"],["61984.20","0.516"],["61986.40","0.016"],["61988.30","0.029"],["61990.00","0.256"],["61990.50","0.016"],["61990.90","0.254"],["61991.50","0.343"],["61992.30","0.000"],["61994.50","1.383"],["61996.40","0.000"],["61996.70","0.002"],["61998.40","0.030"],["61998.50","0.726"],["61998.70","1.898"],["62000.30","0.000"],["62000.50","19.208"],["62000.60","4.627"],["62002.50","0.691"],["62002.60","0.048"],["62002.70","1.417"],["62006.80","2.171"],["62008.80","1.860"],["62015.20","1.362"],["62016.20","4.099"],["62018.00","0.255"],["62021.70","0.839"],["62021.90","0.133"],["62022.00","0.018"],["62022.10","0.122"],["62024.10","0.059"],["62025.90","0.001"],["62026.50","0.528"],["62027.50","0.000"],["62028.00","1.467"],["62028.70","0.708"],["62028.80","0.222"],["62030.00","0.006"],["62031.20","0.294"],["62032.10","0.002"],["62032.50","1.349"],["62033.70","0.004"],["62034.90","0.512"],["62038.50","0.005"],["62038.60","0.001"],["62039.40","0.001"],["62042.50","0.337"],["62043.10","0.000"],["62044.00","2.665"],["62044.60","2.101"],["62044.80","1.364"],["62045.10","0.302"],["62046.00","0.001"],["62046.30","1.241"],["62046.60","0.000"],["62046.90","0.018"],["62047.00","0.016"],["62047.20","0.004"],["62047.50","2.476"],["62048.50","0.058"],["62048.60","0.583"],["62049.30","0.060"],["62049.90","1.425"],["62050.00","0.018"],["62050.10","0.051"],["62051.70","0.133"],["62052.20","0.001"],["62052.60","2.343"],["62052.90","0.725"],["62053.50","0.050"],["62053.80","1.359"],["62053.90","0.021"],["62054.20","0.231"],["62055.50","0.327"],["62056.10","0.003"],["62056.40","0.020"],["62056.60","0.130"],["62057.30","0.278"],["62057.50","1.487"],["62057.60","0.301"],["62057.70","0.002"],["62057.80","0.325"],["62057.90","0.167"],["62058.10","0.328"],["62058.30","0.080"],["62058.50","0.093"],["62058.70","0.242"],["62058.90","1.027"],["62059.00","0.155"],["62059.70","0.056"],["62060.50","0.005"],["62060.80","1.295"],["62060.90","0.047"],["62061.00","0.004"],["62061.30","0.000"],["62061.40","1.815"],["62061.50","1.244"],["62061.60","0.111"],["62061.70","0.000"],["62061.80","0.564"],["62062.90","0.049"],["62063.60","0.003"],["62063.70","0.346"],["62063.80","0.281"],["62064.10","0.318"],["62064.50","0.001"],["62064.60","0.052"],["62064.80","0.004"],["62066.50","0.000"],["62066.70","0.002"],["62066.80","0.000"],["62067.80","0.000"],["62068.60","0.009"],["62069.50","0.002"],["62070.00","0.007"],["62070.10","8.262"]],"e":"depthUpdate","ps":"BTCUSDT","pu":10998400980094,"s":"BTCUSDT","st":1,"u":10998400990481}
{"E":1783504328876,"T":1783504328875,"U":10998400990584,"a":[["62070.20","4.110"],["62072.10","0.191"],["62073.90","0.002"],["62074.40","0.709"],["62076.30","0.091"],["62077.80","1.740"],["62077.90","0.456"],["62078.10","0.748"],["62078.20","0.000"],["62081.20","0.422"],["62081.30","1.555"],["62081.80","0.197"],["62081.90","0.218"],["62083.30","0.152"],["62088.90","0.231"],["62089.30","0.003"],["62089.70","0.701"],["62090.00","2.651"],["62090.40","1.297"],["62090.50","0.060"],["62090.60","0.001"],["62093.60","0.000"],["62096.10","0.105"],["62096.60","0.284"],["62097.00","0.003"],["62097.30","0.836"],["62099.20","0.226"],["62100.80","0.051"],["62102.40","9.448"],["62102.50","0.785"],["62102.60","0.000"],["62106.80","0.918"],["62107.00","0.005"],["62109.00","0.090"],["62109.60","0.190"],["62119.90","0.539"],["62123.30","0.007"],["62124.50","0.679"],["62146.30","0.017"],["62151.40","0.705"],["62151.50","1.746"],["62153.40","0.023"],["62156.20","0.028"],["62157.60","0.045"],["62172.20","0.141"],["62172.30","1.556"],["62193.10","0.001"],["62193.20","1.527"],["62241.40","0.025"],["62241.60","0.030"],["62595.60","5.615"],["62626.70","3.446"],["62628.80","1.344"],["62659.90","3.061"],["62690.90","0.000"],["62863.90","0.003"],["63622.00","2.279"],["89523.20","0.198"]],"b":[["1000.00","210.942"],["11559.60","0.864"],["11570.10","0.320"],["11666.60","0.096"],["11970.10","0.944"],["55863.00","0.005"],["58939.00","0.102"],["59587.20","0.003"],["60828.70","0.003"],["61072.40","4.582"],["61104.70","1.134"],["61134.40","10.520"],["61166.70","3.083"],["61259.70","0.327"],["61284.30","0.814"],["61288.20","9.420"],["61291.90","0.000"],["61320.50","5.070"],["61321.90","6.458"],["61341.90","1.534"],["61347.00","0.840"],["61352.90","1.955"],["61390.20","2.182"],["61433.80","0.576"],["61449.40","0.004"],["61477.10","2.181"],["61563.10","0.973"],["61723.70","0.162"],["61790.10","0.003"],["61796.50","0.029"],["61860.10","0.000"],["61860.20","1.536"],["61860.30","0.787"],["61863.50","0.001"],["61956.30","2.088"],["61962.50","6.864"],["61980.80","0.254"],["61984.80","0.000"],["61984.90","1.586"],["62001.40","0.016"],["62005.60","0.035"],["62005.70","1.529"],["62010.30","0.004"],["62018.10","0.000"],["62018.50","1.056"],["62022.40","0.131"],["62024.10","0.119"],["62024.20","1.422"],["62024.40","0.003"],["62036.10","0.062"],["62036.70","1.012"],["62049.30","0.000"],["62049.50","1.236"],["62049.80","0.233"],["62049.90","1.365"],["62050.40","0.279"],["62050.50","0.000"],["62050.80","2.145"],["62051.00","0.040"],["62052.00","0.001"],["62052.10","0.002"],["62052.70","1.252"],["62053.80","1.327"],["62053.90","0.343"],["62055.50","0.005"],["62057.30","0.338"],["62057.40","0.286"],["62057.60","0.865"],["62057.90","0.199"],["62058.00","0.186"],["62060.90","0.048"],["62061.50","0.889"],["62061.80","0.000"],["62063.70","0.345"],["62064.00","1.366"],["62065.80","0.004"],["62066.10","0.595"],["62066.20","0.039"],["62066.70","0.002"],["62067.80","0.003"],["62068.00","0.102"],["62069.30","0.456"],["62070.00","0.005"],["62070.10","7.928"]],"e":"depthUpdate","ps":"BTCUSDT","pu":10998400990481,"s":"BTCUSDT","st":1,"u":10998400998067}
{"E":1783504328978,"T":1783504328977,"U":10998400998145,"a":[["62070.20","2.968"],["62072.10","0.192"],["62072.90","0.001"],["62073.00","0.050"],["62073.40","0.004"],["62074.30","0.002"],["62074.40","0.814"],["62075.50","0.341"],["62077.80","0.923"],["62078.10","0.000"],["62079.30","0.215"],["62080.60","0.149"],["62081.30","1.663"],["62081.80","0.437"],["62081.90","0.308"],["62083.50","0.463"],["62084.80","2.239"],["62086.50","0.016"],["62086.70","0.426"],["62087.00","0.081"],["62089.60","0.061"],["62091.70","0.024"],["62092.10","0.277"],["62092.50","0.875"],["62093.70","0.110"],["62095.90","0.001"],["62103.80","0.413"],["62123.30","0.103"],["62125.10","0.362"],["62126.50","2.413"],["62130.90","0.001"],["62133.70","0.061"],["62137.90","0.250"],["62152.40","0.108"],["62152.90","0.147"],["62153.00","0.090"],["62157.10","0.027"],["62158.50","0.000"],["62220.90","0.042"],["62224.80","0.011"],["62245.90","0.558"],["62253.80","0.030"],["62256.20","0.028"],["62258.50","0.000"],["62265.80","0.170"],["62278.00","0.002"],["62504.70","0.245"],["62533.60","0.001"],["62564.60","0.000"],["62566.80","1.108"],["62595.60","0.000"],["62597.80","1.585"],["62626.70","2.181"],["62628.80","6.956"],["62657.70","1.943"],["62659.90","4.325"],["62687.10","0.003"],["62690.90","1.976"]],"b":[["11559.60","0.592"],["11570.10","0.464"],["11663.70","0.112"],["11666.40","0.000"],["11666.60","0.000"],["11970.10","1.216"],["55863.00","0.005"],["58966.50","0.000"],["59587.20","0.000"],["61010.30","1.146"],["61042.60","1.190"],["61159.90","7.284"],["61197.70","0.277"],["61197.80","5.131"],["61247.70","0.411"],["61284.00","8.111"],["61288.20","7.790"],["61289.50","3.420"],["61321.90","11.300"],["61449.40","0.004"],["61728.30","0.012"],["61749.20","0.354"],["61749.30","0.001"],["61759.70","0.010"],["61764.80","0.002"],["61805.40","0.000"],["61811.20","0.000"],["61813.30","0.136"],["61863.50","0.000"],["61886.20","0.000"],["61905.60","0.002"],["61981.10","0.033"],["61991.50","0.101"],["61998.90","0.244"],["62017.40","0.262"],["62021.90","0.133"],["62022.10","0.041"],["62022.20","0.163"],["62026.40","0.232"],["62038.40","0.232"],["62046.80","0.130"],["62049.90","1.485"],["62050.50","0.008"],["62051.70","0.005"],["62052.00","0.701"],["62053.00","0.564"],["62053.20","0.013"],["62053.50","0.001"],["62054.10","0.005"],["62057.40","0.346"],["62057.70","0.002"],["62061.60","0.859"],["62066.20","0.041"],["62066.60","0.021"],["62066.70","0.076"],["62067.40","0.308"],["62070.10","7.901"]],"e":"depthUpdate","ps":"BTCUSDT","pu":10998400998067,"s":"BTCUSDT","st":1,"u":10998401013194}
{"E":1783504329080,"T":1783504329079,"U":10998401013236,"a":[["62070.20","2.973"],["62074.40","0.778"],["62075.60","0.411"],["62076.50","0.169"],["62077.20","0.000"],["62080.00","0.331"],["62081.60","0.444"],["62082.70","0.044"],["62088.90","0.235"],["62089.70","0.702"],["62091.70","0.008"],["62093.70","0.030"],["62096.10","0.003"],["62096.40","0.411"],["62097.20","0.010"],["62097.30","0.746"],["62099.20","0.262"],["62099.70","0.657"],["62100.80","0.052"],["62102.00","0.053"],["62102.40","9.553"],["62103.80","0.518"],["62109.10","0.355"],["62109.40","0.056"],["62109.60","0.058"],["62110.20","0.255"],["62123.30","0.007"],["62130.80","0.000"],["62134.70","22.470"],["62140.90","0.000"],["62145.80","0.027"],["62146.30","0.037"],["62147.10","0.002"],["62149.80","0.424"],["62152.00","0.730"],["62158.20","1.285"],["62160.00","0.386"],["62230.40","0.029"],["62240.00","0.448"],["62320.00","0.384"],["62380.60","0.160"],["62400.00","14.339"],["62690.60","0.002"],["62690.90","1.974"],["89523.20","0.204"]],"b":[["11559.60","0.400"],["11570.10","0.592"],["11660.50","0.032"],["11663.70","0.000"],["11870.10","0.080"],["11970.10","1.328"],["49654.50","0.000"],["55863.00","0.005"],["58966.50","0.000"],["59587.20","0.003"],["61134.40","9.377"],["61159.90","2.428"],["61166.70","4.216"],["61197.80","9.985"],["61284.00","6.496"],["61289.40","4.995"],["61320.50","4.093"],["61321.90","14.528"],["61341.90","0.808"],["61352.90","2.923"],["61390.20","2.908"],["61425.60","0.054"],["61434.20","1.384"],["61449.40","0.004"],["61458.40","6.260"],["61680.00","0.940"],["61749.30","0.000"],["61759.70","0.011"],["61760.00","0.432"],["61840.00","0.288"],["61863.50","0.001"],["61920.00","0.345"],["61986.80","0.037"],["61998.90","0.272"],["61999.80","0.035"],["62000.00","8.756"],["62000.20","1.031"],["62003.10","0.043"],["62014.20","0.059"],["62021.60","2.195"],["62021.90","0.001"],["62022.20","0.084"],["62022.40","0.212"],["62024.00","0.697"],["62028.80","0.090"],["62030.10","0.113"],["62031.30","0.088"],["62033.00","0.792"],["62041.20","0.455"],["62042.20","0.002"],["62042.30","2.051"],["62044.50","0.422"],["62047.50","2.478"],["62048.30","0.032"],["62050.20","0.083"],["62051.30","0.003"],["62053.00","0.000"],["62054.20","0.171"],["62054.30","0.188"],["62054.50","0.021"],["62055.00","2.029"],["62055.10","0.966"],["62055.60","0.000"],["62056.20","1.536"],["62056.40","0.000"],["62057.40","0.342"],["62059.10","0.086"],["62060.80","1.296"],["62061.70","0.132"],["62066.60","0.020"],["62069.30","0.458"],["62070.10","7.902"]],"e":"depthUpdate","ps":"BTCUSDT","pu":10998401013194,"s":"BTCUSDT","st":1,"u":10998401027841}
{"E":1783504329182,"T":1783504329181,"U":10998401027922,"a":[["62070.20","2.970"],["62071.80","0.057"],["62073.00","0.001"],["62074.40","0.673"],["62076.20","0.324"],["62076.30","0.002"],["62076.50","0.165"],["62076.60","0.068"],["62080.80","0.003"],["62081.10","0.003"],["62081.30","1.646"],["62081.60","0.429"],["62082.10","0.000"],["62082.60","0.754"],["62082.70","0.041"],["62084.80","1.514"],["62085.70","1.069"],["62087.10","0.007"],["62087.40","0.002"],["62087.70","0.002"],["62088.60","0.580"],["62088.90","0.231"],["62092.10","0.115"],["62094.50","0.043"],["62103.00","0.127"],["62103.60","0.108"],["62103.80","0.413"],["62106.10","0.005"],["62118.20","0.002"],["62123.30","0.007"],["62137.20","0.007"],["62149.30","0.003"],["62152.40","0.000"],["62160.00","0.563"],["62168.30","0.009"],["62180.40","0.002"],["62214.60","0.038"],["62234.80","0.000"],["62236.20","0.004"],["62240.00","0.625"],["62320.00","0.561"],["62380.60","0.161"],["62400.00","14.516"],["62480.00","1.005"],["62690.90","1.974"],["62852.80","1.588"],["62957.30","0.000"],["63132.00","1.197"]],"b":[["1000.00","210.942"],["11559.60","0.256"],["11570.10","0.736"],["11659.60","0.864"],["11660.50","0.000"],["11870.10","0.208"],["11970.10","1.344"],["55863.00","0.005"],["58966.50","0.000"],["61004.50","0.732"],["61069.80","2.290"],["61071.10","4.414"],["61108.00","2.369"],["61131.80","3.431"],["61133.10","2.614"],["61146.40","1.143"],["61170.10","2.266"],["61252.90","3.509"],["61258.50","2.733"],["61263.20","0.330"],["61294.20","1.681"],["61315.40","1.064"],["61449.40","0.004"],["61680.00","1.117"],["61760.00","0.609"],["61840.00","0.465"],["61863.50","0.000"],["61920.00","0.522"],["61948.00","0.016"],["61955.60","0.029"],["61957.00","0.004"],["61960.00","0.044"],["61979.00","0.000"],["61991.00","0.943"],["61995.90","0.020"],["62000.00","8.933"],["62000.70","0.718"],["62004.20","0.001"],["62008.80","1.424"],["62010.10","0.000"],["62016.70","0.229"],["62022.10","0.043"],["62022.40","0.131"],["62022.70","0.082"],["62031.40","0.000"],["62032.20","0.027"],["62036.20","0.065"],["62037.70","0.017"],["62038.50","0.005"],["62039.50","0.003"],["62046.60","0.000"],["62049.00","0.678"],["62051.30","0.023"],["62054.50","0.001"],["62059.40","0.002"],["62059.60","0.033"],["62061.60","0.763"],["62065.70","0.002"],["62066.40","0.056"],["62067.00","0.040"],["62069.30","0.460"]],"e":"depthUpdate","ps":"BTCUSDT","pu":10998401027841,"s":"BTCUSDT","st":1,"u":10998401041667}
{"E":1783504329284,"T":1783504329283,"U":10998401041839,"a":[["62070.20","2.334"],["62072.70","0.000"],["62075.50","0.018"],["62077.10","0.013"],["62077.40","0.002"],["62078.40","1.194"],["62081.10","0.165"],["62081.20","0.584"],["62082.60","0.263"],["62083.90","0.007"],["62085.50","0.736"],["62087.70","0.164"],["62089.60","0.053"],["62091.00","0.013"],["62092.10","0.277"],["62109.10","0.433"],["62109.70","1.399"],["62116.60","0.001"],["62122.00","0.080"],["62123.30","0.007"],["62133.10","0.084"],["62153.00","0.000"],["62154.00","0.018"],["62175.30","0.001"],["62180.30","0.673"],["62189.20","0.814"],["62197.30","0.006"],["62202.20","0.626"],["62242.50","0.000"],["62344.20","0.160"],["62380.60","0.162"],["62422.30","0.045"],["62504.70","0.737"],["62690.90","1.974"],["62808.10","3.471"],["89523.20","0.210"]],"b":[["11559.60","0.128"],["11570.10","0.864"],["11659.60","0.736"],["11870.10","0.352"],["11970.10","1.328"],["55863.00","0.005"],["58966.50","0.000"],["59587.20","0.000"],["60807.30","0.003"],["61072.40","3.437"],["61108.00","3.503"],["61134.40","8.233"],["61165.50","5.012"],["61170.10","3.399"],["61199.10","2.428"],["61288.20","6.160"],["61320.50","3.116"],["61323.30","1.658"],["61356.30","1.205"],["61449.40","0.004"],["61750.10","0.000"],["61759.70","0.011"],["61863.50","0.001"],["61912.00","0.007"],["61928.90","0.001"],["61938.30","0.538"],["61978.10","0.088"],["62004.40","0.016"],["62008.00","0.343"],["62016.20","4.101"],["62016.40","0.017"],["62022.70","0.001"],["62023.00","0.283"],["62029.50","0.060"],["62030.10","0.173"],["62032.20","0.011"],["62042.30","2.054"],["62047.50","1.778"],["62048.70","0.089"],["62053.90","0.907"],["62055.10","0.402"],["62056.20","1.538"],["62057.60","0.866"],["62059.10","0.082"],["62060.30","0.008"],["62066.60","0.016"],["62070.10","7.902"]],"e":"depthUpdate","ps":"BTCUSDT","pu":10998401041667,"s":"BTCUSDT","st":1,"u":10998401054206}
{"E":1783504329386,"T":1783504329385,"U":10998401054485,"a":[["62070.20","2.418"],["62072.10","0.126"],["62074.30","0.001"],["62074.40","0.093"],["62075.50","0.026"],["62075.60","0.000"],["62076.20","0.002"],["62076.40","0.202"],["62076.50","0.737"],["62076.60","0.637"],["62077.60","0.000"],["62077.80","0.842"],["62078.10","0.000"],["62078.70","0.344"],["62078.80","0.000"],["62079.20","0.099"],["62079.50","0.003"],["62079.90","0.000"],["62080.50","0.100"],["62080.90","0.327"],["62081.00","0.714"],["62081.10","0.327"],["62081.20","0.260"],["62081.60","0.188"],["62082.00","0.007"],["62082.10","0.000"],["62082.60","0.261"],["62082.90","0.326"],["62083.00","0.564"],["62083.10","0.002"],["62083.30","0.474"],["62083.50","0.463"],["62084.20","0.002"],["62084.40","0.143"],["62085.60","0.828"],["62085.70","0.344"],["62086.10","0.018"],["62087.70","0.326"],["62090.00","3.629"],["62091.00","0.713"],["62091.20","0.009"],["62092.10","0.439"],["62093.20","2.187"],["62094.30","0.064"],["62098.80","0.000"],["62099.50","2.298"],["62099.80","0.631"],["62100.70","0.016"],["62101.50","0.003"],["62102.30","3.055"],["62103.50","0.004"],["62103.60","0.003"],["62104.00","0.000"],["62104.20","0.658"],["62105.00","0.221"],["62106.20","0.013"],["62106.80","0.000"],["62109.40","0.000"],["62110.40","0.003"],["62110.50","0.001"],["62112.30","0.211"],["62112.80","1.362"],["62113.20","0.002"],["62115.10","0.002"],["62115.20","0.158"],["62119.30","0.000"],["62121.20","0.001"],["62121.40","0.030"],["62121.70","0.016"],["62152.90","0.003"],["62173.90","0.675"],["62247.10","0.003"],["62492.30","0.249"],["62690.90","1.974"],["62945.40","1.586"],["62963.50","19.660"]],"b":[["1000.00","210.542"],["11559.60","0.000"],["11570.10","1.008"],["11659.60","0.592"],["11870.10","0.496"],["11970.10","1.312"],["49656.00","0.000"],["55863.00","0.005"],["58966.50","0.000"],["59587.20","0.003"],["61041.40","2.290"],["61077.00","2.497"],["61134.00","5.142"],["61134.40","7.089"],["61134.60","0.016"],["61165.40","4.575"],["61170.10","6.798"],["61199.10","4.855"],["61324.50","1.358"],["61341.90","0.001"],["61356.30","2.173"],["61393.50","0.806"],["61444.60","1.463"],["61449.40","0.004"],["61480.40","1.661"],["61863.50","0.000"],["61951.40","0.002"],["61953.30","0.003"],["61960.80","4.034"],["61965.90","0.101"],["61969.60","0.003"],["62000.50","0.004"],["62001.80","0.836"],["62004.30","0.255"],["62004.40","0.000"],["62004.50","0.001"],["62005.20","0.497"],["62006.80","21.375"],["62018.60","0.064"],["62019.30","0.003"],["62019.40","0.001"],["62019.50","0.001"],["62019.60","0.010"],["62021.00","0.016"],["62021.30","0.002"],["62022.20","0.082"],["62023.00","0.204"],["62023.10","0.009"],["62023.30","0.082"],["62025.10","0.063"],["62027.40","0.051"],["62028.90","0.003"],["62029.40","0.005"],["62036.70","1.015"],["62037.50","0.001"],["62038.70","0.072"],["62038.80","0.015"],["62039.80","0.732"],["62041.10","1.336"],["62042.10","0.334"],["62042.60","1.020"],["62043.30","0.009"],["62046.00","0.017"],["62046.20","0.385"],["62046.30","1.000"],["62046.90","0.006"],["62047.80","0.012"],["62048.70","0.009"],["62048.90","0.133"],["62049.60","0.014"],["62049.90","1.365"],["62051.00","0.120"],["62051.50","0.734"],["62053.00","0.564"],["62053.90","0.141"],["62054.30","0.128"],["62054.80","0.000"],["62054.90","0.356"],["62055.00","2.031"],["62055.90","0.125"],["62056.60","0.110"],["62057.70","0.324"],["62059.00","0.123"],["62060.70","0.342"],["62060.80","1.356"],["62060.90","0.108"],["62061.30","0.060"],["62061.90","0.033"],["62062.00","0.068"],["62062.50","0.032"],["62064.60","0.002"],["62064.80","0.024"],["62065.40","0.003"],["62065.80","0.000"],["62066.30","0.052"],["62067.30","1.802"],["62068.50","0.006"],["62069.50","0.123"],["62070.10","7.980"]],"e":"depthUpdate","ps":"BTCUSDT","pu":10998401054206,"s":"BTCUSDT","st":1,"u":10998401068799}
{"E":1783504329488,"T":1783504329487,"U":10998401068869,"a":[["62070.20","0.000"],["62070.30","0.000"],["62070.40","0.000"],["62070.60","0.000"],["62070.70","0.000"],["62071.00","0.000"],["62071.10","0.000"],["62071.20","0.000"],["62071.30","0.000"],["62071.40","0.000"],["62071.50","0.000"],["62071.60","0.000"],["62071.80","0.000"],["62071.90","0.000"],["62072.00","4.054"],["62072.10","0.005"],["62072.20","0.000"],["62072.40","0.000"],["62072.50","0.000"],["62072.60","0.002"],["62073.10","0.001"],["62073.40","0.002"],["62073.90","0.000"],["62074.40","0.005"],["62074.50","0.001"],["62074.60","0.003"],["62074.80","0.301"],["62075.10","0.008"],["62075.30","0.005"],["62075.40","0.008"],["62075.50","0.024"],["62075.70","0.000"],["62075.90","0.001"],["62076.00","0.003"],["62076.20","0.650"],["62076.30","0.002"],["62076.40","0.064"],["62076.50","0.566"],["62076.60","0.000"],["62076.70","0.000"],["62076.80","0.317"],["62077.00","0.008"],["62077.10","0.011"],["62077.50","0.224"],["62077.70","0.001"],["62077.80","0.433"],["62077.90","0.007"],["62078.00","0.601"],["62078.20","0.023"],["62078.40","0.199"],["62078.70","1.002"],["62079.20","0.099"],["62079.30","0.220"],["62079.40","0.000"],["62079.50","0.002"],["62079.60","0.001"],["62079.80","0.004"],["62080.30","0.357"],["62080.40","0.085"],["62080.50","0.050"],["62080.60","0.112"],["62080.80","0.067"],["62080.90","1.370"],["62081.00","0.392"],["62081.10","0.003"],["62081.30","0.970"],["62081.40","0.061"],["62081.50","0.367"],["62081.80","0.437"],["62082.00","0.010"],["62082.10","0.322"],["62082.20","0.000"],["62082.30","0.015"],["62082.50","0.093"],["62082.60","0.010"],["62082.90","0.002"],["62083.00","0.000"],["62083.30","0.457"],["62083.40","1.363"],["62083.50","0.343"],["62083.60","0.003"],["62083.90","1.302"],["62084.00","0.699"],["62084.20","0.003"],["62084.30","0.161"],["62084.40","0.394"],["62084.50","0.454"],["62084.70","1.036"],["62084.80","0.152"],["62085.00","0.001"],["62085.30","0.846"],["62085.50","0.006"],["62085.60","0.103"],["62085.70","0.349"],["62085.90","0.002"],["62086.50","0.002"],["62086.60","0.162"],["62087.20","0.000"],["62087.50","0.418"],["62087.70","1.049"],["62087.80","1.026"],["62088.20","0.151"],["62088.60","0.000"],["62088.80","0.003"],["62089.00","0.100"],["62089.90","0.826"],["62090.30","1.385"],["62090.40","1.960"],["62090.50","0.008"],["62091.00","0.701"],["62091.10","0.011"],["62092.10","0.000"],["62092.40","0.005"],["62092.80","0.096"],["62093.10","0.203"],["62093.50","0.000"],["62093.70","0.067"],["62093.90","0.243"],["62094.10","0.687"],["62094.20","0.691"],["62094.30","0.001"],["62094.40","0.661"],["62094.50","0.017"],["62095.10","0.343"],["62095.30","0.000"],["62095.50","0.072"],["62095.60","0.078"],["62095.70","0.015"],["62095.90","0.121"],["62096.10","0.059"],["62097.00","0.003"],["62097.10","0.011"],["62097.70","0.140"],["62098.30","0.001"],["62098.50","0.003"],["62098.60","0.001"],["62099.20","0.912"],["62099.50","2.290"],["62099.60","1.541"],["62099.90","0.699"],["62100.10","0.009"],["62100.70","0.005"],["62101.30","0.009"],["62101.70","0.173"],["62101.80","2.778"],["62102.20","0.178"],["62102.30","3.144"],["62102.40","9.448"],["62102.60","0.000"],["62103.20","0.002"],["62103.40","0.003"],["62103.80","0.324"],["62104.00","0.001"],["62104.40","0.090"],["62104.60","0.015"],["62104.90","0.123"],["62105.10","0.050"],["62105.50","0.486"],["62106.20","0.011"],["62106.50","0.011"],["62107.00","0.008"],["62107.70","0.015"],["62108.00","0.268"],["62108.10","0.006"],["62108.50","1.365"],["62108.80","2.270"],["62109.10","0.431"],["62109.20","0.050"],["62109.60","0.381"],["62109.70","1.385"],["62110.20","0.255"],["62110.30","0.003"],["62110.40","0.001"],["62110.70","0.063"],["62111.10","0.002"],["62111.30","2.532"],["62111.40","0.776"],["62111.90","0.002"],["62112.30","0.208"],["62113.00","0.000"],["62113.20","0.004"],["62113.50","0.660"],["62113.90","0.004"],["62114.80","0.001"],["62115.40","0.001"],["62116.50","1.065"],["62117.00","1.121"],["62118.00","0.645"],["62119.00","0.003"],["62119.20","0.002"],["62120.00","0.196"],["62120.40","0.400"],["62120.70","0.012"],["62121.20","0.026"],["62121.60","0.006"],["62122.20","0.577"],["62123.30","0.004"],["62123.60","0.000"],["62125.70","0.100"],["62126.20","8.028"],["62128.40","1.169"],["62129.80","0.210"],["62129.90","0.247"],["62131.80","0.326"],["62132.30","0.954"],["62133.90","0.313"],["62134.10","0.332"],["62135.80","0.324"],["62136.00","0.004"],["62138.50","1.296"],["62138.80","0.000"],["62139.80","3.364"],["62140.30","12.089"],["62141.20","0.849"],["62144.70","0.000"],["62145.20","0.323"],["62149.80","0.876"],["62150.00","102.313"],["62171.60","0.004"],["62174.30","0.023"],["62511.10","0.003"],["62690.90","1.974"],["62692.50","3.791"],["62692.70","0.003"],["62784.40","8.514"],["62785.90","2.838"],["62846.40","0.789"],["62846.50","6.304"],["62848.00","1.762"],["63074.40","0.679"],["63254.60","0.000"],["63313.40","0.003"],["67593.10","0.000"],["67594.10","0.000"],["67594.50","0.616"],["89523.20","0.216"]],"b":[["1000.00","210.542"],["11570.10","1.120"],["11571.90","0.016"],["11659.60","0.464"],["11870.10","0.720"],["11871.70","0.016"],["11871.90","0.032"],["11970.10","1.040"],["55863.00","0.003"],["55864.70","0.002"],["56518.00","1.114"],["56548.30","0.590"],["58966.50","0.000"],["59587.20","0.000"],["60807.30","0.000"],["60830.30","0.003"],["60830.50","0.003"],["61007.80","0.003"],["61035.60","1.871"],["61045.90","1.135"],["61066.40","0.027"],["61066.60","0.060"],["61067.20","0.020"],["61069.80","1.145"],["61070.10","0.028"],["61071.70","0.047"],["61106.00","1.134"],["61131.80","2.287"],["61142.30","0.450"],["61165.50","2.562"],["61167.70","0.002"],["61170.10","7.931"],["61201.10","2.426"],["61289.60","3.215"],["61325.30","1.614"],["61449.40","0.004"],["61451.00","0.000"],["61451.20","0.072"],["61591.70","0.000"],["61626.10","0.992"],["61787.90","0.006"],["61788.90","0.319"],["61791.10","0.011"],["61823.30","0.001"],["61823.50","0.004"],["61823.60","1.723"],["61863.50","0.001"],["61864.90","0.185"],["61883.60","0.004"],["61900.10","1.540"],["61912.00","0.004"],["61916.60","3.394"],["61917.50","1.156"],["61947.30","0.000"],["61958.30","0.000"],["61962.60","2.596"],["61968.30","0.280"],["61969.20","0.001"],["61975.90","0.000"],["61978.10","0.085"],["61984.10","0.001"],["61984.80","0.122"],["61986.20","0.001"],["61989.20","0.100"],["61990.00","19.460"],["61990.20","4.170"],["61990.80","0.006"],["61992.00","0.018"],["61992.10","0.002"],["61993.20","0.001"],["61994.00","0.002"],["61998.40","0.030"],["61998.70","1.898"],["62000.50","0.004"],["62000.60","0.000"],["62002.40","2.350"],["62002.60","0.048"],["62005.20","0.174"],["62005.60","0.001"],["62006.80","2.171"],["62006.90","0.747"],["62008.00","0.499"],["62008.10","0.100"],["62008.80","1.424"],["62008.90","0.449"],["62009.20","0.576"],["62012.50","0.147"],["62014.90","0.000"],["62016.70","0.213"],["62017.60","0.383"],["62019.10","0.002"],["62019.30","0.001"],["62019.80","0.007"],["62020.40","1.002"],["62020.90","0.002"],["62021.30","0.000"],["62021.60","2.195"],["62021.70","0.866"],["62021.90","0.086"],["62022.10","0.018"],["62022.90","0.002"],["62023.30","0.001"],["62024.00","0.682"],["62024.80","0.702"],["62024.90","0.085"],["62027.20","0.050"],["62027.40","0.002"],["62028.50","0.875"],["62028.80","0.005"],["62028.90","0.000"],["62029.30","0.016"],["62029.70","0.030"],["62030.40","0.005"],["62030.60","0.285"],["62032.00","0.682"],["62033.50","0.007"],["62033.70","0.001"],["62034.20","0.001"],["62034.90","0.452"],["62035.00","0.002"],["62035.20","0.008"],["62035.30","0.009"],["62036.10","0.062"],["62036.20","0.130"],["62036.70","1.012"],["62037.00","0.002"],["62037.70","0.003"],["62038.30","0.003"],["62038.40","0.242"],["62038.70","0.002"],["62039.00","0.002"],["62039.40","0.091"],["62039.70","1.412"],["62039.90","0.015"],["62040.20","0.000"],["62041.80","0.010"],["62042.10","0.323"],["62042.40","0.019"],["62042.70","0.011"],["62042.90","0.033"],["62043.00","0.945"],["62043.30","0.001"],["62043.50","0.002"],["62043.70","0.126"],["62043.90","0.104"],["62044.30","0.055"],["62044.50","0.406"],["62044.60","2.053"],["62046.00","0.001"],["62046.70","0.003"],["62046.80","0.081"],["62047.40","1.295"],["62047.50","1.649"],["62047.60","0.509"],["62048.00","0.038"],["62048.20","0.008"],["62048.40","0.135"],["62048.60","0.003"],["62048.70","0.010"],["62049.30","0.035"],["62049.60","0.190"],["62049.90","1.413"],["62050.00","0.002"],["62050.10","0.001"],["62051.00","0.040"],["62051.40","0.004"],["62051.50","0.071"],["62051.70","0.585"],["62052.50","1.363"],["62052.60","0.972"],["62052.80","0.242"],["62052.90","0.000"],["62053.00","0.000"],["62053.10","0.664"],["62053.20","0.003"],["62053.70","1.298"],["62054.20","0.171"],["62055.10","0.966"],["62055.40","1.104"],["62055.50","0.167"],["62055.60","0.725"],["62055.80","0.006"],["62056.30","0.325"],["62056.50","0.001"],["62056.60","0.110"],["62057.40","0.282"],["62057.50","1.427"],["62057.60","0.302"],["62057.70","0.164"],["62057.80","0.003"],["62057.90","0.167"],["62058.10","0.327"],["62058.40","0.000"],["62058.50","0.061"],["62058.90","2.027"],["62059.30","0.147"],["62059.70","0.067"],["62060.30","0.004"],["62060.50","0.006"],["62060.70","0.355"],["62060.90","0.110"],["62061.00","0.064"],["62061.10","0.111"],["62061.30","0.134"],["62061.40","1.995"],["62061.60","0.004"],["62061.70","0.886"],["62061.80","0.162"],["62062.30","0.004"],["62062.40","0.001"],["62062.80","0.064"],["62063.60","0.001"],["62063.90","0.000"],["62064.00","1.365"],["62064.10","0.447"],["62064.40","0.283"],["62065.00","0.155"],["62065.10","0.004"],["62065.60","0.004"],["62065.80","0.263"],["62066.30","0.002"],["62066.40","0.006"],["62066.60","0.001"],["62066.70","0.078"],["62066.90","0.000"],["62067.00","0.096"],["62067.20","0.130"],["62067.30","0.002"],["62067.40","0.199"],["62067.80","0.050"],["62068.10","0.002"],["62068.20","0.001"],["62068.50","0.002"],["62068.60","0.001"],["62068.70","0.278"],["62069.30","0.016"],["62069.50","0.155"],["62069.90","0.002"],["62070.00","0.007"],["62070.10","0.111"],["62070.20","1.804"],["62070.30","0.881"],["62070.40","0.001"],["62070.50","0.000"],["62070.60","0.000"],["62070.70","0.001"],["62070.90","0.000"],["62071.20","0.000"],["62071.30","0.001"],["62071.50","0.000"],["62071.60","0.005"],["62071.70","0.700"],["62071.80","1.935"],["62071.90","13.638"]],"e":"depthUpdate","ps":"BTCUSDT","pu":10998401068799,"s":"BTCUSDT","st":1,"u":10998401089028}
{"E":1783504329590,"T":1783504329589,"U":10998401089066,"a":[["62072.00","0.000"],["62072.10","0.000"],["62072.30","0.000"],["62072.50","0.000"],["62072.60","0.000"],["62072.90","0.000"],["62073.00","0.000"],["62073.10","0.000"],["62073.30","0.000"],["62073.40","0.000"],["62073.50","0.000"],["62073.60","0.000"],["62073.70","0.000"],["62074.00","0.000"],["62074.10","0.000"],["62074.30","0.000"],["62074.40","0.000"],["62074.50","0.000"],["62074.60","0.000"],["62074.70","0.000"],["62074.80","0.000"],["62074.90","0.000"],["62075.00","0.000"],["62075.10","0.000"],["62075.20","0.000"],["62075.30","0.000"],["62075.40","0.000"],["62075.50","0.000"],["62075.60","5.910"],["62075.70","0.002"],["62075.80","0.001"],["62075.90","0.000"],["62076.00","0.000"],["62076.10","0.000"],["62076.20","0.000"],["62076.40","0.000"],["62076.50","0.001"],["62076.60","0.000"],["62076.80","0.051"],["62076.90","0.001"],["62077.10","0.059"],["62077.20","0.096"],["62077.70","0.000"],["62077.80","0.437"],["62077.90","0.003"],["62078.00","0.025"],["62078.20","0.000"],["62078.40","0.073"],["62078.50","0.025"],["62078.70","0.002"],["62078.80","0.000"],["62078.90","0.000"],["62079.00","0.001"],["62079.10","0.013"],["62079.20","0.000"],["62079.30","0.001"],["62079.40","0.000"],["62079.50","0.002"],["62079.60","0.001"],["62079.70","0.008"],["62079.80","0.576"],["62079.90","0.898"],["62080.00","0.331"],["62080.10","0.001"],["62080.20","0.283"],["62080.30","0.001"],["62080.40","0.085"],["62080.50","0.228"],["62080.60","0.203"],["62080.70","0.172"],["62080.80","1.026"],["62080.90","0.316"],["62081.00","0.058"],["62081.10","0.711"],["62081.20","1.621"],["62081.30","0.379"],["62081.40","0.013"],["62081.50","0.000"],["62081.60","0.187"],["62081.70","0.001"],["62081.80","0.343"],["62081.90","0.358"],["62082.00","0.002"],["62082.10","0.000"],["62082.20","1.000"],["62082.50","0.003"],["62082.70","0.041"],["62082.90","0.003"],["62083.00","0.000"],["62083.10","1.297"],["62083.20","0.018"],["62083.30","0.288"],["62083.40","0.324"],["62083.50","0.345"],["62083.70","1.600"],["62083.80","0.880"],["62083.90","0.027"],["62084.00","0.474"],["62084.10","0.000"],["62084.20","0.003"],["62084.40","0.595"],["62084.50","0.002"],["62084.60","0.392"],["62084.70","0.432"],["62084.80","0.008"],["62085.10","0.003"],["62085.20","0.328"],["62085.30","0.232"],["62085.40","0.003"],["62085.50","0.004"],["62085.70","0.002"],["62085.80","0.066"],["62085.90","0.001"],["62086.00","0.004"],["62086.40","0.004"],["62086.60","0.001"],["62086.70","0.004"],["62086.80","0.004"],["62086.90","0.081"],["62087.00","0.001"],["62087.50","0.057"],["62087.60","0.569"],["62087.70","0.294"],["62087.80","1.348"],["62087.90","0.068"],["62088.00","0.641"],["62088.10","0.001"],["62088.20","0.091"],["62088.40","0.000"],["62088.70","0.049"],["62088.80","0.194"],["62088.90","0.572"],["62089.00","0.000"],["62089.10","0.041"],["62089.20","0.002"],["62089.30","0.000"],["62089.40","0.323"],["62089.50","0.064"],["62089.60","0.325"],["62089.70","0.018"],["62089.80","0.002"],["62089.90","0.078"],["62090.00","1.838"],["62090.10","0.741"],["62090.30","0.805"],["62090.40","1.699"],["62091.10","0.012"],["62091.30","0.545"],["62091.40","0.007"],["62091.50","1.512"],["62091.60","0.010"],["62091.70","0.588"],["62091.80","0.337"],["62091.90","0.021"],["62092.10","0.875"],["62092.20","0.170"],["62092.30","2.422"],["62092.40","0.006"],["62092.50","0.000"],["62092.80","0.061"],["62093.00","0.960"],["62093.10","0.399"],["62093.40","0.043"],["62093.60","0.035"],["62093.70","0.030"],["62093.90","0.163"],["62094.00","0.932"],["62094.10","0.713"],["62095.20","0.000"],["62095.30","0.100"],["62095.50","0.013"],["62095.60","0.001"],["62095.70","0.080"],["62095.90","0.304"],["62096.10","2.500"],["62096.20","13.514"],["62096.40","0.013"],["62096.50","0.011"],["62096.80","0.002"],["62096.90","0.139"],["62097.10","0.001"],["62097.20","0.003"],["62097.30","0.679"],["62097.50","0.080"],["62097.70","0.070"],["62097.80","0.069"],["62097.90","0.002"],["62098.00","0.102"],["62098.50","0.000"],["62098.70","0.012"],["62098.90","0.060"],["62099.20","0.745"],["62099.40","1.488"],["62099.50","1.364"],["62099.60","1.451"],["62099.70","0.657"],["62099.80","0.631"],["62100.10","0.001"],["62100.40","0.361"],["62100.50","0.691"],["62100.60","0.479"],["62100.80","0.052"],["62100.90","0.011"],["62101.10","0.004"],["62101.20","0.009"],["62101.30","0.001"],["62101.60","0.620"],["62101.70","0.030"],["62101.80","2.776"],["62101.90","0.063"],["62102.00","0.001"],["62102.20","0.175"],["62102.30","3.148"],["62102.50","0.005"],["62102.70","0.096"],["62102.80","0.061"],["62102.90","0.002"],["62103.10","0.000"],["62103.20","0.003"],["62103.40","0.017"],["62103.90","1.372"],["62104.00","0.009"],["62104.50","0.529"],["62104.60","0.002"],["62104.70","0.000"],["62104.90","0.006"],["62105.00","0.222"],["62105.30","0.247"],["62105.40","0.022"],["62105.50","0.000"],["62105.90","0.000"],["62106.10","0.125"],["62106.60","0.008"],["62106.70","0.001"],["62106.80","0.004"],["62107.00","0.005"],["62107.10","0.011"],["62107.20","0.005"],["62107.70","0.004"],["62108.00","0.334"],["62108.10","0.003"],["62108.30","0.252"],["62108.60","0.089"],["62108.70","1.616"],["62108.90","0.001"],["62109.10","0.170"],["62109.20","0.117"],["62109.30","0.000"],["62109.50","0.022"],["62109.60","0.201"],["62110.00","0.462"],["62110.40","0.011"],["62110.60","0.792"],["62110.70","0.061"],["62110.90","0.000"],["62111.20","0.030"],["62111.30","0.007"],["62111.50","0.018"],["62111.60","2.344"],["62111.90","0.001"],["62112.20","3.534"],["62112.50","0.016"],["62112.70","0.005"],["62112.80","1.864"],["62113.10","0.004"],["62113.20","0.002"],["62113.30","0.052"],["62113.40","0.660"],["62113.50","0.657"],["62113.60","0.001"],["62113.70","0.004"],["62113.80","3.238"],["62113.90","0.001"],["62114.00","0.001"],["62114.20","0.002"],["62114.30","0.007"],["62114.60","0.030"],["62114.90","2.008"],["62115.10","0.010"],["62115.20","0.146"],["62115.70","0.002"],["62115.90","0.011"],["62116.40","0.752"],["62116.50","1.008"],["62116.80","0.005"],["62116.90","0.003"],["62117.00","1.019"],["62117.10","1.296"],["62117.40","0.012"],["62117.70","1.355"],["62118.40","0.001"],["62118.60","0.005"],["62119.00","0.005"],["62119.10","0.054"],["62119.40","0.037"],["62120.40","0.017"],["62120.70","0.000"],["62121.20","0.938"],["62121.40","0.020"],["62121.50","1.202"],["62121.60","0.003"],["62121.70","0.000"],["62121.80","0.001"],["62122.00","0.000"],["62122.10","0.033"],["62122.20","0.000"],["62123.60","0.000"],["62124.10","0.017"],["62124.20","0.000"],["62124.30","0.017"],["62124.60","0.362"],["62124.70","1.336"],["62124.80","0.659"],["62125.10","0.357"],["62125.30","0.001"],["62125.60","0.084"],["62126.10","0.286"],["62126.20","0.001"],["62126.30","1.641"],["62126.40","0.017"],["62126.50","2.415"],["62127.20","0.043"],["62128.00","0.955"],["62128.10","1.807"],["62128.60","1.951"],["62128.70","0.477"],["62128.80","0.004"],["62128.90","0.026"],["62129.10","0.002"],["62129.60","0.287"],["62129.70","0.008"],["62129.80","0.026"],["62130.00","0.866"],["62130.40","0.061"],["62130.90","0.003"],["62131.30","0.009"],["62131.70","0.899"],["62132.00","0.005"],["62132.50","0.004"],["62132.70","0.071"],["62132.90","0.796"],["62133.60","0.000"],["62134.00","0.065"],["62134.10","0.368"],["62134.20","0.254"],["62134.30","4.058"],["62134.50","0.408"],["62134.60","0.607"],["62134.70","22.470"],["62135.20","0.025"],["62135.90","0.004"],["62136.00","0.056"],["62136.10","0.023"],["62136.30","0.219"],["62136.50","0.827"],["62136.70","2.236"],["62137.50","0.414"],["62138.70","0.154"],["62138.90","0.022"],["62139.50","0.004"],["62139.60","0.293"],["62139.80","3.687"],["62140.50","0.170"],["62140.60","0.048"],["62140.70","0.000"],["62141.00","0.016"],["62141.70","0.896"],["62141.90","0.453"],["62144.90","1.393"],["62146.00","0.712"],["62146.10","0.027"],["62147.30","0.003"],["62149.10","0.334"],["62149.80","0.744"],["62150.00","103.018"],["62150.10","0.601"],["62150.40","0.029"],["62153.00","0.191"],["62153.20","0.000"],["62154.50","0.004"],["62154.80","0.000"],["62156.30","0.003"],["62156.80","0.009"],["62161.60","0.000"],["62162.30","0.001"],["62163.80","4.860"],["62164.90","1.853"],["62165.20","0.153"],["62166.00","0.028"],["62167.50","0.122"],["62168.50","2.085"],["62168.80","0.609"],["62170.00","3.177"],["62173.00","0.162"],["62173.40","0.029"],["62174.10","0.000"],["62174.70","0.014"],["62175.20","25.199"],["62175.70","8.303"],["62176.00","0.000"],["62181.00","0.709"],["62184.10","0.003"],["62185.80","1.385"],["62185.90","0.875"],["62189.30","1.435"],["62190.10","0.247"],["62191.10","0.001"],["62193.60","0.013"],["62198.50","0.214"],["62200.00","12.016"],["62202.80","0.523"],["62204.60","0.678"],["62204.70","0.008"],["62214.80","4.027"],["62234.50","0.804"],["62235.60","1.581"],["62235.70","0.001"],["62236.20","0.001"],["62237.70","0.017"],["62249.80","0.139"],["62252.90","0.674"],["62253.20","0.003"],["62254.40","3.368"],["62255.30","0.001"],["62258.40","0.001"],["62260.60","0.001"],["62268.20","0.043"],["62270.60","0.156"],["62272.30","0.002"],["62274.00","0.217"],["62274.60","0.004"],["62300.30","0.515"],["62315.00","0.016"],["62321.30","0.236"],["62335.30","0.681"],["62336.60","1.330"],["62377.00","0.039"],["62377.30","0.004"],["62384.80","0.001"],["62386.10","0.000"],["62392.40","0.000"],["62392.90","0.004"],["62396.10","0.001"],["62402.40","0.100"],["62412.80","0.256"],["62438.70","0.031"],["62445.40","0.002"],["62474.90","0.471"],["62501.20","0.000"],["62507.50","0.001"],["62562.80","0.000"],["62569.10","0.001"],["62616.90","0.005"],["62617.10","0.001"],["62617.20","0.002"],["62617.80","0.007"],["62620.70","1.428"],["62633.40","0.716"],["62638.20","0.001"],["62658.90","2.763"],["62659.00","0.704"],["62661.50","1.232"],["62663.00","0.713"],["62663.80","1.269"],["62665.10","3.389"],["62665.20","3.476"],["62670.00","3.279"],["62687.10","0.000"],["62692.70","0.003"],["62693.10","0.000"],["62695.10","0.072"],["62696.30","0.013"],["62696.40","0.008"],["62703.90","0.001"],["62704.90","0.080"],["62706.20","4.896"],["62707.10","0.010"],["62707.50","2.797"],["62739.60","0.947"],["62750.70","1.202"],["62752.00","1.466"],["62752.10","1.736"],["62784.30","0.002"],["62784.40","0.000"],["62785.90","0.000"],["62786.20","0.014"],["62786.40","0.000"],["62786.90","0.274"],["62788.50","0.954"],["62789.10","0.946"],["62789.90","7.568"],["62790.00","6.624"],["62820.30","4.729"],["62846.40","0.001"],["62846.50","0.000"],["62848.00","0.186"],["62848.30","3.152"],["62850.60","3.081"],["62851.40","0.269"],["62852.00","3.436"],["62852.10","6.310"],["62910.50","0.000"],["62910.60","0.011"],["62911.00","0.370"],["62943.10","4.718"],["62944.50","3.919"],["62975.60","1.332"],["63004.30","0.000"],["63037.70","1.102"],["67594.50","0.000"],["67594.70","0.004"],["67595.50","0.008"],["67596.00","0.000"],["67596.10","0.000"],["67596.20","0.001"],["67596.30","0.002"],["67596.40","0.613"]],"b":[["11571.90","0.048"],["11575.40","0.016"],["11575.50","0.096"],["11659.60","0.320"],["11871.90","0.096"],["11874.30","0.016"],["11875.50","0.192"],["11966.60","0.416"],["11967.20","0.032"],["11968.10","0.000"],["11970.10","0.848"],["55864.70","0.000"],["55867.90","0.002"],["58971.70","0.012"],["59592.40","0.003"],["60811.10","0.001"],["61067.20","0.006"],["61067.30","0.286"],["61068.10","0.000"],["61070.10","0.016"],["61074.30","1.518"],["61074.60","0.000"],["61075.40","0.500"],["61075.50","0.024"],["61108.00","4.637"],["61134.10","0.000"],["61170.10","9.064"],["61288.20","4.531"],["61325.30","3.228"],["61347.50","0.000"],["61391.60","0.739"],["61433.90","0.647"],["61451.20","0.072"],["61451.70","0.655"],["61453.60","0.001"],["61454.60","0.000"],["61454.70","0.000"],["61480.40","2.377"],["61569.80","0.000"],["61577.70","0.093"],["61631.80","0.001"],["61639.80","0.041"],["61740.40","0.000"],["61750.50","0.256"],["61759.70","0.011"],["61789.00","0.157"],["61794.30","0.023"],["61807.30","0.022"],["61807.50","0.004"],["61807.60","0.271"],["61818.00","0.980"],["61823.60","1.349"],["61826.00","0.101"],["61826.80","0.000"],["61827.90","0.000"],["61829.20","0.530"],["61850.60","0.000"],["61850.90","6.306"],["61851.00","1.943"],["61862.40","0.217"],["61863.50","0.001"],["61864.80","0.152"],["61882.50","0.109"],["61883.00","0.006"],["61885.80","0.000"],["61888.20","0.092"],["61889.30","0.001"],["61889.40","0.000"],["61893.30","0.003"],["61894.40","0.270"],["61895.50","0.071"],["61895.60","0.014"],["61896.00","0.063"],["61897.70","0.712"],["61899.90","0.011"],["61902.60","0.002"],["61906.80","0.004"],["61911.30","0.001"],["61917.30","0.001"],["61923.50","0.139"],["61924.00","0.001"],["61932.90","0.001"],["61936.20","0.000"],["61945.40","0.254"],["61946.30","0.000"],["61946.80","0.631"],["61948.60","0.763"],["61949.20","1.362"],["61950.10","0.027"],["61952.20","0.672"],["61956.20","0.001"],["61957.00","0.001"],["61958.00","3.028"],["61958.40","0.021"],["61960.50","0.150"],["61961.70","0.616"],["61968.10","0.000"],["61970.10","0.003"],["61971.40","0.552"],["61971.50","0.488"],["61974.70","0.001"],["61975.10","2.936"],["61977.60","0.203"],["61979.10","0.053"],["61981.00","0.000"],["61981.20","0.000"],["61982.00","0.288"],["61982.10","0.008"],["61983.90","1.364"],["61985.60","0.000"],["61986.60","0.798"],["61986.70","0.203"],["61987.00","0.003"],["61987.10","0.000"],["61988.30","0.001"],["61988.40","0.000"],["61989.70","0.067"],["61990.00","0.256"],["61990.20","1.455"],["61992.00","0.017"],["61992.10","0.002"],["61992.20","0.600"],["61992.80","0.150"],["61993.00","1.179"],["61993.10","0.840"],["61994.60","0.512"],["61995.10","0.000"],["61997.00","1.201"],["61997.20","0.000"],["61997.60","0.027"],["61997.80","0.000"],["61998.40","0.006"],["61998.50","0.706"],["61999.80","0.036"],["62000.70","0.294"],["62000.90","0.602"],["62001.70","0.000"],["62002.50","0.689"],["62002.70","1.400"],["62004.50","0.000"],["62004.60","0.418"],["62004.70","0.023"],["62005.20","0.001"],["62006.40","0.014"],["62006.60","1.180"],["62007.10","0.158"],["62007.30","0.014"],["62007.60","0.002"],["62008.00","0.419"],["62008.30","0.000"],["62008.40","0.658"],["62008.70","0.005"],["62008.80","0.000"],["62008.90","0.449"],["62009.00","3.994"],["62009.20","0.576"],["62009.70","0.001"],["62010.40","0.008"],["62010.80","0.000"],["62011.00","19.444"],["62011.30","0.020"],["62011.80","0.004"],["62012.20","0.019"],["62012.70","0.880"],["62013.10","0.008"],["62013.40","0.401"],["62015.30","0.001"],["62016.10","0.025"],["62016.70","0.003"],["62017.40","0.202"],["62018.50","1.056"],["62018.90","0.314"],["62019.10","0.000"],["62019.60","0.001"],["62020.90","0.000"],["62021.00","0.000"],["62021.70","0.839"],["62021.80","1.295"],["62021.90","0.437"],["62022.00","0.150"],["62022.40","0.131"],["62022.70","0.003"],["62023.00","0.202"],["62023.10","0.001"],["62023.40","0.048"],["62023.50","0.015"],["62023.60","0.036"],["62023.80","0.011"],["62023.90","0.254"],["62024.10","0.121"],["62024.20","1.362"],["62024.60","0.294"],["62024.80","0.689"],["62024.90","0.004"],["62025.10","0.003"],["62025.30","0.657"],["62025.40","0.324"],["62025.60","0.002"],["62025.70","0.011"],["62025.80","0.329"],["62026.00","0.754"],["62026.10","0.001"],["62026.60","0.061"],["62026.90","0.003"],["62027.20","0.001"],["62027.40","0.001"],["62027.90","0.004"],["62028.80","0.168"],["62029.20","0.013"],["62029.30","0.002"],["62029.70","0.016"],["62030.00","0.002"],["62030.20","0.001"],["62030.30","0.003"],["62030.40","0.002"],["62030.50","0.000"],["62030.60","0.282"],["62030.80","1.235"],["62030.90","1.371"],["62031.00","0.089"],["62031.20","0.293"],["62031.90","0.005"],["62032.00","0.683"],["62032.10","0.027"],["62032.20","0.001"],["62033.00","0.000"],["62033.10","0.009"],["62033.40","0.125"],["62033.50","0.004"],["62033.80","0.017"],["62034.30","0.000"],["62034.60","2.268"],["62034.70","0.007"],["62035.20","0.005"],["62035.30","0.009"],["62036.20","0.060"],["62036.30","1.464"],["62036.40","0.281"],["62036.60","0.306"],["62036.90","0.002"],["62037.00","0.012"],["62037.70","0.006"],["62038.00","0.003"],["62038.20","0.071"],["62038.30","0.004"],["62038.80","0.003"],["62039.00","0.000"],["62039.20","0.026"],["62039.30","0.008"],["62039.40","0.001"],["62039.70","1.411"],["62040.40","0.010"],["62040.50","0.012"],["62040.60","0.003"],["62040.90","1.295"],["62041.00","0.881"],["62041.40","0.004"],["62041.80","0.005"],["62042.00","0.553"],["62042.20","0.000"],["62042.30","2.052"],["62042.50","0.296"],["62042.70","0.003"],["62042.80","0.091"],["62042.90","0.035"],["62043.00","0.012"],["62043.10","0.000"],["62043.30","0.001"],["62043.70","0.003"],["62043.80","0.124"],["62043.90","0.096"],["62044.00","0.330"],["62044.20","0.040"],["62044.30","0.006"],["62044.50","0.403"],["62044.60","1.390"],["62044.70","0.005"],["62044.90","0.065"],["62045.00","0.553"],["62045.20","0.009"],["62045.30","0.008"],["62045.40","0.042"],["62045.50","0.002"],["62045.60","0.004"],["62045.70","0.129"],["62046.30","0.960"],["62046.50","0.003"],["62046.60","0.016"],["62046.70","0.002"],["62046.80","0.014"],["62047.10","0.004"],["62047.60","0.348"],["62047.80","0.000"],["62048.00","0.687"],["62048.20","0.892"],["62048.40","0.003"],["62048.60","0.002"],["62048.70","0.024"],["62049.30","0.040"],["62049.40","0.653"],["62049.50","1.226"],["62049.60","0.061"],["62049.70","0.001"],["62049.90","1.414"],["62050.00","0.005"],["62050.10","0.663"],["62050.40","0.327"],["62050.50","0.000"],["62050.70","0.472"],["62050.80","2.195"],["62050.90","0.169"],["62051.20","0.037"],["62051.30","0.001"],["62051.40","0.003"],["62051.70","0.768"],["62051.90","0.081"],["62052.00","0.717"],["62052.50","1.363"],["62052.60","0.974"],["62052.70","1.251"],["62052.90","0.000"],["62053.10","0.001"],["62053.20","0.002"],["62053.30","0.001"],["62053.60","0.281"],["62053.70","1.298"],["62053.90","0.173"],["62054.30","0.004"],["62055.00","2.045"],["62055.10","0.402"],["62055.50","0.005"],["62055.60","0.001"],["62055.70","0.664"],["62055.90","0.052"],["62056.00","0.412"],["62056.30","0.000"],["62056.40","0.000"],["62056.50","0.001"],["62056.70","0.368"],["62056.80","0.234"],["62057.40","0.160"],["62057.60","0.314"],["62057.70","0.003"],["62057.80","0.002"],["62057.90","0.107"],["62058.00","0.129"],["62058.20","0.678"],["62058.40","1.371"],["62058.60","0.000"],["62058.80","0.725"],["62058.90","1.027"],["62059.00","1.382"],["62059.30","0.125"],["62059.40","0.012"],["62059.50","0.125"],["62059.60","0.133"],["62059.80","0.037"],["62059.90","0.001"],["62060.10","0.051"],["62060.60","0.002"],["62060.70","0.353"],["62060.90","0.802"],["62061.00","0.062"],["62061.10","0.234"],["62061.30","0.194"],["62061.40","2.018"],["62061.50","0.892"],["62061.70","0.000"],["62061.80","0.683"],["62061.90","0.034"],["62062.00","0.128"],["62062.10","0.001"],["62062.20","0.035"],["62062.30","0.000"],["62062.40","0.003"],["62062.50","0.414"],["62062.60","1.415"],["62062.70","0.818"],["62062.80","0.096"],["62063.00","0.033"],["62063.20","0.012"],["62063.50","0.010"],["62063.70","0.344"],["62063.90","0.002"],["62064.10","0.001"],["62064.20","0.937"],["62064.40","0.250"],["62064.50","0.817"],["62064.60","1.979"],["62064.70","0.133"],["62064.90","0.004"],["62065.00","0.155"],["62065.10","0.061"],["62065.50","0.003"],["62065.60","0.820"],["62065.80","0.001"],["62065.90","0.000"],["62066.20","0.039"],["62066.40","0.000"],["62066.70","0.787"],["62067.00","0.000"],["62067.40","0.003"],["62067.80","0.392"],["62067.90","0.687"],["62068.10","0.007"],["62068.30","0.001"],["62068.40","0.001"],["62068.80","0.002"],["62068.90","0.816"],["62069.00","0.002"],["62069.20","0.002"],["62069.30","0.005"],["62069.40","0.049"],["62069.60","0.263"],["62069.80","0.001"],["62070.00","0.010"],["62070.10","0.102"],["62070.20","0.004"],["62070.30","0.241"],["62070.40","0.052"],["62070.50","0.001"],["62071.20","0.046"],["62071.60","0.005"],["62071.70","0.374"],["62071.80","0.042"],["62071.90","0.011"],["62072.00","1.800"],["62072.10","0.002"],["62072.20","0.001"],["62072.30","0.278"],["62072.40","0.058"],["62072.50","0.001"],["62072.80","0.001"],["62072.90","0.000"],["62073.00","0.001"],["62073.10","0.001"],["62073.20","0.000"],["62073.30","0.001"],["62073.50","0.000"],["62073.60","0.000"],["62073.70","0.000"],["62073.90","0.001"],["62074.00","0.000"],["62074.10","0.000"],["62074.20","0.001"],["62074.30","0.001"],["62074.40","0.001"],["62074.50","0.000"],["62074.60","0.000"],["62074.70","0.000"],["62074.80","0.000"],["62074.90","0.002"],["62075.00","0.002"],["62075.10","0.000"],["62075.20","0.000"],["62075.30","0.000"],["62075.40","0.051"],["62075.50","5.013"]],"e":"depthUpdate","ps":"BTCUSDT","pu":10998401089028,"s":"BTCUSDT","st":1,"u":10998401122590}
{"E":1783504329692,"T":1783504329690,"U":10998401122675,"a":[["62075.60","5.799"],["62076.70","0.026"],["62077.10","0.011"],["62077.50","0.004"],["62079.00","0.003"],["62079.60","0.164"],["62079.70","0.493"],["62081.00","0.350"],["62081.20","1.620"],["62081.40","0.072"],["62081.90","0.318"],["62082.20","1.000"],["62082.30","0.002"],["62082.70","0.001"],["62083.00","0.000"],["62083.10","1.297"],["62083.20","0.002"],["62083.90","0.067"],["62085.60","0.106"],["62086.90","0.001"],["62087.00","0.368"],["62087.60","0.005"],["62088.40","0.564"],["62089.40","0.001"],["62090.20","0.004"],["62090.60","0.017"],["62091.00","0.001"],["62091.30","0.465"],["62091.70","0.008"],["62092.50","0.080"],["62092.70","0.086"],["62093.20","2.767"],["62093.60","0.076"],["62095.40","0.018"],["62095.70","0.067"],["62095.90","0.234"],["62097.10","0.002"],["62097.30","0.681"],["62097.60","0.575"],["62099.20","0.712"],["62099.80","0.606"],["62101.10","0.074"],["62101.60","0.710"],["62102.80","0.011"],["62106.00","0.009"],["62106.60","0.021"],["62108.30","0.182"],["62108.70","1.526"],["62109.90","0.927"],["62110.30","0.860"],["62110.60","0.825"],["62115.50","0.876"],["62116.10","1.363"],["62116.20","0.025"],["62116.70","0.002"],["62117.30","0.004"],["62117.90","0.031"],["62118.50","0.001"],["62124.70","1.880"],["62125.20","0.094"],["62127.00","4.701"],["62127.90","0.001"],["62128.10","1.807"],["62128.70","0.400"],["62129.20","0.250"],["62134.30","0.675"],["62134.70","0.002"],["62136.30","0.009"],["62136.70","5.464"],["62136.80","22.530"],["62138.90","0.022"],["62140.80","0.001"],["62141.50","0.363"],["62143.50","0.001"],["62146.50","0.000"],["62146.70","0.033"],["62150.90","0.001"],["62151.20","0.009"],["62151.30","0.035"],["62151.50","0.218"],["62151.60","1.539"],["62152.20","0.640"],["62152.60","0.009"],["62152.80","0.017"],["62155.60","0.673"],["62157.30","0.683"],["62158.00","0.167"],["62161.40","5.373"],["62172.30","0.028"],["62172.40","1.528"],["62181.20","0.003"],["62193.20","0.000"],["62193.30","1.528"],["62207.50","12.152"],["62258.40","0.000"],["62390.20","0.001"],["62620.70","0.000"],["62665.20","4.898"],["62691.50","0.000"],["62696.40","0.008"],["62696.90","0.009"],["62707.50","0.035"],["62752.10","4.497"],["62789.10","0.000"],["62790.00","7.570"],["62802.90","3.941"],["62806.80","5.469"],["62808.10","3.201"],["62851.40","3.030"],["63292.00","0.003"],["89523.20","0.222"]],"b":[["1000.00","210.542"],["11575.50","0.224"],["11659.60","0.192"],["11875.50","0.464"],["11966.60","0.272"],["11970.10","0.720"],["55867.90","0.002"],["60812.60","0.001"],["60813.20","0.000"],["60834.00","0.036"],["61129.00","0.124"],["61170.20","1.133"],["61247.70","0.003"],["61264.20","0.207"],["61294.30","0.859"],["61320.10","2.144"],["61347.00","0.108"],["61353.40","3.227"],["61377.00","0.398"],["61393.60","6.338"],["61413.20","3.225"],["61418.40","6.620"],["61444.20","3.547"],["61447.50","2.177"],["61454.70","0.000"],["61475.20","8.858"],["61508.60","3.226"],["61509.50","2.416"],["61810.70","0.002"],["61810.80","0.212"],["61827.20","0.374"],["61860.20","0.000"],["61860.30","1.709"],["61860.40","0.640"],["61863.50","0.000"],["61877.90","0.000"],["61880.80","0.000"],["61883.10","0.000"],["61896.20","0.071"],["61911.30","2.082"],["61933.20","0.924"],["61941.40","0.000"],["61948.50","0.024"],["61956.00","0.001"],["61956.30","0.482"],["61965.90","0.001"],["61981.90","6.130"],["61984.90","0.056"],["61985.00","2.247"],["61992.00","0.016"],["61993.70","0.077"],["62005.70","0.000"],["62005.80","1.529"],["62007.20","0.158"],["62008.50","0.957"],["62009.00","0.045"],["62011.00","0.240"],["62012.40","1.998"],["62013.10","19.236"],["62013.50","0.353"],["62013.60","0.677"],["62014.70","3.845"],["62015.10","1.072"],["62017.40","0.142"],["62018.20","4.701"],["62018.50","1.653"],["62019.70","0.024"],["62022.00","0.018"],["62024.80","0.687"],["62025.40","0.309"],["62025.90","0.027"],["62027.90","0.006"],["62028.00","1.466"],["62028.60","1.107"],["62028.80","0.167"],["62029.20","0.012"],["62029.30","0.030"],["62029.80","0.014"],["62032.40","0.030"],["62034.00","1.544"],["62034.90","1.286"],["62037.60","0.698"],["62038.40","0.232"],["62041.70","0.001"],["62041.90","0.000"],["62045.70","0.133"],["62048.90","0.132"],["62049.50","1.222"],["62049.60","0.059"],["62053.70","1.314"],["62053.90","0.335"],["62056.60","0.050"],["62057.50","1.367"],["62057.70","0.004"],["62057.90","0.047"],["62058.00","0.009"],["62058.10","0.329"],["62058.20","0.679"],["62058.30","0.083"],["62058.50","0.001"],["62058.70","0.210"],["62059.10","0.244"],["62060.30","0.006"],["62061.30","0.254"],["62061.40","2.078"],["62062.00","0.188"],["62062.80","0.258"],["62063.10","0.002"],["62063.20","0.015"],["62064.40","0.121"],["62064.70","0.295"],["62064.80","0.156"],["62067.60","0.001"],["62068.00","0.393"],["62069.20","0.004"],["62070.10","0.058"],["62071.00","0.001"],["62071.10","0.001"],["62071.60","0.001"],["62072.00","1.801"],["62073.00","0.002"],["62075.50","5.038"]],"e":"depthUpdate","ps":"BTCUSDT","pu":10998401122590,"s":"BTCUSDT","st":1,"u":10998401135336}
{"E":1783504329794,"T":1783504329793,"U":10998401135479,"a":[["62075.60","5.559"],["62076.80","0.002"],["62076.90","0.050"],["62079.30","0.324"],["62079.40","0.164"],["62079.50","0.002"],["62079.60","0.324"],["62079.70","0.329"],["62079.90","0.576"],["62081.80","0.343"],["62082.60","0.251"],["62083.00","0.322"],["62083.40","0.328"],["62083.70","2.119"],["62084.00","0.010"],["62084.50","0.243"],["62085.20","0.006"],["62085.30","0.000"],["62085.40","0.325"],["62086.70","0.084"],["62087.30","0.017"],["62087.60","0.167"],["62087.70","0.358"],["62087.80","1.026"],["62087.90","0.003"],["62088.00","0.641"],["62088.40","0.000"],["62089.80","0.164"],["62089.90","0.642"],["62090.10","0.016"],["62090.60","0.001"],["62091.70","0.733"],["62092.40","0.007"],["62092.70","0.006"],["62092.80","0.093"],["62092.90","0.054"],["62093.10","1.720"],["62093.20","2.769"],["62094.00","0.082"],["62094.40","0.669"],["62094.60","0.001"],["62094.80","0.007"],["62095.90","0.558"],["62096.90","0.099"],["62097.60","0.455"],["62098.80","0.000"],["62098.90","0.001"],["62099.10","0.136"],["62100.90","0.001"],["62101.40","0.061"],["62105.00","0.122"],["62116.70","2.457"],["62125.90","0.012"],["62128.10","1.807"],["62133.50","0.003"],["62135.90","0.000"],["62137.10","0.005"],["62144.10","0.000"],["62150.00","103.024"],["62151.80","0.005"],["62172.00","0.018"],["62179.80","1.361"],["62183.50","0.673"],["62195.60","4.105"],["62204.60","2.443"],["62430.60","0.000"],["62436.20","0.008"],["62696.40","0.008"],["62808.10","2.932"],["63298.00","0.000"]],"b":[["1000.00","210.542"],["11575.50","0.368"],["11659.60","0.048"],["11875.50","0.736"],["11963.70","0.224"],["11966.60","0.224"],["11970.10","0.576"],["49648.00","0.000"],["55867.90","0.002"],["58939.00","0.100"],["58971.70","0.012"],["59592.40","0.000"],["61005.20","0.002"],["61045.90","2.270"],["61069.80","0.000"],["61072.40","2.292"],["61097.70","8.674"],["61108.10","2.268"],["61129.30","0.378"],["61131.80","0.000"],["61134.40","4.802"],["61165.00","8.264"],["61170.10","10.197"],["61170.20","2.266"],["61171.70","6.013"],["61172.50","2.266"],["61201.20","2.430"],["61315.40","0.087"],["61320.50","2.139"],["61354.30","1.271"],["61356.30","3.141"],["61358.80","1.039"],["61405.90","0.989"],["61413.20","0.001"],["61448.70","3.227"],["61454.70","0.000"],["61463.20","0.002"],["61475.20","5.637"],["61479.70","2.415"],["61489.10","0.644"],["61508.10","3.219"],["61510.80","4.542"],["61589.80","0.019"],["61653.40","0.005"],["61796.50","0.021"],["61804.20","0.008"],["61863.50","0.001"],["61902.10","0.000"],["61990.80","0.002"],["62007.50","0.051"],["62013.10","0.008"],["62014.70","0.003"],["62015.10","20.300"],["62015.20","5.498"],["62018.20","4.703"],["62018.80","1.363"],["62027.60","0.146"],["62030.40","0.001"],["62031.00","0.088"],["62031.50","0.051"],["62034.10","0.096"],["62038.50","0.001"],["62038.60","0.001"],["62040.00","0.006"],["62041.30","0.002"],["62042.50","0.294"],["62043.90","0.100"],["62044.90","0.005"],["62045.80","0.739"],["62049.40","3.110"],["62050.70","0.326"],["62051.70","0.188"],["62053.90","0.215"],["62054.10","0.003"],["62054.30","0.584"],["62055.20","0.001"],["62055.80","0.014"],["62055.90","0.052"],["62056.00","0.404"],["62056.40","0.002"],["62057.20","0.120"],["62057.40","0.100"],["62057.50","1.365"],["62057.80","0.002"],["62058.10","0.005"],["62058.70","0.208"],["62059.00","0.564"],["62059.30","0.123"],["62060.90","0.430"],["62061.30","0.252"],["62061.40","2.055"],["62061.50","0.892"],["62062.20","0.033"],["62062.40","0.005"],["62062.50","0.092"],["62064.80","0.478"],["62066.80","1.362"],["62067.80","0.575"],["62069.10","0.005"],["62069.20","0.005"],["62069.50","0.157"],["62070.10","0.046"],["62071.50","0.002"],["62071.80","0.040"],["62071.90","0.010"],["62072.40","0.057"],["62074.90","0.004"],["62075.50","5.042"]],"e":"depthUpdate","ps":"BTCUSDT","pu":10998401135336,"s":"BTCUSDT","st":1,"u":10998401145796}
{"E":1783504329896,"T":1783504329893,"U":10998401146117,"a":[["62078.00","0.009"],["62079.50","0.165"],["62080.90","0.312"],["62086.70","0.004"],["62087.30","0.001"],["62092.80","0.053"],["62093.20","2.849"],["62095.60","0.017"],["62095.90","0.395"],["62096.10","2.501"],["62097.90","0.002"],["62098.00","0.040"],["62099.30","0.040"],["62099.40","2.213"],["62101.70","5.030"],["62105.40","0.111"],["62105.50","0.089"],["62105.60","0.904"],["62106.70","0.005"],["62108.40","0.011"],["62108.60","0.000"],["62108.70","1.437"],["62128.20","1.458"],["62172.40","0.000"],["62172.50","1.563"],["62183.40","0.890"],["62193.30","0.001"],["62193.40","1.527"],["62283.60","0.017"],["62303.10","0.700"],["62305.60","0.020"],["62314.40","0.041"],["62327.30","0.005"],["62452.70","0.521"],["62453.10","2.401"],["62696.40","0.008"],["62772.20","1.080"],["63321.60","0.000"],["89523.20","0.228"]],"b":[["11575.50","0.336"],["11659.60","0.000"],["11875.50","1.008"],["11959.60","0.432"],["11960.50","0.032"],["11962.10","0.000"],["11963.70","0.160"],["11970.10","0.448"],["11975.50","0.080"],["55867.90","0.002"],["58956.60","0.006"],["58956.70","0.003"],["58971.70","0.012"],["59592.40","0.003"],["61010.30","0.000"],["61048.40","1.462"],["61133.10","0.327"],["61138.40","0.004"],["61171.70","7.146"],["61172.50","4.532"],["61262.50","0.001"],["61289.10","7.646"],["61289.50","1.629"],["61295.80","4.360"],["61315.00","0.051"],["61321.90","17.757"],["61358.80","2.007"],["61435.80","1.675"],["61438.40","0.012"],["61454.70","0.000"],["61462.30","0.013"],["61468.00","1.034"],["61476.70","3.453"],["61537.60","4.737"],["61718.60","0.000"],["61757.10","0.053"],["61759.70","0.011"],["61860.30","0.173"],["61860.40","1.536"],["61860.50","0.640"],["61863.50","0.000"],["61985.00","0.717"],["61985.10","1.531"],["62005.80","0.000"],["62005.90","1.539"],["62016.10","0.000"],["62026.60","0.000"],["62026.70","0.027"],["62027.90","0.004"],["62028.60","1.109"],["62037.70","0.016"],["62038.70","0.000"],["62039.00","0.000"],["62039.20","0.026"],["62039.30","0.008"],["62039.70","1.471"],["62039.90","0.013"],["62040.50","0.002"],["62041.20","0.453"],["62042.40","0.017"],["62045.40","0.002"],["62045.80","0.679"],["62047.00","0.016"],["62047.20","0.004"],["62047.60","0.348"],["62047.80","0.060"],["62052.00","0.017"],["62053.50","0.701"],["62053.80","1.367"],["62056.70","0.001"],["62057.30","0.278"],["62062.30","0.002"],["62062.90","0.072"],["62063.20","0.039"],["62064.80","0.845"],["62066.10","0.000"],["62070.10","0.045"],["62070.40","0.053"],["62075.50","5.043"]],"e":"depthUpdate","ps":"BTCUSDT","pu":10998401145796,"s":"BTCUSDT","st":1,"u":10998401154591}
{"E":1783504329998,"T":1783504329997,"U":10998401154787,"a":[["62077.50","0.004"],["62079.20","0.163"],["62079.30","0.161"],["62079.40","0.001"],["62079.50","0.165"],["62080.70","0.334"],["62081.90","0.322"],["62082.10","0.241"],["62082.60","0.010"],["62084.40","0.675"],["62086.90","0.017"],["62087.10","0.024"],["62088.10","0.005"],["62093.20","2.189"],["62094.10","1.293"],["62094.30","0.005"],["62094.40","0.661"],["62095.20","0.008"],["62095.50","0.713"],["62095.60","0.001"],["62101.20","0.000"],["62103.80","0.333"],["62105.40","0.022"],["62105.50","0.000"],["62123.50","0.060"],["62128.20","1.362"],["62130.40","0.001"],["62134.10","0.342"],["62224.60","0.002"],["62323.30","0.005"],["62326.70","0.212"],["62360.50","0.000"],["62394.10","0.122"],["62696.40","0.008"]],"b":[["1000.00","210.542"],["11575.50","0.192"],["11875.50","1.280"],["11959.60","0.304"],["11970.10","0.304"],["11975.50","0.224"],["55867.90","0.002"],["58971.70","0.012"],["59592.40","0.000"],["61072.40","1.147"],["61113.30","4.011"],["61138.10","4.700"],["61159.90","0.000"],["61165.00","5.836"],["61171.10","3.101"],["61175.40","2.061"],["61200.10","1.643"],["61201.10","4.852"],["61206.40","4.883"],["61237.50","0.845"],["61257.20","4.795"],["61262.10","0.002"],["61284.00","0.035"],["61294.20","2.489"],["61297.80","2.055"],["61299.40","0.000"],["61299.60","2.775"],["61320.50","1.162"],["61321.90","20.986"],["61325.30","5.330"],["61326.80","1.858"],["61330.60","4.367"],["61361.60","1.159"],["61454.70","0.000"],["61475.20","2.416"],["61508.10","6.438"],["61814.50","0.002"],["61863.50","0.001"],["62011.20","0.001"],["62033.50","0.064"],["62041.50","0.076"],["62047.80","0.000"],["62050.00","0.015"],["62051.70","0.178"],["62053.90","0.195"],["62059.00","0.000"],["62059.80","0.033"],["62061.40","2.059"],["62061.60","0.568"],["62062.10","0.021"],["62062.90","0.049"],["62066.40","0.003"],["62070.10","0.040"],["62071.90","0.009"],["62075.50","4.850"]],"e":"depthUpdate","ps":"BTCUSDT","pu":10998401154591,"s":"BTCUSDT","st":1,"u":10998401161419}
{"E":1783504330100,"T":1783504330099,"U":10998401161501,"a":[["62075.60","5.942"],["62077.50","0.014"],["62077.80","0.654"],["62078.70","0.130"],["62079.00","0.215"],["62079.10","0.023"],["62079.20","0.665"],["62079.30","0.323"],["62079.40","0.000"],["62079.50","0.925"],["62079.60","0.425"],["62079.70","0.430"],["62079.80","0.012"],["62081.40","0.152"],["62081.50","0.001"],["62082.10","0.261"],["62082.30","0.002"],["62083.50","0.344"],["62084.40","0.595"],["62085.20","0.022"],["62086.90","0.001"],["62087.70","0.858"],["62088.00","1.762"],["62088.80","0.174"],["62089.50","0.095"],["62089.80","1.052"],["62089.90","0.078"],["62091.10","0.324"],["62091.70","0.008"],["62095.80","0.488"],["62095.90","0.558"],["62096.10","2.565"],["62099.10","0.016"],["62100.20","0.123"],["62103.80","0.527"],["62104.00","0.009"],["62104.10","1.491"],["62104.40","0.001"],["62108.80","2.271"],["62113.70","0.061"],["62116.30","0.010"],["62116.40","0.250"],["62127.00","4.703"],["62127.10","0.024"],["62128.50","0.117"],["62128.60","1.949"],["62129.90","0.348"],["62131.00","0.001"],["62131.30","0.009"],["62134.10","0.324"],["62134.60","0.295"],["62149.90","24.483"],["62179.80","2.965"],["62182.10","11.494"],["62492.30","0.004"],["62504.70","0.246"],["62511.00","0.025"],["62696.40","0.008"],["62808.00","0.108"],["63321.40","0.677"],["89523.20","0.234"]],"b":[["1000.00","210.542"],["11575.50","0.064"],["11875.50","1.552"],["11959.60","0.160"],["11970.10","0.176"],["11975.50","0.352"],["49660.00","0.000"],["49660.40","0.000"],["55867.90","0.002"],["58971.70","0.012"],["61027.30","0.575"],["61072.40","0.002"],["61113.30","5.145"],["61134.00","4.332"],["61134.40","2.516"],["61138.10","1.623"],["61165.00","3.408"],["61170.10","14.081"],["61175.40","4.327"],["61201.10","7.278"],["61252.90","2.701"],["61281.30","0.000"],["61289.10","6.031"],["61299.60","3.583"],["61315.80","1.333"],["61320.50","0.185"],["61325.30","6.944"],["61361.60","2.127"],["61454.70","0.000"],["61564.00","1.032"],["61643.80","0.040"],["61682.80","0.000"],["61721.20","0.087"],["61863.50","0.000"],["61963.70","0.002"],["61964.00","12.314"],["61964.10","3.756"],["61964.30","0.001"],["61964.40","0.019"],["61964.70","0.020"],["61994.60","0.040"],["61996.10","8.358"],["61996.20","1.844"],["61996.70","0.030"],["62000.50","19.232"],["62002.40","4.943"],["62002.50","0.724"],["62003.70","0.030"],["62008.50","0.959"],["62009.30","0.001"],["62015.10","1.074"],["62015.20","2.628"],["62016.20","4.099"],["62022.00","0.232"],["62022.70","0.003"],["62028.80","0.085"],["62031.00","0.006"],["62032.00","0.682"],["62032.30","0.010"],["62032.40","0.028"],["62032.50","1.347"],["62033.50","0.124"],["62041.20","0.455"],["62041.30","0.004"],["62041.40","0.006"],["62045.00","0.504"],["62045.10","0.318"],["62046.20","0.326"],["62048.40","0.001"],["62048.50","0.056"],["62048.60","0.000"],["62049.90","1.473"],["62051.80","0.000"],["62051.90","0.130"],["62054.00","0.002"],["62056.90","0.130"],["62057.30","0.280"],["62057.40","0.102"],["62057.50","1.367"],["62058.60","0.725"],["62058.80","0.000"],["62059.00","0.564"],["62060.70","0.353"],["62061.60","0.004"],["62061.90","0.036"],["62063.10","0.002"],["62063.20","0.015"],["62064.60","2.003"],["62064.70","0.163"],["62064.80","0.713"],["62064.90","0.028"],["62066.20","0.039"],["62068.80","0.003"],["62069.00","0.000"],["62071.90","0.008"],["62072.50","0.001"],["62074.20","0.003"],["62075.50","3.887"]],"e":"depthUpdate","ps":"BTCUSDT","pu":10998401161419,"s":"BTCUSDT","st":1,"u":10998401170712}
{"E":1783504330202,"T":1783504330201,"U":10998401170773,"a":[["62075.60","6.238"],["62076.20","0.004"],["62077.80","0.650"],["62078.90","0.818"],["62079.10","0.014"],["62081.40","0.072"],["62081.70","0.242"],["62081.90","0.318"],["62082.10","0.020"],["62082.50","0.053"],["62083.90","0.188"],["62085.20","0.006"],["62085.80","0.016"],["62087.10","0.007"],["62087.70","0.858"],["62088.10","0.001"],["62088.40","0.000"],["62089.40","0.726"],["62089.50","0.131"],["62089.80","0.327"],["62090.50","0.008"],["62092.40","0.009"],["62094.30","0.001"],["62103.70","0.541"],["62106.10","0.122"],["62118.20","0.000"],["62123.50","0.062"],["62125.60","0.024"],["62129.80","0.127"],["62130.80","0.002"],["62133.40","0.000"],["62134.10","0.288"],["62134.20","0.122"],["62134.50","0.312"],["62149.30","0.001"],["62154.60","0.035"],["62180.40","0.000"],["62185.70","0.164"],["62212.10","0.029"],["62380.60","0.160"],["62696.40","0.217"],["62777.10","4.626"],["62814.30","1.749"],["63006.70","0.562"]],"b":[["11570.10","1.104"],["11571.90","0.000"],["11575.40","0.000"],["11575.50","0.000"],["11875.50","1.824"],["11959.60","0.032"],["11970.10","0.032"],["11975.50","0.496"],["55867.90","0.002"],["58971.70","0.012"],["59592.40","0.003"],["60792.80","0.032"],["60828.60","0.822"],["61066.90","0.001"],["61113.30","6.279"],["61134.00","3.198"],["61165.30","0.770"],["61175.40","5.460"],["61206.40","7.309"],["61289.50","0.000"],["61293.10","5.272"],["61325.30","18.245"],["61386.20","0.002"],["61418.40","9.844"],["61434.40","1.168"],["61448.20","9.039"],["61454.70","0.000"],["61475.30","0.000"],["61479.30","10.809"],["61485.80","0.725"],["61511.50","4.831"],["61759.70","0.001"],["61765.10","0.012"],["61863.50","0.001"],["61935.90","0.031"],["61960.00","0.042"],["61965.50","0.004"],["61991.00","0.941"],["61996.50","0.002"],["62002.50","0.784"],["62017.30","0.060"],["62022.10","0.016"],["62027.60","0.148"],["62035.90","0.050"],["62052.90","0.580"],["62053.20","0.002"],["62053.60","0.279"],["62053.80","1.495"],["62054.30","0.004"],["62054.40","0.002"],["62055.80","0.134"],["62056.90","0.002"],["62057.20","0.000"],["62058.30","0.808"],["62058.60","0.000"],["62059.00","0.564"],["62059.40","0.012"],["62059.60","0.116"],["62066.20","0.039"],["62069.00","0.002"],["62070.30","0.245"],["62071.10","0.003"],["62071.90","0.004"],["62072.30","0.000"],["62075.50","3.171"]],"e":"depthUpdate","ps":"BTCUSDT","pu":10998401170712,"s":"BTCUSDT","st":1,"u":10998401179463}
{"E":1783504330304,"T":1783504330303,"U":10998401179464,"a":[["62075.60","6.235"],["62077.60","0.902"],["62077.70","0.818"],["62077.80","1.001"],["62078.30","0.011"],["62078.60","0.191"],["62078.70","1.493"],["62078.80","0.000"],["62079.10","0.006"],["62079.20","0.000"],["62079.50","0.820"],["62079.60","0.001"],["62079.70","0.007"],["62079.80","0.004"],["62080.90","0.553"],["62081.70","0.001"],["62085.70","0.007"],["62087.60","0.484"],["62088.00","1.887"],["62089.60","0.425"],["62091.10","0.424"],["62092.80","0.053"],["62095.00","1.309"],["62095.70","0.199"],["62095.80","0.552"],["62095.90","0.558"],["62096.00","1.363"],["62096.10","2.501"],["62096.20","13.634"],["62097.90","0.042"],["62099.30","0.000"],["62100.20","0.003"],["62101.30","2.015"],["62102.20","0.013"],["62102.30","3.253"],["62102.60","0.000"],["62103.00","0.127"],["62103.60","0.003"],["62103.70","0.452"],["62103.80","0.333"],["62105.70","0.326"],["62107.50","3.327"],["62107.80","0.577"],["62109.90","0.001"],["62113.70","3.082"],["62116.50","0.082"],["62117.00","0.768"],["62119.80","0.505"],["62119.90","2.553"],["62121.50","0.276"],["62124.70","1.780"],["62125.40","0.020"],["62125.70","0.000"],["62126.10","1.160"],["62126.90","0.262"],["62127.40","0.080"],["62128.60","1.949"],["62129.80","0.026"],["62129.90","0.247"],["62134.50","0.000"],["62136.70","2.234"],["62136.80","0.004"],["62137.30","0.016"],["62139.80","7.045"],["62141.00","22.544"],["62141.30","0.000"],["62144.90","1.378"],["62153.70","0.234"],["62154.70","0.210"],["62159.90","0.000"],["62160.90","0.413"],["62223.60","0.020"],["62237.70","0.014"],["62239.80","0.003"],["62385.10","0.018"],["62386.00","0.560"],["62426.80","0.000"],["62427.80","0.551"],["62696.40","0.217"],["63317.10","0.003"],["89523.20","0.240"]],"b":[["1000.00","210.542"],["11570.10","0.976"],["11775.50","0.112"],["11875.50","1.872"],["11959.60","0.000"],["11966.60","0.176"],["11967.20","0.000"],["11969.20","0.000"],["11970.10","0.000"],["11975.50","0.624"],["55867.90","0.000"],["58971.70","0.012"],["59592.40","0.000"],["60800.00","65.091"],["60815.70","0.000"],["61041.40","1.145"],["61082.30","1.462"],["61134.40","1.373"],["61175.40","6.593"],["61258.10","0.727"],["61270.00","0.985"],["61299.60","5.973"],["61435.80","0.597"],["61440.10","0.000"],["61454.70","0.000"],["61473.40","1.077"],["61474.50","0.269"],["61480.40","5.598"],["61492.00","0.758"],["61510.60","3.570"],["61759.70","0.163"],["61863.50","0.000"],["61958.40","0.018"],["61960.60","0.005"],["61970.40","0.551"],["61971.40","0.002"],["61976.10","0.040"],["61976.60","0.200"],["61977.60","0.003"],["61989.00","0.201"],["61990.00","0.056"],["62000.50","0.004"],["62002.40","2.350"],["62002.50","0.749"],["62011.00","0.240"],["62012.40","4.778"],["62013.00","19.229"],["62013.40","0.480"],["62015.10","1.072"],["62016.20","4.101"],["62022.70","0.018"],["62032.40","0.088"],["62033.20","0.108"],["62034.00","1.529"],["62041.50","0.016"],["62045.10","0.302"],["62048.70","0.040"],["62053.50","0.001"],["62057.90","0.772"],["62058.30","0.083"],["62058.50","0.565"],["62059.00","0.000"],["62060.10","1.051"],["62061.20","0.082"],["62061.50","0.892"],["62061.60","0.004"],["62061.80","0.000"],["62062.60","0.415"],["62064.60","1.101"],["62064.80","0.391"],["62064.90","0.028"],["62065.00","0.477"],["62067.80","0.577"],["62068.10","0.007"],["62069.00","0.904"],["62069.50","0.155"],["62072.40","0.059"],["62073.20","0.008"],["62075.50","1.718"]],"e":"depthUpdate","ps":"BTCUSDT","pu":10998401179463,"s":"BTCUSDT","st":1,"u":10998401190996}
{"E":1783504330406,"T":1783504330405,"U":10998401191019,"a":[["62075.60","6.299"],["62076.20","0.006"],["62076.80","0.004"],["62076.90","0.051"],["62077.50","0.016"],["62077.60","1.092"],["62078.30","0.001"],["62078.60","0.001"],["62078.80","0.326"],["62080.10","0.001"],["62080.60","0.203"],["62080.90","0.312"],["62081.10","0.647"],["62084.20","0.008"],["62085.70","0.002"],["62086.10","0.016"],["62087.60","1.559"],["62087.80","0.325"],["62088.00","2.015"],["62088.90","0.592"],["62089.10","0.005"],["62089.50","0.035"],["62089.90","0.018"],["62091.10","0.552"],["62092.00","0.143"],["62095.60","0.065"],["62095.70","0.199"],["62095.80","0.488"],["62095.90","0.538"],["62098.60","0.064"],["62099.20","0.026"],["62111.70","4.020"],["62119.20","0.000"],["62119.90","2.555"],["62136.80","22.532"],["62141.00","0.016"],["62696.40","0.217"],["63020.30","0.171"]],"b":[["1000.00","210.542"],["11570.10","0.832"],["11775.50","0.240"],["11875.50","1.888"],["11966.60","0.032"],["11975.50","0.768"],["49648.00","0.000"],["55867.90","0.002"],["58971.70","0.012"],["59592.40","0.003"],["61009.90","5.000"],["61041.30","0.033"],["61051.30","1.135"],["61082.30","2.597"],["61134.30","1.103"],["61134.40","0.230"],["61165.00","0.980"],["61175.40","8.859"],["61206.40","9.735"],["61257.20","4.519"],["61299.60","6.249"],["61346.90","0.001"],["61398.90","0.795"],["61417.20","3.224"],["61434.40","0.519"],["61444.30","0.000"],["61449.40","3.226"],["61454.70","0.000"],["61479.30","8.394"],["61481.70","0.165"],["61485.80","2.174"],["61511.50","7.245"],["61523.90","4.890"],["61837.00","0.877"],["61863.50","0.001"],["61990.00","0.009"],["61999.20","0.000"],["62001.80","0.680"],["62002.50","0.689"],["62004.70","0.023"],["62006.10","3.945"],["62007.00","0.711"],["62007.20","0.314"],["62007.40","0.063"],["62008.90","0.013"],["62011.00","19.468"],["62012.40","1.998"],["62013.00","0.001"],["62015.20","2.628"],["62019.80","0.054"],["62021.90","0.569"],["62022.70","0.003"],["62023.10","0.016"],["62028.40","1.426"],["62029.10","0.047"],["62031.90","0.005"],["62032.10","0.074"],["62035.20","0.133"],["62036.10","0.015"],["62048.50","0.009"],["62053.80","1.367"],["62054.30","0.012"],["62055.00","2.043"],["62055.80","0.126"],["62057.90","0.725"],["62060.90","0.383"],["62061.10","0.236"],["62061.60","0.004"],["62063.10","0.130"],["62063.60","0.264"],["62064.90","0.004"],["62065.00","0.477"],["62067.10","0.054"],["62068.10","0.909"],["62068.20","0.006"],["62069.00","0.002"],["62069.10","0.005"],["62069.20","0.005"],["62069.60","0.000"],["62070.00","0.013"],["62070.10","0.035"],["62070.40","0.003"],["62070.70","0.003"],["62071.50","0.597"],["62074.10","0.054"],["62075.40","0.050"],["62075.50","1.068"]],"e":"depthUpdate","ps":"BTCUSDT","pu":10998401190996,"s":"BTCUSDT","st":1,"u":10998401199904}
{"E":1783504330508,"T":1783504330504,"U":10998401200060,"a":[["62075.60","6.323"],["62076.20","0.004"],["62076.60","0.002"],["62076.80","0.002"],["62077.10","0.011"],["62077.50","0.014"],["62077.60","0.991"],["62077.90","0.005"],["62079.10","0.005"],["62080.80","1.267"],["62080.90","0.313"],["62081.30","0.379"],["62081.50","0.000"],["62089.10","0.086"],["62091.50","1.514"],["62092.00","0.011"],["62095.30","0.261"],["62095.40","0.082"],["62095.60","0.001"],["62095.70","0.295"],["62101.50","0.325"],["62126.40","0.118"],["62126.90","0.161"],["62134.60","0.607"],["62136.30","0.141"],["62136.70","5.474"],["62139.80","4.110"],["62320.10","0.025"],["62696.40","0.217"],["62988.10","1.346"],["63254.50","0.949"],["89523.20","0.246"]],"b":[["11570.10","0.704"],["11775.50","0.384"],["11875.50","1.872"],["11963.70","0.064"],["11966.60","0.000"],["11975.50","0.896"],["55867.90","0.002"],["58971.70","0.012"],["59592.40","0.000"],["60816.90","0.003"],["60834.00","0.039"],["61041.40","0.000"],["61082.30","3.732"],["61134.00","2.064"],["61138.10","0.813"],["61165.10","0.276"],["61175.40","10.801"],["61200.10","0.834"],["61206.40","12.161"],["61237.50","1.653"],["61351.10","1.057"],["61387.30","3.225"],["61433.80","0.089"],["61434.40","0.032"],["61454.70","0.000"],["61485.80","3.140"],["61765.10","0.012"],["61863.50","0.000"],["61900.80","0.004"],["61952.50","2.719"],["62006.00","0.568"],["62006.10","0.676"],["62007.40","0.016"],["62008.00","0.263"],["62009.80","0.691"],["62012.40","4.778"],["62019.80","0.007"],["62021.90","0.437"],["62022.00","0.232"],["62022.20","0.082"],["62022.70","0.159"],["62032.10","0.027"],["62034.50","0.002"],["62035.20","0.005"],["62041.80","0.052"],["62045.20","0.331"],["62046.30","1.000"],["62047.20","0.005"],["62051.40","0.164"],["62052.00","0.717"],["62053.70","1.298"],["62053.80","1.447"],["62054.10","0.050"],["62055.80","0.006"],["62057.60","0.395"],["62060.10","0.051"],["62060.40","0.068"],["62061.20","1.082"],["62061.60","0.326"],["62061.70","0.902"],["62062.20","0.034"],["62062.60","0.123"],["62062.70","0.002"],["62063.10","0.130"],["62064.90","0.004"],["62065.00","0.155"],["62066.50","0.047"],["62067.00","0.001"],["62067.90","1.139"],["62068.10","0.007"],["62068.20","0.006"],["62069.00","0.002"],["62069.10","0.005"],["62069.20","0.005"],["62070.00","0.513"],["62070.10","0.025"],["62072.10","0.002"],["62073.90","0.000"],["62074.00","0.001"],["62075.40","0.051"],["62075.50","2.591"]],"e":"depthUpdate","ps":"BTCUSDT","pu":10998401199904,"s":"BTCUSDT","st":1,"u":10998401208539}
{"E":1783504330610,"T":1783504330609,"U":10998401208814,"a":[["62071.60","13.037"],["62071.70","2.176"],["62071.80","0.147"],["62071.90","0.002"],["62072.00","0.001"],["62072.10","0.000"],["62072.30","0.000"],["62072.40","0.145"],["62072.50","0.001"],["62072.60","0.000"],["62072.90","0.000"],["62073.10","0.001"],["62073.20","0.001"],["62073.30","0.000"],["62073.40","0.001"],["62074.00","0.002"],["62074.10","1.801"],["62074.20","0.356"],["62074.30","0.547"],["62074.40","0.002"],["62074.50","0.000"],["62074.90","0.002"],["62075.00","0.002"],["62075.10","0.278"],["62075.20","0.001"],["62075.30","0.670"],["62075.40","1.801"],["62075.50","1.428"],["62075.60","0.154"],["62075.70","0.061"],["62076.00","0.001"],["62076.20","0.053"],["62076.30","0.002"],["62076.50","0.163"],["62076.60","0.576"],["62076.70","0.000"],["62076.80","0.003"],["62076.90","0.371"],["62077.10","0.013"],["62077.20","0.000"],["62077.50","0.005"],["62077.60","0.051"],["62077.70","0.000"],["62077.80","0.644"],["62077.90","0.006"],["62078.00","1.009"],["62078.70","1.365"],["62078.80","0.725"],["62078.90","0.000"],["62079.00","0.217"],["62079.10","0.005"],["62079.20","0.000"],["62079.30","0.161"],["62079.50","0.002"],["62079.60","0.001"],["62079.70","0.012"],["62079.90","0.000"],["62080.00","0.331"],["62080.20","0.121"],["62080.30","0.001"],["62080.40","0.085"],["62080.50","0.050"],["62080.60","0.113"],["62080.70","0.654"],["62080.80","1.025"],["62080.90","0.316"],["62081.00","0.398"],["62081.10","0.649"],["62081.30","0.380"],["62081.60","0.191"],["62082.00","0.002"],["62082.20","0.584"],["62082.30","0.004"],["62082.40","0.012"],["62082.50","0.003"],["62083.30","0.441"],["62083.40","0.324"],["62083.50","0.342"],["62083.60","0.325"],["62083.70","1.966"],["62083.90","0.913"],["62084.00","0.006"],["62084.20","0.003"],["62084.30","0.725"],["62085.30","0.000"],["62085.40","0.324"],["62085.50","0.000"],["62085.60","0.103"],["62085.70","0.037"],["62086.30","0.002"],["62086.80","0.010"],["62087.10","0.003"],["62087.30","0.050"],["62087.50","0.121"],["62087.60","0.804"],["62087.70","0.294"],["62087.90","0.003"],["62088.00","0.291"],["62088.10","0.002"],["62088.20","0.090"],["62088.40","0.000"],["62088.80","0.174"],["62088.90","0.572"],["62089.10","0.005"],["62089.40","0.581"],["62089.50","0.124"],["62089.60","0.325"],["62089.80","0.164"],["62090.20","0.168"],["62090.30","0.816"],["62090.40","1.702"],["62090.50","0.671"],["62091.10","0.012"],["62092.00","0.011"],["62092.40","0.008"],["62092.90","0.054"],["62093.00","0.297"],["62093.30","0.420"],["62093.60","0.043"],["62094.00","0.781"],["62094.10","0.713"],["62094.30","0.001"],["62094.70","0.213"],["62094.90","0.155"],["62095.20","0.000"],["62095.30","0.163"],["62095.40","0.020"],["62095.70","0.015"],["62095.80","0.325"],["62095.90","0.538"],["62096.00","1.363"],["62096.10","2.500"],["62096.20","13.514"],["62096.50","0.011"],["62097.00","0.019"],["62097.10","0.005"],["62097.20","0.003"],["62097.30","0.679"],["62097.70","0.264"],["62097.90","0.236"],["62099.00","0.224"],["62099.30","0.194"],["62099.80","0.606"],["62100.30","0.046"],["62100.60","0.463"],["62100.80","0.060"],["62100.90","0.071"],["62101.10","0.001"],["62101.20","0.243"],["62101.30","5.036"],["62101.40","0.002"],["62101.50","0.011"],["62101.60","0.620"],["62101.90","0.063"],["62102.20","0.013"],["62102.30","2.286"],["62102.40","9.359"],["62102.80","0.013"],["62103.00","0.127"],["62103.50","0.007"],["62103.60","0.003"],["62104.00","0.001"],["62104.80","0.050"],["62104.90","0.003"],["62105.00","0.121"],["62105.40","0.018"],["62106.70","0.008"],["62107.40","0.687"],["62107.50","3.327"],["62107.80","0.577"],["62108.10","0.006"],["62108.70","1.437"],["62109.50","0.019"],["62110.20","0.010"],["62110.40","0.071"],["62110.60","0.825"],["62110.70","0.063"],["62111.50","0.001"],["62112.00","0.064"],["62112.50","0.030"],["62112.80","1.815"],["62113.10","0.002"],["62113.50","0.660"],["62113.70","0.061"],["62114.00","0.004"],["62114.10","0.006"],["62114.20","0.000"],["62114.30","0.007"],["62114.60","0.028"],["62114.80","0.002"],["62115.60","0.000"],["62115.70","0.000"],["62116.50","0.079"],["62116.70","0.002"],["62116.80","0.002"],["62116.90","0.165"],["62117.00","0.768"],["62117.30","0.003"],["62117.40","0.000"],["62117.60","0.455"],["62117.70","1.343"],["62117.90","0.030"],["62118.50","0.000"],["62118.60","0.004"],["62119.50","0.001"],["62119.70","0.384"],["62119.80","0.444"],["62119.90","2.580"],["62120.10","0.001"],["62121.40","0.020"],["62121.60","0.006"],["62123.00","0.062"],["62123.50","0.002"],["62124.40","0.000"],["62124.60","0.460"],["62125.10","0.354"],["62125.30","0.001"],["62125.90","0.002"],["62126.00","0.362"],["62126.20","0.001"],["62126.30","1.641"],["62126.40","0.017"],["62127.90","0.005"],["62128.00","0.970"],["62128.20","1.370"],["62128.90","0.001"],["62129.70","0.000"],["62129.80","0.026"],["62131.30","0.001"],["62132.00","0.001"],["62134.30","0.927"],["62134.50","0.312"],["62134.60","0.295"],["62135.20","0.623"],["62135.40","0.100"],["62136.00","0.004"],["62136.20","0.132"],["62136.30","1.531"],["62136.50","0.878"],["62136.70","2.234"],["62136.80","0.056"],["62136.90","0.089"],["62137.30","0.001"],["62139.80","3.787"],["62143.80","3.844"],["62147.30","0.003"],["62149.00","0.003"],["62150.90","0.000"],["62152.80","0.016"],["62154.00","0.019"],["62173.40","0.028"],["62175.20","25.198"],["62181.00","0.706"],["62184.10","0.000"],["62195.80","0.677"],["62239.80","0.000"],["62239.90","0.003"],["62245.40","0.246"],["62249.90","2.782"],["62250.40","0.003"],["62279.10","7.977"],["62279.20","46.628"],["62280.80","0.016"],["62295.30","0.000"],["62319.90","0.304"],["62392.90","0.003"],["62444.10","0.247"],["62456.70","0.000"],["62472.20","0.000"],["62481.30","0.245"],["62483.90","0.492"],["62484.60","0.000"],["62497.60","0.013"],["62504.70","0.000"],["62648.00","0.001"],["62692.30","0.429"],["62692.50","3.791"],["62694.90","0.000"],["62695.00","0.003"],["62696.30","0.013"],["62696.40","0.008"],["62716.90","0.000"],["62785.80","0.002"],["62789.90","3.784"],["62790.00","11.354"],["62852.00","0.284"],["62852.10","9.462"],["62854.70","0.000"],["62903.80","0.000"],["62923.70","0.000"],["62992.60","0.002"],["63034.20","0.002"],["63041.90","0.004"],["63047.10","0.000"],["63049.80","0.003"],["63061.50","0.000"],["63071.60","0.002"],["63071.80","0.004"],["63074.20","0.004"],["63074.30","0.961"],["63130.40","0.475"],["63139.20","0.474"],["63199.30","0.000"],["63268.30","0.000"]],"b":[["1000.00","210.542"],["11570.10","0.560"],["11771.50","0.096"],["11774.10","0.016"],["11775.50","0.448"],["11871.70","0.032"],["11875.40","0.016"],["11875.50","1.760"],["11960.50","0.000"],["11963.70","0.000"],["11971.50","0.064"],["11974.10","0.016"],["11975.50","0.960"],["55864.30","0.006"],["55866.60","0.012"],["55867.90","0.000"],["57068.90","0.001"],["58967.90","0.001"],["60787.10","0.000"],["60832.80","0.007"],["60833.90","0.200"],["60856.10","0.016"],["60925.00","0.812"],["60993.90","0.000"],["61062.80","4.414"],["61072.00","0.015"],["61113.30","7.413"],["61131.70","0.000"],["61138.10","0.003"],["61175.40","11.610"],["61200.10","0.025"],["61200.70","0.033"],["61237.50","2.461"],["61269.60","0.002"],["61330.60","4.644"],["61338.50","0.000"],["61349.90","0.044"],["61398.90","1.521"],["61407.40","1.290"],["61450.80","0.054"],["61451.00","0.000"],["61451.10","1.975"],["61453.40","0.056"],["61453.50","0.000"],["61454.60","0.000"],["61454.70","0.000"],["61759.70","0.325"],["61761.10","0.004"],["61764.80","0.000"],["61810.50","0.653"],["61810.80","0.290"],["61814.30","0.682"],["61852.60","0.000"],["61852.70","0.350"],["61863.50","0.001"],["61881.10","2.234"],["61894.90","0.006"],["61896.00","0.064"],["61898.00","0.001"],["61969.50","0.000"],["61970.10","0.004"],["61983.20","0.000"],["61997.20","0.121"],["62001.40","0.000"],["62002.40","0.032"],["62002.60","0.048"],["62002.70","3.829"],["62002.80","0.440"],["62003.20","0.156"],["62004.10","0.062"],["62008.50","0.957"],["62008.90","0.013"],["62009.10","0.097"],["62009.20","0.323"],["62009.40","0.000"],["62009.60","0.007"],["62011.00","19.350"],["62012.40","4.798"],["62013.00","0.001"],["62014.20","0.001"],["62015.20","2.838"],["62015.30","0.005"],["62015.80","0.015"],["62017.30","0.322"],["62017.90","0.001"],["62018.30","0.000"],["62018.90","0.310"],["62019.00","0.000"],["62019.20","0.015"],["62021.00","0.002"],["62021.80","1.751"],["62021.90","0.001"],["62022.00","0.021"],["62022.50","0.002"],["62022.70","0.001"],["62023.10","0.001"],["62023.50","0.013"],["62023.90","0.044"],["62024.00","0.682"],["62024.10","0.119"],["62025.30","0.654"],["62026.10","0.009"],["62027.40","0.010"],["62027.50","0.000"],["62027.80","0.000"],["62028.20","0.000"],["62028.80","0.085"],["62029.10","0.000"],["62029.20","0.004"],["62029.40","0.030"],["62029.70","0.106"],["62030.50","0.003"],["62030.90","1.363"],["62031.40","0.003"],["62031.60","0.002"],["62031.90","0.004"],["62032.20","0.001"],["62033.10","0.003"],["62033.20","0.105"],["62034.90","1.289"],["62035.20","0.015"],["62035.60","0.004"],["62036.30","1.464"],["62036.80","0.751"],["62036.90","0.012"],["62037.60","0.818"],["62037.70","0.003"],["62038.00","0.050"],["62038.70","0.040"],["62039.20","0.001"],["62039.30","0.004"],["62039.50","0.006"],["62039.80","0.734"],["62040.10","0.004"],["62040.40","0.019"],["62040.80","0.001"],["62041.40","0.004"],["62042.00","0.550"],["62042.80","0.009"],["62043.40","0.004"],["62043.50","0.002"],["62043.60","0.125"],["62043.70","0.006"],["62043.80","0.054"],["62043.90","0.095"],["62044.00","0.210"],["62044.10","0.065"],["62044.40","0.002"],["62044.60","1.390"],["62044.90","0.005"],["62045.10","0.361"],["62045.20","0.009"],["62045.30","0.000"],["62045.40","0.045"],["62045.50","0.051"],["62045.60","0.004"],["62046.10","0.002"],["62046.30","0.976"],["62046.50","0.053"],["62046.60","0.008"],["62046.70","0.003"],["62047.00","0.010"],["62047.10","0.001"],["62047.30","1.367"],["62048.00","0.687"],["62048.20","0.899"],["62048.40","0.033"],["62048.60","0.587"],["62048.70","0.024"],["62049.10","0.004"],["62049.30","0.000"],["62049.40","0.653"],["62049.60","0.179"],["62049.90","1.413"],["62050.00","0.007"],["62050.40","0.327"],["62050.50","0.035"],["62050.80","2.193"],["62050.90","0.169"],["62051.20","0.002"],["62051.30","0.021"],["62051.40","0.003"],["62051.70","0.186"],["62051.80","0.000"],["62051.90","0.081"],["62052.00","0.701"],["62052.60","0.972"],["62052.70","2.057"],["62052.90","0.000"],["62053.10","0.664"],["62053.20","0.566"],["62053.80","1.694"],["62053.90","0.195"],["62054.00","0.003"],["62054.10","0.050"],["62054.30","0.004"],["62055.00","2.029"],["62055.10","0.402"],["62055.50","0.005"],["62055.70","0.001"],["62055.80","0.006"],["62055.90","0.002"],["62056.00","0.424"],["62056.10","0.003"],["62056.30","0.324"],["62056.70","0.001"],["62056.80","0.354"],["62056.90","0.003"],["62057.10","0.006"],["62057.40","0.102"],["62057.50","0.005"],["62057.60","0.296"],["62057.70","1.850"],["62057.80","0.003"],["62057.90","0.064"],["62058.00","0.006"],["62058.20","1.683"],["62058.30","0.003"],["62058.40","1.371"],["62058.50","0.001"],["62058.60","0.000"],["62058.70","0.205"],["62059.00","0.806"],["62059.10","0.002"],["62059.20","0.324"],["62059.30","0.125"],["62059.40","0.830"],["62059.60","0.383"],["62059.80","0.037"],["62059.90","0.001"],["62060.00","0.002"],["62060.20","0.001"],["62060.30","0.006"],["62060.40","0.072"],["62060.50","0.002"],["62060.80","0.061"],["62060.90","0.061"],["62061.00","0.064"],["62061.20","0.082"],["62061.30","0.212"],["62061.40","0.241"],["62061.50","0.005"],["62061.60","2.142"],["62061.70","1.720"],["62061.80","1.359"],["62061.90","0.034"],["62062.00","0.184"],["62062.10","0.130"],["62062.20","0.162"],["62062.40","0.003"],["62062.70","0.820"],["62062.80","0.032"],["62063.10","0.002"],["62063.20","0.006"],["62063.30","0.051"],["62063.40","0.000"],["62063.50","0.051"],["62063.60","0.001"],["62063.80","0.281"],["62063.90","0.818"],["62064.00","0.003"],["62064.20","0.121"],["62064.40","0.000"],["62064.50","0.001"],["62064.60","0.002"],["62064.70","0.001"],["62064.80","0.020"],["62064.90","0.002"],["62065.00","0.164"],["62065.10","0.061"],["62065.40","0.002"],["62065.50","0.001"],["62065.60","0.004"],["62065.70","0.002"],["62065.90","0.004"],["62066.20","0.039"],["62066.40","0.043"],["62066.50","0.008"],["62066.70","0.077"],["62066.80","0.000"],["62067.00","0.033"],["62067.10","0.004"],["62067.20","0.050"],["62067.60","0.025"],["62067.70","0.000"],["62067.80","0.000"],["62067.90","0.000"],["62068.00","0.102"],["62068.10","0.007"],["62068.20","0.001"],["62068.30","0.001"],["62068.50","0.000"],["62068.70","0.000"],["62068.80","0.001"],["62068.90","0.000"],["62069.00","0.002"],["62069.10","0.001"],["62069.20","0.002"],["62069.30","0.004"],["62069.40","0.000"],["62069.50","0.054"],["62069.90","0.002"],["62070.00","0.503"],["62070.20","0.002"],["62070.30","0.000"],["62070.40","0.002"],["62070.50","0.000"],["62070.70","0.001"],["62071.00","0.000"],["62071.10","0.002"],["62071.20","0.000"],["62071.30","0.001"],["62071.40","0.005"],["62071.50","4.583"],["62071.60","0.000"],["62071.70","0.000"],["62071.80","0.000"],["62071.90","0.000"],["62072.00","0.000"],["62072.10","0.000"],["62072.20","0.000"],["62072.30","0.000"],["62072.40","0.000"],["62072.50","0.000"],["62072.80","0.000"],["62073.00","0.000"],["62073.10","0.000"],["62073.20","0.000"],["62073.30","0.000"],["62074.00","0.000"],["62074.10","0.000"],["62074.20","0.000"],["62074.30","0.000"],["62074.40","0.000"],["62074.90","0.000"],["62075.00","0.000"],["62075.40","0.000"],["62075.50","0.000"]],"e":"depthUpdate","ps":"BTCUSDT","pu":10998401208539,"s":"BTCUSDT","st":1,"u":10998401233239}
{"E":1783504330712,"T":1783504330711,"U":10998401233274,"a":[["62071.60","13.016"],["62071.70","2.184"],["62071.80","0.067"],["62071.90","0.000"],["62072.00","0.121"],["62073.70","0.001"],["62074.00","0.582"],["62074.20","0.350"],["62074.30","0.548"],["62074.70","0.003"],["62074.90","0.003"],["62075.10","0.279"],["62075.20","0.295"],["62075.30","0.676"],["62075.40","1.800"],["62075.50","1.365"],["62075.60","0.199"],["62076.10","0.001"],["62076.30","0.004"],["62076.50","0.187"],["62076.70","0.153"],["62076.80","1.298"],["62077.60","0.051"],["62077.70","0.452"],["62078.00","1.009"],["62078.30","0.323"],["62078.50","0.001"],["62078.60","0.001"],["62079.50","0.324"],["62079.70","0.012"],["62080.20","0.001"],["62080.70","0.332"],["62080.90","0.217"],["62081.10","0.768"],["62082.10","0.020"],["62082.20","0.004"],["62082.70","0.123"],["62083.00","0.564"],["62083.90","0.188"],["62084.20","0.126"],["62084.30","0.161"],["62085.00","0.726"],["62085.70","0.002"],["62085.80","0.780"],["62089.90","0.313"],["62090.20","0.540"],["62090.80","0.011"],["62091.80","0.397"],["62092.20","0.240"],["62092.50","0.000"],["62093.00","0.460"],["62093.80","0.040"],["62094.70","0.123"],["62095.40","0.022"],["62096.40","0.071"],["62096.50","0.895"],["62096.90","0.103"],["62098.70","0.002"],["62099.20","0.146"],["62099.50","1.396"],["62100.90","0.001"],["62101.00","0.139"],["62101.40","0.002"],["62101.50","0.011"],["62101.60","0.620"],["62101.90","0.063"],["62102.10","0.010"],["62102.60","0.016"],["62102.80","0.011"],["62103.10","0.014"],["62105.70","0.352"],["62105.90","0.002"],["62106.10","0.002"],["62108.80","2.299"],["62110.20","0.496"],["62110.40","0.061"],["62112.50","0.016"],["62112.70","2.460"],["62115.50","0.875"],["62116.10","1.362"],["62116.70","0.001"],["62121.40","0.121"],["62123.60","0.000"],["62124.60","0.359"],["62124.70","1.780"],["62127.40","0.000"],["62129.80","0.026"],["62133.70","0.306"],["62134.50","0.000"],["62136.20","0.000"],["62136.70","5.519"],["62136.80","22.713"],["62137.30","0.001"],["62138.90","0.022"],["62151.30","4.868"],["62163.80","0.027"],["62164.90","1.861"],["62168.50","2.077"],["62186.80","0.059"],["62200.50","0.758"],["62204.80","0.600"],["62245.40","0.001"],["62252.90","0.673"],["62255.30","0.000"],["62279.10","8.193"],["62302.00","0.494"],["62303.90","6.921"],["62336.60","0.678"],["62385.10","0.000"],["62542.20","0.002"],["62692.30","0.435"],["62788.50","0.000"],["62984.20","0.010"],["63029.90","0.277"],["63313.00","0.103"],["67589.10","0.612"],["89523.20","0.252"]],"b":[["1000.00","210.542"],["11570.10","0.432"],["11771.50","0.368"],["11875.50","1.488"],["11971.50","0.192"],["55864.30","0.006"],["59588.60","0.003"],["61138.30","1.962"],["61171.70","8.279"],["61289.10","0.377"],["61295.80","4.603"],["61325.30","20.667"],["61325.40","3.232"],["61417.20","0.000"],["61450.80","0.054"],["61451.00","3.222"],["61475.20","0.000"],["61479.30","5.979"],["61511.50","12.073"],["61525.30","0.000"],["61532.30","0.008"],["61735.60","0.000"],["61736.00","0.227"],["61754.90","0.008"],["61761.90","0.024"],["61863.50","0.000"],["61941.40","0.024"],["61948.50","0.000"],["61975.10","2.944"],["61982.00","0.280"],["61994.20","0.287"],["61995.10","0.001"],["61996.20","1.844"],["61997.00","1.202"],["62000.30","0.132"],["62000.40","0.011"],["62002.60","19.158"],["62002.70","6.391"],["62002.80","0.572"],["62005.20","0.324"],["62005.90","1.635"],["62006.30","0.018"],["62009.10","0.001"],["62011.00","0.240"],["62012.40","2.000"],["62012.70","0.878"],["62013.40","0.401"],["62021.90","0.083"],["62025.30","0.714"],["62026.50","0.542"],["62029.20","0.005"],["62029.70","0.016"],["62029.80","0.015"],["62030.40","0.002"],["62031.00","0.011"],["62031.90","0.014"],["62032.40","0.028"],["62034.00","1.531"],["62035.20","0.005"],["62036.60","0.382"],["62036.90","0.052"],["62038.70","0.000"],["62040.80","0.001"],["62041.40","0.002"],["62043.80","0.056"],["62044.10","0.185"],["62044.70","0.015"],["62045.40","2.502"],["62045.70","0.133"],["62046.60","0.018"],["62047.00","0.120"],["62047.30","1.365"],["62047.90","0.017"],["62048.90","0.122"],["62049.60","0.053"],["62050.90","0.049"],["62051.30","0.192"],["62052.00","0.001"],["62052.50","1.463"],["62052.60","0.680"],["62052.80","0.534"],["62053.60","0.403"],["62053.90","0.195"],["62054.50","0.001"],["62056.30","0.326"],["62056.80","0.063"],["62057.40","0.002"],["62057.60","0.006"],["62057.70","1.528"],["62058.20","0.683"],["62058.30","0.003"],["62058.80","0.000"],["62058.90","1.023"],["62059.30","0.123"],["62059.50","0.001"],["62059.60","0.116"],["62059.70","0.389"],["62059.80","0.033"],["62060.60","0.002"],["62060.90","0.060"],["62061.00","0.062"],["62061.10","0.113"],["62061.60","0.780"],["62061.70","0.820"],["62061.80","0.931"],["62062.10","0.001"],["62062.20","0.162"],["62062.60","0.001"],["62062.80","0.934"],["62063.70","0.021"],["62064.00","0.136"],["62064.10","0.000"],["62064.20","0.000"],["62064.30","0.000"],["62065.00","0.166"],["62065.90","0.000"],["62066.20","0.007"],["62067.20","0.094"],["62067.30","0.001"],["62069.00","0.000"],["62070.10","0.024"],["62070.20","0.000"],["62070.50","0.002"],["62071.40","0.004"],["62071.50","0.902"]],"e":"depthUpdate","ps":"BTCUSDT","pu":10998401233239,"s":"BTCUSDT","st":1,"u":10998401247309}
{"E":1783504330814,"T":1783504330813,"U":10998401247391,"a":[["62071.60","12.567"],["62071.70","2.185"],["62073.80","0.000"],["62073.90","0.000"],["62074.00","0.904"],["62075.00","0.244"],["62075.70","0.060"],["62075.80","0.121"],["62076.50","0.485"],["62076.70","0.154"],["62076.80","1.299"],["62077.00","0.008"],["62077.60","0.051"],["62077.80","0.812"],["62078.30","0.001"],["62078.70","1.364"],["62079.50","0.324"],["62079.60","0.000"],["62079.70","0.012"],["62079.90","0.000"],["62080.60","0.113"],["62080.70","0.896"],["62081.00","0.340"],["62081.40","0.082"],["62081.60","0.291"],["62081.70","0.736"],["62082.80","0.350"],["62082.90","0.003"],["62083.00","0.000"],["62083.50","0.342"],["62083.60","0.003"],["62084.10","0.020"],["62084.40","0.475"],["62084.70","0.432"],["62085.00","0.001"],["62085.10","0.583"],["62085.40","0.002"],["62087.50","0.241"],["62087.90","0.011"],["62089.40","0.001"],["62089.50","0.004"],["62090.30","0.808"],["62091.10","0.012"],["62091.30","0.455"],["62091.50","1.414"],["62091.60","0.000"],["62092.20","0.170"],["62095.80","0.457"],["62096.90","0.143"],["62097.90","0.196"],["62098.80","0.070"],["62100.30","0.026"],["62101.20","0.257"],["62103.80","0.324"],["62103.90","1.372"],["62109.10","0.092"],["62110.00","0.448"],["62114.80","0.001"],["62114.90","2.007"],["62119.40","0.037"],["62120.00","0.205"],["62121.10","1.030"],["62125.60","0.010"],["62126.30","1.616"],["62127.70","0.051"],["62128.60","1.953"],["62129.20","0.040"],["62130.50","0.025"],["62132.50","0.000"],["62133.10","0.088"],["62134.70","22.659"],["62136.10","0.000"],["62136.80","0.056"],["62137.10","0.001"],["62145.80","0.011"],["62151.60","0.011"],["62151.70","1.691"],["62152.00","0.714"],["62152.50","0.000"],["62158.20","1.269"],["62162.30","0.017"],["62168.50","2.093"],["62172.50","0.035"],["62172.60","2.405"],["62174.70","0.030"],["62209.20","0.022"],["62226.70","0.276"],["62392.50","0.100"],["62394.10","0.010"],["62402.40","0.000"],["62433.30","0.243"],["62692.30","0.429"],["62798.40","0.788"],["62814.30","2.703"],["63130.90","0.791"],["63313.00","0.106"],["67589.10","0.000"]],"b":[["11570.10","0.288"],["11771.50","0.640"],["11875.50","1.216"],["11971.50","0.336"],["55864.30","0.006"],["58939.00","0.102"],["58945.90","0.003"],["58967.90","0.001"],["59588.60","0.000"],["61293.10","2.042"],["61325.40","6.461"],["61351.10","0.000"],["61395.00","1.798"],["61450.80","0.054"],["61723.70","0.000"],["61740.30","0.110"],["61750.50","0.156"],["61765.10","0.012"],["61804.20","0.000"],["61805.50","1.129"],["61811.20","0.677"],["61813.30","0.220"],["61860.40","0.000"],["61860.50","2.176"],["61863.50","0.001"],["61982.00","0.032"],["62002.60","0.048"],["62002.70","3.829"],["62004.70","0.023"],["62005.60","0.097"],["62005.90","1.539"],["62006.00","3.455"],["62006.80","21.281"],["62010.50","0.003"],["62016.90","0.057"],["62026.50","0.528"],["62028.00","1.466"],["62028.40","1.363"],["62028.60","1.110"],["62033.40","0.139"],["62034.30","0.004"],["62037.80","1.126"],["62038.30","0.000"],["62038.50","0.033"],["62041.90","0.059"],["62042.60","1.140"],["62044.10","0.065"],["62045.10","0.302"],["62045.90","0.581"],["62046.40","0.199"],["62046.80","1.384"],["62047.00","0.000"],["62048.60","0.007"],["62049.10","0.014"],["62049.30","0.020"],["62049.40","0.655"],["62049.50","1.957"],["62049.60","0.153"],["62050.90","0.613"],["62051.30","0.172"],["62051.50","0.091"],["62051.70","0.178"],["62052.70","1.352"],["62053.20","0.002"],["62053.40","0.264"],["62054.40","0.002"],["62054.70","1.001"],["62054.80","0.322"],["62056.00","0.404"],["62056.30","0.568"],["62056.40","0.322"],["62056.50","0.345"],["62057.60","0.004"],["62057.80","0.295"],["62058.20","0.005"],["62058.40","0.000"],["62058.90","0.722"],["62059.10","0.002"],["62059.40","0.820"],["62059.60","0.016"],["62059.70","0.067"],["62059.80","0.037"],["62062.20","0.162"],["62062.80","0.032"],["62063.20","0.329"],["62064.00","0.136"],["62065.40","0.001"],["62071.40","0.005"],["62071.50","2.067"]],"e":"depthUpdate","ps":"BTCUSDT","pu":10998401247309,"s":"BTCUSDT","st":1,"u":10998401261113}
{"E":1783504330916,"T":1783504330915,"U":10998401261335,"a":[["62071.60","12.568"],["62071.70","2.342"],["62073.60","0.001"],["62073.80","0.000"],["62073.90","0.000"],["62074.00","0.904"],["62074.40","0.005"],["62075.00","0.003"],["62075.30","0.953"],["62075.60","0.440"],["62076.10","0.002"],["62076.50","0.163"],["62076.70","0.244"],["62077.30","0.067"],["62077.50","0.326"],["62078.00","1.067"],["62078.50","0.193"],["62078.60","0.368"],["62079.80","0.003"],["62079.90","0.000"],["62080.10","0.001"],["62081.20","1.452"],["62083.50","0.902"],["62084.30","0.170"],["62087.00","0.001"],["62087.50","0.121"],["62087.90","0.123"],["62088.40","0.008"],["62090.80","0.001"],["62091.80","0.407"],["62092.00","0.111"],["62100.60","0.552"],["62101.20","0.168"],["62102.10","0.000"],["62102.30","2.294"],["62103.10","0.024"],["62109.70","1.295"],["62110.30","0.003"],["62119.40","0.037"],["62122.20","0.000"],["62122.60","0.000"],["62127.20","0.068"],["62127.70","0.026"],["62133.60","0.016"],["62134.30","4.235"],["62135.20","0.523"],["62135.40","0.000"],["62136.70","2.234"],["62196.10","0.088"],["62692.30","0.429"],["62982.10","0.007"],["63313.00","0.109"],["89523.20","0.258"]],"b":[["1000.00","210.542"],["11570.10","0.160"],["11771.50","0.912"],["11875.50","0.944"],["11971.50","0.464"],["55864.30","0.006"],["58967.90","0.001"],["59588.60","0.003"],["61186.70","0.285"],["61326.70","0.737"],["61448.20","8.233"],["61450.80","0.054"],["61479.00","0.002"],["61479.30","4.691"],["61479.70","3.220"],["61510.30","1.306"],["61510.80","7.439"],["61541.80","1.657"],["61761.10","0.005"],["61860.50","1.947"],["61863.50","0.000"],["61948.30","0.108"],["61981.60","0.004"],["62000.30","0.000"],["62005.50","0.096"],["62005.60","0.001"],["62006.00","0.568"],["62008.50","3.760"],["62010.80","0.016"],["62021.90","0.215"],["62027.90","0.067"],["62031.20","0.294"],["62037.50","0.033"],["62038.10","0.356"],["62038.70","0.032"],["62040.40","0.010"],["62042.10","0.331"],["62046.00","0.701"],["62047.90","0.001"],["62052.20","0.004"],["62056.30","0.004"],["62056.50","0.007"],["62058.60","0.002"],["62058.70","0.207"],["62059.10","0.250"],["62059.60","0.025"],["62061.10","0.111"],["62061.20","0.080"],["62062.20","0.162"],["62062.30","0.000"],["62062.40","0.001"],["62064.10","0.016"],["62064.20","0.002"],["62064.30","0.886"],["62064.90","0.000"],["62068.30","0.002"],["62071.10","0.004"],["62071.50","2.069"]],"e":"depthUpdate","ps":"BTCUSDT","pu":10998401261113,"s":"BTCUSDT","st":1,"u":10998401270601}
{"E":1783504331018,"T":1783504331017,"U":10998401270679,"a":[["62067.90","15.194"],["62068.00","16.591"],["62068.10","6.989"],["62068.20","0.002"],["62068.30","0.002"],["62068.40","0.000"],["62068.50","0.000"],["62068.70","0.000"],["62068.80","0.000"],["62068.90","1.522"],["62069.10","0.001"],["62069.20","0.004"],["62069.30","2.000"],["62069.40","0.130"],["62069.50","1.330"],["62069.60","0.610"],["62069.70","0.000"],["62069.90","0.565"],["62070.00","2.472"],["62070.10","0.575"],["62070.20","0.293"],["62070.50","0.001"],["62070.60","0.000"],["62070.80","0.000"],["62071.00","0.001"],["62071.20","0.000"],["62071.30","3.393"],["62071.40","0.287"],["62071.50","5.527"],["62071.60","1.172"],["62071.70","0.002"],["62071.80","0.066"],["62071.90","0.141"],["62072.10","0.000"],["62072.20","0.001"],["62072.40","0.049"],["62072.60","0.000"],["62073.00","0.123"],["62073.10","0.292"],["62073.30","0.002"],["62073.60","0.002"],["62073.70","0.006"],["62074.00","0.002"],["62074.10","0.002"],["62074.20","1.347"],["62074.30","0.548"],["62074.40","0.029"],["62074.70","0.004"],["62074.90","0.027"],["62075.00","0.005"],["62075.10","0.358"],["62075.20","0.295"],["62075.30","0.954"],["62075.40","0.007"],["62075.50","1.413"],["62075.60","0.060"],["62075.70","0.124"],["62075.80","0.226"],["62076.10","0.001"],["62076.30","0.002"],["62076.50","0.001"],["62076.60","0.000"],["62076.70","0.888"],["62076.80","1.299"],["62076.90","0.051"],["62077.10","0.011"],["62077.30","0.169"],["62077.60","0.004"],["62077.70","0.452"],["62077.80","0.816"],["62078.00","0.175"],["62078.20","0.121"],["62078.40","0.313"],["62078.60","0.458"],["62078.70","1.928"],["62079.00","0.005"],["62079.40","0.000"],["62079.70","0.001"],["62079.80","0.125"],["62079.90","0.000"],["62080.00","0.241"],["62080.30","0.325"],["62080.40","0.085"],["62080.60","0.011"],["62080.70","0.103"],["62080.90","0.055"],["62081.00","1.017"],["62081.10","0.003"],["62081.30","0.395"],["62081.40","0.082"],["62081.60","0.287"],["62081.70","0.011"],["62081.80","0.146"],["62081.90","0.140"],["62082.60","0.011"],["62082.70","0.001"],["62082.80","0.028"],["62082.90","0.288"],["62083.00","0.580"],["62083.50","0.902"],["62083.60","0.004"],["62084.00","0.090"],["62084.20","0.003"],["62084.30","0.186"],["62084.40","0.474"],["62084.60","0.512"],["62085.10","0.003"],["62085.60","0.003"],["62085.80","0.656"],["62086.10","0.051"],["62086.60","0.002"],["62086.70","0.668"],["62086.80","0.011"],["62087.30","0.001"],["62087.50","0.057"],["62087.60","0.642"],["62087.90","0.003"],["62088.10","0.001"],["62088.30","0.001"],["62088.40","0.000"],["62088.70","0.050"],["62088.80","0.225"],["62088.90","0.571"],["62089.20","0.005"],["62089.50","0.012"],["62089.60","0.163"],["62089.70","0.018"],["62089.80","0.067"],["62089.90","0.017"],["62090.20","0.008"],["62090.50","0.008"],["62090.90","0.060"],["62091.30","0.455"],["62091.50","1.412"],["62091.60","0.000"],["62091.70","0.008"],["62091.80","0.337"],["62092.00","0.011"],["62092.80","0.068"],["62093.00","1.278"],["62093.10","1.719"],["62093.30","0.292"],["62093.60","0.041"],["62093.80","0.005"],["62094.00","0.701"],["62094.20","0.711"],["62094.40","0.677"],["62094.90","0.068"],["62095.00","0.302"],["62095.10","0.407"],["62095.30","0.100"],["62095.40","0.022"],["62095.70","0.064"],["62095.80","0.325"],["62095.90","0.163"],["62096.10","2.500"],["62096.30","0.050"],["62096.50","0.892"],["62096.60","0.284"],["62097.00","0.003"],["62097.10","0.002"],["62097.20","0.001"],["62097.70","0.078"],["62097.90","0.002"],["62098.40","0.001"],["62098.60","0.004"],["62098.70","0.002"],["62098.80","0.000"],["62098.90","0.847"],["62099.00","0.030"],["62099.10","0.116"],["62099.20","0.146"],["62099.30","0.000"],["62099.60","1.451"],["62099.80","0.606"],["62099.90","0.699"],["62100.00","0.646"],["62100.10","0.001"],["62100.20","0.003"],["62100.30","0.026"],["62100.40","0.059"],["62100.50","0.691"],["62100.60","0.463"],["62100.70","0.001"],["62100.80","0.052"],["62101.10","0.001"],["62101.20","0.000"],["62101.30","0.071"],["62101.50","0.003"],["62101.60","0.620"],["62101.70","5.010"],["62101.80","2.776"],["62101.90","0.061"],["62102.20","0.016"],["62102.30","2.294"],["62102.70","0.048"],["62103.10","0.000"],["62103.50","0.004"],["62103.60","0.006"],["62105.40","1.427"],["62106.00","0.012"],["62106.70","0.005"],["62106.90","0.048"],["62107.00","0.005"],["62107.50","0.306"],["62107.80","0.637"],["62108.00","0.334"],["62108.10","0.003"],["62108.80","2.250"],["62108.90","0.015"],["62109.40","0.000"],["62109.60","0.041"],["62110.00","0.450"],["62110.10","3.541"],["62110.20","0.507"],["62110.30","0.005"],["62110.40","0.001"],["62110.60","0.827"],["62110.70","0.061"],["62111.50","0.163"],["62111.70","4.023"],["62112.00","0.062"],["62112.10","0.002"],["62112.20","3.534"],["62112.60","0.282"],["62112.80","1.362"],["62113.50","0.657"],["62113.70","0.004"],["62113.90","0.211"],["62114.00","0.001"],["62114.10","0.004"],["62114.30","0.006"],["62114.40","0.001"],["62115.10","0.014"],["62116.50","0.093"],["62116.90","0.003"],["62119.00","0.008"],["62119.20","0.025"],["62119.40","0.025"],["62119.50","0.004"],["62119.70","0.283"],["62119.80","0.343"],["62119.90","0.037"],["62120.00","0.196"],["62121.00","0.000"],["62121.10","0.820"],["62121.20","0.938"],["62121.30","0.687"],["62121.40","0.036"],["62121.50","0.276"],["62121.60","0.003"],["62122.10","0.041"],["62123.00","0.059"],["62124.10","0.001"],["62124.80","0.667"],["62124.90","1.484"],["62125.50","0.000"],["62125.60","0.000"],["62126.00","0.354"],["62126.10","0.154"],["62127.20","0.043"],["62128.20","1.362"],["62129.80","0.000"],["62130.20","0.030"],["62130.50","0.031"],["62132.30","0.250"],["62133.50","0.002"],["62134.00","0.059"],["62134.30","0.858"],["62134.70","0.000"],["62135.20","0.427"],["62135.80","0.001"],["62136.40","0.835"],["62136.50","0.877"],["62136.70","2.234"],["62136.80","0.116"],["62138.40","0.312"],["62138.90","0.022"],["62139.80","6.684"],["62141.00","0.016"],["62141.20","0.846"],["62145.20","0.323"],["62149.00","0.002"],["62150.00","102.198"],["62169.80","0.699"],["62171.60","0.003"],["62181.20","0.000"],["62187.30","0.015"],["62192.20","1.046"],["62193.60","0.012"],["62197.00","0.001"],["62198.50","0.213"],["62221.80","0.004"],["62227.60","0.675"],["62237.40","0.028"],["62239.90","0.000"],["62240.50","0.024"],["62242.40","0.013"],["62254.30","0.001"],["62259.30","0.004"],["62261.20","0.004"],["62336.60","0.000"],["62378.40","0.001"],["62384.80","0.000"],["62385.90","1.036"],["62389.00","2.293"],["62396.10","0.000"],["62433.30","0.131"],["62688.80","0.002"],["62690.10","0.002"],["62690.70","0.000"],["62690.80","1.550"],["62692.10","0.000"],["62692.30","0.429"],["62785.90","0.946"],["62786.00","1.497"],["62790.00","9.462"],["62848.10","2.378"],["62851.40","3.267"],["62852.10","8.674"],["63041.90","0.000"],["63069.40","2.062"],["63069.60","0.002"],["63070.10","1.586"],["63071.40","0.622"],["63074.20","0.000"],["63074.30","0.957"],["63309.40","0.035"],["63313.00","0.112"],["67331.80","0.002"],["67589.60","0.597"]],"b":[["1000.00","210.542"],["11570.10","0.032"],["11768.00","0.016"],["11769.90","0.016"],["11770.00","0.016"],["11771.50","1.120"],["11870.10","0.688"],["11871.70","0.016"],["11871.90","0.048"],["11875.50","0.784"],["11969.30","0.016"],["11971.30","0.016"],["11971.50","0.560"],["55862.30","0.002"],["55864.30","0.004"],["56547.20","0.000"],["56548.30","0.000"],["57224.40","0.010"],["57379.90","0.000"],["57535.40","0.000"],["58956.60","0.003"],["58956.70","0.006"],["58965.90","0.016"],["58967.90","0.001"],["59588.60","0.000"],["61048.40","1.135"],["61324.20","0.352"],["61326.20","0.013"],["61356.40","4.040"],["61357.80","3.227"],["61447.30","0.000"],["61448.20","5.333"],["61449.20","0.000"],["61449.30","0.005"],["61450.60","0.022"],["61450.80","0.054"],["61480.50","2.915"],["61540.90","0.165"],["61571.30","0.003"],["61572.80","1.130"],["61577.70","0.092"],["61609.60","0.246"],["61609.70","0.246"],["61612.00","0.691"],["61633.50","0.065"],["61639.80","0.040"],["61727.00","0.160"],["61785.00","0.301"],["61795.90","0.000"],["61806.90","0.765"],["61819.70","0.001"],["61826.00","0.100"],["61863.50","0.001"],["61879.40","0.668"],["61880.90","1.038"],["61882.10","0.002"],["61889.30","0.000"],["61910.40","0.002"],["61912.50","0.654"],["61935.90","0.028"],["61941.30","0.028"],["61942.50","0.000"],["61943.80","1.309"],["61952.70","0.040"],["61956.20","0.000"],["61956.80","0.025"],["61960.60","0.002"],["61963.20","0.003"],["61966.50","0.001"],["61968.30","0.281"],["61969.50","0.000"],["61972.30","0.310"],["61992.20","0.721"],["61994.60","0.000"],["61998.40","19.116"],["61998.60","0.885"],["61998.70","4.399"],["62002.10","0.671"],["62002.70","3.831"],["62002.80","0.441"],["62003.80","0.000"],["62005.60","0.001"],["62006.20","0.004"],["62006.80","2.173"],["62007.10","0.290"],["62008.50","0.959"],["62008.70","0.003"],["62009.40","0.015"],["62013.40","0.400"],["62014.30","0.059"],["62014.80","0.025"],["62015.20","2.628"],["62015.60","0.002"],["62015.80","0.000"],["62016.90","0.001"],["62017.20","0.030"],["62017.70","0.182"],["62018.40","0.003"],["62018.70","0.005"],["62019.00","0.000"],["62019.20","0.013"],["62019.50","0.011"],["62019.80","0.007"],["62020.10","0.000"],["62020.40","1.027"],["62020.70","9.368"],["62020.90","0.000"],["62021.00","0.000"],["62021.60","2.443"],["62021.80","1.997"],["62021.90","0.083"],["62022.00","0.018"],["62022.10","0.016"],["62022.50","0.063"],["62022.70","0.009"],["62023.40","0.032"],["62023.50","0.021"],["62023.70","0.055"],["62023.80","0.001"],["62024.60","0.308"],["62025.30","0.654"],["62026.00","0.824"],["62026.10","0.001"],["62026.50","0.542"],["62026.70","0.002"],["62026.80","0.003"],["62026.90","0.003"],["62027.40","0.005"],["62027.80","0.120"],["62027.90","0.054"],["62028.30","0.160"],["62028.80","0.004"],["62029.40","0.005"],["62029.80","0.015"],["62030.00","0.092"],["62030.40","0.002"],["62030.50","0.000"],["62031.00","0.013"],["62031.30","0.094"],["62031.40","0.000"],["62031.80","0.005"],["62031.90","0.004"],["62033.00","0.049"],["62033.40","0.125"],["62033.90","0.343"],["62034.60","2.271"],["62034.70","0.001"],["62034.90","1.286"],["62035.00","0.004"],["62035.20","0.005"],["62035.60","0.000"],["62036.40","0.285"],["62036.60","0.292"],["62036.80","0.681"],["62036.90","0.042"],["62037.60","0.700"],["62037.70","0.003"],["62038.30","0.000"],["62038.70","0.044"],["62039.50","0.003"],["62039.80","0.732"],["62039.90","0.021"],["62040.10","0.040"],["62040.20","0.000"],["62040.30","0.112"],["62040.50","0.061"],["62040.90","1.295"],["62041.20","0.455"],["62041.50","0.008"],["62041.60","0.004"],["62041.80","0.052"],["62041.90","0.000"],["62042.10","0.323"],["62042.20","0.000"],["62042.40","0.017"],["62042.50","0.294"],["62042.60","1.507"],["62042.80","0.001"],["62042.90","0.021"],["62043.00","0.000"],["62043.20","0.038"],["62043.50","0.003"],["62043.60","0.125"],["62043.70","0.011"],["62043.80","0.054"],["62043.90","0.095"],["62044.00","0.330"],["62044.10","0.057"],["62044.30","0.006"],["62044.40","0.004"],["62044.70","0.585"],["62044.90","0.085"],["62045.00","0.504"],["62045.40","2.459"],["62045.50","0.002"],["62045.80","0.679"],["62045.90","0.001"],["62046.10","0.002"],["62046.30","1.424"],["62046.40","0.079"],["62046.50","0.004"],["62046.60","0.000"],["62046.70","0.002"],["62047.60","0.056"],["62048.00","0.739"],["62048.20","0.015"],["62048.30","0.054"],["62048.70","0.010"],["62048.80","0.000"],["62049.00","1.020"],["62049.20","0.003"],["62049.30","0.074"],["62049.40","1.720"],["62049.50","1.232"],["62049.60","0.718"],["62049.90","2.138"],["62050.00","0.005"],["62050.20","0.003"],["62050.40","0.279"],["62050.50","0.744"],["62050.60","0.342"],["62050.80","2.145"],["62050.90","0.001"],["62051.00","0.000"],["62051.30","0.173"],["62051.40","0.003"],["62051.50","0.071"],["62051.60","0.154"],["62051.90","0.205"],["62052.60","0.684"],["62052.70","1.574"],["62052.80","0.242"],["62052.90","0.096"],["62053.10","0.001"],["62053.20","0.002"],["62053.40","0.124"],["62053.50","0.003"],["62053.70","0.003"],["62053.80","0.000"],["62053.90","0.163"],["62054.20","0.174"],["62054.40","0.002"],["62054.50","0.001"],["62054.70","0.001"],["62054.80","0.000"],["62054.90","0.014"],["62055.00","1.809"],["62055.10","0.002"],["62055.20","0.001"],["62055.30","0.003"],["62055.50","0.323"],["62055.60","0.000"],["62055.70","0.000"],["62055.80","0.006"],["62056.00","0.002"],["62056.10","0.005"],["62056.20","1.196"],["62056.30","0.008"],["62056.40","1.825"],["62056.50","0.005"],["62056.60","0.171"],["62056.70","0.719"],["62056.90","0.003"],["62057.00","0.001"],["62057.30","0.335"],["62057.40","0.002"],["62057.50","0.005"],["62057.60","0.002"],["62057.70","0.166"],["62057.80","0.003"],["62057.90","0.000"],["62058.10","0.006"],["62058.50","0.051"],["62058.70","0.054"],["62058.80","0.024"],["62058.90","0.004"],["62059.00","0.000"],["62059.10","0.002"],["62059.30","0.002"],["62059.40","0.824"],["62059.50","0.001"],["62059.60","0.016"],["62059.70","0.056"],["62059.80","0.001"],["62060.00","0.002"],["62060.40","0.002"],["62060.60","0.003"],["62061.50","0.000"],["62061.60","0.328"],["62061.70","0.002"],["62061.80","0.000"],["62061.90","0.034"],["62062.20","0.034"],["62062.50","0.092"],["62062.80","0.080"],["62062.90","0.000"],["62063.00","0.001"],["62063.20","0.006"],["62063.30","0.001"],["62063.40","0.056"],["62063.50","0.007"],["62063.60","0.055"],["62063.80","0.003"],["62063.90","0.000"],["62064.00","0.007"],["62064.10","0.000"],["62064.30","0.000"],["62064.40","0.002"],["62064.50","0.001"],["62064.60","0.000"],["62065.00","0.004"],["62065.10","0.007"],["62065.20","0.000"],["62065.50","0.000"],["62065.60","0.003"],["62065.70","0.002"],["62065.80","0.000"],["62066.40","0.003"],["62066.50","0.000"],["62066.60","0.000"],["62066.70","0.075"],["62067.00","0.000"],["62067.20","0.001"],["62067.40","0.000"],["62067.50","0.000"],["62067.60","0.299"],["62067.70","0.148"],["62067.80","1.023"],["62067.90","0.000"],["62068.00","0.000"],["62068.10","0.000"],["62068.20","0.000"],["62068.30","0.000"],["62068.40","0.000"],["62068.60","0.000"],["62068.80","0.000"],["62069.10","0.000"],["62069.20","0.000"],["62069.30","0.000"],["62069.50","0.000"],["62069.80","0.000"],["62069.90","0.000"],["62070.00","0.000"],["62070.10","0.000"],["62070.40","0.000"],["62070.50","0.000"],["62070.70","0.000"],["62071.10","0.000"],["62071.30","0.000"],["62071.40","0.000"],["62071.50","0.000"]],"e":"depthUpdate","ps":"BTCUSDT","pu":10998401270601,"s":"BTCUSDT","st":1,"u":10998401313181}
