{"E":1785353518616,"T":1785353518614,"U":11165394093350,"a":[["64060.00","0.000"],["64060.20","0.000"],["64060.30","0.000"],["64060.60","0.000"],["64060.70","0.000"],["64060.80","0.000"],["64060.90","0.000"],["64061.00","0.000"],["64061.30","0.000"],["64061.50","0.000"],["64061.70","1.565"],["64061.80","0.007"],["64061.90","0.001"],["64062.00","0.002"],["64062.20","0.000"],["64062.40","0.003"],["64062.50","0.002"],["64062.90","0.004"],["64063.10","0.008"],["64063.20","0.008"],["64063.40","0.000"],["64063.80","0.000"],["64064.00","0.011"],["64064.30","0.002"],["64064.60","0.003"],["64064.90","0.002"],["64065.00","0.001"],["64065.20","0.002"],["64065.40","0.025"],["64065.50","0.009"],["64065.60","0.003"],["64065.70","0.002"],["64065.80","0.058"],["64065.90","0.002"],["64066.00","0.007"],["64066.20","0.000"],["64066.40","0.016"],["64066.70","0.000"],["64066.80","0.000"],["64066.90","0.005"],["64067.00","0.050"],["64067.10","0.001"],["64067.20","0.011"],["64067.30","0.392"],["64067.70","0.157"],["64067.80","0.001"],["64068.10","0.018"],["64068.30","0.177"],["64068.40","0.007"],["64068.80","0.001"],["64068.90","0.316"],["64069.20","0.077"],["64069.30","0.002"],["64069.40","0.003"],["64069.50","0.001"],["64069.60","0.240"],["64069.80","0.009"],["64070.10","0.218"],["64070.30","0.174"],["64070.50","0.007"],["64070.70","0.002"],["64070.80","0.134"],["64070.90","0.011"],["64071.10","0.119"],["64071.30","0.158"],["64071.80","0.022"],["64071.90","0.248"],["64072.00","0.901"],["64072.10","0.594"],["64072.20","2.016"],["64072.30","0.001"],["64072.40","0.000"],["64072.60","0.106"],["64072.70","0.169"],["64072.80","1.283"],["64072.90","0.327"],["64073.20","0.597"],["64073.40","0.610"],["64073.50","0.919"],["64073.60","0.637"],["64073.70","0.318"],["64073.80","0.000"],["64073.90","0.000"],["64074.00","2.409"],["64074.20","0.000"],["64074.50","0.229"],["64074.60","10.234"],["64075.50","0.062"],["64075.80","0.001"],["64075.90","1.001"],["64076.30","2.585"],["64076.50","0.014"],["64076.60","0.258"],["64076.90","0.085"],["64077.00","1.190"],["64077.10","0.002"],["64077.50","0.230"],["64077.70","0.041"],["64078.20","0.020"],["64078.40","2.242"],["64078.50","1.267"],["64078.60","0.161"],["64078.70","0.563"],["64078.80","0.321"],["64078.90","0.226"],["64079.20","0.119"],["64079.40","0.028"],["64080.10","1.753"],["64080.40","0.047"],["64080.60","0.000"],["64080.90","0.070"],["64081.00","0.027"],["64081.30","0.003"],["64081.50","0.002"],["64082.30","0.217"],["64082.60","0.019"],["64083.30","0.001"],["64083.90","0.275"],["64084.10","0.342"],["64084.60","0.001"],["64085.60","0.105"],["64086.70","1.070"],["64087.10","0.013"],["64087.20","0.000"],["64087.30","1.027"],["64087.60","0.014"],["64087.80","0.510"],["64088.80","0.354"],["64089.00","0.047"],["64089.10","0.008"],["64089.20","0.006"],["64089.30","0.642"],["64089.40","0.001"],["64089.50","0.112"],["64089.90","0.001"],["64090.00","0.064"],["64090.20","0.177"],["64090.30","1.077"],["64090.80","0.006"],["64091.60","2.358"],["64092.10","0.002"],["64092.20","1.764"],["64092.40","1.598"],["64092.70","0.049"],["64093.40","0.001"],["64093.60","0.003"],["64095.30","0.079"],["64096.40","0.169"],["64096.60","0.001"],["64097.20","5.901"],["64097.30","0.001"],["64097.80","0.015"],["64098.10","0.012"],["64098.20","0.110"],["64099.20","1.498"],["64099.40","0.002"],["64099.60","2.993"],["64099.70","0.000"],["64099.90","0.140"],["64100.00","2.813"],["64100.10","0.001"],["64102.20","0.508"],["64102.80","0.003"],["64103.30","0.502"],["64103.40","0.002"],["64104.20","0.017"],["64104.50","1.251"],["64104.90","0.018"],["64105.00","0.003"],["64105.30","1.527"],["64106.30","0.801"],["64106.50","0.340"],["64106.70","0.001"],["64107.60","0.157"],["64107.70","2.343"],["64107.90","0.003"],["64108.40","0.001"],["64108.60","0.566"],["64108.80","0.037"],["64108.90","4.576"],["64109.00","10.001"],["64109.10","0.009"],["64110.10","12.233"],["64111.80","0.005"],["64111.90","0.029"],["64112.40","1.381"],["64112.50","0.003"],["64112.90","0.027"],["64113.00","0.339"],["64113.30","0.118"],["64114.60","0.018"],["64114.80","0.100"],["64114.90","0.601"],["64118.10","0.000"],["64119.10","0.211"],["64119.90","0.608"],["64120.60","0.005"],["64122.80","0.054"],["64125.50","0.000"],["64125.80","0.003"],["64126.00","0.402"],["64126.30","0.044"],["64134.60","1.482"],["64136.00","0.001"],["64136.50","0.314"],["64140.80","4.501"],["64142.00","0.005"],["64143.20","0.031"],["64144.30","2.336"],["64145.30","0.000"],["64152.00","0.002"],["64154.00","1.209"],["64154.10","0.011"],["64154.90","0.282"],["64155.70","0.005"],["64156.50","2.925"],["64159.70","0.000"],["64160.00","0.840"],["64162.90","23.216"],["64163.80","0.001"],["64165.00","0.081"],["64176.50","3.842"],["64178.00","0.000"],["64180.10","0.020"],["64183.10","0.003"],["64183.20","0.005"],["64189.80","0.282"],["64202.50","0.520"],["64215.30","0.001"],["64232.40","0.543"],["64232.50","0.161"],["64240.00","1.597"],["64240.90","0.001"],["64243.40","5.937"],["64244.10","0.001"],["64246.60","0.002"],["64247.50","0.000"],["64247.70","1.954"],["64253.90","0.006"],["64265.00","0.378"],["64265.80","0.000"],["64266.00","0.518"],["64266.20","1.947"],["64266.70","0.117"],["64290.10","0.001"],["64292.90","0.510"],["64311.20","0.385"],["64317.90","0.002"],["64320.00","0.489"],["64374.70","0.004"],["64380.30","0.455"],["64381.10","0.469"],["64382.00","0.300"],["64400.00","12.139"],["64400.10","0.001"],["64438.70","0.000"],["64445.20","0.001"],["64480.00","0.649"],["64502.80","0.000"],["64510.10","0.001"],["64547.70","0.110"],["64548.10","0.110"],["64548.60","0.220"],["64566.80","0.000"],["64573.30","0.006"],["64638.00","0.075"],["64670.10","2.068"],["64700.60","0.205"],["64701.40","0.000"],["64702.30","0.000"],["64797.20","0.000"],["64797.90","0.009"],["64798.00","0.360"],["64798.30","3.289"],["64798.80","11.041"],["64861.30","0.344"],["64862.00","0.018"],["64862.10","0.763"],["64862.40","3.122"],["64862.90","6.979"],["65148.90","1.778"],["65341.10","0.018"],["65342.90","0.006"],["65981.70","0.022"]],"b":[["1000.00","37.592"],["13559.90","1.092"],["13659.90","0.924"],["13660.70","0.014"],["13661.60","0.070"],["13759.90","0.756"],["13760.70","0.014"],["13761.60","0.070"],["13859.90","0.882"],["13959.90","0.224"],["13960.70","0.014"],["13961.60","0.070"],["57653.90","0.000"],["57654.60","0.000"],["57655.40","0.002"],["61497.50","0.000"],["63052.50","0.001"],["63054.90","0.018"],["63059.90","0.949"],["63060.70","0.005"],["63150.20","0.276"],["63226.20","1.879"],["63259.20","9.398"],["63275.20","10.953"],["63312.60","2.346"],["63312.70","0.002"],["63361.60","3.907"],["63375.70","1.250"],["63402.30","0.003"],["63408.10","0.000"],["63419.30","0.792"],["63420.10","1.786"],["63421.00","0.002"],["63451.30","7.941"],["63680.00","3.941"],["63721.10","0.003"],["63724.30","7.882"],["63727.40","0.000"],["63760.00","0.480"],["63787.80","0.001"],["63803.80","0.000"],["63804.50","5.359"],["63840.00","1.719"],["63857.40","0.000"],["63865.30","0.117"],["63884.70","7.508"],["63888.90","0.390"],["63892.10","0.118"],["63915.00","1.959"],["63915.30","0.312"],["63920.00","0.865"],["63924.20","0.000"],["63929.20","0.000"],["63933.40","1.986"],["63933.70","3.903"],["63935.50","0.000"],["63940.10","0.601"],["63944.20","0.001"],["63944.30","0.004"],["63946.00","0.001"],["63951.90","0.381"],["63952.10","0.203"],["63954.10","0.000"],["63954.50","0.511"],["63954.60","1.694"],["63957.20","2.118"],["63963.50","0.000"],["63969.50","21.840"],["63970.70","2.252"],["63974.30","0.095"],["63975.90","0.001"],["63978.50","0.001"],["63979.00","0.001"],["63979.20","0.001"],["63980.80","0.017"],["63981.10","0.000"],["63983.00","0.003"],["63983.70","0.001"],["63986.30","0.656"],["63987.40","0.000"],["63987.50","2.188"],["63988.90","0.027"],["63989.40","0.123"],["63991.50","0.000"],["63994.10","0.000"],["63996.60","0.016"],["63996.70","0.000"],["63997.40","0.011"],["63999.30","0.613"],["64000.00","11.003"],["64000.10","2.474"],["64000.30","0.656"],["64000.90","0.068"],["64001.20","0.001"],["64001.90","0.003"],["64003.30","0.044"],["64004.50","0.000"],["64006.00","0.381"],["64006.40","1.212"],["64007.10","0.000"],["64007.40","0.008"],["64008.40","0.130"],["64008.60","0.422"],["64009.40","0.549"],["64009.70","0.318"],["64009.80","0.109"],["64010.30","0.555"],["64010.40","0.005"],["64010.80","2.428"],["64011.10","0.003"],["64011.20","0.095"],["64011.50","0.002"],["64012.10","0.100"],["64012.30","0.000"],["64012.40","0.369"],["64012.80","0.037"],["64013.20","0.125"],["64013.30","0.100"],["64014.50","0.000"],["64014.90","0.097"],["64016.50","3.020"],["64017.10","0.000"],["64017.50","0.004"],["64018.20","0.001"],["64018.50","0.002"],["64018.80","0.026"],["64020.20","0.048"],["64021.10","0.015"],["64021.20","0.195"],["64021.40","1.081"],["64021.60","0.000"],["64021.80","0.002"],["64022.50","0.010"],["64022.80","0.010"],["64022.90","1.721"],["64023.10","0.131"],["64023.30","0.324"],["64023.90","0.330"],["64024.10","0.001"],["64025.00","0.000"],["64025.10","0.001"],["64025.50","0.006"],["64025.70","2.407"],["64025.90","0.007"],["64026.20","0.292"],["64026.30","0.362"],["64026.60","0.120"],["64026.90","0.131"],["64027.50","0.006"],["64027.70","0.000"],["64028.00","0.042"],["64028.10","0.001"],["64028.60","0.002"],["64029.10","1.265"],["64029.20","0.025"],["64029.50","0.034"],["64029.60","0.052"],["64030.70","0.002"],["64030.80","0.196"],["64030.90","0.016"],["64031.00","0.002"],["64031.10","0.016"],["64031.20","0.000"],["64031.30","0.044"],["64031.90","0.120"],["64032.20","0.382"],["64032.50","0.058"],["64032.80","0.031"],["64033.10","2.325"],["64033.20","0.002"],["64033.50","0.991"],["64033.60","0.004"],["64033.80","0.293"],["64033.90","0.076"],["64034.00","1.079"],["64034.30","0.001"],["64034.80","2.343"],["64035.10","0.889"],["64035.40","0.330"],["64035.50","0.002"],["64035.60","0.563"],["64035.70","0.003"],["64035.80","0.314"],["64035.90","0.000"],["64036.00","0.044"],["64036.30","0.000"],["64036.60","0.616"],["64036.70","0.003"],["64036.80","0.014"],["64036.90","0.003"],["64037.00","0.050"],["64037.80","0.000"],["64038.00","0.021"],["64038.10","0.000"],["64038.40","1.093"],["64038.80","0.000"],["64039.60","0.023"],["64039.80","0.005"],["64040.00","0.580"],["64040.20","0.001"],["64041.00","0.935"],["64042.00","0.026"],["64042.60","0.005"],["64043.50","0.122"],["64043.60","0.016"],["64044.70","0.080"],["64046.00","0.061"],["64046.20","0.001"],["64046.60","0.034"],["64046.80","0.023"],["64047.50","0.501"],["64047.70","0.000"],["64047.80","0.037"],["64047.90","2.374"],["64048.20","0.003"],["64048.60","0.872"],["64048.80","0.066"],["64049.00","0.000"],["64049.30","0.021"],["64049.40","0.003"],["64049.80","0.611"],["64050.30","0.001"],["64050.40","0.022"],["64050.70","0.002"],["64051.10","2.345"],["64051.20","2.773"],["64051.30","0.664"],["64051.40","0.000"],["64051.90","0.001"],["64052.00","0.003"],["64052.10","0.001"],["64052.30","10.001"],["64052.40","0.003"],["64052.50","2.865"],["64052.60","0.022"],["64052.70","0.001"],["64053.50","0.001"],["64053.60","0.004"],["64053.80","0.001"],["64054.00","0.003"],["64054.20","0.316"],["64054.40","0.004"],["64054.60","0.023"],["64054.90","0.469"],["64055.20","0.005"],["64055.30","0.012"],["64055.40","0.051"],["64055.50","0.068"],["64055.70","0.191"],["64056.10","0.004"],["64056.20","0.515"],["64056.30","0.004"],["64056.40","2.502"],["64056.60","0.374"],["64056.70","0.032"],["64056.80","0.000"],["64057.00","0.000"],["64057.20","0.081"],["64057.30","0.002"],["64057.60","1.393"],["64057.70","0.002"],["64057.80","0.002"],["64058.00","0.002"],["64058.10","0.000"],["64058.30","0.001"],["64058.50","0.121"],["64058.60","0.001"],["64058.80","0.250"],["64058.90","0.251"],["64059.00","0.000"],["64059.10","0.000"],["64059.30","0.019"],["64059.40","0.433"],["64059.50","0.002"],["64059.60","0.000"],["64059.70","0.000"],["64059.80","0.002"],["64059.90","2.979"],["64060.00","3.829"],["64060.10","0.001"],["64060.20","0.000"],["64060.50","0.001"],["64060.60","2.341"],["64060.70","1.077"],["64060.80","2.504"],["64060.90","1.961"],["64061.00","0.185"],["64061.20","0.000"],["64061.40","0.001"],["64061.50","0.100"],["64061.60","22.477"]],"e":"depthUpdate","ps":"BTCUSDT","pu":11165394093325,"s":"BTCUSDT","st":1,"u":11165394110421}
{"E":1785353518718,"T":1785353518717,"U":11165394110717,"a":[["64061.70","0.331"],["64061.80","0.005"],["64064.00","0.008"],["64064.40","0.001"],["64065.70","0.001"],["64065.80","0.018"],["64066.10","0.003"],["64067.20","0.031"],["64067.60","0.001"],["64067.80","0.157"],["64067.90","0.546"],["64068.00","0.054"],["64068.10","0.018"],["64068.80","0.126"],["64069.00","0.441"],["64069.20","0.076"],["64069.60","0.002"],["64070.10","0.042"],["64070.20","0.335"],["64070.80","0.009"],["64071.10","0.025"],["64071.20","0.093"],["64071.30","0.080"],["64071.50","0.107"],["64071.80","0.159"],["64072.00","0.355"],["64072.10","0.048"],["64072.80","0.091"],["64073.50","0.917"],["64073.60","0.637"],["64073.70","0.316"],["64073.90","0.546"],["64074.00","2.407"],["64074.40","1.249"],["64074.50","0.230"],["64075.70","0.338"],["64075.90","0.001"],["64076.00","0.008"],["64077.30","1.002"],["64077.50","0.232"],["64078.70","0.001"],["64078.90","0.135"],["64079.00","0.001"],["64080.00","1.193"],["64080.50","0.206"],["64081.40","0.005"],["64085.00","0.535"],["64087.30","1.028"],["64090.30","1.069"],["64090.60","0.376"],["64090.90","0.921"],["64093.60","0.035"],["64097.10","0.538"],["64100.10","0.002"],["64103.40","0.003"],["64103.50","2.798"],["64103.60","0.001"],["64104.00","0.006"],["64106.40","0.501"],["64107.60","0.000"],["64108.60","0.646"],["64109.00","12.070"],["64109.10","0.007"],["64111.90","0.004"],["64112.20","0.375"],["64113.30","0.110"],["64113.60","2.607"],["64117.60","0.034"],["64117.70","0.001"],["64119.30","0.030"],["64119.90","0.633"],["64120.60","2.072"],["64123.90","1.538"],["64124.00","0.024"],["64125.80","0.002"],["64132.20","0.040"],["64135.10","0.012"],["64140.80","1.345"],["64144.30","6.975"],["64144.40","2.949"],["64145.30","23.215"],["64160.20","1.356"],["64162.90","0.001"],["64188.90","4.416"],["64205.30","0.024"],["64214.80","1.744"],["64233.10","0.025"],["64243.30","1.526"],["64243.60","0.008"],["64244.10","0.000"],["64255.80","0.147"],["64266.70","0.117"],["64285.20","0.779"],["64285.50","0.002"],["64380.30","0.156"],["64381.10","0.170"],["64382.00","0.300"],["64702.30","0.000"],["64754.40","0.000"],["64814.60","0.999"],["64958.50","25.671"],["64992.70","0.019"]],"b":[["1000.00","37.592"],["13559.90","0.966"],["13661.60","0.196"],["13759.90","0.630"],["13761.60","0.182"],["13859.90","0.770"],["13961.60","0.196"],["51249.00","0.001"],["57655.40","0.002"],["61499.10","0.006"],["62414.30","0.002"],["63068.30","4.274"],["63158.60","0.000"],["63226.20","0.000"],["63275.20","12.831"],["63312.60","1.642"],["63328.80","0.003"],["63361.60","4.610"],["63377.70","0.001"],["63419.10","0.056"],["63421.00","0.002"],["63739.60","0.236"],["63749.40","0.000"],["63787.70","0.000"],["63788.10","0.166"],["63790.20","0.014"],["63805.40","0.146"],["63857.80","0.211"],["63884.80","1.392"],["63888.90","0.389"],["63917.30","0.000"],["63940.80","1.487"],["63940.90","0.496"],["63948.70","1.139"],["63961.10","1.491"],["63961.20","0.186"],["63963.80","0.491"],["63969.30","0.000"],["63969.50","0.000"],["63970.70","2.252"],["63983.00","0.000"],["63984.80","0.314"],["63985.80","1.828"],["63988.60","0.529"],["63988.80","0.002"],["63990.20","1.440"],["63990.50","0.517"],["63995.70","0.000"],["63997.40","1.839"],["63998.30","0.000"],["64004.60","0.244"],["64006.00","0.405"],["64007.40","0.000"],["64007.80","0.090"],["64008.20","1.827"],["64009.80","0.077"],["64010.30","0.518"],["64010.40","0.006"],["64010.80","2.340"],["64012.00","0.002"],["64012.90","0.050"],["64013.20","0.060"],["64019.10","2.559"],["64020.50","0.051"],["64021.00","0.033"],["64022.40","0.010"],["64022.90","0.000"],["64027.80","0.002"],["64029.20","0.000"],["64029.50","0.154"],["64029.60","0.056"],["64030.00","1.738"],["64032.50","0.003"],["64034.20","0.001"],["64035.60","0.001"],["64037.30","0.411"],["64037.50","0.573"],["64038.50","0.013"],["64039.10","0.107"],["64039.30","0.937"],["64039.80","0.004"],["64040.20","0.051"],["64041.00","0.000"],["64041.10","0.637"],["64041.60","0.708"],["64041.70","4.439"],["64041.80","0.367"],["64042.40","0.373"],["64043.50","0.129"],["64043.70","0.266"],["64044.00","0.009"],["64045.60","0.124"],["64046.60","0.265"],["64046.80","0.003"],["64047.20","0.037"],["64048.00","1.168"],["64048.20","0.234"],["64048.40","0.002"],["64048.80","0.004"],["64049.30","0.022"],["64049.80","0.826"],["64051.00","0.002"],["64051.20","1.069"],["64051.30","0.110"],["64051.40","0.226"],["64051.70","0.000"],["64052.30","0.001"],["64052.60","0.104"],["64053.00","0.000"],["64053.30","10.374"],["64053.40","2.240"],["64054.80","0.024"],["64055.00","0.007"],["64055.20","0.003"],["64056.40","2.502"],["64056.70","0.029"],["64057.60","1.391"],["64058.60","0.314"],["64058.90","0.021"],["64059.50","0.002"],["64059.90","2.743"],["64060.00","3.829"],["64060.50","0.235"],["64060.70","0.988"],["64060.80","2.506"],["64061.00","0.738"],["64061.60","23.403"]],"e":"depthUpdate","ps":"BTCUSDT","pu":11165394110421,"s":"BTCUSDT","st":1,"u":11165394127032}
{"E":1785353518820,"T":1785353518818,"U":11165394127135,"a":[["64063.20","0.010"],["64064.90","0.002"],["64065.20","0.024"],["64066.90","0.003"],["64067.80","0.158"],["64070.20","0.315"],["64070.40","1.122"],["64071.30","0.197"],["64071.70","0.022"],["64072.80","0.101"],["64074.60","10.154"],["64075.30","0.081"],["64080.50","0.116"],["64083.80","0.295"],["64084.80","0.004"],["64089.50","0.063"],["64093.60","0.003"],["64093.70","0.349"],["64096.50","0.052"],["64098.20","0.095"],["64098.90","0.774"],["64100.10","0.001"],["64103.50","2.321"],["64103.90","0.002"],["64105.40","0.000"],["64108.70","0.003"],["64109.00","2.070"],["64113.00","0.399"],["64113.30","2.110"],["64120.50","0.104"],["64120.60","2.068"],["64126.30","0.013"],["64126.50","0.325"],["64127.30","0.042"],["64130.40","0.122"],["64133.00","0.094"],["64139.30","0.150"],["64266.70","0.000"],["64286.80","4.241"],["64365.80","0.027"],["64384.10","0.911"],["64632.70","0.000"],["64634.30","0.053"],["64702.30","0.000"],["64720.60","0.925"],["64798.30","1.455"],["64798.90","1.834"],["64901.70","0.000"],["64903.40","0.058"]],"b":[["13559.90","0.854"],["13661.60","0.308"],["13759.90","0.518"],["13761.60","0.308"],["13859.90","0.644"],["13961.60","0.308"],["57655.40","0.002"],["60840.70","0.038"],["63050.00","12.680"],["63280.90","0.782"],["63310.40","0.554"],["63312.60","0.938"],["63361.70","0.705"],["63402.20","0.005"],["63421.00","0.002"],["63451.40","1.787"],["63788.10","0.100"],["63931.10","0.001"],["63943.70","0.000"],["63960.70","0.482"],["63969.50","0.000"],["63982.90","0.000"],["63985.70","10.150"],["63998.90","0.000"],["63999.30","0.854"],["64001.10","1.276"],["64003.50","0.064"],["64007.30","0.210"],["64008.40","0.105"],["64011.80","0.000"],["64018.80","0.024"],["64019.10","2.561"],["64021.10","0.000"],["64021.90","0.025"],["64029.50","0.034"],["64032.00","1.635"],["64036.60","0.736"],["64037.00","0.001"],["64044.90","0.049"],["64050.70","0.000"],["64053.30","0.374"],["64053.50","0.171"],["64055.30","0.000"],["64056.50","3.591"],["64057.10","2.006"],["64058.60","0.315"],["64059.50","0.017"],["64059.90","1.179"],["64060.50","0.001"],["64060.70","1.000"],["64061.00","0.022"],["64061.10","0.546"],["64061.40","0.019"],["64061.50","0.100"],["64061.60","23.642"]],"e":"depthUpdate","ps":"BTCUSDT","pu":11165394127032,"s":"BTCUSDT","st":1,"u":11165394141206}
{"E":1785353518922,"T":1785353518921,"U":11165394141463,"a":[["64065.20","0.002"],["64067.50","0.005"],["64069.70","0.087"],["64070.30","0.017"],["64071.40","0.003"],["64071.90","0.091"],["64073.10","0.087"],["64073.70","0.002"],["64073.90","0.546"],["64074.70","0.314"],["64077.60","0.007"],["64079.20","0.002"],["64080.60","0.117"],["64108.90","4.578"],["64109.00","2.068"],["64109.30","10.103"],["64110.90","0.420"],["64113.30","0.110"],["64119.90","0.608"],["64146.10","0.003"],["64147.50","0.001"],["64163.50","1.184"],["64165.10","0.071"],["64195.70","2.123"],["64197.70","0.000"],["64199.70","0.001"],["64201.70","0.000"],["64201.90","0.501"],["64203.70","0.023"],["64205.70","0.001"],["64207.70","0.000"],["64209.70","0.000"],["64211.70","0.000"],["64213.70","9.856"],["64215.70","0.019"],["64217.70","0.491"],["64219.70","0.000"],["64227.90","0.000"],["64253.90","0.080"],["64263.50","0.000"],["64266.70","0.000"],["64285.20","1.324"],["64317.80","0.383"],["64702.30","0.002"],["64958.50","27.977"],["64960.90","1.540"],["64990.50","12.652"],["67905.30","0.038"]],"b":[["1000.00","37.592"],["13559.90","0.728"],["13661.60","0.434"],["13755.10","0.000"],["13756.20","0.000"],["13759.90","0.434"],["13761.60","0.420"],["13859.90","0.532"],["13961.60","0.434"],["51249.30","0.000"],["57655.40","0.002"],["61499.10","0.003"],["62600.00","29.866"],["63421.00","0.002"],["63931.20","2.340"],["63945.40","1.719"],["63954.10","22.314"],["63954.60","4.806"],["63987.20","2.940"],["64007.30","0.000"],["64007.80","0.300"],["64008.50","0.003"],["64008.70","1.567"],["64010.30","0.567"],["64012.40","0.394"],["64014.70","0.000"],["64020.50","0.026"],["64035.80","0.002"],["64048.10","0.024"],["64049.90","0.376"],["64051.50","0.422"],["64051.60","0.552"],["64052.60","0.022"],["64053.40","0.668"],["64053.50","0.001"],["64054.80","0.002"],["64056.30","0.612"],["64059.90","0.529"],["64060.70","0.981"],["64060.90","1.334"],["64061.00","0.022"],["64061.10","0.000"],["64061.60","23.125"]],"e":"depthUpdate","ps":"BTCUSDT","pu":11165394141206,"s":"BTCUSDT","st":1,"u":11165394156261}
{"E":1785353519024,"T":1785353519023,"U":11165394156429,"a":[["64061.70","0.000"],["64061.80","0.000"],["64061.90","0.000"],["64062.00","0.000"],["64062.10","0.000"],["64062.40","0.000"],["64062.50","0.000"],["64062.90","0.000"],["64063.10","0.000"],["64063.20","0.000"],["64063.30","0.000"],["64063.50","0.000"],["64063.60","0.000"],["64064.00","0.000"],["64064.20","0.000"],["64064.30","0.000"],["64064.40","0.000"],["64064.60","0.000"],["64064.80","0.000"],["64064.90","0.000"],["64065.00","0.000"],["64065.10","0.000"],["64065.20","0.000"],["64065.30","0.000"],["64065.40","0.000"],["64065.50","0.400"],["64065.60","0.002"],["64065.80","0.000"],["64066.00","0.003"],["64066.10","0.000"],["64066.20","0.001"],["64066.40","0.015"],["64066.90","0.022"],["64067.00","0.000"],["64067.20","0.011"],["64067.30","0.000"],["64067.70","0.000"],["64067.80","0.005"],["64067.90","0.000"],["64068.00","0.007"],["64068.10","0.016"],["64068.20","0.027"],["64068.30","0.001"],["64068.80","0.025"],["64068.90","0.003"],["64069.10","0.007"],["64069.20","0.002"],["64069.40","0.158"],["64069.70","0.007"],["64070.00","0.058"],["64070.10","0.003"],["64070.20","0.002"],["64070.30","0.001"],["64070.50","0.007"],["64070.70","0.000"],["64070.80","0.010"],["64070.90","0.003"],["64071.00","0.001"],["64071.10","0.001"],["64071.20","0.094"],["64071.30","0.002"],["64071.40","0.003"],["64071.50","0.107"],["64071.70","0.002"],["64071.80","0.002"],["64071.90","0.092"],["64072.00","0.017"],["64072.10","0.389"],["64072.20","2.006"],["64072.30","0.012"],["64072.40","0.001"],["64072.60","0.100"],["64072.70","0.247"],["64072.90","0.328"],["64073.00","0.171"],["64073.10","0.007"],["64073.30","0.160"],["64073.40","0.451"],["64073.50","0.151"],["64073.60","0.480"],["64073.90","0.000"],["64074.00","0.161"],["64074.50","0.005"],["64074.60","10.150"],["64074.70","0.329"],["64074.80","0.010"],["64075.20","0.002"],["64075.30","0.547"],["64075.40","0.554"],["64075.50","0.003"],["64075.60","0.183"],["64075.70","0.002"],["64076.00","0.008"],["64076.10","0.001"],["64076.20","0.049"],["64076.30","2.565"],["64076.50","0.013"],["64076.60","0.164"],["64076.70","0.006"],["64076.90","0.129"],["64077.20","0.000"],["64077.30","0.002"],["64077.50","0.230"],["64077.70","0.001"],["64077.80","0.481"],["64077.90","0.138"],["64078.40","0.015"],["64078.50","0.140"],["64078.60","0.158"],["64078.70","1.001"],["64078.80","0.314"],["64079.20","0.002"],["64079.30","0.000"],["64079.40","0.029"],["64079.70","0.106"],["64079.90","0.492"],["64080.00","1.168"],["64080.30","0.003"],["64080.50","0.001"],["64080.60","0.000"],["64080.70","0.022"],["64080.90","0.001"],["64081.00","0.015"],["64081.10","0.007"],["64081.20","0.007"],["64081.50","0.033"],["64081.60","0.102"],["64081.80","0.000"],["64082.30","0.501"],["64082.60","0.020"],["64082.80","0.013"],["64083.00","0.014"],["64083.20","0.022"],["64083.60","0.003"],["64083.70","0.002"],["64083.80","0.003"],["64083.90","0.117"],["64084.00","0.380"],["64084.10","0.373"],["64084.20","0.001"],["64084.30","0.261"],["64084.50","0.064"],["64084.60","0.001"],["64085.30","0.002"],["64085.40","0.144"],["64085.50","1.383"],["64085.70","0.626"],["64085.80","0.062"],["64085.90","0.378"],["64086.00","0.002"],["64086.30","0.296"],["64086.50","0.124"],["64087.10","0.002"],["64088.10","0.062"],["64088.20","0.000"],["64088.60","0.122"],["64088.70","0.377"],["64088.80","0.351"],["64089.20","0.007"],["64090.30","0.971"],["64090.50","0.014"],["64090.60","0.377"],["64090.80","0.002"],["64090.90","0.917"],["64091.00","0.105"],["64091.40","0.128"],["64091.60","2.357"],["64091.90","0.527"],["64092.00","0.587"],["64092.20","0.008"],["64092.30","0.000"],["64092.40","1.793"],["64092.70","0.049"],["64094.20","0.013"],["64094.40","2.353"],["64094.50","0.000"],["64094.60","0.001"],["64094.70","0.004"],["64095.10","0.002"],["64095.30","0.074"],["64096.00","1.080"],["64096.30","0.006"],["64096.40","0.175"],["64096.90","0.158"],["64097.00","1.221"],["64097.80","0.004"],["64098.00","0.006"],["64098.10","0.004"],["64098.20","0.001"],["64099.10","0.000"],["64099.70","0.011"],["64099.90","0.046"],["64100.10","0.391"],["64100.40","0.005"],["64100.70","0.001"],["64101.00","0.001"],["64101.20","0.011"],["64101.30","0.000"],["64101.60","0.002"],["64102.00","0.636"],["64102.20","0.012"],["64102.50","0.291"],["64104.50","1.250"],["64104.60","0.098"],["64104.80","0.343"],["64105.20","0.023"],["64105.30","1.060"],["64105.90","0.073"],["64106.20","0.002"],["64106.40","0.591"],["64107.90","0.001"],["64108.60","0.708"],["64108.70","0.003"],["64108.90","4.576"],["64109.20","0.001"],["64109.30","0.003"],["64109.50","1.523"],["64109.90","0.001"],["64110.60","1.985"],["64111.60","0.001"],["64111.90","0.000"],["64112.90","0.001"],["64113.00","0.224"],["64113.30","0.110"],["64113.60","2.599"],["64113.80","0.190"],["64114.40","10.505"],["64114.50","0.001"],["64114.80","0.101"],["64115.30","0.000"],["64115.70","2.485"],["64116.60","0.100"],["64119.30","0.005"],["64121.30","0.024"],["64122.70","0.023"],["64122.80","0.554"],["64123.30","0.000"],["64123.80","0.023"],["64125.70","0.510"],["64126.90","0.391"],["64128.10","0.657"],["64129.80","0.213"],["64133.30","0.017"],["64136.80","0.046"],["64138.60","0.014"],["64141.50","0.313"],["64149.30","0.503"],["64162.10","0.532"],["64164.10","0.011"],["64165.00","0.078"],["64165.30","0.496"],["64165.40","0.094"],["64165.70","0.001"],["64167.30","0.375"],["64167.60","0.212"],["64168.60","0.003"],["64174.90","0.507"],["64188.20","0.000"],["64188.60","0.002"],["64192.00","0.860"],["64193.60","0.883"],["64195.60","0.880"],["64197.60","1.702"],["64198.00","0.001"],["64199.60","0.880"],["64199.70","0.501"],["64200.00","2.646"],["64201.60","0.881"],["64203.60","0.880"],["64203.70","0.023"],["64205.60","1.035"],["64205.70","0.001"],["64207.60","0.900"],["64207.70","0.000"],["64209.60","0.880"],["64209.70","0.000"],["64211.60","0.880"],["64211.70","0.000"],["64212.70","0.000"],["64213.60","1.188"],["64213.70","9.856"],["64215.70","0.019"],["64216.00","0.005"],["64217.60","0.904"],["64217.70","0.491"],["64219.60","0.880"],["64219.70","0.000"],["64224.00","0.024"],["64226.70","0.000"],["64232.50","0.158"],["64233.90","0.103"],["64243.20","0.371"],["64263.50","0.117"],["64293.30","0.038"],["64321.10","0.383"],["64383.40","0.301"],["64385.20","0.299"],["64490.10","9.570"],["64510.10","0.126"],["64554.10","6.028"],["64576.10","0.031"],["64644.40","0.000"],["64644.60","0.000"],["64702.30","0.000"],["64703.20","0.002"],["64703.50","0.000"],["64704.20","0.015"],["64705.50","0.000"],["64798.80","4.622"],["64799.80","6.418"],["64799.90","6.768"],["64800.60","3.668"],["64826.00","0.003"],["64832.00","1.596"],["64832.10","3.055"],["64862.40","1.596"],["64862.90","4.690"],["64863.80","2.513"],["64863.90","1.679"],["64864.60","2.292"],["64959.10","0.005"],["64959.90","0.000"],["64960.00","3.410"],["64988.90","0.115"],["64991.30","1.066"],["64992.10","1.067"],["64992.20","2.291"],["65055.20","0.000"],["65087.40","1.832"]],"b":[["1000.00","37.592"],["13559.90","0.616"],["13561.60","0.056"],["13563.00","0.014"],["13564.80","0.014"],["13661.60","0.378"],["13754.90","0.000"],["13761.60","0.518"],["13763.50","0.014"],["13765.40","0.014"],["13859.90","0.406"],["13961.60","0.518"],["13962.10","0.014"],["13963.50","0.014"],["51249.00","0.005"],["57655.40","0.000"],["57657.10","0.177"],["61499.10","0.006"],["63054.90","0.000"],["63063.50","0.012"],["63063.90","0.150"],["63182.30","0.710"],["63299.30","0.142"],["63421.00","0.002"],["63422.20","0.005"],["63422.90","0.003"],["63423.30","0.000"],["63424.20","0.002"],["63543.80","0.000"],["63550.30","0.001"],["63616.90","0.002"],["63648.00","0.005"],["63674.40","0.000"],["63681.00","0.002"],["63721.60","0.000"],["63730.70","0.000"],["63735.90","0.000"],["63741.30","0.010"],["63742.50","0.001"],["63744.10","0.027"],["63765.00","0.033"],["63805.40","0.000"],["63806.40","0.009"],["63807.20","0.151"],["63860.10","0.000"],["63864.00","0.000"],["63866.40","0.001"],["63870.60","0.017"],["63872.10","0.000"],["63881.50","0.010"],["63882.00","0.003"],["63892.10","0.117"],["63898.40","1.294"],["63906.40","0.391"],["63910.30","0.274"],["63926.40","0.001"],["63928.10","0.001"],["63930.80","0.061"],["63931.80","0.936"],["63934.70","0.001"],["63940.30","3.539"],["63944.20","0.000"],["63944.30","0.001"],["63945.70","0.005"],["63946.10","3.238"],["63951.70","0.013"],["63953.60","0.161"],["63954.10","0.000"],["63956.40","2.341"],["63960.10","0.001"],["63963.80","0.483"],["63965.20","0.502"],["63974.60","0.011"],["63975.30","0.168"],["63975.60","0.001"],["63975.70","0.132"],["63978.10","0.006"],["63979.80","0.004"],["63983.00","0.003"],["63983.30","0.000"],["63990.40","0.003"],["63990.50","1.017"],["63992.10","2.344"],["63993.30","0.204"],["63995.40","0.002"],["63996.60","0.001"],["63996.80","0.065"],["63998.10","0.003"],["63998.70","0.005"],["63998.80","0.547"],["64000.90","0.005"],["64001.10","1.251"],["64003.30","2.044"],["64003.50","0.002"],["64004.60","0.153"],["64004.90","0.015"],["64006.20","0.391"],["64007.80","0.090"],["64008.50","0.007"],["64008.70","1.067"],["64009.20","0.000"],["64009.40","0.549"],["64010.30","0.518"],["64010.60","0.025"],["64010.80","2.340"],["64011.10","0.000"],["64011.90","0.001"],["64012.10","0.021"],["64012.50","0.002"],["64012.70","0.005"],["64012.90","0.001"],["64013.10","0.002"],["64013.30","0.184"],["64013.50","0.160"],["64013.60","0.009"],["64014.00","0.001"],["64014.20","0.002"],["64015.00","0.534"],["64015.20","0.947"],["64015.60","0.001"],["64015.70","0.004"],["64015.80","0.011"],["64016.10","0.000"],["64016.20","0.500"],["64017.50","0.009"],["64017.80","0.470"],["64018.20","0.002"],["64018.40","0.000"],["64018.50","0.001"],["64019.10","2.401"],["64019.20","0.061"],["64020.70","0.004"],["64021.20","0.000"],["64021.50","0.034"],["64022.60","1.251"],["64022.80","0.007"],["64022.90","0.210"],["64023.10","0.094"],["64023.30","0.244"],["64023.90","0.299"],["64024.60","0.000"],["64024.90","0.004"],["64025.00","0.000"],["64025.90","0.005"],["64026.20","0.000"],["64026.40","0.001"],["64026.90","0.041"],["64027.40","0.006"],["64028.40","1.811"],["64028.80","0.036"],["64029.00","1.077"],["64029.10","1.254"],["64029.20","0.000"],["64029.60","0.006"],["64031.30","0.011"],["64031.40","0.082"],["64031.50","0.007"],["64032.00","1.555"],["64033.10","2.405"],["64033.50","0.679"],["64033.70","0.134"],["64033.80","0.002"],["64034.00","1.076"],["64034.30","0.091"],["64034.60","0.000"],["64035.40","0.314"],["64035.70","0.000"],["64035.80","0.023"],["64036.40","0.018"],["64036.70","0.000"],["64036.80","0.002"],["64036.90","0.015"],["64037.50","0.571"],["64037.80","0.312"],["64037.90","0.007"],["64038.00","0.002"],["64038.80","0.012"],["64038.90","0.001"],["64039.20","0.065"],["64039.30","0.935"],["64039.50","0.148"],["64040.10","0.018"],["64040.30","0.003"],["64040.80","0.010"],["64041.00","0.312"],["64041.10","0.831"],["64041.20","0.016"],["64041.50","0.002"],["64041.80","0.867"],["64042.00","0.003"],["64042.40","0.374"],["64042.50","2.361"],["64042.60","0.004"],["64042.70","1.251"],["64043.00","0.001"],["64043.20","0.540"],["64043.50","0.008"],["64043.60","0.001"],["64044.00","0.008"],["64044.80","0.706"],["64045.10","0.000"],["64045.30","2.499"],["64045.70","0.436"],["64046.50","0.396"],["64047.00","0.313"],["64047.50","0.035"],["64047.60","0.293"],["64047.80","0.002"],["64048.10","0.004"],["64048.60","0.871"],["64049.20","1.408"],["64049.30","0.042"],["64049.50","0.264"],["64050.10","0.017"],["64050.20","0.120"],["64050.40","0.002"],["64050.60","0.000"],["64051.40","0.260"],["64051.50","0.252"],["64051.90","0.235"],["64052.00","0.002"],["64052.30","0.017"],["64052.50","1.833"],["64052.60","0.003"],["64052.70","0.001"],["64052.90","0.222"],["64053.20","0.314"],["64053.40","0.669"],["64053.60","0.003"],["64053.90","0.032"],["64054.20","0.315"],["64054.30","0.000"],["64054.50","0.001"],["64054.60","0.000"],["64055.00","0.006"],["64055.20","0.003"],["64055.40","0.050"],["64055.50","0.294"],["64055.70","0.000"],["64055.80","0.002"],["64056.40","0.000"],["64056.50","3.591"],["64056.90","0.002"],["64057.10","0.027"],["64057.40","0.000"],["64057.50","0.062"],["64057.80","0.002"],["64058.10","0.006"],["64058.30","0.004"],["64058.50","0.000"],["64058.60","0.315"],["64058.80","0.249"],["64058.90","0.018"],["64059.00","0.001"],["64059.10","0.015"],["64059.20","0.002"],["64059.30","0.000"],["64059.40","0.000"],["64059.50","0.065"],["64059.80","0.315"],["64059.90","0.792"],["64060.00","0.004"],["64060.10","0.002"],["64060.30","0.001"],["64060.60","2.344"],["64060.70","1.797"],["64060.80","2.506"],["64060.90","0.068"],["64061.00","0.022"],["64061.20","0.001"],["64061.40","0.001"],["64061.50","0.003"],["64061.60","3.532"],["64061.70","13.785"],["64061.80","0.001"],["64061.90","0.159"],["64062.00","0.237"],["64062.10","0.995"],["64062.20","0.001"],["64062.30","0.277"],["64062.40","0.001"],["64062.50","0.401"],["64062.60","0.144"],["64062.70","0.002"],["64062.80","1.059"],["64062.90","0.023"],["64063.00","4.761"],["64063.10","1.695"],["64063.20","0.570"],["64063.30","0.001"],["64063.40","3.572"],["64063.50","11.548"],["64063.60","2.502"],["64063.80","0.022"],["64063.90","3.911"],["64064.00","0.010"],["64064.10","1.498"],["64064.20","0.939"],["64064.50","1.117"],["64064.70","0.420"],["64064.80","5.608"],["64064.90","1.231"],["64065.20","0.000"],["64065.30","1.999"],["64065.40","27.334"]],"e":"depthUpdate","ps":"BTCUSDT","pu":11165394156261,"s":"BTCUSDT","st":1,"u":11165394181031}
{"E":1785353519126,"T":1785353519125,"U":11165394181034,"a":[["64065.50","0.000"],["64065.60","0.000"],["64065.70","0.000"],["64065.90","0.000"],["64066.00","0.000"],["64066.20","0.000"],["64066.40","0.000"],["64066.60","0.000"],["64066.80","7.087"],["64066.90","0.004"],["64067.00","0.001"],["64067.20","0.007"],["64067.50","0.004"],["64067.70","0.000"],["64067.80","0.000"],["64068.00","0.001"],["64068.20","0.000"],["64068.30","0.000"],["64068.50","0.001"],["64068.70","0.001"],["64068.80","0.002"],["64068.90","0.003"],["64069.00","0.076"],["64069.20","0.001"],["64069.30","0.027"],["64069.40","0.166"],["64069.50","0.003"],["64069.60","0.001"],["64069.70","0.320"],["64070.00","0.008"],["64070.30","0.002"],["64070.40","0.051"],["64070.50","0.006"],["64070.60","0.120"],["64070.80","0.002"],["64071.20","0.001"],["64071.30","0.000"],["64071.50","0.001"],["64071.90","0.052"],["64072.00","0.023"],["64072.10","0.048"],["64072.20","0.000"],["64072.30","0.001"],["64072.60","0.001"],["64072.70","0.001"],["64072.80","0.023"],["64072.90","0.002"],["64073.00","0.003"],["64073.10","0.006"],["64073.20","0.015"],["64073.30","0.002"],["64073.40","0.055"],["64073.50","0.001"],["64073.60","0.006"],["64073.90","0.782"],["64074.00","0.592"],["64074.10","2.335"],["64074.20","0.313"],["64074.30","0.001"],["64074.40","0.001"],["64074.50","2.754"],["64074.70","0.016"],["64074.80","0.002"],["64074.90","0.254"],["64075.10","0.182"],["64075.30","0.547"],["64075.70","0.000"],["64075.90","0.609"],["64076.00","1.008"],["64076.50","0.251"],["64076.80","0.007"],["64076.90","0.145"],["64077.00","1.181"],["64077.30","0.020"],["64077.50","0.107"],["64077.60","0.005"],["64077.80","0.470"],["64078.10","0.257"],["64078.20","0.000"],["64078.40","0.170"],["64078.50","0.100"],["64078.60","0.160"],["64078.70","0.139"],["64078.80","1.563"],["64078.90","1.063"],["64079.30","0.001"],["64079.40","0.030"],["64079.50","0.382"],["64079.70","0.267"],["64079.80","2.344"],["64080.00","0.513"],["64080.10","1.247"],["64080.20","0.010"],["64080.50","0.068"],["64080.80","0.043"],["64080.90","0.002"],["64081.10","0.000"],["64081.20","0.018"],["64081.30","0.003"],["64081.40","0.001"],["64081.50","0.034"],["64081.60","0.102"],["64082.00","0.012"],["64082.20","0.222"],["64082.30","0.628"],["64082.50","0.002"],["64082.60","0.013"],["64082.80","0.014"],["64082.90","0.501"],["64083.00","0.003"],["64083.10","0.000"],["64083.20","0.022"],["64083.40","0.619"],["64083.60","0.006"],["64083.90","0.123"],["64084.00","0.514"],["64084.10","0.340"],["64084.20","0.008"],["64084.30","0.101"],["64084.40","0.562"],["64084.60","0.021"],["64085.50","1.343"],["64085.70","0.325"],["64085.90","0.338"],["64086.00","0.066"],["64086.50","0.009"],["64086.60","0.419"],["64087.30","0.986"],["64087.90","0.002"],["64088.20","0.040"],["64088.30","0.040"],["64088.50","0.010"],["64088.70","0.377"],["64088.80","0.344"],["64089.10","0.168"],["64089.20","0.087"],["64089.30","0.641"],["64089.60","1.706"],["64090.10","0.020"],["64090.60","0.376"],["64090.70","0.010"],["64090.80","0.002"],["64090.90","0.913"],["64091.10","0.013"],["64091.20","0.012"],["64091.40","0.285"],["64091.50","0.684"],["64091.60","2.346"],["64091.90","0.563"],["64092.00","0.603"],["64092.40","2.922"],["64092.50","0.313"],["64092.60","0.560"],["64092.80","0.205"],["64092.90","0.004"],["64093.00","0.035"],["64093.20","0.007"],["64093.30","0.001"],["64093.60","0.003"],["64093.80","0.001"],["64093.90","1.445"],["64094.00","2.587"],["64094.10","0.000"],["64094.40","2.346"],["64094.70","0.004"],["64094.80","0.002"],["64095.00","0.001"],["64095.20","0.004"],["64095.50","0.123"],["64095.60","0.690"],["64095.70","0.033"],["64095.80","0.002"],["64096.30","0.001"],["64096.40","0.122"],["64096.70","0.011"],["64096.80","0.079"],["64097.20","5.897"],["64097.40","0.003"],["64098.00","0.506"],["64098.40","0.001"],["64098.60","0.006"],["64098.80","0.053"],["64098.90","2.759"],["64099.00","0.008"],["64099.10","0.005"],["64099.30","0.005"],["64099.50","0.028"],["64099.70","0.000"],["64099.90","0.019"],["64100.40","0.001"],["64100.90","0.048"],["64101.10","0.059"],["64102.00","0.722"],["64102.20","0.006"],["64102.50","0.298"],["64102.60","1.575"],["64102.70","0.004"],["64103.10","0.002"],["64103.50","1.491"],["64103.70","0.064"],["64103.80","0.002"],["64104.00","0.021"],["64104.20","0.021"],["64104.30","0.003"],["64104.40","2.340"],["64104.60","0.004"],["64104.90","0.021"],["64105.00","0.007"],["64105.10","0.001"],["64105.20","0.032"],["64105.30","1.460"],["64105.50","0.001"],["64105.60","0.005"],["64106.30","0.755"],["64106.40","0.624"],["64106.70","0.001"],["64106.80","0.077"],["64107.00","0.145"],["64107.10","0.079"],["64107.50","0.374"],["64107.70","2.347"],["64107.80","0.094"],["64107.90","0.013"],["64108.40","0.144"],["64108.60","0.708"],["64108.90","4.578"],["64109.10","0.019"],["64109.50","1.472"],["64110.00","0.034"],["64110.10","12.700"],["64110.50","0.063"],["64110.60","1.983"],["64110.90","0.421"],["64111.30","0.007"],["64111.40","0.004"],["64111.50","0.315"],["64111.60","0.002"],["64111.70","1.252"],["64112.00","0.048"],["64112.10","0.027"],["64112.40","1.054"],["64112.50","0.005"],["64113.00","0.008"],["64113.10","0.610"],["64113.20","0.032"],["64113.30","0.110"],["64113.70","0.000"],["64113.80","0.022"],["64113.90","0.001"],["64114.00","0.068"],["64114.20","0.510"],["64114.40","0.505"],["64114.90","0.502"],["64115.40","0.171"],["64115.60","0.013"],["64115.70","2.487"],["64115.80","0.001"],["64116.40","0.049"],["64117.60","0.042"],["64118.00","0.002"],["64118.10","0.001"],["64118.40","1.172"],["64118.50","0.025"],["64118.60","0.004"],["64119.10","0.379"],["64119.40","0.180"],["64120.40","0.509"],["64120.50","0.100"],["64120.70","1.650"],["64120.80","1.001"],["64121.10","0.247"],["64121.30","0.000"],["64122.40","0.004"],["64124.10","0.001"],["64124.50","0.005"],["64125.00","0.524"],["64127.00","0.094"],["64127.30","0.011"],["64128.80","1.583"],["64129.60","0.001"],["64130.90","1.625"],["64131.70","0.000"],["64132.30","2.537"],["64132.80","0.005"],["64133.50","0.000"],["64134.30","0.497"],["64134.70","0.608"],["64134.90","0.016"],["64137.10","0.176"],["64137.40","0.482"],["64137.60","0.002"],["64137.70","0.000"],["64137.80","1.381"],["64138.00","0.002"],["64138.20","0.000"],["64138.30","0.000"],["64138.50","0.211"],["64139.40","0.346"],["64139.50","0.087"],["64139.80","0.000"],["64140.10","0.005"],["64140.50","0.590"],["64141.40","0.000"],["64142.70","0.006"],["64143.70","0.216"],["64144.00","0.003"],["64144.30","3.820"],["64145.30","0.000"],["64146.00","0.068"],["64149.60","2.345"],["64151.00","0.094"],["64151.10","0.785"],["64152.80","0.000"],["64152.90","1.106"],["64154.00","4.412"],["64154.10","22.924"],["64154.50","0.200"],["64154.80","0.001"],["64154.90","0.121"],["64157.50","0.007"],["64159.10","0.497"],["64161.00","0.035"],["64161.60","0.000"],["64162.10","0.524"],["64163.50","0.835"],["64164.10","0.020"],["64165.20","3.122"],["64165.70","0.017"],["64169.60","2.169"],["64170.50","2.000"],["64183.00","0.005"],["64192.00","0.022"],["64193.60","0.003"],["64195.60","0.000"],["64197.60","0.822"],["64197.70","0.244"],["64199.60","0.000"],["64201.00","0.161"],["64201.60","0.001"],["64203.60","0.000"],["64205.60","0.677"],["64207.60","0.020"],["64209.60","0.000"],["64211.60","0.000"],["64213.60","0.001"],["64215.60","0.000"],["64217.60","0.024"],["64219.60","0.000"],["64220.90","0.764"],["64221.60","0.000"],["64223.80","1.934"],["64223.90","0.001"],["64225.80","0.221"],["64228.60","0.308"],["64240.00","2.337"],["64241.80","0.120"],["64241.90","5.620"],["64242.80","0.006"],["64246.00","0.001"],["64265.20","0.000"],["64266.70","0.117"],["64285.20","0.779"],["64286.80","0.003"],["64292.00","0.000"],["64294.40","0.013"],["64309.90","0.019"],["64335.80","0.540"],["64335.90","0.651"],["64362.00","0.151"],["64380.30","0.155"],["64384.00","0.575"],["64387.20","0.001"],["64397.40","0.000"],["64426.60","0.047"],["64426.70","0.242"],["64686.20","0.116"],["64686.30","0.057"],["64703.20","0.000"],["64703.70","0.000"],["64704.20","0.015"],["64706.20","0.004"],["64707.50","0.164"],["64739.50","2.263"],["64798.80","0.037"],["64798.90","0.000"],["64799.50","0.313"],["64799.80","0.000"],["64799.90","4.323"],["64800.60","0.000"],["64801.70","0.000"],["64802.60","0.778"],["64802.70","0.771"],["64804.20","13.228"],["64824.20","0.496"],["64831.90","0.458"],["64832.10","4.582"],["64833.10","1.533"],["64834.00","2.482"],["64835.40","1.527"],["64835.60","1.529"],["64862.90","0.112"],["64863.80","1.750"],["64863.90","0.916"],["64864.60","0.003"],["64865.00","0.393"],["64866.70","0.000"],["64866.80","0.000"],["64867.60","2.259"],["64868.30","8.393"],["64927.50","0.008"],["64927.80","0.002"],["64927.90","0.000"],["64960.00","0.209"],["64963.30","5.334"],["64963.50","2.286"],["64963.70","2.286"],["64995.40","2.102"],["64995.60","2.143"],["65024.00","0.184"],["65027.80","0.000"],["65056.00","0.056"],["65059.60","1.065"],["65059.80","3.212"],["65088.00","2.300"],["65091.70","1.065"],["65123.50","1.064"],["65322.60","0.126"],["65348.10","0.007"],["67267.20","0.004"]],"b":[["13559.90","0.490"],["13566.70","0.126"],["13661.60","0.252"],["13766.70","0.112"],["13859.90","0.294"],["13965.40","0.014"],["13966.70","0.112"],["51249.00","0.001"],["57657.10","0.175"],["57660.00","0.313"],["61499.10","0.003"],["63064.80","0.005"],["63067.00","15.239"],["63163.10","44.669"],["63299.20","0.955"],["63422.90","0.001"],["63424.70","0.003"],["63426.00","0.001"],["63610.40","0.000"],["63648.00","0.004"],["63719.50","0.000"],["63739.60","0.235"],["63746.30","0.001"],["63792.50","0.002"],["63802.60","0.001"],["63807.20","0.005"],["63809.10","0.003"],["63846.40","2.001"],["63849.20","1.517"],["63861.20","0.000"],["63863.80","0.002"],["63864.20","0.000"],["63864.40","0.001"],["63864.50","0.000"],["63865.70","0.026"],["63866.00","0.478"],["63868.00","0.337"],["63868.70","0.000"],["63870.50","0.388"],["63871.30","0.120"],["63871.90","0.783"],["63876.90","2.768"],["63878.20","0.063"],["63878.30","0.892"],["63878.80","0.070"],["63885.40","0.017"],["63886.40","0.357"],["63892.50","0.000"],["63893.90","0.000"],["63895.70","15.980"],["63896.80","0.012"],["63897.10","0.001"],["63898.10","4.173"],["63900.00","9.323"],["63900.10","0.000"],["63900.30","3.328"],["63905.80","0.072"],["63910.40","1.306"],["63915.60","0.000"],["63916.70","0.881"],["63918.70","0.880"],["63920.70","0.880"],["63922.70","0.880"],["63924.70","0.880"],["63926.70","0.880"],["63928.40","0.064"],["63931.90","0.805"],["63932.40","0.000"],["63941.50","0.005"],["63943.00","0.044"],["63945.00","0.591"],["63945.60","0.379"],["63946.60","0.003"],["63947.00","0.000"],["63947.20","0.000"],["63947.60","0.000"],["63949.60","0.013"],["63950.50","0.000"],["63954.40","0.001"],["63954.60","1.694"],["63956.30","0.006"],["63957.20","2.076"],["63958.10","4.417"],["63961.60","0.950"],["63961.70","0.000"],["63963.30","0.378"],["63963.70","0.023"],["63964.90","0.000"],["63968.00","0.506"],["63968.70","2.999"],["63969.30","0.042"],["63969.80","0.246"],["63970.90","0.006"],["63974.00","0.000"],["63974.20","0.017"],["63974.80","0.002"],["63975.10","0.026"],["63975.40","0.000"],["63975.70","0.100"],["63976.10","0.000"],["63976.60","0.000"],["63977.00","0.621"],["63980.00","0.078"],["63981.60","2.352"],["63981.70","0.098"],["63982.00","0.497"],["63982.60","0.002"],["63984.00","0.016"],["63985.90","0.006"],["63987.10","22.408"],["63989.20","0.000"],["63989.40","0.003"],["63989.60","0.004"],["63989.70","8.662"],["63989.90","0.201"],["63990.00","0.001"],["63992.60","0.001"],["63992.70","0.000"],["63992.90","0.009"],["63993.30","0.144"],["63994.90","0.062"],["63996.90","0.000"],["63998.00","0.001"],["63999.30","0.613"],["63999.40","0.000"],["63999.50","0.031"],["64000.80","1.501"],["64000.90","0.001"],["64001.30","0.315"],["64002.20","0.001"],["64002.60","0.635"],["64002.70","2.442"],["64003.30","2.040"],["64004.60","0.001"],["64005.10","0.000"],["64005.40","2.436"],["64005.50","0.000"],["64005.60","0.063"],["64005.70","0.003"],["64007.20","0.514"],["64008.10","0.211"],["64008.50","0.003"],["64008.80","0.035"],["64009.80","0.067"],["64010.30","0.542"],["64010.60","0.000"],["64011.90","0.002"],["64012.10","0.280"],["64012.40","0.369"],["64012.70","0.001"],["64012.80","0.061"],["64013.00","0.004"],["64013.10","0.002"],["64013.50","0.081"],["64013.60","0.001"],["64015.80","0.010"],["64016.70","0.062"],["64016.80","0.287"],["64017.50","0.083"],["64019.70","0.000"],["64020.00","0.015"],["64020.20","0.053"],["64020.40","0.001"],["64020.70","0.000"],["64020.80","0.527"],["64021.30","0.002"],["64021.50","0.059"],["64021.80","0.026"],["64021.90","0.003"],["64022.90","0.000"],["64024.40","0.360"],["64024.90","0.001"],["64025.20","0.526"],["64025.30","0.083"],["64025.40","0.005"],["64025.60","1.171"],["64025.90","0.004"],["64026.20","0.010"],["64027.00","0.019"],["64027.10","0.049"],["64028.30","2.343"],["64028.40","1.807"],["64030.00","1.740"],["64030.30","0.002"],["64030.70","0.092"],["64030.80","0.233"],["64030.90","0.000"],["64031.30","0.002"],["64031.70","0.135"],["64031.90","0.003"],["64032.20","0.070"],["64032.70","0.000"],["64033.30","0.029"],["64033.60","0.005"],["64033.90","0.070"],["64034.10","0.022"],["64034.20","0.005"],["64034.30","0.001"],["64034.90","0.021"],["64035.20","1.968"],["64035.40","0.324"],["64035.50","0.001"],["64035.80","0.002"],["64036.00","0.002"],["64036.90","0.003"],["64037.10","0.003"],["64037.30","0.000"],["64037.40","1.300"],["64037.50","0.002"],["64037.70","0.252"],["64037.80","0.987"],["64038.50","0.014"],["64039.00","0.002"],["64039.30","0.000"],["64039.40","0.000"],["64040.10","0.040"],["64040.70","0.036"],["64040.80","1.097"],["64040.90","0.442"],["64041.10","0.873"],["64041.20","0.023"],["64041.30","0.522"],["64041.50","0.002"],["64041.90","0.981"],["64042.00","0.565"],["64042.20","0.004"],["64042.50","2.457"],["64042.60","0.613"],["64043.50","0.006"],["64043.60","0.002"],["64043.70","10.009"],["64044.20","0.002"],["64044.30","3.447"],["64044.40","1.457"],["64044.50","0.237"],["64044.60","0.004"],["64044.70","0.101"],["64044.90","0.218"],["64045.30","2.342"],["64045.60","0.004"],["64045.70","0.376"],["64045.80","0.002"],["64045.90","0.002"],["64046.00","0.001"],["64046.10","0.002"],["64046.30","0.000"],["64046.40","0.032"],["64046.50","0.395"],["64046.60","0.233"],["64046.70","0.000"],["64046.80","0.002"],["64046.90","0.004"],["64047.10","0.148"],["64047.20","0.005"],["64047.30","0.000"],["64047.50","0.003"],["64047.90","2.344"],["64048.00","1.168"],["64048.20","0.001"],["64048.40","0.005"],["64048.60","0.324"],["64048.70","0.057"],["64048.90","0.086"],["64049.00","0.002"],["64049.10","0.763"],["64049.20","1.667"],["64049.40","0.001"],["64049.50","0.263"],["64049.70","0.372"],["64049.80","0.611"],["64049.90","0.325"],["64050.30","0.000"],["64050.70","0.233"],["64050.90","0.469"],["64051.10","2.405"],["64051.20","1.129"],["64051.40","0.034"],["64051.50","0.250"],["64051.60","0.065"],["64052.30","0.216"],["64052.50","1.689"],["64052.90","0.000"],["64053.40","0.497"],["64053.50","0.021"],["64053.70","0.000"],["64053.80","0.002"],["64053.90","0.244"],["64054.00","0.003"],["64054.10","0.000"],["64054.80","0.338"],["64054.90","0.474"],["64055.00","0.004"],["64055.20","0.002"],["64055.40","0.071"],["64055.80","0.001"],["64056.00","0.005"],["64056.60","0.376"],["64056.90","0.002"],["64057.00","0.001"],["64057.10","0.006"],["64057.40","0.015"],["64057.50","0.003"],["64057.60","1.394"],["64057.70","0.000"],["64057.80","0.065"],["64058.10","0.007"],["64058.30","0.002"],["64058.40","0.223"],["64058.90","0.011"],["64059.00","0.000"],["64059.10","0.001"],["64059.50","0.050"],["64059.80","0.002"],["64059.90","0.350"],["64060.00","0.005"],["64060.10","0.182"],["64060.30","0.026"],["64060.50","0.023"],["64060.60","2.341"],["64060.70","1.482"],["64060.80","0.195"],["64060.90","0.005"],["64061.00","0.003"],["64061.30","0.000"],["64061.40","0.002"],["64061.50","0.003"],["64061.60","2.682"],["64061.70","3.596"],["64061.90","0.002"],["64062.00","0.024"],["64062.10","0.003"],["64062.20","0.002"],["64062.30","0.078"],["64062.40","0.001"],["64062.50","0.384"],["64062.70","0.003"],["64062.80","0.000"],["64062.90","0.001"],["64063.00","0.383"],["64063.10","0.001"],["64063.20","0.000"],["64063.30","0.003"],["64063.40","2.341"],["64063.50","1.293"],["64063.60","2.502"],["64063.70","2.620"],["64063.80","0.002"],["64063.90","0.029"],["64064.00","0.002"],["64064.10","0.001"],["64064.20","0.001"],["64064.30","0.000"],["64064.40","0.001"],["64064.50","0.432"],["64064.60","0.001"],["64064.70","0.000"],["64064.80","0.407"],["64064.90","0.002"],["64065.00","1.328"],["64065.20","0.003"],["64065.30","0.000"],["64065.40","0.808"],["64065.50","0.000"],["64065.60","0.000"],["64065.70","0.002"],["64065.80","0.000"],["64065.90","0.002"],["64066.00","0.001"],["64066.10","0.330"],["64066.20","0.000"],["64066.30","0.007"],["64066.40","0.002"],["64066.50","0.000"],["64066.60","0.081"],["64066.70","12.094"]],"e":"depthUpdate","ps":"BTCUSDT","pu":11165394181031,"s":"BTCUSDT","st":1,"u":11165394198135}
{"E":1785353519228,"T":1785353519227,"U":11165394198195,"a":[["64066.80","9.946"],["64066.90","0.006"],["64067.30","0.003"],["64068.50","0.024"],["64068.70","0.024"],["64068.90","0.003"],["64069.00","0.173"],["64069.10","0.007"],["64069.30","0.005"],["64069.40","0.479"],["64069.50","0.000"],["64070.10","0.386"],["64070.40","0.354"],["64070.80","0.857"],["64071.40","0.014"],["64071.90","0.052"],["64072.80","0.904"],["64073.20","0.093"],["64073.80","0.881"],["64074.00","0.590"],["64074.10","2.333"],["64074.40","0.999"],["64074.50","2.756"],["64074.80","0.000"],["64075.00","0.002"],["64075.10","0.171"],["64075.40","0.634"],["64075.60","0.171"],["64076.00","1.006"],["64076.10","0.060"],["64076.20","0.047"],["64076.50","0.252"],["64076.60","0.257"],["64077.00","1.287"],["64077.20","0.090"],["64077.30","0.018"],["64077.50","0.116"],["64077.60","0.088"],["64077.90","0.002"],["64078.10","0.425"],["64078.50","0.662"],["64078.60","0.816"],["64078.70","0.445"],["64078.90","0.284"],["64079.10","0.118"],["64079.70","1.202"],["64079.90","0.494"],["64080.00","0.341"],["64080.10","1.249"],["64081.20","0.007"],["64081.50","0.033"],["64082.00","0.081"],["64082.10","0.161"],["64082.20","0.379"],["64083.10","0.000"],["64083.40","0.539"],["64084.40","0.000"],["64085.40","0.179"],["64085.70","0.314"],["64086.30","0.309"],["64086.60","0.302"],["64087.00","0.398"],["64088.40","0.136"],["64089.50","10.063"],["64089.70","0.315"],["64090.50","0.003"],["64091.40","0.442"],["64092.70","0.060"],["64093.00","0.000"],["64093.40","1.148"],["64093.50","0.000"],["64093.60","0.001"],["64093.90","0.011"],["64094.40","2.344"],["64095.50","0.060"],["64096.40","0.006"],["64097.80","0.002"],["64098.60","0.005"],["64098.80","0.064"],["64098.90","0.759"],["64099.00","1.759"],["64099.50","0.001"],["64101.40","0.027"],["64102.00","0.644"],["64102.40","0.021"],["64102.50","0.287"],["64102.60","1.591"],["64103.00","0.005"],["64103.40","1.487"],["64103.50","0.005"],["64104.40","2.342"],["64104.70","0.095"],["64105.00","0.067"],["64105.10","0.107"],["64105.40","0.090"],["64105.70","0.086"],["64106.10","0.001"],["64106.70","0.002"],["64107.10","0.001"],["64107.30","0.003"],["64107.80","0.157"],["64107.90","0.014"],["64108.40","0.066"],["64108.70","0.108"],["64109.50","1.460"],["64109.80","0.005"],["64111.30","0.003"],["64112.30","0.004"],["64113.40","0.016"],["64114.00","0.008"],["64114.90","0.504"],["64115.50","0.025"],["64117.30","0.008"],["64118.10","0.008"],["64118.70","0.168"],["64118.90","0.559"],["64119.40","0.314"],["64119.50","0.156"],["64120.70","1.626"],["64120.80","0.026"],["64123.80","1.507"],["64123.90","0.054"],["64124.80","0.002"],["64128.00","0.025"],["64129.70","0.012"],["64129.80","0.215"],["64131.20","0.854"],["64132.60","0.011"],["64132.80","0.006"],["64142.60","0.248"],["64143.50","0.002"],["64143.70","0.228"],["64144.20","2.140"],["64144.30","2.336"],["64151.10","4.113"],["64151.90","22.913"],["64154.00","1.209"],["64154.10","0.011"],["64156.10","0.188"],["64160.00","0.668"],["64163.50","1.198"],["64165.10","0.079"],["64169.60","2.161"],["64172.80","1.017"],["64172.90","2.342"],["64174.20","0.002"],["64186.30","3.700"],["64188.80","0.633"],["64195.80","0.039"],["64234.50","10.643"],["64235.40","0.000"],["64240.00","2.165"],["64320.00","0.317"],["64400.00","11.967"],["64634.30","0.022"],["64639.50","0.038"],["64707.50","0.162"],["64750.20","0.322"],["64789.90","0.567"],["64816.40","0.539"],["64903.40","0.027"],["64908.60","0.031"],["64995.80","1.076"],["65322.60","0.123"],["65348.10","0.010"]],"b":[["1000.00","37.592"],["13559.90","0.378"],["13566.70","0.238"],["13661.60","0.140"],["13766.70","0.238"],["13859.90","0.168"],["13966.70","0.224"],["57660.00","0.313"],["61497.50","0.696"],["61504.00","0.014"],["63163.10","47.041"],["63229.30","2.349"],["63265.90","0.784"],["63289.90","0.000"],["63293.80","0.033"],["63297.60","3.104"],["63299.20","0.008"],["63426.00","0.001"],["63526.80","0.003"],["63530.80","0.031"],["63598.80","0.001"],["63620.00","0.602"],["63680.00","3.769"],["63686.50","0.454"],["63688.80","0.008"],["63712.30","0.003"],["63721.50","0.022"],["63727.90","0.009"],["63760.00","0.308"],["63810.40","0.149"],["63829.70","0.107"],["63832.90","0.179"],["63834.00","0.000"],["63840.00","1.547"],["63846.50","0.002"],["63852.10","0.136"],["63862.40","3.673"],["63865.30","0.000"],["63871.30","0.003"],["63874.40","0.002"],["63880.70","0.012"],["63881.60","0.298"],["63897.60","2.674"],["63904.00","0.020"],["63909.00","0.010"],["63910.40","0.895"],["63912.30","1.181"],["63916.70","0.001"],["63918.70","0.000"],["63920.00","0.693"],["63920.70","0.000"],["63922.70","0.000"],["63923.40","0.000"],["63924.70","0.000"],["63926.70","0.000"],["63931.20","7.040"],["63931.90","1.404"],["63940.70","1.486"],["63940.80","0.001"],["63942.80","0.027"],["63945.20","3.267"],["63948.30","0.543"],["63958.10","1.200"],["63961.00","1.485"],["63961.10","0.006"],["63962.40","0.000"],["63963.90","0.597"],["63964.60","0.000"],["63984.00","0.015"],["63987.10","0.094"],["63990.20","2.640"],["63991.50","0.000"],["63995.90","0.062"],["63996.20","1.183"],["63996.50","0.049"],["63996.80","0.097"],["63998.10","0.018"],["64000.00","10.831"],["64001.50","0.214"],["64003.30","2.140"],["64004.90","0.000"],["64005.10","0.013"],["64005.60","1.817"],["64006.00","0.403"],["64008.10","0.001"],["64008.80","0.030"],["64013.40","2.854"],["64014.20","0.000"],["64016.30","0.098"],["64017.90","0.977"],["64020.50","0.116"],["64020.80","0.526"],["64022.40","0.009"],["64022.70","0.513"],["64023.30","0.243"],["64028.30","12.343"],["64028.40","3.158"],["64028.80","0.007"],["64029.60","0.002"],["64029.90","0.121"],["64030.70","0.002"],["64031.70","0.170"],["64031.90","0.005"],["64032.00","1.553"],["64032.30","0.022"],["64032.60","0.004"],["64034.10","0.001"],["64034.80","2.343"],["64036.60","0.616"],["64037.10","0.083"],["64037.30","0.070"],["64037.40","0.615"],["64037.80","1.358"],["64038.90","0.001"],["64039.00","0.002"],["64039.10","0.107"],["64039.90","0.468"],["64040.10","0.040"],["64040.60","0.047"],["64040.70","0.015"],["64040.80","2.032"],["64041.00","0.546"],["64041.10","0.882"],["64041.60","0.008"],["64041.90","0.981"],["64042.00","0.003"],["64042.80","0.047"],["64042.90","0.028"],["64043.70","0.007"],["64044.00","0.005"],["64044.30","1.884"],["64044.40","0.522"],["64044.70","0.080"],["64044.90","0.080"],["64045.10","0.057"],["64045.20","0.001"],["64045.40","0.001"],["64045.50","0.003"],["64046.00","0.121"],["64046.10","0.002"],["64046.40","0.368"],["64047.10","0.051"],["64047.60","0.001"],["64048.10","0.164"],["64048.50","0.292"],["64048.70","0.000"],["64048.90","0.086"],["64049.00","0.000"],["64049.20","0.418"],["64049.30","1.251"],["64049.50","0.263"],["64049.60","0.023"],["64049.80","0.003"],["64050.20","0.000"],["64050.80","0.060"],["64050.90","0.001"],["64051.00","0.062"],["64051.10","2.465"],["64051.30","0.718"],["64051.40","0.013"],["64051.60","0.125"],["64051.90","0.001"],["64052.00","0.003"],["64052.20","0.033"],["64052.50","1.721"],["64052.60","0.557"],["64052.80","0.034"],["64053.10","0.034"],["64053.20","0.001"],["64053.40","0.001"],["64053.50","0.001"],["64053.60","0.025"],["64053.70","2.340"],["64053.80","1.218"],["64053.90","0.241"],["64054.10","0.002"],["64054.20","0.315"],["64054.30","0.000"],["64054.80","0.002"],["64055.40","0.050"],["64055.50","0.002"],["64056.00","0.098"],["64056.30","0.004"],["64056.50","0.000"],["64056.60","0.004"],["64056.70","2.371"],["64056.80","1.326"],["64057.60","0.873"],["64057.70","0.007"],["64057.90","0.180"],["64058.60","0.023"],["64058.90","1.041"],["64059.50","0.003"],["64060.10","0.002"],["64060.20","0.003"],["64060.30","0.004"],["64060.50","0.001"],["64060.60","0.001"],["64060.70","0.451"],["64060.80","0.004"],["64061.10","0.003"],["64061.40","0.001"],["64061.50","0.006"],["64061.60","0.681"],["64061.70","0.001"],["64061.80","0.008"],["64061.90","0.002"],["64062.00","0.004"],["64062.30","0.075"],["64062.40","0.002"],["64062.50","0.001"],["64062.60","0.000"],["64063.00","0.029"],["64063.10","0.001"],["64063.40","0.001"],["64063.50","0.048"],["64063.60","0.000"],["64063.70","0.002"],["64063.80","0.436"],["64063.90","0.003"],["64064.00","0.003"],["64064.60","0.066"],["64064.80","0.050"],["64064.90","0.000"],["64065.00","0.002"],["64065.40","0.018"],["64065.90","0.000"],["64066.10","0.008"],["64066.30","0.000"],["64066.60","0.002"],["64066.70","3.421"]],"e":"depthUpdate","ps":"BTCUSDT","pu":11165394198135,"s":"BTCUSDT","st":1,"u":11165394209077}
{"E":1785353519330,"T":1785353519329,"U":11165394209162,"a":[["64066.80","9.520"],["64067.70","0.002"],["64068.00","0.023"],["64068.70","0.001"],["64068.90","0.002"],["64069.30","0.006"],["64070.30","0.001"],["64070.40","0.229"],["64070.80","0.002"],["64071.90","0.151"],["64072.00","0.023"],["64072.40","0.003"],["64072.80","0.958"],["64073.00","0.001"],["64073.40","0.001"],["64073.70","2.538"],["64073.80","0.000"],["64073.90","0.702"],["64074.00","0.570"],["64074.30","0.004"],["64074.50","0.322"],["64075.40","0.554"],["64077.30","0.018"],["64077.90","0.181"],["64078.30","0.158"],["64078.50","0.830"],["64078.60","0.816"],["64078.80","1.719"],["64079.00","0.151"],["64080.80","0.003"],["64081.00","0.135"],["64082.90","0.621"],["64083.90","0.003"],["64085.40","0.144"],["64085.70","0.234"],["64086.50","0.007"],["64086.80","0.699"],["64088.70","0.379"],["64089.40","0.158"],["64089.50","0.063"],["64089.60","3.706"],["64092.20","0.043"],["64092.80","0.048"],["64093.40","2.494"],["64093.90","0.010"],["64094.80","10.002"],["64099.50","1.947"],["64099.60","1.047"],["64104.40","2.346"],["64106.20","0.101"],["64106.40","0.780"],["64108.40","0.144"],["64108.50","0.001"],["64109.10","0.019"],["64112.30","0.000"],["64115.50","0.029"],["64117.30","0.008"],["64118.10","0.004"],["64119.00","0.159"],["64119.10","0.547"],["64119.20","0.151"],["64134.60","1.581"],["64143.70","0.216"],["64160.00","0.840"],["64233.90","0.004"],["64236.50","17.966"],["64240.00","2.337"],["64247.70","1.953"],["64266.20","1.946"],["64292.00","0.970"],["64320.00","0.489"],["64400.00","12.139"],["64480.00","0.821"],["64707.50","0.162"],["64775.70","0.001"],["64867.60","2.520"],["65322.60","0.117"]],"b":[["1000.00","37.592"],["13559.90","0.252"],["13566.70","0.364"],["13661.60","0.014"],["13766.70","0.350"],["13859.90","0.056"],["13966.70","0.350"],["51248.00","0.000"],["51253.00","0.000"],["57660.00","0.313"],["60839.60","0.000"],["60839.70","0.010"],["62760.90","1.033"],["63101.30","4.639"],["63134.10","1.105"],["63297.60","4.998"],["63426.00","0.001"],["63554.20","0.022"],["63680.00","3.941"],["63741.30","0.010"],["63754.70","0.000"],["63760.00","0.480"],["63795.10","0.027"],["63813.00","0.152"],["63829.70","0.181"],["63840.00","1.719"],["63914.80","2.038"],["63915.00","0.002"],["63920.00","0.865"],["63928.00","0.029"],["63933.30","2.216"],["63933.40","0.030"],["63949.70","22.316"],["63951.70","0.022"],["63951.90","0.371"],["63954.10","0.003"],["63956.30","0.006"],["63958.10","1.200"],["63995.10","0.545"],["64000.00","11.003"],["64005.80","0.003"],["64015.30","0.683"],["64017.50","0.004"],["64020.50","0.026"],["64021.80","0.001"],["64028.30","2.343"],["64028.40","1.897"],["64029.20","0.079"],["64030.70","0.029"],["64031.70","0.135"],["64032.20","2.070"],["64034.30","0.001"],["64034.60","0.004"],["64035.40","0.344"],["64036.10","0.001"],["64038.20","0.524"],["64038.90","0.936"],["64039.10","0.142"],["64039.50","0.150"],["64039.90","0.000"],["64040.60","0.045"],["64040.80","1.097"],["64041.10","2.450"],["64041.20","0.080"],["64041.80","1.335"],["64041.90","0.325"],["64042.00","0.659"],["64044.80","0.006"],["64045.10","0.000"],["64046.50","0.375"],["64050.70","0.293"],["64051.00","0.122"],["64051.20","1.189"],["64051.30","0.110"],["64051.40","0.621"],["64051.50","0.310"],["64051.70","0.032"],["64052.10","0.314"],["64052.60","0.003"],["64053.10","0.032"],["64053.80","1.000"],["64054.00","0.003"],["64054.40","0.195"],["64054.50","0.063"],["64054.70","0.003"],["64055.30","0.000"],["64055.80","0.001"],["64056.70","0.031"],["64056.80","1.709"],["64056.90","2.113"],["64057.60","1.180"],["64057.70","2.367"],["64057.80","0.085"],["64058.30","0.002"],["64058.50","0.000"],["64059.00","0.767"],["64059.10","0.547"],["64059.20","0.022"],["64059.30","0.022"],["64059.40","0.000"],["64060.20","0.237"],["64060.70","0.835"],["64060.80","0.842"],["64060.90","2.347"],["64061.00","0.166"],["64061.50","0.003"],["64061.60","0.672"],["64061.70","0.003"],["64061.80","0.001"],["64062.10","0.001"],["64062.30","0.078"],["64062.70","0.002"],["64063.00","0.027"],["64063.30","0.001"],["64063.80","0.476"],["64063.90","0.001"],["64065.70","0.001"],["64066.20","0.002"],["64066.40","0.000"],["64066.50","0.000"],["64066.60","0.003"],["64066.70","3.785"]],"e":"depthUpdate","ps":"BTCUSDT","pu":11165394209077,"s":"BTCUSDT","st":1,"u":11165394219009}
{"E":1785353519432,"T":1785353519429,"U":11165394219060,"a":[["64066.80","9.525"],["64067.60","0.002"],["64069.20","0.001"],["64069.60","0.002"],["64070.80","0.001"],["64071.90","0.286"],["64074.50","0.421"],["64077.00","1.318"],["64077.30","0.026"],["64078.60","0.936"],["64078.70","0.757"],["64078.80","1.869"],["64078.90","0.452"],["64081.50","0.002"],["64086.80","1.064"],["64093.40","1.148"],["64094.80","0.002"],["64096.90","0.001"],["64097.60","0.001"],["64100.00","2.764"],["64110.00","0.191"],["64115.50","0.001"],["64117.40","0.166"],["64118.10","0.032"],["64118.80","1.104"],["64118.90","0.715"],["64119.00","0.315"],["64119.10","0.865"],["64166.50","2.501"],["64707.50","0.162"],["64963.00","0.778"]],"b":[["13559.90","0.140"],["13566.70","0.476"],["13659.90","0.840"],["13660.70","0.000"],["13661.60","0.000"],["13666.70","0.070"],["13766.70","0.336"],["13859.90","0.000"],["13966.70","0.462"],["51253.00","0.000"],["57660.00","0.313"],["61504.00","0.011"],["63163.20","0.007"],["63198.10","1.097"],["63426.00","0.001"],["63949.70","0.002"],["63952.00","3.932"],["63981.80","0.001"],["63982.30","4.261"],["63989.30","22.314"],["64003.30","2.040"],["64005.80","0.120"],["64015.30","0.658"],["64024.60","0.025"],["64041.10","0.882"],["64050.80","0.120"],["64050.90","0.061"],["64051.00","0.242"],["64051.20","1.249"],["64053.90","0.261"],["64056.90","0.864"],["64057.00","2.341"],["64057.40","0.015"],["64057.60","0.873"],["64057.70","0.007"],["64057.80","0.065"],["64058.00","0.236"],["64059.20","0.022"],["64059.30","0.042"],["64060.20","0.003"],["64060.80","0.843"],["64060.90","2.347"],["64061.10","0.003"],["64061.60","0.049"],["64063.80","0.284"],["64066.20","0.000"],["64066.50","0.002"],["64066.60","0.005"],["64066.70","4.099"]],"e":"depthUpdate","ps":"BTCUSDT","pu":11165394219009,"s":"BTCUSDT","st":1,"u":11165394225339}
{"E":1785353519534,"T":1785353519532,"U":11165394225506,"a":[["64066.80","9.570"],["64070.80","0.121"],["64073.10","0.007"],["64074.50","0.556"],["64075.30","0.667"],["64076.50","0.369"],["64076.70","0.002"],["64078.50","0.834"],["64079.10","0.001"],["64080.30","0.010"],["64081.00","0.015"],["64082.10","0.004"],["64082.20","0.536"],["64082.40","2.983"],["64082.90","0.501"],["64083.50","2.147"],["64084.20","0.001"],["64084.80","0.003"],["64085.10","2.387"],["64085.20","10.003"],["64086.40","0.009"],["64086.90","0.391"],["64088.70","0.377"],["64089.60","1.706"],["64092.20","0.008"],["64093.30","0.001"],["64097.00","1.219"],["64098.70","0.090"],["64099.70","0.000"],["64106.40","0.690"],["64108.40","0.066"],["64113.00","0.036"],["64118.10","0.004"],["64132.90","0.093"],["64133.20","3.231"],["64133.50","0.090"],["64133.80","0.084"],["64144.30","5.225"],["64145.30","22.913"],["64151.10","0.785"],["64151.90","0.000"],["64175.90","0.658"],["64700.50","1.226"],["64707.50","0.162"],["64846.50","0.923"],["65500.00","141.451"],["65981.70","0.000"],["67905.30","0.000"]],"b":[["1000.00","37.592"],["13559.90","0.014"],["13566.70","0.602"],["13659.90","0.714"],["13666.70","0.182"],["13766.70","0.224"],["13966.70","0.588"],["57660.00","0.313"],["61504.00","0.014"],["63100.00","29.707"],["63229.30","1.566"],["63259.30","1.565"],["63262.20","0.782"],["63294.20","1.595"],["63426.00","0.001"],["63952.00","0.706"],["63967.80","0.035"],["63968.10","0.032"],["63968.40","0.091"],["63968.70","3.031"],["63981.80","0.040"],["63982.30","4.222"],["63990.20","5.817"],["63994.70","0.001"],["64010.60","0.060"],["64011.10","0.060"],["64022.70","0.573"],["64029.50","0.034"],["64030.60","10.059"],["64031.70","0.136"],["64032.20","0.070"],["64033.10","2.407"],["64035.90","0.000"],["64039.70","0.008"],["64041.20","0.073"],["64042.30","0.000"],["64043.60","0.001"],["64049.40","0.021"],["64053.90","0.241"],["64056.80","0.383"],["64056.90","0.049"],["64057.00","0.001"],["64057.60","0.873"],["64057.70","2.347"],["64058.00","0.002"],["64059.20","0.002"],["64059.90","0.349"],["64060.40","0.234"],["64060.90","0.009"],["64061.10","1.329"],["64061.60","0.042"],["64063.00","0.001"],["64063.80","0.501"],["64066.70","3.900"]],"e":"depthUpdate","ps":"BTCUSDT","pu":11165394225339,"s":"BTCUSDT","st":1,"u":11165394232170}
{"E":1785353519636,"T":1785353519632,"U":11165394232276,"a":[["64067.50","0.005"],["64068.90","0.007"],["64069.20","0.001"],["64070.30","0.008"],["64070.80","0.121"],["64072.20","0.054"],["64072.80","0.905"],["64079.90","0.494"],["64083.70","0.092"],["64100.20","0.518"],["64149.70","2.081"],["64232.80","0.026"],["64707.50","0.162"],["64823.90","0.924"],["65348.10","0.013"]],"b":[["1000.00","37.592"],["13559.90","0.000"],["13566.70","0.714"],["13659.90","0.602"],["13666.70","0.308"],["13766.70","0.098"],["13866.70","0.098"],["13966.70","0.504"],["57660.00","0.313"],["61504.00","0.011"],["63133.30","16.722"],["63169.80","2.351"],["63178.00","1.338"],["63182.30","1.262"],["63426.00","0.001"],["63741.30","0.000"],["63746.40","0.018"],["63914.70","0.000"],["63916.70","0.001"],["63918.70","0.000"],["63920.70","0.000"],["63922.70","0.000"],["63924.70","0.000"],["63926.70","0.000"],["63928.70","0.004"],["63930.70","0.001"],["63932.70","0.001"],["63934.70","0.001"],["63936.70","0.001"],["63938.70","0.000"],["63940.70","1.486"],["63956.30","22.320"],["63958.10","4.380"],["63966.80","0.033"],["63989.30","0.000"],["63990.20","2.640"],["64010.20","0.060"],["64010.40","0.066"],["64010.90","2.091"],["64011.00","0.062"],["64030.30","0.000"],["64032.00","2.952"],["64037.30","0.021"],["64039.10","0.107"],["64046.80","0.037"],["64047.20","0.054"],["64049.40","0.001"],["64053.90","0.261"],["64054.00","0.010"],["64054.70","0.006"],["64057.60","0.626"],["64058.00","0.236"],["64059.20","1.328"],["64059.40","0.015"],["64060.40","0.000"],["64060.70","1.155"],["64060.80","3.182"],["64060.90","0.165"],["64061.00","0.003"],["64061.10","0.003"],["64061.70","0.013"],["64061.80","0.004"],["64062.30","0.075"],["64062.50","0.009"],["64066.70","3.925"]],"e":"depthUpdate","ps":"BTCUSDT","pu":11165394232170,"s":"BTCUSDT","st":1,"u":11165394237847}
{"E":1785353519738,"T":1785353519736,"U":11165394238120,"a":[["64066.80","9.525"],["64067.90","0.023"],["64068.00","0.001"],["64068.70","0.004"],["64073.60","0.009"],["64082.30","0.471"],["64082.40","2.948"],["64088.90","0.051"],["64092.90","0.001"],["64124.10","0.000"],["64130.90","1.626"],["64143.60","0.509"],["64144.30","2.336"],["64145.30","0.000"],["64148.90","0.076"],["64160.20","4.602"],["64162.80","0.008"],["64162.90","22.914"],["64165.10","0.071"],["64205.60","0.155"],["64210.10","0.019"],["64382.00","0.001"],["64387.10","0.299"],["64500.00","7.484"],["64707.50","0.162"],["64804.20","12.311"],["64994.80","0.000"],["65058.80","0.790"]],"b":[["13566.70","0.840"],["13659.90","0.476"],["13666.70","0.420"],["13765.40","0.000"],["13766.70","0.000"],["13866.70","0.224"],["13966.70","0.378"],["57660.00","0.313"],["63037.20","3.297"],["63073.70","1.099"],["63133.30","14.370"],["63169.80","4.702"],["63195.10","6.933"],["63261.30","3.139"],["63297.90","1.566"],["63426.00","0.001"],["63792.40","0.000"],["63920.40","0.000"],["63923.50","0.017"],["63956.30","0.006"],["63958.10","1.200"],["63965.20","0.500"],["63971.70","22.314"],["63973.30","4.087"],["63984.00","0.017"],["63995.80","0.000"],["64002.60","0.636"],["64010.50","0.120"],["64010.70","0.154"],["64011.00","0.122"],["64023.30","0.303"],["64049.40","0.001"],["64053.90","0.241"],["64054.00","0.030"],["64054.40","0.004"],["64057.70","0.007"],["64058.00","0.002"],["64059.10","0.001"],["64059.30","2.382"],["64059.40","0.015"],["64060.10","0.236"],["64060.80","1.033"],["64061.00","0.549"],["64063.80","0.284"]],"e":"depthUpdate","ps":"BTCUSDT","pu":11165394237847,"s":"BTCUSDT","st":1,"u":11165394243101}
{"E":1785353519840,"T":1785353519838,"U":11165394243253,"a":[["64066.80","9.612"],["64066.90","0.008"],["64067.40","0.002"],["64068.40","0.009"],["64068.90","0.002"],["64069.70","0.325"],["64076.80","0.707"],["64088.60","0.124"],["64144.30","5.225"],["64145.30","22.913"],["64160.20","1.356"],["64162.80","0.000"],["64162.90","0.001"],["64165.10","0.079"],["64707.50","0.162"],["64804.20","13.236"],["64829.20","0.924"],["64832.40","0.004"],["65322.60","0.114"]],"b":[["1000.00","37.592"],["13566.70","0.952"],["13659.90","0.364"],["13666.70","0.546"],["13761.60","0.406"],["13763.50","0.000"],["13866.70","0.336"],["13966.70","0.266"],["57660.00","0.313"],["61504.00","0.014"],["63131.50","0.000"],["63133.30","9.666"],["63156.60","1.732"],["63166.10","2.351"],["63169.80","9.404"],["63229.30","0.783"],["63233.00","0.006"],["63259.30","0.000"],["63265.90","1.566"],["63281.90","3.915"],["63297.90","3.130"],["63426.00","0.001"],["63954.10","22.317"],["63954.60","4.831"],["63971.70","0.000"],["63973.30","0.936"],["64010.50","0.180"],["64010.70","0.274"],["64010.80","2.400"],["64030.60","10.061"],["64032.10","2.341"],["64053.10","0.034"],["64053.30","0.376"],["64053.90","0.241"],["64054.00","0.030"],["64054.10","0.883"],["64054.70","0.887"],["64058.90","1.019"],["64060.10","0.002"],["64060.30","0.027"],["64060.50","0.235"],["64060.90","0.711"],["64061.00","0.003"],["64061.60","0.003"],["64061.70","0.011"],["64063.80","0.265"],["64066.70","5.478"]],"e":"depthUpdate","ps":"BTCUSDT","pu":11165394243101,"s":"BTCUSDT","st":1,"u":11165394248043}
{"E":1785353519942,"T":1785353519940,"U":11165394248116,"a":[["64066.80","9.584"],["64067.10","0.003"],["64069.10","0.007"],["64071.90","0.052"],["64074.50","0.421"],["64082.30","0.159"],["64083.50","0.959"],["64084.90","0.312"],["64085.20","0.003"],["64086.80","2.216"],["64086.90","0.548"],["64088.30","10.040"],["64088.60","0.122"],["64089.40","0.001"],["64102.70","0.002"],["64115.50","0.001"],["64119.30","0.002"],["64123.50","0.003"],["64143.70","0.216"],["64233.90","0.001"],["64236.00","0.004"],["64264.10","0.234"],["64707.50","0.162"],["64804.20","12.319"],["64867.60","2.781"],["64995.80","2.151"]],"b":[["1000.00","37.592"],["13566.70","1.078"],["13659.90","0.238"],["13666.70","0.658"],["13761.60","0.294"],["13866.70","0.462"],["13966.70","0.140"],["51248.00","0.002"],["51253.40","0.000"],["57660.00","0.313"],["61504.00","0.011"],["63229.30","0.000"],["63242.70","0.790"],["63262.20","1.564"],["63426.00","0.001"],["63721.60","0.010"],["63741.30","0.000"],["63746.40","0.008"],["63945.70","0.002"],["63947.80","0.004"],["63954.10","0.003"],["63954.60","1.694"],["63969.50","22.517"],["63969.80","0.238"],["63970.70","5.275"],["63970.80","0.009"],["63983.00","0.000"],["64033.30","0.032"],["64034.90","2.021"],["64041.00","0.652"],["64052.50","1.723"],["64058.40","0.536"],["64059.30","2.360"],["64060.60","0.023"],["64063.90","0.003"],["64066.70","5.517"]],"e":"depthUpdate","ps":"BTCUSDT","pu":11165394248043,"s":"BTCUSDT","st":1,"u":11165394252834}
{"E":1785353520044,"T":1785353520043,"U":11165394253036,"a":[["64066.80","10.132"],["64067.30","0.004"],["64068.00","0.095"],["64069.20","0.095"],["64069.40","0.323"],["64069.70","0.319"],["64070.00","0.023"],["64070.40","0.758"],["64071.50","0.002"],["64071.60","1.030"],["64071.90","0.286"],["64072.00","0.046"],["64072.50","1.165"],["64072.60","0.001"],["64072.70","0.095"],["64073.50","0.087"],["64073.60","0.890"],["64073.80","0.001"],["64073.90","0.250"],["64074.00","0.726"],["64074.30","0.005"],["64074.40","0.064"],["64074.70","0.015"],["64075.10","0.265"],["64075.30","0.121"],["64075.80","0.001"],["64078.20","0.001"],["64078.40","0.640"],["64080.10","2.512"],["64080.30","0.010"],["64081.50","10.002"],["64082.20","0.222"],["64082.30","0.159"],["64084.10","0.342"],["64084.40","0.000"],["64084.80","0.053"],["64084.90","0.000"],["64085.10","2.389"],["64085.20","0.001"],["64086.80","0.860"],["64088.30","0.040"],["64090.00","0.184"],["64092.00","0.553"],["64092.40","2.673"],["64094.60","0.058"],["64094.70","0.000"],["64097.80","0.006"],["64098.70","0.000"],["64100.00","2.644"],["64101.10","0.002"],["64105.30","1.550"],["64109.50","1.458"],["64113.50","0.001"],["64115.50","0.001"],["64116.20","0.925"],["64120.90","0.000"],["64121.70","2.375"],["64129.80","0.005"],["64141.60","0.000"],["64143.70","0.216"],["64148.30","0.511"],["64173.70","0.001"],["64180.40","2.342"],["64202.80","0.882"],["64204.80","4.222"],["64206.80","0.881"],["64208.80","4.118"],["64210.80","0.946"],["64212.80","0.883"],["64214.80","2.625"],["64249.00","0.390"],["64263.50","0.000"],["64264.10","0.135"],["64265.40","0.119"],["64292.80","0.000"],["64298.00","0.379"],["64383.40","0.002"],["64385.20","0.000"],["64707.50","0.162"],["64804.20","13.244"],["64829.20","1.848"],["64995.80","3.227"],["65059.80","4.285"],["65348.10","0.016"]],"b":[["13566.70","1.190"],["13659.90","0.126"],["13666.70","0.784"],["13761.60","0.168"],["13866.70","0.574"],["13966.70","0.028"],["51248.00","0.000"],["51253.00","0.002"],["57660.00","0.313"],["61504.00","0.014"],["63037.20","2.198"],["63073.70","2.198"],["63101.30","2.443"],["63133.30","7.314"],["63134.10","2.203"],["63137.70","1.098"],["63166.10","4.702"],["63214.90","0.000"],["63216.50","0.000"],["63254.70","0.002"],["63426.00","0.007"],["63741.20","0.157"],["63823.50","1.496"],["63832.10","0.000"],["63841.10","0.014"],["63850.10","0.039"],["63946.20","2.351"],["63953.20","0.029"],["63970.80","0.287"],["63971.60","0.279"],["63978.20","0.010"],["63985.20","3.241"],["64010.30","0.540"],["64017.30","0.020"],["64023.90","0.299"],["64024.10","0.000"],["64026.60","0.190"],["64028.00","10.042"],["64028.80","0.007"],["64030.60","0.061"],["64032.00","1.589"],["64033.90","0.000"],["64034.10","0.050"],["64034.90","0.021"],["64035.30","0.106"],["64035.60","0.002"],["64036.70","0.562"],["64037.80","0.796"],["64038.60","0.012"],["64038.90","0.001"],["64039.00","0.314"],["64039.10","1.042"],["64039.50","0.151"],["64039.70","0.001"],["64039.90","0.000"],["64041.00","0.340"],["64041.20","0.031"],["64041.30","0.579"],["64041.60","0.708"],["64042.30","0.000"],["64042.40","0.372"],["64042.80","0.141"],["64043.40","0.003"],["64045.40","0.002"],["64047.20","0.005"],["64047.60","0.016"],["64048.10","0.258"],["64050.30","0.003"],["64052.30","0.310"],["64053.40","0.095"],["64053.90","0.335"],["64054.00","0.003"],["64054.10","0.881"],["64054.30","0.000"],["64054.40","0.195"],["64054.60","0.002"],["64054.70","0.887"],["64054.80","0.002"],["64055.00","0.254"],["64055.20","1.328"],["64055.30","0.547"],["64055.80","0.001"],["64056.10","0.004"],["64056.70","0.031"],["64056.80","0.000"],["64056.90","0.002"],["64057.60","0.855"],["64058.00","1.010"],["64058.10","0.010"],["64058.40","0.223"],["64058.90","0.011"],["64059.00","0.000"],["64059.20","0.002"],["64059.30","2.340"],["64059.90","0.205"],["64060.20","0.000"],["64060.30","0.004"],["64060.50","0.001"],["64060.60","0.024"],["64060.70","0.793"],["64060.80","0.842"],["64060.90","0.243"],["64061.00","0.006"],["64061.40","0.001"],["64061.50","0.003"],["64061.80","0.001"],["64062.20","0.004"],["64063.80","0.190"],["64066.10","0.007"],["64066.60","0.005"],["64066.70","4.032"]],"e":"depthUpdate","ps":"BTCUSDT","pu":11165394252834,"s":"BTCUSDT","st":1,"u":11165394280032}
{"E":1785353520146,"T":1785353520145,"U":11165394280235,"a":[["64066.80","9.698"],["64067.30","0.003"],["64067.40","0.001"],["64067.50","0.004"],["64067.60","0.001"],["64067.80","0.000"],["64067.90","0.023"],["64068.40","0.031"],["64068.50","0.001"],["64069.00","0.244"],["64069.20","0.095"],["64070.30","0.008"],["64070.40","0.620"],["64071.50","0.002"],["64071.60","0.095"],["64071.90","0.146"],["64072.00","0.009"],["64072.30","0.001"],["64072.40","0.003"],["64072.50","0.072"],["64072.70","0.641"],["64072.80","0.024"],["64072.90","0.937"],["64073.40","0.096"],["64073.50","0.633"],["64073.60","0.009"],["64073.70","2.445"],["64073.80","0.000"],["64074.00","0.727"],["64074.40","0.065"],["64074.50","0.323"],["64075.10","0.382"],["64076.50","0.252"],["64076.80","0.007"],["64077.00","1.784"],["64078.20","0.000"],["64078.30","0.158"],["64078.40","0.327"],["64080.00","0.324"],["64080.10","1.249"],["64080.80","0.003"],["64081.50","0.002"],["64082.20","0.222"],["64082.30","0.471"],["64084.10","0.342"],["64088.50","2.010"],["64088.70","0.377"],["64089.20","0.431"],["64090.00","0.064"],["64092.60","10.560"],["64093.70","0.005"],["64096.50","0.172"],["64098.30","0.002"],["64098.40","0.001"],["64108.40","0.144"],["64111.90","0.001"],["64113.00","0.008"],["64115.50","0.029"],["64118.10","0.028"],["64121.70","2.165"],["64128.90","0.311"],["64143.70","0.240"],["64144.30","5.238"],["64145.30","22.996"],["64154.00","1.209"],["64154.10","0.011"],["64160.00","0.823"],["64186.00","0.027"],["64202.80","0.001"],["64204.80","3.341"],["64206.80","0.000"],["64208.80","3.237"],["64210.80","0.065"],["64212.80","0.002"],["64214.80","1.744"],["64240.00","2.320"],["64320.00","0.472"],["64362.00","0.161"],["64387.20","0.000"],["64400.00","12.122"],["64523.80","0.000"],["64707.50","0.162"],["65047.20","0.000"],["65117.80","0.000"]],"b":[["1000.00","37.592"],["13566.70","1.316"],["13659.90","0.000"],["13666.70","0.896"],["13761.60","0.056"],["13866.70","0.700"],["13961.60","0.462"],["13962.10","0.000"],["13963.50","0.000"],["13965.40","0.000"],["13966.70","0.000"],["51253.00","0.000"],["57660.00","0.313"],["61504.00","0.011"],["62965.80","0.554"],["62990.40","0.014"],["63037.20","1.099"],["63073.70","3.297"],["63101.30","1.345"],["63133.30","4.962"],["63137.70","2.196"],["63169.80","11.755"],["63261.30","1.574"],["63291.20","37.550"],["63297.90","4.694"],["63426.00","0.001"],["63680.00","3.924"],["63726.70","0.032"],["63746.30","0.000"],["63746.40","0.018"],["63760.00","0.463"],["63840.00","1.702"],["63858.10","0.046"],["63864.90","0.117"],["63912.70","0.011"],["63914.70","0.000"],["63916.70","0.001"],["63918.70","0.000"],["63920.00","0.848"],["63920.70","0.000"],["63922.70","0.000"],["63924.70","0.000"],["63926.70","0.000"],["63928.70","0.004"],["63930.70","0.001"],["63932.70","0.001"],["63934.70","0.001"],["63936.70","0.001"],["63938.70","0.000"],["63954.10","0.003"],["63954.60","1.694"],["63956.30","22.523"],["63958.10","4.410"],["63969.50","0.000"],["63970.70","2.252"],["63970.80","0.009"],["63971.60","0.001"],["63977.60","0.005"],["64000.00","10.986"],["64003.40","0.278"],["64005.80","0.003"],["64008.40","0.011"],["64009.60","0.006"],["64011.00","0.400"],["64013.30","0.095"],["64021.50","0.058"],["64023.50","0.015"],["64025.00","0.000"],["64025.60","1.171"],["64026.70","0.003"],["64027.00","0.004"],["64028.00","0.042"],["64028.40","1.897"],["64029.20","0.079"],["64033.50","0.679"],["64034.10","0.001"],["64035.30","0.105"],["64035.50","0.001"],["64035.60","0.001"],["64036.40","0.018"],["64036.70","0.000"],["64037.10","0.083"],["64037.40","0.613"],["64037.80","1.360"],["64038.80","0.012"],["64039.10","0.107"],["64039.50","0.150"],["64039.60","0.958"],["64040.20","0.001"],["64040.60","0.095"],["64042.00","0.708"],["64042.50","2.460"],["64043.40","0.002"],["64045.10","0.000"],["64045.40","0.001"],["64045.50","0.003"],["64045.80","0.003"],["64046.80","0.002"],["64047.50","0.038"],["64048.60","0.324"],["64049.40","0.002"],["64051.10","2.559"],["64051.30","0.112"],["64051.50","0.311"],["64051.60","0.126"],["64052.00","0.004"],["64052.60","0.000"],["64053.40","0.001"],["64053.50","0.095"],["64054.10","0.000"],["64054.30","0.020"],["64054.40","0.004"],["64054.60","0.000"],["64054.90","0.568"],["64055.00","0.044"],["64055.20","0.002"],["64055.30","0.000"],["64056.10","0.004"],["64056.20","0.515"],["64056.30","0.184"],["64056.40","1.249"],["64056.70","0.837"],["64056.80","0.383"],["64057.40","0.015"],["64057.50","0.005"],["64057.60","1.284"],["64057.90","0.000"],["64058.00","0.002"],["64058.30","0.315"],["64058.80","0.105"],["64059.40","0.817"],["64059.50","1.499"],["64059.60","0.000"],["64060.20","0.000"],["64060.30","1.035"],["64060.60","0.001"],["64060.70","1.132"],["64060.80","1.033"],["64060.90","0.575"],["64061.00","0.003"],["64061.10","0.000"],["64061.50","0.237"],["64061.60","0.003"],["64062.00","0.007"],["64062.20","0.007"],["64062.70","0.883"],["64062.80","0.002"],["64063.80","0.267"],["64063.90","0.001"],["64066.60","0.006"],["64066.70","4.435"]],"e":"depthUpdate","ps":"BTCUSDT","pu":11165394280032,"s":"BTCUSDT","st":1,"u":11165394311332}
{"E":1785353520248,"T":1785353520247,"U":11165394311942,"a":[["64066.80","10.050"],["64066.90","0.009"],["64070.40","0.622"],["64070.50","0.007"],["64071.50","0.001"],["64072.60","0.002"],["64072.80","0.025"],["64073.80","0.001"],["64073.90","0.251"],["64074.00","0.726"],["64074.30","0.004"],["64074.40","0.064"],["64074.50","0.418"],["64083.20","2.728"],["64083.30","10.001"],["64083.50","0.014"],["64088.50","0.010"],["64089.60","1.706"],["64092.60","0.560"],["64100.50","0.634"],["64104.00","0.006"],["64108.40","0.066"],["64113.00","0.036"],["64114.90","0.535"],["64115.50","0.001"],["64118.10","0.004"],["64132.30","2.506"],["64143.70","0.216"],["64144.30","2.336"],["64145.30","0.000"],["64154.00","4.480"],["64154.10","23.007"],["64160.00","0.840"],["64240.00","2.337"],["64264.10","0.234"],["64266.70","0.252"],["64320.00","0.489"],["64387.20","0.001"],["64400.00","12.139"],["64480.00","0.838"],["64707.50","0.164"],["65143.20","0.031"]],"b":[["1000.00","37.592"],["13566.70","1.204"],["13666.70","1.022"],["13759.90","0.378"],["13760.70","0.000"],["13761.60","0.000"],["13866.70","0.812"],["13961.60","0.350"],["13966.70","0.112"],["34000.00","7.450"],["57660.00","0.313"],["57660.10","0.055"],["62990.40","0.031"],["63037.20","0.000"],["63073.70","4.396"],["63131.20","0.003"],["63166.00","0.998"],["63169.80","14.106"],["63265.90","2.355"],["63293.40","0.000"],["63329.90","1.086"],["63409.00","1.174"],["63426.00","0.001"],["63458.10","0.702"],["63680.00","3.941"],["63686.50","0.002"],["63702.80","0.453"],["63726.70","0.002"],["63739.60","0.392"],["63746.30","0.001"],["63760.00","0.480"],["63832.90","0.000"],["63840.00","1.719"],["63852.10","0.019"],["63855.30","0.123"],["63920.00","0.865"],["63956.30","0.006"],["63958.10","1.200"],["63969.80","0.246"],["63970.80","0.001"],["63971.70","22.517"],["63973.30","4.117"],["63977.60","0.002"],["64000.00","11.003"],["64026.60","0.120"],["64029.10","11.254"],["64032.00","2.947"],["64033.80","0.002"],["64040.90","0.512"],["64045.80","0.002"],["64051.20","1.250"],["64054.00","0.720"],["64054.40","0.195"],["64054.70","0.006"],["64056.70","0.031"],["64057.60","0.824"],["64058.20","0.002"],["64059.40","0.109"],["64059.50","1.329"],["64060.80","0.842"],["64060.90","0.029"],["64062.30","0.077"],["64063.80","0.402"],["64066.70","4.446"]],"e":"depthUpdate","ps":"BTCUSDT","pu":11165394311332,"s":"BTCUSDT","st":1,"u":11165394330292}
{"E":1785353520350,"T":1785353520349,"U":11165394330363,"a":[["64066.80","10.213"],["64066.90","0.013"],["64069.00","0.175"],["64069.10","0.007"],["64071.90","0.245"],["64072.00","0.046"],["64072.50","0.073"],["64072.60","0.883"],["64072.80","0.024"],["64073.60","0.010"],["64073.90","0.250"],["64077.00","3.167"],["64078.10","10.427"],["64079.80","2.342"],["64081.20","0.009"],["64081.40","0.003"],["64083.20","1.236"],["64083.30","0.001"],["64088.70","0.379"],["64113.00","0.008"],["64147.40","4.705"],["64147.50","22.997"],["64154.00","1.209"],["64154.10","0.011"],["64264.10","0.135"],["64707.50","0.162"],["65348.10","0.019"]],"b":[["13566.70","1.078"],["13666.70","1.134"],["13759.90","0.266"],["13866.70","0.938"],["13961.60","0.224"],["13966.70","0.238"],["51253.00","0.000"],["57660.00","0.313"],["61504.00","0.014"],["62785.40","0.017"],["63016.50","0.317"],["63133.30","2.610"],["63169.80","16.457"],["63261.30","0.009"],["63297.90","6.258"],["63426.00","0.001"],["64012.40","0.394"],["64023.60","10.000"],["64024.40","0.360"],["64024.60","0.000"],["64025.60","2.568"],["64027.10","0.063"],["64029.10","1.254"],["64030.60","0.059"],["64032.00","1.591"],["64033.30","0.102"],["64040.90","0.442"],["64049.90","0.419"],["64054.00","0.003"],["64054.10","0.000"],["64054.70","0.006"],["64054.80","0.002"],["64054.90","0.474"],["64055.00","0.004"],["64055.50","0.002"],["64056.70","0.033"],["64057.50","0.003"],["64058.30","0.002"],["64058.90","1.019"],["64059.50","0.003"],["64060.30","0.027"],["64060.70","0.713"],["64060.90","1.596"],["64061.00","0.752"],["64061.50","0.003"],["64061.60","0.006"],["64061.70","0.014"],["64062.00","0.004"],["64062.20","0.004"],["64062.70","0.002"],["64066.70","3.687"]],"e":"depthUpdate","ps":"BTCUSDT","pu":11165394330292,"s":"BTCUSDT","st":1,"u":11165394345596}
{"E":1785353520452,"T":1785353520451,"U":11165394345802,"a":[["64066.80","10.067"],["64069.00","0.263"],["64069.10","0.008"],["64070.30","0.008"],["64070.70","0.000"],["64070.80","0.899"],["64071.50","0.936"],["64072.00","0.009"],["64072.50","0.619"],["64072.70","0.096"],["64072.90","0.002"],["64073.70","2.444"],["64074.70","0.093"],["64076.10","0.622"],["64077.00","1.784"],["64078.10","0.427"],["64078.50","0.272"],["64080.30","2.010"],["64083.20","2.573"],["64083.80","0.005"],["64084.30","0.258"],["64084.40","10.002"],["64085.10","2.387"],["64085.30","0.000"],["64086.90","0.391"],["64091.90","0.563"],["64093.60","0.058"],["64094.60","0.001"],["64106.00","0.005"],["64108.20","0.001"],["64112.10","0.026"],["64168.60","0.000"],["64707.40","0.036"],["64707.50","0.162"],["64886.50","0.143"]],"b":[["1000.00","37.592"],["13566.70","0.966"],["13666.70","1.260"],["13759.90","0.140"],["13866.70","1.050"],["13961.60","0.112"],["13966.70","0.350"],["57660.00","0.313"],["61504.00","0.011"],["62785.40","0.020"],["63165.30","0.552"],["63201.80","1.101"],["63426.00","0.001"],["63741.20","0.000"],["63746.40","0.008"],["63954.10","22.520"],["63954.60","4.861"],["63971.70","0.000"],["63973.30","0.936"],["63974.00","0.016"],["63974.20","0.001"],["63989.30","0.000"],["63990.20","2.640"],["64023.00","2.948"],["64023.60","10.002"],["64028.40","1.898"],["64035.50","0.563"],["64036.70","0.000"],["64037.40","0.613"],["64037.80","0.798"],["64038.10","0.000"],["64039.00","1.249"],["64039.60","0.023"],["64040.30","0.060"],["64041.30","0.522"],["64045.10","0.002"],["64045.50","0.001"],["64054.00","0.043"],["64054.30","0.022"],["64055.00","0.004"],["64055.20","1.328"],["64056.70","0.031"],["64056.80","0.000"],["64059.40","0.109"],["64059.50","0.739"],["64060.40","0.234"],["64060.80","0.004"],["64060.90","0.009"],["64061.00","0.003"],["64061.10","0.000"],["64061.20","0.001"],["64061.30","0.003"],["64061.70","0.011"],["64063.80","0.035"],["64066.70","3.589"]],"e":"depthUpdate","ps":"BTCUSDT","pu":11165394345596,"s":"BTCUSDT","st":1,"u":11165394357682}
{"E":1785353520554,"T":1785353520552,"U":11165394357888,"a":[["64066.80","10.230"],["64066.90","0.032"],["64068.40","0.033"],["64069.10","0.007"],["64070.40","0.622"],["64070.80","0.121"],["64071.40","0.014"],["64071.50","0.001"],["64072.50","0.073"],["64072.60","0.002"],["64072.70","0.095"],["64073.00","0.001"],["64073.10","0.007"],["64073.30","0.102"],["64073.40","0.642"],["64073.50","0.634"],["64073.60","0.711"],["64073.70","2.344"],["64073.80","0.000"],["64074.30","0.939"],["64074.70","0.015"],["64075.10","0.265"],["64076.10","0.060"],["64076.60","0.374"],["64077.40","0.019"],["64078.40","0.170"],["64078.60","0.936"],["64079.60","0.562"],["64080.30","0.010"],["64081.10","0.312"],["64083.20","2.597"],["64083.60","10.006"],["64083.80","0.003"],["64084.20","0.001"],["64084.40","0.004"],["64084.60","0.021"],["64084.90","0.000"],["64085.00","0.537"],["64087.20","0.078"],["64092.20","0.005"],["64093.60","0.157"],["64096.00","1.137"],["64100.10","0.703"],["64115.50","0.001"],["64143.70","0.216"],["64266.70","0.351"],["64707.50","0.162"],["65322.60","0.108"],["65326.20","0.000"]],"b":[["1000.00","37.592"],["13566.70","0.840"],["13666.70","1.372"],["13759.90","0.028"],["13866.70","1.176"],["13960.70","0.000"],["13961.60","0.000"],["13966.70","0.476"],["51253.00","0.002"],["57660.00","0.313"],["61504.00","0.014"],["63137.70","2.315"],["63214.40","0.355"],["63233.80","0.236"],["63256.70","0.790"],["63426.00","0.001"],["63610.20","0.000"],["63669.50","0.689"],["63954.10","0.003"],["63954.60","1.694"],["63971.70","0.000"],["63973.30","0.936"],["63983.10","0.000"],["63987.30","0.382"],["64000.10","2.435"],["64003.30","2.001"],["64005.80","0.042"],["64009.70","0.319"],["64011.20","0.001"],["64023.60","0.002"],["64025.40","0.005"],["64025.60","1.171"],["64029.10","11.254"],["64029.90","0.433"],["64032.00","2.949"],["64035.50","0.001"],["64036.30","0.156"],["64038.00","0.564"],["64039.00","0.314"],["64041.40","0.935"],["64042.70","1.329"],["64045.10","0.000"],["64045.60","0.004"],["64045.70","0.322"],["64045.90","0.002"],["64046.00","0.121"],["64046.10","0.002"],["64046.20","0.001"],["64049.40","0.001"],["64050.40","0.314"],["64052.60","0.001"],["64054.00","0.023"],["64054.30","0.000"],["64054.80","0.096"],["64055.20","0.002"],["64055.30","0.000"],["64055.40","0.931"],["64056.00","0.192"],["64056.30","0.186"],["64056.70","0.912"],["64056.80","0.000"],["64057.20","0.081"],["64057.60","1.278"],["64058.50","0.313"],["64059.40","2.330"],["64059.50","0.179"],["64059.60","0.000"],["64060.30","0.027"],["64060.40","0.000"],["64060.70","0.998"],["64060.80","0.887"],["64060.90","0.827"],["64061.00","0.023"],["64062.80","0.000"],["64063.80","0.284"],["64065.00","0.044"],["64066.60","0.006"],["64066.70","4.445"]],"e":"depthUpdate","ps":"BTCUSDT","pu":11165394357682,"s":"BTCUSDT","st":1,"u":11165394381597}
{"E":1785353520656,"T":1785353520654,"U":11165394382585,"a":[["64066.80","10.181"],["64067.80","0.023"],["64067.90","0.000"],["64069.10","0.008"],["64071.90","0.146"],["64073.20","0.133"],["64073.30","0.927"],["64073.60","0.011"],["64083.90","0.003"],["64084.00","0.514"],["64084.20","0.001"],["64084.30","0.258"],["64084.40","0.002"],["64084.60","0.021"],["64084.90","0.002"],["64085.00","0.535"],["64102.20","0.008"],["64102.30","0.008"],["64102.40","0.023"],["64105.20","0.033"],["64123.50","0.003"],["64124.70","0.015"],["64129.00","0.002"],["64133.90","0.005"],["64134.30","0.482"],["64137.80","1.379"],["64144.30","5.238"],["64145.30","22.996"],["64147.40","1.363"],["64147.50","0.001"],["64162.80","0.002"],["64236.00","0.001"],["64236.30","0.003"],["64268.60","0.006"],["64268.70","0.002"],["64268.80","0.244"],["64298.10","0.000"],["64323.20","0.004"],["64458.90","0.000"],["64484.00","0.019"],["64620.00","0.390"],["64645.20","0.016"],["64707.50","0.162"],["65326.70","0.006"],["65348.10","0.022"]],"b":[["13566.70","0.826"],["13666.70","1.302"],["13759.90","0.000"],["13866.70","1.288"],["13959.90","0.112"],["13966.70","0.588"],["51253.00","0.000"],["57660.00","0.313"],["60863.30","0.006"],["62764.80","0.000"],["62796.10","0.000"],["63319.40","0.704"],["63368.40","0.781"],["63383.00","0.725"],["63409.00","0.159"],["63409.30","0.000"],["63426.00","0.001"],["63438.80","1.045"],["63445.30","1.043"],["63458.10","1.716"],["63468.50","0.002"],["63493.30","26.122"],["63561.50","0.078"],["63609.90","0.000"],["63622.70","0.002"],["63627.20","0.014"],["63643.90","0.004"],["63652.00","0.086"],["63669.50","0.785"],["63746.40","0.165"],["63786.20","0.000"],["63811.20","0.005"],["63945.70","0.000"],["63947.80","0.001"],["63948.10","0.006"],["63969.50","22.517"],["63969.80","0.238"],["63970.70","5.277"],["63970.80","0.009"],["63995.20","0.016"],["63998.10","0.003"],["64005.30","0.313"],["64014.50","0.091"],["64036.70","0.562"],["64038.00","0.002"],["64040.50","0.935"],["64041.40","0.000"],["64041.70","4.398"],["64043.60","0.293"],["64045.10","0.000"],["64045.40","0.001"],["64045.70","0.320"],["64045.80","0.002"],["64046.00","0.121"],["64046.10","0.002"],["64046.20","0.003"],["64048.50","0.000"],["64054.00","0.043"],["64055.40","0.050"],["64056.00","0.098"],["64056.20","0.515"],["64056.60","0.004"],["64056.70","0.031"],["64057.40","0.015"],["64057.60","0.824"],["64059.30","2.342"],["64059.50","0.159"],["64059.60","0.000"],["64060.90","0.830"],["64061.00","0.043"],["64061.30","0.000"],["64061.60","0.003"],["64062.40","0.005"],["64062.60","0.003"],["64063.90","0.003"],["64066.60","0.006"],["64066.70","4.423"]],"e":"depthUpdate","ps":"BTCUSDT","pu":11165394381597,"s":"BTCUSDT","st":1,"u":11165394420733}
{"E":1785353520758,"T":1785353520757,"U":11165394420885,"a":[["64066.80","10.025"],["64069.10","0.007"],["64073.40","0.548"],["64074.50","0.512"],["64082.30","0.159"],["64083.20","1.236"],["64083.60","0.006"],["64084.50","0.064"],["64084.90","0.314"],["64085.20","0.001"],["64085.30","0.000"],["64087.40","0.000"],["64110.20","0.002"],["64115.50","0.029"],["64124.70","0.000"],["64131.20","0.869"],["64143.70","0.228"],["64144.30","2.336"],["64145.30","0.000"],["64148.80","0.021"],["64200.80","0.000"],["64202.80","0.001"],["64204.80","3.341"],["64206.80","0.000"],["64208.80","3.237"],["64210.80","0.065"],["64212.80","0.002"],["64214.80","1.744"],["64216.80","0.000"],["64264.10","0.234"],["64540.90","0.212"],["64553.70","0.096"],["64707.50","4.478"],["65988.80","0.429"]],"b":[["1000.00","37.592"],["13566.70","0.812"],["13666.70","1.190"],["13766.70","0.014"],["13866.70","1.386"],["13959.90","0.000"],["13966.70","0.714"],["51248.00","0.004"],["51253.00","0.000"],["57660.00","0.313"],["61504.00","0.011"],["62778.70","0.002"],["63222.20","0.098"],["63260.80","0.241"],["63322.10","0.028"],["63368.40","1.562"],["63426.00","0.003"],["63656.70","0.684"],["63669.50","0.387"],["63682.30","1.277"],["63700.00","18.141"],["63726.00","0.008"],["63746.40","0.165"],["63764.40","0.002"],["63969.50","0.000"],["63969.80","0.246"],["63970.70","2.254"],["63970.80","0.001"],["63971.70","0.000"],["63973.30","0.936"],["63995.20","0.001"],["64007.70","0.015"],["64036.00","2.002"],["64037.80","1.155"],["64046.00","0.123"],["64046.20","0.001"],["64046.30","0.000"],["64046.50","0.375"],["64046.70","0.000"],["64054.00","0.043"],["64054.40","0.004"],["64056.40","1.343"],["64057.70","0.101"],["64059.50","0.159"],["64060.80","1.078"],["64060.90","0.830"],["64061.00","0.043"],["64066.70","4.463"]],"e":"depthUpdate","ps":"BTCUSDT","pu":11165394420733,"s":"BTCUSDT","st":1,"u":11165394434370}
{"E":1785353520860,"T":1785353520857,"U":11165394434435,"a":[["64066.80","10.578"],["64067.60","0.002"],["64075.80","0.957"],["64078.00","0.002"],["64078.50","0.429"],["64082.30","0.159"],["64082.40","3.586"],["64082.60","0.015"],["64084.30","2.258"],["64084.40","0.002"],["64084.50","0.066"],["64084.90","0.312"],["64085.60","0.106"],["64086.40","2.670"],["64086.50","10.007"],["64086.60","0.745"],["64086.80","0.003"],["64087.20","0.000"],["64093.30","0.746"],["64093.60","0.001"],["64097.60","0.004"],["64100.10","0.391"],["64102.70","0.859"],["64106.20","0.226"],["64115.50","0.001"],["64143.70","0.216"],["64147.50","22.997"],["64208.80","4.117"],["64210.80","0.945"],["64212.80","0.882"],["64214.80","2.624"],["64216.80","0.878"],["64522.10","0.011"],["64540.90","0.308"],["64553.70","0.192"],["64707.50","0.162"],["65000.00","153.504"]],"b":[["1000.00","37.592"],["13566.70","0.826"],["13666.70","1.064"],["13766.70","0.126"],["13866.70","1.274"],["13966.70","0.826"],["51248.00","0.000"],["57660.00","0.313"],["60839.70","0.008"],["61504.00","0.014"],["62753.30","1.433"],["63181.40","1.567"],["63357.40","0.000"],["63394.00","3.125"],["63426.00","0.001"],["63656.70","0.286"],["63669.50","0.785"],["63714.40","0.030"],["63912.70","0.011"],["63914.70","0.000"],["63916.70","0.001"],["63918.70","0.000"],["63920.70","0.000"],["63922.70","0.000"],["63924.70","0.000"],["63926.70","0.000"],["63928.70","0.004"],["63930.70","0.001"],["63932.70","0.001"],["63934.70","0.001"],["63971.70","22.517"],["63973.30","4.117"],["63981.80","0.001"],["63982.30","4.261"],["64027.00","2.004"],["64029.10","1.254"],["64029.90","0.121"],["64032.00","1.591"],["64036.00","0.002"],["64036.30","0.001"],["64037.80","0.798"],["64042.70","1.251"],["64045.70","0.322"],["64045.80","0.002"],["64045.90","0.002"],["64046.00","0.121"],["64050.00","0.038"],["64054.00","0.043"],["64056.10","0.098"],["64056.40","1.249"],["64057.70","0.007"],["64059.40","2.236"],["64060.90","0.830"],["64061.90","0.005"],["64062.00","0.007"],["64062.40","0.002"],["64062.60","0.000"],["64066.70","4.464"]],"e":"depthUpdate","ps":"BTCUSDT","pu":11165394434370,"s":"BTCUSDT","st":1,"u":11165394444757}
{"E":1785353520962,"T":1785353520960,"U":11165394444956,"a":[["64066.80","10.555"],["64069.10","0.007"],["64069.60","0.004"],["64073.30","0.928"],["64073.60","0.010"],["64074.80","0.000"],["64077.90","0.181"],["64080.00","0.356"],["64084.00","0.514"],["64084.20","0.003"],["64084.50","0.064"],["64086.40","1.166"],["64086.50","0.007"],["64137.50","0.075"],["64147.40","4.705"],["64172.90","0.000"],["64181.30","2.835"],["64208.80","3.237"],["64210.80","0.065"],["64212.80","0.002"],["64214.80","1.744"],["64216.80","0.000"],["64553.70","0.096"],["64681.90","0.000"],["64707.50","0.162"],["64753.10","0.002"],["64804.20","12.327"],["64824.20","0.348"],["64895.40","0.007"],["64966.50","0.004"],["65037.70","0.019"],["65108.90","0.000"],["65180.00","4.088"],["65251.20","0.000"],["65322.30","0.001"],["65326.70","0.003"]],"b":[["13566.70","0.812"],["13666.70","0.952"],["13766.70","0.252"],["13866.70","1.148"],["13966.70","0.952"],["51253.40","0.000"],["57660.00","0.313"],["61504.00","0.011"],["62760.70","0.795"],["62831.80","0.000"],["62903.00","0.000"],["62974.10","0.000"],["63045.30","0.000"],["63116.50","0.000"],["63187.60","1.891"],["63258.80","0.250"],["63329.90","0.938"],["63401.10","0.025"],["63426.00","0.004"],["63498.70","0.000"],["63520.10","0.000"],["63553.30","0.010"],["63864.90","0.000"],["63945.60","0.376"],["63957.60","0.481"],["63965.10","2.368"],["63971.70","0.000"],["63973.30","0.936"],["63989.30","0.000"],["63990.20","5.829"],["64005.80","0.159"],["64026.40","10.001"],["64027.00","0.004"],["64028.40","3.253"],["64034.40","0.017"],["64045.50","0.003"],["64045.70","0.320"],["64056.10","0.004"],["64056.20","0.609"],["64056.30","0.186"],["64059.40","2.330"],["64066.70","4.464"]],"e":"depthUpdate","ps":"BTCUSDT","pu":11165394444757,"s":"BTCUSDT","st":1,"u":11165394454813}
{"E":1785353521064,"T":1785353521063,"U":11165394454894,"a":[["64066.20","31.145"],["64066.30","0.003"],["64066.40","1.036"],["64066.50","0.902"],["64066.60","0.164"],["64066.70","14.846"],["64066.80","1.037"],["64066.90","0.030"],["64067.00","0.003"],["64067.50","0.015"],["64067.70","0.049"],["64068.40","0.325"],["64068.80","0.101"],["64069.00","0.004"],["64069.20","0.212"],["64070.30","0.554"],["64070.40","0.830"],["64070.50","0.006"],["64071.20","0.001"],["64071.30","0.135"],["64071.40","0.003"],["64071.60","0.096"],["64071.70","0.001"],["64071.80","0.648"],["64071.90","0.245"],["64072.30","1.250"],["64072.40","0.003"],["64072.50","0.000"],["64072.60","0.001"],["64073.00","0.001"],["64073.10","0.027"],["64073.20","0.093"],["64073.30","0.002"],["64073.40","0.563"],["64073.50","0.002"],["64073.60","0.020"],["64073.90","0.094"],["64074.30","0.004"],["64074.50","0.510"],["64074.70","10.015"],["64076.10","0.119"],["64076.40","0.377"],["64076.50","0.251"],["64076.60","0.257"],["64076.80","0.010"],["64077.30","0.010"],["64077.50","0.105"],["64077.80","0.606"],["64078.00","0.009"],["64078.10","0.436"],["64078.30","0.158"],["64078.50","0.272"],["64078.70","0.759"],["64079.00","0.154"],["64079.60","0.000"],["64080.10","1.249"],["64080.30","0.003"],["64080.70","0.002"],["64082.00","0.070"],["64082.20","0.065"],["64082.30","0.002"],["64082.40","3.588"],["64082.50","0.003"],["64082.60","0.012"],["64082.90","0.501"],["64083.40","0.540"],["64083.70","0.092"],["64083.80","0.003"],["64083.90","0.003"],["64084.20","0.001"],["64084.30","0.258"],["64084.40","0.000"],["64084.80","0.003"],["64085.10","2.389"],["64085.50","1.263"],["64085.60","0.105"],["64087.00","0.106"],["64087.50","1.102"],["64088.40","0.000"],["64088.80","0.011"],["64088.90","0.016"],["64089.50","0.123"],["64089.90","0.058"],["64090.30","0.679"],["64091.40","0.128"],["64091.90","0.598"],["64092.40","2.478"],["64092.50","0.321"],["64092.70","0.049"],["64093.50","0.000"],["64093.80","0.067"],["64093.90","0.122"],["64094.70","0.000"],["64094.90","0.403"],["64095.60","0.690"],["64096.00","1.080"],["64096.40","0.000"],["64096.50","0.003"],["64096.60","0.050"],["64098.00","0.006"],["64098.30","0.008"],["64098.80","0.053"],["64099.50","1.947"],["64102.60","1.575"],["64103.00","0.009"],["64103.50","0.001"],["64103.70","0.068"],["64104.20","0.017"],["64104.50","1.254"],["64104.70","0.095"],["64105.00","0.003"],["64106.60","0.005"],["64106.80","0.073"],["64107.90","0.002"],["64108.60","0.646"],["64109.10","0.007"],["64110.90","0.396"],["64112.20","0.375"],["64113.00","0.008"],["64115.40","0.179"],["64116.80","0.000"],["64117.60","0.034"],["64118.90","0.740"],["64121.40","0.210"],["64122.80","0.054"],["64128.10","0.682"],["64128.90","0.101"],["64130.90","1.614"],["64131.20","0.854"],["64132.40","0.015"],["64133.60","0.044"],["64137.10","0.151"],["64140.00","0.030"],["64147.50","0.001"],["64149.30","0.003"],["64152.90","1.103"],["64165.70","0.001"],["64172.80","0.667"],["64174.90","0.007"],["64199.70","0.001"],["64202.80","0.001"],["64204.80","3.341"],["64206.80","0.000"],["64208.80","4.117"],["64210.80","0.065"],["64212.80","0.002"],["64225.80","0.010"],["64236.30","0.000"],["64236.50","17.969"],["64264.10","0.000"],["64266.70","0.117"],["64277.50","0.000"],["64285.20","0.680"],["64451.20","1.176"],["64515.70","0.096"],["64540.80","0.136"],["64540.90","0.212"],["64547.70","0.000"],["64548.10","0.000"],["64548.60","0.000"],["64706.90","0.006"],["64707.40","0.038"],["64707.50","0.164"],["64838.10","0.771"],["64944.50","0.537"],["64968.50","0.000"],["65066.20","0.004"],["65073.90","0.004"],["65074.50","0.000"],["65081.40","0.701"],["65085.00","0.219"],["65219.40","0.005"],["65326.70","0.000"],["67261.90","0.000"],["67267.20","0.000"],["67910.80","0.038"],["70429.00","0.002"],["70432.70","0.000"],["91269.40","0.000"]],"b":[["1000.00","37.592"],["13566.70","0.812"],["13666.70","0.840"],["13766.70","0.364"],["13866.70","1.036"],["13966.10","0.014"],["13966.70","1.050"],["57660.00","0.313"],["61504.00","0.014"],["62414.30","0.000"],["62784.80","0.003"],["63265.90","2.622"],["63319.40","0.000"],["63368.40","2.265"],["63383.00","0.100"],["63425.40","0.004"],["63425.90","0.000"],["63426.00","0.004"],["63438.80","1.669"],["63693.50","0.862"],["63693.60","0.136"],["63746.40","0.175"],["63852.10","0.136"],["63940.30","3.065"],["63948.10","0.003"],["63948.30","0.546"],["63956.30","0.006"],["63958.10","0.851"],["63959.70","0.008"],["63965.20","0.000"],["63966.60","0.886"],["63966.80","0.311"],["63973.80","0.001"],["63974.00","0.000"],["63981.60","2.344"],["63984.90","0.022"],["63987.20","6.115"],["63990.20","2.640"],["63990.30","0.278"],["63990.50","0.517"],["63998.90","0.015"],["64003.40","0.000"],["64004.80","0.338"],["64005.80","0.042"],["64006.70","0.004"],["64007.20","0.510"],["64007.70","0.000"],["64011.00","0.122"],["64012.20","0.000"],["64012.40","0.369"],["64012.90","0.005"],["64013.00","0.000"],["64013.50","0.106"],["64014.50","0.000"],["64015.50","0.977"],["64016.20","0.000"],["64017.20","0.039"],["64018.40","0.060"],["64019.40","0.093"],["64021.50","0.033"],["64023.60","0.002"],["64024.90","0.004"],["64025.20","0.466"],["64025.30","0.080"],["64025.60","2.568"],["64026.00","0.002"],["64026.40","0.003"],["64028.40","1.808"],["64029.40","0.021"],["64029.60","0.006"],["64030.00","1.738"],["64032.30","0.001"],["64032.50","0.565"],["64033.60","0.085"],["64034.10","0.021"],["64034.50","0.323"],["64034.60","0.000"],["64034.90","0.001"],["64035.30","1.089"],["64035.50","0.001"],["64035.60","0.036"],["64036.30","0.000"],["64036.70","0.000"],["64037.10","0.003"],["64037.20","0.010"],["64037.40","0.336"],["64037.50","0.003"],["64037.90","0.001"],["64038.00","0.002"],["64038.60","0.005"],["64038.80","0.012"],["64039.80","0.010"],["64039.90","0.000"],["64040.00","0.601"],["64040.10","0.040"],["64040.30","0.003"],["64040.50","0.000"],["64041.10","0.687"],["64041.20","0.074"],["64041.80","0.835"],["64041.90","0.314"],["64042.00","0.003"],["64042.10","0.005"],["64042.30","0.094"],["64042.50","2.343"],["64042.60","0.616"],["64042.80","0.301"],["64042.90","0.007"],["64043.10","0.374"],["64043.40","0.096"],["64043.60","0.001"],["64044.00","0.157"],["64044.60","0.098"],["64045.10","0.000"],["64045.30","0.002"],["64045.40","2.341"],["64045.50","0.001"],["64045.60","0.612"],["64045.70","0.316"],["64045.80","0.096"],["64046.00","0.001"],["64046.40","0.032"],["64046.70","0.021"],["64047.00","0.407"],["64047.50","0.003"],["64047.70","0.312"],["64047.90","0.004"],["64048.10","0.094"],["64048.20","0.095"],["64048.40","0.002"],["64048.70","0.000"],["64049.10","0.470"],["64049.20","0.260"],["64049.30","0.002"],["64049.60","0.002"],["64049.90","0.325"],["64050.10","0.001"],["64050.40","0.002"],["64050.70","0.314"],["64051.10","0.125"],["64051.30","2.452"],["64051.40","0.013"],["64051.60","0.220"],["64052.10","0.001"],["64052.30","0.216"],["64052.50","1.726"],["64053.30","0.005"],["64053.50","0.001"],["64053.60","0.004"],["64053.70","0.000"],["64053.80","1.002"],["64053.90","0.226"],["64054.00","2.363"],["64054.20","0.002"],["64054.40","0.004"],["64054.70","0.003"],["64054.80","0.002"],["64054.90","0.097"],["64055.10","0.001"],["64055.20","0.002"],["64056.00","0.098"],["64056.20","0.051"],["64056.30","0.183"],["64056.40","0.000"],["64056.60","0.002"],["64056.80","0.000"],["64057.50","0.003"],["64057.60","0.560"],["64057.70","0.022"],["64057.80","0.002"],["64058.00","0.001"],["64058.10","0.007"],["64058.50","0.001"],["64058.80","0.005"],["64058.90","1.041"],["64059.30","0.014"],["64059.40","1.340"],["64059.60","0.000"],["64059.90","0.157"],["64060.20","0.000"],["64060.30","0.004"],["64060.40","0.000"],["64060.60","0.011"],["64060.70","0.986"],["64060.80","0.006"],["64060.90","0.553"],["64061.00","0.022"],["64061.10","0.000"],["64061.30","0.000"],["64061.40","0.001"],["64061.50","0.003"],["64061.70","0.001"],["64061.90","0.001"],["64062.00","0.004"],["64062.40","0.001"],["64062.50","0.001"],["64062.90","0.083"],["64063.70","0.000"],["64063.80","0.001"],["64064.50","0.000"],["64064.60","0.001"],["64064.80","0.001"],["64065.00","0.000"],["64065.40","0.016"],["64066.00","0.000"],["64066.10","0.007"],["64066.50","0.000"],["64066.60","0.000"],["64066.70","0.000"]],"e":"depthUpdate","ps":"BTCUSDT","pu":11165394454813,"s":"BTCUSDT","st":1,"u":11165394474936}
{"E":1785353521166,"T":1785353521165,"U":11165394474943,"a":[["64063.20","20.283"],["64063.30","0.005"],["64063.40","0.001"],["64063.50","0.002"],["64063.60","0.000"],["64063.70","0.313"],["64063.90","0.002"],["64064.00","0.337"],["64064.10","0.000"],["64064.20","0.000"],["64064.30","0.002"],["64064.40","1.345"],["64064.50","0.002"],["64064.60","0.000"],["64064.70","0.000"],["64064.80","0.001"],["64064.90","0.000"],["64065.00","0.003"],["64065.10","0.000"],["64065.20","0.001"],["64065.30","0.421"],["64065.40","0.000"],["64065.50","0.000"],["64065.60","0.002"],["64065.70","0.003"],["64065.80","0.000"],["64065.90","0.002"],["64066.00","0.026"],["64066.10","2.909"],["64066.20","1.258"],["64066.30","0.001"],["64066.40","0.017"],["64066.50","0.384"],["64066.60","0.001"],["64066.70","4.850"],["64066.80","0.747"],["64066.90","0.030"],["64067.00","0.000"],["64067.10","0.004"],["64067.20","0.006"],["64067.30","0.000"],["64067.50","0.005"],["64067.60","0.339"],["64067.70","0.049"],["64067.80","0.001"],["64068.00","0.097"],["64068.10","0.017"],["64068.20","0.117"],["64068.30","0.000"],["64068.40","0.061"],["64068.50","0.295"],["64068.80","0.002"],["64069.00","1.174"],["64069.10","0.008"],["64069.20","0.191"],["64069.60","0.016"],["64069.70","0.611"],["64069.80","0.243"],["64069.90","0.002"],["64070.00","0.025"],["64070.10","0.397"],["64070.30","0.008"],["64070.40","2.094"],["64070.60","0.000"],["64070.80","0.121"],["64071.00","0.001"],["64071.30","0.000"],["64071.40","0.274"],["64071.50","0.777"],["64071.60","10.096"],["64071.70","0.003"],["64071.80","0.002"],["64071.90","0.001"],["64072.00","0.007"],["64072.20","0.002"],["64072.40","0.013"],["64072.50","1.031"],["64072.60","0.001"],["64072.70","0.111"],["64072.80","0.025"],["64072.90","0.002"],["64073.00","0.239"],["64073.10","0.026"],["64073.20","0.003"],["64073.40","0.001"],["64073.50","0.002"],["64073.60","0.706"],["64074.00","0.744"],["64074.20","0.313"],["64074.30","0.003"],["64074.40","0.064"],["64074.50","0.414"],["64074.60","10.586"],["64074.70","0.015"],["64074.80","0.000"],["64074.90","0.003"],["64075.20","0.502"],["64075.40","0.554"],["64075.70","1.917"],["64075.80","0.957"],["64076.00","0.006"],["64076.10","0.118"],["64076.20","0.304"],["64076.40","0.376"],["64076.50","0.013"],["64076.60","0.268"],["64076.70","0.002"],["64077.00","1.753"],["64077.20","0.092"],["64078.00","0.002"],["64078.10","0.168"],["64078.30","0.161"],["64078.40","0.170"],["64078.50","0.793"],["64078.60","0.936"],["64078.80","1.869"],["64079.20","0.346"],["64079.30","0.000"],["64079.40","0.030"],["64079.50","0.384"],["64079.60","0.312"],["64079.70","0.945"],["64079.80","2.342"],["64079.90","0.651"],["64080.00","0.339"],["64080.20","0.010"],["64080.40","1.114"],["64080.50","0.070"],["64080.60","0.000"],["64080.70","0.002"],["64080.80","0.001"],["64080.90","0.005"],["64081.20","0.009"],["64081.60","0.703"],["64081.80","0.011"],["64082.00","0.070"],["64082.40","3.960"],["64082.50","0.034"],["64082.70","3.566"],["64082.80","0.013"],["64082.90","0.490"],["64083.40","0.539"],["64083.50","0.014"],["64083.80","0.003"],["64083.90","0.003"],["64084.00","0.549"],["64084.10","0.339"],["64084.30","0.101"],["64084.50","0.049"],["64084.60","0.001"],["64084.70","0.821"],["64084.90","0.000"],["64085.00","0.692"],["64085.20","0.012"],["64085.70","0.000"],["64085.90","0.002"],["64086.00","0.001"],["64086.50","1.662"],["64086.80","0.060"],["64087.00","0.095"],["64087.50","1.102"],["64088.40","0.000"],["64088.80","0.042"],["64088.90","0.016"],["64089.10","1.258"],["64089.20","0.618"],["64089.50","0.063"],["64089.60","1.720"],["64089.70","0.318"],["64089.80","0.003"],["64089.90","0.001"],["64090.70","0.010"],["64090.90","0.899"],["64091.20","0.012"],["64091.30","0.009"],["64091.40","0.139"],["64091.50","0.684"],["64091.90","0.563"],["64092.10","0.000"],["64092.40","1.343"],["64092.50","0.313"],["64092.70","0.109"],["64093.20","0.000"],["64093.50","1.952"],["64093.60","0.050"],["64093.90","0.002"],["64094.00","2.707"],["64094.20","0.017"],["64094.90","0.392"],["64095.00","0.000"],["64095.20","0.008"],["64095.60","0.695"],["64095.70","0.123"],["64096.20","0.000"],["64096.60","0.001"],["64096.70","0.041"],["64096.80","0.079"],["64096.90","0.016"],["64097.00","1.221"],["64097.50","0.204"],["64097.80","0.002"],["64098.00","0.006"],["64098.50","0.019"],["64098.80","0.085"],["64099.10","0.000"],["64099.30","0.005"],["64099.80","0.002"],["64100.00","2.644"],["64100.30","0.004"],["64100.50","0.635"],["64100.60","0.503"],["64100.90","0.049"],["64101.10","0.006"],["64101.40","0.000"],["64101.80","0.997"],["64102.10","0.005"],["64103.00","0.079"],["64103.20","0.004"],["64103.70","0.064"],["64104.30","0.029"],["64104.50","1.250"],["64104.70","0.095"],["64105.30","1.460"],["64105.90","0.003"],["64106.60","0.001"],["64106.80","0.135"],["64107.30","0.081"],["64107.60","0.235"],["64107.80","0.235"],["64107.90","0.001"],["64108.20","0.000"],["64108.50","0.000"],["64109.90","0.026"],["64110.00","0.034"],["64111.10","0.077"],["64111.30","0.034"],["64113.00","0.008"],["64113.40","0.016"],["64114.90","0.504"],["64117.10","0.037"],["64117.50","2.945"],["64118.90","0.715"],["64119.60","0.041"],["64121.40","0.000"],["64121.60","0.024"],["64124.50","0.001"],["64126.20","0.501"],["64127.30","0.042"],["64128.40","0.000"],["64129.90","0.037"],["64130.30","1.249"],["64130.90","0.762"],["64132.40","0.000"],["64132.60","0.026"],["64132.90","0.093"],["64140.50","0.590"],["64141.50","0.000"],["64143.70","0.041"],["64146.00","0.067"],["64147.40","1.363"],["64151.10","1.234"],["64152.10","0.541"],["64152.50","3.125"],["64154.90","0.137"],["64158.50","0.019"],["64160.00","0.823"],["64163.50","0.835"],["64165.20","0.000"],["64167.60","0.211"],["64168.50","0.029"],["64177.50","0.500"],["64178.10","3.902"],["64190.00","0.050"],["64208.80","3.237"],["64236.20","0.001"],["64240.00","2.320"],["64247.50","1.947"],["64247.70","0.007"],["64249.00","0.387"],["64265.00","0.495"],["64265.40","0.002"],["64266.00","2.464"],["64266.20","0.001"],["64266.70","0.000"],["64288.00","1.957"],["64288.30","10.747"],["64292.00","0.000"],["64319.50","0.110"],["64320.00","0.472"],["64330.80","0.351"],["64332.30","0.540"],["64332.40","0.539"],["64335.90","0.110"],["64383.60","0.091"],["64386.30","0.299"],["64386.50","0.299"],["64387.20","0.000"],["64400.00","12.122"],["64486.00","0.412"],["64489.00","0.335"],["64502.90","0.192"],["64515.70","0.000"],["64527.50","0.003"],["64540.00","0.044"],["64540.80","0.040"],["64575.70","0.110"],["64604.40","0.108"],["64629.70","0.098"],["64703.80","0.000"],["64706.50","0.011"],["64706.90","0.000"],["64707.40","0.036"],["64707.50","0.162"],["64804.20","13.252"],["64902.10","0.769"],["65063.20","0.012"],["65066.20","0.012"],["65070.50","0.001"],["65080.10","0.004"],["65081.40","0.699"],["65344.40","0.003"],["65347.50","0.003"],["70472.80","0.003"],["91518.80","0.003"]],"b":[["1000.00","37.592"],["13563.10","0.112"],["13566.10","0.014"],["13566.70","0.686"],["13666.70","0.714"],["13763.10","0.112"],["13766.10","0.014"],["13866.70","0.910"],["13963.10","0.112"],["13965.70","0.014"],["57656.70","0.002"],["57659.10","0.000"],["57660.00","0.311"],["60839.70","0.006"],["60859.90","0.012"],["62781.90","0.003"],["63422.50","0.000"],["63425.30","0.000"],["63425.40","0.000"],["63426.00","0.076"],["63648.00","0.006"],["63680.00","3.924"],["63719.50","0.001"],["63730.70","0.001"],["63746.30","0.000"],["63760.00","0.463"],["63829.10","0.000"],["63829.30","0.179"],["63829.70","0.002"],["63840.00","1.702"],["63851.70","0.144"],["63852.10","0.019"],["63855.30","0.006"],["63886.40","0.358"],["63889.60","0.001"],["63893.10","0.001"],["63899.50","0.001"],["63907.10","0.658"],["63909.10","0.001"],["63911.10","0.006"],["63913.10","0.000"],["63914.80","0.082"],["63914.90","2.038"],["63915.10","0.000"],["63917.10","0.274"],["63919.10","0.001"],["63920.00","0.848"],["63921.20","2.998"],["63921.30","0.000"],["63923.10","3.508"],["63923.30","4.407"],["63923.50","0.538"],["63925.10","0.001"],["63926.20","1.931"],["63927.10","0.001"],["63928.00","0.030"],["63929.10","1.482"],["63933.30","2.217"],["63933.70","0.000"],["63935.80","0.623"],["63941.50","0.002"],["63945.30","22.391"],["63945.40","5.251"],["63946.10","3.239"],["63947.40","0.502"],["63948.10","0.003"],["63949.70","0.002"],["63950.10","0.000"],["63951.70","0.023"],["63952.00","0.706"],["63957.10","0.012"],["63963.40","0.018"],["63966.10","0.278"],["63975.40","0.500"],["63978.10","0.003"],["63987.20","3.145"],["63990.30","0.000"],["63990.70","0.000"],["63993.30","0.457"],["63993.80","0.001"],["63995.90","0.093"],["63998.10","0.003"],["63998.60","0.474"],["63998.90","0.000"],["63999.50","0.000"],["64000.00","10.986"],["64000.10","2.450"],["64001.50","0.004"],["64003.40","0.210"],["64004.80","0.313"],["64005.20","0.000"],["64005.50","0.004"],["64005.80","0.028"],["64008.70","0.000"],["64008.80","0.026"],["64009.40","0.553"],["64009.50","0.532"],["64009.60","1.195"],["64010.00","0.381"],["64011.60","0.003"],["64011.80","0.000"],["64012.90","0.001"],["64013.30","0.001"],["64014.00","0.092"],["64014.10","0.573"],["64014.50","0.000"],["64015.20","0.000"],["64015.60","10.001"],["64015.70","2.683"],["64016.30","0.096"],["64016.60","0.064"],["64016.70","0.067"],["64017.20","0.129"],["64018.30","0.097"],["64018.40","0.000"],["64018.60","0.036"],["64018.90","0.133"],["64019.10","2.472"],["64019.30","0.617"],["64019.40","0.003"],["64019.50","0.156"],["64019.70","0.000"],["64019.90","2.696"],["64020.20","0.048"],["64020.80","0.526"],["64021.40","1.084"],["64022.10","1.000"],["64022.40","0.010"],["64022.90","0.001"],["64023.00","2.949"],["64023.30","0.304"],["64023.50","0.000"],["64023.60","0.005"],["64024.00","0.030"],["64024.20","0.501"],["64024.90","0.001"],["64025.40","0.045"],["64025.60","1.171"],["64026.10","0.004"],["64026.60","0.120"],["64026.80","0.028"],["64026.90","0.001"],["64027.10","0.060"],["64028.40","1.808"],["64028.60","0.122"],["64028.80","0.223"],["64029.20","0.159"],["64029.30","0.013"],["64029.40","0.000"],["64029.50","0.104"],["64029.60","0.294"],["64029.70","0.562"],["64029.90","0.001"],["64030.30","0.935"],["64030.70","0.023"],["64031.10","0.020"],["64031.40","0.082"],["64031.70","0.135"],["64031.80","0.674"],["64032.20","0.090"],["64032.30","0.001"],["64032.50","0.003"],["64032.60","0.004"],["64032.80","0.032"],["64033.00","0.316"],["64033.10","2.325"],["64033.30","0.089"],["64033.40","0.001"],["64033.60","0.005"],["64033.80","0.002"],["64033.90","0.000"],["64034.10","0.032"],["64034.50","0.358"],["64034.60","0.021"],["64034.70","0.117"],["64035.30","0.417"],["64035.40","0.324"],["64035.50","0.001"],["64035.60","0.001"],["64036.90","0.003"],["64037.20","0.003"],["64037.30","0.539"],["64037.40","0.356"],["64037.50","0.046"],["64037.60","0.002"],["64037.70","0.082"],["64037.80","0.847"],["64038.40","0.393"],["64038.80","0.000"],["64038.90","0.293"],["64039.00","0.002"],["64039.40","0.336"],["64039.50","0.053"],["64039.60","0.296"],["64040.00","0.580"],["64040.50","0.011"],["64040.60","0.045"],["64040.80","1.099"],["64040.90","0.599"],["64041.00","0.340"],["64041.10","0.648"],["64041.20","0.002"],["64041.30","0.543"],["64041.40","0.000"],["64041.70","4.518"],["64041.80","1.023"],["64041.90","0.314"],["64042.20","0.004"],["64042.30","0.094"],["64042.50","2.340"],["64042.80","0.207"],["64042.90","0.101"],["64043.20","0.540"],["64044.00","0.037"],["64044.20","0.002"],["64044.30","1.821"],["64044.40","0.713"],["64044.50","0.001"],["64045.00","0.005"],["64045.30","0.021"],["64045.40","2.343"],["64045.60","0.004"],["64045.80","0.927"],["64045.90","0.072"],["64046.60","0.311"],["64046.70","0.000"],["64047.10","0.659"],["64048.10","0.000"],["64048.20","0.099"],["64048.60","0.322"],["64048.70","0.000"],["64049.20","0.001"],["64049.30","0.002"],["64049.50","0.204"],["64049.60","0.005"],["64049.70","0.467"],["64049.90","0.314"],["64050.00","0.006"],["64050.20","0.000"],["64050.70","0.060"],["64050.90","0.061"],["64051.00","0.242"],["64051.10","0.125"],["64051.20","0.671"],["64051.30","0.049"],["64051.40","0.106"],["64051.50","0.311"],["64051.60","0.126"],["64051.90","0.001"],["64052.00","0.025"],["64052.10","0.001"],["64052.30","0.001"],["64052.40","0.003"],["64052.50","1.726"],["64052.60","2.341"],["64052.80","0.034"],["64052.90","0.001"],["64053.00","0.000"],["64053.20","0.181"],["64053.30","0.003"],["64053.60","0.003"],["64053.70","0.014"],["64053.80","1.000"],["64053.90","0.001"],["64054.00","0.005"],["64054.10","1.326"],["64054.20","0.883"],["64054.30","1.008"],["64054.40","0.024"],["64054.60","0.022"],["64054.70","0.003"],["64054.90","0.097"],["64055.00","0.008"],["64055.10","0.803"],["64055.20","0.739"],["64055.30","0.000"],["64055.40","0.003"],["64056.00","0.007"],["64056.10","0.007"],["64056.30","0.004"],["64056.40","0.003"],["64056.50","0.000"],["64056.60","0.004"],["64056.70","0.030"],["64056.80","0.000"],["64056.90","0.002"],["64057.00","0.566"],["64057.20","0.081"],["64057.30","0.002"],["64057.40","0.001"],["64057.50","0.003"],["64057.60","0.009"],["64057.70","0.002"],["64057.90","0.002"],["64058.00","0.002"],["64058.10","0.007"],["64058.20","0.000"],["64058.40","0.002"],["64058.50","0.001"],["64058.60","0.002"],["64058.70","0.076"],["64058.90","0.011"],["64059.00","0.000"],["64059.30","0.082"],["64059.40","0.000"],["64059.50","0.003"],["64059.60","0.000"],["64059.80","0.001"],["64059.90","0.198"],["64060.00","0.003"],["64060.30","0.002"],["64060.50","0.002"],["64060.60","0.001"],["64060.70","0.008"],["64060.80","0.003"],["64060.90","0.007"],["64061.00","0.004"],["64061.10","0.000"],["64061.40","0.000"],["64061.50","0.001"],["64061.60","0.001"],["64061.80","0.000"],["64062.00","0.001"],["64062.10","0.000"],["64062.20","0.002"],["64062.30","0.001"],["64062.50","0.002"],["64062.70","0.000"],["64062.90","0.000"],["64063.00","0.000"],["64063.10","0.446"],["64063.30","0.000"],["64063.40","0.000"],["64063.50","0.000"],["64063.80","0.000"],["64063.90","0.000"],["64064.00","0.000"],["64064.10","0.000"],["64064.20","0.000"],["64064.40","0.000"],["64064.60","0.000"],["64064.80","0.000"],["64065.20","0.000"],["64065.40","0.000"],["64065.70","0.000"],["64065.80","0.000"],["64066.10","0.000"]],"e":"depthUpdate","ps":"BTCUSDT","pu":11165394474936,"s":"BTCUSDT","st":1,"u":11165394506967}
{"E":1785353521268,"T":1785353521267,"U":11165394507037,"a":[["64063.20","12.809"],["64063.30","0.026"],["64063.90","0.002"],["64064.30","0.007"],["64064.40","1.273"],["64064.50","0.001"],["64064.80","0.008"],["64064.90","0.000"],["64065.00","0.003"],["64065.20","0.001"],["64065.50","0.015"],["64065.60","0.042"],["64065.70","0.193"],["64065.80","1.343"],["64065.90","0.012"],["64066.00","0.078"],["64066.10","2.886"],["64066.20","1.258"],["64066.80","0.736"],["64067.20","0.017"],["64067.60","0.488"],["64068.20","0.000"],["64068.60","0.935"],["64068.90","0.548"],["64069.00","0.612"],["64069.70","0.606"],["64070.10","0.395"],["64070.30","0.001"],["64070.40","0.911"],["64070.70","0.117"],["64071.10","0.001"],["64071.30","0.000"],["64071.40","0.254"],["64071.50","0.001"],["64071.60","0.098"],["64072.00","0.002"],["64072.20","0.002"],["64072.60","0.094"],["64072.80","0.014"],["64072.90","0.548"],["64073.00","0.239"],["64073.10","0.026"],["64073.50","0.114"],["64073.60","0.789"],["64073.90","0.656"],["64074.10","2.501"],["64074.80","0.138"],["64074.90","0.159"],["64075.00","0.152"],["64076.00","0.006"],["64078.20","0.156"],["64078.40","0.327"],["64078.70","0.591"],["64079.50","0.382"],["64079.70","0.945"],["64079.80","2.342"],["64079.90","0.691"],["64080.00","0.339"],["64080.20","0.010"],["64080.60","0.000"],["64080.80","0.001"],["64083.90","0.003"],["64086.20","0.165"],["64086.70","0.000"],["64086.80","0.003"],["64088.20","0.000"],["64088.90","0.016"],["64091.60","2.403"],["64092.60","0.026"],["64095.40","0.005"],["64104.30","0.069"],["64104.40","2.342"],["64104.90","0.018"],["64106.10","0.000"],["64106.70","0.001"],["64106.80","0.135"],["64107.30","0.080"],["64109.40","0.248"],["64123.50","0.000"],["64132.40","0.013"],["64140.20","0.011"],["64154.00","4.536"],["64156.30","23.354"],["64160.00","0.840"],["64161.60","0.008"],["64165.10","0.071"],["64195.70","2.162"],["64195.80","0.000"],["64240.00","2.337"],["64265.60","0.248"],["64291.30","1.357"],["64320.00","0.489"],["64400.00","12.139"],["64480.00","0.855"],["64703.80","0.002"],["64804.10","1.834"],["64804.20","11.418"],["64868.20","3.815"],["64868.30","4.578"]],"b":[["13563.10","0.238"],["13566.70","0.574"],["13666.70","0.588"],["13763.10","0.224"],["13866.70","0.798"],["13963.10","0.224"],["51253.00","0.002"],["57656.70","0.002"],["61504.00","0.011"],["62013.80","1.000"],["62653.20","0.300"],["63239.80","2.668"],["63259.20","8.616"],["63291.20","35.986"],["63422.50","0.000"],["63426.00","0.004"],["63680.00","3.941"],["63702.80","0.001"],["63709.50","0.455"],["63742.70","0.001"],["63760.00","0.480"],["63832.50","0.179"],["63840.00","1.719"],["63851.70","0.144"],["63886.40","0.357"],["63889.60","0.000"],["63895.80","0.076"],["63905.80","0.000"],["63920.00","0.865"],["63945.30","0.000"],["63947.10","0.001"],["63949.10","0.000"],["63950.00","0.270"],["63952.60","0.027"],["63966.10","0.000"],["63966.80","0.033"],["63967.70","0.000"],["63969.50","22.391"],["63969.80","0.238"],["63981.80","0.040"],["63982.00","0.498"],["63982.30","4.222"],["63987.00","0.000"],["63990.30","0.278"],["63998.30","0.100"],["64000.00","11.003"],["64002.20","0.040"],["64003.40","0.488"],["64008.60","0.422"],["64009.00","0.156"],["64011.80","0.039"],["64014.60","1.250"],["64014.90","0.003"],["64015.60","0.001"],["64015.70","1.190"],["64016.30","0.002"],["64017.20","0.115"],["64018.30","0.058"],["64019.40","0.003"],["64020.80","0.527"],["64021.40","1.085"],["64022.00","0.004"],["64023.00","2.951"],["64023.60","0.003"],["64025.80","10.522"],["64026.40","0.017"],["64027.80","0.000"],["64028.40","3.163"],["64030.30","0.000"],["64032.60","0.004"],["64034.50","0.378"],["64034.60","0.021"],["64035.90","0.935"],["64037.40","0.336"],["64037.70","0.000"],["64040.20","0.073"],["64040.80","1.097"],["64041.00","0.340"],["64041.30","0.543"],["64041.40","0.000"],["64041.60","0.008"],["64041.70","4.518"],["64042.10","0.005"],["64045.80","0.097"],["64047.20","0.005"],["64048.10","0.000"],["64048.20","0.095"],["64049.20","1.250"],["64049.30","2.342"],["64049.60","0.003"],["64050.40","0.003"],["64050.90","0.155"],["64051.10","0.125"],["64051.20","1.174"],["64051.30","0.049"],["64052.40","0.099"],["64052.50","1.726"],["64052.70","0.882"],["64052.80","0.179"],["64053.60","0.097"],["64053.70","0.014"],["64053.80","1.015"],["64054.00","0.003"],["64054.40","0.004"],["64054.90","0.097"],["64055.10","0.815"],["64055.20","2.358"],["64055.30","0.254"],["64055.40","0.617"],["64056.10","0.017"],["64056.70","0.030"],["64056.90","0.010"],["64057.00","0.001"],["64057.10","0.887"],["64057.20","0.297"],["64057.30","1.496"],["64057.50","0.002"],["64059.10","0.774"],["64059.90","0.196"],["64060.00","0.171"],["64061.60","0.002"],["64061.70","0.041"],["64063.00","0.001"],["64063.10","2.387"]],"e":"depthUpdate","ps":"BTCUSDT","pu":11165394506967,"s":"BTCUSDT","st":1,"u":11165394522995}
{"E":1785353521370,"T":1785353521369,"U":11165394523064,"a":[["64063.20","16.957"],["64063.30","0.005"],["64063.60","0.022"],["64063.70","0.000"],["64064.40","0.772"],["64064.80","0.001"],["64065.20","0.008"],["64065.60","0.002"],["64065.70","0.117"],["64065.80","1.249"],["64065.90","0.011"],["64066.00","0.078"],["64066.20","1.258"],["64066.70","4.845"],["64069.20","0.097"],["64069.70","0.314"],["64070.70","0.000"],["64072.20","0.179"],["64072.70","0.228"],["64072.90","0.654"],["64073.30","0.092"],["64073.50","0.461"],["64073.90","0.755"],["64074.00","0.724"],["64074.30","0.159"],["64074.50","0.739"],["64074.60","10.706"],["64074.70","0.035"],["64074.80","0.444"],["64075.00","0.444"],["64076.20","0.306"],["64076.60","0.175"],["64077.00","1.647"],["64077.20","0.002"],["64077.30","0.012"],["64077.60","0.005"],["64078.30","0.005"],["64078.40","0.484"],["64078.70","0.589"],["64078.80","1.713"],["64078.90","0.296"],["64079.00","0.004"],["64080.00","3.404"],["64080.10","10.008"],["64080.80","0.003"],["64081.10","0.312"],["64082.40","3.960"],["64084.60","0.001"],["64097.80","0.004"],["64103.30","1.986"],["64103.40","0.003"],["64106.80","0.073"],["64109.40","0.211"],["64117.50","2.735"],["64119.00","0.159"],["64119.40","0.176"],["64121.00","0.004"],["64123.70","1.485"],["64123.80","0.023"],["64124.00","0.234"],["64144.10","1.485"],["64144.20","0.656"],["64154.00","1.209"],["64156.30","0.000"],["64156.80","3.925"],["64158.50","23.373"],["64232.30","0.135"],["64263.10","0.111"],["64286.10","1.127"],["64522.00","0.020"],["64703.80","0.000"],["65333.60","0.023"],["65344.40","0.006"],["65390.00","0.120"]],"b":[["1000.00","37.592"],["13561.60","0.000"],["13563.00","0.000"],["13563.10","0.350"],["13564.80","0.000"],["13566.70","0.560"],["13666.70","0.476"],["13763.10","0.350"],["13863.10","0.028"],["13866.70","0.672"],["13963.10","0.322"],["13966.70","1.022"],["51253.00","0.000"],["57656.70","0.002"],["57729.20","0.006"],["60735.20","3.001"],["60859.90","0.014"],["60863.30","0.000"],["61374.50","2.000"],["61500.50","0.003"],["63230.30","1.738"],["63422.50","0.000"],["63561.40","0.204"],["63746.40","0.165"],["63921.60","0.000"],["63940.60","1.486"],["63940.70","0.000"],["63945.40","1.719"],["63960.90","1.485"],["63961.00","0.000"],["63970.70","5.257"],["64014.60","1.249"],["64017.20","0.025"],["64018.50","0.002"],["64020.80","0.526"],["64024.30","0.090"],["64025.20","10.466"],["64025.60","2.655"],["64025.80","0.522"],["64028.40","1.808"],["64029.80","0.001"],["64033.10","2.325"],["64034.50","0.343"],["64037.80","0.798"],["64038.80","0.049"],["64041.60","0.043"],["64042.20","0.006"],["64042.30","0.000"],["64042.50","2.340"],["64042.70","1.251"],["64044.40","0.522"],["64045.70","0.316"],["64048.00","0.766"],["64049.30","2.344"],["64049.40","0.157"],["64050.80","0.311"],["64051.10","0.123"],["64052.40","0.412"],["64052.70","0.001"],["64053.10","0.032"],["64053.30","0.001"],["64054.50","0.001"],["64054.60","0.000"],["64054.80","0.002"],["64054.90","0.097"],["64055.00","0.030"],["64055.20","2.344"],["64055.30","0.234"],["64055.40","0.206"],["64055.50","0.589"],["64055.60","0.000"],["64056.00","0.029"],["64057.20","0.081"],["64057.30","0.921"],["64057.40","0.001"],["64057.50","0.016"],["64057.60","0.647"],["64057.70","0.000"],["64061.00","0.002"],["64063.10","2.346"]],"e":"depthUpdate","ps":"BTCUSDT","pu":11165394522995,"s":"BTCUSDT","st":1,"u":11165394532315}
{"E":1785353521472,"T":1785353521471,"U":11165394532410,"a":[["64063.20","16.555"],["64063.60","0.000"],["64064.00","0.431"],["64064.20","0.000"],["64064.40","1.691"],["64064.50","0.002"],["64065.00","0.014"],["64065.70","0.003"],["64065.80","0.000"],["64066.00","0.006"],["64066.20","1.050"],["64066.50","0.001"],["64066.80","0.724"],["64068.60","0.000"],["64068.90","0.002"],["64069.70","0.860"],["64069.80","0.944"],["64072.00","0.002"],["64072.20","0.179"],["64072.70","0.095"],["64073.50","0.421"],["64073.60","0.221"],["64074.50","0.896"],["64074.70","0.191"],["64074.80","0.680"],["64074.90","0.327"],["64075.00","0.561"],["64076.20","0.540"],["64077.90","0.082"],["64078.10","0.000"],["64078.50","0.625"],["64078.70","0.295"],["64080.00","1.900"],["64080.10","0.008"],["64080.80","0.001"],["64081.00","0.015"],["64081.20","0.009"],["64081.30","0.003"],["64081.60","0.623"],["64081.80","0.013"],["64084.30","0.101"],["64086.40","2.676"],["64088.50","10.010"],["64091.30","0.001"],["64091.60","2.403"],["64091.90","0.571"],["64098.50","0.003"],["64106.80","0.135"],["64196.70","0.211"],["64209.20","0.000"],["64211.20","2.531"],["64213.20","0.004"],["64215.20","0.000"],["64288.00","0.410"],["64288.30","0.000"],["64316.90","0.156"],["64703.80","0.002"],["64864.50","0.763"],["64868.20","3.815"],["64868.30","3.815"],["65333.60","0.020"],["65344.40","0.009"]],"b":[["1000.00","37.592"],["13563.10","0.476"],["13666.70","0.350"],["13763.10","0.462"],["13863.10","0.140"],["13866.70","0.560"],["13966.70","0.910"],["57656.70","0.002"],["57656.80","0.004"],["57729.20","0.004"],["60095.90","4.000"],["61500.50","0.000"],["62397.60","0.001"],["62773.90","0.011"],["63262.30","0.789"],["63294.30","1.578"],["63422.50","0.002"],["63721.60","1.468"],["63948.00","0.002"],["63969.50","0.000"],["63970.70","2.254"],["63971.70","22.391"],["63973.30","4.099"],["63984.90","0.022"],["63987.20","3.145"],["63990.30","0.000"],["64003.40","0.210"],["64008.60","0.539"],["64011.00","0.400"],["64025.20","0.466"],["64025.60","1.171"],["64028.90","0.523"],["64029.20","0.437"],["64029.50","0.034"],["64029.70","0.562"],["64032.00","3.106"],["64032.80","0.031"],["64033.30","0.032"],["64033.40","2.001"],["64037.60","0.072"],["64038.80","0.000"],["64039.70","0.058"],["64040.90","0.442"],["64042.20","0.004"],["64042.30","0.000"],["64042.60","0.616"],["64042.70","1.251"],["64043.20","0.542"],["64043.40","0.002"],["64043.60","0.158"],["64047.30","0.049"],["64047.60","0.032"],["64048.70","0.004"],["64049.40","0.095"],["64050.00","0.068"],["64050.20","0.003"],["64054.20","1.196"],["64054.30","0.000"],["64054.90","0.191"],["64055.00","0.008"],["64055.20","2.344"],["64055.30","0.020"],["64055.40","0.050"],["64055.50","0.002"],["64055.60","0.170"],["64055.70","0.023"],["64055.90","0.234"],["64056.00","0.007"],["64056.10","0.014"],["64056.40","0.000"],["64056.70","0.124"],["64057.30","1.929"],["64057.40","0.608"],["64057.50","0.600"],["64057.60","0.009"],["64057.70","0.002"],["64057.80","0.002"],["64057.90","0.002"],["64059.20","0.004"],["64059.90","0.199"],["64060.00","0.180"],["64060.10","0.005"],["64062.10","0.002"],["64063.10","3.431"]],"e":"depthUpdate","ps":"BTCUSDT","pu":11165394532315,"s":"BTCUSDT","st":1,"u":11165394547192}
{"E":1785353521574,"T":1785353521573,"U":11165394547216,"a":[["64060.20","12.574"],["64060.30","0.562"],["64060.40","0.000"],["64060.60","0.001"],["64060.70","0.001"],["64060.80","1.670"],["64060.90","0.001"],["64061.00","0.096"],["64061.10","0.000"],["64061.30","0.005"],["64061.50","0.001"],["64061.60","0.000"],["64061.70","0.000"],["64061.80","0.001"],["64061.90","0.002"],["64062.00","0.001"],["64062.20","0.000"],["64062.30","0.011"],["64062.40","0.002"],["64062.50","0.000"],["64062.60","0.000"],["64062.70","0.015"],["64062.90","0.023"],["64063.00","2.500"],["64063.10","5.506"],["64063.20","5.064"],["64063.30","0.050"],["64063.40","0.000"],["64063.50","0.002"],["64063.80","0.001"],["64063.90","0.006"],["64064.00","0.435"],["64064.10","0.000"],["64064.30","0.314"],["64064.40","0.000"],["64064.80","0.002"],["64065.00","0.003"],["64065.40","0.051"],["64065.50","0.002"],["64065.90","0.946"],["64066.00","0.941"],["64066.20","0.808"],["64066.30","0.001"],["64066.40","0.015"],["64066.60","0.548"],["64066.70","2.341"],["64066.80","0.156"],["64066.90","0.029"],["64067.60","0.836"],["64067.70","0.053"],["64068.30","0.001"],["64068.40","0.022"],["64068.50","0.293"],["64068.90","0.002"],["64069.20","0.096"],["64069.30","1.055"],["64069.40","0.322"],["64069.60","0.015"],["64069.70","0.314"],["64069.80","1.024"],["64069.90","0.002"],["64070.10","0.383"],["64070.40","0.911"],["64070.80","0.122"],["64070.90","0.019"],["64071.60","0.097"],["64071.70","0.119"],["64071.90","0.505"],["64072.20","0.159"],["64072.50","0.031"],["64072.70","0.095"],["64072.80","0.013"],["64072.90","0.666"],["64073.40","0.158"],["64073.50","0.348"],["64073.60","0.149"],["64074.00","1.036"],["64074.50","1.064"],["64074.60","10.695"],["64074.70","0.315"],["64075.00","0.444"],["64075.10","0.171"],["64075.20","0.002"],["64075.50","0.002"],["64075.80","0.001"],["64075.90","1.245"],["64076.20","0.884"],["64076.40","0.688"],["64076.50","0.013"],["64076.80","2.860"],["64076.90","10.145"],["64077.00","0.004"],["64077.30","0.010"],["64078.40","0.316"],["64078.50","0.521"],["64078.60","0.816"],["64078.70","0.139"],["64078.80","1.563"],["64078.90","0.128"],["64079.10","0.012"],["64079.20","0.002"],["64079.40","0.033"],["64079.50","0.442"],["64079.60","0.000"],["64079.90","0.690"],["64080.10","0.451"],["64080.40","1.114"],["64080.80","0.001"],["64081.00","0.015"],["64081.10","0.000"],["64081.20","0.008"],["64081.60","0.523"],["64081.80","0.002"],["64082.30","0.074"],["64082.40","2.950"],["64082.50","0.001"],["64082.60","0.014"],["64083.60","0.017"],["64084.00","0.514"],["64084.30","0.001"],["64085.20","0.003"],["64085.60","0.005"],["64085.80","0.104"],["64085.90","0.548"],["64086.00","0.176"],["64086.40","1.166"],["64086.60","0.202"],["64086.70","0.003"],["64086.80","0.746"],["64087.00","0.094"],["64087.10","0.052"],["64087.20","0.000"],["64087.50","1.052"],["64087.90","0.000"],["64088.40","2.414"],["64088.50","0.010"],["64088.80","0.000"],["64089.00","0.061"],["64089.50","0.067"],["64089.60","1.714"],["64089.70","0.326"],["64089.80","0.001"],["64089.90","0.036"],["64090.60","0.376"],["64091.40","0.128"],["64091.90","0.569"],["64092.20","0.006"],["64092.50","0.001"],["64092.70","0.049"],["64092.80","0.108"],["64093.30","0.001"],["64093.50","1.953"],["64093.60","0.001"],["64093.90","0.017"],["64094.00","2.587"],["64094.20","0.017"],["64095.10","0.002"],["64095.20","0.004"],["64095.70","0.033"],["64096.10","0.014"],["64096.20","0.857"],["64096.30","0.000"],["64096.90","0.001"],["64097.10","0.538"],["64097.30","0.005"],["64097.50","0.203"],["64098.10","0.004"],["64098.30","0.122"],["64098.70","0.440"],["64099.00","0.008"],["64099.20","1.547"],["64099.40","1.948"],["64099.50","0.001"],["64099.60","1.141"],["64099.70","0.125"],["64100.30","0.000"],["64100.50","0.725"],["64101.20","0.060"],["64101.50","0.315"],["64102.50","0.381"],["64102.70","0.002"],["64103.00","0.009"],["64104.30","0.029"],["64104.80","0.249"],["64105.30","1.060"],["64105.40","0.160"],["64106.20","0.101"],["64106.30","0.755"],["64106.40","0.714"],["64106.70","0.158"],["64106.80","0.073"],["64107.00","0.007"],["64107.60","0.078"],["64107.70","2.347"],["64107.80","0.141"],["64107.90","0.001"],["64108.30","0.032"],["64110.40","2.344"],["64110.90","0.395"],["64111.30","0.003"],["64111.60","0.001"],["64112.50","0.005"],["64113.50","0.009"],["64113.80","0.020"],["64115.40","0.171"],["64115.70","2.483"],["64118.10","0.008"],["64120.50","0.000"],["64121.60","0.020"],["64121.80","6.422"],["64122.30","0.000"],["64124.00","0.024"],["64127.20","0.239"],["64128.10","0.482"],["64129.40","0.022"],["64129.90","0.000"],["64130.90","0.528"],["64132.00","4.441"],["64132.40","0.000"],["64132.50","0.006"],["64134.30","0.482"],["64140.00","0.030"],["64142.00","0.004"],["64144.00","0.002"],["64148.30","0.513"],["64148.80","0.521"],["64152.10","0.041"],["64156.80","0.505"],["64158.50","0.019"],["64165.70","0.000"],["64169.60","2.169"],["64187.80","0.014"],["64188.90","4.440"],["64198.00","0.000"],["64200.00","2.645"],["64205.30","0.000"],["64210.90","0.004"],["64216.00","0.001"],["64236.50","17.966"],["64238.90","0.005"],["64242.80","0.005"],["64246.00","0.000"],["64247.40","1.947"],["64247.50","0.000"],["64262.40","0.027"],["64264.90","0.117"],["64288.20","0.000"],["64316.40","0.094"],["64316.90","0.062"],["64319.50","0.016"],["64700.80","0.000"],["64703.70","0.000"],["64703.80","0.000"],["64800.50","4.146"],["64804.10","0.000"],["64864.50","3.052"],["64864.60","1.529"],["64868.20","0.000"],["64947.80","0.001"],["65059.80","3.220"],["65063.10","1.099"],["65064.30","0.355"],["65079.40","0.000"],["65081.40","0.697"],["65336.00","0.002"],["70558.10","0.006"]],"b":[["13560.10","0.070"],["13563.10","0.518"],["13666.70","0.238"],["13760.10","0.070"],["13763.00","0.014"],["13763.10","0.504"],["13860.10","0.084"],["13863.10","0.182"],["13866.70","0.434"],["13966.70","0.784"],["57654.00","0.256"],["57656.70","0.000"],["57656.80","0.006"],["60856.90","0.004"],["60857.00","0.008"],["61497.60","0.699"],["62773.90","0.008"],["62778.90","0.057"],["63214.40","0.000"],["63221.50","1.410"],["63419.50","0.007"],["63422.50","0.000"],["63426.00","0.085"],["63791.00","0.584"],["63791.10","0.540"],["63791.70","0.292"],["63851.70","0.027"],["63851.90","0.117"],["63864.70","0.122"],["63890.60","0.000"],["63908.10","0.095"],["63910.10","0.000"],["63912.10","0.000"],["63914.10","0.240"],["63914.80","2.039"],["63914.90","0.081"],["63916.10","0.000"],["63918.10","0.001"],["63920.10","0.000"],["63920.40","0.521"],["63923.30","3.907"],["63925.00","0.144"],["63927.80","0.503"],["63933.20","2.463"],["63933.30","0.261"],["63944.20","0.001"],["63947.50","22.901"],["63948.30","0.543"],["63948.70","4.396"],["63950.70","0.003"],["63959.70","0.000"],["63970.20","0.000"],["63971.70","0.000"],["63971.80","0.000"],["63973.30","0.936"],["63975.40","0.000"],["63979.00","0.501"],["63990.00","0.001"],["63990.90","0.141"],["63992.50","0.097"],["63994.00","0.211"],["63997.20","0.015"],["64000.10","2.435"],["64001.20","0.005"],["64003.30","2.002"],["64003.40","0.000"],["64005.50","0.000"],["64005.60","0.063"],["64007.40","0.008"],["64007.50","0.002"],["64007.60","0.159"],["64008.60","0.422"],["64009.00","0.000"],["64009.70","0.318"],["64011.00","0.122"],["64011.10","0.060"],["64012.10","0.281"],["64012.20","0.003"],["64012.40","0.366"],["64012.50","0.004"],["64013.20","0.064"],["64014.00","0.001"],["64014.10","0.571"],["64015.00","0.531"],["64015.70","1.186"],["64015.90","0.466"],["64016.90","0.015"],["64017.70","0.014"],["64019.00","0.001"],["64019.60","0.572"],["64019.90","2.681"],["64020.20","0.049"],["64020.60","0.003"],["64020.80","0.527"],["64021.20","0.090"],["64021.50","0.033"],["64021.70","0.079"],["64023.10","0.098"],["64023.60","0.000"],["64024.00","0.009"],["64024.30","0.000"],["64024.70","10.026"],["64025.00","0.002"],["64025.10","0.022"],["64025.20","0.468"],["64025.30","0.160"],["64025.60","2.649"],["64026.10","0.000"],["64026.40","0.003"],["64027.40","0.007"],["64028.10","0.005"],["64028.30","2.343"],["64028.40","1.808"],["64028.60","0.002"],["64028.70","0.610"],["64029.00","1.086"],["64029.20","0.079"],["64029.50","0.034"],["64030.20","0.281"],["64030.70","0.002"],["64031.10","0.016"],["64031.80","0.686"],["64032.00","1.591"],["64032.40","0.023"],["64033.00","0.316"],["64033.10","2.325"],["64033.40","0.008"],["64033.80","0.001"],["64034.40","0.426"],["64034.50","0.385"],["64034.60","0.935"],["64034.90","0.001"],["64035.20","1.968"],["64035.40","0.336"],["64035.50","0.158"],["64035.70","0.021"],["64035.90","0.000"],["64036.70","0.057"],["64037.50","0.004"],["64037.60","0.002"],["64037.70","0.002"],["64039.00","0.002"],["64039.50","0.003"],["64039.70","0.036"],["64039.80","0.004"],["64040.10","0.090"],["64040.20","0.081"],["64041.00","0.106"],["64041.10","0.636"],["64041.30","0.523"],["64041.50","0.000"],["64041.60","0.008"],["64041.80","1.023"],["64042.30","0.143"],["64042.40","0.393"],["64042.60","0.631"],["64043.00","0.001"],["64043.40","0.704"],["64043.50","0.163"],["64043.80","0.002"],["64044.10","0.000"],["64044.40","0.000"],["64045.10","0.001"],["64045.30","0.000"],["64045.50","0.821"],["64045.90","0.404"],["64046.10","0.883"],["64046.40","0.053"],["64046.60","0.305"],["64047.00","0.408"],["64047.10","0.051"],["64047.30","0.000"],["64047.60","0.001"],["64047.70","0.000"],["64047.90","0.195"],["64048.10","0.156"],["64048.20","0.095"],["64048.30","0.001"],["64048.40","0.002"],["64049.20","1.250"],["64049.30","0.004"],["64049.40","0.001"],["64049.60","0.005"],["64049.70","0.467"],["64050.00","0.006"],["64050.30","0.004"],["64050.40","0.002"],["64050.50","0.000"],["64050.60","0.015"],["64050.80","0.120"],["64051.20","0.635"],["64052.00","0.004"],["64052.20","0.142"],["64052.40","0.003"],["64052.60","0.003"],["64052.70","2.404"],["64052.80","1.472"],["64052.90","1.556"],["64053.10","0.053"],["64053.60","0.003"],["64053.70","0.001"],["64053.80","1.000"],["64053.90","0.000"],["64054.00","0.097"],["64054.10","0.000"],["64054.20","0.003"],["64054.60","0.006"],["64054.80","0.002"],["64054.90","0.097"],["64055.00","0.008"],["64055.10","0.001"],["64055.20","0.003"],["64055.30","1.010"],["64055.40","0.464"],["64055.50","0.003"],["64055.60","0.000"],["64055.70","0.075"],["64055.90","0.000"],["64056.10","0.026"],["64056.30","0.003"],["64056.70","0.029"],["64056.90","0.002"],["64057.00","0.000"],["64057.10","0.006"],["64057.20","0.081"],["64057.30","0.004"],["64057.40","0.001"],["64057.50","0.002"],["64057.60","0.009"],["64057.80","0.005"],["64057.90","0.000"],["64058.00","0.005"],["64058.10","0.000"],["64058.50","0.000"],["64058.70","0.000"],["64058.90","0.010"],["64059.00","0.000"],["64059.10","0.083"],["64059.30","0.000"],["64059.50","0.003"],["64059.80","0.000"],["64059.90","0.195"],["64060.00","0.052"],["64060.10","7.387"],["64060.30","0.000"],["64060.50","0.000"],["64060.60","0.000"],["64060.70","0.000"],["64060.80","0.000"],["64060.90","0.000"],["64061.00","0.000"],["64061.20","0.000"],["64061.50","0.000"],["64061.60","0.000"],["64061.70","0.000"],["64061.90","0.000"],["64062.00","0.000"],["64062.10","0.000"],["64062.20","0.000"],["64062.30","0.000"],["64062.40","0.000"],["64062.50","0.000"],["64063.00","0.000"],["64063.10","0.000"]],"e":"depthUpdate","ps":"BTCUSDT","pu":11165394547192,"s":"BTCUSDT","st":1,"u":11165394569237}
{"E":1785353521676,"T":1785353521675,"U":11165394569308,"a":[["64060.20","12.583"],["64062.60","0.005"],["64062.90","0.030"],["64063.20","5.057"],["64064.10","0.001"],["64064.50","0.024"],["64065.10","0.022"],["64065.80","1.249"],["64065.90","0.937"],["64066.80","0.154"],["64067.20","0.006"],["64074.00","1.068"],["64076.90","10.147"],["64077.00","0.002"],["64078.20","0.000"],["64078.70","0.001"],["64079.40","0.377"],["64080.00","1.877"],["64082.60","0.014"],["64082.80","0.048"],["64089.90","0.001"],["64092.10","0.049"],["64092.30","0.060"],["64092.80","0.048"],["64098.30","0.192"],["64099.20","1.498"],["64103.70","0.063"],["64103.80","0.026"],["64104.30","0.028"],["64104.90","0.017"],["64105.40","0.090"],["64105.50","0.000"],["64106.20","0.258"],["64106.40","0.690"],["64106.70","0.001"],["64115.40","0.309"],["64115.70","2.498"],["64125.40","0.001"],["64132.60","0.011"],["64156.80","3.925"],["64158.50","0.019"],["64160.00","0.817"],["64165.10","23.425"],["64240.00","2.314"],["64285.20","1.311"],["64286.70","4.726"],["64286.80","0.003"],["64320.00","0.466"],["64700.80","0.000"],["64800.50","3.229"],["64800.60","0.917"],["64803.60","0.917"],["64804.20","10.493"],["64823.90","0.000"],["64864.60","3.055"],["64868.30","2.289"],["70466.20","0.002"],["70558.10","0.004"]],"b":[["1000.00","37.592"],["13560.10","0.196"],["13666.70","0.112"],["13760.10","0.182"],["13860.10","0.196"],["13866.70","0.322"],["13966.70","0.672"],["57654.00","0.256"],["57654.10","0.002"],["62774.00","0.006"],["63419.50","0.005"],["63652.80","0.704"],["63690.60","0.034"],["63742.80","0.001"],["63760.00","0.457"],["63840.00","1.696"],["63920.00","0.842"],["63980.00","0.079"],["63984.00","0.018"],["64000.00","10.980"],["64011.80","0.041"],["64012.50","0.002"],["64017.80","0.471"],["64018.40","0.001"],["64024.70","10.028"],["64025.20","0.466"],["64033.30","0.967"],["64034.30","0.041"],["64034.60","0.000"],["64035.60","0.050"],["64040.60","0.005"],["64042.30","0.094"],["64048.70","0.000"],["64052.80","1.412"],["64052.90","1.536"],["64053.00","0.578"],["64053.60","0.109"],["64054.00","0.003"],["64054.10","0.881"],["64054.20","0.083"],["64054.60","0.016"],["64055.30","1.032"],["64055.40","0.194"],["64055.50","0.281"],["64056.10","0.004"],["64056.30","0.004"],["64057.30","0.002"],["64060.10","7.389"]],"e":"depthUpdate","ps":"BTCUSDT","pu":11165394569237,"s":"BTCUSDT","st":1,"u":11165394583725}
{"E":1785353521778,"T":1785353521776,"U":11165394583804,"a":[["64060.20","13.303"],["64060.70","0.001"],["64060.80","0.889"],["64060.90","0.001"],["64061.00","0.002"],["64061.40","0.000"],["64061.90","0.002"],["64062.10","0.094"],["64062.60","0.005"],["64062.90","0.003"],["64063.00","0.020"],["64063.10","2.857"],["64063.20","5.046"],["64064.20","0.022"],["64064.30","0.001"],["64065.10","0.000"],["64065.60","0.003"],["64065.90","0.002"],["64066.10","2.897"],["64066.60","0.002"],["64067.30","0.935"],["64067.50","0.551"],["64067.60","0.834"],["64068.40","0.011"],["64070.10","0.394"],["64072.40","0.013"],["64072.90","0.655"],["64073.60","0.849"],["64074.00","0.756"],["64074.60","10.706"],["64076.80","1.377"],["64076.90","0.145"],["64081.10","0.000"],["64081.50","0.314"],["64082.30","0.002"],["64085.20","0.003"],["64086.40","1.868"],["64086.60","2.202"],["64088.70","0.377"],["64089.60","1.714"],["64089.70","0.315"],["64091.10","0.013"],["64091.20","0.132"],["64091.40","0.139"],["64092.40","3.094"],["64098.30","0.072"],["64103.40","0.002"],["64106.40","0.714"],["64108.80","0.109"],["64115.10","0.163"],["64156.80","0.505"],["64160.00","0.840"],["64163.50","4.215"],["64199.40","0.000"],["64201.90","0.335"],["64202.50","0.000"],["64240.00","2.337"],["64286.50","7.508"],["64286.70","0.000"],["64313.90","0.094"],["64320.00","0.489"],["64335.80","0.000"],["64400.00","12.162"],["64495.80","0.098"],["64508.60","0.107"],["64540.90","0.116"],["64553.70","0.000"],["64700.80","0.000"],["64829.20","2.772"],["64864.50","2.289"],["64867.70","1.844"],["64975.90","0.459"],["65059.80","4.295"],["65341.10","0.015"],["70466.20","0.004"]],"b":[["1000.00","37.592"],["13560.10","0.308"],["13666.70","0.000"],["13760.10","0.308"],["13860.10","0.322"],["13866.70","0.196"],["13966.70","0.546"],["57654.00","0.256"],["57654.10","0.000"],["61497.60","0.696"],["62773.90","0.005"],["62778.80","0.575"],["63107.70","0.000"],["63123.50","1.190"],["63419.50","0.005"],["63760.00","0.480"],["63840.00","1.719"],["63885.00","0.122"],["63920.00","0.865"],["63947.50","0.510"],["63948.70","1.139"],["63971.70","22.391"],["63980.50","0.000"],["63980.60","4.042"],["63999.00","2.660"],["63999.30","0.914"],["64000.00","11.003"],["64017.80","0.470"],["64024.70","0.026"],["64025.60","1.171"],["64029.20","0.357"],["64031.00","10.002"],["64031.80","0.686"],["64032.00","3.177"],["64032.20","0.090"],["64033.30","0.941"],["64036.40","0.018"],["64038.40","1.093"],["64042.30","0.000"],["64043.40","0.610"],["64045.50","0.001"],["64046.10","0.002"],["64047.90","0.004"],["64048.10","0.000"],["64050.00","0.006"],["64051.60","0.188"],["64052.10","0.314"],["64052.60","0.001"],["64052.80","0.085"],["64052.90","0.002"],["64053.00","0.000"],["64054.20","0.194"],["64055.00","0.102"],["64055.10","0.235"],["64055.20","0.004"],["64055.40","2.355"],["64055.50","0.552"],["64055.60","0.156"],["64056.10","0.822"],["64056.20","1.411"],["64056.30","1.183"],["64056.60","0.002"],["64057.70","0.000"],["64059.20","0.002"],["64060.00","0.053"],["64060.10","8.847"]],"e":"depthUpdate","ps":"BTCUSDT","pu":11165394583725,"s":"BTCUSDT","st":1,"u":11165394600734}
{"E":1785353521880,"T":1785353521879,"U":11165394601262,"a":[["64057.70","21.067"],["64057.80","0.735"],["64057.90","0.002"],["64058.00","0.001"],["64058.10","7.996"],["64058.20","0.001"],["64058.40","1.193"],["64058.50","0.001"],["64058.70","0.383"],["64058.80","0.021"],["64058.90","0.000"],["64059.00","0.001"],["64059.10","0.000"],["64059.20","0.000"],["64059.30","0.094"],["64059.40","0.001"],["64059.50","0.002"],["64059.60","3.331"],["64059.70","0.569"],["64059.80","0.007"],["64059.90","0.051"],["64060.00","0.003"],["64060.10","5.946"],["64060.20","4.868"],["64060.30","0.573"],["64060.50","0.000"],["64060.60","0.094"],["64060.70","0.002"],["64060.80","0.000"],["64060.90","0.001"],["64061.30","0.318"],["64061.40","0.001"],["64061.70","0.001"],["64062.00","0.003"],["64062.20","0.001"],["64062.30","0.609"],["64062.60","0.000"],["64062.70","0.060"],["64062.90","0.004"],["64063.00","3.593"],["64063.10","2.852"],["64063.20","5.044"],["64063.90","0.319"],["64064.00","0.435"],["64064.10","0.346"],["64064.20","0.050"],["64064.30","0.002"],["64064.50","0.002"],["64064.90","0.000"],["64065.10","0.001"],["64065.20","0.014"],["64065.30","0.409"],["64065.40","0.001"],["64065.50","0.000"],["64065.60","2.003"],["64065.70","0.003"],["64065.90","0.005"],["64066.00","0.940"],["64066.10","2.886"],["64066.20","1.059"],["64066.40","0.000"],["64066.60","0.012"],["64066.70","2.341"],["64066.80","0.153"],["64066.90","0.028"],["64067.10","1.004"],["64067.30","0.936"],["64067.40","0.001"],["64067.60","2.186"],["64067.70","0.116"],["64067.80","0.239"],["64067.90","0.117"],["64068.00","0.217"],["64068.10","0.028"],["64068.30","0.000"],["64068.70","0.046"],["64068.80","0.003"],["64068.90","0.080"],["64069.10","0.002"],["64069.20","0.096"],["64069.30","1.055"],["64069.40","0.579"],["64069.50","0.000"],["64069.60","0.003"],["64069.70","0.314"],["64069.80","0.025"],["64070.00","0.083"],["64070.10","0.383"],["64070.20","0.004"],["64070.30","0.563"],["64070.50","2.596"],["64071.00","0.258"],["64071.10","0.012"],["64071.40","0.003"],["64071.60","0.003"],["64071.70","0.001"],["64071.80","0.009"],["64072.20","0.002"],["64072.30","1.253"],["64072.40","0.011"],["64072.70","0.001"],["64072.80","0.033"],["64072.90","0.108"],["64073.00","0.001"],["64073.10","0.026"],["64073.20","0.003"],["64073.40","0.001"],["64073.50","0.001"],["64073.60","0.789"],["64073.90","0.102"],["64074.30","0.156"],["64074.40","0.065"],["64074.50","1.073"],["64074.60","10.438"],["64075.20","0.051"],["64075.30","0.001"],["64075.40","0.570"],["64075.70","0.035"],["64076.20","0.283"],["64076.40","0.688"],["64076.50","0.016"],["64076.80","1.374"],["64077.00","0.001"],["64077.60","0.037"],["64077.90","0.002"],["64078.00","0.001"],["64078.40","0.002"],["64078.60","0.816"],["64078.70","0.051"],["64079.00","0.014"],["64079.10","0.001"],["64079.40","0.030"],["64079.50","0.412"],["64080.00","1.877"],["64080.10","2.451"],["64081.30","0.001"],["64081.50","0.004"],["64082.10","0.003"],["64082.20","0.063"],["64082.40","2.950"],["64082.80","0.013"],["64083.30","0.001"],["64083.50","0.189"],["64083.60","0.000"],["64083.70","0.002"],["64084.20","0.100"],["64084.30","0.091"],["64084.50","0.047"],["64084.80","0.068"],["64085.00","0.535"],["64085.80","0.062"],["64086.00","0.997"],["64086.20","0.008"],["64086.30","0.016"],["64086.60","0.203"],["64086.70","1.952"],["64087.10","0.004"],["64087.60","0.026"],["64087.90","0.011"],["64088.10","0.004"],["64088.40","2.342"],["64089.10","1.254"],["64089.40","0.001"],["64089.50","0.063"],["64089.60","1.706"],["64090.00","0.063"],["64090.10","0.026"],["64090.30","0.000"],["64090.70","0.014"],["64091.10","0.083"],["64091.20","0.012"],["64091.40","0.128"],["64091.70","0.121"],["64091.90","0.563"],["64092.10","0.005"],["64092.30","0.000"],["64093.00","0.000"],["64093.30","0.501"],["64093.50","0.001"],["64093.80","0.005"],["64093.90","0.033"],["64094.00","2.614"],["64094.20","0.013"],["64094.40","2.343"],["64095.60","0.690"],["64096.10","0.001"],["64096.90","0.005"],["64097.30","0.001"],["64097.50","0.176"],["64097.70","0.198"],["64098.30","0.002"],["64098.70","0.400"],["64099.10","0.000"],["64099.30","1.951"],["64099.40","0.002"],["64099.90","0.079"],["64100.10","0.395"],["64100.50","0.635"],["64100.60","0.003"],["64101.10","0.002"],["64101.20","0.011"],["64101.80","0.001"],["64103.20","1.484"],["64103.30","0.502"],["64103.80","0.003"],["64103.90","0.159"],["64104.30","0.027"],["64106.20","0.101"],["64106.40","0.690"],["64107.80","0.141"],["64108.50","0.100"],["64108.80","0.037"],["64109.30","0.002"],["64111.20","0.001"],["64113.30","0.210"],["64113.50","0.001"],["64114.40","0.715"],["64115.70","0.483"],["64116.00","0.006"],["64117.10","0.000"],["64119.00","0.659"],["64119.50","0.156"],["64119.60","0.004"],["64121.00","0.104"],["64121.40","0.100"],["64121.80","6.434"],["64122.50","0.016"],["64123.60","1.547"],["64123.70","0.001"],["64124.40","0.025"],["64125.30","0.022"],["64126.20","0.001"],["64126.90","0.000"],["64127.20","0.029"],["64129.40","0.009"],["64130.00","0.103"],["64131.20","0.879"],["64132.00","4.417"],["64133.60","0.041"],["64136.50","0.001"],["64140.00","0.029"],["64144.00","1.486"],["64144.10","0.001"],["64147.30","0.100"],["64158.40","0.008"],["64163.50","0.835"],["64163.80","0.000"],["64165.10","0.071"],["64170.20","0.500"],["64177.50","0.000"],["64195.10","0.063"],["64247.30","1.947"],["64247.40","0.000"],["64263.10","0.012"],["64264.90","0.000"],["64265.00","0.378"],["64265.60","0.149"],["64265.90","9.609"],["64266.00","0.518"],["64313.90","0.214"],["64316.20","0.000"],["64316.40","0.000"],["64365.30","0.015"],["64467.70","0.096"],["64495.80","0.002"],["64508.60","0.011"],["64595.80","0.097"],["64629.70","0.002"],["64698.30","0.004"],["64700.20","0.008"],["64700.80","0.000"],["64800.60","1.834"],["64804.20","9.576"],["64864.60","3.818"],["64868.30","1.526"],["65057.70","0.002"],["65058.40","0.351"],["65060.20","0.010"],["65063.20","0.002"],["65066.20","0.000"],["65145.90","0.541"],["70429.00","0.001"],["70465.60","0.009"],["70558.10","0.002"]],"b":[["13566.70","0.434"],["13757.60","0.014"],["13759.50","0.014"],["13760.10","0.392"],["13857.60","0.028"],["13860.10","0.406"],["13866.70","0.084"],["13957.60","0.028"],["13959.50","0.014"],["13960.10","0.084"],["13966.70","0.434"],["57651.80","0.002"],["57653.50","0.050"],["57654.00","0.254"],["57729.20","0.002"],["61497.60","0.699"],["62574.40","0.000"],["62778.80","0.572"],["63179.60","0.091"],["63259.30","0.354"],["63417.00","0.010"],["63417.70","0.003"],["63419.00","0.000"],["63419.50","0.005"],["63609.90","0.001"],["63616.90","0.001"],["63674.00","0.002"],["63681.00","0.001"],["63721.10","0.004"],["63724.30","7.883"],["63727.40","0.001"],["63736.20","0.089"],["63802.10","0.001"],["63809.10","0.002"],["63849.40","0.000"],["63851.90","0.000"],["63864.70","0.005"],["63897.60","3.555"],["63899.60","0.881"],["63901.60","1.399"],["63903.60","0.882"],["63905.60","0.881"],["63907.60","0.881"],["63909.60","0.882"],["63911.60","0.881"],["63913.60","2.379"],["63914.70","1.957"],["63914.80","0.082"],["63915.60","0.881"],["63917.60","0.881"],["63919.60","1.708"],["63921.60","0.881"],["63922.50","0.001"],["63923.60","0.881"],["63925.60","0.883"],["63927.60","0.883"],["63929.60","0.903"],["63931.60","0.881"],["63933.20","2.464"],["63933.60","0.881"],["63936.80","0.500"],["63940.50","1.496"],["63940.60","0.000"],["63942.30","0.001"],["63947.40","0.002"],["63951.60","0.011"],["63951.70","0.013"],["63954.10","22.162"],["63955.70","0.000"],["63960.10","2.001"],["63960.20","0.278"],["63960.80","1.486"],["63960.90","0.000"],["63961.60","1.498"],["63968.00","0.626"],["63971.70","0.000"],["63971.80","0.000"],["63973.30","0.936"],["63977.00","0.501"],["63979.80","0.317"],["63980.60","0.970"],["63985.30","2.653"],["63988.40","0.500"],["63988.60","0.529"],["63989.30","0.313"],["63989.40","0.001"],["63989.70","8.664"],["63994.30","0.000"],["63995.90","0.108"],["63996.30","0.001"],["63996.70","0.025"],["63997.20","0.000"],["63997.40","2.214"],["63998.60","0.000"],["63999.30","0.002"],["63999.50","0.000"],["63999.60","2.411"],["64003.30","0.002"],["64005.80","0.003"],["64006.10","0.009"],["64006.20","0.003"],["64006.30","0.019"],["64007.10","2.000"],["64007.40","0.000"],["64007.90","2.227"],["64008.30","0.002"],["64008.60","0.013"],["64009.40","0.549"],["64009.90","0.645"],["64010.00","0.506"],["64010.20","0.061"],["64010.40","0.068"],["64010.70","0.278"],["64011.10","0.060"],["64011.80","0.039"],["64011.90","0.002"],["64012.20","0.000"],["64012.30","0.090"],["64012.80","0.122"],["64013.20","0.065"],["64016.10","0.047"],["64016.40","0.610"],["64016.70","0.062"],["64018.00","0.540"],["64018.80","0.027"],["64018.90","0.203"],["64019.10","1.686"],["64019.20","1.267"],["64019.50","0.096"],["64019.70","0.021"],["64020.40","0.196"],["64020.60","0.000"],["64020.70","0.000"],["64021.20","0.000"],["64021.40","1.082"],["64022.10","1.120"],["64022.40","0.010"],["64022.80","0.011"],["64023.10","0.094"],["64023.20","0.080"],["64023.30","0.331"],["64023.40","0.537"],["64024.20","0.001"],["64025.10","0.001"],["64025.20","1.075"],["64025.60","1.171"],["64026.30","0.382"],["64026.80","0.050"],["64027.10","0.080"],["64027.50","0.004"],["64027.60","0.000"],["64027.70","0.292"],["64028.10","0.001"],["64028.20","0.039"],["64028.70","0.420"],["64028.80","0.143"],["64029.10","1.254"],["64029.20","0.079"],["64029.30","0.013"],["64029.60","0.136"],["64030.00","0.017"],["64030.10","0.611"],["64030.20","0.010"],["64030.30","0.021"],["64030.40","0.315"],["64030.80","0.001"],["64031.00","0.002"],["64031.60","0.006"],["64031.70","0.001"],["64031.80","0.658"],["64031.90","1.995"],["64032.00","1.591"],["64032.20","0.140"],["64032.80","0.033"],["64033.10","2.325"],["64033.20","0.002"],["64033.30","0.006"],["64033.40","0.001"],["64033.60","0.097"],["64033.90","0.042"],["64034.40","0.426"],["64034.50","0.323"],["64034.80","2.635"],["64035.10","0.890"],["64035.30","0.145"],["64035.40","0.324"],["64035.50","0.001"],["64035.60","0.001"],["64035.70","0.336"],["64036.40","0.112"],["64036.70","0.059"],["64037.00","0.021"],["64037.50","0.161"],["64037.60","0.096"],["64038.00","0.037"],["64038.40","1.372"],["64038.50","2.354"],["64038.70","0.141"],["64038.80","0.001"],["64038.90","0.001"],["64039.10","0.187"],["64039.40","0.000"],["64039.60","0.003"],["64039.70","0.001"],["64039.90","0.094"],["64040.10","0.041"],["64040.20","0.454"],["64040.40","0.001"],["64040.60","0.341"],["64040.80","1.097"],["64041.00","0.021"],["64041.10","0.730"],["64041.20","0.096"],["64041.30","0.001"],["64041.60","0.239"],["64041.70","4.398"],["64041.80","0.367"],["64042.00","0.004"],["64042.30","0.095"],["64042.40","0.372"],["64042.50","2.342"],["64042.60","0.022"],["64042.70","0.042"],["64042.80","0.047"],["64042.90","0.007"],["64043.10","0.001"],["64043.20","0.755"],["64043.30","0.609"],["64043.40","0.096"],["64043.50","0.006"],["64043.60","0.001"],["64043.70","0.007"],["64044.20","0.003"],["64044.30","1.823"],["64044.40","0.000"],["64044.50","0.001"],["64044.80","0.232"],["64044.90","0.000"],["64045.20","0.000"],["64045.40","0.003"],["64045.50","2.341"],["64045.60","0.873"],["64045.70","0.003"],["64045.80","0.116"],["64045.90","0.072"],["64046.00","0.001"],["64046.10","0.001"],["64046.20","0.235"],["64046.30","0.094"],["64046.40","0.032"],["64046.50","0.004"],["64046.60","0.074"],["64046.70","0.000"],["64046.90","0.002"],["64047.00","0.001"],["64047.10","0.051"],["64047.30","0.000"],["64047.50","0.003"],["64047.60","0.021"],["64047.70","0.001"],["64047.80","0.002"],["64047.90","0.002"],["64048.00","0.495"],["64048.10","2.532"],["64048.20","0.191"],["64048.30","0.001"],["64048.40","0.002"],["64048.60","0.001"],["64048.80","0.003"],["64048.90","0.004"],["64049.00","0.000"],["64049.10","0.000"],["64049.20","0.001"],["64049.30","0.004"],["64049.50","0.004"],["64049.60","0.004"],["64049.70","0.002"],["64049.80","0.003"],["64049.90","0.001"],["64050.20","0.000"],["64050.40","0.002"],["64050.60","0.014"],["64050.70","0.060"],["64050.80","0.121"],["64050.90","0.061"],["64051.00","0.242"],["64051.10","0.123"],["64051.20","0.634"],["64051.30","0.577"],["64051.40","0.014"],["64051.50","0.064"],["64051.60","0.129"],["64052.00","0.004"],["64052.10","0.001"],["64052.20","0.033"],["64052.40","0.003"],["64052.50","0.042"],["64052.60","0.001"],["64052.70","0.001"],["64052.80","0.085"],["64053.10","0.032"],["64053.20","0.076"],["64053.60","0.003"],["64053.70","0.000"],["64053.80","0.002"],["64053.90","0.000"],["64054.00","0.003"],["64054.10","0.000"],["64054.20","0.003"],["64054.50","0.002"],["64054.60","0.006"],["64054.90","0.007"],["64055.00","0.005"],["64055.10","0.001"],["64055.20","0.001"],["64055.30","0.000"],["64055.40","0.005"],["64055.50","0.004"],["64055.60","0.000"],["64055.70","0.000"],["64055.90","0.000"],["64056.00","0.005"],["64056.10","0.002"],["64056.20","0.000"],["64056.30","0.002"],["64056.40","0.000"],["64056.60","0.001"],["64056.80","0.000"],["64056.90","0.001"],["64057.20","0.079"],["64057.50","0.000"],["64057.60","0.005"],["64057.80","0.000"],["64058.00","0.000"],["64058.30","0.000"],["64058.40","0.000"],["64058.60","0.000"],["64058.80","0.000"],["64058.90","0.000"],["64059.00","0.000"],["64059.10","0.000"],["64059.20","0.000"],["64059.50","0.000"],["64059.90","0.000"],["64060.00","0.000"],["64060.10","0.000"]],"e":"depthUpdate","ps":"BTCUSDT","pu":11165394600734,"s":"BTCUSDT","st":1,"u":11165394648806}
{"E":1785353521982,"T":1785353521981,"U":11165394648898,"a":[["64051.70","17.391"],["64051.80","0.005"],["64052.20","0.000"],["64052.30","0.000"],["64052.40","0.000"],["64052.50","1.297"],["64052.60","0.931"],["64052.70","0.000"],["64052.80","1.245"],["64052.90","4.508"],["64053.00","0.001"],["64053.30","0.001"],["64053.40","0.931"],["64053.50","0.000"],["64053.60","8.732"],["64053.70","10.459"],["64053.80","0.002"],["64053.90","0.000"],["64054.10","0.000"],["64054.20","0.001"],["64054.30","0.141"],["64054.40","0.001"],["64054.50","1.293"],["64054.60","0.000"],["64054.70","0.001"],["64054.80","0.000"],["64055.00","0.003"],["64055.10","0.000"],["64055.20","0.001"],["64055.30","0.001"],["64055.40","0.001"],["64055.50","0.000"],["64055.70","0.001"],["64055.80","0.001"],["64055.90","0.001"],["64056.00","0.026"],["64056.10","0.094"],["64056.20","0.000"],["64056.30","0.002"],["64056.40","0.001"],["64056.50","0.001"],["64056.60","0.040"],["64056.70","2.727"],["64056.80","1.739"],["64056.90","0.001"],["64057.00","0.001"],["64057.10","0.000"],["64057.20","0.331"],["64057.30","0.000"],["64057.40","0.118"],["64057.50","4.938"],["64057.60","2.255"],["64057.70","1.111"],["64057.80","0.002"],["64058.00","0.001"],["64058.10","0.002"],["64058.20","0.000"],["64058.30","0.002"],["64058.40","0.946"],["64058.60","0.050"],["64058.80","0.048"],["64058.90","0.003"],["64059.00","0.056"],["64059.10","0.001"],["64059.20","1.250"],["64059.50","0.000"],["64059.60","0.003"],["64059.70","0.506"],["64059.80","0.007"],["64059.90","0.004"],["64060.00","0.004"],["64060.10","2.355"],["64060.20","4.839"],["64060.30","0.557"],["64060.50","0.001"],["64060.60","0.094"],["64060.70","0.002"],["64060.80","0.015"],["64060.90","0.000"],["64061.00","1.002"],["64061.20","0.015"],["64061.30","0.320"],["64061.40","0.003"],["64061.50","0.121"],["64061.70","0.014"],["64061.90","0.253"],["64062.00","0.019"],["64062.20","0.001"],["64062.30","0.608"],["64062.50","0.002"],["64062.60","0.000"],["64062.70","0.315"],["64062.80","0.656"],["64062.90","1.221"],["64063.00","2.467"],["64063.10","2.851"],["64063.20","0.407"],["64063.30","0.053"],["64063.40","0.336"],["64063.50","0.240"],["64063.90","0.318"],["64064.00","0.433"],["64064.10","0.060"],["64064.20","0.003"],["64064.50","0.003"],["64064.70","0.000"],["64064.80","0.001"],["64064.90","2.983"],["64065.00","0.007"],["64065.10","0.258"],["64065.20","0.008"],["64065.40","0.000"],["64065.50","0.004"],["64065.60","0.084"],["64065.70","0.659"],["64065.80","1.250"],["64066.00","0.297"],["64066.10","0.388"],["64066.20","0.807"],["64066.40","0.003"],["64066.50","0.001"],["64066.60","0.024"],["64066.70","3.655"],["64066.80","0.099"],["64067.10","0.004"],["64067.20","0.006"],["64067.30","0.020"],["64067.50","0.141"],["64067.60","0.836"],["64067.70","0.116"],["64067.80","0.032"],["64067.90","0.017"],["64068.00","0.003"],["64068.30","0.500"],["64068.40","0.144"],["64068.50","0.304"],["64068.70","0.043"],["64068.80","2.001"],["64068.90","0.080"],["64069.00","0.610"],["64069.20","0.523"],["64069.40","0.322"],["64069.50","0.000"],["64069.60","0.001"],["64069.70","0.314"],["64069.80","0.245"],["64070.00","0.081"],["64070.10","0.384"],["64070.30","0.000"],["64070.40","0.935"],["64070.50","2.595"],["64070.80","0.280"],["64070.90","0.066"],["64071.00","0.001"],["64071.10","0.001"],["64071.20","0.000"],["64071.30","0.001"],["64071.40","0.002"],["64071.60","0.001"],["64071.80","0.002"],["64071.90","0.001"],["64072.20","0.005"],["64072.30","1.775"],["64072.40","0.024"],["64072.50","0.000"],["64072.60","0.099"],["64072.70","0.001"],["64072.80","0.013"],["64072.90","0.108"],["64073.00","0.001"],["64073.10","0.005"],["64073.30","0.091"],["64073.40","0.001"],["64073.50","0.315"],["64073.70","2.343"],["64074.00","0.629"],["64074.10","3.568"],["64074.50","1.219"],["64074.60","10.440"],["64074.70","0.297"],["64074.80","0.600"],["64074.90","0.338"],["64075.20","0.002"],["64075.40","1.092"],["64075.50","0.002"],["64075.70","0.000"],["64076.00","0.006"],["64076.10","0.118"],["64076.20","0.049"],["64076.50","0.015"],["64076.60","0.164"],["64076.70","0.003"],["64077.10","1.658"],["64077.20","0.000"],["64077.40","0.004"],["64077.60","0.004"],["64077.80","0.470"],["64077.90","0.001"],["64078.10","0.000"],["64078.20","0.050"],["64078.30","0.002"],["64078.50","0.538"],["64078.60","0.816"],["64078.70","0.001"],["64078.90","0.000"],["64079.00","0.000"],["64079.20","0.014"],["64079.30","0.045"],["64079.50","0.557"],["64079.60","1.633"],["64079.70","0.941"],["64079.80","2.340"],["64079.90","0.533"],["64080.10","2.451"],["64080.20","0.010"],["64080.30","1.955"],["64080.40","0.047"],["64080.60","0.000"],["64080.80","0.005"],["64080.90","0.005"],["64081.10","0.057"],["64081.30","0.050"],["64081.40","0.002"],["64081.60","0.543"],["64081.70","0.557"],["64081.80","0.090"],["64082.00","0.001"],["64082.50","0.001"],["64082.60","0.012"],["64082.80","0.547"],["64082.90","1.030"],["64083.00","0.003"],["64083.20","1.250"],["64083.30","0.001"],["64083.60","1.093"],["64083.70","0.002"],["64083.80","0.005"],["64083.90","0.005"],["64084.00","0.512"],["64084.10","0.003"],["64084.20","0.718"],["64084.30","0.001"],["64084.60","0.121"],["64084.70","0.825"],["64084.80","0.065"],["64085.00","0.534"],["64085.10","2.393"],["64085.20","0.001"],["64085.30","0.000"],["64085.40","0.144"],["64085.50","1.269"],["64085.70","0.001"],["64085.90","0.002"],["64086.00","0.001"],["64086.10","0.000"],["64086.30","0.003"],["64086.50","0.007"],["64086.60","0.203"],["64086.70","0.000"],["64086.80","0.746"],["64086.90","0.392"],["64087.00","0.094"],["64087.20","0.976"],["64087.30","1.013"],["64087.40","0.015"],["64087.60","0.063"],["64087.70","0.008"],["64087.90","0.000"],["64088.20","0.070"],["64088.50","0.017"],["64089.10","1.094"],["64089.30","0.657"],["64089.60","1.184"],["64089.70","0.316"],["64090.00","0.067"],["64090.10","0.000"],["64090.40","0.005"],["64090.50","0.000"],["64090.70","0.010"],["64090.90","0.908"],["64091.00","0.105"],["64091.10","0.001"],["64091.20","0.007"],["64091.30","0.021"],["64091.40","0.106"],["64091.50","0.659"],["64091.60","2.346"],["64091.70","0.001"],["64091.80","0.001"],["64091.90","0.524"],["64092.00","0.529"],["64092.10","0.000"],["64092.20","0.405"],["64092.30","0.312"],["64092.40","1.343"],["64092.50","0.000"],["64092.60","0.071"],["64092.80","0.010"],["64093.00","0.094"],["64093.30","0.001"],["64093.50","0.004"],["64093.60","0.001"],["64093.80","0.005"],["64093.90","0.002"],["64094.00","2.587"],["64094.10","0.032"],["64094.30","0.015"],["64094.70","0.000"],["64094.90","0.455"],["64095.10","0.000"],["64095.90","0.107"],["64096.00","1.174"],["64096.10","0.065"],["64096.20","0.857"],["64096.80","0.032"],["64096.90","0.001"],["64097.00","1.219"],["64097.70","0.194"],["64097.80","0.004"],["64098.00","0.001"],["64098.70","0.000"],["64099.00","0.001"],["64099.10","0.157"],["64099.20","1.478"],["64099.60","1.047"],["64099.90","0.019"],["64100.10","0.391"],["64100.40","0.000"],["64100.50","0.017"],["64100.90","0.027"],["64101.70","0.026"],["64101.90","0.091"],["64102.20","0.007"],["64102.40","0.022"],["64102.50","0.287"],["64102.80","0.002"],["64103.00","0.004"],["64103.10","0.140"],["64103.30","0.503"],["64103.60","0.001"],["64103.90","0.006"],["64104.50","1.249"],["64105.20","0.032"],["64106.00","0.002"],["64106.10","0.005"],["64106.20","0.311"],["64106.40","0.657"],["64107.60","0.115"],["64107.70","2.343"],["64107.80","0.078"],["64108.30","0.001"],["64108.40","0.001"],["64108.70","0.003"],["64109.50","0.482"],["64109.90","0.001"],["64110.00","0.034"],["64110.40","2.340"],["64111.60","0.005"],["64112.60","0.482"],["64113.20","0.032"],["64113.30","0.210"],["64114.00","0.007"],["64114.40","0.505"],["64114.50","0.000"],["64114.90","0.504"],["64115.50","0.001"],["64115.80","0.001"],["64116.10","0.020"],["64117.60","0.029"],["64117.80","0.003"],["64118.10","0.004"],["64118.30","0.000"],["64118.90","0.324"],["64119.00","0.159"],["64119.20","0.150"],["64120.90","0.049"],["64121.10","0.287"],["64121.80","6.397"],["64121.90","2.821"],["64122.40","0.004"],["64122.50","0.001"],["64122.60","0.026"],["64122.90","0.000"],["64123.90","0.001"],["64124.40","0.001"],["64125.20","0.017"],["64125.50","0.000"],["64125.80","0.001"],["64126.20","0.001"],["64126.40","0.048"],["64127.30","0.011"],["64128.10","0.506"],["64128.80","1.826"],["64128.90","0.077"],["64129.80","0.003"],["64130.60","3.240"],["64131.20","0.854"],["64131.50","0.001"],["64131.80","0.502"],["64132.60","0.010"],["64133.40","0.011"],["64135.90","3.138"],["64136.00","0.000"],["64138.00","0.001"],["64140.50","0.590"],["64142.60","0.005"],["64143.20","0.047"],["64143.40","0.195"],["64145.20","0.012"],["64148.20","0.215"],["64148.80","0.021"],["64150.50","0.010"],["64151.10","0.785"],["64152.50","0.003"],["64153.20","0.005"],["64153.30","0.059"],["64154.50","0.200"],["64154.90","0.121"],["64156.10","0.000"],["64158.10","0.003"],["64158.40","0.000"],["64160.00","0.839"],["64160.20","4.748"],["64160.70","0.012"],["64161.90","0.000"],["64164.10","0.011"],["64166.40","1.395"],["64168.20","2.343"],["64168.50","0.026"],["64170.20","0.000"],["64171.80","0.003"],["64172.60","2.341"],["64181.30","0.494"],["64181.80","0.019"],["64183.10","0.252"],["64184.10","0.002"],["64189.50","0.000"],["64189.80","0.281"],["64192.80","0.000"],["64197.70","0.000"],["64199.90","0.100"],["64205.80","0.000"],["64210.90","0.000"],["64211.80","0.001"],["64212.60","0.001"],["64213.80","0.308"],["64228.60","0.000"],["64233.90","0.118"],["64239.20","0.000"],["64240.90","0.000"],["64245.90","0.001"],["64252.60","0.983"],["64253.90","0.079"],["64262.70","0.707"],["64274.50","0.000"],["64283.50","0.000"],["64309.90","0.020"],["64313.70","0.537"],["64313.90","0.000"],["64317.90","0.001"],["64329.10","0.536"],["64332.30","0.000"],["64374.00","0.002"],["64374.20","0.000"],["64382.00","0.000"],["64400.10","0.000"],["64400.70","0.002"],["64403.30","0.001"],["64406.50","0.000"],["64413.30","0.850"],["64438.00","0.001"],["64445.20","0.000"],["64476.50","0.096"],["64478.30","0.110"],["64486.00","0.316"],["64489.30","0.001"],["64502.10","0.005"],["64506.10","0.097"],["64510.10","0.125"],["64566.10","0.001"],["64573.30","0.005"],["64578.90","0.111"],["64598.00","0.040"],["64692.20","0.002"],["64694.20","0.000"],["64697.40","0.040"],["64698.20","0.000"],["64698.30","0.000"],["64797.50","1.834"],["64804.20","7.742"],["64822.80","0.024"],["64861.60","3.510"],["64864.50","1.526"],["64868.30","0.763"],["65053.70","0.010"],["65056.80","0.008"],["65057.60","0.004"],["65057.70","0.006"],["65060.20","0.008"],["65063.10","1.089"],["65063.20","0.000"],["65337.90","2.008"],["70462.50","0.003"]],"b":[["1000.00","37.592"],["13566.70","0.322"],["13651.60","0.014"],["13653.60","0.028"],["13753.60","0.042"],["13756.70","0.028"],["13757.60","0.028"],["13766.70","0.322"],["13853.60","0.084"],["13856.70","0.014"],["13857.60","0.042"],["13866.70","0.000"],["13951.60","0.014"],["13953.60","0.070"],["13956.70","0.028"],["13966.70","0.322"],["51248.10","0.000"],["57646.40","0.002"],["57648.20","0.000"],["57651.00","0.058"],["57651.80","0.000"],["57729.20","0.000"],["60859.90","0.008"],["61497.60","0.696"],["62776.50","0.003"],["63099.20","0.011"],["63147.50","0.276"],["63401.40","0.000"],["63411.10","3.747"],["63413.10","0.000"],["63416.10","0.000"],["63416.90","0.000"],["63417.00","0.000"],["63543.60","0.001"],["63550.30","0.000"],["63603.20","0.002"],["63609.90","0.000"],["63667.30","0.014"],["63674.00","0.001"],["63735.70","0.001"],["63736.20","0.090"],["63742.50","0.000"],["63742.80","0.011"],["63784.50","1.080"],["63787.70","0.540"],["63788.10","0.168"],["63795.40","0.001"],["63802.10","0.000"],["63851.70","0.144"],["63863.80","0.003"],["63870.60","0.016"],["63884.10","0.017"],["63887.30","0.010"],["63890.30","0.001"],["63897.60","2.674"],["63898.70","0.399"],["63899.60","0.000"],["63900.70","0.456"],["63901.60","0.518"],["63902.70","0.001"],["63903.60","0.001"],["63904.70","0.001"],["63905.60","0.000"],["63906.70","0.000"],["63907.60","0.000"],["63908.70","0.006"],["63909.60","0.001"],["63910.70","0.491"],["63911.60","0.000"],["63912.70","0.011"],["63913.60","1.498"],["63914.20","0.524"],["63914.70","1.957"],["63915.60","0.000"],["63916.50","0.001"],["63917.30","0.522"],["63917.60","0.000"],["63918.50","0.496"],["63919.60","0.827"],["63921.60","0.000"],["63923.60","0.000"],["63923.90","2.842"],["63925.60","0.002"],["63927.60","0.002"],["63927.80","0.003"],["63927.90","0.001"],["63929.60","0.022"],["63931.60","0.000"],["63932.20","0.001"],["63933.60","0.000"],["63934.60","0.004"],["63934.70","0.000"],["63936.80","0.000"],["63938.40","0.032"],["63938.50","0.375"],["63939.90","0.035"],["63940.10","0.600"],["63940.40","0.032"],["63940.90","22.655"],["63941.00","7.845"],["63950.50","0.003"],["63951.70","0.029"],["63952.30","2.342"],["63952.60","0.297"],["63952.90","0.000"],["63953.70","0.281"],["63954.10","0.003"],["63954.20","0.008"],["63954.60","1.694"],["63954.70","0.027"],["63957.10","0.009"],["63957.40","0.042"],["63957.70","0.000"],["63960.20","3.122"],["63961.70","0.000"],["63963.10","0.001"],["63963.40","0.002"],["63965.10","0.027"],["63966.60","0.568"],["63968.60","0.001"],["63968.70","3.030"],["63969.30","0.000"],["63970.60","0.064"],["63973.60","0.002"],["63974.80","0.315"],["63975.50","0.000"],["63975.70","0.200"],["63975.80","1.562"],["63976.80","0.200"],["63979.00","0.001"],["63981.30","0.313"],["63984.90","0.232"],["63985.40","0.018"],["63985.90","0.017"],["63987.90","4.224"],["63988.40","0.000"],["63988.60","0.544"],["63989.10","0.000"],["63989.90","0.001"],["63990.30","0.000"],["63991.50","0.004"],["63991.90","0.002"],["63992.30","0.003"],["63993.40","0.000"],["63993.60","0.038"],["63994.00","0.001"],["63994.80","0.808"],["63995.90","0.062"],["63996.00","0.003"],["63996.20","1.187"],["63996.70","0.000"],["63996.90","0.001"],["63997.40","2.205"],["63997.80","0.001"],["63998.10","0.001"],["63998.30","1.077"],["63998.70","0.004"],["63999.00","0.906"],["63999.10","0.004"],["63999.60","0.712"],["63999.80","0.318"],["63999.90","0.003"],["64000.20","0.260"],["64000.40","0.000"],["64000.50","0.008"],["64001.00","0.510"],["64001.10","1.251"],["64001.20","0.001"],["64001.30","0.316"],["64001.40","0.021"],["64002.20","0.001"],["64002.70","2.342"],["64003.20","3.869"],["64003.30","0.012"],["64003.40","0.000"],["64003.70","0.528"],["64003.90","0.592"],["64004.00","0.004"],["64004.60","0.088"],["64004.70","0.173"],["64004.90","0.001"],["64005.00","0.257"],["64005.10","0.018"],["64005.20","0.090"],["64005.50","0.025"],["64006.00","0.406"],["64006.10","0.001"],["64006.20","0.013"],["64006.30","0.015"],["64006.40","1.212"],["64006.50","0.000"],["64006.60","0.047"],["64006.70","0.004"],["64006.80","0.014"],["64006.90","0.033"],["64007.00","0.017"],["64007.10","0.000"],["64007.20","0.510"],["64007.60","0.003"],["64008.20","0.000"],["64008.50","0.003"],["64008.70","0.000"],["64008.80","0.028"],["64008.90","0.033"],["64009.30","0.001"],["64009.40","0.538"],["64009.50","0.532"],["64009.60","2.339"],["64009.90","0.640"],["64010.00","0.006"],["64010.10","0.317"],["64010.30","0.610"],["64010.40","0.066"],["64010.50","0.195"],["64010.70","0.275"],["64010.90","2.093"],["64011.00","0.123"],["64011.20","0.004"],["64011.60","0.003"],["64011.90","0.041"],["64012.00","0.049"],["64012.10","0.022"],["64012.30","0.000"],["64012.50","0.010"],["64012.60","1.241"],["64012.80","0.062"],["64013.10","0.122"],["64013.20","0.060"],["64013.30","0.005"],["64013.50","0.081"],["64013.90","0.003"],["64014.10","0.599"],["64014.20","0.000"],["64014.60","1.250"],["64014.70","0.021"],["64014.80","0.000"],["64015.30","0.002"],["64015.80","0.666"],["64015.90","0.467"],["64016.30","0.002"],["64016.60","0.091"],["64016.70","0.063"],["64016.90","0.000"],["64017.00","0.000"],["64017.10","0.130"],["64017.20","0.025"],["64017.30","0.010"],["64017.60","0.004"],["64017.70","0.000"],["64017.90","0.000"],["64018.00","0.538"],["64018.30","0.031"],["64018.80","0.024"],["64018.90","0.133"],["64019.00","0.081"],["64019.10","0.370"],["64019.40","0.028"],["64019.70","1.722"],["64019.90","2.681"],["64020.00","0.017"],["64020.10","0.316"],["64020.20","0.054"],["64020.50","0.036"],["64020.60","0.562"],["64020.80","0.528"],["64021.00","0.002"],["64021.20","0.292"],["64021.30","0.002"],["64021.50","0.005"],["64021.60","0.004"],["64021.70","0.134"],["64021.90","0.001"],["64022.10","1.000"],["64022.30","0.242"],["64022.50","0.020"],["64022.70","0.582"],["64022.80","0.007"],["64022.90","0.000"],["64023.00","0.003"],["64023.10","2.434"],["64023.20","0.000"],["64023.30","0.304"],["64023.70","0.586"],["64024.00","0.321"],["64024.10","0.935"],["64024.20","0.118"],["64024.30","0.007"],["64024.40","0.360"],["64024.50","0.027"],["64024.60","0.000"],["64024.70","0.160"],["64024.80","0.387"],["64024.90","0.136"],["64025.00","0.540"],["64025.30","0.080"],["64025.40","0.062"],["64025.70","0.067"],["64025.90","2.344"],["64026.10","0.003"],["64026.30","0.363"],["64026.40","0.002"],["64026.70","0.003"],["64026.80","0.062"],["64026.90","0.007"],["64027.00","0.004"],["64027.10","0.060"],["64027.40","0.001"],["64027.50","0.005"],["64027.60","0.034"],["64027.70","0.003"],["64027.80","0.000"],["64027.90","0.409"],["64028.00","0.084"],["64028.10","0.003"],["64028.20","0.004"],["64028.30","0.000"],["64028.40","0.014"],["64028.50","0.314"],["64028.60","0.633"],["64028.90","0.523"],["64029.00","1.117"],["64029.10","0.000"],["64029.20","5.028"],["64029.50","0.138"],["64029.60","0.002"],["64029.70","0.000"],["64030.10","0.004"],["64030.20","0.003"],["64030.30","0.003"],["64030.50","0.105"],["64030.80","0.004"],["64031.00","0.314"],["64031.10","0.000"],["64031.30","0.159"],["64031.50","0.087"],["64031.60","0.040"],["64031.70","0.387"],["64031.90","0.824"],["64032.00","1.591"],["64032.10","0.006"],["64032.20","2.403"],["64032.40","0.028"],["64032.50","0.002"],["64032.70","0.001"],["64032.80","0.033"],["64032.90","0.143"],["64033.00","0.313"],["64033.30","0.009"],["64033.40","0.002"],["64033.50","0.699"],["64033.60","0.005"],["64033.70","0.141"],["64033.90","0.000"],["64034.00","1.170"],["64034.10","0.001"],["64034.30","0.022"],["64034.40","0.001"],["64034.50","0.002"],["64034.70","0.000"],["64034.80","0.001"],["64034.90","0.004"],["64035.00","0.003"],["64035.10","0.371"],["64035.20","1.405"],["64035.30","2.512"],["64035.40","0.325"],["64035.50","0.442"],["64035.70","0.608"],["64035.80","1.251"],["64036.00","0.082"],["64036.20","0.231"],["64036.60","0.011"],["64036.70","0.001"],["64037.00","0.001"],["64037.10","0.000"],["64037.30","0.000"],["64037.50","0.004"],["64037.70","0.000"],["64037.80","0.741"],["64037.90","0.042"],["64038.10","0.001"],["64038.20","0.006"],["64038.30","0.000"],["64038.40","0.379"],["64038.50","0.014"],["64038.60","2.349"],["64038.70","0.205"],["64038.80","0.002"],["64038.90","0.001"],["64039.00","0.315"],["64039.10","0.068"],["64039.20","0.059"],["64039.50","0.001"],["64039.80","0.007"],["64039.90","0.000"],["64040.00","0.673"],["64040.10","0.001"],["64040.20","0.081"],["64040.30","0.002"],["64040.40","0.001"],["64040.50","0.000"],["64040.60","0.005"],["64040.70","0.249"],["64040.80","0.010"],["64040.90","0.002"],["64041.00","0.000"],["64041.10","0.636"],["64041.20","0.001"],["64041.60","0.006"],["64041.70","4.179"],["64041.80","0.367"],["64041.90","0.002"],["64042.00","0.004"],["64042.10","1.500"],["64042.20","0.004"],["64042.30","0.095"],["64042.40","0.001"],["64042.50","0.001"],["64042.60","0.160"],["64042.70","0.000"],["64042.80","0.049"],["64043.00","0.021"],["64043.10","0.003"],["64043.20","0.002"],["64043.30","0.001"],["64043.40","0.883"],["64043.50","0.002"],["64043.70","0.000"],["64044.00","0.005"],["64044.20","0.016"],["64044.30","1.883"],["64044.40","0.548"],["64044.60","0.001"],["64044.70","0.000"],["64044.80","0.006"],["64044.90","0.222"],["64045.00","0.003"],["64045.10","0.002"],["64045.20","0.001"],["64045.40","0.001"],["64045.50","0.033"],["64045.60","0.790"],["64045.70","0.577"],["64045.80","0.004"],["64045.90","0.002"],["64046.10","0.001"],["64046.20","0.004"],["64046.30","0.000"],["64046.40","0.033"],["64046.80","0.003"],["64046.90","0.002"],["64047.00","0.001"],["64047.10","0.002"],["64047.20","0.005"],["64047.50","0.001"],["64047.60","0.002"],["64047.80","0.084"],["64047.90","0.001"],["64048.00","0.319"],["64048.10","0.003"],["64048.20","0.001"],["64048.30","0.001"],["64048.40","0.004"],["64048.60","0.002"],["64048.70","0.003"],["64048.80","0.005"],["64048.90","0.005"],["64049.00","0.001"],["64049.20","0.004"],["64049.30","0.003"],["64049.50","0.005"],["64049.60","0.002"],["64049.70","0.000"],["64049.80","0.003"],["64050.00","0.004"],["64050.10","0.000"],["64050.20","0.000"],["64050.30","0.000"],["64050.40","0.001"],["64050.50","0.002"],["64050.60","0.000"],["64050.70","0.000"],["64050.80","0.001"],["64050.90","0.000"],["64051.00","0.000"],["64051.10","0.002"],["64051.20","0.008"],["64051.30","0.004"],["64051.40","0.013"],["64051.50","0.001"],["64051.60","0.161"],["64051.70","0.000"],["64051.80","0.000"],["64051.90","0.000"],["64052.00","0.000"],["64052.10","0.000"],["64052.20","0.000"],["64052.30","0.000"],["64052.40","0.000"],["64052.50","0.000"],["64052.60","0.000"],["64052.70","0.000"],["64052.80","0.000"],["64052.90","0.000"],["64053.10","0.000"],["64053.20","0.000"],["64053.30","0.000"],["64053.40","0.000"],["64053.50","0.000"],["64053.60","0.000"],["64053.80","0.000"],["64054.00","0.000"],["64054.20","0.000"],["64054.40","0.000"],["64054.50","0.000"],["64054.60","0.000"],["64054.70","0.000"],["64054.80","0.000"],["64054.90","0.000"],["64055.00","0.000"],["64055.10","0.000"],["64055.20","0.000"],["64055.40","0.000"],["64055.50","0.000"],["64055.80","0.000"],["64056.00","0.000"],["64056.10","0.000"],["64056.30","0.000"],["64056.40","0.000"],["64056.60","0.000"],["64056.70","0.000"],["64056.90","0.000"],["64057.10","0.000"],["64057.20","0.000"],["64057.30","0.000"],["64057.40","0.000"],["64057.50","0.000"],["64057.60","0.000"]],"e":"depthUpdate","ps":"BTCUSDT","pu":11165394648806,"s":"BTCUSDT","st":1,"u":11165394691547}
