{"E":1785353525348,"T":1785353525347,"U":11165395438154,"a":[["64059.60","7.243"],["64060.10","0.710"],["64060.20","0.054"],["64060.40","0.001"],["64060.70","0.028"],["64061.50","0.408"],["64062.10","0.021"],["64062.20","0.136"],["64062.80","0.094"],["64062.90","0.479"],["64063.20","0.013"],["64063.30","0.339"],["64063.60","0.882"],["64064.00","2.230"],["64064.10","1.649"],["64064.30","0.377"],["64064.70","0.937"],["64066.30","0.000"],["64067.20","0.760"],["64067.30","0.157"],["64067.40","0.609"],["64067.50","0.006"],["64067.60","0.003"],["64067.90","0.000"],["64068.20","0.002"],["64068.30","0.024"],["64068.60","0.003"],["64068.90","0.003"],["64069.00","0.080"],["64069.10","0.128"],["64069.20","0.096"],["64069.30","0.315"],["64069.40","0.004"],["64069.50","0.001"],["64069.60","0.439"],["64070.40","3.681"],["64070.50","1.683"],["64071.40","0.158"],["64071.60","0.157"],["64071.80","0.122"],["64072.00","0.002"],["64072.10","0.047"],["64072.20","0.022"],["64072.60","0.083"],["64072.90","10.003"],["64073.60","0.709"],["64076.80","1.389"],["64080.30","0.019"],["64081.20","2.350"],["64082.30","0.022"],["64082.80","0.063"],["64085.30","0.249"],["64086.00","0.001"],["64086.20","0.009"],["64086.80","0.001"],["64087.40","0.000"],["64087.60","0.195"],["64088.40","0.018"],["64088.50","0.001"],["64089.10","0.067"],["64089.60","1.139"],["64090.00","0.064"],["64091.60","0.014"],["64092.90","0.122"],["64093.50","0.079"],["64093.70","0.004"],["64094.10","0.049"],["64094.20","0.013"],["64094.80","0.013"],["64096.10","0.162"],["64096.40","0.081"],["64096.90","0.005"],["64097.20","5.896"],["64097.30","0.033"],["64098.00","0.017"],["64098.40","0.976"],["64099.70","0.158"],["64099.90","0.819"],["64100.70","0.001"],["64101.40","0.000"],["64103.10","0.029"],["64103.30","0.678"],["64104.70","0.002"],["64105.10","0.001"],["64105.40","0.025"],["64105.60","0.005"],["64105.70","0.003"],["64105.80","0.656"],["64106.20","0.002"],["64106.30","1.259"],["64106.40","1.169"],["64106.50","0.315"],["64110.60","2.008"],["64110.70","0.011"],["64110.80","0.000"],["64112.10","0.120"],["64115.10","0.007"],["64115.40","0.003"],["64118.40","1.636"],["64118.90","0.391"],["64119.00","0.003"],["64119.10","0.211"],["64119.20","0.000"],["64120.20","0.210"],["64126.60","0.327"],["64131.40","0.015"],["64132.90","0.000"],["64133.20","3.125"],["64133.50","0.000"],["64133.80","0.001"],["64134.60","1.482"],["64195.60","0.000"],["64197.60","0.822"],["64199.60","0.000"],["64201.60","0.001"],["64203.60","0.000"],["64205.60","0.155"],["64207.60","0.020"],["64209.60","0.000"],["64379.90","3.832"],["64520.80","0.316"],["64546.50","0.097"],["64700.20","0.008"],["64946.00","40.764"],["65246.60","0.241"],["65348.10","0.004"],["65458.50","0.000"]],"b":[["1000.00","37.592"],["13553.30","0.000"],["13553.50","0.000"],["13554.70","0.000"],["13559.50","0.462"],["13659.50","0.392"],["13759.50","1.316"],["13846.60","0.028"],["13959.50","1.162"],["51237.00","0.000"],["57653.50","0.052"],["61497.10","0.000"],["62785.40","0.017"],["63073.70","3.297"],["63175.10","39.694"],["63418.90","0.000"],["63736.20","0.088"],["63739.20","0.189"],["63928.30","0.000"],["63928.40","0.064"],["63928.50","0.010"],["63966.80","0.001"],["63967.80","0.003"],["63968.10","0.000"],["63968.40","0.059"],["63968.70","3.118"],["63969.80","0.238"],["63970.00","0.484"],["63970.30","0.000"],["63970.50","0.010"],["63973.90","22.245"],["63976.10","0.167"],["63978.30","0.000"],["63994.90","0.210"],["63995.10","0.513"],["63995.30","0.922"],["63995.90","0.004"],["63996.20","1.151"],["63996.50","0.000"],["63996.80","0.069"],["63997.30","0.313"],["64000.90","0.001"],["64001.00","0.510"],["64002.20","0.001"],["64005.40","2.600"],["64005.70","0.008"],["64005.80","0.003"],["64005.90","0.060"],["64006.70","0.000"],["64007.10","0.001"],["64007.20","0.510"],["64007.50","0.982"],["64007.70","0.000"],["64007.80","0.001"],["64012.70","0.001"],["64016.20","0.000"],["64017.30","0.010"],["64017.50","0.066"],["64017.60","0.068"],["64018.70","0.000"],["64019.70","0.001"],["64021.40","1.082"],["64022.00","0.008"],["64022.30","0.242"],["64023.30","2.244"],["64024.30","0.020"],["64025.50","0.006"],["64025.80","0.642"],["64027.50","0.014"],["64027.60","0.191"],["64027.70","0.000"],["64027.80","0.001"],["64027.90","0.037"],["64028.00","0.604"],["64028.70","1.096"],["64029.20","4.203"],["64029.40","0.000"],["64029.90","0.321"],["64030.20","0.004"],["64030.90","0.312"],["64031.50","0.042"],["64031.80","0.026"],["64032.00","3.486"],["64032.20","2.407"],["64032.60","0.076"],["64032.70","2.970"],["64033.30","0.083"],["64033.50","0.679"],["64033.80","0.270"],["64034.80","0.058"],["64035.20","2.101"],["64036.80","0.002"],["64037.40","0.000"],["64038.30","0.000"],["64039.00","0.389"],["64039.50","0.144"],["64039.70","0.001"],["64039.90","0.312"],["64040.50","0.000"],["64040.70","0.110"],["64041.50","0.000"],["64042.80","0.538"],["64042.90","0.007"],["64043.10","1.250"],["64043.30","0.384"],["64044.70","2.340"],["64047.20","0.194"],["64047.30","0.235"],["64047.40","0.015"],["64047.50","0.000"],["64047.60","0.002"],["64047.70","0.665"],["64047.80","0.218"],["64047.90","0.000"],["64048.00","0.066"],["64048.10","0.097"],["64048.20","1.538"],["64048.30","2.350"],["64048.40","0.286"],["64048.50","1.468"],["64048.60","0.290"],["64048.70","0.000"],["64049.10","0.000"],["64049.30","0.062"],["64049.40","0.000"],["64049.50","0.881"],["64049.60","0.096"],["64049.70","0.003"],["64049.90","0.002"],["64050.50","0.002"],["64050.60","0.024"],["64050.80","0.002"],["64050.90","0.101"],["64051.10","0.001"],["64051.30","0.333"],["64051.40","0.000"],["64051.50","2.341"],["64051.70","0.179"],["64051.80","0.017"],["64051.90","0.000"],["64052.00","0.002"],["64052.10","0.000"],["64052.20","0.005"],["64052.80","0.005"],["64052.90","0.001"],["64053.30","0.004"],["64053.50","0.881"],["64053.60","0.005"],["64054.00","0.003"],["64054.10","0.000"],["64054.20","0.230"],["64056.30","0.002"],["64057.40","0.002"],["64057.50","0.000"],["64057.60","0.002"],["64059.50","2.211"]],"e":"depthUpdate","ps":"BTCUSDT","pu":11165395438032,"s":"BTCUSDT","st":1,"u":11165395456402}
{"E":1785353525450,"T":1785353525449,"U":11165395456439,"a":[["64059.60","7.368"],["64060.40","0.024"],["64062.10","0.025"],["64062.20","0.235"],["64062.80","0.016"],["64064.70","0.002"],["64065.90","0.938"],["64069.30","0.315"],["64070.80","0.083"],["64072.00","0.314"],["64072.10","0.197"],["64072.20","0.190"],["64096.70","1.687"],["64099.00","0.083"],["64099.90","0.835"],["64106.30","1.287"],["64112.20","0.531"],["64112.30","0.306"],["64112.40","0.952"],["64127.10","0.084"],["64193.50","0.384"],["64193.70","0.079"],["64264.60","0.117"],["64700.20","0.008"]],"b":[["13546.60","0.112"],["13551.30","0.000"],["13559.50","0.588"],["13659.50","0.350"],["13759.50","1.260"],["13846.60","0.000"],["13959.50","1.288"],["57653.50","0.052"],["61497.10","0.003"],["62785.40","0.014"],["63245.90","0.000"],["63258.80","0.486"],["63418.90","0.000"],["63739.20","0.190"],["63903.50","0.001"],["63905.50","0.001"],["63907.50","2.340"],["63909.50","0.034"],["63911.50","0.002"],["63913.50","0.000"],["63915.50","0.003"],["63917.50","0.000"],["63973.90","0.000"],["63978.30","22.245"],["63980.60","3.942"],["63981.80","0.001"],["63981.90","0.039"],["63992.50","0.126"],["63994.90","0.000"],["64002.00","0.211"],["64008.10","0.001"],["64019.40","0.003"],["64032.00","2.786"],["64044.80","0.099"],["64047.30","0.001"],["64047.40","0.075"],["64047.50","0.120"],["64047.60","0.062"],["64047.70","0.496"],["64048.20","1.531"],["64048.30","2.343"],["64048.40","0.192"],["64048.50","0.881"],["64048.60","0.290"],["64048.70","0.032"],["64049.30","0.296"],["64050.90","0.007"],["64051.10","2.341"],["64051.50","0.001"],["64051.60","1.446"],["64051.80","0.031"],["64052.10","0.003"],["64053.30","0.001"],["64054.20","0.550"],["64059.50","1.852"]],"e":"depthUpdate","ps":"BTCUSDT","pu":11165395456402,"s":"BTCUSDT","st":1,"u":11165395470504}
{"E":1785353525552,"T":1785353525550,"U":11165395470650,"a":[["64059.60","7.369"],["64060.40","0.001"],["64060.50","0.023"],["64061.40","0.006"],["64062.00","0.001"],["64065.70","0.316"],["64069.20","0.097"],["64069.80","0.237"],["64069.90","0.157"],["64070.20","0.421"],["64070.50","1.773"],["64071.20","0.101"],["64071.60","0.325"],["64071.70","0.286"],["64072.00","0.452"],["64084.20","0.798"],["64090.60","0.376"],["64097.00","0.002"],["64098.00","0.110"],["64098.30","0.108"],["64098.60","0.095"],["64099.50","0.104"],["64100.30","0.425"],["64111.80","0.173"],["64112.40","1.120"],["64126.10","0.093"],["64126.40","0.107"],["64126.80","0.151"],["64243.30","1.526"],["64243.60","0.011"],["64274.00","0.902"],["64700.20","0.008"],["64823.80","1.585"],["64824.20","0.002"],["64830.80","3.149"],["64924.40","0.569"]],"b":[["1000.00","37.592"],["13546.60","0.000"],["13559.50","0.700"],["13659.50","0.364"],["13759.50","1.134"],["13959.50","1.400"],["57653.50","0.052"],["62778.40","0.018"],["62954.90","0.554"],["63065.80","1.110"],["63361.70","0.002"],["63418.90","0.000"],["63739.20","0.190"],["63955.00","0.000"],["63955.40","0.005"],["63971.70","0.000"],["63976.10","22.412"],["63977.60","0.000"],["63978.30","0.000"],["63980.60","0.970"],["63980.80","0.015"],["63981.80","0.040"],["63981.90","0.000"],["63991.70","0.530"],["63992.80","0.033"],["63993.10","0.036"],["63993.40","0.032"],["63999.70","0.025"],["64001.60","0.000"],["64008.70","0.000"],["64020.60","10.000"],["64022.10","2.368"],["64023.30","0.244"],["64027.10","0.060"],["64027.60","0.191"],["64033.50","0.679"],["64033.80","0.235"],["64039.90","0.312"],["64040.90","0.037"],["64041.60","0.010"],["64044.80","0.101"],["64047.60","0.122"],["64047.80","0.278"],["64047.90","0.060"],["64048.30","2.375"],["64049.00","0.033"],["64049.30","0.094"],["64049.40","0.094"],["64049.60","0.002"],["64049.70","0.035"],["64050.10","0.234"],["64057.40","0.218"],["64059.50","1.848"]],"e":"depthUpdate","ps":"BTCUSDT","pu":11165395470504,"s":"BTCUSDT","st":1,"u":11165395480385}
{"E":1785353525654,"T":1785353525652,"U":11165395480586,"a":[["64059.60","7.241"],["64060.10","0.456"],["64060.20","0.056"],["64061.40","0.006"],["64062.20","0.136"],["64062.80","0.016"],["64063.60","0.001"],["64063.70","0.000"],["64064.00","1.389"],["64064.50","0.002"],["64065.20","0.012"],["64066.00","0.007"],["64067.30","0.256"],["64068.60","0.001"],["64069.50","0.158"],["64070.00","0.820"],["64071.30","0.324"],["64071.90","0.731"],["64072.00","0.590"],["64072.20","0.346"],["64073.50","0.317"],["64074.10","3.401"],["64077.00","0.003"],["64077.40","0.002"],["64081.00","0.015"],["64082.90","1.118"],["64088.50","0.003"],["64091.90","0.523"],["64094.90","0.456"],["64095.00","0.002"],["64095.10","0.103"],["64098.80","0.079"],["64112.00","0.216"],["64112.10","0.288"],["64112.60","0.620"],["64112.80","0.156"],["64150.80","4.737"],["64193.60","0.042"],["64193.70","0.040"],["64268.60","0.006"],["64268.70","0.002"],["64268.80","0.244"],["64390.40","2.752"],["64487.00","3.573"],["64487.50","0.000"],["64669.40","0.000"],["64700.20","0.008"],["65114.20","1.438"],["65300.00","26.534"],["65372.80","1.222"]],"b":[["1000.00","37.592"],["13559.50","0.826"],["13659.50","0.350"],["13759.50","1.022"],["13859.50","0.126"],["13959.50","1.274"],["57653.50","0.052"],["61497.10","0.000"],["62965.50","0.005"],["63418.90","0.000"],["63720.50","0.017"],["63721.00","3.290"],["63746.50","0.817"],["63851.30","0.000"],["63976.10","0.167"],["63978.30","22.245"],["63983.50","7.711"],["63999.30","0.003"],["63999.70","0.000"],["64008.60","0.038"],["64009.20","0.010"],["64010.00","0.033"],["64010.90","2.120"],["64020.60","0.000"],["64022.10","0.946"],["64024.40","2.360"],["64028.00","0.042"],["64029.30","0.002"],["64030.50","0.562"],["64031.60","0.008"],["64039.90","0.000"],["64041.90","0.316"],["64047.40","0.135"],["64047.50","0.180"],["64047.70","0.556"],["64048.20","0.108"],["64050.60","0.024"],["64050.70","0.001"],["64050.80","0.002"],["64050.90","0.005"],["64051.10","2.343"],["64051.40","0.022"],["64051.80","1.514"],["64052.10","0.000"],["64052.80","0.002"],["64053.70","0.006"],["64059.50","2.805"]],"e":"depthUpdate","ps":"BTCUSDT","pu":11165395480385,"s":"BTCUSDT","st":1,"u":11165395489779}
{"E":1785353525756,"T":1785353525752,"U":11165395489913,"a":[["64059.60","7.086"],["64059.70","0.181"],["64060.20","0.054"],["64061.40","0.001"],["64061.60","0.002"],["64062.00","0.001"],["64062.20","0.001"],["64062.80","0.022"],["64064.30","0.376"],["64065.20","0.012"],["64065.70","0.317"],["64067.30","0.157"],["64068.30","0.008"],["64070.70","0.214"],["64071.80","0.290"],["64072.10","0.353"],["64072.30","0.680"],["64074.80","0.003"],["64075.00","0.007"],["64081.50","0.002"],["64086.20","0.001"],["64086.60","0.297"],["64087.00","0.011"],["64094.10","0.033"],["64112.30","0.462"],["64112.40","1.288"],["64112.50","0.153"],["64145.40","9.322"],["64147.50","24.319"],["64150.80","1.256"],["64152.00","0.002"],["64193.20","0.200"],["64264.60","0.252"],["64267.20","0.099"],["64700.20","0.008"],["65340.70","2.812"],["65348.10","0.001"]],"b":[["13559.50","0.938"],["13656.70","0.462"],["13656.90","0.000"],["13658.70","0.000"],["13659.40","0.000"],["13659.50","0.448"],["13759.50","0.896"],["13859.50","0.238"],["13959.50","1.162"],["57653.50","0.052"],["61497.10","0.003"],["63258.80","1.196"],["63418.90","0.000"],["63739.20","0.116"],["63905.50","0.001"],["63907.50","2.340"],["63909.50","0.034"],["63911.50","0.002"],["63913.50","0.000"],["63915.50","0.885"],["63917.30","0.000"],["63917.50","0.882"],["63964.30","3.166"],["63965.30","0.037"],["63999.20","0.025"],["64007.20","0.570"],["64007.60","0.133"],["64008.60","0.013"],["64019.90","2.715"],["64028.20","10.004"],["64028.40","0.013"],["64042.80","0.554"],["64047.30","0.061"],["64047.50","0.240"],["64047.80","0.338"],["64048.40","0.002"],["64050.10","0.000"],["64050.50","0.236"],["64050.60","0.001"],["64051.10","2.533"],["64051.60","1.540"],["64051.70","0.022"],["64051.90","0.000"],["64052.00","0.025"],["64053.50","0.883"],["64053.70","0.000"],["64054.30","0.081"],["64054.40","0.016"],["64054.60","0.002"],["64059.50","3.562"]],"e":"depthUpdate","ps":"BTCUSDT","pu":11165395489779,"s":"BTCUSDT","st":1,"u":11165395496518}
{"E":1785353525858,"T":1785353525857,"U":11165395496897,"a":[["64059.60","6.603"],["64060.70","0.005"],["64061.60","0.000"],["64063.00","0.002"],["64063.50","0.062"],["64063.90","0.236"],["64064.00","1.349"],["64069.00","0.080"],["64069.40","0.001"],["64070.00","0.508"],["64070.40","3.046"],["64070.70","0.136"],["64071.00","4.342"],["64071.40","0.002"],["64072.80","0.074"],["64072.90","0.003"],["64073.50","0.629"],["64073.90","0.315"],["64074.20","0.570"],["64077.80","0.470"],["64079.30","0.327"],["64080.40","0.204"],["64081.30","0.003"],["64083.90","2.342"],["64085.60","0.610"],["64086.00","10.001"],["64086.40","0.009"],["64103.10","0.186"],["64103.30","0.521"],["64111.40","0.004"],["64111.50","0.341"],["64127.80","0.101"],["64147.50","0.001"],["64193.60","0.003"],["64193.70","0.079"],["64387.10","0.010"],["64693.80","0.698"],["64700.20","0.008"],["65103.90","2.585"]],"b":[["1000.00","37.592"],["13559.50","1.064"],["13656.70","0.336"],["13659.50","0.560"],["13759.50","0.784"],["13859.50","0.364"],["13959.50","1.036"],["57653.50","0.052"],["61497.10","0.000"],["62778.30","0.318"],["62778.40","0.021"],["63230.40","0.002"],["63257.00","0.270"],["63361.30","0.708"],["63418.90","0.000"],["63739.20","0.001"],["63851.30","0.117"],["63915.50","0.003"],["63917.50","0.000"],["63919.60","0.575"],["63963.30","0.410"],["63964.60","0.032"],["63964.90","0.032"],["63971.70","22.245"],["63978.30","0.000"],["63999.20","0.000"],["64007.10","0.061"],["64007.30","0.060"],["64007.40","0.060"],["64008.60","0.038"],["64024.40","0.360"],["64029.30","0.002"],["64030.50","0.000"],["64031.00","0.563"],["64033.30","0.003"],["64039.50","0.050"],["64041.80","2.562"],["64043.60","0.007"],["64044.80","0.101"],["64045.50","0.003"],["64047.20","0.003"],["64047.80","0.181"],["64050.30","0.096"],["64050.50","0.002"],["64050.70","0.314"],["64051.10","2.767"],["64051.40","0.007"],["64051.90","0.040"],["64052.00","0.002"],["64052.80","0.119"],["64052.90","0.001"],["64053.60","0.196"],["64054.30","0.078"],["64054.40","0.013"],["64054.70","0.097"],["64055.10","0.001"],["64055.20","0.004"],["64056.80","0.005"],["64059.50","2.965"]],"e":"depthUpdate","ps":"BTCUSDT","pu":11165395496518,"s":"BTCUSDT","st":1,"u":11165395506202}
{"E":1785353525960,"T":1785353525959,"U":11165395506248,"a":[["64059.60","15.057"],["64059.70","0.183"],["64060.10","0.681"],["64060.20","0.055"],["64060.90","0.005"],["64061.30","0.002"],["64061.40","0.007"],["64061.90","0.002"],["64062.00","0.003"],["64062.20","0.235"],["64062.80","0.016"],["64063.00","0.000"],["64063.60","0.883"],["64063.80","0.001"],["64063.90","0.206"],["64064.00","1.895"],["64064.10","1.103"],["64064.30","0.376"],["64065.20","0.002"],["64065.70","0.316"],["64066.90","0.028"],["64067.00","0.829"],["64067.70","0.067"],["64068.70","0.028"],["64068.90","0.023"],["64069.00","2.080"],["64069.10","0.003"],["64069.20","0.096"],["64069.40","0.004"],["64069.50","0.001"],["64069.80","0.315"],["64070.00","0.625"],["64070.30","0.001"],["64071.00","4.654"],["64071.60","0.325"],["64071.70","0.169"],["64072.40","0.346"],["64073.50","0.160"],["64074.00","0.004"],["64074.10","3.401"],["64076.70","0.005"],["64076.80","1.387"],["64076.90","0.091"],["64079.00","0.000"],["64079.30","0.327"],["64081.70","0.549"],["64082.00","0.083"],["64083.90","1.255"],["64084.90","0.090"],["64085.10","0.054"],["64085.30","0.424"],["64085.70","0.120"],["64086.00","0.052"],["64086.20","0.001"],["64086.40","0.017"],["64086.70","0.007"],["64087.00","0.003"],["64092.00","0.545"],["64092.90","0.002"],["64093.20","0.016"],["64093.50","0.030"],["64094.20","0.083"],["64098.10","0.003"],["64102.50","0.159"],["64103.00","0.004"],["64103.10","0.029"],["64104.20","0.017"],["64105.80","0.656"],["64108.10","0.094"],["64108.30","0.025"],["64111.50","0.341"],["64115.00","0.028"],["64123.20","0.002"],["64152.00","24.540"],["64204.10","0.008"],["64210.00","0.007"],["64264.60","0.117"],["64267.20","0.000"],["64700.20","0.008"]],"b":[["1000.00","37.792"],["13559.50","1.176"],["13656.70","0.224"],["13659.50","0.686"],["13759.50","0.658"],["13859.50","0.476"],["13959.50","0.924"],["51237.00","0.002"],["51248.00","0.000"],["57653.50","0.052"],["60856.50","0.002"],["61497.10","0.003"],["62735.70","0.000"],["62992.20","0.679"],["63198.90","0.394"],["63297.90","4.694"],["63418.90","0.000"],["63736.20","0.089"],["63901.50","4.405"],["63903.50","0.883"],["63905.50","0.883"],["63907.50","3.222"],["63909.50","0.916"],["63911.50","0.884"],["63913.50","0.882"],["63915.50","0.885"],["63971.70","0.000"],["63976.10","21.801"],["63979.80","0.320"],["63985.20","3.252"],["63994.50","0.001"],["63995.50","0.211"],["63998.70","0.029"],["64001.80","0.118"],["64002.00","0.001"],["64007.20","0.630"],["64007.70","0.060"],["64008.60","0.013"],["64013.50","0.134"],["64014.60","1.265"],["64017.30","0.987"],["64019.30","0.613"],["64023.70","2.279"],["64023.90","0.363"],["64025.70","0.137"],["64028.10","0.001"],["64028.20","10.006"],["64028.60","0.004"],["64029.20","4.763"],["64029.90","0.009"],["64030.00","0.028"],["64030.10","0.004"],["64030.70","0.009"],["64031.00","0.001"],["64031.60","0.001"],["64032.60","0.006"],["64032.80","0.058"],["64034.40","0.022"],["64036.40","0.006"],["64036.60","0.124"],["64037.10","0.094"],["64038.30","0.094"],["64039.00","0.349"],["64039.10","0.025"],["64039.50","0.095"],["64040.20","0.001"],["64041.80","2.482"],["64041.90","0.004"],["64042.00","0.002"],["64042.40","0.111"],["64042.80","0.538"],["64044.60","2.158"],["64044.80","1.103"],["64045.00","0.023"],["64045.50","1.330"],["64046.60","1.283"],["64046.80","0.002"],["64046.90","0.386"],["64047.20","0.192"],["64048.10","0.003"],["64048.30","0.035"],["64048.40","0.192"],["64048.50","0.000"],["64048.70","1.040"],["64048.80","0.022"],["64049.40","0.000"],["64049.50","0.000"],["64049.90","0.002"],["64050.00","0.030"],["64050.20","0.004"],["64050.30","0.002"],["64050.50","0.017"],["64050.60","0.001"],["64050.70","0.001"],["64051.00","0.294"],["64051.10","0.003"],["64051.30","0.233"],["64051.40","0.000"],["64051.60","0.859"],["64051.70","0.022"],["64051.80","0.029"],["64051.90","0.000"],["64052.00","0.005"],["64052.10","0.003"],["64052.30","0.004"],["64052.50","0.000"],["64052.80","0.002"],["64053.60","0.005"],["64053.70","0.000"],["64054.40","0.004"],["64054.70","0.094"],["64055.20","0.001"],["64055.50","0.000"],["64056.30","0.001"],["64057.40","0.002"],["64059.50","1.871"]],"e":"depthUpdate","ps":"BTCUSDT","pu":11165395506202,"s":"BTCUSDT","st":1,"u":11165395527600}
{"E":1785353526062,"T":1785353526061,"U":11165395527754,"a":[["64059.60","14.210"],["64059.70","0.184"],["64059.80","0.082"],["64060.10","0.940"],["64060.20","0.054"],["64060.30","0.004"],["64060.40","0.006"],["64060.50","0.000"],["64060.70","0.005"],["64060.80","0.066"],["64060.90","0.608"],["64061.00","0.002"],["64061.10","0.002"],["64061.40","0.007"],["64061.60","0.000"],["64062.60","0.941"],["64062.80","0.016"],["64063.40","0.548"],["64063.50","0.062"],["64063.60","0.001"],["64063.70","0.000"],["64063.90","0.050"],["64064.00","1.349"],["64064.10","1.103"],["64064.40","0.145"],["64064.60","0.020"],["64065.10","0.001"],["64065.20","0.064"],["64065.50","0.000"],["64065.60","0.352"],["64065.80","0.001"],["64065.90","0.003"],["64066.70","0.820"],["64066.90","0.028"],["64067.00","0.323"],["64067.20","2.430"],["64067.30","0.719"],["64067.90","0.000"],["64068.10","0.027"],["64068.50","0.106"],["64068.70","0.008"],["64068.80","0.258"],["64068.90","0.003"],["64069.00","0.080"],["64069.20","0.096"],["64069.40","10.001"],["64069.80","0.244"],["64069.90","0.095"],["64070.00","0.508"],["64070.20","0.107"],["64070.40","2.603"],["64071.10","3.098"],["64071.60","0.464"],["64071.90","0.169"],["64072.30","0.673"],["64073.40","0.001"],["64073.50","0.003"],["64073.80","0.156"],["64074.20","0.313"],["64074.60","10.150"],["64076.20","0.636"],["64076.90","0.080"],["64078.50","0.524"],["64078.90","0.000"],["64080.40","0.047"],["64080.80","1.952"],["64081.90","0.003"],["64082.90","1.030"],["64083.90","1.312"],["64084.90","0.000"],["64085.70","0.000"],["64089.10","0.010"],["64091.40","0.096"],["64092.30","0.121"],["64098.00","0.107"],["64105.80","0.681"],["64108.30","0.000"],["64143.10","0.030"],["64153.80","0.020"],["64155.60","0.508"],["64162.80","0.000"],["64185.60","0.031"],["64187.60","0.003"],["64189.60","0.001"],["64191.60","0.000"],["64193.60","0.042"],["64193.70","0.040"],["64195.60","0.000"],["64197.60","0.822"],["64199.60","0.000"],["64201.60","0.001"],["64203.60","0.000"],["64205.60","0.155"],["64207.60","0.020"],["64209.60","0.000"],["64216.10","0.000"],["64316.00","0.004"],["64323.20","0.000"],["64476.80","0.008"],["64484.00","0.011"],["64638.00","0.091"],["64645.20","0.000"],["64700.20","0.008"],["65116.60","1.118"],["65286.60","0.766"]],"b":[["13559.50","1.302"],["13656.70","0.098"],["13659.50","0.798"],["13759.50","0.546"],["13859.50","0.602"],["13959.50","0.798"],["51237.00","0.000"],["51247.60","0.000"],["57653.50","0.052"],["62778.40","0.024"],["62846.00","0.000"],["63418.90","0.000"],["63486.20","0.016"],["63493.30","0.000"],["63620.00","0.702"],["63644.90","1.110"],["63652.00","0.078"],["63804.00","0.086"],["63811.20","0.001"],["63828.90","0.010"],["63851.30","0.000"],["63901.50","3.523"],["63903.50","0.001"],["63905.50","0.001"],["63907.50","2.340"],["63909.50","0.034"],["63911.50","0.002"],["63913.50","0.000"],["63915.50","0.003"],["63936.20","0.095"],["63937.20","0.034"],["63951.60","0.017"],["63962.30","0.000"],["63963.50","0.002"],["63970.70","4.080"],["63971.70","0.000"],["63976.10","21.801"],["63996.90","0.003"],["64001.80","0.001"],["64007.00","0.017"],["64007.40","0.120"],["64008.30","0.003"],["64010.50","0.000"],["64010.90","2.031"],["64013.30","0.002"],["64013.90","10.003"],["64014.70","0.000"],["64015.90","0.369"],["64023.50","0.563"],["64026.40","0.000"],["64027.20","0.010"],["64027.90","0.000"],["64028.10","0.002"],["64028.20","0.006"],["64028.30","0.312"],["64029.00","2.012"],["64029.20","4.201"],["64029.30","0.002"],["64030.20","0.015"],["64030.70","0.002"],["64030.90","0.312"],["64031.10","0.057"],["64032.00","1.851"],["64033.20","0.122"],["64033.60","0.040"],["64033.90","0.042"],["64034.40","0.315"],["64034.90","0.337"],["64035.10","0.897"],["64036.60","0.004"],["64036.90","0.295"],["64037.80","0.376"],["64038.20","0.502"],["64038.60","0.319"],["64039.00","0.002"],["64039.70","0.101"],["64040.80","0.204"],["64040.90","0.002"],["64041.10","0.000"],["64041.90","0.004"],["64042.40","0.071"],["64042.60","0.061"],["64043.10","0.061"],["64043.70","0.032"],["64043.80","0.002"],["64044.10","0.015"],["64044.60","1.324"],["64044.70","2.372"],["64044.80","0.983"],["64044.90","0.646"],["64045.40","0.096"],["64045.50","0.885"],["64045.60","0.002"],["64045.70","0.192"],["64046.60","1.283"],["64046.70","0.004"],["64046.90","0.003"],["64047.00","0.017"],["64047.10","0.000"],["64047.20","0.001"],["64047.40","0.015"],["64047.50","0.000"],["64047.60","0.002"],["64047.70","0.238"],["64047.80","0.001"],["64047.90","0.397"],["64048.00","0.122"],["64048.10","0.001"],["64048.20","0.048"],["64048.30","0.003"],["64048.40","0.002"],["64048.60","0.002"],["64048.70","1.008"],["64048.80","0.178"],["64048.90","0.001"],["64049.00","0.890"],["64049.20","0.013"],["64049.30","0.062"],["64049.50","0.882"],["64049.60","0.009"],["64049.70","0.003"],["64049.90","0.002"],["64050.00","0.011"],["64050.70","0.007"],["64050.80","0.001"],["64051.00","0.798"],["64051.50","0.883"],["64051.60","1.438"],["64052.00","0.002"],["64052.10","0.000"],["64052.30","0.001"],["64053.10","0.348"],["64053.50","0.000"],["64053.60","0.004"],["64053.70","0.176"],["64054.20","0.000"],["64054.30","0.079"],["64055.60","0.002"],["64055.70","0.001"],["64056.80","0.001"],["64059.50","2.628"]],"e":"depthUpdate","ps":"BTCUSDT","pu":11165395527600,"s":"BTCUSDT","st":1,"u":11165395544708}
{"E":1785353526164,"T":1785353526163,"U":11165395544752,"a":[["64059.60","7.313"],["64059.80","0.023"],["64060.40","0.001"],["64060.80","0.066"],["64061.10","0.001"],["64061.40","0.006"],["64061.90","0.002"],["64062.20","0.136"],["64062.60","0.006"],["64063.00","0.008"],["64063.20","0.209"],["64063.70","0.935"],["64063.90","0.596"],["64064.00","1.255"],["64064.20","2.345"],["64065.50","0.003"],["64066.70","0.001"],["64067.00","0.283"],["64067.20","0.992"],["64067.30","0.157"],["64067.60","0.001"],["64068.60","0.118"],["64069.30","0.877"],["64069.40","0.003"],["64071.30","0.480"],["64072.90","0.001"],["64073.70","3.915"],["64073.80","0.000"],["64078.90","10.000"],["64083.90","1.255"],["64085.70","0.057"],["64086.00","0.003"],["64092.30","0.001"],["64092.70","0.097"],["64094.20","0.013"],["64097.90","0.025"],["64098.40","0.980"],["64099.00","0.203"],["64101.30","0.074"],["64108.30","0.000"],["64120.20","0.000"],["64126.70","0.210"],["64185.60","0.913"],["64187.60","0.885"],["64189.60","0.883"],["64191.60","0.882"],["64193.60","0.924"],["64195.60","0.882"],["64197.60","1.704"],["64199.60","0.882"],["64201.60","0.883"],["64203.60","0.882"],["64205.60","1.037"],["64207.60","0.902"],["64209.60","0.882"],["64211.60","0.882"],["64213.60","0.794"],["64264.60","0.216"],["64520.80","0.522"],["64533.60","0.322"],["64575.70","0.000"],["64604.40","0.012"],["64700.20","0.008"],["64833.20","0.000"],["65136.30","0.012"],["65340.70","2.815"],["65347.50","0.000"]],"b":[["1000.00","37.792"],["13559.50","1.386"],["13656.70","0.000"],["13659.50","0.924"],["13759.50","0.420"],["13859.50","0.714"],["13959.50","0.700"],["57653.50","0.052"],["60856.50","0.008"],["61497.10","0.000"],["62781.90","0.000"],["62784.80","0.000"],["62983.30","0.015"],["62983.60","0.008"],["63297.90","3.130"],["63418.90","0.000"],["63739.20","0.001"],["63828.90","0.189"],["63832.10","0.179"],["63935.00","0.094"],["63936.50","0.059"],["63936.80","0.000"],["63967.00","0.087"],["63967.30","0.004"],["63976.10","0.167"],["63978.30","21.634"],["63991.80","0.060"],["64001.80","0.118"],["64002.10","0.127"],["64005.40","2.444"],["64008.30","0.042"],["64013.90","0.003"],["64014.70","0.000"],["64018.30","2.065"],["64020.70","0.020"],["64023.50","0.001"],["64024.30","0.000"],["64027.20","0.009"],["64028.10","0.001"],["64028.20","0.004"],["64028.40","0.575"],["64029.20","4.203"],["64037.10","0.000"],["64038.30","0.000"],["64039.50","0.001"],["64040.80","0.013"],["64041.30","0.215"],["64042.30","0.004"],["64042.50","0.120"],["64042.80","0.658"],["64043.00","0.844"],["64043.30","0.416"],["64043.40","1.254"],["64044.00","0.090"],["64044.30","0.032"],["64044.90","0.079"],["64045.00","0.037"],["64045.60","0.065"],["64045.70","0.002"],["64045.80","0.003"],["64046.70","0.004"],["64046.80","0.315"],["64047.20","0.192"],["64047.70","0.004"],["64047.90","0.619"],["64048.80","0.192"],["64049.00","0.883"],["64049.10","2.340"],["64049.30","0.156"],["64049.50","1.116"],["64049.60","2.112"],["64049.70","0.065"],["64049.80","0.001"],["64050.40","0.094"],["64050.50","0.017"],["64050.60","0.001"],["64050.70","0.007"],["64050.90","0.005"],["64051.00","0.810"],["64051.60","0.009"],["64051.70","0.116"],["64051.80","0.053"],["64053.10","0.013"],["64053.20","0.003"],["64053.50","0.882"],["64053.70","0.314"],["64059.50","3.417"]],"e":"depthUpdate","ps":"BTCUSDT","pu":11165395544708,"s":"BTCUSDT","st":1,"u":11165395559660}
{"E":1785353526266,"T":1785353526265,"U":11165395559703,"a":[["64059.60","6.615"],["64059.70","0.181"],["64059.80","0.001"],["64060.00","0.003"],["64060.10","0.288"],["64060.20","0.054"],["64060.30","0.004"],["64060.80","0.003"],["64060.90","0.000"],["64061.40","0.001"],["64061.50","0.095"],["64062.20","0.001"],["64062.80","0.016"],["64063.00","0.000"],["64063.20","0.013"],["64063.40","0.002"],["64063.70","0.006"],["64063.90","0.008"],["64064.00","0.006"],["64064.10","0.569"],["64064.20","0.006"],["64065.00","0.561"],["64065.10","0.001"],["64065.20","0.002"],["64065.30","0.937"],["64065.50","0.000"],["64066.50","0.002"],["64067.00","0.158"],["64067.10","0.018"],["64067.20","1.416"],["64067.30","0.157"],["64067.70","0.051"],["64068.30","0.710"],["64068.40","2.350"],["64068.60","0.001"],["64069.10","0.128"],["64069.20","0.097"],["64069.40","0.001"],["64069.80","0.299"],["64070.30","0.158"],["64070.90","0.118"],["64071.00","3.998"],["64071.30","0.244"],["64071.70","0.825"],["64071.80","0.297"],["64072.40","0.002"],["64073.50","0.160"],["64073.60","0.789"],["64073.70","1.915"],["64074.00","0.161"],["64076.00","0.005"],["64076.30","2.567"],["64076.70","0.003"],["64077.50","0.107"],["64078.80","3.507"],["64078.90","0.000"],["64079.30","0.292"],["64079.80","0.159"],["64079.90","0.378"],["64081.50","0.002"],["64082.00","0.427"],["64082.60","0.012"],["64082.70","4.099"],["64082.80","0.013"],["64083.60","0.002"],["64085.70","0.000"],["64086.40","0.009"],["64086.90","0.426"],["64087.20","1.292"],["64087.50","1.109"],["64087.90","0.008"],["64089.30","0.052"],["64089.40","2.001"],["64089.60","1.079"],["64093.20","0.000"],["64096.10","0.158"],["64096.40","0.085"],["64096.90","0.001"],["64097.20","5.960"],["64108.30","0.012"],["64114.50","0.000"],["64179.60","0.846"],["64181.60","0.815"],["64183.60","0.000"],["64185.60","0.031"],["64187.60","0.003"],["64189.60","0.001"],["64191.60","0.000"],["64192.30","1.049"],["64193.60","0.003"],["64195.60","0.000"],["64197.60","0.822"],["64199.60","0.000"],["64201.60","0.001"],["64203.60","0.000"],["64205.60","0.155"],["64207.60","0.020"],["64209.60","0.000"],["64211.60","0.000"],["64213.60","0.001"],["64264.60","0.216"],["64267.80","0.124"],["64340.00","0.066"],["64379.90","3.831"],["64400.00","11.971"],["64482.40","0.327"],["64508.00","0.206"],["64520.80","0.316"],["64533.60","0.006"],["64700.20","0.008"],["65135.90","0.017"],["65344.40","0.006"]],"b":[["1000.00","37.792"],["13559.50","1.260"],["13659.50","1.036"],["13759.50","0.308"],["13859.50","0.840"],["13959.50","0.700"],["51248.00","0.002"],["57653.50","0.052"],["61497.10","0.003"],["62714.30","0.319"],["63290.80","1.578"],["63418.90","0.000"],["63694.60","0.000"],["63705.20","0.770"],["63736.20","0.088"],["63905.50","0.001"],["63907.50","2.340"],["63909.50","0.034"],["63911.50","0.002"],["63913.50","0.000"],["63928.30","0.002"],["63928.40","0.066"],["63928.50","0.012"],["63966.90","0.559"],["63967.10","0.120"],["63976.10","21.801"],["63978.30","0.000"],["63979.80","0.320"],["63991.80","0.000"],["63995.50","0.001"],["63998.70","0.004"],["64000.50","0.024"],["64001.80","0.157"],["64003.10","0.050"],["64004.60","0.211"],["64005.70","0.004"],["64005.80","0.007"],["64007.50","0.005"],["64007.80","0.026"],["64008.30","0.159"],["64011.40","0.050"],["64017.30","0.984"],["64017.50","0.069"],["64018.30","0.065"],["64020.30","0.007"],["64022.00","0.004"],["64022.30","0.246"],["64023.80","1.955"],["64025.70","0.067"],["64025.80","0.522"],["64027.40","0.014"],["64027.70","0.002"],["64028.20","0.124"],["64029.00","1.077"],["64029.30","0.081"],["64030.00","0.418"],["64030.20","0.017"],["64030.30","0.002"],["64030.40","0.337"],["64030.50","0.002"],["64030.60","0.148"],["64030.70","0.004"],["64031.10","0.000"],["64031.50","0.977"],["64031.90","2.017"],["64032.80","0.008"],["64033.20","0.002"],["64033.30","0.198"],["64033.60","0.005"],["64034.30","0.071"],["64035.30","2.406"],["64035.40","0.002"],["64039.70","0.159"],["64040.70","0.016"],["64041.20","0.349"],["64041.40","0.002"],["64041.80","2.437"],["64041.90","0.660"],["64042.30","0.001"],["64042.40","0.131"],["64042.60","0.181"],["64042.90","0.023"],["64043.00","0.750"],["64043.40","1.374"],["64044.60","1.322"],["64044.90","0.000"],["64045.00","0.023"],["64047.30","0.076"],["64047.90","0.621"],["64048.00","0.100"],["64048.50","0.000"],["64049.00","0.001"],["64049.10","2.342"],["64049.20","0.001"],["64049.50","0.882"],["64049.60","1.908"],["64049.70","0.065"],["64049.90","0.002"],["64050.00","0.008"],["64050.10","0.116"],["64050.50","0.002"],["64050.60","0.235"],["64050.70","0.001"],["64050.80","0.314"],["64051.00","1.131"],["64051.10","0.001"],["64051.60","0.009"],["64051.70","0.677"],["64051.80","2.517"],["64051.90","0.000"],["64052.00","0.045"],["64052.30","0.048"],["64053.00","0.000"],["64053.10","0.098"],["64053.20","0.015"],["64053.30","0.001"],["64053.40","0.004"],["64053.70","0.748"],["64054.30","0.087"],["64054.40","0.004"],["64054.50","0.009"],["64055.50","0.882"],["64055.60","0.567"],["64055.80","0.000"],["64056.30","0.002"],["64056.40","0.008"],["64057.30","0.435"],["64057.40","0.002"],["64057.50","0.882"],["64057.60","0.353"],["64059.50","3.550"]],"e":"depthUpdate","ps":"BTCUSDT","pu":11165395559660,"s":"BTCUSDT","st":1,"u":11165395575410}
{"E":1785353526368,"T":1785353526364,"U":11165395575567,"a":[["64059.60","6.286"],["64060.10","0.194"],["64060.20","0.148"],["64062.00","0.003"],["64063.90","0.000"],["64064.10","0.772"],["64064.90","0.000"],["64065.00","0.005"],["64065.10","0.555"],["64065.20","0.884"],["64066.50","0.012"],["64067.00","0.158"],["64067.10","0.980"],["64068.20","0.822"],["64069.20","0.098"],["64069.30","0.877"],["64070.30","0.001"],["64071.30","0.324"],["64071.90","0.172"],["64073.50","0.003"],["64073.60","0.009"],["64074.00","0.004"],["64079.80","0.002"],["64082.60","0.012"],["64084.80","0.016"],["64084.90","0.000"],["64086.50","0.037"],["64086.90","0.391"],["64088.50","10.003"],["64089.40","0.001"],["64093.00","0.018"],["64098.00","0.106"],["64110.60","1.983"],["64111.00","0.261"],["64114.50","0.003"],["64115.00","0.013"],["64119.70","0.025"],["64124.40","0.016"],["64179.60","0.000"],["64181.60","0.000"],["64185.60","0.913"],["64187.60","0.885"],["64189.60","0.883"],["64191.60","0.882"],["64192.30","1.010"],["64193.60","0.885"],["64193.70","0.079"],["64195.60","0.882"],["64197.60","1.704"],["64199.60","0.882"],["64201.60","0.883"],["64203.60","0.882"],["64205.60","1.037"],["64207.60","0.902"],["64209.60","0.882"],["64211.60","0.882"],["64213.60","0.883"],["64215.60","0.829"],["64243.60","0.008"],["64243.70","2.456"],["64700.20","0.008"],["65340.70","2.818"]],"b":[["13559.50","1.148"],["13659.50","1.162"],["13759.50","0.182"],["13859.50","0.952"],["13959.50","0.700"],["51248.00","0.000"],["57653.50","0.052"],["61497.10","0.000"],["63112.10","0.000"],["63225.00","0.155"],["63241.00","1.140"],["63258.80","1.432"],["63418.90","0.000"],["63739.20","0.001"],["63966.60","0.628"],["63967.50","0.000"],["63976.10","0.167"],["63978.30","21.634"],["63991.00","0.062"],["64004.20","0.210"],["64004.60","0.001"],["64005.20","0.156"],["64005.60","0.164"],["64013.10","0.002"],["64023.90","0.283"],["64028.70","1.096"],["64033.40","0.112"],["64040.50","0.120"],["64042.70","0.062"],["64042.80","0.718"],["64043.00","0.810"],["64043.40","1.254"],["64044.80","0.121"],["64044.90","0.000"],["64045.10","0.001"],["64045.20","0.000"],["64045.50","0.003"],["64045.60","0.127"],["64047.90","0.347"],["64048.80","0.195"],["64049.50","0.000"],["64049.60","1.752"],["64049.70","0.003"],["64050.00","0.030"],["64050.10","0.000"],["64050.60","0.001"],["64051.40","0.234"],["64051.70","0.116"],["64051.80","2.342"],["64051.90","0.302"],["64052.00","0.742"],["64053.20","0.014"],["64053.40","0.001"],["64053.80","0.001"],["64054.40","0.098"],["64054.50","0.009"],["64054.60","0.002"],["64054.70","0.094"],["64054.80","0.006"],["64054.90","0.003"],["64055.00","0.002"],["64055.50","0.884"],["64055.60","0.568"],["64056.80","0.003"],["64059.50","3.470"]],"e":"depthUpdate","ps":"BTCUSDT","pu":11165395575410,"s":"BTCUSDT","st":1,"u":11165395596411}
{"E":1785353526470,"T":1785353526469,"U":11165395596830,"a":[["64059.60","5.516"],["64060.10","0.172"],["64060.20","0.054"],["64062.00","0.005"],["64062.40","0.003"],["64062.60","0.008"],["64064.00","0.228"],["64064.10","1.213"],["64064.20","0.004"],["64064.60","0.000"],["64065.00","2.913"],["64065.10","0.009"],["64065.20","0.002"],["64065.30","0.002"],["64066.30","0.935"],["64066.90","0.028"],["64067.00","0.158"],["64067.10","0.564"],["64068.20","0.002"],["64068.30","0.008"],["64069.30","0.315"],["64069.60","0.459"],["64069.80","0.065"],["64071.00","3.686"],["64071.70","1.387"],["64073.60","0.321"],["64088.50","0.003"],["64092.10","10.402"],["64185.60","0.031"],["64187.60","0.003"],["64189.60","0.001"],["64191.60","0.000"],["64193.20","0.722"],["64193.60","0.003"],["64195.60","0.000"],["64197.60","0.822"],["64199.60","0.000"],["64201.60","0.001"],["64203.60","0.000"],["64205.60","0.155"],["64207.60","0.020"],["64209.60","0.000"],["64211.60","0.000"],["64213.60","0.001"],["64215.60","0.000"],["64236.40","0.179"],["64262.00","0.111"],["64379.90","3.832"],["64518.80","0.001"],["64520.00","0.419"],["64700.20","0.010"],["64775.60","0.000"],["64860.30","0.261"],["65045.30","4.260"],["65344.40","0.003"]],"b":[["1000.00","37.792"],["13559.50","1.022"],["13659.50","1.274"],["13759.50","0.070"],["13859.50","1.078"],["13959.50","0.700"],["57653.50","0.052"],["63231.20","0.004"],["63290.00","1.905"],["63418.90","0.000"],["63561.40","0.184"],["63739.20","0.011"],["63905.50","0.001"],["63907.50","2.340"],["63909.50","0.034"],["63911.50","0.002"],["63913.50","0.000"],["63915.50","0.003"],["63917.50","0.000"],["63919.50","0.010"],["63921.50","0.008"],["63923.50","0.538"],["63925.50","0.000"],["63927.50","2.342"],["63929.50","0.051"],["63935.00","0.062"],["63937.20","0.002"],["63966.60","0.568"],["63967.20","0.061"],["63980.60","3.897"],["63996.90","0.000"],["64001.80","0.217"],["64002.00","0.061"],["64002.50","0.439"],["64013.00","0.003"],["64020.10","0.315"],["64023.00","0.091"],["64028.10","0.001"],["64029.50","0.002"],["64031.90","0.017"],["64037.00","10.471"],["64041.20","0.314"],["64041.50","0.035"],["64042.70","0.122"],["64046.70","0.551"],["64046.90","0.193"],["64047.20","0.001"],["64047.90","0.345"],["64048.70","0.000"],["64048.80","0.005"],["64049.20","0.001"],["64049.50","0.002"],["64049.60","1.712"],["64050.30","0.025"],["64050.90","0.005"],["64051.00","0.736"],["64051.40","0.000"],["64051.70","0.114"],["64051.80","2.344"],["64051.90","0.094"],["64052.00","0.002"],["64052.10","0.190"],["64052.80","0.236"],["64053.20","0.002"],["64053.60","1.203"],["64053.80","0.044"],["64054.80","0.003"],["64054.90","0.000"],["64055.50","0.893"],["64055.60","0.568"],["64055.70","0.001"],["64055.80","0.003"],["64056.00","0.007"],["64056.80","0.001"],["64059.50","5.071"]],"e":"depthUpdate","ps":"BTCUSDT","pu":11165395596411,"s":"BTCUSDT","st":1,"u":11165395608446}
{"E":1785353526572,"T":1785353526570,"U":11165395608613,"a":[["64059.60","6.721"],["64060.10","0.266"],["64060.50","0.000"],["64060.70","0.027"],["64062.00","0.005"],["64062.90","0.484"],["64063.50","0.049"],["64064.00","0.222"],["64064.90","0.000"],["64065.50","0.013"],["64066.20","0.933"],["64066.40","0.002"],["64066.50","0.002"],["64066.60","0.011"],["64067.10","0.018"],["64068.40","2.349"],["64080.30","0.003"],["64081.70","0.637"],["64082.30","0.038"],["64082.70","4.101"],["64083.60","0.000"],["64084.30","0.001"],["64084.80","0.003"],["64086.80","0.014"],["64088.10","2.004"],["64090.70","0.015"],["64092.10","0.402"],["64097.10","0.503"],["64110.80","0.001"],["64111.00","0.105"],["64155.10","0.000"],["64155.70","0.006"],["64179.60","0.000"],["64181.60","0.000"],["64183.60","0.000"],["64185.60","0.031"],["64187.60","0.003"],["64189.60","0.001"],["64191.60","0.000"],["64193.60","0.003"],["64195.60","0.000"],["64197.60","0.822"],["64199.60","0.000"],["64201.60","0.001"],["64203.60","0.000"],["64205.60","0.155"],["64207.60","0.020"],["64209.60","0.000"],["64211.60","0.000"],["64213.60","0.001"],["64264.60","0.351"],["64522.00","0.000"],["64700.20","0.008"],["65052.50","1.079"],["65344.40","0.000"]],"b":[["1000.00","37.992"],["13559.50","0.910"],["13659.50","1.400"],["13757.20","0.000"],["13758.70","0.000"],["13759.40","0.000"],["13759.50","0.000"],["13859.50","1.190"],["13959.50","0.700"],["51248.00","0.000"],["57653.50","0.052"],["61497.10","0.003"],["63149.80","0.276"],["63418.90","0.000"],["63936.50","0.027"],["63949.80","0.000"],["63955.40","0.002"],["63955.50","0.471"],["63963.40","0.077"],["63966.90","0.499"],["63967.10","0.060"],["63976.10","0.167"],["63978.30","21.634"],["63980.60","0.970"],["63985.20","3.237"],["63991.00","0.002"],["63995.40","0.017"],["64002.10","0.187"],["64002.30","0.060"],["64010.30","0.606"],["64023.70","2.259"],["64026.90","0.021"],["64027.20","0.009"],["64030.40","0.317"],["64031.80","2.026"],["64033.60","0.025"],["64034.40","0.295"],["64037.00","0.473"],["64037.60","0.021"],["64038.10","1.475"],["64040.00","0.425"],["64040.80","0.010"],["64041.00","0.004"],["64044.30","0.055"],["64044.80","1.003"],["64045.00","0.003"],["64047.90","0.517"],["64048.20","0.068"],["64050.00","0.008"],["64050.30","0.002"],["64051.70","0.094"],["64051.90","0.094"],["64052.00","0.002"],["64052.10","0.190"],["64052.50","0.000"],["64053.00","0.015"],["64053.30","0.023"],["64054.30","0.078"],["64054.40","0.098"],["64054.80","0.003"],["64054.90","0.020"],["64055.70","0.001"],["64059.50","3.951"]],"e":"depthUpdate","ps":"BTCUSDT","pu":11165395608446,"s":"BTCUSDT","st":1,"u":11165395617895}
{"E":1785353526674,"T":1785353526673,"U":11165395618029,"a":[["64059.60","4.651"],["64059.80","0.001"],["64060.10","0.172"],["64060.30","0.001"],["64060.50","0.022"],["64061.40","0.001"],["64061.50","0.001"],["64061.60","0.094"],["64062.20","0.004"],["64064.00","0.162"],["64065.00","2.893"],["64066.00","0.005"],["64066.40","0.001"],["64067.10","0.019"],["64068.20","0.004"],["64070.90","0.001"],["64071.90","0.289"],["64073.60","1.021"],["64073.90","0.003"],["64075.20","0.327"],["64086.80","0.018"],["64088.10","0.004"],["64088.50","0.001"],["64091.80","1.872"],["64091.90","10.523"],["64092.10","0.404"],["64099.00","0.083"],["64111.00","0.105"],["64130.10","0.078"],["64150.80","4.770"],["64204.10","0.004"],["64210.30","0.004"],["64572.10","1.236"],["64700.20","0.010"]],"b":[["13559.50","0.896"],["13659.50","1.288"],["13859.50","1.316"],["13959.50","0.700"],["57653.50","0.052"],["61497.10","0.000"],["63418.90","0.004"],["63966.50","0.371"],["63967.00","0.027"],["63967.10","0.000"],["63967.20","0.001"],["64001.10","1.470"],["64004.20","0.000"],["64011.90","0.019"],["64027.20","0.002"],["64028.20","0.004"],["64028.30","0.120"],["64028.40","0.013"],["64030.10","0.566"],["64031.00","0.008"],["64031.80","0.026"],["64033.60","0.337"],["64034.80","0.008"],["64037.00","0.316"],["64037.30","10.282"],["64037.40","0.000"],["64038.10","1.525"],["64038.60","0.007"],["64042.00","0.159"],["64043.90","0.313"],["64044.10","0.014"],["64044.20","0.097"],["64044.80","1.003"],["64045.50","0.885"],["64046.90","0.030"],["64047.60","0.001"],["64048.00","0.103"],["64049.60","0.385"],["64051.00","0.523"],["64051.20","0.008"],["64053.60","1.204"],["64053.80","1.371"],["64053.90","0.729"],["64054.30","0.078"],["64054.40","0.098"],["64054.70","0.094"],["64055.60","0.003"],["64055.70","0.001"],["64055.80","0.000"],["64055.90","0.096"],["64056.00","0.004"],["64056.10","0.001"],["64056.90","0.005"],["64057.00","0.004"],["64057.70","0.001"],["64059.50","5.702"]],"e":"depthUpdate","ps":"BTCUSDT","pu":11165395617895,"s":"BTCUSDT","st":1,"u":11165395628380}
{"E":1785353526776,"T":1785353526774,"U":11165395628429,"a":[["64059.60","6.288"],["64060.10","0.380"],["64060.40","0.117"],["64060.50","0.000"],["64060.70","0.005"],["64061.90","0.002"],["64062.90","0.484"],["64063.90","0.040"],["64064.00","1.411"],["64064.70","0.008"],["64064.90","0.114"],["64066.60","0.001"],["64069.00","0.000"],["64071.60","0.542"],["64072.20","0.326"],["64072.80","0.154"],["64073.30","0.021"],["64078.80","3.509"],["64085.60","2.610"],["64091.90","0.525"],["64092.10","0.402"],["64111.00","0.105"],["64700.20","0.008"],["65340.70","2.821"]],"b":[["1000.00","37.992"],["13559.50","0.910"],["13659.50","1.162"],["13759.50","0.028"],["13859.50","1.372"],["13959.50","0.728"],["57653.50","0.052"],["61497.10","0.003"],["62778.90","0.054"],["62983.30","0.728"],["63195.60","0.002"],["63258.80","1.786"],["63275.70","0.789"],["63418.90","0.000"],["63739.20","0.011"],["63976.10","21.801"],["63978.30","0.000"],["64021.20","0.002"],["64023.90","0.283"],["64033.30","0.198"],["64033.40","0.112"],["64037.00","0.314"],["64037.20","0.007"],["64037.30","0.284"],["64043.00","0.904"],["64046.10","0.159"],["64046.70","0.004"],["64046.90","0.030"],["64047.30","0.076"],["64047.40","0.022"],["64047.70","0.551"],["64049.00","0.002"],["64049.70","0.003"],["64049.80","1.348"],["64051.20","0.007"],["64051.50","0.001"],["64051.80","2.367"],["64051.90","0.000"],["64053.10","0.004"],["64053.20","0.096"],["64053.30","0.001"],["64053.60","1.013"],["64053.70","0.000"],["64053.80","0.003"],["64053.90","0.771"],["64054.00","0.004"],["64054.10","0.000"],["64054.40","0.004"],["64055.80","0.003"],["64055.90","0.002"],["64056.10","0.004"],["64056.40","0.008"],["64056.90","0.002"],["64057.00","0.001"],["64058.00","0.040"],["64059.50","4.167"]],"e":"depthUpdate","ps":"BTCUSDT","pu":11165395628380,"s":"BTCUSDT","st":1,"u":11165395636081}
{"E":1785353526878,"T":1785353526877,"U":11165395636154,"a":[["64059.60","12.557"],["64059.70","0.183"],["64060.10","0.539"],["64060.20","0.077"],["64061.40","0.006"],["64061.50","0.314"],["64061.80","0.006"],["64062.20","0.329"],["64063.60","0.883"],["64063.90","0.915"],["64064.00","1.411"],["64064.10","1.214"],["64064.20","0.002"],["64064.70","0.002"],["64064.90","0.114"],["64065.10","0.001"],["64066.20","0.933"],["64067.10","0.018"],["64069.20","0.097"],["64069.80","0.164"],["64070.40","2.915"],["64070.60","0.037"],["64071.20","2.101"],["64071.60","0.542"],["64071.90","0.286"],["64073.60","0.709"],["64074.10","5.167"],["64075.60","0.542"],["64075.90","0.001"],["64078.60","0.161"],["64079.20","0.014"],["64079.80","0.002"],["64082.00","0.083"],["64082.10","0.053"],["64085.60","0.612"],["64086.00","0.001"],["64086.50","0.002"],["64089.30","0.002"],["64108.30","0.000"],["64111.00","0.261"],["64119.50","0.210"],["64126.70","0.000"],["64130.10","0.000"],["64183.60","0.882"],["64185.60","0.913"],["64187.60","0.885"],["64189.60","0.883"],["64191.60","0.882"],["64193.60","0.885"],["64195.60","0.882"],["64197.60","1.704"],["64199.60","0.882"],["64201.60","0.883"],["64203.60","0.882"],["64205.60","1.037"],["64207.60","0.902"],["64209.60","0.882"],["64236.40","0.044"],["64262.00","0.012"],["64264.60","0.117"],["64290.50","0.000"],["64295.10","0.000"],["64311.00","0.000"],["64313.00","0.411"],["64700.20","0.008"],["64884.40","0.001"],["65200.00","47.031"],["65650.00","6.415"]],"b":[["1000.00","37.992"],["13559.50","0.896"],["13659.50","1.050"],["13759.50","0.154"],["13859.50","1.246"],["13959.50","0.854"],["57653.50","0.052"],["60856.50","0.010"],["61497.10","0.000"],["63418.90","0.000"],["63851.30","0.117"],["63976.10","21.801"],["63978.30","0.000"],["63994.00","0.211"],["64001.10","1.260"],["64001.80","0.100"],["64008.30","0.042"],["64015.00","2.531"],["64021.20","0.000"],["64021.70","0.134"],["64023.10","2.342"],["64025.20","1.095"],["64026.90","0.001"],["64028.30","0.000"],["64029.20","4.763"],["64029.70","0.002"],["64030.10","0.004"],["64031.00","0.320"],["64031.80","0.046"],["64032.80","0.009"],["64033.60","0.005"],["64035.80","0.349"],["64037.20","0.005"],["64037.60","0.001"],["64039.00","0.122"],["64040.50","0.000"],["64040.70","0.110"],["64041.70","4.705"],["64041.80","2.531"],["64042.50","0.140"],["64043.90","0.001"],["64044.30","0.035"],["64044.80","0.983"],["64044.90","0.703"],["64045.00","0.010"],["64045.50","0.886"],["64046.00","0.002"],["64046.10","0.003"],["64046.50","0.024"],["64046.90","0.010"],["64047.00","0.017"],["64047.20","0.194"],["64047.30","0.076"],["64047.40","0.015"],["64047.70","0.004"],["64048.20","0.048"],["64048.30","0.193"],["64048.80","0.002"],["64049.00","0.001"],["64049.50","0.000"],["64049.60","0.407"],["64049.80","0.001"],["64049.90","1.010"],["64050.40","0.000"],["64050.50","0.096"],["64050.80","0.001"],["64051.30","0.248"],["64051.70","0.001"],["64051.80","0.004"],["64051.90","0.094"],["64052.00","0.002"],["64052.10","0.000"],["64052.20","0.005"],["64052.30","1.375"],["64052.80","0.002"],["64053.00","0.000"],["64053.10","0.030"],["64053.20","0.002"],["64053.30","0.013"],["64053.60","0.013"],["64054.00","0.004"],["64054.10","0.000"],["64054.90","0.000"],["64055.00","0.002"],["64055.50","0.884"],["64055.80","0.000"],["64056.10","0.001"],["64056.40","0.000"],["64057.50","0.000"],["64057.60","0.226"],["64057.70","0.000"],["64059.50","1.989"]],"e":"depthUpdate","ps":"BTCUSDT","pu":11165395636081,"s":"BTCUSDT","st":1,"u":11165395644374}
{"E":1785353526980,"T":1785353526978,"U":11165395644475,"a":[["64059.60","13.938"],["64059.70","0.206"],["64060.10","0.778"],["64060.40","0.095"],["64061.10","0.006"],["64061.30","0.007"],["64061.40","0.001"],["64061.80","0.001"],["64061.90","0.002"],["64062.70","0.004"],["64063.20","0.015"],["64063.80","0.001"],["64063.90","0.094"],["64064.00","1.255"],["64064.10","0.827"],["64064.90","0.546"],["64065.00","3.282"],["64066.10","0.126"],["64066.20","0.387"],["64066.30","0.000"],["64067.00","0.174"],["64068.30","0.730"],["64069.10","0.003"],["64069.20","0.096"],["64069.50","0.001"],["64070.10","0.387"],["64070.30","0.021"],["64070.60","0.564"],["64070.90","0.118"],["64071.60","0.464"],["64071.70","0.825"],["64071.90","0.169"],["64074.10","3.401"],["64080.10","2.037"],["64086.60","0.305"],["64087.30","0.377"],["64087.90","0.000"],["64092.30","0.017"],["64096.10","0.162"],["64096.40","0.081"],["64096.90","0.005"],["64097.20","5.956"],["64108.30","0.037"],["64189.60","0.883"],["64191.60","0.000"],["64193.60","0.003"],["64195.60","0.000"],["64197.60","0.822"],["64199.60","0.000"],["64201.60","0.001"],["64203.60","0.000"],["64205.60","0.155"],["64207.60","0.020"],["64209.60","0.000"],["64508.00","0.302"],["64595.80","0.001"],["64700.20","0.008"],["64978.20","0.015"],["65200.00","47.061"],["65337.90","2.011"],["65613.00","0.404"]],"b":[["13559.50","0.910"],["13659.50","0.924"],["13759.50","0.266"],["13859.50","1.134"],["13959.50","0.966"],["51248.00","0.000"],["57653.50","0.052"],["60856.50","0.004"],["62776.50","0.000"],["63295.00","0.146"],["63302.80","0.583"],["63418.90","0.000"],["63492.00","0.000"],["63532.00","0.000"],["63539.80","0.044"],["63884.80","1.384"],["63901.50","3.523"],["63901.60","0.518"],["63903.50","0.883"],["63905.50","0.883"],["63907.50","3.222"],["63909.50","0.916"],["63911.50","0.884"],["63913.50","0.882"],["63915.50","0.885"],["63917.50","0.882"],["63919.50","0.892"],["63921.50","0.890"],["63923.50","1.420"],["63963.10","0.001"],["63976.10","0.167"],["63978.30","0.000"],["63982.70","21.059"],["64001.80","0.217"],["64002.50","0.442"],["64005.10","0.156"],["64005.20","0.000"],["64005.70","0.008"],["64005.80","0.003"],["64007.30","1.037"],["64013.00","0.000"],["64017.30","0.987"],["64017.50","0.066"],["64020.70","0.000"],["64022.00","0.008"],["64022.30","0.242"],["64023.80","0.001"],["64027.40","0.084"],["64027.70","0.564"],["64027.80","0.001"],["64029.20","4.201"],["64030.10","0.011"],["64030.30","0.022"],["64030.50","0.937"],["64031.00","0.313"],["64031.40","0.132"],["64031.50","0.042"],["64031.90","0.001"],["64033.00","0.604"],["64034.30","0.001"],["64034.60","0.049"],["64035.30","2.349"],["64038.10","1.475"],["64038.40","0.708"],["64040.80","0.201"],["64041.30","0.321"],["64041.80","2.482"],["64042.90","0.007"],["64044.90","0.000"],["64045.00","0.003"],["64045.40","0.098"],["64045.50","0.889"],["64045.60","0.065"],["64046.70","0.004"],["64046.90","0.003"],["64047.20","0.001"],["64047.50","0.864"],["64047.90","0.853"],["64048.70","0.234"],["64049.20","0.025"],["64049.60","0.385"],["64050.00","0.048"],["64050.10","2.216"],["64050.20","0.066"],["64050.50","0.096"],["64051.00","1.075"],["64051.50","0.796"],["64051.60","0.719"],["64051.70","0.003"],["64051.90","0.000"],["64052.30","0.048"],["64053.80","0.000"],["64053.90","0.001"],["64054.00","0.289"],["64055.50","0.000"],["64057.60","0.002"],["64059.50","1.991"]],"e":"depthUpdate","ps":"BTCUSDT","pu":11165395644374,"s":"BTCUSDT","st":1,"u":11165395657750}
{"E":1785353527082,"T":1785353527081,"U":11165395657856,"a":[["64059.60","6.914"],["64059.70","0.181"],["64060.10","0.539"],["64061.10","0.001"],["64061.30","0.002"],["64061.40","0.001"],["64061.50","0.314"],["64061.60","0.096"],["64062.20","0.100"],["64062.30","0.014"],["64062.60","0.010"],["64063.60","0.001"],["64063.90","0.250"],["64064.70","0.330"],["64065.00","3.292"],["64065.50","0.000"],["64066.10","0.001"],["64067.10","0.143"],["64067.30","0.256"],["64068.30","0.574"],["64071.10","3.098"],["64071.20","0.101"],["64075.00","0.163"],["64076.90","0.081"],["64079.10","0.021"],["64080.10","2.002"],["64081.70","0.549"],["64082.30","0.022"],["64083.60","0.013"],["64086.60","0.340"],["64086.80","0.005"],["64107.60","0.115"],["64187.60","0.003"],["64189.60","0.001"],["64520.80","0.412"],["64589.70","0.002"],["64700.20","0.008"],["64962.80","0.925"]],"b":[["1000.00","37.992"],["13559.50","0.896"],["13659.50","0.812"],["13759.50","0.392"],["13859.50","1.008"],["13959.50","1.092"],["51247.60","0.000"],["57653.50","0.052"],["61497.10","0.003"],["62778.40","0.030"],["63418.90","0.000"],["63736.20","0.089"],["63739.20","0.001"],["63832.10","0.000"],["63903.50","0.001"],["63904.00","0.028"],["63905.50","0.001"],["63907.50","2.340"],["63909.50","0.034"],["63911.50","0.002"],["63913.50","0.000"],["63915.50","0.003"],["63917.50","0.000"],["63919.50","0.010"],["63976.10","21.226"],["63982.70","0.000"],["63991.70","0.529"],["63994.40","0.053"],["64003.80","0.001"],["64015.00","0.531"],["64015.80","0.756"],["64019.40","10.003"],["64023.00","0.001"],["64027.60","0.192"],["64029.20","4.203"],["64029.70","0.000"],["64033.20","0.037"],["64038.40","0.008"],["64040.70","0.016"],["64040.80","0.010"],["64041.30","0.215"],["64041.50","0.000"],["64047.20","0.192"],["64048.00","0.103"],["64048.70","0.256"],["64049.20","0.002"],["64051.80","0.122"],["64052.30","0.048"],["64053.40","0.095"],["64053.60","0.014"],["64053.80","0.000"],["64054.00","0.288"],["64054.10","0.001"],["64055.50","0.882"],["64055.60","0.002"],["64056.30","0.001"],["64059.50","3.312"]],"e":"depthUpdate","ps":"BTCUSDT","pu":11165395657750,"s":"BTCUSDT","st":1,"u":11165395667239}
{"E":1785353527184,"T":1785353527183,"U":11165395667261,"a":[["64059.60","15.271"],["64060.00","0.003"],["64060.30","0.095"],["64060.40","0.001"],["64061.40","0.006"],["64061.60","0.097"],["64061.80","0.006"],["64061.90","0.002"],["64062.20","0.329"],["64062.30","0.001"],["64062.70","0.003"],["64063.70","0.006"],["64063.80","0.041"],["64063.90","0.094"],["64064.60","0.013"],["64064.70","0.429"],["64064.90","0.546"],["64065.00","3.362"],["64065.10","0.001"],["64066.00","0.083"],["64067.00","0.158"],["64067.10","0.143"],["64067.20","2.640"],["64068.30","0.710"],["64068.40","2.347"],["64069.20","10.098"],["64069.60","0.459"],["64069.80","0.065"],["64070.30","0.001"],["64072.80","0.074"],["64075.70","0.041"],["64076.40","0.376"],["64076.70","0.003"],["64076.90","0.080"],["64079.10","0.005"],["64080.90","0.003"],["64081.20","2.348"],["64081.40","0.110"],["64082.30","0.142"],["64083.60","0.000"],["64083.80","0.054"],["64085.90","0.015"],["64086.60","0.332"],["64087.00","0.003"],["64087.30","0.385"],["64088.40","0.032"],["64091.30","0.085"],["64091.80","1.752"],["64092.30","0.001"],["64092.70","0.048"],["64101.30","0.004"],["64105.80","0.656"],["64107.60","0.037"],["64108.30","0.000"],["64111.80","0.383"],["64119.50","0.000"],["64183.60","0.000"],["64189.60","0.883"],["64191.60","0.882"],["64193.60","0.885"],["64195.60","0.882"],["64197.60","1.704"],["64199.60","0.882"],["64201.60","0.883"],["64203.60","0.882"],["64205.20","0.012"],["64205.60","1.037"],["64207.60","0.902"],["64209.60","0.882"],["64210.30","0.000"],["64211.60","0.785"],["64267.80","0.007"],["64508.00","0.398"],["64520.80","0.316"],["64547.30","0.020"],["64700.20","0.013"],["64775.50","0.002"],["64828.30","2.777"],["64924.40","0.952"],["65337.90","2.008"],["65498.60","0.861"],["65981.20","0.005"]],"b":[["1000.00","37.992"],["13559.50","0.910"],["13659.50","0.686"],["13759.50","0.504"],["13859.50","0.896"],["13959.50","1.204"],["57653.50","0.052"],["61497.10","0.000"],["63157.60","0.000"],["63239.90","0.000"],["63418.90","0.000"],["63547.00","0.318"],["63586.30","0.020"],["63921.50","0.008"],["63923.50","0.538"],["63976.10","0.167"],["63978.30","21.059"],["63993.00","0.000"],["64006.10","0.014"],["64013.70","10.000"],["64017.70","0.000"],["64018.40","0.001"],["64019.40","0.005"],["64020.00","0.015"],["64023.10","2.342"],["64023.20","0.007"],["64023.30","0.324"],["64026.40","0.000"],["64027.60","0.191"],["64027.70","0.002"],["64029.40","0.562"],["64030.50","0.002"],["64030.70","0.004"],["64032.20","3.342"],["64033.20","0.002"],["64033.40","0.032"],["64033.50","0.714"],["64038.30","0.094"],["64039.50","0.095"],["64040.40","0.002"],["64040.70","0.110"],["64041.80","2.482"],["64041.90","0.004"],["64042.80","0.734"],["64043.40","0.005"],["64044.80","0.121"],["64045.40","0.096"],["64047.30","0.078"],["64047.50","0.000"],["64047.80","0.095"],["64047.90","0.467"],["64048.00","0.009"],["64048.10","0.095"],["64048.20","0.048"],["64048.70","0.022"],["64048.90","0.001"],["64049.00","0.001"],["64049.10","0.096"],["64049.20","0.002"],["64049.30","0.062"],["64049.40","0.000"],["64049.60","0.002"],["64049.70","0.003"],["64050.00","0.008"],["64050.40","0.000"],["64050.50","0.002"],["64050.60","0.001"],["64050.80","0.001"],["64051.70","0.023"],["64051.80","0.028"],["64053.40","0.001"],["64054.00","0.413"],["64054.60","0.002"],["64054.90","0.000"],["64055.30","0.003"],["64056.70","0.001"],["64056.90","0.001"],["64057.40","0.002"],["64058.00","0.001"],["64059.50","1.991"]],"e":"depthUpdate","ps":"BTCUSDT","pu":11165395667239,"s":"BTCUSDT","st":1,"u":11165395688318}
{"E":1785353527286,"T":1785353527284,"U":11165395688563,"a":[["64059.60","13.861"],["64060.20","0.077"],["64061.10","0.006"],["64061.20","0.000"],["64061.60","0.096"],["64061.80","0.001"],["64063.00","0.001"],["64063.80","0.587"],["64063.90","0.250"],["64064.10","1.134"],["64065.40","0.003"],["64067.90","0.016"],["64068.30","0.008"],["64068.70","0.125"],["64069.20","10.020"],["64070.90","0.001"],["64073.60","0.709"],["64074.20","0.363"],["64080.10","2.004"],["64081.60","0.525"],["64082.10","0.003"],["64082.30","0.022"],["64086.80","0.013"],["64087.30","0.377"],["64089.60","1.199"],["64093.10","1.617"],["64094.90","0.454"],["64095.00","0.000"],["64095.10","0.101"],["64098.40","0.976"],["64105.80","0.656"],["64111.80","0.173"],["64114.70","0.016"],["64118.40","1.846"],["64121.80","6.397"],["64124.40","0.001"],["64185.60","0.031"],["64187.60","0.840"],["64189.60","0.001"],["64191.60","0.000"],["64193.60","0.003"],["64195.60","0.000"],["64197.60","0.822"],["64199.60","0.000"],["64201.60","0.001"],["64203.60","0.000"],["64205.60","0.155"],["64207.60","0.020"],["64209.60","0.000"],["64211.60","0.000"],["64267.80","0.124"],["64268.60","0.004"],["64268.70","0.000"],["64268.80","0.242"],["64345.70","0.100"],["64345.80","0.118"],["64376.70","0.299"],["64379.90","3.832"],["64520.80","0.000"],["64700.20","0.009"],["64860.30","0.606"],["65340.70","2.824"]],"b":[["13559.50","0.896"],["13659.50","0.574"],["13759.50","0.630"],["13859.50","0.770"],["13959.50","1.330"],["51248.00","0.000"],["57653.50","0.052"],["61497.10","0.003"],["63418.90","0.000"],["63594.40","0.000"],["63611.10","0.198"],["63705.20","0.318"],["63711.70","0.456"],["63739.20","0.000"],["63899.50","0.001"],["63901.50","3.523"],["63903.50","0.001"],["63905.50","0.001"],["63907.50","2.340"],["63909.50","0.034"],["63911.50","0.002"],["63913.50","0.000"],["63915.50","0.003"],["63917.50","0.000"],["63919.50","0.892"],["63993.50","1.122"],["63999.20","0.025"],["64001.80","0.178"],["64007.80","0.001"],["64013.30","0.005"],["64023.30","0.244"],["64028.00","0.091"],["64028.70","1.176"],["64029.30","0.002"],["64031.10","0.935"],["64032.20","2.407"],["64033.00","0.604"],["64034.60","0.000"],["64037.90","0.005"],["64038.30","0.000"],["64041.40","0.002"],["64041.90","0.004"],["64042.80","0.718"],["64044.60","1.324"],["64044.80","0.271"],["64044.90","0.666"],["64045.70","1.329"],["64046.70","0.043"],["64047.30","0.076"],["64047.90","0.745"],["64048.00","0.006"],["64048.10","0.001"],["64048.40","1.010"],["64049.00","0.024"],["64049.50","0.234"],["64049.90","0.002"],["64050.10","0.882"],["64050.30","0.096"],["64051.00","0.523"],["64051.60","0.015"],["64051.70","0.003"],["64051.80","0.004"],["64052.40","0.001"],["64053.10","0.024"],["64055.50","0.000"]],"e":"depthUpdate","ps":"BTCUSDT","pu":11165395688318,"s":"BTCUSDT","st":1,"u":11165395701789}
{"E":1785353527388,"T":1785353527384,"U":11165395701934,"a":[["64059.60","7.029"],["64060.10","0.539"],["64061.10","0.001"],["64061.40","0.006"],["64061.50","0.314"],["64061.90","0.002"],["64063.00","0.000"],["64063.70","0.100"],["64063.90","0.156"],["64065.00","3.282"],["64065.10","0.002"],["64065.20","0.012"],["64065.40","0.001"],["64066.00","0.005"],["64067.10","0.141"],["64067.20","1.274"],["64068.40","2.349"],["64068.70","0.008"],["64069.00","0.080"],["64069.20","0.018"],["64069.60","0.576"],["64073.30","0.021"],["64074.20","0.313"],["64075.10","0.003"],["64078.60","10.161"],["64081.00","0.106"],["64081.20","2.350"],["64081.60","0.523"],["64081.90","0.053"],["64083.80","0.005"],["64087.40","0.005"],["64090.30","0.049"],["64090.70","0.011"],["64091.30","0.015"],["64098.20","0.005"],["64099.00","2.029"],["64099.10","0.095"],["64099.60","1.116"],["64105.80","0.681"],["64107.60","0.115"],["64110.60","2.008"],["64118.40","1.636"],["64119.70","0.000"],["64120.50","0.078"],["64124.90","0.210"],["64130.10","0.078"],["64187.60","0.003"],["64247.40","1.944"],["64247.50","0.000"],["64266.00","2.461"],["64266.10","0.000"],["64379.90","3.833"],["64520.80","0.316"],["64700.20","0.009"],["64828.30","4.318"],["64833.10","0.006"],["64936.00","0.176"],["65327.60","0.009"]],"b":[["1000.00","37.992"],["13559.50","0.952"],["13659.50","0.448"],["13759.50","0.742"],["13859.50","0.700"],["13959.50","1.358"],["57653.50","0.052"],["60853.90","0.001"],["60854.00","0.003"],["61497.10","0.000"],["62646.40","0.002"],["62710.30","0.000"],["63418.90","0.000"],["63662.30","0.209"],["63669.50","0.579"],["63739.20","0.000"],["63914.10","2.194"],["63919.50","0.010"],["63951.00","0.007"],["63951.10","0.000"],["63990.30","0.142"],["63999.20","0.000"],["64005.60","0.102"],["64008.30","0.067"],["64013.40","2.852"],["64013.70","0.002"],["64019.10","2.140"],["64027.10","0.060"],["64028.00","0.042"],["64035.80","0.398"],["64039.50","0.001"],["64040.70","0.016"],["64043.10","1.310"],["64044.90","0.099"],["64045.00","0.885"],["64046.60","1.369"],["64046.70","0.043"],["64046.90","0.003"],["64048.30","0.191"],["64048.50","3.224"],["64048.60","0.631"],["64049.50","0.000"],["64049.90","0.002"],["64050.20","0.004"],["64050.30","0.096"],["64050.70","0.314"],["64050.80","0.235"],["64051.00","0.865"],["64051.50","0.890"],["64052.70","0.001"],["64053.20","0.096"],["64053.60","0.014"],["64057.30","0.436"],["64059.00","0.000"],["64059.20","0.003"],["64059.30","0.002"],["64059.50","3.456"]],"e":"depthUpdate","ps":"BTCUSDT","pu":11165395701789,"s":"BTCUSDT","st":1,"u":11165395716501}
{"E":1785353527490,"T":1785353527488,"U":11165395716800,"a":[["64059.60","7.026"],["64061.40","0.001"],["64061.80","0.006"],["64063.70","0.006"],["64064.90","0.640"],["64067.10","0.016"],["64069.20","0.096"],["64069.50","0.126"],["64090.80","0.006"],["64108.30","0.012"],["64120.50","0.000"],["64130.10","0.000"],["64187.60","0.786"],["64189.60","0.001"],["64191.60","0.000"],["64193.60","0.003"],["64195.60","0.000"],["64197.60","0.822"],["64199.60","0.000"],["64201.60","0.001"],["64203.60","0.000"],["64205.60","0.155"],["64207.60","0.020"],["64209.60","0.000"],["64211.60","0.000"],["64213.60","0.001"],["64379.90","3.832"],["64700.20","0.009"],["64830.30","18.709"]],"b":[["1000.00","37.992"],["13559.50","1.064"],["13659.50","0.336"],["13759.50","0.868"],["13859.50","0.700"],["13959.50","1.232"],["57653.50","0.052"],["63019.40","0.792"],["63050.10","3.878"],["63290.80","3.470"],["63306.30","0.001"],["63418.90","0.000"],["63662.30","0.003"],["63736.20","0.088"],["63942.40","0.390"],["63976.10","21.226"],["63978.30","0.000"],["63982.70","0.000"],["63983.60","5.434"],["63994.00","0.001"],["64001.80","0.388"],["64025.30","10.080"],["64025.60","2.814"],["64027.40","0.014"],["64030.30","0.002"],["64034.50","0.189"],["64037.80","0.396"],["64044.80","0.115"],["64048.70","0.178"],["64049.20","0.088"],["64056.30","0.002"],["64057.40","0.088"],["64059.50","3.456"]],"e":"depthUpdate","ps":"BTCUSDT","pu":11165395716501,"s":"BTCUSDT","st":1,"u":11165395724984}
{"E":1785353527592,"T":1785353527590,"U":11165395725131,"a":[["64059.60","3.653"],["64060.10","0.227"],["64060.20","0.054"],["64060.30","0.001"],["64060.70","0.005"],["64061.50","0.001"],["64061.60","0.000"],["64061.70","0.095"],["64061.80","0.001"],["64062.00","0.005"],["64062.20","0.001"],["64062.80","0.015"],["64062.90","0.096"],["64063.20","0.018"],["64063.30","0.003"],["64063.70","0.007"],["64063.80","0.001"],["64063.90","0.004"],["64064.00","0.006"],["64064.10","0.512"],["64064.20","0.001"],["64064.30","0.063"],["64064.40","0.153"],["64064.70","0.002"],["64064.90","0.000"],["64065.00","0.007"],["64065.10","0.001"],["64065.20","0.002"],["64065.80","0.009"],["64066.10","0.936"],["64067.00","0.900"],["64067.10","0.562"],["64067.20","1.284"],["64067.30","0.157"],["64067.90","0.000"],["64068.30","0.008"],["64069.00","0.000"],["64069.60","0.459"],["64069.80","0.264"],["64070.10","0.384"],["64070.30","0.002"],["64070.40","2.603"],["64070.70","0.253"],["64070.90","0.095"],["64071.00","3.592"],["64071.70","0.825"],["64072.80","0.154"],["64073.50","0.315"],["64078.60","0.163"],["64080.00","1.828"],["64085.00","0.532"],["64085.20","0.043"],["64086.80","0.005"],["64087.20","1.292"],["64087.50","1.109"],["64088.00","0.003"],["64088.40","0.040"],["64089.60","1.079"],["64090.20","0.177"],["64091.90","10.525"],["64093.10","1.601"],["64093.40","0.001"],["64096.10","0.158"],["64096.20","0.123"],["64096.30","0.004"],["64096.90","0.001"],["64097.20","5.960"],["64099.80","0.001"],["64106.20","0.002"],["64107.60","0.037"],["64108.30","0.012"],["64110.60","1.983"],["64114.50","0.000"],["64114.70","0.001"],["64120.10","0.026"],["64124.10","0.015"],["64130.10","0.000"],["64189.60","0.883"],["64191.60","0.000"],["64193.60","0.003"],["64195.60","0.000"],["64197.60","0.822"],["64199.60","0.000"],["64201.60","0.001"],["64203.60","0.000"],["64205.60","0.155"],["64207.60","0.020"],["64209.60","0.000"],["64211.60","0.000"],["64213.60","0.001"],["64214.70","0.405"],["64215.60","0.000"],["64217.60","0.024"],["64264.60","0.117"],["64315.80","0.214"],["64632.30","0.032"],["64635.90","0.000"],["64700.20","0.009"],["64828.30","5.859"],["64901.30","0.404"],["64905.00","0.560"],["64956.40","0.169"],["64974.30","0.002"],["65340.70","2.830"]],"b":[["13559.50","1.190"],["13659.50","0.210"],["13759.50","0.980"],["13859.50","0.700"],["13959.50","1.120"],["57653.50","0.052"],["61497.10","0.003"],["62343.20","0.401"],["62834.50","0.321"],["63018.10","0.012"],["63093.40","0.486"],["63114.20","11.624"],["63258.80","2.053"],["63418.90","0.000"],["63675.10","1.190"],["63739.20","0.001"],["63888.00","3.797"],["63945.90","2.434"],["63953.50","0.006"],["63979.80","0.320"],["63983.60","2.714"],["63986.80","0.527"],["63990.30","0.001"],["63990.90","0.000"],["63992.00","2.002"],["64002.10","0.121"],["64005.70","0.004"],["64005.80","0.007"],["64007.30","0.060"],["64008.30","0.067"],["64015.80","0.666"],["64017.30","0.984"],["64017.50","0.069"],["64019.10","0.140"],["64021.00","0.032"],["64021.70","0.014"],["64022.00","0.004"],["64022.20","0.014"],["64022.90","0.117"],["64023.70","4.213"],["64025.30","0.082"],["64025.60","1.864"],["64026.00","0.081"],["64028.80","1.374"],["64029.00","1.252"],["64029.20","4.203"],["64031.10","0.000"],["64031.40","0.082"],["64032.00","1.867"],["64032.80","0.008"],["64033.50","1.614"],["64033.60","0.005"],["64033.80","0.001"],["64033.90","0.081"],["64035.80","0.349"],["64036.30","1.251"],["64038.30","2.000"],["64038.50","0.054"],["64040.70","0.016"],["64041.80","2.388"],["64041.90","0.660"],["64042.70","0.157"],["64043.00","0.826"],["64043.20","0.051"],["64044.60","1.322"],["64044.80","0.101"],["64044.90","0.000"],["64045.00","0.003"],["64045.70","0.002"],["64046.60","1.579"],["64046.70","0.004"],["64048.30","0.001"],["64048.40","0.002"],["64048.60","0.022"],["64048.70","0.156"],["64048.80","0.064"],["64049.00","0.001"],["64049.10","0.096"],["64049.20","0.064"],["64049.30","0.062"],["64049.60","0.385"],["64049.80","0.001"],["64049.90","0.002"],["64050.20","0.098"],["64050.80","0.001"],["64051.00","0.867"],["64051.10","2.341"],["64051.20","0.007"],["64051.30","0.233"],["64051.60","1.336"],["64051.70","0.581"],["64051.80","0.133"],["64052.10","0.313"],["64052.40","0.191"],["64052.70","0.001"],["64053.30","0.001"],["64053.40","0.004"],["64054.00","0.577"],["64054.40","1.246"],["64054.50","0.106"],["64054.60","0.005"],["64055.50","0.890"],["64055.80","0.000"],["64056.20","0.001"],["64057.40","0.010"],["64057.50","0.882"],["64057.60","0.613"],["64059.50","4.971"]],"e":"depthUpdate","ps":"BTCUSDT","pu":11165395724984,"s":"BTCUSDT","st":1,"u":11165395742561}
{"E":1785353527694,"T":1785353527693,"U":11165395742669,"a":[["64059.60","11.528"],["64059.70","0.183"],["64060.00","0.006"],["64060.10","0.497"],["64060.30","0.024"],["64060.50","0.094"],["64060.80","0.026"],["64061.30","0.315"],["64061.80","0.006"],["64062.00","0.005"],["64062.80","2.360"],["64062.90","0.479"],["64063.50","0.751"],["64063.60","0.883"],["64063.90","0.002"],["64064.00","1.255"],["64064.10","1.149"],["64064.30","0.376"],["64064.70","0.335"],["64065.00","0.005"],["64065.30","0.096"],["64065.40","2.889"],["64065.50","0.882"],["64065.80","0.001"],["64066.00","0.005"],["64066.90","0.153"],["64067.00","0.178"],["64067.10","0.016"],["64067.20","1.290"],["64067.30","0.158"],["64068.70","0.344"],["64069.10","0.003"],["64069.50","0.313"],["64069.80","0.263"],["64070.40","4.057"],["64070.70","0.136"],["64070.80","0.083"],["64071.00","3.592"],["64071.70","0.942"],["64071.80","0.609"],["64072.80","10.154"],["64073.30","0.001"],["64073.50","0.003"],["64074.10","3.421"],["64075.20","0.015"],["64075.70","0.076"],["64077.40","0.002"],["64078.10","3.591"],["64078.60","0.161"],["64080.90","0.001"],["64081.20","2.352"],["64082.70","4.099"],["64083.70","0.004"],["64086.60","0.297"],["64087.00","0.011"],["64087.60","0.195"],["64087.70","0.007"],["64088.40","0.032"],["64089.60","0.031"],["64091.70","2.342"],["64091.90","0.525"],["64092.30","0.017"],["64096.90","0.005"],["64108.30","0.000"],["64110.80","0.000"],["64185.60","0.031"],["64189.60","0.001"],["64191.60","0.000"],["64193.60","0.003"],["64214.70","0.198"],["64700.20","0.009"],["64988.50","1.614"],["65327.60","0.006"],["65650.10","0.707"]],"b":[["1000.00","37.992"],["13559.50","1.302"],["13659.50","0.098"],["13759.50","1.106"],["13859.50","0.700"],["13959.50","0.994"],["57653.50","0.052"],["60839.70","0.000"],["60860.00","0.184"],["61497.10","0.000"],["62765.70","0.006"],["62770.40","0.345"],["63157.80","0.895"],["63221.80","1.427"],["63418.90","0.000"],["63421.00","0.002"],["63739.20","0.001"],["63901.50","3.523"],["63903.50","0.001"],["63905.50","0.001"],["63907.50","2.340"],["63909.50","0.034"],["63911.50","0.002"],["63913.50","0.882"],["63915.50","0.885"],["63917.50","0.882"],["63919.50","0.892"],["63921.50","0.890"],["63990.30","0.063"],["64005.70","0.008"],["64005.80","0.003"],["64007.60","1.110"],["64014.60","1.265"],["64017.30","0.987"],["64019.30","10.613"],["64023.70","2.259"],["64029.10","0.448"],["64029.40","0.562"],["64031.00","0.001"],["64032.00","1.851"],["64032.40","0.959"],["64032.70","2.970"],["64032.80","0.009"],["64033.10","0.030"],["64033.50","0.679"],["64033.80","0.235"],["64033.90","0.042"],["64034.20","0.005"],["64036.20","0.659"],["64037.30","0.282"],["64037.80","0.376"],["64038.30","0.000"],["64039.50","0.095"],["64039.90","0.312"],["64040.60","0.236"],["64040.70","0.110"],["64041.70","4.393"],["64041.80","2.482"],["64042.20","0.252"],["64043.00","0.904"],["64043.20","0.002"],["64043.50","0.043"],["64043.80","0.217"],["64044.10","0.076"],["64044.80","0.333"],["64044.90","0.922"],["64045.10","0.001"],["64045.20","0.547"],["64045.40","0.322"],["64045.50","2.213"],["64046.60","1.283"],["64047.20","0.001"],["64047.90","0.467"],["64048.00","0.196"],["64048.50","2.342"],["64048.60","0.810"],["64048.70","0.000"],["64048.80","0.002"],["64049.10","0.000"],["64049.20","0.001"],["64049.40","0.000"],["64049.60","0.002"],["64049.70","0.003"],["64049.80","0.001"],["64050.10","0.000"],["64050.20","0.004"],["64050.30","0.002"],["64050.70","0.002"],["64050.80","1.009"],["64051.00","0.002"],["64051.10","0.003"],["64051.20","0.594"],["64051.50","0.001"],["64051.60","0.009"],["64051.70","0.006"],["64051.80","0.004"],["64052.10","0.000"],["64052.30","0.048"],["64052.40","0.001"],["64052.50","0.000"],["64052.80","0.002"],["64052.90","0.016"],["64053.20","0.002"],["64053.50","0.000"],["64053.60","0.014"],["64053.70","0.002"],["64053.80","0.000"],["64054.00","0.003"],["64054.10","0.001"],["64054.20","0.294"],["64054.40","0.004"],["64054.50","0.009"],["64054.60","0.002"],["64054.80","0.001"],["64055.50","0.008"],["64056.70","0.001"],["64057.40","0.002"],["64057.50","0.000"],["64057.60","0.002"],["64059.50","2.065"]],"e":"depthUpdate","ps":"BTCUSDT","pu":11165395742561,"s":"BTCUSDT","st":1,"u":11165395755332}
{"E":1785353527796,"T":1785353527795,"U":11165395755350,"a":[["64059.60","5.723"],["64059.70","0.181"],["64059.90","0.024"],["64060.00","2.346"],["64060.10","0.901"],["64060.80","0.003"],["64061.20","0.000"],["64061.90","0.002"],["64062.70","0.023"],["64062.90","0.481"],["64063.40","0.002"],["64063.50","0.771"],["64063.60","0.001"],["64064.20","0.002"],["64064.40","0.145"],["64064.70","0.096"],["64065.20","0.012"],["64065.30","0.642"],["64065.40","2.343"],["64065.50","0.000"],["64066.00","0.005"],["64066.90","0.028"],["64067.00","0.158"],["64067.30","0.157"],["64068.30","0.133"],["64069.20","0.096"],["64069.40","0.005"],["64070.30","0.118"],["64070.40","2.603"],["64071.70","0.825"],["64072.80","0.156"],["64073.70","1.913"],["64075.70","0.041"],["64077.00","0.003"],["64081.40","0.112"],["64081.50","0.002"],["64083.00","0.000"],["64084.20","0.833"],["64084.60","10.657"],["64096.10","0.162"],["64096.30","0.000"],["64097.20","5.956"],["64105.80","0.681"],["64117.30","0.011"],["64130.10","0.078"],["64185.60","0.031"],["64187.60","0.885"],["64189.60","0.883"],["64191.60","0.882"],["64193.60","0.885"],["64195.60","0.882"],["64197.50","0.501"],["64700.20","0.009"],["65661.10","0.079"]],"b":[["1000.00","37.992"],["13559.50","1.372"],["13659.50","0.000"],["13759.50","1.218"],["13859.50","0.700"],["13959.50","0.910"],["57653.50","0.052"],["60844.30","0.002"],["60844.40","0.082"],["61497.10","0.003"],["62458.00","0.809"],["62891.30","0.794"],["63034.50","1.291"],["63066.60","1.125"],["63130.60","3.004"],["63194.70","0.791"],["63322.80","0.945"],["63418.90","0.000"],["63662.30","0.209"],["63675.10","0.984"],["63725.00","1.058"],["63736.20","0.089"],["63828.90","0.189"],["63851.30","0.000"],["63901.50","3.523"],["63903.50","0.001"],["63905.50","0.001"],["63907.50","2.340"],["63909.50","0.034"],["63911.50","0.002"],["63913.50","0.000"],["63915.50","0.003"],["63917.50","0.000"],["63919.50","0.010"],["63921.50","0.008"],["63990.30","0.204"],["64000.60","0.063"],["64001.80","0.388"],["64003.10","0.013"],["64005.60","0.089"],["64008.30","0.184"],["64015.30","0.002"],["64017.50","0.066"],["64019.30","0.613"],["64020.50","2.000"],["64022.00","0.008"],["64022.20","0.010"],["64022.40","0.101"],["64022.90","0.027"],["64025.30","0.080"],["64025.90","2.346"],["64026.00","0.081"],["64026.70","0.072"],["64030.00","10.418"],["64034.50","0.119"],["64035.80","0.384"],["64039.50","0.001"],["64040.70","0.016"],["64040.80","0.201"],["64042.70","0.122"],["64043.50","0.004"],["64044.10","0.079"],["64044.60","1.324"],["64044.80","0.101"],["64044.90","0.882"],["64045.00","0.003"],["64045.20","0.000"],["64045.50","0.886"],["64046.70","0.004"],["64048.10","0.023"],["64048.30","0.003"],["64048.40","0.003"],["64048.60","1.818"],["64048.70","1.327"],["64048.80","0.016"],["64049.10","0.094"],["64049.20","0.013"],["64049.50","0.882"],["64049.60","0.064"],["64049.90","0.002"],["64050.30","0.096"],["64050.60","0.314"],["64050.70","0.235"],["64050.80","0.001"],["64051.00","0.000"],["64051.10","0.018"],["64051.20","1.080"],["64051.50","0.883"],["64051.60","0.029"],["64051.70","0.703"],["64051.80","0.036"],["64052.30","0.060"],["64052.40","0.095"],["64052.90","0.001"],["64053.00","0.003"],["64053.20","0.005"],["64053.50","0.882"],["64053.60","0.013"],["64053.70","0.096"],["64054.10","0.000"],["64054.20","0.631"],["64055.50","0.000"],["64059.50","3.987"]],"e":"depthUpdate","ps":"BTCUSDT","pu":11165395755332,"s":"BTCUSDT","st":1,"u":11165395764167}
{"E":1785353527898,"T":1785353527897,"U":11165395764191,"a":[["64059.60","5.724"],["64059.70","0.182"],["64059.80","0.736"],["64059.90","0.632"],["64060.40","0.002"],["64061.20","0.006"],["64062.20","0.100"],["64062.70","0.004"],["64062.80","2.362"],["64063.20","0.017"],["64063.50","0.069"],["64063.70","0.006"],["64063.90","0.548"],["64065.20","0.002"],["64065.30","0.096"],["64066.00","0.005"],["64067.10","0.002"],["64067.30","0.256"],["64069.40","0.004"],["64069.80","0.398"],["64077.00","0.070"],["64078.60","2.161"],["64079.60","0.631"],["64081.00","0.015"],["64082.40","0.375"],["64082.70","4.101"],["64083.70","0.002"],["64084.60","0.657"],["64108.30","0.012"],["64185.60","0.913"],["64191.60","0.000"],["64193.60","0.003"],["64195.60","0.000"],["64243.70","2.453"],["64243.90","0.013"],["64700.20","0.011"],["64702.20","0.002"],["65340.70","2.836"]],"b":[["13559.50","1.260"],["13759.50","1.344"],["13859.50","0.700"],["13959.50","0.896"],["57653.50","0.052"],["63282.80","0.888"],["63346.90","0.884"],["63418.90","0.000"],["63955.50","0.468"],["63955.70","0.003"],["63992.90","0.142"],["64000.60","0.129"],["64003.10","0.076"],["64020.50","0.000"],["64021.00","10.032"],["64023.40","0.557"],["64025.20","1.075"],["64026.70","0.002"],["64029.20","4.201"],["64030.00","0.420"],["64030.10","0.030"],["64031.80","0.026"],["64034.00","0.103"],["64035.20","1.401"],["64035.80","0.364"],["64040.70","0.035"],["64040.80","0.010"],["64042.50","0.120"],["64043.50","0.004"],["64044.70","2.392"],["64046.50","0.004"],["64047.20","0.192"],["64048.70","0.000"],["64048.80","0.056"],["64050.30","0.002"],["64051.30","0.252"],["64051.60","2.039"],["64051.70","0.000"],["64051.80","0.016"],["64052.40","0.001"],["64052.50","0.000"],["64052.80","0.002"],["64053.10","0.004"],["64053.60","0.014"],["64053.70","0.002"],["64054.20","0.582"],["64054.30","0.079"],["64056.30","0.001"],["64059.50","2.220"]],"e":"depthUpdate","ps":"BTCUSDT","pu":11165395764167,"s":"BTCUSDT","st":1,"u":11165395771816}
{"E":1785353528000,"T":1785353527998,"U":11165395771978,"a":[["64060.00","2.410"],["64060.30","0.025"],["64062.20","0.235"],["64077.40","0.092"],["64079.60","0.540"],["64700.20","0.009"]],"b":[["1000.00","37.992"],["13559.50","1.134"],["13659.50","0.056"],["13759.50","1.344"],["13859.50","0.756"],["13959.50","0.910"],["51247.60","0.002"],["57653.50","0.052"],["60856.50","0.012"],["61497.10","0.000"],["63418.90","0.000"],["63739.20","0.011"],["63901.50","4.350"],["63903.50","0.883"],["63905.50","0.883"],["63907.50","3.222"],["63909.50","0.916"],["63911.50","0.884"],["63913.50","0.882"],["63915.50","0.885"],["63992.90","0.175"],["63994.40","0.020"],["64002.70","2.409"],["64006.00","0.379"],["64006.70","0.088"],["64010.30","0.517"],["64052.40","0.004"],["64052.50","0.003"],["64053.00","0.000"],["64053.20","0.002"]],"e":"depthUpdate","ps":"BTCUSDT","pu":11165395771816,"s":"BTCUSDT","st":1,"u":11165395779094}
{"E":1785353528102,"T":1785353528101,"U":11165395779216,"a":[["64047.60","7.793"],["64048.00","0.938"],["64048.10","1.641"],["64048.20","3.199"],["64048.30","7.519"],["64048.40","1.202"],["64048.50","11.032"],["64048.60","3.485"],["64048.70","9.056"],["64048.80","8.314"],["64048.90","3.338"],["64049.00","2.239"],["64049.10","3.264"],["64049.20","0.000"],["64049.40","0.000"],["64049.60","3.274"],["64049.70","0.019"],["64049.80","0.000"],["64049.90","0.001"],["64050.10","2.574"],["64050.20","0.002"],["64050.30","1.267"],["64050.40","1.912"],["64050.50","2.161"],["64050.60","2.342"],["64050.70","0.010"],["64050.80","2.228"],["64050.90","3.265"],["64051.00","0.368"],["64051.20","3.421"],["64051.30","3.776"],["64051.40","0.484"],["64051.50","0.160"],["64051.60","4.032"],["64051.70","11.472"],["64051.80","14.898"],["64051.90","10.019"],["64052.00","0.146"],["64052.10","0.328"],["64052.20","0.000"],["64052.30","0.015"],["64052.40","0.000"],["64052.50","0.095"],["64052.70","0.000"],["64052.80","0.001"],["64052.90","0.001"],["64053.00","0.000"],["64053.10","0.001"],["64053.20","0.000"],["64053.30","5.210"],["64053.40","5.500"],["64053.50","3.606"],["64053.60","0.203"],["64053.70","0.095"],["64053.80","3.264"],["64053.90","0.001"],["64054.00","3.433"],["64054.10","0.002"],["64054.30","0.000"],["64054.40","0.001"],["64054.50","0.001"],["64054.60","0.000"],["64054.70","3.264"],["64054.80","0.002"],["64054.90","0.001"],["64055.00","0.001"],["64055.10","0.001"],["64055.20","3.264"],["64055.30","0.001"],["64055.40","4.834"],["64055.50","2.230"],["64055.60","0.001"],["64055.70","0.023"],["64055.80","0.000"],["64055.90","0.000"],["64056.00","0.004"],["64056.10","0.000"],["64056.20","3.265"],["64056.30","3.266"],["64056.40","6.311"],["64056.50","1.003"],["64056.60","0.054"],["64056.70","2.345"],["64056.80","0.001"],["64056.90","0.000"],["64057.00","3.595"],["64057.10","0.004"],["64057.20","0.000"],["64057.30","0.000"],["64057.40","0.082"],["64057.50","0.004"],["64057.60","0.001"],["64057.70","0.050"],["64057.80","0.001"],["64057.90","0.000"],["64058.00","0.001"],["64058.10","4.515"],["64058.20","0.047"],["64058.30","0.019"],["64058.40","0.294"],["64058.50","0.234"],["64058.60","5.116"],["64058.70","0.002"],["64058.80","0.009"],["64058.90","0.013"],["64059.00","2.228"],["64059.10","0.000"],["64059.20","0.000"],["64059.30","2.228"],["64059.40","3.265"],["64059.50","6.288"],["64059.60","0.245"],["64059.70","0.182"],["64059.80","0.000"],["64059.90","0.610"],["64060.00","2.642"],["64060.10","0.937"],["64060.20","0.293"],["64060.30","0.061"],["64060.40","0.060"],["64060.50","0.345"],["64060.70","0.006"],["64060.80","0.006"],["64061.00","0.003"],["64061.10","0.001"],["64061.20","0.001"],["64061.30","0.318"],["64061.40","0.023"],["64061.50","0.003"],["64061.60","0.016"],["64061.80","0.001"],["64061.90","0.502"],["64062.00","0.007"],["64062.10","0.554"],["64062.20","0.001"],["64062.30","0.000"],["64062.40","0.005"],["64062.50","0.005"],["64062.60","0.004"],["64062.70","0.661"],["64062.80","2.359"],["64062.90","0.491"],["64063.00","1.000"],["64063.10","0.001"],["64063.20","10.005"],["64063.30","0.002"],["64063.40","0.000"],["64063.50","0.049"],["64063.60","0.001"],["64063.70","0.257"],["64063.80","0.001"],["64063.90","0.002"],["64064.00","0.006"],["64064.10","1.173"],["64064.20","0.001"],["64064.30","0.375"],["64064.40","0.095"],["64064.50","0.001"],["64064.60","0.000"],["64064.70","0.003"],["64064.80","1.913"],["64064.90","0.996"],["64065.00","0.004"],["64065.20","0.687"],["64065.30","0.415"],["64065.60","0.146"],["64065.90","0.002"],["64066.00","0.085"],["64066.10","0.002"],["64066.20","0.386"],["64066.30","0.075"],["64066.60","0.000"],["64066.80","0.016"],["64066.90","0.035"],["64067.00","0.472"],["64067.10","0.006"],["64067.20","1.040"],["64067.30","0.063"],["64067.50","0.004"],["64067.70","0.197"],["64067.80","0.001"],["64067.90","0.004"],["64068.00","0.045"],["64068.20","0.004"],["64068.30","0.177"],["64068.50","0.012"],["64068.60","0.003"],["64068.80","0.001"],["64069.00","0.017"],["64069.10","0.003"],["64069.20","0.522"],["64069.40","0.001"],["64069.50","0.312"],["64069.60","0.439"],["64069.70","0.314"],["64069.80","0.002"],["64070.00","0.008"],["64070.20","0.421"],["64070.30","0.000"],["64070.40","2.252"],["64070.50","1.382"],["64070.60","0.009"],["64070.70","0.120"],["64070.90","0.094"],["64071.00","3.593"],["64071.10","3.128"],["64071.20","0.099"],["64071.30","0.200"],["64071.50","0.002"],["64071.60","0.465"],["64071.80","0.601"],["64072.50","0.939"],["64072.70","0.001"],["64072.80","0.076"],["64073.10","0.006"],["64073.20","0.003"],["64073.50","0.317"],["64073.60","0.720"],["64073.70","0.003"],["64074.00","0.002"],["64074.10","3.578"],["64074.30","2.948"],["64074.40","0.064"],["64074.70","0.091"],["64075.00","0.160"],["64075.10","0.002"],["64075.20","0.002"],["64075.60","0.183"],["64075.70","0.041"],["64076.00","0.004"],["64076.20","0.479"],["64076.50","0.068"],["64076.70","0.003"],["64076.80","1.390"],["64077.20","0.000"],["64077.40","0.104"],["64077.60","0.004"],["64077.70","0.176"],["64077.80","0.470"],["64078.00","0.001"],["64078.50","0.522"],["64078.60","0.161"],["64078.70","0.058"],["64078.80","3.165"],["64079.20","0.022"],["64079.30","0.000"],["64079.60","0.557"],["64079.80","0.000"],["64079.90","0.378"],["64080.20","0.006"],["64080.30","0.003"],["64080.40","0.050"],["64080.80","1.659"],["64080.90","0.006"],["64081.00","0.015"],["64081.20","2.353"],["64081.30","0.001"],["64081.40","0.096"],["64081.90","2.005"],["64082.00","0.058"],["64082.10","0.003"],["64082.40","0.380"],["64082.50","0.001"],["64082.60","0.010"],["64083.10","0.000"],["64083.30","0.001"],["64083.40","0.539"],["64083.50","0.014"],["64083.90","1.255"],["64084.00","0.426"],["64084.20","0.803"],["64084.40","0.012"],["64084.50","0.047"],["64084.70","0.837"],["64085.00","0.531"],["64085.20","0.001"],["64085.30","0.074"],["64085.40","0.242"],["64085.50","0.014"],["64085.60","0.612"],["64085.70","0.021"],["64085.80","0.062"],["64085.90","0.068"],["64086.50","0.002"],["64086.60","0.296"],["64086.70","0.011"],["64086.90","0.391"],["64087.00","0.000"],["64087.10","0.004"],["64087.20","0.683"],["64087.30","0.377"],["64087.40","0.000"],["64087.50","1.052"],["64087.90","0.000"],["64088.90","2.346"],["64089.00","0.047"],["64089.10","0.004"],["64089.40","0.005"],["64089.50","0.063"],["64089.60","0.029"],["64089.70","0.509"],["64090.00","0.063"],["64090.30","0.000"],["64090.40","0.039"],["64090.50","0.001"],["64090.70","0.010"],["64090.80","0.002"],["64090.90","0.899"],["64091.00","0.103"],["64091.30","0.000"],["64091.40","0.003"],["64091.60","0.134"],["64091.80","0.001"],["64092.00","0.529"],["64092.10","0.400"],["64092.30","0.001"],["64092.50","0.000"],["64092.60","0.105"],["64092.70","0.001"],["64092.80","0.007"],["64093.00","0.000"],["64093.30","0.000"],["64093.50","0.003"],["64093.70","0.053"],["64094.20","0.048"],["64095.10","0.001"],["64095.60","2.752"],["64095.70","0.073"],["64095.90","0.108"],["64096.10","0.064"],["64096.20","0.003"],["64096.50","0.035"],["64096.60","0.001"],["64096.80","0.003"],["64096.90","0.061"],["64097.20","5.896"],["64097.40","0.003"],["64097.60","0.003"],["64098.00","0.263"],["64098.20","0.001"],["64099.10","0.001"],["64099.20","0.016"],["64099.40","0.002"],["64099.50","0.100"],["64099.60","1.046"],["64099.90","0.925"],["64100.40","0.000"],["64100.90","0.001"],["64101.00","0.001"],["64101.30","0.001"],["64101.60","0.072"],["64102.20","0.005"],["64102.50","0.002"],["64103.40","0.110"],["64104.00","0.020"],["64104.50","1.254"],["64104.80","0.249"],["64104.90","0.017"],["64105.10","0.001"],["64105.50","0.000"],["64105.80","0.656"],["64106.10","0.005"],["64106.30","0.811"],["64106.60","0.005"],["64107.60","0.000"],["64107.80","0.031"],["64108.30","0.210"],["64108.60","0.567"],["64109.50","0.559"],["64109.80","0.008"],["64110.00","0.009"],["64111.00","0.161"],["64112.50","0.153"],["64112.90","0.000"],["64113.40","0.516"],["64114.00","0.007"],["64114.70","0.000"],["64114.80","0.100"],["64116.00","0.006"],["64118.50","0.000"],["64118.90","0.000"],["64119.20","0.025"],["64120.10","0.001"],["64120.20","0.028"],["64121.00","0.101"],["64121.10","0.271"],["64121.30","0.000"],["64121.90","2.821"],["64122.20","0.000"],["64122.30","0.025"],["64122.90","0.000"],["64123.00","1.499"],["64123.70","0.001"],["64124.10","0.000"],["64124.90","0.000"],["64129.30","0.001"],["64130.10","0.000"],["64131.00","0.083"],["64131.50","0.001"],["64133.60","0.037"],["64134.00","0.618"],["64136.00","0.000"],["64136.50","3.126"],["64137.40","0.482"],["64138.00","0.001"],["64139.10","0.502"],["64140.00","0.059"],["64146.90","0.027"],["64150.80","1.256"],["64150.90","0.057"],["64152.00","0.002"],["64154.20","0.017"],["64155.50","0.014"],["64160.00","0.839"],["64160.20","4.949"],["64160.70","0.012"],["64161.90","0.000"],["64163.80","0.000"],["64164.60","1.281"],["64165.00","0.078"],["64165.10","0.071"],["64172.50","0.027"],["64176.30","0.000"],["64183.00","0.005"],["64183.60","0.000"],["64185.60","0.031"],["64186.50","0.000"],["64187.60","0.003"],["64187.90","0.592"],["64188.70","0.000"],["64189.60","0.001"],["64191.60","0.000"],["64191.90","0.000"],["64193.40","0.775"],["64193.60","0.003"],["64193.90","2.468"],["64200.80","0.004"],["64203.80","0.001"],["64205.20","0.008"],["64226.10","0.109"],["64251.80","0.372"],["64308.10","0.192"],["64315.80","0.000"],["64349.70","0.078"],["64374.20","0.000"],["64400.70","0.002"],["64403.30","0.001"],["64406.50","0.000"],["64413.30","0.850"],["64423.40","0.316"],["64449.00","0.317"],["64475.90","0.001"],["64476.30","0.000"],["64482.40","0.011"],["64502.90","0.000"],["64508.00","0.000"],["64520.80","0.000"],["64551.50","0.112"],["64564.30","0.115"],["64578.90","0.001"],["64588.30","0.001"],["64588.80","0.106"],["64589.90","0.193"],["64591.50","0.302"],["64689.20","0.002"],["64692.40","0.005"],["64694.00","0.000"],["64700.20","0.009"],["65011.60","0.006"],["65013.10","0.002"],["65013.30","0.228"],["65015.90","0.004"],["65017.40","0.002"],["65019.00","0.063"],["65023.00","0.548"],["65051.70","0.010"],["65051.90","0.005"],["65053.50","0.028"],["65053.70","0.002"],["65056.40","0.102"],["65057.60","0.002"],["65057.70","0.000"],["65058.40","0.347"],["65093.40","0.000"],["65143.20","0.014"],["65327.60","0.000"],["65340.70","2.839"],["67259.70","0.005"],["70427.30","0.004"],["70429.00","0.000"],["70457.10","0.004"],["70458.80","0.003"]],"b":[["13559.50","1.022"],["13651.80","0.014"],["13653.40","0.014"],["13658.70","0.014"],["13659.50","0.126"],["13759.50","1.232"],["13851.80","0.014"],["13853.40","0.014"],["13856.30","0.014"],["13859.50","0.826"],["13951.80","0.028"],["13953.40","0.014"],["13959.50","0.868"],["51247.60","0.000"],["51248.00","0.000"],["57646.60","0.002"],["57648.00","0.050"],["57653.50","0.050"],["61497.10","0.003"],["62767.50","0.003"],["62990.40","0.014"],["63407.90","0.004"],["63411.10","3.749"],["63411.30","0.002"],["63412.90","0.000"],["63418.90","0.000"],["63530.40","1.357"],["63537.20","0.011"],["63547.00","0.349"],["63603.40","0.001"],["63609.90","0.000"],["63662.30","0.003"],["63667.50","0.005"],["63674.00","0.001"],["63675.10","1.190"],["63729.40","0.001"],["63731.50","0.105"],["63736.00","0.189"],["63736.20","0.090"],["63784.30","0.576"],["63795.60","0.001"],["63802.10","0.000"],["63828.90","0.084"],["63853.20","0.000"],["63857.50","0.004"],["63882.30","0.002"],["63887.60","0.882"],["63888.70","0.001"],["63889.80","0.873"],["63891.80","0.790"],["63893.00","0.031"],["63893.80","0.897"],["63895.80","0.866"],["63897.80","0.884"],["63899.80","1.257"],["63901.50","3.523"],["63901.80","0.910"],["63903.50","0.001"],["63903.80","0.882"],["63905.50","0.001"],["63905.80","0.882"],["63907.50","2.340"],["63907.80","0.882"],["63909.00","0.010"],["63909.50","0.034"],["63909.80","0.882"],["63911.50","0.002"],["63911.80","0.882"],["63913.50","0.001"],["63913.80","0.976"],["63914.20","0.522"],["63915.10","0.000"],["63915.50","0.003"],["63915.80","0.885"],["63917.30","0.520"],["63917.80","0.882"],["63918.30","0.001"],["63919.80","0.883"],["63921.80","0.032"],["63922.10","0.784"],["63923.80","0.012"],["63928.30","0.000"],["63928.40","0.064"],["63928.50","0.010"],["63933.60","0.000"],["63934.50","0.500"],["63938.50","0.375"],["63940.40","0.032"],["63942.30","0.001"],["63942.80","0.023"],["63947.70","0.008"],["63948.20","0.000"],["63950.30","0.010"],["63954.10","20.759"],["63956.30","0.006"],["63959.20","0.500"],["63960.90","0.000"],["63970.90","0.021"],["63971.70","0.000"],["63973.80","0.001"],["63974.30","1.656"],["63974.60","0.011"],["63974.80","0.315"],["63976.10","0.167"],["63980.50","0.000"],["63983.20","0.409"],["63985.30","2.653"],["63985.60","0.003"],["63986.00","0.092"],["63986.30","0.686"],["63986.50","0.211"],["63986.70","0.000"],["63988.10","0.000"],["63989.00","0.000"],["63989.90","0.063"],["63990.10","0.512"],["63992.30","0.003"],["63992.90","0.142"],["63993.10","0.040"],["63993.30","0.441"],["63993.60","0.054"],["63994.50","0.002"],["63995.10","0.513"],["63995.40","0.014"],["63996.00","0.003"],["63996.30","0.002"],["63996.80","0.065"],["63997.80","0.977"],["63998.00","0.026"],["63998.40","0.003"],["63998.60","0.977"],["63999.20","0.000"],["63999.40","0.000"],["63999.60","0.658"],["64000.40","0.033"],["64000.60","0.129"],["64001.30","0.316"],["64001.50","0.003"],["64001.80","0.061"],["64002.50","0.439"],["64002.60","0.716"],["64002.70","2.407"],["64003.10","0.142"],["64003.20","5.165"],["64003.80","0.117"],["64004.00","0.002"],["64004.60","0.001"],["64004.80","0.313"],["64004.90","0.001"],["64005.10","0.161"],["64005.70","2.005"],["64005.80","0.006"],["64005.90","0.099"],["64006.10","0.134"],["64006.30","0.004"],["64006.50","0.004"],["64006.70","0.000"],["64006.80","0.012"],["64006.90","0.001"],["64007.40","0.120"],["64007.90","1.250"],["64008.30","0.042"],["64008.80","0.002"],["64008.90","0.037"],["64009.30","0.047"],["64009.40","0.529"],["64010.20","0.001"],["64010.90","2.031"],["64011.40","0.550"],["64011.70","0.000"],["64012.00","0.072"],["64012.40","0.385"],["64012.50","0.006"],["64012.60","1.243"],["64013.30","0.002"],["64013.40","2.854"],["64013.50","0.139"],["64013.70","0.000"],["64014.30","0.000"],["64014.90","0.178"],["64015.20","0.003"],["64015.30","0.037"],["64015.40","0.000"],["64015.50","0.004"],["64015.80","0.010"],["64016.00","0.007"],["64016.70","0.033"],["64016.80","0.002"],["64016.90","0.080"],["64017.00","0.000"],["64017.30","0.008"],["64017.50","0.041"],["64018.20","0.001"],["64018.70","0.050"],["64018.80","0.112"],["64019.50","0.000"],["64020.00","0.017"],["64020.20","0.049"],["64020.30","0.003"],["64020.60","0.019"],["64020.80","0.528"],["64021.00","0.030"],["64021.30","0.022"],["64021.50","0.016"],["64021.70","0.020"],["64021.80","0.095"],["64022.00","0.004"],["64022.10","0.946"],["64022.40","0.011"],["64022.70","0.513"],["64022.90","0.000"],["64023.10","2.880"],["64023.30","0.242"],["64023.40","0.656"],["64023.70","0.538"],["64024.10","0.671"],["64024.20","0.196"],["64024.60","0.000"],["64024.70","0.000"],["64024.90","0.009"],["64025.80","0.522"],["64026.10","1.077"],["64026.20","0.977"],["64026.30","0.363"],["64026.40","0.000"],["64026.70","0.002"],["64026.90","0.013"],["64027.00","0.004"],["64027.10","0.060"],["64027.20","0.002"],["64027.40","0.013"],["64027.50","0.010"],["64027.60","0.175"],["64027.70","0.002"],["64028.00","0.091"],["64028.10","0.003"],["64028.30","0.000"],["64028.60","0.005"],["64028.70","0.420"],["64028.80","0.012"],["64028.90","0.527"],["64029.00","1.077"],["64029.10","0.000"],["64029.20","0.006"],["64029.40","0.082"],["64029.60","0.002"],["64029.70","0.057"],["64030.00","0.017"],["64030.10","0.097"],["64030.20","0.015"],["64030.30","0.001"],["64030.40","0.315"],["64030.50","0.000"],["64030.60","0.059"],["64030.70","0.002"],["64030.80","0.001"],["64030.90","0.000"],["64031.00","0.002"],["64031.30","0.115"],["64031.50","0.162"],["64031.80","0.027"],["64032.20","0.004"],["64032.30","0.001"],["64032.40","0.118"],["64032.60","0.008"],["64032.70","2.954"],["64032.80","0.004"],["64033.00","0.313"],["64033.10","0.030"],["64033.30","0.061"],["64033.60","0.100"],["64033.70","0.022"],["64033.80","0.001"],["64033.90","0.000"],["64034.00","0.002"],["64034.10","0.002"],["64034.40","0.002"],["64034.50","0.002"],["64034.70","0.000"],["64034.80","0.102"],["64034.90","0.002"],["64035.10","0.373"],["64035.30","0.009"],["64035.50","0.001"],["64035.80","0.330"],["64035.90","0.023"],["64036.00","0.255"],["64036.20","0.000"],["64036.30","0.000"],["64036.40","0.006"],["64036.70","0.000"],["64036.80","0.002"],["64036.90","0.003"],["64037.10","0.001"],["64037.20","0.005"],["64037.50","0.004"],["64037.80","0.003"],["64037.90","0.064"],["64038.00","0.004"],["64038.10","0.643"],["64038.20","0.006"],["64038.30","0.000"],["64038.40","0.022"],["64038.50","0.004"],["64038.70","0.048"],["64038.80","0.001"],["64039.00","0.002"],["64039.40","0.000"],["64039.50","0.001"],["64039.70","0.002"],["64039.80","0.063"],["64039.90","0.001"],["64040.00","0.042"],["64040.10","0.001"],["64040.30","0.006"],["64040.50","0.001"],["64040.60","0.005"],["64040.70","0.015"],["64040.90","0.003"],["64041.00","0.003"],["64041.10","0.000"],["64041.30","0.216"],["64041.40","0.001"],["64041.60","0.013"],["64041.70","4.080"],["64041.80","0.048"],["64041.90","0.021"],["64042.00","0.002"],["64042.10","0.096"],["64042.20","0.003"],["64042.40","0.121"],["64042.50","0.121"],["64042.70","0.123"],["64042.80","0.180"],["64042.90","0.008"],["64043.00","0.202"],["64043.10","0.061"],["64043.20","0.192"],["64043.30","0.033"],["64043.50","0.005"],["64043.60","0.009"],["64043.70","0.032"],["64043.80","0.017"],["64043.90","0.001"],["64044.00","0.057"],["64044.10","1.023"],["64044.20","0.003"],["64044.30","0.032"],["64044.60","1.323"],["64044.70","0.032"],["64044.80","0.008"],["64044.90","0.000"],["64045.10","0.002"],["64045.40","0.002"],["64045.50","0.002"],["64045.60","0.002"],["64045.80","0.002"],["64045.90","0.003"],["64046.00","0.025"],["64046.10","0.003"],["64046.20","0.003"],["64046.40","0.032"],["64046.60","0.112"],["64046.70","0.001"],["64046.80","0.002"],["64046.90","0.002"],["64047.00","0.001"],["64047.20","0.001"],["64047.30","0.060"],["64047.40","0.001"],["64047.60","0.000"],["64047.70","0.000"],["64047.80","0.000"],["64047.90","0.000"],["64048.00","0.000"],["64048.10","0.000"],["64048.20","0.000"],["64048.30","0.000"],["64048.40","0.000"],["64048.50","0.000"],["64048.60","0.000"],["64048.70","0.000"],["64048.80","0.000"],["64048.90","0.000"],["64049.00","0.000"],["64049.10","0.000"],["64049.20","0.000"],["64049.30","0.000"],["64049.50","0.000"],["64049.60","0.000"],["64049.70","0.000"],["64049.80","0.000"],["64049.90","0.000"],["64050.00","0.000"],["64050.10","0.000"],["64050.20","0.000"],["64050.30","0.000"],["64050.50","0.000"],["64050.60","0.000"],["64050.70","0.000"],["64050.80","0.000"],["64050.90","0.000"],["64051.10","0.000"],["64051.20","0.000"],["64051.30","0.000"],["64051.40","0.000"],["64051.50","0.000"],["64051.60","0.000"],["64051.70","0.000"],["64051.80","0.000"],["64051.90","0.000"],["64052.00","0.000"],["64052.20","0.000"],["64052.30","0.000"],["64052.40","0.000"],["64052.50","0.000"],["64052.60","0.000"],["64052.70","0.000"],["64052.80","0.000"],["64052.90","0.000"],["64053.10","0.000"],["64053.20","0.000"],["64053.30","0.000"],["64053.40","0.000"],["64053.50","0.000"],["64053.60","0.000"],["64053.70","0.000"],["64053.90","0.000"],["64054.00","0.000"],["64054.20","0.000"],["64054.30","0.000"],["64054.40","0.000"],["64054.50","0.000"],["64054.60","0.000"],["64054.70","0.000"],["64054.80","0.000"],["64055.00","0.000"],["64055.10","0.000"],["64055.20","0.000"],["64055.30","0.000"],["64055.40","0.000"],["64055.60","0.000"],["64055.70","0.000"],["64055.90","0.000"],["64056.00","0.000"],["64056.10","0.000"],["64056.20","0.000"],["64056.30","0.000"],["64056.60","0.000"],["64056.70","0.000"],["64056.80","0.000"],["64056.90","0.000"],["64057.00","0.000"],["64057.20","0.000"],["64057.30","0.000"],["64057.40","0.000"],["64057.60","0.000"],["64058.00","0.000"],["64058.10","0.000"],["64058.20","0.000"],["64058.70","0.000"],["64058.80","0.000"],["64058.90","0.000"],["64059.20","0.000"],["64059.30","0.000"],["64059.40","0.000"],["64059.50","0.000"]],"e":"depthUpdate","ps":"BTCUSDT","pu":11165395779094,"s":"BTCUSDT","st":1,"u":11165395808532}
{"E":1785353528204,"T":1785353528203,"U":11165395808556,"a":[["64035.30","6.465"],["64035.40","0.070"],["64035.60","0.334"],["64036.10","0.010"],["64036.40","0.076"],["64036.50","0.424"],["64036.70","0.386"],["64036.80","5.846"],["64036.90","0.001"],["64037.00","2.154"],["64037.10","4.053"],["64037.20","1.036"],["64037.40","0.013"],["64037.60","0.509"],["64037.80","0.001"],["64038.00","1.461"],["64038.10","4.002"],["64038.20","1.046"],["64038.30","1.378"],["64038.40","0.001"],["64038.50","1.378"],["64038.60","2.228"],["64038.70","1.026"],["64039.00","0.001"],["64039.10","1.732"],["64039.20","9.585"],["64039.30","3.735"],["64039.40","0.313"],["64039.50","0.946"],["64039.60","3.264"],["64039.70","0.019"],["64039.80","3.265"],["64039.90","1.990"],["64040.00","1.441"],["64040.10","1.711"],["64040.20","2.228"],["64040.30","2.229"],["64040.40","3.400"],["64040.60","2.228"],["64040.70","0.900"],["64040.80","0.602"],["64040.90","2.423"],["64041.00","2.054"],["64041.10","2.372"],["64041.20","0.001"],["64041.30","0.011"],["64041.40","0.001"],["64041.60","0.001"],["64041.70","6.272"],["64041.80","13.076"],["64041.90","0.015"],["64042.00","1.000"],["64042.20","0.003"],["64042.30","0.000"],["64042.40","0.000"],["64042.50","0.001"],["64042.60","0.000"],["64042.70","0.001"],["64042.80","0.884"],["64042.90","0.000"],["64043.00","1.961"],["64043.10","1.611"],["64043.20","0.001"],["64043.30","0.000"],["64043.40","0.001"],["64043.50","0.000"],["64043.60","0.001"],["64043.70","0.000"],["64043.80","2.507"],["64043.90","0.007"],["64044.00","0.002"],["64044.10","0.000"],["64044.20","0.383"],["64044.30","0.001"],["64044.40","0.000"],["64044.50","0.001"],["64044.60","0.344"],["64044.70","2.342"],["64044.80","2.502"],["64044.90","0.226"],["64045.00","0.096"],["64045.10","0.001"],["64045.20","0.001"],["64045.40","0.001"],["64045.50","0.000"],["64045.60","0.127"],["64045.70","0.000"],["64045.80","0.315"],["64046.00","0.001"],["64046.10","0.001"],["64046.20","0.001"],["64046.30","0.109"],["64046.50","0.642"],["64046.60","0.080"],["64046.70","0.053"],["64046.80","1.630"],["64046.90","0.628"],["64047.00","0.056"],["64047.10","0.001"],["64047.20","0.000"],["64047.30","0.117"],["64047.40","0.001"],["64047.50","2.972"],["64047.60","0.793"],["64047.70","0.001"],["64047.80","1.248"],["64047.90","0.002"],["64048.00","0.385"],["64048.10","0.000"],["64048.20","0.188"],["64048.30","1.370"],["64048.40","0.008"],["64048.50","0.086"],["64048.60","0.156"],["64048.70","0.060"],["64048.80","0.202"],["64048.90","0.098"],["64049.00","0.004"],["64049.10","0.001"],["64049.20","0.000"],["64049.30","0.135"],["64049.50","0.054"],["64049.60","0.000"],["64049.70","0.004"],["64049.80","0.047"],["64049.90","1.250"],["64050.00","0.005"],["64050.10","0.000"],["64050.20","0.001"],["64050.30","0.001"],["64050.40","0.009"],["64050.50","0.001"],["64050.60","2.344"],["64050.70","0.679"],["64050.80","0.017"],["64050.90","0.002"],["64051.00","0.001"],["64051.20","0.003"],["64051.30","0.000"],["64051.40","0.314"],["64051.50","0.000"],["64051.60","1.835"],["64051.70","0.524"],["64051.80","0.167"],["64051.90","1.187"],["64052.00","0.146"],["64052.10","0.565"],["64052.30","0.000"],["64052.40","0.000"],["64052.50","0.095"],["64052.60","0.013"],["64052.70","0.064"],["64052.80","0.001"],["64053.00","0.000"],["64053.10","0.002"],["64053.20","0.354"],["64053.30","2.437"],["64053.40","0.609"],["64053.50","2.569"],["64053.60","0.218"],["64053.70","0.095"],["64053.80","0.239"],["64054.00","0.181"],["64054.10","0.001"],["64054.30","0.000"],["64054.40","0.003"],["64054.50","0.059"],["64054.60","0.355"],["64054.70","1.202"],["64054.80","0.001"],["64054.90","0.118"],["64055.00","6.186"],["64055.10","0.003"],["64055.20","1.202"],["64055.30","0.000"],["64055.40","0.851"],["64055.50","1.204"],["64055.60","0.337"],["64055.70","0.002"],["64055.90","0.624"],["64056.00","0.004"],["64056.20","1.203"],["64056.30","2.240"],["64056.40","5.234"],["64056.50","1.002"],["64056.60","1.000"],["64056.70","1.002"],["64056.80","0.000"],["64056.90","0.000"],["64057.00","3.605"],["64057.10","0.003"],["64057.20","0.000"],["64057.30","0.016"],["64057.40","0.102"],["64057.50","0.157"],["64057.60","0.004"],["64057.70","0.000"],["64057.80","0.000"],["64058.10","3.267"],["64058.20","0.058"],["64058.30","0.001"],["64058.50","0.235"],["64058.60","3.565"],["64058.70","0.000"],["64058.80","0.167"],["64058.90","2.007"],["64059.10","0.081"],["64059.20","0.000"],["64059.30","1.577"],["64059.40","2.238"],["64059.50","0.073"],["64059.60","0.225"],["64059.70","0.180"],["64059.80","0.004"],["64059.90","0.611"],["64060.00","2.408"],["64060.10","0.001"],["64060.20","2.204"],["64060.30","0.217"],["64060.40","0.215"],["64060.50","0.168"],["64060.70","0.005"],["64060.80","0.006"],["64061.00","0.182"],["64061.10","0.004"],["64061.20","0.000"],["64061.30","0.316"],["64061.40","0.004"],["64061.50","0.004"],["64061.60","0.007"],["64061.70","0.000"],["64061.80","0.374"],["64061.90","0.005"],["64062.00","0.004"],["64062.10","0.316"],["64062.20","0.121"],["64062.30","0.000"],["64062.40","0.003"],["64062.50","0.177"],["64062.60","0.002"],["64062.70","0.543"],["64062.80","2.342"],["64062.90","0.479"],["64063.00","0.523"],["64063.20","0.018"],["64063.60","0.000"],["64063.70","0.000"],["64063.80","0.270"],["64063.90","0.005"],["64064.00","0.019"],["64064.10","0.264"],["64064.30","0.375"],["64064.40","0.156"],["64064.50","0.001"],["64064.60","0.134"],["64064.70","0.159"],["64064.80","0.005"],["64064.90","0.000"],["64065.00","0.002"],["64065.10","0.005"],["64065.20","0.000"],["64065.30","0.095"],["64065.60","0.049"],["64065.80","0.538"],["64065.90","0.002"],["64066.00","0.002"],["64066.10","0.562"],["64066.20","0.401"],["64066.30","0.001"],["64066.40","0.000"],["64066.50","0.002"],["64066.80","0.005"],["64066.90","0.028"],["64067.00","0.315"],["64067.10","0.081"],["64067.20","1.035"],["64067.40","0.651"],["64067.50","0.004"],["64067.70","0.050"],["64067.80","0.001"],["64067.90","0.001"],["64068.00","0.124"],["64068.10","0.016"],["64068.20","0.332"],["64068.30","2.177"],["64068.50","0.001"],["64068.60","1.954"],["64068.70","0.006"],["64068.90","0.005"],["64069.00","0.000"],["64069.10","0.004"],["64069.50","0.000"],["64069.60","0.000"],["64069.70","0.314"],["64069.80","0.000"],["64069.90","0.095"],["64070.00","0.012"],["64070.10","0.383"],["64070.20","0.107"],["64070.30","0.014"],["64070.40","2.264"],["64070.50","0.703"],["64070.60","0.009"],["64070.70","0.060"],["64070.80","0.621"],["64070.90","0.095"],["64071.00","3.592"],["64071.10","4.754"],["64071.40","0.002"],["64071.50","0.009"],["64071.60","0.170"],["64071.80","0.293"],["64071.90","0.169"],["64072.00","0.596"],["64072.10","0.197"],["64072.30","0.739"],["64072.40","0.006"],["64072.50","0.935"],["64072.60","0.002"],["64072.70","0.003"],["64072.80","0.015"],["64072.90","0.001"],["64073.00","0.006"],["64073.30","0.001"],["64073.50","0.547"],["64073.60","0.742"],["64073.70","0.003"],["64073.80","0.007"],["64073.90","0.000"],["64074.00","0.002"],["64074.10","2.333"],["64074.20","0.317"],["64074.30","3.928"],["64074.40","0.065"],["64074.50","0.319"],["64074.60","10.150"],["64074.70","8.698"],["64074.80","0.003"],["64074.90","0.002"],["64075.00","0.003"],["64075.10","0.001"],["64075.30","0.005"],["64075.40","1.092"],["64075.50","0.007"],["64075.60","0.174"],["64075.70","0.057"],["64075.80","0.033"],["64075.90","0.001"],["64076.00","0.004"],["64076.10","0.598"],["64076.20","0.143"],["64076.50","0.002"],["64076.60","0.165"],["64076.80","1.403"],["64076.90","0.001"],["64077.00","0.003"],["64077.10","0.542"],["64077.20","0.011"],["64077.30","0.510"],["64077.40","0.108"],["64077.50","0.127"],["64077.70","0.023"],["64077.80","0.002"],["64078.20","0.000"],["64078.50","0.521"],["64078.60","0.159"],["64078.70","0.062"],["64078.80","3.165"],["64079.10","0.001"],["64079.20","0.001"],["64079.30","0.004"],["64079.40","0.001"],["64079.50","0.410"],["64079.60","0.540"],["64080.00","1.827"],["64080.10","0.004"],["64080.20","0.000"],["64080.30","0.824"],["64080.40","0.047"],["64080.60","0.000"],["64080.70","0.002"],["64080.80","0.008"],["64080.90","0.001"],["64081.00","0.115"],["64081.20","2.350"],["64081.40","0.096"],["64081.60","0.757"],["64081.90","0.029"],["64082.00","2.102"],["64082.10","0.003"],["64082.20","0.063"],["64082.30","0.001"],["64082.40","0.271"],["64082.70","3.566"],["64082.80","0.013"],["64083.00","0.000"],["64083.10","0.011"],["64083.20","0.036"],["64083.30","0.121"],["64083.40","0.001"],["64083.60","0.000"],["64083.80","0.003"],["64083.90","0.000"],["64084.00","0.378"],["64084.10","0.001"],["64084.20","0.758"],["64084.40","0.000"],["64084.50","0.000"],["64084.70","0.821"],["64084.80","0.105"],["64085.10","0.047"],["64085.20","0.401"],["64085.30","0.000"],["64085.40","0.108"],["64085.50","0.012"],["64085.60","0.612"],["64085.70","0.015"],["64085.90","0.002"],["64086.10","0.000"],["64086.20","0.001"],["64086.40","0.023"],["64086.60","0.297"],["64086.70","0.005"],["64086.80","0.010"],["64087.30","0.402"],["64087.50","1.051"],["64087.70","0.004"],["64087.80","0.510"],["64088.30","0.054"],["64088.40","0.025"],["64088.50","0.000"],["64088.60","0.001"],["64088.70","0.110"],["64088.90","2.414"],["64089.30","0.001"],["64089.40","0.001"],["64089.50","0.063"],["64089.70","0.315"],["64089.80","0.062"],["64090.00","0.220"],["64090.70","0.009"],["64090.80","0.000"],["64091.00","0.003"],["64091.10","0.000"],["64091.20","0.015"],["64091.60","0.014"],["64091.70","2.341"],["64092.10","0.000"],["64092.30","0.001"],["64092.60","0.010"],["64092.70","0.001"],["64092.80","0.006"],["64092.90","0.002"],["64093.10","0.002"],["64093.50","0.021"],["64093.70","0.004"],["64093.80","0.091"],["64093.90","0.004"],["64094.00","0.521"],["64094.10","0.004"],["64094.20","0.013"],["64094.30","1.090"],["64094.40","2.343"],["64094.50","0.005"],["64094.70","0.031"],["64094.90","0.391"],["64095.10","0.000"],["64095.20","0.000"],["64095.30","0.608"],["64095.40","0.001"],["64095.50","0.059"],["64095.70","0.001"],["64095.90","0.001"],["64096.10","0.001"],["64096.40","0.081"],["64096.50","0.002"],["64096.60","0.001"],["64096.70","1.644"],["64096.90","0.001"],["64097.10","0.502"],["64097.20","2.405"],["64097.30","0.001"],["64097.40","0.002"],["64097.80","0.004"],["64097.90","0.052"],["64098.00","0.106"],["64098.40","0.025"],["64098.50","0.004"],["64098.70","0.000"],["64098.80","0.000"],["64098.90","2.705"],["64099.00","0.083"],["64099.10","0.008"],["64099.30","0.000"],["64099.40","0.000"],["64099.70","0.157"],["64099.90","0.835"],["64100.00","2.695"],["64100.20","0.503"],["64100.30","0.424"],["64100.50","0.000"],["64100.70","0.258"],["64101.10","0.013"],["64101.30","0.000"],["64101.60","0.001"],["64101.70","0.025"],["64101.90","0.160"],["64102.40","0.120"],["64102.50","0.003"],["64102.60","1.575"],["64102.90","0.504"],["64103.10","0.028"],["64103.30","0.520"],["64103.40","0.102"],["64103.90","0.002"],["64104.00","0.106"],["64104.10","0.001"],["64104.30","0.005"],["64104.40","4.409"],["64104.50","1.252"],["64104.90","0.015"],["64105.10","0.002"],["64105.20","0.021"],["64105.30","1.042"],["64105.40","0.000"],["64105.60","0.215"],["64106.00","0.001"],["64106.10","0.000"],["64106.30","4.931"],["64106.40","1.169"],["64106.60","0.001"],["64106.70","0.501"],["64106.90","0.393"],["64107.20","0.202"],["64107.50","0.370"],["64107.80","0.000"],["64108.30","0.000"],["64108.50","0.000"],["64108.60","3.430"],["64108.90","3.290"],["64109.20","0.001"],["64109.50","0.481"],["64109.70","0.101"],["64109.90","0.001"],["64110.00","0.009"],["64110.10","12.333"],["64110.70","0.012"],["64110.90","0.004"],["64111.50","0.315"],["64111.80","0.171"],["64112.10","0.168"],["64112.30","0.462"],["64112.70","0.012"],["64113.10","0.610"],["64113.40","0.016"],["64113.50","0.001"],["64113.90","0.016"],["64114.20","0.510"],["64114.30","0.005"],["64114.80","0.074"],["64114.90","0.011"],["64115.20","0.027"],["64115.30","0.029"],["64115.40","0.001"],["64115.50","0.001"],["64115.80","0.001"],["64116.00","0.007"],["64116.20","0.921"],["64116.40","0.075"],["64117.00","0.149"],["64117.40","0.010"],["64117.50","2.735"],["64117.70","0.001"],["64118.00","0.001"],["64118.30","3.123"],["64118.40","0.028"],["64119.20","0.000"],["64119.60","0.029"],["64120.20","0.000"],["64120.60","0.007"],["64121.00","0.001"],["64121.10","0.247"],["64121.40","0.000"],["64121.60","0.020"],["64121.90","2.868"],["64122.30","0.000"],["64122.60","0.001"],["64122.80","0.024"],["64123.00","1.629"],["64123.90","0.001"],["64124.10","0.000"],["64125.90","0.656"],["64126.00","0.370"],["64126.50","0.012"],["64127.20","0.000"],["64127.30","0.000"],["64128.00","0.024"],["64128.50","0.001"],["64128.70","0.000"],["64128.90","0.004"],["64130.00","0.002"],["64130.20","0.213"],["64130.40","0.065"],["64130.50","0.001"],["64131.00","0.000"],["64131.70","0.063"],["64131.90","0.018"],["64132.00","4.416"],["64132.20","0.540"],["64133.60","0.011"],["64134.60","0.000"],["64134.90","0.706"],["64135.00","0.591"],["64135.10","0.001"],["64136.40","0.012"],["64136.50","0.004"],["64136.80","0.017"],["64138.50","0.252"],["64138.70","0.550"],["64139.60","0.002"],["64140.00","0.030"],["64142.00","0.018"],["64143.10","0.014"],["64143.40","1.494"],["64143.60","0.509"],["64144.10","0.002"],["64144.70","0.120"],["64145.00","0.002"],["64145.90","0.028"],["64146.10","0.003"],["64146.20","0.001"],["64146.40","0.002"],["64146.70","0.489"],["64149.10","0.589"],["64150.50","0.009"],["64150.70","0.008"],["64150.80","0.000"],["64151.70","0.704"],["64151.90","0.000"],["64152.20","0.000"],["64152.40","0.000"],["64154.20","0.014"],["64154.30","0.015"],["64154.40","0.000"],["64154.90","0.000"],["64155.50","0.000"],["64155.70","0.005"],["64156.20","2.341"],["64156.50","2.335"],["64157.70","0.002"],["64157.80","0.999"],["64158.10","0.003"],["64159.00","0.000"],["64160.20","1.356"],["64161.60","0.608"],["64163.20","0.177"],["64163.50","0.834"],["64164.60","0.781"],["64165.70","0.000"],["64169.90","0.503"],["64170.10","0.000"],["64171.70","2.342"],["64173.00","0.243"],["64174.80","3.904"],["64175.30","0.133"],["64175.60","0.000"],["64176.90","0.001"],["64178.90","0.002"],["64179.90","0.040"],["64181.70","0.429"],["64181.90","0.337"],["64184.20","0.000"],["64188.60","0.002"],["64188.80","0.494"],["64189.10","0.382"],["64192.80","0.004"],["64193.90","2.343"],["64194.90","1.509"],["64198.80","1.182"],["64200.80","0.000"],["64206.40","0.667"],["64213.20","0.000"],["64215.80","5.936"],["64221.90","0.363"],["64223.90","0.000"],["64226.00","0.117"],["64230.20","0.002"],["64232.80","0.026"],["64233.10","0.172"],["64235.10","0.004"],["64237.20","0.000"],["64238.80","0.001"],["64239.20","0.000"],["64242.00","0.095"],["64243.20","0.021"],["64243.30","0.641"],["64243.40","0.003"],["64245.80","0.000"],["64247.10","1.946"],["64247.20","0.000"],["64247.40","0.000"],["64250.20","0.002"],["64255.80","0.000"],["64257.40","0.000"],["64265.60","1.959"],["64265.80","0.000"],["64266.00","0.518"],["64267.80","0.007"],["64302.90","0.001"],["64308.10","0.093"],["64309.80","0.534"],["64317.80","0.000"],["64321.10","0.000"],["64323.70","0.000"],["64325.30","0.079"],["64327.90","0.000"],["64332.40","0.078"],["64335.90","0.010"],["64336.70","0.000"],["64362.00","0.251"],["64364.10","0.000"],["64365.10","0.000"],["64366.10","0.000"],["64366.90","2.508"],["64367.50","0.000"],["64373.90","0.000"],["64379.70","0.626"],["64380.00","2.564"],["64380.30","0.251"],["64387.40","0.000"],["64388.00","0.005"],["64393.20","0.001"],["64393.40","0.002"],["64423.40","0.000"],["64429.10","0.053"],["64429.20","0.112"],["64429.50","0.000"],["64431.00","0.002"],["64437.90","0.000"],["64449.00","0.001"],["64456.60","0.096"],["64464.00","0.001"],["64482.20","0.206"],["64495.00","0.042"],["64502.00","0.445"],["64508.40","0.003"],["64521.20","0.000"],["64534.30","0.000"],["64544.40","0.110"],["64546.30","0.192"],["64546.50","0.001"],["64546.90","0.110"],["64551.50","0.002"],["64559.10","0.002"],["64559.30","0.000"],["64559.70","0.000"],["64564.30","0.005"],["64566.00","0.851"],["64571.90","0.288"],["64588.80","0.010"],["64589.90","0.001"],["64591.50","0.000"],["64682.20","0.000"],["64683.50","0.544"],["64684.30","0.005"],["64685.30","0.000"],["64687.20","0.000"],["64687.80","0.029"],["64688.00","0.342"],["64688.70","0.006"],["64689.00","0.199"],["64689.20","0.000"],["64692.40","0.003"],["64700.20","0.008"],["64830.80","3.919"],["65011.60","0.004"],["65014.60","0.020"],["65015.30","0.000"],["65015.90","0.002"],["65019.30","0.004"],["65022.80","0.000"],["65043.90","0.018"],["65044.70","0.006"],["65044.90","0.004"],["65046.70","0.000"],["65047.30","0.004"],["65047.50","0.017"],["65048.20","0.002"],["65048.30","0.306"],["65048.50","0.000"],["65051.70","0.000"],["65053.50","0.018"],["65053.70","0.000"],["65056.40","0.100"],["65056.80","0.004"],["65325.70","0.004"]],"b":[["13559.50","0.910"],["13641.70","0.014"],["13643.00","0.014"],["13643.80","0.014"],["13644.80","0.028"],["13646.60","0.028"],["13647.40","0.014"],["13648.40","0.014"],["13759.50","1.106"],["13839.20","0.014"],["13843.00","0.028"],["13844.80","0.028"],["13846.60","0.028"],["13847.20","0.014"],["13848.10","0.014"],["13941.70","0.014"],["13943.00","0.014"],["13944.80","0.042"],["13946.60","0.028"],["13947.40","0.014"],["13959.50","0.742"],["57637.50","0.052"],["57638.70","0.000"],["57640.30","0.003"],["57641.90","0.000"],["57642.40","0.000"],["57646.60","0.000"],["61497.10","0.000"],["62764.00","0.017"],["62765.70","0.000"],["62983.30","0.745"],["63221.70","0.000"],["63247.10","0.237"],["63251.30","1.056"],["63401.30","0.516"],["63402.60","0.184"],["63403.40","0.013"],["63404.30","0.000"],["63404.40","0.043"],["63406.10","0.000"],["63406.70","0.011"],["63407.00","0.003"],["63407.60","0.000"],["63407.90","0.000"],["63411.10","3.747"],["63411.30","0.000"],["63530.70","0.001"],["63537.20","0.010"],["63544.20","0.000"],["63596.50","0.001"],["63603.40","0.000"],["63625.60","3.446"],["63660.50","0.005"],["63667.50","0.004"],["63706.80","0.001"],["63708.40","0.016"],["63711.60","0.002"],["63714.70","0.007"],["63718.00","0.107"],["63721.50","0.127"],["63722.80","0.106"],["63729.40","0.000"],["63731.50","0.000"],["63736.00","0.084"],["63736.40","0.000"],["63771.70","0.540"],["63776.00","0.554"],["63778.20","0.541"],["63778.90","0.389"],["63779.80","0.538"],["63784.60","0.545"],["63788.60","0.123"],["63790.90","0.384"],["63795.60","0.000"],["63812.40","0.000"],["63825.20","0.000"],["63841.30","0.117"],["63843.20","0.002"],["63850.90","0.002"],["63857.50","0.003"],["63857.80","0.000"],["63857.90","5.936"],["63858.00","1.098"],["63860.80","0.312"],["63864.00","0.002"],["63864.50","0.000"],["63871.90","0.997"],["63872.90","0.001"],["63876.10","0.095"],["63876.20","0.000"],["63876.80","0.014"],["63879.40","0.001"],["63884.50","0.247"],["63884.70","1.574"],["63884.80","0.644"],["63885.20","0.000"],["63886.00","0.107"],["63887.60","0.000"],["63889.80","0.063"],["63891.80","0.000"],["63893.00","0.028"],["63893.70","1.448"],["63893.80","0.015"],["63895.80","0.076"],["63897.80","0.002"],["63898.40","1.294"],["63899.00","0.729"],["63899.80","0.375"],["63900.70","0.211"],["63901.30","0.003"],["63901.60","0.519"],["63901.80","0.028"],["63903.20","0.004"],["63903.80","0.000"],["63904.90","0.520"],["63905.80","0.000"],["63906.60","0.005"],["63907.80","0.000"],["63908.00","1.020"],["63909.50","0.035"],["63909.80","0.000"],["63911.10","0.526"],["63911.50","0.003"],["63911.80","0.000"],["63913.80","0.094"],["63914.10","2.196"],["63915.50","0.004"],["63915.80","0.003"],["63916.20","0.001"],["63917.80","0.000"],["63919.70","0.006"],["63919.80","0.029"],["63920.20","0.001"],["63920.40","0.521"],["63921.50","0.008"],["63922.10","0.783"],["63922.90","0.511"],["63923.50","0.538"],["63923.80","0.015"],["63924.10","0.501"],["63925.50","0.000"],["63927.50","2.342"],["63928.60","0.368"],["63929.50","0.051"],["63930.90","0.492"],["63931.20","2.340"],["63931.50","0.006"],["63931.90","0.805"],["63932.10","0.374"],["63932.60","1.955"],["63932.80","0.513"],["63933.00","0.002"],["63933.40","0.002"],["63933.90","2.063"],["63934.50","0.000"],["63934.70","0.001"],["63936.20","0.127"],["63936.60","0.001"],["63938.80","3.124"],["63938.90","0.781"],["63939.20","0.846"],["63940.10","0.001"],["63940.50","0.026"],["63940.90","0.496"],["63941.10","2.000"],["63941.40","0.103"],["63941.90","0.492"],["63943.30","0.002"],["63944.40","0.000"],["63944.70","0.027"],["63945.30","0.042"],["63945.90","0.092"],["63947.50","21.266"],["63947.60","0.187"],["63947.70","0.000"],["63948.00","0.044"],["63948.70","1.139"],["63949.50","11.742"],["63949.70","0.502"],["63949.90","0.039"],["63950.00","0.271"],["63950.70","2.342"],["63951.00","0.008"],["63951.60","0.001"],["63952.30","0.000"],["63953.50","0.000"],["63954.10","0.003"],["63954.60","1.694"],["63955.20","0.235"],["63955.50","3.487"],["63956.20","0.240"],["63956.30","0.006"],["63956.40","2.424"],["63956.80","0.064"],["63957.20","0.013"],["63957.30","0.000"],["63957.40","0.000"],["63957.70","0.075"],["63958.10","0.022"],["63958.50","0.020"],["63958.70","0.147"],["63959.00","0.120"],["63959.20","1.561"],["63959.70","0.011"],["63960.10","0.001"],["63960.20","0.000"],["63961.10","0.006"],["63961.60","1.589"],["63962.10","0.001"],["63962.90","0.011"],["63963.40","0.076"],["63963.60","0.166"],["63964.30","0.044"],["63964.40","0.210"],["63966.50","0.386"],["63966.90","0.559"],["63967.10","0.120"],["63968.60","0.001"],["63968.70","2.998"],["63969.10","0.000"],["63969.30","0.313"],["63969.80","0.313"],["63969.90","0.000"],["63970.20","0.000"],["63970.90","0.006"],["63971.20","0.002"],["63971.30","0.025"],["63971.70","0.000"],["63973.30","1.249"],["63973.50","0.001"],["63973.70","0.022"],["63974.30","0.095"],["63975.00","0.100"],["63975.30","0.502"],["63976.10","0.000"],["63976.20","0.489"],["63976.80","0.200"],["63976.90","0.004"],["63977.20","0.380"],["63977.30","2.141"],["63977.70","0.040"],["63977.80","0.876"],["63978.20","0.010"],["63979.00","0.001"],["63979.20","0.002"],["63979.50","0.025"],["63979.60","0.617"],["63979.80","0.320"],["63980.00","0.079"],["63980.20","0.664"],["63980.90","0.009"],["63981.30","0.313"],["63981.40","1.344"],["63981.90","0.000"],["63982.20","0.003"],["63982.30","4.609"],["63982.40","0.493"],["63982.80","0.001"],["63983.40","0.019"],["63983.50","7.711"],["63983.90","0.000"],["63984.00","0.007"],["63984.90","0.052"],["63985.00","0.589"],["63985.20","3.277"],["63985.30","2.653"],["63985.60","0.002"],["63985.90","0.000"],["63986.00","0.002"],["63986.20","0.001"],["63986.30","0.656"],["63986.50","0.001"],["63986.70","0.001"],["63987.10","0.101"],["63987.30","0.382"],["63987.40","0.978"],["63987.70","0.262"],["63988.20","1.829"],["63988.30","0.979"],["63988.40","0.004"],["63989.10","0.000"],["63989.50","0.000"],["63989.60","0.004"],["63989.80","1.840"],["63989.90","0.068"],["63990.30","0.063"],["63990.40","0.178"],["63990.90","0.000"],["63991.00","0.002"],["63991.10","0.066"],["63991.40","0.005"],["63991.60","0.003"],["63991.70","0.763"],["63991.80","0.185"],["63992.20","0.000"],["63992.30","0.003"],["63992.40","0.003"],["63992.60","0.002"],["63992.70","0.000"],["63992.80","0.153"],["63992.90","0.001"],["63993.10","10.036"],["63993.30","0.416"],["63993.40","0.032"],["63993.60","0.054"],["63993.90","0.000"],["63994.00","0.001"],["63994.10","0.003"],["63994.20","0.005"],["63994.40","0.000"],["63994.50","0.032"],["63994.60","1.255"],["63994.80","0.808"],["63995.00","0.000"],["63995.30","0.922"],["63995.40","0.016"],["63995.50","0.002"],["63995.70","0.000"],["63995.80","5.258"],["63996.00","0.003"],["63996.10","3.160"],["63996.30","0.001"],["63996.40","0.002"],["63996.50","2.544"],["63996.60","0.011"],["63996.70","0.000"],["63996.80","0.065"],["63996.90","0.000"],["63997.00","0.000"],["63997.10","0.000"],["63997.30","0.314"],["63997.40","0.002"],["63997.50","0.000"],["63997.60","0.003"],["63997.70","0.001"],["63997.80","0.094"],["63998.00","0.001"],["63998.10","0.002"],["63998.20","0.027"],["63998.40","0.003"],["63998.60","0.977"],["63998.70","0.000"],["63998.90","0.000"],["63999.00","0.907"],["63999.10","1.497"],["63999.60","0.658"],["63999.90","0.000"],["64000.10","2.341"],["64000.20","0.000"],["64000.30","0.674"],["64000.40","0.033"],["64000.50","0.024"],["64000.60","0.066"],["64000.90","0.001"],["64001.10","1.260"],["64001.20","0.006"],["64001.50","0.001"],["64001.60","0.000"],["64001.70","0.509"],["64001.90","0.004"],["64002.20","0.071"],["64002.30","0.074"],["64002.70","2.342"],["64002.90","0.001"],["64003.00","0.128"],["64003.10","0.001"],["64003.20","4.102"],["64003.30","0.001"],["64003.40","0.000"],["64003.70","0.597"],["64003.80","0.079"],["64004.00","0.051"],["64004.10","0.512"],["64004.30","0.000"],["64004.40","0.065"],["64004.50","0.028"],["64004.60","0.095"],["64004.70","0.176"],["64004.80","0.338"],["64005.00","0.184"],["64005.10","0.063"],["64005.20","0.000"],["64005.40","2.389"],["64005.50","0.043"],["64005.60","0.063"],["64005.70","0.005"],["64005.80","0.003"],["64005.90","0.060"],["64006.10","0.014"],["64006.20","0.042"],["64006.30","0.033"],["64006.40","1.138"],["64006.50","0.105"],["64006.70","0.001"],["64006.80","0.092"],["64007.10","0.060"],["64007.50","0.005"],["64007.60","0.134"],["64007.90","1.297"],["64008.00","2.365"],["64008.10","0.001"],["64008.20","0.030"],["64008.30","0.002"],["64008.40","0.000"],["64008.50","0.003"],["64008.60","0.028"],["64008.80","0.006"],["64009.00","0.001"],["64009.30","0.048"],["64009.70","0.314"],["64009.80","0.095"],["64009.90","0.635"],["64010.00","0.035"],["64010.30","0.517"],["64010.40","0.000"],["64010.70","0.000"],["64010.80","2.340"],["64010.90","2.422"],["64011.00","0.162"],["64011.10","0.001"],["64011.20","0.001"],["64011.30","0.001"],["64011.40","0.050"],["64011.50","0.002"],["64011.60","0.001"],["64011.80","0.007"],["64011.90","0.002"],["64012.00","0.049"],["64012.10","0.002"],["64012.30","0.004"],["64012.40","0.366"],["64012.50","0.002"],["64012.60","1.360"],["64012.70","0.001"],["64012.80","0.038"],["64012.90","0.564"],["64013.00","0.195"],["64013.10","0.002"],["64013.20","1.781"],["64013.40","2.860"],["64013.50","0.134"],["64013.60","0.001"],["64013.70","0.001"],["64013.80","0.094"],["64013.90","0.001"],["64014.00","0.003"],["64014.10","0.532"],["64014.20","0.001"],["64014.30","0.019"],["64014.50","0.288"],["64014.60","1.265"],["64014.70","0.936"],["64014.90","0.003"],["64015.00","0.553"],["64015.10","1.726"],["64015.20","0.000"],["64015.30","0.002"],["64015.40","0.312"],["64015.50","0.001"],["64015.70","0.000"],["64015.80","0.015"],["64016.00","0.253"],["64016.10","0.090"],["64016.20","0.007"],["64016.30","0.009"],["64016.40","0.005"],["64016.50","2.974"],["64016.60","0.064"],["64016.70","0.620"],["64016.80","0.001"],["64016.90","0.000"],["64017.10","0.001"],["64017.20","0.119"],["64017.30","0.003"],["64017.40","0.007"],["64017.50","0.001"],["64017.60","0.062"],["64017.70","0.001"],["64017.80","0.508"],["64017.90","0.000"],["64018.10","0.040"],["64018.30","0.095"],["64018.40","0.060"],["64018.50","0.003"],["64018.60","0.000"],["64018.70","0.002"],["64018.80","0.006"],["64018.90","0.000"],["64019.10","0.133"],["64019.20","0.937"],["64019.40","0.005"],["64019.50","0.001"],["64019.60","0.572"],["64019.70","0.001"],["64019.80","0.103"],["64019.90","0.400"],["64020.00","0.031"],["64020.10","0.315"],["64020.20","0.089"],["64020.30","0.001"],["64020.40","0.014"],["64020.50","0.157"],["64020.60","0.028"],["64020.70","0.085"],["64020.80","0.531"],["64020.90","0.005"],["64021.00","0.053"],["64021.10","0.000"],["64021.20","0.017"],["64021.30","0.070"],["64021.40","0.009"],["64021.50","0.005"],["64021.60","0.009"],["64021.70","0.014"],["64021.80","0.001"],["64022.00","0.124"],["64022.10","0.948"],["64022.20","0.041"],["64022.30","0.162"],["64022.40","0.013"],["64022.50","0.539"],["64022.60","0.005"],["64022.80","0.034"],["64023.00","0.009"],["64023.10","0.540"],["64023.20","0.000"],["64023.30","0.163"],["64023.40","0.539"],["64023.50","0.001"],["64023.60","0.002"],["64023.70","0.538"],["64023.80","0.001"],["64023.90","0.283"],["64024.10","0.000"],["64024.20","0.098"],["64024.40","0.360"],["64024.60","0.003"],["64024.80","0.007"],["64024.90","0.002"],["64025.00","0.021"],["64025.10","0.001"],["64025.20","0.314"],["64025.30","0.000"],["64025.40","0.095"],["64025.60","1.831"],["64025.70","0.004"],["64025.80","0.316"],["64025.90","0.006"],["64026.00","0.246"],["64026.10","0.014"],["64026.20","0.000"],["64026.30","0.084"],["64026.40","0.002"],["64026.50","0.000"],["64026.60","0.214"],["64026.70","0.817"],["64026.80","0.015"],["64026.90","0.001"],["64027.00","0.005"],["64027.10","0.000"],["64027.20","0.003"],["64027.30","0.000"],["64027.40","0.002"],["64027.50","0.005"],["64027.60","0.000"],["64027.70","0.002"],["64027.80","0.001"],["64027.90","0.000"],["64028.00","0.052"],["64028.20","0.002"],["64028.40","0.014"],["64028.60","0.005"],["64028.70","0.420"],["64028.80","0.008"],["64028.90","0.005"],["64029.00","0.003"],["64029.10","0.003"],["64029.20","0.005"],["64029.30","0.002"],["64029.40","0.002"],["64029.50","1.332"],["64029.70","0.001"],["64029.80","0.003"],["64029.90","0.002"],["64030.00","0.020"],["64030.10","0.003"],["64030.20","0.196"],["64030.30","0.000"],["64030.40","0.002"],["64030.60","0.000"],["64030.80","0.001"],["64031.00","0.001"],["64031.10","0.001"],["64031.20","0.000"],["64031.30","0.000"],["64031.40","0.002"],["64031.50","0.002"],["64031.60","0.020"],["64031.70","0.001"],["64031.80","0.028"],["64032.00","1.130"],["64032.10","0.002"],["64032.30","0.001"],["64032.40","0.023"],["64032.50","1.008"],["64032.60","0.006"],["64032.70","0.002"],["64032.80","0.003"],["64032.90","0.000"],["64033.00","0.313"],["64033.10","0.012"],["64033.20","0.064"],["64033.30","0.003"],["64033.40","0.002"],["64033.50","0.000"],["64033.60","0.552"],["64033.70","0.000"],["64033.80","0.001"],["64033.90","0.004"],["64034.00","0.003"],["64034.10","0.002"],["64034.20","0.004"],["64034.40","0.002"],["64034.50","0.003"],["64034.60","0.000"],["64034.70","0.001"],["64034.80","0.001"],["64034.90","0.001"],["64035.00","0.000"],["64035.10","0.000"],["64035.20","0.000"],["64035.30","0.000"],["64035.40","0.000"],["64035.50","0.000"],["64035.60","0.000"],["64035.70","0.000"],["64035.80","0.000"],["64035.90","0.000"],["64036.00","0.000"],["64036.10","0.000"],["64036.20","0.000"],["64036.30","0.000"],["64036.40","0.000"],["64036.50","0.000"],["64036.60","0.000"],["64036.70","0.000"],["64036.80","0.000"],["64036.90","0.000"],["64037.00","0.000"],["64037.10","0.000"],["64037.20","0.000"],["64037.30","0.000"],["64037.40","0.000"],["64037.50","0.000"],["64037.60","0.000"],["64037.70","0.000"],["64037.80","0.000"],["64037.90","0.000"],["64038.00","0.000"],["64038.10","0.000"],["64038.20","0.000"],["64038.40","0.000"],["64038.50","0.000"],["64038.60","0.000"],["64038.70","0.000"],["64038.80","0.000"],["64038.90","0.000"],["64039.00","0.000"],["64039.10","0.000"],["64039.20","0.000"],["64039.30","0.000"],["64039.40","0.000"],["64039.50","0.000"],["64039.60","0.000"],["64039.70","0.000"],["64039.80","0.000"],["64039.90","0.000"],["64040.00","0.000"],["64040.10","0.000"],["64040.20","0.000"],["64040.30","0.000"],["64040.40","0.000"],["64040.50","0.000"],["64040.60","0.000"],["64040.70","0.000"],["64040.80","0.000"],["64040.90","0.000"],["64041.00","0.000"],["64041.20","0.000"],["64041.30","0.000"],["64041.40","0.000"],["64041.60","0.000"],["64041.70","0.000"],["64041.80","0.000"],["64041.90","0.000"],["64042.00","0.000"],["64042.10","0.000"],["64042.20","0.000"],["64042.30","0.000"],["64042.40","0.000"],["64042.50","0.000"],["64042.60","0.000"],["64042.70","0.000"],["64042.80","0.000"],["64042.90","0.000"],["64043.00","0.000"],["64043.10","0.000"],["64043.20","0.000"],["64043.30","0.000"],["64043.40","0.000"],["64043.50","0.000"],["64043.60","0.000"],["64043.70","0.000"],["64043.80","0.000"],["64043.90","0.000"],["64044.00","0.000"],["64044.10","0.000"],["64044.20","0.000"],["64044.30","0.000"],["64044.50","0.000"],["64044.60","0.000"],["64044.70","0.000"],["64044.80","0.000"],["64045.00","0.000"],["64045.10","0.000"],["64045.40","0.000"],["64045.50","0.000"],["64045.60","0.000"],["64045.70","0.000"],["64045.80","0.000"],["64045.90","0.000"],["64046.00","0.000"],["64046.10","0.000"],["64046.20","0.000"],["64046.30","0.000"],["64046.40","0.000"],["64046.50","0.000"],["64046.60","0.000"],["64046.70","0.000"],["64046.80","0.000"],["64046.90","0.000"],["64047.00","0.000"],["64047.20","0.000"],["64047.30","0.000"],["64047.40","0.000"]],"e":"depthUpdate","ps":"BTCUSDT","pu":11165395808532,"s":"BTCUSDT","st":1,"u":11165395862062}
{"E":1785353528306,"T":1785353528305,"U":11165395862088,"a":[["64029.10","15.094"],["64029.20","0.564"],["64029.30","3.783"],["64029.40","2.963"],["64029.50","0.003"],["64029.60","0.001"],["64029.70","0.000"],["64029.80","0.020"],["64029.90","0.000"],["64030.00","0.002"],["64030.20","0.054"],["64030.30","0.000"],["64030.40","0.001"],["64030.60","0.001"],["64030.70","0.002"],["64031.00","0.001"],["64031.10","0.068"],["64031.20","0.001"],["64031.30","0.001"],["64031.40","0.002"],["64031.50","0.013"],["64031.60","0.002"],["64031.70","0.136"],["64031.80","1.160"],["64031.90","0.000"],["64032.00","0.207"],["64032.10","2.340"],["64032.20","0.003"],["64032.30","0.003"],["64032.40","3.048"],["64032.50","2.668"],["64032.60","0.203"],["64032.70","0.002"],["64032.80","0.002"],["64032.90","0.000"],["64033.00","0.001"],["64033.10","0.671"],["64033.20","1.208"],["64033.30","0.295"],["64033.40","0.294"],["64033.50","2.238"],["64033.60","0.936"],["64033.70","3.743"],["64033.80","0.002"],["64033.90","0.095"],["64034.00","1.040"],["64034.10","0.697"],["64034.20","0.000"],["64034.30","1.037"],["64034.40","0.000"],["64034.50","0.017"],["64034.60","0.003"],["64034.70","0.000"],["64034.80","0.002"],["64034.90","0.007"],["64035.00","4.823"],["64035.10","0.002"],["64035.20","0.002"],["64035.30","1.038"],["64035.40","0.002"],["64035.50","0.346"],["64035.60","0.000"],["64035.70","0.048"],["64035.80","0.017"],["64035.90","0.003"],["64036.00","2.492"],["64036.10","0.000"],["64036.20","2.288"],["64036.30","5.765"],["64036.40","3.305"],["64036.50","0.001"],["64036.60","3.266"],["64036.70","3.264"],["64036.80","3.749"],["64036.90","0.001"],["64037.00","0.001"],["64037.10","1.038"],["64037.20","1.036"],["64037.30","0.059"],["64037.40","0.020"],["64037.50","0.004"],["64037.60","1.286"],["64037.70","0.293"],["64037.80","0.001"],["64037.90","0.000"],["64038.00","0.506"],["64038.10","2.340"],["64038.20","1.038"],["64038.30","1.036"],["64038.40","0.004"],["64038.50","0.001"],["64038.60","3.499"],["64038.70","2.231"],["64038.90","0.002"],["64039.00","0.081"],["64039.10","0.095"],["64039.20","3.643"],["64039.30","0.422"],["64039.40","0.313"],["64039.50","0.001"],["64039.60","3.265"],["64039.70","0.063"],["64039.80","3.267"],["64039.90","1.644"],["64040.00","0.433"],["64040.10","0.082"],["64040.20","0.000"],["64040.30","4.140"],["64040.40","0.005"],["64040.50","0.000"],["64040.60","2.229"],["64040.70","0.013"],["64040.80","0.258"],["64040.90","2.340"],["64041.00","0.000"],["64041.10","0.001"],["64041.20","0.021"],["64041.30","0.001"],["64041.40","0.001"],["64041.50","0.050"],["64041.60","0.004"],["64041.70","3.542"],["64041.80","4.550"],["64041.90","0.003"],["64042.00","0.063"],["64042.10","0.013"],["64042.20","0.004"],["64042.30","0.001"],["64042.40","0.935"],["64042.80","0.000"],["64042.90","0.003"],["64043.00","1.309"],["64043.10","0.243"],["64043.20","0.001"],["64043.30","0.000"],["64043.40","0.121"],["64043.50","0.011"],["64043.60","0.161"],["64043.70","0.001"],["64043.80","0.313"],["64044.00","0.004"],["64044.30","0.000"],["64044.50","0.001"],["64044.60","0.657"],["64044.70","2.343"],["64044.80","0.172"],["64044.90","0.225"],["64045.10","0.000"],["64045.30","0.001"],["64045.40","0.001"],["64045.50","0.002"],["64045.60","0.047"],["64045.80","0.323"],["64045.90","0.080"],["64046.00","0.001"],["64046.10","0.001"],["64046.20","0.075"],["64046.30","10.094"],["64046.40","0.188"],["64046.50","0.470"],["64046.60","0.080"],["64046.70","0.052"],["64046.80","0.468"],["64046.90","0.618"],["64047.00","0.000"],["64047.10","0.091"],["64047.20","0.001"],["64047.30","0.314"],["64047.40","0.000"],["64047.50","2.874"],["64047.70","0.000"],["64047.80","0.393"],["64047.90","0.563"],["64048.00","0.404"],["64048.10","0.538"],["64048.20","0.191"],["64048.30","1.469"],["64048.40","0.001"],["64048.50","0.081"],["64048.60","0.066"],["64048.70","0.123"],["64048.80","0.201"],["64048.90","0.003"],["64049.00","0.003"],["64049.30","0.000"],["64049.50","0.014"],["64049.70","0.002"],["64050.00","0.004"],["64050.10","0.007"],["64050.20","0.137"],["64050.30","0.000"],["64050.40","0.047"],["64050.50","0.000"],["64050.60","2.862"],["64050.70","0.679"],["64050.80","0.001"],["64050.90","0.002"],["64051.00","0.002"],["64051.10","1.656"],["64051.20","0.017"],["64051.30","0.000"],["64051.40","0.326"],["64051.60","1.833"],["64051.70","0.443"],["64051.80","0.127"],["64052.00","0.145"],["64052.10","0.313"],["64052.20","0.049"],["64052.40","2.119"],["64052.50","0.030"],["64052.60","3.170"],["64052.80","0.013"],["64052.90","0.000"],["64053.00","0.000"],["64053.10","0.159"],["64053.20","0.000"],["64053.50","2.571"],["64053.60","0.206"],["64053.70","0.696"],["64053.80","0.000"],["64053.90","0.000"],["64054.00","0.169"],["64054.20","0.609"],["64054.30","0.004"],["64054.50","0.001"],["64054.60","0.001"],["64054.70","1.245"],["64054.80","0.054"],["64054.90","0.000"],["64055.00","3.345"],["64055.10","0.001"],["64055.20","1.292"],["64055.40","0.000"],["64055.50","1.203"],["64055.60","2.290"],["64055.70","0.003"],["64055.90","0.003"],["64056.00","0.004"],["64056.10","0.000"],["64056.30","1.202"],["64056.40","4.202"],["64056.50","1.064"],["64056.60","1.066"],["64056.70","1.108"],["64056.80","0.520"],["64056.90","0.058"],["64057.00","3.346"],["64057.10","0.018"],["64057.20","0.000"],["64057.30","0.000"],["64057.40","0.082"],["64057.50","0.140"],["64057.60","0.017"],["64057.90","0.209"],["64058.00","0.001"],["64058.10","1.260"],["64058.20","2.125"],["64058.30","1.216"],["64058.40","0.009"],["64058.50","0.001"],["64058.60","0.788"],["64058.70","0.538"],["64058.80","0.009"],["64058.90","0.006"],["64059.00","1.202"],["64059.10","0.001"],["64059.30","0.328"],["64059.40","0.002"],["64059.50","0.071"],["64059.60","0.094"],["64059.70","0.180"],["64059.80","0.000"],["64059.90","1.131"],["64060.00","2.411"],["64060.20","0.000"],["64060.40","0.157"],["64060.60","0.000"],["64060.70","0.004"],["64060.90","0.005"],["64061.00","0.592"],["64061.10","0.059"],["64061.20","0.007"],["64061.30","0.315"],["64061.40","0.001"],["64061.50","0.553"],["64061.60","0.002"],["64061.90","0.002"],["64062.00","0.003"],["64062.10","0.670"],["64062.20","0.000"],["64062.30","0.014"],["64062.40","0.004"],["64062.50","0.097"],["64062.70","0.000"],["64062.80","2.359"],["64062.90","0.467"],["64063.20","0.003"],["64063.30","0.001"],["64063.40","0.000"],["64063.50","0.123"],["64063.70","0.500"],["64063.80","0.274"],["64063.90","0.002"],["64064.00","0.048"],["64064.20","0.831"],["64064.40","0.003"],["64064.70","0.708"],["64064.80","0.001"],["64065.00","0.001"],["64065.10","0.000"],["64065.20","0.001"],["64065.30","0.106"],["64065.40","2.343"],["64065.50","0.002"],["64065.70","0.314"],["64065.80","0.000"],["64066.00","0.003"],["64066.10","0.521"],["64066.20","0.385"],["64066.30","0.004"],["64066.40","0.004"],["64066.60","0.003"],["64066.80","0.037"],["64066.90","0.030"],["64067.00","0.158"],["64067.10","0.011"],["64067.20","1.035"],["64067.40","0.608"],["64067.50","0.006"],["64067.60","0.541"],["64067.70","0.050"],["64067.80","0.043"],["64067.90","0.413"],["64068.00","0.047"],["64068.20","0.001"],["64068.30","0.269"],["64068.40","3.325"],["64068.60","0.095"],["64068.70","0.004"],["64069.00","0.004"],["64069.10","0.003"],["64069.90","0.001"],["64070.00","0.006"],["64070.30","0.048"],["64070.40","2.269"],["64070.50","0.094"],["64070.60","2.077"],["64070.70","0.000"],["64070.80","0.538"],["64071.00","3.592"],["64071.10","3.098"],["64071.40","0.002"],["64071.50","0.050"],["64071.60","0.309"],["64071.70","0.829"],["64071.90","0.179"],["64072.00","0.456"],["64072.30","0.675"],["64072.40","0.091"],["64072.50","0.028"],["64072.60","0.000"],["64072.70","0.079"],["64072.80","0.041"],["64073.00","0.001"],["64073.10","0.006"],["64073.20","0.002"],["64073.30","0.000"],["64073.40","0.000"],["64073.50","0.637"],["64073.60","0.707"],["64073.70","0.004"],["64073.80","0.000"],["64073.90","0.078"],["64074.00","0.159"],["64074.10","3.914"],["64074.20","0.318"],["64074.30","3.924"],["64074.70","8.698"],["64074.80","0.002"],["64075.00","0.001"],["64075.30","0.001"],["64075.40","0.523"],["64075.50","0.002"],["64075.60","0.171"],["64075.70","0.041"],["64076.00","0.003"],["64076.10","0.622"],["64076.20","0.094"],["64076.40","0.071"],["64076.70","0.001"],["64077.00","0.002"],["64077.20","0.000"],["64077.30","0.041"],["64077.50","0.123"],["64077.70","0.003"],["64077.80","0.039"],["64078.10","3.614"],["64078.30","0.002"],["64078.50","0.521"],["64078.60","0.006"],["64078.70","0.001"],["64078.80","3.163"],["64079.10","0.001"],["64079.30","0.000"],["64079.50","0.315"],["64080.10","0.002"],["64080.30","0.003"],["64080.40","0.000"],["64080.50","0.000"],["64080.70","0.001"],["64080.80","0.004"],["64080.90","0.000"],["64081.00","0.015"],["64081.20","2.349"],["64081.30","0.000"],["64081.40","2.162"],["64081.50","0.030"],["64081.60","0.531"],["64081.70","0.541"],["64081.80","0.000"],["64082.00","0.001"],["64082.30","0.000"],["64082.40","0.002"],["64082.60","0.000"],["64082.80","0.005"],["64082.90","1.029"],["64083.30","0.001"],["64083.40","0.000"],["64083.50","0.013"],["64083.60","0.000"],["64083.70","0.002"],["64083.80","0.005"],["64084.10","0.459"],["64084.20","0.100"],["64084.30","0.000"],["64084.70","0.819"],["64084.80","0.004"],["64084.90","0.000"],["64085.00","0.529"],["64085.10","0.000"],["64085.20","0.001"],["64085.40","0.000"],["64085.50","0.011"],["64085.70","0.244"],["64085.80","0.059"],["64086.20","0.000"],["64086.30","0.001"],["64086.40","0.006"],["64086.60","0.297"],["64086.70","0.674"],["64086.80","0.009"],["64087.10","1.207"],["64087.20","0.002"],["64087.30","0.401"],["64087.40","0.004"],["64087.60","0.000"],["64087.70","0.015"],["64087.90","0.025"],["64088.00","0.004"],["64088.10","0.003"],["64088.40","0.016"],["64088.70","2.068"],["64088.80","0.000"],["64088.90","2.342"],["64089.00","0.046"],["64089.10","0.043"],["64089.30","0.001"],["64089.50","0.093"],["64089.60","0.022"],["64089.70","0.815"],["64090.00","0.063"],["64090.10","0.000"],["64090.30","0.100"],["64090.40","0.038"],["64090.60","0.376"],["64090.70","0.102"],["64090.80","6.147"],["64091.10","0.000"],["64091.20","0.007"],["64091.40","0.001"],["64091.50","0.003"],["64091.60","0.004"],["64091.70","2.341"],["64091.80","0.001"],["64091.90","7.525"],["64092.00","0.527"],["64092.10","7.700"],["64092.20","15.504"],["64092.80","0.006"],["64092.90","0.102"],["64093.10","0.102"],["64093.20","0.821"],["64093.30","3.227"],["64093.40","0.387"],["64093.50","0.000"],["64093.60","2.001"],["64093.70","2.504"],["64093.80","15.201"],["64093.90","0.000"],["64094.00","0.521"],["64094.10","0.004"],["64094.20","0.013"],["64094.30","0.025"],["64094.50","0.000"],["64094.60","0.000"],["64094.80","0.002"],["64095.60","0.894"],["64095.70","0.000"],["64095.90","0.001"],["64096.10","0.000"],["64096.20","0.000"],["64096.40","0.000"],["64096.50","0.002"],["64096.70","0.967"],["64096.80","0.000"],["64097.30","0.002"],["64097.60","0.003"],["64097.90","0.001"],["64098.00","0.094"],["64098.40","0.073"],["64098.70","1.946"],["64098.80","0.129"],["64098.90","0.368"],["64099.00","0.098"],["64099.10","0.100"],["64099.70","0.156"],["64099.90","1.230"],["64100.00","2.664"],["64100.30","0.138"],["64100.70","0.027"],["64101.00","0.000"],["64101.20","0.075"],["64101.70","0.000"],["64101.90","0.107"],["64102.00","0.775"],["64102.10","0.003"],["64102.40","0.020"],["64102.50","1.485"],["64102.70","3.126"],["64102.80","0.000"],["64102.90","0.095"],["64103.10","0.002"],["64103.20","0.083"],["64103.30","0.502"],["64103.40","0.002"],["64103.60","0.001"],["64103.90","0.002"],["64104.00","0.006"],["64104.10","0.000"],["64104.30","0.001"],["64104.40","2.342"],["64104.70","0.151"],["64104.80","0.171"],["64105.60","0.005"],["64106.00","0.510"],["64106.20","1.272"],["64106.30","4.121"],["64106.40","0.501"],["64106.70","0.001"],["64106.80","0.076"],["64106.90","0.002"],["64107.10","0.030"],["64107.30","0.000"],["64108.40","0.009"],["64108.60","0.566"],["64108.70","0.001"],["64108.80","0.021"],["64108.90","3.321"],["64109.70","0.101"],["64110.10","12.233"],["64110.20","0.150"],["64110.30","0.242"],["64110.70","0.000"],["64111.50","0.002"],["64111.70","1.249"],["64112.00","0.215"],["64113.30","0.104"],["64113.50","0.001"],["64113.90","0.001"],["64114.00","0.006"],["64114.80","0.000"],["64115.30","0.500"],["64116.00","0.006"],["64116.40","0.000"],["64116.50","0.000"],["64116.70","0.030"],["64117.00","0.065"],["64117.40","0.194"],["64117.70","0.000"],["64118.00","0.000"],["64118.10","0.003"],["64118.30","0.000"],["64118.70","0.724"],["64119.20","0.016"],["64119.60","0.004"],["64120.00","0.017"],["64120.20","0.000"],["64121.10","0.003"],["64121.50","0.003"],["64121.90","2.821"],["64122.00","0.506"],["64122.40","0.002"],["64122.70","0.064"],["64122.90","1.484"],["64123.00","0.000"],["64123.20","0.032"],["64123.40","0.066"],["64124.00","0.023"],["64124.20","0.012"],["64124.60","2.356"],["64125.90","0.541"],["64126.60","0.227"],["64127.60","0.066"],["64127.70","0.001"],["64128.80","1.583"],["64130.20","0.025"],["64130.80","0.005"],["64131.10","1.429"],["64131.20","0.954"],["64131.90","0.002"],["64132.00","4.591"],["64132.10","0.029"],["64132.20","0.048"],["64132.80","0.124"],["64133.50","0.244"],["64134.90","1.283"],["64136.30","4.456"],["64137.90","0.043"],["64138.50","0.211"],["64138.60","0.795"],["64138.70","0.509"],["64139.00","0.001"],["64139.10","0.501"],["64140.20","0.016"],["64140.40","0.512"],["64141.00","0.000"],["64142.00","0.004"],["64142.90","0.512"],["64143.30","1.498"],["64143.40","0.010"],["64144.30","2.344"],["64144.70","0.000"],["64144.80","0.027"],["64145.00","0.782"],["64145.90","0.000"],["64147.30","0.000"],["64148.60","0.178"],["64148.90","0.011"],["64149.10","0.000"],["64150.50","0.000"],["64150.70","0.000"],["64150.90","0.025"],["64151.40","1.299"],["64153.20","0.166"],["64154.50","0.000"],["64156.60","0.386"],["64157.20","0.009"],["64157.70","0.126"],["64157.80","0.499"],["64158.50","2.362"],["64159.10","0.495"],["64160.20","1.201"],["64161.40","0.007"],["64161.60","0.000"],["64161.70","0.001"],["64161.80","0.048"],["64162.00","0.396"],["64162.20","4.401"],["64164.60","0.000"],["64164.90","2.340"],["64165.10","0.063"],["64165.40","0.123"],["64166.10","0.247"],["64166.70","0.030"],["64166.80","0.124"],["64166.90","0.125"],["64168.20","0.015"],["64168.40","0.498"],["64169.50","0.121"],["64169.60","1.413"],["64170.50","2.278"],["64171.00","0.000"],["64171.50","0.524"],["64171.70","0.000"],["64172.80","0.667"],["64173.00","0.000"],["64173.60","0.000"],["64174.80","0.000"],["64174.90","0.000"],["64175.30","0.009"],["64177.40","0.494"],["64182.40","2.453"],["64183.10","0.003"],["64185.00","0.001"],["64185.10","0.008"],["64185.40","0.377"],["64186.00","0.144"],["64186.80","0.201"],["64187.50","0.005"],["64189.80","0.001"],["64191.80","0.000"],["64192.30","0.981"],["64192.80","0.000"],["64194.10","0.002"],["64196.30","0.309"],["64196.70","0.000"],["64201.00","0.000"],["64201.10","0.007"],["64201.30","0.068"],["64201.50","0.069"],["64202.20","0.382"],["64205.30","0.072"],["64209.10","0.000"],["64211.40","0.021"],["64213.40","0.383"],["64213.50","0.000"],["64213.80","0.000"],["64214.70","1.027"],["64216.70","0.000"],["64217.60","0.172"],["64219.40","0.026"],["64220.40","0.073"],["64220.80","0.001"],["64220.90","1.937"],["64221.00","3.242"],["64221.60","0.001"],["64221.80","0.000"],["64224.10","0.315"],["64225.80","0.009"],["64226.00","0.000"],["64226.10","0.010"],["64227.60","0.003"],["64228.10","3.099"],["64228.90","0.012"],["64229.20","1.470"],["64229.60","0.000"],["64238.80","0.000"],["64240.10","0.751"],["64241.90","5.470"],["64242.00","0.001"],["64246.80","2.037"],["64246.90","0.001"],["64247.10","0.001"],["64251.00","0.000"],["64253.90","0.005"],["64264.60","0.000"],["64265.30","1.947"],["64265.50","0.000"],["64265.60","0.014"],["64272.00","2.295"],["64272.90","0.116"],["64273.40","12.940"],["64281.80","0.090"],["64284.70","0.000"],["64285.60","0.123"],["64292.90","0.510"],["64302.90","0.000"],["64310.50","0.123"],["64311.20","0.014"],["64313.60","0.233"],["64314.30","0.000"],["64314.50","0.036"],["64318.60","0.000"],["64323.60","0.250"],["64323.80","0.161"],["64323.90","0.160"],["64324.00","0.299"],["64325.30","0.001"],["64332.40","0.000"],["64344.80","0.070"],["64349.20","0.317"],["64349.50","0.101"],["64349.60","0.000"],["64349.70","0.000"],["64352.50","0.053"],["64353.90","0.000"],["64357.00","0.005"],["64362.00","0.151"],["64366.90","2.507"],["64374.70","0.003"],["64376.40","0.000"],["64376.70","0.000"],["64379.10","0.014"],["64379.70","0.310"],["64379.90","3.532"],["64380.00","2.454"],["64380.30","0.155"],["64384.10","0.769"],["64387.70","0.316"],["64390.20","0.243"],["64390.60","0.000"],["64391.10","0.002"],["64393.80","0.177"],["64400.60","0.119"],["64413.30","0.851"],["64421.00","0.242"],["64426.60","0.002"],["64426.70","0.000"],["64429.10","0.036"],["64429.20","0.002"],["64431.00","0.001"],["64477.30","0.463"],["64485.10","0.122"],["64495.00","0.041"],["64528.50","0.302"],["64541.30","0.001"],["64544.40","0.000"],["64546.30","0.000"],["64546.90","0.000"],["64549.10","0.002"],["64554.10","6.316"],["64559.10","0.001"],["64571.90","0.000"],["64643.80","0.727"],["64644.40","0.055"],["64669.40","0.002"],["64669.70","0.000"],["64672.80","0.047"],["64675.40","0.000"],["64686.20","0.005"],["64686.30","0.002"],["64783.90","0.921"],["64786.10","0.918"],["64796.50","14.086"],["64850.20","0.765"],["64860.60","7.690"],["64971.40","10.307"],["65029.10","0.407"],["65029.20","0.349"],["65029.40","0.547"],["65029.50","0.009"],["65032.50","0.003"],["65035.00","0.008"],["65035.30","0.535"],["65043.90","0.012"],["65044.70","0.002"],["65044.90","0.002"],["65047.30","0.000"],["65047.50","0.005"],["65048.30","0.304"],["65051.90","0.001"],["65053.50","0.010"],["65067.50","1.801"],["65135.90","0.034"]],"b":[["1000.00","37.992"],["13559.50","0.784"],["13629.00","0.056"],["13629.30","0.028"],["13632.40","0.014"],["13634.90","0.028"],["13759.50","0.980"],["13829.00","0.056"],["13829.30","0.042"],["13833.60","0.014"],["13834.90","0.014"],["13929.00","0.056"],["13929.30","0.028"],["13933.10","0.014"],["13934.90","0.014"],["13936.30","0.014"],["13959.50","0.616"],["57626.10","0.070"],["57626.30","0.000"],["57631.40","0.000"],["57637.50","0.050"],["61467.80","0.003"],["63036.70","1.891"],["63037.10","2.198"],["63073.70","0.000"],["63101.20","2.197"],["63103.40","1.140"],["63133.20","14.112"],["63134.10","1.105"],["63135.50","2.352"],["63136.20","2.352"],["63137.30","2.352"],["63137.70","0.119"],["63164.80","1.097"],["63166.10","0.000"],["63169.80","0.000"],["63201.80","0.005"],["63228.80","0.783"],["63229.20","2.351"],["63232.90","0.908"],["63261.20","4.697"],["63262.20","0.000"],["63262.30","0.000"],["63264.30","1.565"],["63265.90","1.058"],["63277.50","0.034"],["63293.30","0.939"],["63294.20","0.031"],["63294.30","0.000"],["63297.90","0.002"],["63302.80","0.552"],["63329.90","0.000"],["63360.90","3.136"],["63388.70","0.000"],["63388.80","0.102"],["63389.00","0.090"],["63389.10","0.001"],["63392.10","0.005"],["63392.20","0.403"],["63392.80","0.001"],["63394.00","0.002"],["63394.60","0.002"],["63401.30","0.514"],["63408.50","1.594"],["63445.30","0.000"],["63514.40","0.031"],["63517.10","0.001"],["63523.90","3.533"],["63530.70","0.000"],["63539.80","0.013"],["63581.10","0.001"],["63589.20","0.000"],["63596.50","0.000"],["63608.70","0.055"],["63618.00","0.009"],["63618.30","0.454"],["63618.40","0.182"],["63645.10","0.064"],["63653.30","0.000"],["63660.50","0.004"],["63669.50","0.387"],["63675.10","1.094"],["63676.20","0.130"],["63678.20","0.034"],["63682.30","1.181"],["63683.10","0.000"],["63683.90","0.034"],["63694.10","0.002"],["63695.70","0.001"],["63698.90","0.001"],["63702.00","0.040"],["63704.30","0.001"],["63708.30","0.000"],["63708.90","0.946"],["63709.20","0.001"],["63709.60","0.009"],["63711.70","0.004"],["63716.00","0.043"],["63718.90","0.000"],["63721.50","0.022"],["63722.20","0.011"],["63722.80","0.000"],["63735.40","0.000"],["63736.00","0.010"],["63739.20","0.011"],["63747.70","0.001"],["63760.00","1.020"],["63760.40","0.561"],["63761.10","0.000"],["63762.50","0.357"],["63763.40","0.551"],["63763.60","0.540"],["63766.10","0.261"],["63771.80","0.538"],["63773.20","0.002"],["63778.90","0.230"],["63781.00","0.386"],["63781.40","0.001"],["63784.30","0.959"],["63787.60","0.383"],["63788.60","0.122"],["63796.70","1.050"],["63804.40","6.088"],["63809.50","0.002"],["63816.50","0.147"],["63822.20","0.998"],["63826.30","0.178"],["63828.20","0.000"],["63828.90","0.010"],["63830.80","0.001"],["63830.90","0.000"],["63837.20","0.002"],["63839.50","0.014"],["63841.20","0.011"],["63841.30","0.000"],["63844.10","0.074"],["63845.40","0.574"],["63847.20","0.072"],["63847.50","0.001"],["63850.90","0.001"],["63851.50","0.350"],["63853.80","0.002"],["63853.90","0.029"],["63854.00","0.000"],["63860.80","0.000"],["63861.50","0.000"],["63862.00","0.005"],["63862.30","0.220"],["63863.10","16.619"],["63863.70","16.222"],["63863.80","0.074"],["63863.90","0.000"],["63865.20","0.504"],["63865.60","5.215"],["63865.90","0.014"],["63867.20","0.246"],["63867.30","0.230"],["63868.00","0.915"],["63868.40","0.009"],["63868.60","0.001"],["63870.60","3.440"],["63870.90","0.000"],["63871.20","0.011"],["63871.90","1.518"],["63873.20","0.147"],["63874.90","3.370"],["63875.20","1.015"],["63876.00","0.688"],["63877.20","0.000"],["63877.70","0.130"],["63878.30","0.646"],["63879.20","0.502"],["63880.40","0.164"],["63881.00","0.949"],["63881.20","0.010"],["63881.60","0.499"],["63881.70","0.000"],["63884.30","0.276"],["63884.50","0.000"],["63884.60","0.098"],["63884.80","0.520"],["63886.00","0.000"],["63886.30","0.244"],["63887.10","0.000"],["63887.90","0.500"],["63889.40","0.539"],["63891.10","0.224"],["63891.40","2.244"],["63892.50","0.520"],["63893.70","1.016"],["63894.20","0.007"],["63895.60","0.520"],["63895.70","0.002"],["63895.80","0.004"],["63896.10","0.001"],["63897.60","0.307"],["63897.70","0.091"],["63898.10","0.030"],["63898.50","0.004"],["63898.70","0.520"],["63898.80","3.904"],["63899.00","0.229"],["63900.10","0.024"],["63900.30","2.591"],["63901.10","0.000"],["63901.20","0.001"],["63901.50","3.242"],["63901.80","0.548"],["63903.00","0.000"],["63903.70","0.886"],["63905.00","2.000"],["63905.30","0.020"],["63905.70","24.531"],["63905.80","0.000"],["63906.80","0.028"],["63907.20","4.845"],["63907.30","0.161"],["63907.40","0.021"],["63908.60","0.000"],["63909.70","0.889"],["63910.60","0.781"],["63913.00","0.524"],["63913.50","0.501"],["63913.80","0.875"],["63914.10","2.198"],["63915.30","0.312"],["63915.50","0.003"],["63916.20","0.009"],["63916.50","0.000"],["63918.90","20.821"],["63919.10","0.005"],["63919.70","0.003"],["63919.80","0.001"],["63920.80","14.429"],["63920.90","8.760"],["63921.00","0.044"],["63921.40","0.005"],["63922.40","3.126"],["63922.60","0.008"],["63922.90","0.497"],["63923.30","0.596"],["63924.10","0.001"],["63924.30","0.157"],["63924.90","0.033"],["63925.20","0.002"],["63925.50","0.000"],["63925.70","0.000"],["63926.30","0.492"],["63926.50","0.584"],["63926.90","0.065"],["63927.10","0.002"],["63927.80","0.019"],["63928.70","2.347"],["63929.00","0.001"],["63929.30","0.000"],["63929.40","0.187"],["63930.00","0.540"],["63930.40","0.003"],["63930.60","0.608"],["63930.70","0.001"],["63930.80","0.061"],["63930.90","0.503"],["63931.70","0.000"],["63931.80","0.978"],["63931.90","0.001"],["63932.40","0.000"],["63932.60","1.999"],["63932.70","1.259"],["63933.10","0.000"],["63933.60","0.000"],["63933.70","0.000"],["63933.80","0.013"],["63934.10","0.006"],["63934.40","0.004"],["63935.00","0.094"],["63935.80","0.623"],["63936.50","0.059"],["63936.80","0.032"],["63937.10","0.000"],["63937.70","0.490"],["63938.60","0.000"],["63938.70","0.000"],["63938.80","0.001"],["63938.90","1.433"],["63939.10","0.500"],["63939.20","0.065"],["63939.30","0.441"],["63939.70","1.606"],["63939.90","0.003"],["63940.00","23.919"],["63940.50","0.010"],["63941.10","0.000"],["63941.40","0.095"],["63941.80","0.150"],["63942.00","0.001"],["63942.10","0.503"],["63942.60","0.232"],["63943.10","0.075"],["63943.40","6.073"],["63944.80","1.563"],["63945.10","0.074"],["63945.30","0.000"],["63946.20","2.359"],["63947.50","0.510"],["63947.60","0.000"],["63948.00","0.001"],["63948.50","0.067"],["63948.70","1.139"],["63949.00","0.013"],["63949.20","2.320"],["63949.30","0.164"],["63949.50","11.710"],["63949.60","0.013"],["63949.70","0.004"],["63950.00","0.270"],["63950.20","0.015"],["63950.70","0.000"],["63951.00","0.010"],["63952.10","1.024"],["63952.60","0.019"],["63953.60","0.000"],["63953.90","0.002"],["63954.50","0.485"],["63954.70","0.016"],["63954.80","0.313"],["63955.20","0.172"],["63955.50","0.468"],["63956.20","0.000"],["63956.30","0.000"],["63956.40","2.341"],["63956.50","0.527"],["63956.80","0.000"],["63957.70","0.210"],["63958.10","0.019"],["63958.50","0.029"],["63958.70","0.000"],["63958.80","11.502"],["63959.00","0.030"],["63959.20","0.000"],["63959.30","0.002"],["63959.80","0.314"],["63960.00","1.715"],["63960.30","0.000"],["63960.50","0.002"],["63960.70","2.311"],["63961.30","0.416"],["63961.60","2.674"],["63962.30","10.944"],["63962.50","0.063"],["63962.70","0.002"],["63962.80","0.025"],["63962.90","0.211"],["63963.00","4.528"],["63963.10","0.001"],["63963.40","0.002"],["63963.60","0.000"],["63963.90","2.197"],["63964.30","0.052"],["63964.40","0.000"],["63964.60","0.032"],["63964.70","0.652"],["63964.80","0.827"],["63964.90","0.506"],["63965.30","0.351"],["63966.50","0.371"],["63966.60","0.568"],["63966.70","0.000"],["63966.80","0.000"],["63967.50","0.060"],["63967.70","0.000"],["63967.90","0.001"],["63968.00","0.538"],["63968.10","0.026"],["63968.20","0.509"],["63968.90","0.027"],["63969.70","6.305"],["63969.90","0.375"],["63970.00","0.496"],["63970.40","0.002"],["63970.50","0.008"],["63970.70","2.252"],["63970.80","0.001"],["63970.90","0.027"],["63971.20","0.002"],["63971.30","0.002"],["63971.60","1.838"],["63971.70","0.001"],["63971.80","0.027"],["63972.20","0.001"],["63972.40","1.010"],["63972.60","0.000"],["63973.50","0.116"],["63973.70","0.000"],["63973.80","0.002"],["63974.20","0.002"],["63974.80","0.315"],["63975.10","0.287"],["63975.30","0.002"],["63975.40","0.004"],["63975.50","0.004"],["63976.00","0.000"],["63976.50","0.481"],["63976.60","0.000"],["63976.70","0.002"],["63976.80","0.000"],["63976.90","0.000"],["63977.10","0.010"],["63977.20","0.380"],["63977.30","0.313"],["63977.40","0.468"],["63977.50","0.083"],["63977.70","0.003"],["63977.80","0.885"],["63978.30","0.000"],["63978.50","0.001"],["63978.90","1.037"],["63979.00","0.000"],["63979.10","0.058"],["63979.20","0.003"],["63979.40","0.000"],["63979.50","0.000"],["63979.60","0.609"],["63979.70","0.001"],["63979.80","0.322"],["63980.10","0.003"],["63980.20","0.704"],["63980.40","0.000"],["63980.90","0.053"],["63981.00","0.063"],["63981.40","1.359"],["63981.50","0.590"],["63981.60","2.344"],["63981.70","0.020"],["63982.20","0.000"],["63982.30","4.234"],["63982.40","0.583"],["63982.50","0.015"],["63983.30","0.032"],["63983.40","0.002"],["63983.60","2.714"],["63983.70","0.004"],["63983.80","0.001"],["63984.20","0.029"],["63984.50","0.003"],["63984.80","0.313"],["63984.90","0.048"],["63985.10","0.000"],["63985.20","3.239"],["63985.30","4.145"],["63985.40","0.011"],["63985.50","0.489"],["63985.60","1.223"],["63985.70","0.000"],["63985.90","0.028"],["63986.20","0.005"],["63986.60","0.303"],["63986.80","0.527"],["63987.10","0.001"],["63987.20","0.035"],["63987.50","0.106"],["63987.70","0.001"],["63987.80","0.000"],["63988.10","0.000"],["63988.20","0.001"],["63988.40","0.094"],["63988.50","0.027"],["63988.60","0.496"],["63988.70","0.000"],["63988.80","0.074"],["63988.90","0.027"],["63989.00","0.002"],["63989.10","0.000"],["63989.30","0.313"],["63989.50","0.001"],["63989.70","0.004"],["63989.80","1.872"],["63990.20","2.815"],["63990.30","0.626"],["63990.40","0.065"],["63990.60","0.408"],["63990.80","10.000"],["63990.90","0.035"],["63991.00","0.393"],["63991.10","0.004"],["63991.30","0.020"],["63991.40","0.004"],["63991.50","0.047"],["63991.60","0.001"],["63991.70","0.529"],["63991.80","0.001"],["63991.90","0.005"],["63992.40","0.003"],["63992.50","0.032"],["63992.70","0.032"],["63992.80","0.033"],["63992.90","0.015"],["63993.00","0.000"],["63993.10","0.036"],["63993.20","0.084"],["63993.30","0.316"],["63993.40","0.192"],["63993.50","1.414"],["63993.60","0.148"],["63993.70","0.003"],["63994.00","0.001"],["63994.10","0.000"],["63994.20","0.011"],["63994.30","0.150"],["63994.60","1.254"],["63994.80","0.808"],["63995.00","0.002"],["63995.20","0.002"],["63995.40","0.013"],["63995.60","0.068"],["63995.70","0.312"],["63995.80","5.260"],["63995.90","0.000"],["63996.00","0.007"],["63996.20","1.722"],["63996.30","0.002"],["63996.40","0.000"],["63996.50","1.804"],["63996.60","0.001"],["63996.70","0.002"],["63996.80","0.677"],["63996.90","0.219"],["63997.10","0.019"],["63997.20","0.563"],["63997.30","0.314"],["63997.40","0.069"],["63997.50","0.007"],["63997.60","0.046"],["63997.80","0.000"],["63998.00","0.023"],["63998.20","0.001"],["63998.30","0.005"],["63998.40","0.012"],["63998.50","0.000"],["63998.60","0.000"],["63998.90","0.012"],["63999.10","0.167"],["63999.20","0.000"],["63999.40","0.031"],["63999.50","0.003"],["63999.60","0.460"],["63999.70","0.052"],["63999.80","1.250"],["63999.90","0.001"],["64000.00","11.005"],["64000.10","2.442"],["64000.30","0.656"],["64000.40","0.001"],["64000.60","0.016"],["64000.90","0.100"],["64001.10","1.251"],["64001.20","0.002"],["64001.40","0.001"],["64001.50","0.003"],["64001.70","0.000"],["64001.80","0.061"],["64001.90","0.683"],["64002.00","0.150"],["64002.10","0.178"],["64002.20","0.000"],["64002.30","0.060"],["64002.50","0.439"],["64002.60","0.927"],["64002.80","0.010"],["64003.00","0.365"],["64003.10","0.005"],["64003.20","3.207"],["64003.30","0.251"],["64003.40","0.042"],["64003.60","0.000"],["64003.70","0.528"],["64003.80","0.075"],["64003.90","0.692"],["64004.00","0.141"],["64004.10","0.524"],["64004.20","0.002"],["64004.30","0.002"],["64004.40","0.065"],["64004.50","0.000"],["64004.60","0.002"],["64004.70","0.711"],["64004.80","0.313"],["64004.90","0.001"],["64005.00","0.014"],["64005.10","0.007"],["64005.20","0.012"],["64005.30","0.470"],["64005.40","2.381"],["64005.50","0.005"],["64005.60","0.088"],["64005.70","0.033"],["64005.90","0.118"],["64006.10","0.057"],["64006.20","0.122"],["64006.30","0.001"],["64006.40","1.148"],["64006.50","0.000"],["64006.60","0.011"],["64006.80","0.012"],["64006.90","0.052"],["64007.00","0.183"],["64007.20","0.630"],["64007.30","0.062"],["64007.40","0.132"],["64007.50","0.002"],["64007.60","0.562"],["64007.70","0.351"],["64007.80","0.115"],["64007.90","1.297"],["64008.00","2.382"],["64008.10","0.884"],["64008.20","0.443"],["64008.30","0.362"],["64008.50","0.004"],["64008.60","0.047"],["64008.70","0.000"],["64008.80","0.041"],["64008.90","0.099"],["64009.20","0.312"],["64009.30","0.056"],["64009.40","0.529"],["64009.50","0.534"],["64009.60","0.893"],["64009.80","0.884"],["64009.90","0.270"],["64010.00","0.016"],["64010.10","0.413"],["64010.30","0.520"],["64010.60","0.000"],["64010.80","0.001"],["64010.90","2.033"],["64011.00","2.356"],["64011.10","0.004"],["64011.30","0.094"],["64011.40","0.001"],["64011.50","1.655"],["64011.60","0.001"],["64011.70","0.020"],["64011.80","0.001"],["64012.20","0.000"],["64012.30","0.004"],["64012.40","0.369"],["64012.50","0.096"],["64012.60","0.816"],["64012.70","0.001"],["64012.80","0.009"],["64012.90","0.001"],["64013.00","0.001"],["64013.10","0.217"],["64013.20","0.191"],["64013.30","0.001"],["64013.40","0.003"],["64013.50","0.883"],["64013.60","0.107"],["64013.70","0.001"],["64013.80","0.001"],["64013.90","0.001"],["64014.00","0.198"],["64014.10","0.000"],["64014.20","1.022"],["64014.30","0.000"],["64014.50","0.192"],["64014.60","0.002"],["64014.70","0.226"],["64014.80","0.094"],["64014.90","0.005"],["64015.00","0.002"],["64015.10","0.627"],["64015.20","0.089"],["64015.30","0.885"],["64015.40","0.647"],["64015.50","0.001"],["64015.60","0.001"],["64015.70","0.000"],["64015.80","0.084"],["64016.00","0.007"],["64016.10","0.142"],["64016.20","0.586"],["64016.30","0.002"],["64016.40","0.000"],["64016.50","0.124"],["64016.60","0.004"],["64016.70","0.001"],["64016.80","0.001"],["64016.90","0.000"],["64017.10","0.001"],["64017.20","0.025"],["64017.30","0.887"],["64017.40","0.094"],["64017.50","0.001"],["64017.60","0.004"],["64017.70","0.095"],["64017.80","0.002"],["64017.90","0.000"],["64018.00","0.002"],["64018.10","0.003"],["64018.20","0.001"],["64018.30","0.001"],["64018.40","0.020"],["64018.50","0.003"],["64018.60","0.000"],["64018.70","0.001"],["64018.80","0.007"],["64018.90","0.000"],["64019.00","0.001"],["64019.10","0.123"],["64019.20","0.300"],["64019.30","0.093"],["64019.40","0.890"],["64019.50","0.036"],["64019.60","0.001"],["64019.80","0.001"],["64019.90","0.062"],["64020.00","0.015"],["64020.10","0.000"],["64020.20","0.049"],["64020.30","0.000"],["64020.40","0.001"],["64020.50","0.001"],["64020.60","0.001"],["64020.70","0.000"],["64020.80","0.105"],["64020.90","0.006"],["64021.00","0.001"],["64021.10","0.000"],["64021.20","0.001"],["64021.30","0.885"],["64021.40","0.004"],["64021.50","0.006"],["64021.60","0.001"],["64021.70","0.015"],["64021.80","0.003"],["64021.90","0.001"],["64022.00","0.002"],["64022.10","0.314"],["64022.20","0.011"],["64022.30","0.062"],["64022.40","0.010"],["64022.50","0.001"],["64022.60","0.000"],["64022.70","0.001"],["64022.80","0.006"],["64023.00","0.001"],["64023.10","0.002"],["64023.20","0.000"],["64023.30","0.003"],["64023.40","0.002"],["64023.60","0.001"],["64023.70","0.001"],["64023.80","0.001"],["64023.90","0.282"],["64024.00","0.058"],["64024.10","0.002"],["64024.20","0.001"],["64024.30","0.001"],["64024.40","0.001"],["64024.50","0.000"],["64024.60","0.067"],["64024.90","0.002"],["64025.00","0.003"],["64025.10","0.001"],["64025.20","0.001"],["64025.30","0.001"],["64025.40","0.001"],["64025.50","0.004"],["64025.60","0.008"],["64025.70","0.003"],["64025.80","0.003"],["64026.00","0.004"],["64026.10","0.004"],["64026.30","0.008"],["64026.40","0.001"],["64026.60","0.001"],["64026.70","0.002"],["64026.80","0.001"],["64026.90","0.001"],["64027.00","0.002"],["64027.10","0.000"],["64027.20","0.002"],["64027.40","0.003"],["64027.50","0.002"],["64027.60","0.000"],["64027.70","0.000"],["64027.80","0.000"],["64028.00","0.001"],["64028.10","0.001"],["64028.20","0.000"],["64028.40","0.012"],["64028.50","0.001"],["64028.60","0.001"],["64028.70","0.007"],["64028.80","0.001"],["64028.90","0.005"],["64029.00","0.535"],["64029.10","0.000"],["64029.20","0.000"],["64029.30","0.000"],["64029.40","0.000"],["64029.50","0.000"],["64029.60","0.000"],["64029.70","0.000"],["64029.80","0.000"],["64029.90","0.000"],["64030.00","0.000"],["64030.10","0.000"],["64030.20","0.000"],["64030.40","0.000"],["64030.50","0.000"],["64030.70","0.000"],["64030.80","0.000"],["64031.00","0.000"],["64031.10","0.000"],["64031.30","0.000"],["64031.40","0.000"],["64031.50","0.000"],["64031.60","0.000"],["64031.70","0.000"],["64031.80","0.000"],["64031.90","0.000"],["64032.00","0.000"],["64032.10","0.000"],["64032.20","0.000"],["64032.30","0.000"],["64032.40","0.000"],["64032.50","0.000"],["64032.60","0.000"],["64032.70","0.000"],["64032.80","0.000"],["64033.00","0.000"],["64033.10","0.000"],["64033.20","0.000"],["64033.30","0.000"],["64033.40","0.000"],["64033.60","0.000"],["64033.80","0.000"],["64033.90","0.000"],["64034.00","0.000"],["64034.10","0.000"],["64034.20","0.000"],["64034.30","0.000"],["64034.40","0.000"],["64034.50","0.000"],["64034.70","0.000"],["64034.80","0.000"],["64034.90","0.000"]],"e":"depthUpdate","ps":"BTCUSDT","pu":11165395862062,"s":"BTCUSDT","st":1,"u":11165395911871}
{"E":1785353528408,"T":1785353528407,"U":11165395911964,"a":[["64029.10","13.424"],["64029.20","0.009"],["64029.30","0.096"],["64029.40","2.555"],["64029.50","0.002"],["64029.80","0.000"],["64029.90","0.000"],["64030.00","1.002"],["64030.10","0.001"],["64030.40","0.097"],["64031.00","0.314"],["64031.10","0.001"],["64031.30","0.000"],["64031.60","0.003"],["64031.70","0.349"],["64031.80","0.002"],["64031.90","0.001"],["64032.00","0.686"],["64032.10","2.340"],["64032.20","0.005"],["64032.30","0.003"],["64032.40","2.619"],["64032.50","1.632"],["64033.00","0.002"],["64033.20","0.006"],["64033.40","0.002"],["64033.50","0.000"],["64033.60","0.937"],["64033.70","0.479"],["64034.00","0.004"],["64034.30","0.001"],["64034.70","0.005"],["64034.90","0.554"],["64035.00","2.754"],["64035.20","0.005"],["64035.30","0.002"],["64035.40","0.002"],["64035.50","0.002"],["64036.00","0.254"],["64036.20","1.252"],["64036.30","2.501"],["64036.40","0.041"],["64036.60","0.002"],["64036.70","0.000"],["64036.80","0.485"],["64037.10","0.002"],["64037.20","0.000"],["64037.40","0.082"],["64037.50","0.161"],["64037.60","0.250"],["64038.00","0.663"],["64038.20","0.002"],["64038.30","0.000"],["64038.60","0.235"],["64038.70","0.001"],["64038.90","0.014"],["64039.20","0.379"],["64039.30","0.422"],["64039.50","0.158"],["64039.60","0.001"],["64039.80","1.039"],["64040.00","0.435"],["64040.20","0.292"],["64040.30","1.912"],["64040.40","0.006"],["64040.60","0.001"],["64041.40","0.004"],["64041.60","0.319"],["64041.70","2.586"],["64041.80","1.286"],["64041.90","0.004"],["64042.00","0.001"],["64042.10","0.387"],["64042.30","0.126"],["64042.70","0.003"],["64043.00","1.307"],["64043.20","0.169"],["64043.40","0.289"],["64043.50","0.149"],["64043.90","0.002"],["64044.70","2.499"],["64045.10","0.345"],["64045.90","0.000"],["64046.30","0.000"],["64046.70","0.049"],["64047.50","3.394"],["64048.20","1.758"],["64048.30","0.538"],["64048.40","0.000"],["64048.90","1.068"],["64049.50","0.316"],["64049.60","0.000"],["64050.00","0.006"],["64050.80","0.004"],["64051.50","10.346"],["64051.80","0.002"],["64052.30","0.001"],["64052.80","0.170"],["64053.40","0.609"],["64054.60","0.002"],["64055.00","4.975"],["64055.90","0.043"],["64057.40","0.087"],["64057.50","0.137"],["64057.70","0.001"],["64058.10","0.058"],["64058.20","1.321"],["64058.30","1.096"],["64059.00","0.000"],["64059.60","0.091"],["64059.70","0.196"],["64060.00","2.427"],["64061.10","0.038"],["64061.50","0.550"],["64061.80","0.001"],["64061.90","0.003"],["64062.40","0.041"],["64062.90","0.483"],["64064.40","0.054"],["64064.50","0.003"],["64064.60","0.136"],["64064.80","0.121"],["64065.00","0.001"],["64065.10","0.106"],["64065.50","0.000"],["64066.10","0.547"],["64066.50","0.001"],["64067.10","0.006"],["64067.50","0.020"],["64067.80","0.003"],["64069.30","0.343"],["64069.40","0.026"],["64070.20","0.001"],["64070.50","0.004"],["64071.50","0.001"],["64071.60","0.141"],["64071.70","0.661"],["64071.80","0.173"],["64071.90","0.011"],["64072.00","0.300"],["64072.10","0.047"],["64072.20","0.158"],["64072.40","0.001"],["64072.70","0.103"],["64073.90","0.079"],["64074.70","8.698"],["64075.30","0.000"],["64075.90","0.000"],["64076.50","0.001"],["64077.10","0.541"],["64077.30","0.033"],["64077.70","0.002"],["64078.30","0.001"],["64078.60","0.005"],["64079.20","0.000"],["64079.50","0.314"],["64080.10","0.001"],["64080.30","0.004"],["64082.00","0.026"],["64083.70","0.002"],["64084.30","0.000"],["64085.50","0.048"],["64087.00","0.004"],["64087.10","1.207"],["64087.30","0.376"],["64087.40","0.000"],["64087.50","1.079"],["64088.10","0.040"],["64089.10","0.018"],["64090.80","1.913"],["64091.50","0.001"],["64092.10","0.000"],["64092.20","0.104"],["64093.30","0.946"],["64093.40","0.387"],["64093.60","0.001"],["64093.70","0.004"],["64093.80","0.001"],["64093.90","0.029"],["64094.00","0.519"],["64098.30","0.106"],["64099.50","0.101"],["64100.30","0.138"],["64102.60","1.234"],["64102.70","0.002"],["64105.90","0.081"],["64108.50","0.013"],["64108.90","3.290"],["64109.90","0.031"],["64111.60","0.000"],["64111.80","0.003"],["64112.30","0.466"],["64112.40","1.445"],["64116.70","0.001"],["64118.40","3.152"],["64119.50","0.028"],["64123.20","0.001"],["64127.80","0.002"],["64130.50","0.009"],["64132.60","0.006"],["64140.20","0.008"],["64158.50","2.356"],["64169.90","0.502"],["64180.20","0.121"],["64192.30","1.020"],["64193.70","0.040"],["64200.00","2.773"],["64211.50","0.001"],["64212.50","0.000"],["64214.70","1.027"],["64234.00","0.109"],["64242.70","0.000"],["64253.00","0.065"],["64262.40","0.018"],["64262.80","0.117"],["64268.60","0.006"],["64268.70","0.002"],["64268.80","0.438"],["64276.90","0.000"],["64304.00","0.014"],["64307.30","0.183"],["64309.80","0.003"],["64349.20","0.466"],["64350.70","0.109"],["64365.30","0.000"],["64445.30","0.000"],["64466.90","0.000"],["64669.40","0.002"],["64691.10","0.000"],["64781.00","0.998"],["64781.60","1.865"],["64783.90","1.838"],["64796.50","12.252"],["64801.10","1.539"],["64834.80","0.000"],["64847.90","0.784"],["64850.20","0.002"],["64929.20","3.358"],["64933.00","3.116"],["64958.50","23.405"],["64971.40","9.240"],["65025.20","1.112"],["65035.50","5.720"],["65054.60","9.585"],["65220.50","1.334"],["65309.60","0.054"],["65317.30","0.002"]],"b":[["13559.50","0.658"],["13629.00","0.168"],["13759.50","0.868"],["13829.00","0.168"],["13929.00","0.182"],["13959.50","0.504"],["57626.10","0.070"],["63093.60","0.000"],["63100.80","3.579"],["63134.10","0.007"],["63164.80","2.194"],["63198.10","0.000"],["63291.20","34.422"],["63312.80","2.365"],["63388.70","0.002"],["63529.60","0.401"],["63675.10","0.984"],["63708.80","0.309"],["63712.10","0.240"],["63830.50","0.491"],["63849.90","0.014"],["63853.10","0.001"],["63856.10","0.001"],["63859.30","0.499"],["63871.30","0.248"],["63886.30","0.000"],["63907.60","0.001"],["63914.30","0.003"],["63918.20","11.710"],["63918.90","0.065"],["63919.60","2.294"],["63922.30","0.003"],["63922.40","0.002"],["63923.20","0.027"],["63925.50","0.000"],["63926.20","1.443"],["63930.40","0.000"],["63934.40","0.001"],["63935.90","3.634"],["63939.50","0.002"],["63940.90","0.496"],["63941.00","4.531"],["63945.30","0.000"],["63945.40","4.848"],["63945.80","0.004"],["63946.20","2.351"],["63947.40","0.003"],["63947.50","21.266"],["63948.00","0.002"],["63949.00","0.011"],["63949.10","0.000"],["63949.50","0.000"],["63950.00","0.273"],["63951.00","0.013"],["63952.00","0.707"],["63954.00","0.491"],["63956.00","0.001"],["63957.70","0.000"],["63958.00","0.001"],["63958.70","0.027"],["63959.00","0.000"],["63959.80","0.314"],["63960.00","1.716"],["63961.30","0.414"],["63962.00","0.003"],["63962.20","0.031"],["63962.30","10.946"],["63964.00","0.008"],["63965.10","0.237"],["63966.00","2.368"],["63966.60","0.628"],["63967.20","0.061"],["63967.50","0.000"],["63968.00","0.539"],["63969.60","0.065"],["63970.00","0.485"],["63970.10","0.066"],["63970.90","0.036"],["63971.40","0.058"],["63971.60","1.837"],["63972.00","0.004"],["63973.50","0.026"],["63974.00","0.001"],["63975.70","0.200"],["63976.00","0.001"],["63977.30","0.320"],["63977.80","0.861"],["63979.00","0.025"],["63979.10","0.000"],["63981.30","0.313"],["63981.50","0.622"],["63981.70","0.011"],["63983.40","0.003"],["63983.70","0.002"],["63983.80","0.027"],["63984.20","0.047"],["63985.60","1.103"],["63985.80","0.015"],["63987.30","0.383"],["63987.60","0.001"],["63988.50","0.117"],["63990.20","1.862"],["63990.60","0.424"],["63990.80","0.066"],["63990.90","0.000"],["63991.00","0.453"],["63991.20","0.001"],["63991.30","0.000"],["63991.40","0.005"],["63992.10","2.344"],["63992.30","0.008"],["63992.70","0.000"],["63992.80","0.153"],["63993.50","1.414"],["63993.80","0.048"],["63994.30","0.080"],["63994.80","0.808"],["63995.10","0.514"],["63995.20","0.021"],["63996.50","1.802"],["63996.90","0.353"],["63997.00","0.001"],["63997.30","0.326"],["63997.40","0.019"],["63997.70","0.118"],["63997.80","0.011"],["63998.00","0.023"],["63998.60","0.000"],["63998.80","0.547"],["63999.00","0.919"],["63999.40","0.609"],["63999.60","0.001"],["63999.90","0.819"],["64000.20","0.013"],["64000.50","0.000"],["64001.40","0.071"],["64002.00","0.101"],["64002.80","0.022"],["64002.90","0.001"],["64003.30","0.403"],["64004.40","0.358"],["64004.50","0.050"],["64004.60","0.003"],["64004.70","0.711"],["64005.20","0.047"],["64005.40","2.342"],["64005.50","0.099"],["64006.20","0.123"],["64006.60","0.013"],["64006.70","0.001"],["64006.80","0.093"],["64006.90","0.012"],["64007.00","0.184"],["64007.20","0.570"],["64007.40","0.072"],["64007.70","0.291"],["64007.80","0.021"],["64008.00","2.410"],["64008.10","0.001"],["64008.60","0.032"],["64008.80","0.001"],["64008.90","0.005"],["64009.30","0.106"],["64009.50","0.532"],["64009.80","0.001"],["64009.90","0.258"],["64010.00","0.624"],["64010.10","0.320"],["64010.50","0.000"],["64010.70","0.002"],["64011.00","2.451"],["64011.10","0.164"],["64011.20","0.002"],["64011.50","1.108"],["64011.70","0.000"],["64011.80","0.002"],["64012.00","0.049"],["64012.20","0.000"],["64012.60","1.176"],["64012.70","0.064"],["64012.80","0.303"],["64012.90","0.001"],["64013.20","0.071"],["64013.40","0.001"],["64013.60","2.449"],["64013.90","0.001"],["64014.00","0.199"],["64014.20","1.010"],["64015.20","0.027"],["64015.40","0.903"],["64015.50","1.250"],["64016.10","0.154"],["64016.20","0.041"],["64016.30","2.910"],["64016.40","0.081"],["64016.50","0.122"],["64016.60","0.003"],["64016.70","0.001"],["64017.40","0.062"],["64018.40","0.001"],["64018.70","0.014"],["64019.10","0.530"],["64019.20","0.849"],["64019.40","0.929"],["64019.50","0.036"],["64020.00","0.015"],["64020.60","0.155"],["64020.70","0.060"],["64020.80","0.102"],["64021.20","0.001"],["64021.40","0.004"],["64022.00","0.004"],["64022.10","0.469"],["64022.30","0.002"],["64023.00","0.884"],["64023.10","0.003"],["64023.40","0.002"],["64024.00","0.196"],["64025.70","0.001"],["64026.10","0.009"],["64026.30","0.007"],["64027.50","0.003"],["64028.90","0.006"],["64029.00","2.361"]],"e":"depthUpdate","ps":"BTCUSDT","pu":11165395911871,"s":"BTCUSDT","st":1,"u":11165395927554}
{"E":1785353528510,"T":1785353528509,"U":11165395927620,"a":[["64029.10","0.000"],["64029.20","0.000"],["64029.30","0.000"],["64029.40","0.128"],["64029.50","0.001"],["64029.60","0.000"],["64029.90","0.000"],["64030.00","0.002"],["64030.10","0.000"],["64030.20","0.000"],["64030.40","0.000"],["64030.80","0.000"],["64030.90","0.000"],["64031.00","0.001"],["64031.40","0.001"],["64031.50","0.013"],["64031.60","0.002"],["64031.70","0.136"],["64031.80","0.002"],["64031.90","0.002"],["64032.00","0.005"],["64032.10","0.000"],["64032.20","0.005"],["64032.30","0.003"],["64032.40","0.002"],["64032.50","0.004"],["64032.60","0.003"],["64033.00","0.002"],["64033.10","0.000"],["64033.20","0.029"],["64033.30","0.002"],["64033.40","0.002"],["64033.60","0.002"],["64033.70","0.002"],["64033.90","0.001"],["64034.10","0.001"],["64034.20","0.135"],["64034.50","0.001"],["64034.70","0.002"],["64034.80","0.002"],["64034.90","0.007"],["64035.00","0.007"],["64035.10","0.002"],["64035.40","0.003"],["64035.50","0.014"],["64035.60","0.001"],["64035.70","0.048"],["64036.00","0.255"],["64036.20","0.294"],["64036.30","0.003"],["64036.40","0.001"],["64036.50","0.001"],["64036.60","0.097"],["64036.80","0.060"],["64037.20","0.001"],["64037.30","0.001"],["64037.40","0.000"],["64037.50","0.318"],["64037.60","0.264"],["64037.70","0.001"],["64037.90","0.000"],["64038.00","0.163"],["64038.10","0.000"],["64038.50","1.001"],["64038.60","0.001"],["64038.90","0.002"],["64039.00","0.002"],["64039.10","0.548"],["64039.20","0.377"],["64039.30","0.328"],["64039.40","0.000"],["64039.60","0.126"],["64039.70","0.779"],["64039.80","0.548"],["64039.90","0.000"],["64040.10","0.937"],["64040.20","0.000"],["64040.50","0.000"],["64040.90","0.000"],["64041.20","0.001"],["64041.40","0.097"],["64041.50","0.070"],["64041.60","3.688"],["64041.70","2.729"],["64041.80","0.100"],["64041.90","0.004"],["64042.00","0.002"],["64042.10","0.014"],["64042.20","0.005"],["64042.30","0.107"],["64042.40","0.003"],["64042.70","0.003"],["64042.80","0.168"],["64042.90","0.065"],["64043.00","0.000"],["64043.30","0.168"],["64043.50","0.287"],["64043.70","0.766"],["64043.80","0.464"],["64044.20","0.385"],["64044.40","2.340"],["64044.60","0.001"],["64044.70","0.003"],["64045.10","0.001"],["64045.50","0.000"],["64046.00","0.121"],["64046.20","0.169"],["64046.40","0.345"],["64046.50","1.446"],["64046.80","0.468"],["64046.90","0.010"],["64047.00","2.340"],["64047.10","0.071"],["64047.40","1.437"],["64047.50","1.054"],["64048.10","0.911"],["64048.20","1.309"],["64048.40","0.001"],["64048.80","0.292"],["64049.40","0.002"],["64049.90","0.001"],["64050.00","0.084"],["64050.10","0.299"],["64050.40","0.049"],["64050.50","2.633"],["64050.60","0.523"],["64050.70","0.971"],["64051.10","1.813"],["64051.40","2.677"],["64051.50","0.002"],["64051.60","0.003"],["64051.90","1.031"],["64052.30","1.158"],["64052.50","0.030"],["64052.80","0.013"],["64053.20","0.094"],["64053.30","2.538"],["64053.90","0.390"],["64054.70","1.589"],["64054.80","0.055"],["64055.00","5.507"],["64055.60","0.337"],["64055.70","0.001"],["64055.80","0.020"],["64056.30","0.080"],["64056.40","2.998"],["64056.70","1.158"],["64057.40","0.086"],["64057.70","0.000"],["64057.90","0.152"],["64058.10","0.008"],["64058.60","0.097"],["64058.80","0.001"],["64059.10","0.001"],["64059.30","0.312"],["64059.50","0.072"],["64059.60","0.084"],["64059.70","0.196"],["64060.00","2.425"],["64060.20","0.000"],["64060.30","0.216"],["64060.40","0.156"],["64060.70","0.004"],["64061.00","0.600"],["64061.10","0.007"],["64061.20","0.034"],["64061.50","0.544"],["64062.50","0.004"],["64062.60","0.059"],["64062.70","1.752"],["64062.90","0.400"],["64063.60","0.000"],["64063.70","0.000"],["64063.80","0.270"],["64064.00","0.052"],["64064.30","0.719"],["64064.40","0.005"],["64064.50","0.003"],["64064.70","0.697"],["64064.80","0.005"],["64065.10","0.016"],["64065.70","0.314"],["64068.40","3.325"],["64068.70","0.008"],["64069.00","0.000"],["64070.10","0.409"],["64071.40","0.051"],["64071.60","0.081"],["64071.70","0.781"],["64071.90","0.046"],["64072.20","0.004"],["64072.30","0.525"],["64073.50","0.635"],["64074.00","0.002"],["64074.70","8.724"],["64074.80","10.000"],["64074.90","0.978"],["64075.90","0.000"],["64076.00","0.001"],["64077.30","0.031"],["64078.00","0.501"],["64078.30","0.061"],["64078.60","0.003"],["64079.90","0.376"],["64081.10","0.000"],["64081.20","2.347"],["64082.00","0.001"],["64082.10","0.027"],["64082.40","0.000"],["64084.30","0.023"],["64084.90","0.090"],["64089.70","0.315"],["64090.80","0.868"],["64091.30","0.025"],["64091.90","0.525"],["64093.10","0.103"],["64093.90","2.864"],["64094.90","0.391"],["64095.60","0.684"],["64102.30","0.216"],["64103.60","0.501"],["64104.20","0.015"],["64106.00","0.348"],["64108.10","0.097"],["64108.40","0.001"],["64108.50","0.000"],["64110.60","1.981"],["64110.90","0.004"],["64112.50","0.003"],["64112.80","0.000"],["64113.60","2.345"],["64115.30","0.000"],["64117.00","0.063"],["64120.90","0.000"],["64123.40","0.064"],["64129.20","0.504"],["64135.70","0.009"],["64136.40","0.014"],["64137.80","2.041"],["64140.40","0.012"],["64140.70","4.684"],["64151.40","0.781"],["64152.50","3.907"],["64154.70","0.500"],["64162.20","0.497"],["64169.10","0.246"],["64171.10","0.015"],["64173.10","0.933"],["64175.10","0.503"],["64177.10","0.794"],["64179.10","0.000"],["64179.20","1.136"],["64181.10","0.000"],["64183.10","0.003"],["64185.10","0.008"],["64186.00","0.027"],["64186.50","0.004"],["64187.10","0.063"],["64187.50","0.001"],["64188.80","0.533"],["64189.10","0.382"],["64192.30","0.981"],["64194.00","0.070"],["64220.90","0.976"],["64222.20","0.077"],["64266.00","0.635"],["64669.40","0.000"],["64687.10","1.637"],["64711.60","0.841"],["64734.20","0.926"],["64864.60","1.071"],["64928.80","12.274"],["64960.70","1.990"],["64988.50","2.690"],["65052.50","2.154"],["65056.70","1.842"],["65099.50","0.006"]],"b":[["13559.50","0.546"],["13629.00","0.294"],["13759.50","0.742"],["13829.00","0.294"],["13929.00","0.294"],["13959.50","0.378"],["57626.10","0.070"],["61467.80","0.000"],["63051.30","0.011"],["63167.20","0.001"],["63226.20","0.790"],["63260.70","1.212"],["63388.70","0.000"],["63388.80","0.104"],["63406.10","0.030"],["63516.80","0.192"],["63600.00","19.547"],["63620.00","0.698"],["63704.30","0.000"],["63708.90","1.125"],["63729.30","0.001"],["63827.60","0.000"],["63830.50","0.374"],["63846.50","0.119"],["63849.90","0.013"],["63867.10","0.098"],["63886.70","0.000"],["63887.30","4.711"],["63887.40","1.487"],["63887.90","0.000"],["63896.80","0.020"],["63903.30","0.500"],["63904.00","0.020"],["63913.50","0.001"],["63920.90","2.743"],["63923.10","3.508"],["63928.90","0.500"],["63934.10","2.878"],["63935.80","0.002"],["63936.00","2.369"],["63937.20","0.034"],["63939.10","0.000"],["63943.40","2.564"],["63944.80","0.001"],["63944.90","0.000"],["63945.30","20.756"],["63945.40","4.325"],["63947.50","0.510"],["63948.70","1.139"],["63949.10","0.000"],["63951.00","0.010"],["63951.90","0.371"],["63952.00","0.707"],["63954.50","0.985"],["63959.40","0.002"],["63960.00","3.278"],["63961.10","0.006"],["63961.40","0.060"],["63961.50","1.403"],["63961.90","0.060"],["63962.20","0.031"],["63964.90","0.032"],["63965.00","0.047"],["63965.10","0.027"],["63965.20","1.754"],["63966.60","0.957"],["63967.30","0.005"],["63968.10","0.029"],["63970.10","0.129"],["63971.40","0.083"],["63972.60","0.000"],["63972.80","0.210"],["63973.70","0.001"],["63975.00","0.100"],["63975.10","0.291"],["63975.20","0.004"],["63975.40","0.000"],["63977.60","0.000"],["63977.70","0.003"],["63977.80","0.851"],["63978.00","2.346"],["63978.90","0.059"],["63979.70","0.001"],["63980.10","0.478"],["63980.20","0.712"],["63981.60","2.348"],["63983.70","0.081"],["63984.90","0.048"],["63985.20","3.242"],["63985.40","0.048"],["63986.50","0.002"],["63988.30","0.002"],["63988.50","0.027"],["63989.60","0.004"],["63989.70","0.000"],["63989.90","0.072"],["63990.20","1.389"],["63990.30","0.126"],["63990.40","0.038"],["63990.60","0.449"],["63992.60","0.001"],["63992.80","0.033"],["63992.90","0.002"],["63993.50","1.122"],["63994.90","0.000"],["63995.30","0.922"],["63996.00","0.007"],["63996.40","0.000"],["63996.90","0.158"],["63997.40","0.017"],["63997.70","2.073"],["63998.10","0.004"],["63998.90","0.001"],["63999.40","0.569"],["63999.80","0.314"],["63999.90","0.818"],["64001.40","0.001"],["64001.60","0.016"],["64001.80","0.001"],["64002.00","0.191"],["64002.10","0.118"],["64002.60","0.933"],["64003.00","0.003"],["64003.20","3.205"],["64003.30","0.169"],["64003.40","0.042"],["64003.50","0.016"],["64003.80","0.075"],["64003.90","0.532"],["64004.10","0.644"],["64004.50","0.000"],["64004.70","0.711"],["64004.90","0.001"],["64005.20","0.012"],["64005.40","3.278"],["64005.70","0.533"],["64005.90","0.142"],["64006.20","0.003"],["64006.30","0.041"],["64006.40","1.148"],["64006.60","0.013"],["64006.70","0.001"],["64006.80","0.092"],["64006.90","0.082"],["64007.00","0.184"],["64007.70","0.292"],["64008.30","0.363"],["64008.40","0.000"],["64008.50","0.015"],["64008.80","0.005"],["64008.90","0.006"],["64009.00","0.001"],["64009.30","0.057"],["64009.50","0.533"],["64009.80","0.002"],["64010.30","0.520"],["64010.70","0.002"],["64011.00","2.437"],["64011.30","0.000"],["64011.50","0.233"],["64011.70","0.058"],["64012.50","0.002"],["64012.60","1.226"],["64012.80","0.069"],["64013.10","0.217"],["64013.30","0.001"],["64013.50","0.000"],["64013.60","2.343"],["64013.70","0.657"],["64014.00","0.008"],["64014.20","0.002"],["64014.40","0.047"],["64014.60","0.002"],["64014.90","0.297"],["64015.20","0.007"],["64015.30","0.002"],["64015.40","0.901"],["64015.50","1.250"],["64015.70","0.049"],["64016.00","0.009"],["64016.10","0.376"],["64016.20","0.002"],["64016.30","2.343"],["64016.40","0.410"],["64016.50","0.730"],["64016.60","0.003"],["64017.20","10.025"],["64017.30","0.039"],["64017.40","0.058"],["64017.60","0.004"],["64017.70","0.215"],["64018.20","0.017"],["64018.50","0.004"],["64018.70","0.002"],["64019.20","2.287"],["64019.30","2.433"],["64019.40","0.171"],["64019.50","0.038"],["64019.60","0.708"],["64019.70","0.001"],["64020.10","0.022"],["64020.20","0.432"],["64020.30","0.083"],["64020.40","0.001"],["64020.50","0.061"],["64020.60","0.215"],["64021.10","0.060"],["64021.30","0.068"],["64021.40","0.004"],["64021.50","1.073"],["64021.60","0.033"],["64022.10","1.097"],["64022.20","3.600"],["64022.40","0.394"],["64022.50","0.221"],["64022.90","0.001"],["64023.10","0.507"],["64023.40","0.003"],["64023.60","0.337"],["64023.80","0.095"],["64024.00","0.010"],["64024.20","0.001"],["64024.40","0.048"],["64025.00","0.802"],["64025.10","2.341"],["64025.20","1.238"],["64025.50","0.098"],["64025.70","0.384"],["64025.80","0.004"],["64025.90","0.004"],["64026.70","0.061"],["64027.00","0.884"],["64027.10","0.137"],["64027.60","0.094"],["64028.10","0.002"],["64028.40","0.012"],["64029.00","11.069"],["64029.10","13.125"],["64029.20","0.415"],["64029.30","14.606"]],"e":"depthUpdate","ps":"BTCUSDT","pu":11165395927554,"s":"BTCUSDT","st":1,"u":11165395957597}
