{"E":1785353514842,"T":1785353514840,"U":11165393541974,"a":[["64041.80","3.220"],["64044.40","0.007"],["64052.00","0.137"],["64052.40","0.610"],["64054.60","1.187"],["64063.80","1.353"],["64070.20","0.313"],["64076.60","0.164"],["64099.50","0.004"],["64132.10","23.521"],["64134.30","0.482"],["64224.30","0.000"],["64224.50","0.030"],["64236.50","1.117"],["64362.10","0.000"],["64541.30","0.316"],["64643.80","0.617"],["64682.20","0.000"],["65322.60","0.156"]],"b":[["1000.00","37.592"],["13541.70","0.896"],["13641.70","1.092"],["13741.70","0.112"],["13841.70","1.288"],["13941.70","0.812"],["51233.40","0.000"],["57637.50","0.052"],["63401.30","0.874"],["63936.10","0.000"],["63936.40","0.003"],["63964.80","0.890"],["63971.20","0.000"],["63974.40","0.025"],["63984.00","0.013"],["64007.30","0.047"],["64013.70","0.000"],["64020.10","0.313"],["64031.50","0.001"],["64032.30","0.161"],["64035.20","0.460"],["64038.40","0.019"],["64040.40","0.002"],["64041.70","8.940"]],"e":"depthUpdate","ps":"BTCUSDT","pu":11165393541811,"s":"BTCUSDT","st":1,"u":11165393550671}
{"E":1785353514944,"T":1785353514943,"U":11165393550921,"a":[["64041.80","4.485"],["64041.90","0.661"],["64042.80","0.010"],["64045.30","0.040"],["64050.80","0.154"],["64051.20","1.708"],["64052.70","0.000"],["64072.10","0.120"],["64072.20","0.017"],["64073.70","0.003"],["64076.10","0.001"],["64076.70","10.002"],["64081.40","0.000"],["64089.00","0.094"],["64093.10","0.040"],["64095.60","0.684"],["64126.40","0.013"],["64128.90","0.004"],["64132.10","0.000"],["64145.30","23.521"],["64164.00","0.037"],["64682.20","0.000"],["64810.30","6.236"],["64830.30","21.763"],["64838.60","0.000"],["64874.30","0.539"]],"b":[["13541.70","0.910"],["13641.70","0.966"],["13741.70","0.224"],["13841.70","1.176"],["13941.70","0.924"],["57637.50","0.052"],["60839.60","0.010"],["61480.00","0.222"],["63281.00","2.660"],["63401.30","0.876"],["63721.40","0.001"],["63893.70","1.016"],["63895.70","0.002"],["63897.70","0.091"],["63899.70","0.000"],["63901.70","0.000"],["63903.70","0.885"],["63905.70","24.531"],["63907.70","0.000"],["63909.70","0.889"],["63943.80","0.067"],["63945.40","2.714"],["63980.70","0.029"],["63985.30","2.743"],["63990.90","0.025"],["64016.10","0.462"],["64023.20","2.000"],["64024.40","0.361"],["64029.30","0.002"],["64033.10","0.012"],["64036.50","0.021"],["64039.30","0.000"],["64039.40","0.011"],["64039.60","0.003"],["64039.80","0.234"],["64040.30","0.001"],["64041.70","8.940"]],"e":"depthUpdate","ps":"BTCUSDT","pu":11165393550671,"s":"BTCUSDT","st":1,"u":11165393566438}
{"E":1785353515046,"T":1785353515044,"U":11165393566581,"a":[["64041.80","4.485"],["64042.80","0.037"],["64044.00","0.003"],["64044.40","0.007"],["64045.00","0.001"],["64045.30","0.020"],["64045.70","0.002"],["64046.10","0.016"],["64047.60","0.009"],["64048.40","0.001"],["64049.50","0.001"],["64049.80","0.005"],["64050.40","0.005"],["64050.80","0.174"],["64052.00","0.002"],["64053.30","0.020"],["64053.60","0.003"],["64054.60","1.407"],["64054.70","0.493"],["64055.90","0.007"],["64056.80","0.296"],["64063.90","0.127"],["64067.40","0.478"],["64067.50","0.670"],["64069.80","4.331"],["64070.30","0.005"],["64070.80","0.023"],["64078.20","0.004"],["64080.60","0.000"],["64089.00","0.090"],["64110.50","0.089"],["64185.80","0.884"],["64187.80","0.898"],["64189.80","0.885"],["64191.80","0.884"],["64193.80","0.895"],["64236.50","1.252"],["64333.10","5.657"],["64334.40","35.002"],["64362.10","0.001"],["64515.70","0.288"],["64541.30","0.000"],["64682.20","0.000"],["64810.30","6.698"],["64830.30","20.236"],["64844.10","0.000"],["64940.90","0.769"],["65322.60","0.150"],["66539.40","1.277"]],"b":[["1000.00","37.592"],["13541.70","0.896"],["13641.70","0.854"],["13741.70","0.350"],["13841.70","1.050"],["13941.70","1.050"],["57637.50","0.052"],["60839.60","0.008"],["60839.70","0.008"],["61480.00","0.219"],["63401.30","0.874"],["63721.50","0.201"],["63918.00","2.340"],["63964.80","0.893"],["64005.70","0.005"],["64017.30","0.532"],["64022.30","1.698"],["64023.50","0.280"],["64030.10","0.143"],["64030.20","0.068"],["64030.40","0.330"],["64036.50","0.001"],["64037.10","0.000"],["64037.70","0.863"],["64039.40","0.001"],["64039.60","0.013"],["64039.70","0.004"],["64039.90","0.009"],["64040.10","0.000"],["64041.30","0.003"],["64041.40","0.001"],["64041.70","9.593"]],"e":"depthUpdate","ps":"BTCUSDT","pu":11165393566438,"s":"BTCUSDT","st":1,"u":11165393576392}
{"E":1785353515148,"T":1785353515144,"U":11165393576775,"a":[["64041.80","4.482"],["64042.80","0.037"],["64049.50","0.136"],["64053.30","0.015"],["64055.80","0.477"],["64056.20","0.022"],["64057.20","0.295"],["64063.90","0.125"],["64065.30","0.023"],["64070.80","0.023"],["64071.30","0.002"],["64072.90","1.054"],["64077.70","0.001"],["64077.80","0.008"],["64078.30","9.325"],["64078.60","0.159"],["64081.50","0.977"],["64081.60","0.611"],["64134.30","23.998"],["64145.30","0.000"],["64185.80","0.000"],["64187.80","0.014"],["64189.80","0.001"],["64191.80","0.000"],["64193.80","0.011"],["64233.90","0.100"],["64515.70","0.192"],["64578.20","0.000"],["64682.20","0.000"],["65054.60","11.715"]],"b":[["1000.00","37.592"],["13541.70","0.910"],["13641.70","0.728"],["13741.70","0.462"],["13841.70","0.938"],["13941.70","1.162"],["57637.50","0.052"],["60840.70","0.040"],["61480.00","0.222"],["63082.20","22.686"],["63214.00","1.027"],["63224.70","0.789"],["63401.30","0.874"],["63561.40","0.184"],["63670.30","0.000"],["63683.10","0.398"],["63836.50","0.000"],["63849.60","0.001"],["63895.70","0.002"],["63897.70","0.091"],["63899.70","0.000"],["63901.70","0.000"],["63903.70","0.885"],["63905.70","24.531"],["63907.70","0.000"],["63909.70","0.889"],["63911.70","0.003"],["63913.70","3.590"],["63915.70","0.885"],["63917.70","0.888"],["63919.70","0.887"],["63921.70","0.986"],["63923.70","0.884"],["63987.80","0.000"],["63987.90","4.227"],["63998.70","0.047"],["63999.00","0.911"],["64003.60","0.000"],["64003.70","0.532"],["64008.10","0.360"],["64012.60","0.895"],["64014.70","0.001"],["64017.30","0.516"],["64019.30","0.015"],["64020.00","0.025"],["64023.60","0.002"],["64030.10","0.143"],["64030.20","0.063"],["64030.40","0.314"],["64036.50","0.001"],["64039.00","0.001"],["64039.10","0.011"],["64039.40","0.257"],["64039.50","0.432"],["64039.60","0.011"],["64039.80","0.000"],["64039.90","0.001"],["64040.10","0.001"],["64040.30","0.001"],["64040.40","0.001"],["64040.80","0.018"],["64041.00","0.001"],["64041.30","0.000"],["64041.40","0.000"],["64041.50","0.000"],["64041.60","0.004"],["64041.70","9.589"]],"e":"depthUpdate","ps":"BTCUSDT","pu":11165393576392,"s":"BTCUSDT","st":1,"u":11165393586883}
{"E":1785353515250,"T":1785353515248,"U":11165393587122,"a":[["64043.70","0.023"],["64043.80","0.001"],["64044.40","0.007"],["64054.00","0.005"],["64054.40","0.084"],["64073.80","0.260"],["64075.80","0.001"],["64076.70","0.002"],["64095.60","0.696"],["64096.90","0.073"],["64128.90","0.016"],["64132.10","23.516"],["64134.30","0.482"],["64320.40","0.117"],["64342.80","0.030"],["64515.70","0.288"],["64522.00","0.000"],["64682.20","0.000"],["64810.30","12.861"],["64837.20","0.000"]],"b":[["13541.70","0.896"],["13641.70","0.616"],["13741.70","0.588"],["13841.70","0.812"],["13941.70","1.288"],["57637.50","0.052"],["60839.70","0.006"],["61480.00","0.219"],["63220.00","1.316"],["63241.20","1.765"],["63401.30","0.386"],["63703.70","0.002"],["63704.00","0.478"],["63750.00","5.194"],["63849.60","0.118"],["63852.80","0.017"],["63915.70","0.001"],["63917.70","0.004"],["63919.70","0.003"],["63923.70","0.000"],["63947.50","0.510"],["63982.10","0.037"],["63985.30","2.719"],["63990.90","0.000"],["64012.60","0.875"],["64014.00","0.541"],["64019.30","0.035"],["64019.40","0.030"],["64020.80","1.185"],["64022.60","11.253"],["64023.20","0.000"],["64035.00","0.002"],["64039.20","0.023"],["64039.40","0.001"],["64039.80","0.234"],["64041.30","0.001"],["64041.60","0.003"],["64041.70","9.808"]],"e":"depthUpdate","ps":"BTCUSDT","pu":11165393586883,"s":"BTCUSDT","st":1,"u":11165393594620}
{"E":1785353515352,"T":1785353515348,"U":11165393594843,"a":[["64041.80","4.482"],["64041.90","0.762"],["64042.80","0.008"],["64043.70","0.001"],["64043.80","0.023"],["64049.50","0.001"],["64051.40","0.096"],["64053.00","0.005"],["64054.40","0.006"],["64056.90","0.198"],["64057.20","0.430"],["64065.30","0.003"],["64065.50","0.007"],["64068.70","0.021"],["64081.50","10.977"],["64095.60","0.684"],["64128.90","0.004"],["64130.00","0.002"],["64132.10","0.000"],["64145.30","23.516"],["64515.70","0.192"],["64682.20","0.000"]],"b":[["1000.00","37.592"],["13541.70","0.910"],["13641.70","0.490"],["13741.70","0.700"],["13841.70","0.700"],["13941.70","1.400"],["51233.00","0.000"],["57637.50","0.052"],["63401.30","0.386"],["63721.50","0.211"],["63917.70","0.888"],["63919.70","0.887"],["63945.30","22.428"],["64000.00","10.993"],["64008.10","0.082"],["64022.60","1.253"],["64023.10","0.372"],["64024.10","10.002"],["64029.80","0.180"],["64040.00","0.041"],["64041.20","0.114"],["64041.70","9.814"]],"e":"depthUpdate","ps":"BTCUSDT","pu":11165393594620,"s":"BTCUSDT","st":1,"u":11165393601673}
{"E":1785353515454,"T":1785353515452,"U":11165393601848,"a":[["64041.80","2.401"],["64043.50","0.004"],["64043.80","0.001"],["64044.20","0.010"],["64044.40","0.007"],["64046.10","0.002"],["64047.10","0.005"],["64047.60","0.007"],["64048.00","0.031"],["64048.20","0.425"],["64048.30","0.027"],["64048.70","0.000"],["64048.80","0.015"],["64050.60","0.002"],["64050.80","0.134"],["64050.90","0.000"],["64051.00","0.051"],["64051.20","0.708"],["64051.30","0.431"],["64051.40","0.016"],["64051.70","0.002"],["64052.10","0.002"],["64052.20","1.003"],["64052.40","0.002"],["64052.50","1.097"],["64053.20","0.001"],["64053.30","0.001"],["64053.50","0.001"],["64053.80","0.011"],["64053.90","0.012"],["64054.20","0.021"],["64054.60","1.503"],["64054.70","0.494"],["64055.10","0.174"],["64055.20","0.232"],["64055.70","0.120"],["64056.20","0.006"],["64056.80","2.519"],["64056.90","0.975"],["64057.20","0.295"],["64057.70","0.001"],["64057.80","0.003"],["64058.40","1.296"],["64058.50","0.011"],["64058.70","0.430"],["64059.40","0.002"],["64059.60","2.346"],["64060.20","0.012"],["64060.40","1.137"],["64060.50","0.001"],["64061.30","1.249"],["64061.40","1.440"],["64061.50","1.132"],["64062.20","2.343"],["64063.40","0.006"],["64063.50","0.000"],["64063.60","0.739"],["64065.50","0.087"],["64065.80","0.669"],["64066.40","0.001"],["64067.00","0.115"],["64067.10","2.958"],["64067.20","0.215"],["64067.30","1.720"],["64067.40","0.388"],["64069.60","0.553"],["64070.40","0.430"],["64070.50","0.057"],["64070.80","0.015"],["64071.10","0.043"],["64071.30","0.002"],["64071.60","0.501"],["64071.80","0.009"],["64072.10","0.048"],["64073.40","0.001"],["64075.20","0.013"],["64077.20","0.000"],["64078.30","9.445"],["64078.50","0.608"],["64079.90","0.403"],["64081.50","0.979"],["64081.70","0.035"],["64085.40","0.090"],["64088.60","0.526"],["64089.00","2.090"],["64092.80","0.046"],["64093.70","0.244"],["64096.90","0.001"],["64130.20","0.097"],["64132.20","0.039"],["64134.20","0.074"],["64134.30","23.998"],["64145.30","0.000"],["64233.90","0.235"],["64490.10","9.695"],["64515.70","0.192"],["64554.10","6.059"],["64574.10","0.002"],["64682.20","0.000"],["65034.40","3.224"],["65322.60","0.150"]],"b":[["1000.00","37.592"],["13541.70","1.022"],["13641.70","0.378"],["13741.70","0.826"],["13841.70","0.700"],["13941.70","1.274"],["57637.50","0.052"],["61480.00","0.222"],["62760.90","1.060"],["63113.10","8.194"],["63148.10","0.002"],["63177.10","2.525"],["63401.30","0.386"],["63721.50","0.137"],["63727.90","0.083"],["63852.80","0.134"],["63917.70","0.004"],["63919.70","0.003"],["63921.70","0.102"],["63943.80","0.059"],["63945.30","0.000"],["63945.40","2.722"],["63950.30","1.735"],["63982.10","0.012"],["63987.90","4.203"],["63990.40","0.055"],["63990.60","0.459"],["63994.50","0.001"],["64006.50","0.573"],["64010.50","0.029"],["64014.20","0.978"],["64014.60","1.250"],["64015.60","0.000"],["64015.70","0.003"],["64017.00","1.019"],["64017.80","0.046"],["64017.90","0.012"],["64018.10","0.642"],["64018.80","0.613"],["64019.50","0.000"],["64022.20","0.454"],["64023.10","0.094"],["64023.40","0.591"],["64023.50","0.002"],["64024.10","0.004"],["64025.20","0.363"],["64025.40","0.063"],["64025.60","1.584"],["64026.10","0.000"],["64028.40","1.807"],["64028.60","0.002"],["64029.00","0.699"],["64029.20","0.000"],["64030.10","0.123"],["64030.30","0.187"],["64030.80","0.038"],["64031.80","0.016"],["64031.90","0.035"],["64032.00","0.680"],["64032.30","0.099"],["64032.50","0.000"],["64032.70","0.547"],["64032.80","0.003"],["64032.90","0.067"],["64034.10","0.004"],["64034.20","10.002"],["64035.20","2.229"],["64036.10","1.265"],["64036.20","0.001"],["64036.40","0.325"],["64036.50","0.609"],["64037.30","0.074"],["64037.40","0.313"],["64038.30","1.193"],["64038.40","0.390"],["64038.50","0.013"],["64039.10","0.001"],["64039.20","0.001"],["64039.40","0.023"],["64039.60","0.015"],["64039.80","0.000"],["64039.90","0.001"],["64040.10","0.001"],["64040.20","0.012"],["64040.60","0.000"],["64040.80","0.015"],["64041.00","0.008"],["64041.10","0.002"],["64041.20","0.165"],["64041.30","0.008"],["64041.40","0.001"],["64041.50","0.000"],["64041.70","15.780"]],"e":"depthUpdate","ps":"BTCUSDT","pu":11165393601673,"s":"BTCUSDT","st":1,"u":11165393627968}
{"E":1785353515556,"T":1785353515555,"U":11165393628320,"a":[["64041.80","0.000"],["64041.90","0.000"],["64042.00","0.000"],["64042.10","0.000"],["64042.20","0.000"],["64042.70","0.000"],["64042.80","0.000"],["64042.90","0.000"],["64043.20","0.000"],["64043.30","0.000"],["64043.40","0.000"],["64043.50","0.000"],["64043.70","0.000"],["64043.80","0.000"],["64043.90","0.000"],["64044.00","0.000"],["64044.10","0.000"],["64044.20","0.000"],["64044.30","0.000"],["64044.40","0.000"],["64044.60","0.000"],["64044.70","0.000"],["64044.80","0.000"],["64045.00","0.000"],["64045.10","0.000"],["64045.20","0.000"],["64045.30","0.000"],["64045.40","0.000"],["64045.50","0.000"],["64045.60","0.000"],["64045.70","0.000"],["64045.80","4.553"],["64045.90","0.003"],["64046.00","0.009"],["64046.10","0.000"],["64046.30","0.002"],["64046.50","0.000"],["64046.60","0.004"],["64046.80","0.003"],["64046.90","0.001"],["64047.00","0.000"],["64047.10","0.002"],["64047.40","0.000"],["64047.60","0.001"],["64048.00","0.008"],["64048.10","0.009"],["64048.20","0.004"],["64048.30","0.001"],["64048.40","0.002"],["64048.70","0.001"],["64048.80","0.000"],["64049.20","0.007"],["64049.30","0.362"],["64049.40","0.003"],["64049.60","0.140"],["64049.70","0.004"],["64050.00","0.527"],["64050.30","0.001"],["64050.40","0.006"],["64050.80","0.001"],["64051.00","0.001"],["64051.10","0.005"],["64051.20","0.724"],["64051.30","0.282"],["64051.60","0.003"],["64051.70","0.009"],["64051.80","0.001"],["64052.20","0.015"],["64052.30","0.002"],["64052.50","0.002"],["64052.60","0.115"],["64052.80","0.002"],["64053.00","0.003"],["64053.10","0.050"],["64053.30","0.011"],["64053.40","0.005"],["64053.50","0.013"],["64053.60","0.330"],["64053.70","0.183"],["64053.80","0.007"],["64053.90","0.001"],["64054.00","0.552"],["64054.10","0.004"],["64054.20","0.055"],["64054.50","0.148"],["64054.60","1.618"],["64054.70","0.259"],["64054.80","0.001"],["64054.90","0.935"],["64055.00","1.003"],["64055.20","0.210"],["64055.30","0.000"],["64055.40","0.107"],["64055.70","0.051"],["64055.80","0.477"],["64055.90","0.000"],["64056.00","0.005"],["64056.30","0.242"],["64056.40","0.100"],["64056.60","0.720"],["64056.70","1.318"],["64056.80","2.501"],["64056.90","0.740"],["64057.00","0.421"],["64057.50","0.152"],["64058.00","1.609"],["64058.10","0.004"],["64058.20","0.124"],["64058.40","1.295"],["64058.50","0.031"],["64058.60","0.115"],["64058.70","0.235"],["64058.80","0.001"],["64058.90","0.081"],["64059.20","0.315"],["64059.50","2.603"],["64059.60","0.006"],["64059.70","0.059"],["64059.90","0.313"],["64060.10","0.000"],["64060.30","0.001"],["64060.40","0.001"],["64060.60","0.612"],["64060.70","0.004"],["64060.80","0.010"],["64061.00","0.174"],["64061.30","0.562"],["64061.40","0.995"],["64061.50","0.083"],["64061.70","0.354"],["64061.80","0.319"],["64061.90","0.001"],["64062.00","0.032"],["64062.10","0.058"],["64062.20","0.339"],["64062.30","0.005"],["64062.40","0.004"],["64062.50","0.022"],["64062.70","0.002"],["64062.80","0.033"],["64062.90","0.003"],["64063.00","0.883"],["64063.10","0.254"],["64063.20","1.256"],["64063.40","0.003"],["64063.50","0.094"],["64063.60","0.740"],["64063.80","1.061"],["64063.90","0.047"],["64064.00","0.049"],["64064.20","0.783"],["64064.40","0.001"],["64064.50","0.002"],["64064.60","0.002"],["64064.90","0.380"],["64065.00","0.168"],["64065.30","0.004"],["64065.50","0.319"],["64065.70","0.004"],["64065.80","0.014"],["64065.90","0.338"],["64066.40","0.000"],["64066.50","0.656"],["64066.60","0.010"],["64066.80","0.000"],["64067.00","0.000"],["64067.10","2.995"],["64067.20","0.215"],["64067.30","1.720"],["64067.40","0.044"],["64067.50","0.495"],["64067.60","1.079"],["64067.70","0.002"],["64067.80","0.295"],["64068.00","0.411"],["64068.30","0.544"],["64068.50","0.153"],["64068.70","0.008"],["64068.80","0.081"],["64069.00","0.153"],["64069.40","0.314"],["64069.60","0.541"],["64069.70","1.876"],["64069.90","0.003"],["64070.00","0.300"],["64070.20","0.314"],["64070.30","0.005"],["64070.40","0.041"],["64070.50","0.003"],["64070.60","0.400"],["64070.70","0.157"],["64071.10","0.003"],["64071.40","0.347"],["64071.50","0.313"],["64071.60","0.001"],["64071.70","0.001"],["64071.80","0.001"],["64072.20","0.017"],["64072.60","0.026"],["64072.80","0.013"],["64073.10","0.086"],["64073.30","0.095"],["64073.40","0.001"],["64073.50","0.015"],["64073.60","0.084"],["64073.70","0.007"],["64073.80","0.260"],["64073.90","0.899"],["64074.10","2.677"],["64074.20","2.340"],["64074.50","0.228"],["64074.80","0.008"],["64074.90","0.002"],["64075.00","0.002"],["64075.10","0.002"],["64075.20","0.002"],["64075.60","0.317"],["64075.70","0.010"],["64075.90","0.515"],["64076.00","0.008"],["64076.70","0.002"],["64076.80","0.127"],["64077.00","2.724"],["64077.10","2.393"],["64077.20","0.005"],["64077.50","0.105"],["64077.60","0.104"],["64077.70","0.001"],["64077.80","0.008"],["64078.20","0.000"],["64078.30","9.325"],["64078.60","0.155"],["64078.80","0.314"],["64078.90","0.004"],["64079.00","1.292"],["64079.20","0.005"],["64079.40","0.774"],["64079.70","0.060"],["64079.90","0.385"],["64080.10","1.055"],["64080.20","0.015"],["64080.30","0.003"],["64080.40","0.447"],["64080.50","0.002"],["64080.80","0.005"],["64081.00","0.019"],["64081.10","0.000"],["64081.20","0.051"],["64081.60","0.607"],["64081.80","0.000"],["64082.40","0.018"],["64082.70","0.080"],["64082.90","1.542"],["64083.30","0.269"],["64083.80","0.002"],["64083.90","2.503"],["64084.00","0.386"],["64084.10","0.001"],["64084.20","0.280"],["64085.00","0.234"],["64085.10","0.047"],["64085.20","0.017"],["64085.30","0.000"],["64085.40","0.000"],["64085.60","1.834"],["64085.90","0.203"],["64086.20","0.287"],["64086.30","0.095"],["64086.40","0.917"],["64086.70","0.095"],["64086.80","0.001"],["64087.20","0.094"],["64087.30","0.436"],["64087.40","0.000"],["64087.50","1.052"],["64087.60","0.000"],["64088.00","0.002"],["64088.10","0.004"],["64088.20","0.001"],["64088.40","0.000"],["64088.60","0.026"],["64088.90","0.000"],["64089.00","0.160"],["64089.70","0.315"],["64089.90","0.977"],["64090.30","0.000"],["64091.00","0.004"],["64091.60","4.416"],["64092.10","0.003"],["64092.80","0.047"],["64093.50","0.000"],["64093.60","0.001"],["64093.80","0.001"],["64093.90","0.000"],["64094.10","0.500"],["64094.20","0.013"],["64094.30","0.000"],["64094.50","0.000"],["64094.60","0.001"],["64094.80","0.002"],["64094.90","0.392"],["64095.00","0.004"],["64095.10","0.055"],["64095.50","0.059"],["64095.60","0.684"],["64096.30","0.001"],["64096.70","0.009"],["64097.80","0.162"],["64098.00","0.001"],["64099.00","0.072"],["64099.10","2.100"],["64099.20","2.305"],["64099.50","0.104"],["64099.60","1.058"],["64100.00","4.639"],["64100.10","0.000"],["64100.80","0.254"],["64101.10","0.001"],["64101.20","0.011"],["64101.90","0.062"],["64103.40","0.002"],["64103.90","0.078"],["64105.70","0.028"],["64105.80","0.657"],["64110.10","12.232"],["64110.60","1.981"],["64110.90","0.395"],["64114.50","0.210"],["64118.00","0.001"],["64121.50","0.316"],["64121.80","1.708"],["64124.00","0.024"],["64126.00","0.371"],["64130.20","0.025"],["64130.40","0.077"],["64130.50","0.001"],["64131.30","0.000"],["64132.00","3.106"],["64134.20","0.002"],["64134.30","0.482"],["64141.90","0.010"],["64142.30","0.024"],["64143.70","0.041"],["64147.10","0.000"],["64147.30","0.000"],["64148.60","0.179"],["64149.00","0.004"],["64150.50","0.001"],["64157.50","0.007"],["64157.90","0.712"],["64159.90","0.000"],["64160.30","2.996"],["64164.10","0.030"],["64166.40","5.432"],["64166.70","0.002"],["64167.30","23.891"],["64168.40","0.499"],["64168.80","0.527"],["64170.90","0.500"],["64172.40","0.008"],["64176.10","2.344"],["64179.90","0.041"],["64183.90","0.541"],["64188.80","0.497"],["64193.80","0.011"],["64195.30","3.152"],["64197.30","0.000"],["64198.30","0.063"],["64199.30","0.000"],["64200.00","2.645"],["64201.30","0.000"],["64221.80","0.001"],["64224.50","0.027"],["64225.00","0.002"],["64226.50","0.003"],["64227.20","0.024"],["64248.00","1.949"],["64248.20","0.000"],["64266.50","1.947"],["64266.70","0.000"],["64270.30","0.001"],["64278.90","0.499"],["64286.40","0.000"],["64288.40","0.000"],["64297.50","0.080"],["64304.60","0.371"],["64313.70","0.737"],["64314.30","0.538"],["64326.50","6.090"],["64333.00","0.117"],["64362.00","0.161"],["64362.10","0.300"],["64365.00","0.348"],["64365.20","0.443"],["64388.00","0.006"],["64471.50","3.206"],["64473.20","0.000"],["64531.50","0.112"],["64531.70","0.096"],["64532.00","0.316"],["64682.20","0.000"],["64682.30","0.000"],["64685.20","0.001"],["64685.80","0.013"],["64686.30","0.004"],["64778.50","0.016"],["64778.70","0.000"],["64778.90","0.002"],["64781.80","0.027"],["64781.90","0.002"],["64782.40","1.836"],["64782.70","6.419"],["64782.80","1.835"],["64783.00","2.922"],["64806.70","0.925"],["64842.60","0.006"],["64842.80","0.000"],["64843.00","0.002"],["64845.80","0.000"],["64845.90","0.239"],["64846.70","2.289"],["64847.00","6.122"],["65322.60","0.147"],["65326.20","0.003"],["65326.70","0.006"],["67243.90","0.027"]],"b":[["13541.70","1.050"],["13541.80","0.014"],["13544.70","0.014"],["13545.70","0.070"],["13641.70","0.252"],["13741.70","0.854"],["13741.80","0.014"],["13745.20","0.014"],["13745.70","0.056"],["13841.70","0.616"],["13844.70","0.014"],["13845.20","0.014"],["13845.70","0.056"],["13941.70","1.162"],["57637.50","0.050"],["57640.20","0.000"],["57641.10","0.002"],["61480.00","0.219"],["62015.60","0.000"],["62894.40","0.002"],["63029.60","0.067"],["63030.30","0.005"],["63030.90","0.002"],["63031.40","0.000"],["63044.70","0.012"],["63045.20","0.010"],["63045.70","0.008"],["63401.30","0.386"],["63401.40","0.000"],["63404.30","2.311"],["63404.50","0.169"],["63404.70","0.004"],["63405.20","0.004"],["63523.00","0.710"],["63529.40","4.975"],["63529.50","0.001"],["63532.80","0.003"],["63545.60","0.000"],["63558.30","0.000"],["63571.50","0.003"],["63587.10","0.002"],["63596.40","0.001"],["63609.90","0.096"],["63610.20","0.302"],["63622.70","0.098"],["63651.10","0.000"],["63660.40","0.001"],["63683.10","0.096"],["63696.00","0.025"],["63697.20","0.000"],["63715.10","0.000"],["63721.60","0.011"],["63779.20","0.003"],["63788.50","0.011"],["63803.50","0.133"],["63807.00","0.681"],["63843.20","0.005"],["63844.90","0.063"],["63847.50","0.000"],["63849.70","0.077"],["63852.40","0.001"],["63852.60","2.003"],["63853.80","0.001"],["63862.10","0.000"],["63862.50","0.003"],["63865.70","0.376"],["63873.20","0.147"],["63876.80","0.014"],["63905.10","0.015"],["63907.20","4.845"],["63907.60","0.000"],["63912.30","0.000"],["63913.70","3.591"],["63914.60","0.001"],["63915.50","1.960"],["63917.10","0.000"],["63917.40","0.001"],["63919.60","0.575"],["63921.30","0.474"],["63923.80","0.013"],["63925.70","0.832"],["63928.10","0.001"],["63928.30","0.004"],["63928.40","0.067"],["63928.50","0.012"],["63930.90","0.491"],["63933.90","2.157"],["63936.40","0.000"],["63938.40","0.160"],["63939.90","0.003"],["63940.40","4.059"],["63940.70","0.000"],["63943.80","0.067"],["63944.60","0.500"],["63945.40","2.714"],["63946.60","0.003"],["63950.80","0.514"],["63951.70","0.013"],["63952.00","0.000"],["63952.20","0.087"],["63952.30","0.010"],["63952.40","4.856"],["63952.50","4.517"],["63953.00","0.239"],["63954.80","0.000"],["63955.00","0.000"],["63955.10","1.153"],["63957.10","0.009"],["63958.40","0.002"],["63959.10","0.000"],["63961.60","13.379"],["63962.00","0.000"],["63962.30","0.000"],["63962.50","0.000"],["63964.00","0.007"],["63964.70","0.492"],["63964.80","0.831"],["63964.90","0.200"],["63965.30","0.005"],["63966.00","2.368"],["63966.30","0.101"],["63967.80","0.003"],["63967.90","0.001"],["63970.60","0.005"],["63971.30","0.000"],["63971.90","0.008"],["63972.40","1.010"],["63972.50","0.500"],["63973.30","1.036"],["63974.50","0.001"],["63977.10","0.025"],["63977.40","0.003"],["63977.70","0.013"],["63977.80","0.873"],["63978.50","0.002"],["63979.10","0.000"],["63980.80","0.033"],["63981.20","0.005"],["63981.60","2.344"],["63982.30","4.234"],["63982.90","1.861"],["63983.20","0.400"],["63983.30","0.000"],["63983.60","3.221"],["63983.70","0.002"],["63983.80","0.000"],["63983.90","0.000"],["63984.10","0.003"],["63984.20","0.089"],["63985.30","2.653"],["63986.40","0.061"],["63987.30","0.415"],["63987.90","4.199"],["63988.00","0.195"],["63988.40","0.000"],["63988.80","0.026"],["63989.20","0.060"],["63989.30","0.375"],["63989.40","0.183"],["63989.60","0.204"],["63990.30","0.004"],["63990.40","0.006"],["63990.60","0.434"],["63990.70","0.003"],["63990.80","0.000"],["63991.00","0.025"],["63991.10","0.001"],["63991.30","0.000"],["63991.60","0.001"],["63991.70","0.497"],["63991.80","0.018"],["63992.00","2.002"],["63992.10","2.344"],["63993.30","0.316"],["63993.60","0.722"],["63993.90","0.000"],["63994.00","0.001"],["63994.40","0.066"],["63994.50","0.211"],["63994.60","1.262"],["63996.80","0.098"],["63997.00","0.060"],["63997.60","0.005"],["63998.00","0.505"],["63998.20","0.001"],["63998.50","0.000"],["63998.60","0.010"],["63998.80","0.590"],["63998.90","0.000"],["63999.00","0.907"],["64000.70","0.001"],["64000.80","0.002"],["64000.90","0.002"],["64001.40","0.004"],["64002.10","0.053"],["64002.70","2.342"],["64003.10","0.002"],["64003.30","0.074"],["64003.70","0.528"],["64004.00","0.003"],["64004.10","0.511"],["64004.60","1.906"],["64004.90","0.000"],["64005.30","0.314"],["64005.40","2.436"],["64006.00","0.469"],["64006.50","0.033"],["64006.60","0.052"],["64006.70","0.004"],["64007.40","0.000"],["64007.50","0.113"],["64007.70","0.028"],["64007.80","0.001"],["64008.20","0.001"],["64009.10","0.005"],["64009.30","0.003"],["64009.40","0.530"],["64009.80","0.067"],["64009.90","0.715"],["64011.20","0.095"],["64011.30","0.040"],["64011.50","0.033"],["64011.60","0.001"],["64012.40","0.367"],["64012.50","0.005"],["64012.60","0.877"],["64012.70","0.010"],["64012.80","0.024"],["64012.90","0.003"],["64013.00","0.005"],["64013.20","0.060"],["64013.50","0.000"],["64013.70","0.007"],["64013.80","0.000"],["64014.40","0.047"],["64014.60","1.251"],["64014.80","0.000"],["64015.10","0.630"],["64015.40","0.121"],["64015.70","0.000"],["64015.80","0.001"],["64015.90","1.477"],["64016.00","0.007"],["64016.40","0.612"],["64016.50","3.065"],["64016.60","0.344"],["64016.70","0.633"],["64016.90","0.000"],["64017.00","0.084"],["64017.30","0.013"],["64017.50","0.032"],["64017.80","0.514"],["64018.00","0.537"],["64018.10","0.096"],["64018.70","0.005"],["64018.80","0.597"],["64019.10","1.870"],["64019.20","0.762"],["64019.30","0.573"],["64019.70","0.013"],["64019.90","2.660"],["64020.00","0.356"],["64020.20","0.490"],["64020.30","0.035"],["64020.60","0.024"],["64020.70","0.001"],["64021.10","0.000"],["64021.20","1.422"],["64021.40","1.937"],["64022.00","0.008"],["64022.30","1.749"],["64022.40","0.010"],["64022.50","0.529"],["64022.60","1.253"],["64022.80","0.260"],["64022.90","0.000"],["64023.00","2.966"],["64023.10","0.094"],["64023.20","0.000"],["64023.30","1.054"],["64023.40","0.567"],["64023.50","0.278"],["64023.70","0.003"],["64023.90","0.290"],["64024.10","0.005"],["64024.30","0.002"],["64024.40","0.381"],["64024.70","0.000"],["64025.00","0.002"],["64025.20","0.314"],["64025.30","0.080"],["64025.40","0.001"],["64025.60","1.583"],["64025.70","2.410"],["64025.90","0.002"],["64026.20","0.260"],["64026.40","0.471"],["64026.50","0.019"],["64026.60","0.508"],["64027.00","0.002"],["64027.10","0.046"],["64027.40","0.220"],["64028.20","0.005"],["64028.30","2.342"],["64028.60","0.018"],["64028.70","0.421"],["64028.80","0.009"],["64029.00","0.231"],["64029.20","0.278"],["64029.50","0.000"],["64029.80","0.181"],["64029.90","0.183"],["64030.20","0.063"],["64030.30","0.182"],["64030.40","0.314"],["64030.50","0.060"],["64030.70","0.002"],["64030.80","0.003"],["64031.80","0.026"],["64031.90","0.035"],["64032.10","2.637"],["64032.20","0.298"],["64032.30","0.022"],["64032.40","0.023"],["64032.60","0.013"],["64032.70","0.000"],["64032.80","0.237"],["64032.90","0.047"],["64033.10","0.010"],["64033.20","0.019"],["64033.40","0.061"],["64033.50","0.022"],["64033.70","0.000"],["64033.80","0.001"],["64033.90","0.001"],["64034.10","0.002"],["64034.20","0.003"],["64034.30","0.001"],["64034.50","0.032"],["64034.60","0.063"],["64034.80","0.001"],["64035.00","0.003"],["64035.10","0.592"],["64035.20","0.749"],["64035.30","0.012"],["64035.40","0.034"],["64035.60","0.001"],["64035.70","0.000"],["64035.80","0.001"],["64035.90","0.031"],["64036.00","2.344"],["64036.10","1.266"],["64036.20","0.000"],["64036.30","0.000"],["64036.40","0.003"],["64036.50","0.609"],["64036.60","0.001"],["64036.70","0.002"],["64036.80","0.002"],["64036.90","0.003"],["64037.00","0.001"],["64037.20","0.394"],["64037.30","0.001"],["64037.50","0.005"],["64037.70","0.001"],["64037.80","0.001"],["64038.00","0.006"],["64038.30","0.528"],["64038.40","0.537"],["64038.50","0.013"],["64038.70","0.047"],["64039.10","0.000"],["64039.30","0.000"],["64039.40","0.002"],["64039.50","0.005"],["64039.60","0.003"],["64039.70","0.001"],["64039.80","0.191"],["64039.90","0.002"],["64040.00","0.042"],["64040.10","0.267"],["64040.20","0.001"],["64040.40","0.002"],["64040.50","0.000"],["64040.70","0.009"],["64040.80","0.073"],["64041.00","0.001"],["64041.10","0.000"],["64041.20","0.000"],["64041.30","0.000"],["64041.40","0.001"],["64041.50","0.001"],["64041.60","0.315"],["64041.70","5.833"],["64041.80","13.879"],["64041.90","2.688"],["64042.00","0.021"],["64042.10","0.000"],["64042.20","0.110"],["64042.50","0.001"],["64042.60","0.001"],["64042.70","0.001"],["64042.80","0.000"],["64042.90","0.095"],["64043.10","0.001"],["64043.20","0.002"],["64043.40","0.023"],["64043.50","0.434"],["64043.60","0.001"],["64043.80","0.018"],["64044.00","0.002"],["64044.10","0.002"],["64044.20","0.002"],["64044.30","1.008"],["64044.40","0.000"],["64044.50","0.002"],["64044.60","2.341"],["64044.70","0.646"],["64044.80","0.599"],["64044.90","0.011"],["64045.00","0.000"],["64045.10","1.526"],["64045.20","4.631"],["64045.30","0.002"],["64045.40","0.547"],["64045.50","0.000"],["64045.60","0.100"],["64045.70","18.060"]],"e":"depthUpdate","ps":"BTCUSDT","pu":11165393627968,"s":"BTCUSDT","st":1,"u":11165393659233}
{"E":1785353515658,"T":1785353515657,"U":11165393659242,"a":[["64045.80","6.843"],["64048.40","0.016"],["64049.60","0.453"],["64049.70","0.003"],["64049.80","0.028"],["64051.20","0.024"],["64051.60","0.004"],["64052.00","0.004"],["64052.50","0.001"],["64053.60","0.384"],["64053.80","0.004"],["64054.10","0.001"],["64054.20","0.001"],["64054.30","0.000"],["64054.40","0.098"],["64054.50","0.220"],["64054.90","0.000"],["64056.10","0.098"],["64056.90","1.675"],["64058.00","1.689"],["64058.20","0.140"],["64059.50","3.165"],["64061.30","0.000"],["64062.00","0.013"],["64062.40","0.004"],["64062.50","0.002"],["64062.70","0.022"],["64063.60","0.743"],["64063.70","0.073"],["64063.90","0.050"],["64064.80","0.553"],["64067.00","0.081"],["64067.40","0.002"],["64067.80","1.359"],["64069.00","0.073"],["64070.00","0.350"],["64070.90","10.004"],["64071.40","0.389"],["64072.60","0.075"],["64073.00","0.379"],["64073.70","0.015"],["64073.80","0.250"],["64074.20","2.340"],["64074.30","0.074"],["64074.60","10.158"],["64074.80","0.000"],["64075.70","0.010"],["64076.70","0.006"],["64077.10","2.343"],["64077.60","0.174"],["64077.80","0.018"],["64079.00","1.277"],["64079.70","0.011"],["64081.00","0.029"],["64081.30","0.003"],["64081.50","0.977"],["64082.90","1.542"],["64083.00","0.118"],["64083.90","2.546"],["64085.20","0.001"],["64087.10","0.033"],["64088.70","0.002"],["64089.00","0.090"],["64089.10","0.006"],["64089.30","0.611"],["64090.30","0.030"],["64092.60","0.012"],["64093.50","0.050"],["64093.60","0.003"],["64096.70","0.063"],["64096.90","0.001"],["64097.20","2.581"],["64097.30","0.122"],["64097.40","0.327"],["64097.80","0.154"],["64099.00","0.000"],["64099.20","1.475"],["64099.60","1.046"],["64102.00","0.611"],["64103.10","0.002"],["64103.80","0.003"],["64103.90","0.006"],["64107.30","0.002"],["64108.80","0.021"],["64109.80","0.047"],["64111.30","0.035"],["64121.80","8.008"],["64129.10","0.023"],["64133.00","0.106"],["64134.30","23.998"],["64140.20","0.008"],["64145.30","0.008"],["64166.40","2.087"],["64167.30","0.375"],["64205.30","0.000"],["64205.80","0.000"],["64205.90","0.001"],["64220.90","1.706"],["64223.80","1.971"],["64223.90","5.471"],["64225.00","0.001"],["64237.10","10.551"],["64270.90","7.349"],["64686.30","0.004"]],"b":[["1000.00","37.592"],["13545.70","0.182"],["13641.70","0.140"],["13745.70","0.182"],["13841.70","0.490"],["13845.70","0.182"],["13941.70","1.036"],["57641.10","0.002"],["61483.80","0.003"],["62764.80","0.003"],["63270.70","2.682"],["63271.80","0.009"],["63405.20","0.000"],["63432.00","0.005"],["63721.50","0.137"],["63804.90","0.156"],["63834.70","0.000"],["63836.80","0.271"],["63852.90","0.000"],["63863.70","16.222"],["63883.80","0.415"],["63934.70","0.001"],["63936.50","0.027"],["63943.80","0.059"],["63946.20","2.359"],["63947.20","0.000"],["63948.60","0.187"],["63949.70","22.430"],["63950.00","0.268"],["63950.30","0.010"],["63953.50","0.141"],["63953.70","0.003"],["63956.30","0.006"],["63958.30","0.008"],["63967.40","0.000"],["63969.70","6.303"],["63970.70","1.612"],["63971.90","0.000"],["63975.20","0.004"],["63977.70","0.005"],["63978.50","0.033"],["63980.80","0.243"],["63981.80","0.703"],["63981.90","1.563"],["63982.30","4.242"],["63987.60","0.001"],["63992.20","0.084"],["63993.80","0.001"],["63994.50","0.001"],["63997.00","0.060"],["63998.80","0.565"],["63999.50","0.024"],["63999.80","0.314"],["64000.20","0.278"],["64000.40","0.279"],["64002.10","0.101"],["64004.10","0.567"],["64004.60","1.978"],["64006.00","0.484"],["64007.90","1.275"],["64010.50","0.001"],["64010.80","2.340"],["64011.10","0.071"],["64013.80","0.004"],["64016.10","0.420"],["64016.50","3.054"],["64017.40","10.000"],["64017.70","0.157"],["64017.90","0.012"],["64019.70","0.575"],["64019.90","2.663"],["64020.00","0.357"],["64020.10","0.355"],["64020.40","0.002"],["64020.70","0.008"],["64021.10","0.468"],["64021.40","1.375"],["64022.00","0.001"],["64023.00","2.950"],["64023.50","0.057"],["64024.40","0.361"],["64024.60","0.050"],["64025.50","0.006"],["64025.60","2.283"],["64025.70","2.408"],["64026.20","0.552"],["64026.40","0.003"],["64026.60","0.508"],["64028.40","1.151"],["64028.50","0.970"],["64028.60","0.018"],["64029.20","0.000"],["64029.30","0.064"],["64029.60","0.113"],["64030.00","0.691"],["64030.40","0.475"],["64032.00","0.678"],["64032.10","2.345"],["64032.90","0.049"],["64033.00","0.373"],["64033.10","0.070"],["64033.20","0.019"],["64033.30","0.060"],["64033.50","0.002"],["64033.90","0.061"],["64034.00","0.034"],["64034.60","0.001"],["64034.80","0.033"],["64035.10","0.624"],["64035.90","0.015"],["64036.10","1.266"],["64036.50","0.001"],["64037.20","0.081"],["64038.00","0.008"],["64038.40","0.380"],["64038.80","0.336"],["64039.30","0.003"],["64040.30","0.000"],["64040.60","0.001"],["64041.00","0.094"],["64041.20","0.001"],["64041.60","0.002"],["64041.70","5.710"],["64041.80","11.322"],["64041.90","4.964"],["64042.00","0.569"],["64042.30","1.008"],["64042.40","1.543"],["64042.80","0.234"],["64043.30","0.000"],["64043.40","0.001"],["64044.00","0.003"],["64044.10","0.001"],["64044.30","0.000"],["64044.50","0.001"],["64044.60","0.001"],["64044.70","0.606"],["64045.00","0.006"],["64045.10","0.003"],["64045.20","4.391"],["64045.30","0.000"],["64045.40","0.000"],["64045.50","0.000"],["64045.60","0.102"],["64045.70","13.977"]],"e":"depthUpdate","ps":"BTCUSDT","pu":11165393659233,"s":"BTCUSDT","st":1,"u":11165393669970}
{"E":1785353515760,"T":1785353515759,"U":11165393670116,"a":[["64045.80","6.058"],["64048.30","0.314"],["64049.70","0.032"],["64049.80","0.005"],["64052.40","1.308"],["64053.00","0.057"],["64053.50","0.085"],["64053.60","0.330"],["64053.80","0.002"],["64053.90","0.609"],["64054.40","0.098"],["64054.50","0.148"],["64056.10","0.110"],["64056.90","0.740"],["64058.20","0.020"],["64058.70","0.469"],["64059.30","0.000"],["64059.80","0.401"],["64060.10","0.003"],["64062.90","0.160"],["64063.10","0.137"],["64064.60","0.005"],["64065.70","0.164"],["64067.50","0.261"],["64067.80","1.361"],["64070.70","0.159"],["64070.90","0.004"],["64071.60","0.001"],["64073.80","0.407"],["64075.40","0.524"],["64078.00","1.754"],["64079.40","0.774"],["64099.90","1.965"],["64100.00","2.693"],["64102.80","0.032"],["64103.70","0.067"],["64103.80","1.487"],["64103.90","0.002"],["64104.00","0.006"],["64104.10","0.000"],["64107.80","2.865"],["64123.90","0.003"],["64124.20","1.496"],["64124.30","0.001"],["64130.70","0.200"],["64132.20","0.039"],["64134.30","23.998"],["64144.60","1.486"],["64144.70","0.000"],["64233.90","0.100"],["64236.50","1.117"],["64247.90","5.185"],["64248.00","0.002"],["64266.40","1.947"],["64266.50","0.000"],["64614.30","0.000"],["64618.40","0.031"],["64686.30","0.002"],["64883.30","0.005"],["64887.30","0.037"],["65322.60","0.144"]],"b":[["1000.00","37.592"],["13545.70","0.308"],["13641.70","0.014"],["13745.70","0.294"],["13841.70","0.378"],["13845.70","0.294"],["13941.70","0.924"],["57641.10","0.002"],["60839.60","0.006"],["60839.70","0.008"],["61483.80","0.000"],["63082.20","21.587"],["63113.20","1.098"],["63242.20","23.036"],["63274.20","13.681"],["63279.60","0.947"],["63310.20","10.611"],["63338.20","14.192"],["63370.30","8.591"],["63405.20","0.000"],["63466.20","2.309"],["63498.30","2.321"],["63901.80","0.031"],["63915.40","1.973"],["63915.50","0.003"],["63933.80","1.970"],["63933.90","0.200"],["63941.20","1.549"],["63941.30","0.000"],["63945.30","0.000"],["63947.50","22.938"],["63949.70","0.002"],["63952.20","0.097"],["63952.30","0.000"],["63954.90","2.875"],["63961.50","2.828"],["63961.60","11.894"],["63984.70","1.755"],["63985.40","0.290"],["63989.90","0.001"],["63991.90","0.003"],["63997.00","0.060"],["64000.20","0.000"],["64000.40","0.278"],["64001.00","0.518"],["64001.60","0.066"],["64002.10","0.167"],["64013.30","0.113"],["64013.80","0.000"],["64015.90","1.459"],["64016.30","0.103"],["64016.70","0.713"],["64017.40","0.000"],["64017.50","0.032"],["64018.00","1.099"],["64018.10","0.016"],["64019.70","0.013"],["64019.90","2.681"],["64020.80","11.185"],["64021.60","2.000"],["64022.50","0.511"],["64023.10","0.156"],["64024.00","0.023"],["64025.50","0.004"],["64025.70","2.410"],["64026.50","0.001"],["64028.50","0.314"],["64028.60","0.178"],["64029.30","0.002"],["64029.70","0.000"],["64029.80","0.121"],["64030.00","0.083"],["64030.10","0.731"],["64030.30","0.122"],["64030.40","0.315"],["64031.00","0.001"],["64031.30","0.000"],["64031.40","0.719"],["64031.50","0.019"],["64031.60","0.000"],["64031.90","0.003"],["64032.70","0.000"],["64033.20","0.121"],["64033.30","0.080"],["64033.50","0.122"],["64033.80","0.061"],["64034.60","0.019"],["64034.70","0.002"],["64034.80","2.375"],["64034.90","0.020"],["64035.30","0.729"],["64035.40","0.034"],["64035.90","0.015"],["64036.00","0.002"],["64036.10","0.017"],["64036.20","1.249"],["64036.70","0.000"],["64037.20","0.004"],["64038.30","0.281"],["64038.70","0.053"],["64038.80","0.000"],["64040.40","0.025"],["64041.20","0.019"],["64041.50","0.000"],["64041.60","0.003"],["64041.70","4.359"],["64041.80","3.440"],["64041.90","2.610"],["64042.00","0.004"],["64042.20","0.344"],["64042.40","1.330"],["64042.50","2.341"],["64042.60","0.041"],["64042.80","0.000"],["64043.80","0.000"],["64044.30","0.006"],["64044.80","0.600"],["64044.90","0.010"],["64045.00","0.000"],["64045.10","0.001"],["64045.20","2.687"],["64045.30","0.000"],["64045.40","0.002"],["64045.60","0.100"],["64045.70","10.708"]],"e":"depthUpdate","ps":"BTCUSDT","pu":11165393669970,"s":"BTCUSDT","st":1,"u":11165393677292}
{"E":1785353515862,"T":1785353515860,"U":11165393677413,"a":[["64048.10","0.008"],["64048.20","0.005"],["64048.40","0.016"],["64051.30","0.489"],["64052.10","0.158"],["64052.20","0.015"],["64052.30","0.549"],["64053.50","0.208"],["64054.00","0.396"],["64054.50","0.695"],["64056.10","0.098"],["64056.60","0.173"],["64056.90","0.193"],["64057.80","0.011"],["64060.40","0.079"],["64069.00","0.113"],["64075.10","0.001"],["64075.60","10.317"],["64076.80","0.087"],["64079.60","0.090"],["64086.70","0.005"],["64088.70","0.003"],["64092.60","0.011"],["64097.10","0.682"],["64099.60","1.046"],["64103.80","1.487"],["64105.90","1.735"],["64132.20","0.039"],["64133.00","0.094"],["64134.30","0.482"],["64143.10","23.357"],["64237.10","10.335"],["64334.30","0.219"],["64522.10","0.031"],["64686.30","0.002"]],"b":[["13545.70","0.224"],["13641.70","0.000"],["13745.70","0.420"],["13841.70","0.252"],["13845.70","0.420"],["13941.70","0.798"],["13945.70","0.098"],["51236.60","0.000"],["57641.10","0.002"],["63018.10","11.955"],["63050.00","12.680"],["63082.20","19.389"],["63114.10","3.495"],["63405.20","0.000"],["63561.50","0.098"],["63721.40","0.000"],["63840.70","0.000"],["63863.80","3.070"],["63895.70","0.002"],["63897.70","0.091"],["63946.20","2.351"],["63946.60","0.035"],["63947.60","0.040"],["63986.80","0.590"],["63991.90","0.025"],["63994.40","0.068"],["64006.00","0.394"],["64013.10","0.224"],["64013.80","0.004"],["64020.00","0.320"],["64020.80","1.185"],["64029.90","0.063"],["64030.00","0.023"],["64030.50","0.000"],["64030.60","0.059"],["64033.10","0.130"],["64033.30","0.200"],["64033.70","0.060"],["64040.10","0.231"],["64041.70","4.357"],["64041.80","3.419"],["64042.20","0.110"],["64042.60","0.276"],["64042.90","0.094"],["64043.20","0.001"],["64043.60","0.002"],["64045.30","0.002"],["64045.40","0.000"],["64045.50","0.000"],["64045.60","0.100"],["64045.70","10.728"]],"e":"depthUpdate","ps":"BTCUSDT","pu":11165393677292,"s":"BTCUSDT","st":1,"u":11165393683176}
{"E":1785353515964,"T":1785353515963,"U":11165393683296,"a":[["64045.80","5.639"],["64046.00","0.007"],["64046.30","0.000"],["64048.20","0.003"],["64048.60","0.024"],["64049.30","0.157"],["64049.70","0.009"],["64050.00","0.504"],["64051.20","0.724"],["64052.10","0.002"],["64053.50","0.001"],["64054.40","0.182"],["64055.60","0.003"],["64056.00","0.005"],["64056.10","0.086"],["64056.80","2.499"],["64058.10","0.002"],["64060.40","0.001"],["64063.10","0.139"],["64073.70","0.087"],["64073.80","0.479"],["64075.60","0.317"],["64077.50","10.105"],["64082.70","3.564"],["64088.70","0.006"],["64099.60","1.058"],["64103.80","1.497"],["64133.00","0.106"],["64134.30","23.824"],["64143.00","0.009"],["64143.10","0.015"],["64145.30","0.000"],["64149.00","0.001"],["64362.10","0.299"],["64366.10","0.001"],["64686.30","0.004"],["64848.90","3.222"]],"b":[["1000.00","37.592"],["13545.70","0.098"],["13645.70","0.014"],["13745.70","0.504"],["13841.70","0.154"],["13845.70","0.532"],["13941.70","0.686"],["13945.70","0.224"],["57641.10","0.002"],["61483.80","0.003"],["62760.90","1.057"],["63018.10","9.755"],["63050.00","13.779"],["63053.00","2.052"],["63082.20","18.290"],["63114.10","4.593"],["63210.20","8.148"],["63241.20","2.554"],["63245.10","2.317"],["63296.80","2.902"],["63401.30","0.544"],["63404.30","0.000"],["63405.20","0.000"],["63437.30","2.310"],["63721.50","0.137"],["63725.40","0.002"],["63807.00","0.671"],["63897.70","0.972"],["63899.70","0.881"],["63901.70","0.881"],["63947.20","0.032"],["63985.40","0.012"],["63989.50","0.060"],["63991.90","0.001"],["64000.40","0.000"],["64003.30","0.074"],["64020.30","0.000"],["64021.60","0.000"],["64023.10","0.094"],["64025.20","10.314"],["64025.30","0.142"],["64025.80","0.514"],["64027.40","0.255"],["64029.60","0.053"],["64029.80","0.001"],["64030.10","0.611"],["64032.60","0.015"],["64033.40","0.121"],["64033.60","0.062"],["64041.70","4.330"],["64042.60","0.042"],["64043.00","0.234"],["64044.80","0.602"],["64045.70","10.808"]],"e":"depthUpdate","ps":"BTCUSDT","pu":11165393683176,"s":"BTCUSDT","st":1,"u":11165393692061}
{"E":1785353516066,"T":1785353516065,"U":11165393692117,"a":[["64045.80","4.581"],["64048.30","0.001"],["64048.50","0.006"],["64049.10","0.001"],["64049.20","0.286"],["64049.30","0.001"],["64049.60","0.140"],["64052.30","0.002"],["64052.40","0.380"],["64053.10","0.206"],["64053.80","0.549"],["64053.90","1.544"],["64054.50","0.675"],["64055.00","1.014"],["64055.80","0.475"],["64057.00","0.419"],["64057.30","0.451"],["64058.30","0.001"],["64060.10","0.000"],["64062.00","0.102"],["64062.40","0.024"],["64073.70","0.015"],["64073.80","0.407"],["64075.00","0.004"],["64076.30","2.564"],["64077.50","0.107"],["64078.80","0.434"],["64082.50","2.002"],["64083.00","0.140"],["64085.90","0.083"],["64099.60","1.058"],["64103.80","1.487"],["64104.10","0.072"],["64133.00","0.106"],["64134.30","0.482"],["64136.60","23.342"],["64143.00","0.001"],["64143.10","0.015"],["64145.20","0.016"],["64145.30","0.000"],["64235.40","0.135"],["64240.20","0.009"],["64261.90","0.027"],["64686.30","0.002"],["64845.20","0.017"],["65038.50","0.000"],["65326.70","0.009"]],"b":[["1000.00","37.592"],["13544.70","0.000"],["13545.70","0.000"],["13645.70","0.140"],["13745.70","0.378"],["13845.70","0.658"],["13941.70","0.560"],["13945.70","0.336"],["51237.00","0.000"],["57641.10","0.002"],["61483.80","0.000"],["62954.20","0.001"],["62988.90","1.100"],["63018.10","7.555"],["63053.00","4.250"],["63082.20","17.191"],["63117.00","1.221"],["63274.30","4.073"],["63309.20","0.938"],["63405.20","0.000"],["63897.70","0.091"],["63899.70","0.000"],["63901.70","0.000"],["63969.00","0.001"],["63985.10","0.001"],["63991.90","0.038"],["63993.30","0.376"],["63994.30","0.090"],["64001.60","0.006"],["64025.20","0.316"],["64025.70","2.408"],["64026.00","10.544"],["64026.40","0.281"],["64028.40","1.807"],["64029.90","0.003"],["64030.20","0.003"],["64034.20","0.003"],["64035.40","0.347"],["64038.30","0.387"],["64040.40","0.002"],["64041.50","0.016"],["64042.00","0.067"],["64043.10","0.013"],["64043.60","0.012"],["64044.80","0.610"],["64045.20","2.684"],["64045.70","10.836"]],"e":"depthUpdate","ps":"BTCUSDT","pu":11165393692061,"s":"BTCUSDT","st":1,"u":11165393706049}
{"E":1785353516168,"T":1785353516165,"U":11165393706236,"a":[["64045.80","3.436"],["64048.20","0.002"],["64048.50","0.005"],["64048.60","0.001"],["64049.80","0.027"],["64051.10","0.003"],["64051.20","0.024"],["64051.30","0.568"],["64051.70","0.011"],["64052.40","0.009"],["64053.70","0.308"],["64053.80","0.002"],["64053.90","0.001"],["64054.40","0.162"],["64054.50","0.570"],["64054.90","0.000"],["64055.00","0.014"],["64055.50","0.935"],["64055.80","0.473"],["64055.90","0.547"],["64056.00","1.005"],["64056.60","0.173"],["64056.70","0.069"],["64056.80","0.159"],["64056.90","0.183"],["64058.20","0.004"],["64058.50","0.011"],["64058.60","0.005"],["64058.70","0.235"],["64058.90","2.421"],["64059.50","0.825"],["64059.80","0.286"],["64060.60","0.004"],["64061.10","0.608"],["64061.50","2.343"],["64061.90","0.118"],["64062.10","0.018"],["64062.40","0.024"],["64062.90","0.310"],["64063.10","1.388"],["64063.20","0.007"],["64063.50","0.000"],["64064.10","2.340"],["64064.50","0.096"],["64066.50","0.000"],["64067.00","2.421"],["64067.10","0.047"],["64068.30","0.544"],["64069.70","1.856"],["64071.50","0.547"],["64071.80","0.021"],["64073.70","0.007"],["64074.50","0.228"],["64075.20","0.010"],["64077.00","2.726"],["64077.50","0.105"],["64077.60","0.104"],["64078.80","0.314"],["64079.60","0.000"],["64084.30","0.102"],["64085.60","1.954"],["64086.30","0.185"],["64087.30","0.376"],["64088.80","0.000"],["64095.30","0.060"],["64099.40","0.004"],["64099.50","0.101"],["64103.00","0.007"],["64103.70","0.067"],["64104.10","0.000"],["64109.80","0.048"],["64134.20","0.074"],["64134.30","23.824"],["64136.60","0.000"],["64145.20","0.008"],["64145.30","0.008"],["64148.90","0.010"],["64161.80","0.007"],["64320.40","0.000"],["64330.80","0.342"],["64333.00","0.000"],["64519.70","0.115"],["64686.30","0.002"],["64958.50","27.957"],["65029.10","0.381"],["65134.60","0.536"]],"b":[["13541.70","0.938"],["13541.80","0.000"],["13645.70","0.252"],["13745.70","0.266"],["13845.70","0.770"],["13941.70","0.448"],["13945.70","0.462"],["57641.10","0.002"],["61483.80","0.003"],["63018.10","6.455"],["63018.20","0.000"],["63053.00","6.448"],["63082.20","16.092"],["63117.00","2.319"],["63405.20","0.000"],["63654.10","0.005"],["63784.30","0.038"],["63964.80","0.828"],["63977.10","0.010"],["63980.80","0.033"],["63984.00","0.010"],["63985.60","0.017"],["63987.90","4.199"],["63991.00","0.000"],["63991.90","0.001"],["63996.30","0.001"],["63996.60","0.211"],["64000.00","11.018"],["64003.60","0.000"],["64006.10","0.091"],["64007.90","1.250"],["64011.10","0.001"],["64013.10","0.134"],["64017.00","0.109"],["64018.60","0.070"],["64019.80","0.035"],["64020.00","0.322"],["64021.30","0.091"],["64023.60","0.000"],["64025.30","0.080"],["64025.80","0.236"],["64025.90","0.005"],["64026.00","0.544"],["64026.20","0.614"],["64026.40","0.003"],["64027.40","0.220"],["64027.60","0.003"],["64030.20","2.003"],["64034.20","0.019"],["64035.30","0.012"],["64035.90","0.015"],["64036.30","0.000"],["64041.00","0.001"],["64041.60","0.003"],["64041.70","4.643"],["64042.00","0.067"],["64042.40","1.701"],["64042.60","0.280"],["64042.80","0.023"],["64043.00","0.000"],["64043.10","0.001"],["64043.70","0.010"],["64044.30","0.000"],["64044.50","0.001"],["64045.30","2.340"],["64045.40","0.973"],["64045.50","0.020"],["64045.70","11.831"]],"e":"depthUpdate","ps":"BTCUSDT","pu":11165393706049,"s":"BTCUSDT","st":1,"u":11165393728680}
{"E":1785353516270,"T":1785353516269,"U":11165393729098,"a":[["64045.80","0.000"],["64045.90","0.000"],["64046.00","0.000"],["64046.40","0.000"],["64046.60","0.000"],["64046.70","0.000"],["64046.80","0.000"],["64046.90","0.000"],["64047.10","0.000"],["64047.20","0.000"],["64047.30","0.000"],["64047.60","0.000"],["64047.80","0.000"],["64047.90","0.000"],["64048.00","0.000"],["64048.10","0.000"],["64048.20","0.000"],["64048.30","0.000"],["64048.40","0.000"],["64048.50","0.000"],["64048.60","0.000"],["64048.70","0.000"],["64049.00","0.000"],["64049.10","0.000"],["64049.20","0.000"],["64049.30","0.000"],["64049.40","0.000"],["64049.50","0.000"],["64049.60","0.000"],["64049.70","0.000"],["64049.80","0.000"],["64049.90","0.000"],["64050.00","0.000"],["64050.10","0.000"],["64050.30","0.000"],["64050.40","0.000"],["64050.60","0.000"],["64050.70","0.000"],["64050.80","0.000"],["64050.90","0.000"],["64051.00","0.000"],["64051.10","0.000"],["64051.20","0.000"],["64051.30","0.000"],["64051.40","0.000"],["64051.50","0.000"],["64051.60","0.003"],["64051.70","0.004"],["64051.80","0.000"],["64052.00","0.001"],["64052.10","0.001"],["64052.20","0.001"],["64052.40","0.003"],["64052.50","0.001"],["64052.60","0.113"],["64052.80","0.002"],["64053.00","0.002"],["64053.10","0.156"],["64053.30","0.002"],["64053.50","0.041"],["64053.60","0.004"],["64053.70","0.002"],["64053.90","0.001"],["64054.00","0.003"],["64054.10","0.008"],["64054.20","0.007"],["64054.30","0.040"],["64054.40","0.007"],["64054.50","0.547"],["64054.60","0.004"],["64054.70","0.257"],["64054.90","0.001"],["64055.00","0.003"],["64055.10","1.103"],["64055.20","0.210"],["64055.30","0.139"],["64055.40","0.107"],["64055.50","0.000"],["64055.70","0.004"],["64055.80","0.002"],["64055.90","0.000"],["64056.00","0.006"],["64056.10","0.003"],["64056.20","0.007"],["64056.30","0.241"],["64056.40","0.100"],["64056.60","0.001"],["64056.70","0.003"],["64056.90","0.195"],["64057.00","0.169"],["64057.10","0.125"],["64057.20","0.295"],["64057.30","0.452"],["64057.50","0.202"],["64057.60","0.006"],["64057.80","0.003"],["64057.90","0.806"],["64058.00","0.638"],["64058.40","0.055"],["64058.50","0.000"],["64058.60","0.005"],["64058.70","0.936"],["64058.90","0.001"],["64059.00","1.946"],["64059.10","0.005"],["64059.20","0.002"],["64059.30","0.000"],["64059.40","0.002"],["64059.50","0.566"],["64059.60","0.004"],["64059.70","0.000"],["64059.80","0.164"],["64059.90","0.002"],["64060.00","0.006"],["64060.70","0.004"],["64060.80","0.013"],["64061.00","0.188"],["64061.10","0.000"],["64061.20","0.440"],["64061.30","0.005"],["64061.40","1.478"],["64061.50","0.001"],["64061.60","0.540"],["64061.70","0.227"],["64061.90","0.002"],["64062.00","0.006"],["64062.10","0.016"],["64062.20","0.003"],["64062.40","0.003"],["64062.70","0.002"],["64062.80","0.014"],["64062.90","0.155"],["64063.00","0.375"],["64063.10","0.003"],["64063.20","0.003"],["64063.40","0.006"],["64063.50","0.000"],["64063.60","0.692"],["64063.70","0.016"],["64063.80","0.002"],["64064.00","0.019"],["64064.10","0.000"],["64064.20","0.794"],["64064.40","0.001"],["64064.50","0.006"],["64064.60","0.162"],["64064.70","0.602"],["64064.80","0.553"],["64065.00","0.001"],["64065.20","0.001"],["64065.30","0.005"],["64065.50","0.317"],["64065.60","0.003"],["64065.70","0.002"],["64065.80","0.007"],["64065.90","0.002"],["64066.30","0.117"],["64066.40","0.000"],["64066.60","0.011"],["64066.80","0.000"],["64067.00","0.000"],["64067.10","1.661"],["64067.20","0.164"],["64067.30","1.880"],["64067.50","0.023"],["64067.70","0.000"],["64067.80","1.068"],["64067.90","0.609"],["64068.00","0.120"],["64068.20","0.045"],["64068.30","0.171"],["64068.50","0.165"],["64068.60","1.070"],["64068.80","0.337"],["64068.90","0.002"],["64069.00","0.062"],["64069.20","0.555"],["64069.50","0.000"],["64069.60","0.541"],["64069.70","2.947"],["64069.80","4.331"],["64070.00","0.008"],["64070.10","0.336"],["64070.40","0.175"],["64070.50","0.003"],["64070.60","0.398"],["64070.70","0.002"],["64070.80","0.047"],["64071.40","0.056"],["64071.70","0.001"],["64072.00","0.009"],["64072.20","0.097"],["64072.60","0.026"],["64072.70","0.001"],["64072.90","1.054"],["64073.00","0.459"],["64073.30","0.374"],["64073.50","0.003"],["64073.60","1.490"],["64073.70","2.437"],["64073.80","0.687"],["64074.00","0.065"],["64074.20","0.000"],["64074.70","0.318"],["64074.80","0.001"],["64074.90","0.177"],["64075.10","0.198"],["64075.20","0.002"],["64075.30","0.001"],["64075.50","0.002"],["64075.70","0.063"],["64075.80","0.013"],["64075.90","0.512"],["64076.00","0.009"],["64076.20","0.703"],["64076.40","0.005"],["64076.70","2.342"],["64076.80","0.078"],["64076.90","2.068"],["64077.10","0.001"],["64077.20","0.000"],["64077.30","0.042"],["64077.60","0.004"],["64077.70","0.001"],["64077.90","0.000"],["64078.00","0.002"],["64078.10","0.057"],["64078.20","0.002"],["64078.70","0.002"],["64078.90","0.000"],["64079.00","0.001"],["64079.10","0.001"],["64079.20","0.005"],["64079.30","0.058"],["64079.40","0.098"],["64079.50","0.318"],["64079.70","0.000"],["64079.80","0.001"],["64079.90","0.379"],["64080.00","0.667"],["64080.10","0.665"],["64080.40","0.047"],["64080.80","0.001"],["64081.00","0.030"],["64081.30","0.009"],["64081.50","0.001"],["64081.70","0.049"],["64081.90","0.003"],["64082.00","0.001"],["64082.10","0.004"],["64082.30","0.002"],["64082.40","2.948"],["64082.50","0.002"],["64082.60","0.000"],["64082.70","3.566"],["64083.00","0.018"],["64083.70","0.099"],["64083.90","0.358"],["64084.00","0.382"],["64084.20","0.186"],["64084.30","0.132"],["64084.90","0.165"],["64085.50","1.273"],["64085.60","0.938"],["64085.70","0.000"],["64086.20","0.307"],["64086.30","0.095"],["64086.40","0.005"],["64086.50","0.004"],["64086.60","0.304"],["64087.00","0.054"],["64087.10","0.022"],["64087.20","0.000"],["64087.30","0.470"],["64088.10","0.404"],["64088.70","0.002"],["64089.00","0.079"],["64089.50","0.067"],["64089.80","0.001"],["64090.30","0.124"],["64090.40","0.001"],["64090.80","0.000"],["64090.90","0.899"],["64091.50","0.659"],["64091.60","4.414"],["64091.70","0.003"],["64091.80","0.000"],["64092.30","0.000"],["64092.40","1.592"],["64092.80","0.021"],["64093.50","0.025"],["64093.80","0.002"],["64094.00","1.091"],["64094.10","0.000"],["64094.30","0.018"],["64094.40","2.345"],["64095.00","0.000"],["64095.10","0.000"],["64095.30","0.000"],["64095.70","0.003"],["64096.70","0.064"],["64097.10","0.772"],["64097.20","2.573"],["64097.30","0.122"],["64097.40","0.171"],["64097.70","0.434"],["64097.80","0.158"],["64099.10","2.000"],["64099.40","0.004"],["64099.50","0.001"],["64099.80","1.967"],["64099.90","0.020"],["64100.20","0.504"],["64100.40","0.070"],["64101.30","1.076"],["64101.90","0.070"],["64102.80","0.002"],["64103.00","0.008"],["64103.40","0.002"],["64103.70","0.067"],["64104.90","0.115"],["64105.00","0.603"],["64105.30","2.018"],["64105.40","0.000"],["64105.70","0.003"],["64107.20","0.202"],["64107.90","0.001"],["64109.00","0.001"],["64109.90","0.001"],["64110.70","0.011"],["64111.80","0.005"],["64111.90","0.025"],["64112.00","0.137"],["64112.40","0.243"],["64112.70","0.001"],["64113.30","0.110"],["64113.60","2.355"],["64114.30","0.028"],["64114.90","0.501"],["64115.30","0.000"],["64119.60","0.064"],["64119.80","0.004"],["64120.80","0.015"],["64123.00","0.000"],["64123.70","0.147"],["64124.50","0.001"],["64126.50","0.325"],["64126.80","0.061"],["64126.90","0.000"],["64127.90","0.000"],["64128.50","0.001"],["64128.90","0.012"],["64129.60","0.001"],["64130.00","0.003"],["64130.70","0.186"],["64130.80","0.003"],["64131.10","0.840"],["64134.20","0.002"],["64134.30","0.482"],["64140.20","0.010"],["64141.50","0.041"],["64143.30","0.028"],["64143.60","0.491"],["64143.80","0.001"],["64145.60","0.053"],["64147.50","0.004"],["64148.60","0.251"],["64149.40","0.072"],["64149.50","1.249"],["64149.80","0.489"],["64152.40","0.001"],["64152.90","1.103"],["64153.00","2.343"],["64154.10","0.011"],["64154.30","0.002"],["64154.40","0.003"],["64166.80","0.000"],["64167.30","0.375"],["64168.50","0.026"],["64169.50","0.124"],["64170.90","0.000"],["64176.10","2.345"],["64178.30","23.885"],["64179.20","3.154"],["64179.80","0.501"],["64181.20","0.881"],["64181.80","0.018"],["64183.20","0.885"],["64183.80","2.368"],["64185.20","0.092"],["64185.80","0.000"],["64186.70","0.003"],["64187.00","0.729"],["64187.20","0.881"],["64187.80","0.014"],["64189.20","0.881"],["64189.80","0.001"],["64190.80","0.000"],["64191.20","3.224"],["64191.80","0.028"],["64193.80","0.011"],["64194.10","0.016"],["64195.20","0.888"],["64195.80","0.004"],["64197.20","0.881"],["64197.80","0.000"],["64199.20","0.884"],["64199.80","0.206"],["64201.20","1.375"],["64201.70","0.000"],["64201.80","0.001"],["64202.10","0.018"],["64203.20","0.881"],["64203.80","0.001"],["64205.80","0.000"],["64206.40","0.948"],["64207.20","0.881"],["64210.30","0.000"],["64218.80","0.000"],["64225.80","0.010"],["64226.50","0.000"],["64226.70","0.350"],["64226.80","0.003"],["64229.00","0.001"],["64234.50","0.135"],["64240.10","0.752"],["64247.70","1.955"],["64247.90","3.238"],["64266.20","1.949"],["64266.40","0.000"],["64278.90","0.000"],["64304.20","0.001"],["64307.90","0.371"],["64331.00","0.154"],["64334.00","0.004"],["64361.60","0.000"],["64362.10","0.000"],["64365.00","0.198"],["64365.20","0.293"],["64368.20","0.001"],["64387.40","0.001"],["64425.60","0.004"],["64432.10","0.001"],["64464.00","0.003"],["64489.70","0.000"],["64496.30","0.001"],["64519.70","0.005"],["64522.80","0.110"],["64523.20","0.002"],["64531.50","0.002"],["64532.00","0.096"],["64553.70","0.000"],["64560.20","0.001"],["64686.30","0.004"],["64689.50","0.002"],["64689.70","0.004"],["64690.10","1.227"],["64782.40","0.919"],["64782.70","0.000"],["64782.80","0.001"],["64783.00","0.171"],["64785.70","5.730"],["64786.20","3.668"],["64786.30","2.762"],["64846.70","0.000"],["64847.00","0.018"],["64849.60","1.553"],["64849.70","1.526"],["64850.30","2.289"],["64850.40","3.054"]],"b":[["1000.00","37.592"],["13541.70","0.854"],["13645.70","0.308"],["13648.60","0.028"],["13649.50","0.014"],["13745.70","0.168"],["13845.70","0.826"],["13848.60","0.014"],["13848.90","0.014"],["13849.50","0.014"],["13849.70","0.014"],["13941.70","0.336"],["13945.70","0.504"],["13945.90","0.014"],["13948.60","0.014"],["13949.10","0.014"],["57555.00","2.536"],["57641.10","0.000"],["57644.00","0.052"],["61483.80","0.000"],["62963.70","0.555"],["62965.30","1.578"],["63030.90","0.000"],["63035.30","0.000"],["63038.80","0.011"],["63041.70","0.000"],["63044.70","0.002"],["63045.20","0.008"],["63045.70","0.006"],["63048.60","0.795"],["63048.90","0.002"],["63049.50","0.011"],["63051.50","0.002"],["63082.20","13.894"],["63117.00","4.515"],["63146.20","7.837"],["63181.10","3.467"],["63242.30","15.692"],["63273.20","15.390"],["63277.20","1.567"],["63338.20","13.254"],["63373.20","0.938"],["63405.20","0.000"],["63408.60","1.596"],["63409.00","1.877"],["63529.50","0.000"],["63536.70","0.009"],["63660.40","0.000"],["63667.20","0.004"],["63686.00","0.126"],["63695.20","0.452"],["63695.30","0.077"],["63704.00","0.026"],["63708.40","0.015"],["63711.60","0.001"],["63714.70","0.006"],["63721.50","0.127"],["63725.50","0.010"],["63728.90","0.010"],["63804.90","0.010"],["63807.00","0.525"],["63817.10","0.003"],["63819.20","0.000"],["63834.80","0.000"],["63839.50","0.163"],["63842.40","0.509"],["63849.60","0.001"],["63849.80","0.011"],["63850.10","0.133"],["63852.80","0.017"],["63855.60","0.002"],["63857.00","0.001"],["63867.00","0.012"],["63867.60","0.023"],["63871.90","3.083"],["63875.10","0.029"],["63877.10","0.013"],["63880.70","1.038"],["63881.00","0.579"],["63887.90","0.248"],["63891.10","0.238"],["63897.70","0.091"],["63899.70","0.000"],["63901.10","0.029"],["63901.70","0.000"],["63901.80","0.028"],["63902.40","0.280"],["63903.70","0.885"],["63905.70","24.531"],["63905.80","0.000"],["63907.70","0.000"],["63909.70","0.889"],["63909.90","0.006"],["63911.70","0.003"],["63911.90","0.001"],["63913.70","2.342"],["63914.80","0.082"],["63915.30","2.278"],["63915.40","0.016"],["63915.70","0.001"],["63916.60","0.009"],["63917.70","0.004"],["63919.70","0.003"],["63921.00","0.028"],["63927.60","0.003"],["63928.00","0.032"],["63928.30","0.023"],["63932.60","0.000"],["63932.80","0.512"],["63933.80","1.971"],["63937.80","0.088"],["63938.40","0.157"],["63938.60","0.667"],["63940.60","0.003"],["63944.60","0.000"],["63944.70","0.027"],["63947.50","0.510"],["63949.10","0.000"],["63949.30","0.000"],["63949.50","0.032"],["63949.90","0.081"],["63950.20","0.000"],["63950.30","0.510"],["63950.40","0.000"],["63951.20","0.002"],["63952.20","0.098"],["63953.00","0.098"],["63953.50","0.000"],["63954.70","0.027"],["63958.30","0.000"],["63959.00","0.122"],["63963.00","2.415"],["63963.80","0.556"],["63964.80","0.514"],["63966.00","2.367"],["63968.00","0.507"],["63968.30","0.097"],["63969.30","1.828"],["63970.40","0.001"],["63970.60","0.004"],["63970.80","0.001"],["63971.40","0.058"],["63974.20","0.001"],["63975.00","0.100"],["63977.30","0.305"],["63977.80","0.872"],["63978.80","0.000"],["63980.10","0.003"],["63981.00","0.089"],["63981.80","0.040"],["63982.10","0.012"],["63983.60","3.217"],["63984.10","0.002"],["63984.20","0.027"],["63984.70","0.001"],["63985.10","0.002"],["63985.60","0.019"],["63986.60","0.241"],["63988.00","0.116"],["63988.60","0.500"],["63989.30","0.313"],["63989.60","0.204"],["63989.70","0.097"],["63990.00","0.077"],["63990.30","0.000"],["63990.60","0.408"],["63991.20","0.000"],["63991.80","0.000"],["63992.00","2.002"],["63992.20","0.074"],["63993.00","0.000"],["63993.60","0.726"],["63993.70","0.057"],["63994.30","0.001"],["63994.40","0.001"],["63995.30","0.922"],["63995.70","1.828"],["63995.80","0.004"],["63996.20","1.151"],["63996.50","0.005"],["63996.60","0.001"],["63996.70","0.001"],["63996.80","0.070"],["63996.90","0.058"],["63997.00","0.003"],["63997.30","0.313"],["63997.40","0.001"],["63997.60","0.000"],["63998.00","0.505"],["63998.60","0.018"],["63998.70","0.000"],["63998.80","0.547"],["63999.00","0.906"],["63999.50","0.000"],["64000.00","10.993"],["64000.30","0.947"],["64000.70","0.000"],["64001.40","0.001"],["64001.60","0.001"],["64001.80","0.084"],["64001.90","0.036"],["64002.00","0.020"],["64002.10","0.130"],["64002.40","0.065"],["64002.60","2.129"],["64002.90","0.000"],["64003.20","3.207"],["64003.30","0.058"],["64004.60","0.225"],["64005.60","0.063"],["64006.00","0.604"],["64006.50","0.017"],["64006.60","0.047"],["64006.70","0.000"],["64006.80","0.017"],["64007.10","0.002"],["64007.20","0.546"],["64007.30","0.110"],["64007.50","0.145"],["64007.60","0.003"],["64007.70","0.001"],["64007.80","0.029"],["64008.60","0.013"],["64008.70","0.000"],["64009.10","0.043"],["64009.60","0.101"],["64009.70","0.349"],["64009.80","0.077"],["64009.90","0.756"],["64010.00","0.006"],["64011.50","0.002"],["64011.60","0.001"],["64011.90","0.001"],["64012.30","0.001"],["64012.80","0.023"],["64013.00","0.008"],["64013.10","0.135"],["64013.30","0.095"],["64013.40","2.854"],["64013.50","1.724"],["64014.00","0.366"],["64014.20","0.983"],["64014.30","0.000"],["64015.40","0.001"],["64015.50","0.000"],["64015.90","0.463"],["64016.10","0.047"],["64016.40","0.611"],["64016.50","3.056"],["64016.60","0.304"],["64016.80","0.001"],["64017.00","0.080"],["64017.30","0.015"],["64017.50","0.026"],["64017.60","0.029"],["64017.90","0.000"],["64018.00","1.103"],["64018.60","0.000"],["64018.70","0.000"],["64018.80","0.347"],["64019.10","1.726"],["64019.30","0.553"],["64019.70","0.006"],["64019.80","0.000"],["64019.90","2.657"],["64020.20","0.487"],["64020.50","0.234"],["64020.60","0.021"],["64020.70","0.001"],["64020.90","0.997"],["64021.10","0.000"],["64021.20","0.195"],["64021.30","0.075"],["64021.40","1.081"],["64021.70","0.044"],["64021.90","0.010"],["64022.30","1.698"],["64022.60","1.252"],["64022.70","0.634"],["64022.80","0.266"],["64023.10","0.240"],["64023.20","0.000"],["64023.30","1.075"],["64023.40","1.100"],["64023.60","0.012"],["64023.70","0.000"],["64023.80","0.235"],["64023.90","0.350"],["64024.00","0.008"],["64024.20","0.001"],["64024.40","0.969"],["64025.00","0.014"],["64025.30","0.087"],["64025.40","0.015"],["64025.60","3.232"],["64025.70","2.478"],["64025.80","0.003"],["64025.90","0.008"],["64026.00","0.542"],["64026.20","0.630"],["64026.50","0.000"],["64026.60","0.511"],["64026.70","0.001"],["64026.90","0.036"],["64027.30","0.018"],["64027.40","0.004"],["64027.60","0.000"],["64027.80","0.000"],["64027.90","0.000"],["64028.00","0.055"],["64028.20","0.023"],["64028.60","0.162"],["64028.70","0.420"],["64029.00","0.003"],["64029.10","1.249"],["64029.40","0.002"],["64029.60","0.102"],["64029.90","0.001"],["64030.00","0.254"],["64030.10","0.610"],["64030.20","0.003"],["64030.30","0.002"],["64030.60","0.060"],["64030.80","0.198"],["64031.00","0.002"],["64031.10","0.000"],["64031.40","0.721"],["64031.50","0.001"],["64031.60","0.000"],["64031.70","0.004"],["64032.00","0.675"],["64032.20","0.064"],["64032.30","0.002"],["64032.70","0.006"],["64032.80","0.003"],["64033.00","0.389"],["64033.20","0.122"],["64033.30","0.180"],["64033.50","0.801"],["64033.60","0.062"],["64034.00","0.037"],["64034.10","0.002"],["64034.20","0.003"],["64034.60","0.001"],["64034.70","0.001"],["64034.90","0.000"],["64035.20","1.381"],["64035.50","0.232"],["64035.70","1.171"],["64035.80","0.002"],["64035.90","0.021"],["64036.10","0.352"],["64036.30","0.000"],["64036.60","0.609"],["64036.80","0.086"],["64036.90","0.021"],["64037.50","0.004"],["64037.70","0.000"],["64037.80","0.002"],["64037.90","0.019"],["64038.30","0.382"],["64038.40","0.381"],["64038.60","0.002"],["64038.70","0.047"],["64038.80","0.000"],["64039.00","0.018"],["64039.20","0.060"],["64039.30","0.001"],["64039.40","0.000"],["64039.50","0.017"],["64039.80","0.000"],["64039.90","0.002"],["64040.10","0.105"],["64040.40","0.001"],["64040.70","0.022"],["64040.80","0.015"],["64040.90","10.000"],["64041.00","1.594"],["64041.10","0.001"],["64041.20","0.001"],["64041.40","0.000"],["64041.50","0.000"],["64041.80","0.762"],["64041.90","0.424"],["64042.10","0.236"],["64042.20","0.110"],["64042.30","0.000"],["64042.40","0.372"],["64042.50","2.342"],["64042.60","2.969"],["64042.70","1.250"],["64042.80","0.047"],["64043.10","0.293"],["64043.20","0.003"],["64043.50","0.002"],["64043.60","0.152"],["64043.70","0.011"],["64043.80","0.000"],["64044.00","0.005"],["64044.30","0.001"],["64044.50","0.002"],["64044.60","0.000"],["64044.70","0.460"],["64044.80","0.741"],["64044.90","0.000"],["64045.00","0.002"],["64045.10","0.002"],["64045.20","0.156"],["64045.30","2.342"],["64045.40","0.000"],["64045.50","0.001"],["64045.60","0.098"],["64045.70","1.009"],["64045.80","4.378"],["64045.90","0.289"],["64046.00","1.489"],["64046.10","0.001"],["64046.30","0.303"],["64046.40","0.494"],["64046.50","1.396"],["64046.60","0.165"],["64046.70","0.163"],["64046.80","0.165"],["64046.90","0.002"],["64047.00","0.477"],["64047.10","0.445"],["64047.20","0.158"],["64047.30","0.111"],["64047.40","0.001"],["64047.50","0.943"],["64047.60","0.020"],["64047.70","0.000"],["64047.80","1.108"],["64047.90","2.928"],["64048.00","0.163"],["64048.10","0.157"],["64048.20","0.163"],["64048.30","0.455"],["64048.40","0.000"],["64048.50","0.001"],["64048.60","2.259"],["64048.70","4.555"],["64048.80","0.002"],["64048.90","4.870"],["64049.00","1.483"],["64049.10","5.219"],["64049.20","0.163"],["64049.30","0.000"],["64049.40","0.001"],["64049.50","14.129"],["64049.60","2.718"],["64049.70","2.651"],["64049.80","11.074"],["64049.90","24.549"],["64050.00","0.019"],["64050.10","0.001"],["64050.20","1.079"],["64050.30","0.884"],["64050.60","0.000"],["64051.00","0.000"],["64051.10","3.377"],["64051.30","0.000"],["64051.40","0.001"],["64051.50","11.956"]],"e":"depthUpdate","ps":"BTCUSDT","pu":11165393728680,"s":"BTCUSDT","st":1,"u":11165393770155}
{"E":1785353516372,"T":1785353516371,"U":11165393770159,"a":[["64051.60","0.000"],["64051.70","0.000"],["64052.00","0.000"],["64052.10","0.000"],["64052.20","0.000"],["64052.30","0.000"],["64052.40","0.000"],["64052.50","0.000"],["64052.60","0.000"],["64052.70","0.000"],["64052.80","0.000"],["64053.00","0.000"],["64053.10","0.000"],["64053.20","0.000"],["64053.30","0.000"],["64053.40","0.000"],["64053.50","0.000"],["64053.60","0.000"],["64053.70","0.000"],["64053.80","0.000"],["64053.90","0.000"],["64054.00","0.000"],["64054.10","0.000"],["64054.20","0.000"],["64054.30","0.000"],["64054.40","0.000"],["64054.50","0.000"],["64054.60","0.000"],["64054.70","0.000"],["64054.80","0.000"],["64054.90","0.000"],["64055.00","0.536"],["64055.10","0.017"],["64055.20","0.206"],["64055.30","0.000"],["64055.40","0.000"],["64055.50","0.000"],["64055.80","0.001"],["64056.00","0.004"],["64056.10","0.001"],["64056.20","0.002"],["64056.30","0.001"],["64056.40","0.001"],["64056.50","0.000"],["64056.70","0.002"],["64056.80","0.001"],["64056.90","0.000"],["64057.00","0.000"],["64057.10","0.003"],["64057.20","0.001"],["64057.30","0.001"],["64057.40","0.001"],["64057.50","0.001"],["64057.70","0.007"],["64057.80","0.001"],["64057.90","0.000"],["64058.00","0.001"],["64058.20","0.140"],["64058.60","0.001"],["64058.70","0.001"],["64058.80","0.002"],["64058.90","0.041"],["64059.00","1.947"],["64059.10","0.005"],["64059.40","0.003"],["64059.50","0.004"],["64059.60","0.006"],["64059.80","0.047"],["64060.00","0.008"],["64060.10","0.000"],["64060.20","0.001"],["64060.30","0.002"],["64060.40","0.002"],["64060.50","0.004"],["64060.60","0.002"],["64060.80","0.008"],["64060.90","0.005"],["64061.00","0.173"],["64061.10","0.000"],["64061.20","0.002"],["64061.30","0.439"],["64061.40","0.418"],["64061.50","0.001"],["64061.60","0.002"],["64061.70","0.212"],["64061.80","0.006"],["64061.90","0.257"],["64062.10","0.016"],["64062.20","0.004"],["64062.30","0.000"],["64062.50","0.004"],["64062.80","0.014"],["64063.20","0.015"],["64063.40","0.769"],["64063.50","0.257"],["64063.60","0.445"],["64063.70","0.000"],["64063.80","0.002"],["64064.00","0.019"],["64064.10","0.000"],["64064.20","0.315"],["64064.40","0.187"],["64064.50","0.002"],["64064.60","0.160"],["64064.70","0.906"],["64064.80","0.015"],["64065.10","0.001"],["64065.30","0.940"],["64065.40","0.002"],["64065.50","0.005"],["64065.60","0.003"],["64065.70","0.185"],["64065.90","0.002"],["64066.00","0.320"],["64066.10","0.000"],["64066.20","0.000"],["64066.30","0.000"],["64066.40","0.000"],["64066.60","0.013"],["64066.70","0.165"],["64066.80","1.381"],["64066.90","0.161"],["64067.00","2.340"],["64067.10","1.442"],["64067.20","0.165"],["64067.30","1.720"],["64067.40","0.001"],["64067.50","0.010"],["64067.60","0.001"],["64067.80","0.321"],["64067.90","0.003"],["64068.00","0.118"],["64068.10","0.017"],["64068.20","0.004"],["64068.40","0.009"],["64068.50","0.062"],["64068.60","0.002"],["64068.70","0.021"],["64068.80","0.001"],["64068.90","0.010"],["64069.00","0.000"],["64069.10","0.002"],["64069.20","0.002"],["64069.30","0.013"],["64069.40","0.316"],["64069.50","0.000"],["64069.60","0.003"],["64069.80","4.339"],["64069.90","0.001"],["64070.10","0.000"],["64070.20","0.315"],["64070.30","0.002"],["64070.40","0.012"],["64070.60","0.635"],["64070.80","0.014"],["64071.10","0.003"],["64071.20","0.562"],["64071.30","0.041"],["64071.40","0.003"],["64071.50","0.002"],["64071.70","0.001"],["64071.80","0.121"],["64072.00","0.009"],["64072.10","0.048"],["64072.20","0.028"],["64072.40","0.122"],["64072.60","0.003"],["64072.70","0.118"],["64072.80","0.013"],["64073.00","0.379"],["64073.10","0.106"],["64073.30","0.001"],["64073.40","0.003"],["64073.50","0.335"],["64073.60","1.553"],["64073.70","2.343"],["64073.80","0.699"],["64073.90","0.212"],["64074.00","0.147"],["64074.10","3.397"],["64074.50","0.228"],["64074.60","10.658"],["64074.80","0.000"],["64074.90","0.002"],["64075.10","0.003"],["64075.30","0.001"],["64075.40","1.061"],["64075.60","0.314"],["64075.80","0.001"],["64075.90","0.010"],["64076.40","0.085"],["64076.50","0.002"],["64076.60","0.166"],["64076.70","2.342"],["64076.80","0.080"],["64076.90","2.071"],["64077.00","1.873"],["64077.10","0.001"],["64077.20","0.000"],["64077.30","0.000"],["64077.50","0.107"],["64077.80","0.032"],["64077.90","0.000"],["64078.10","0.000"],["64078.20","0.124"],["64078.30","9.871"],["64078.40","1.637"],["64078.50","1.855"],["64078.60","0.156"],["64078.90","0.135"],["64079.00","0.041"],["64079.20","0.001"],["64079.30","0.013"],["64079.50","0.327"],["64079.70","0.174"],["64079.80","0.002"],["64079.90","0.377"],["64080.00","0.797"],["64080.10","1.272"],["64080.20","0.025"],["64080.50","0.118"],["64080.80","0.095"],["64081.00","0.025"],["64081.20","0.051"],["64081.30","0.009"],["64081.40","0.004"],["64081.50","0.001"],["64081.60","0.951"],["64081.70","0.002"],["64081.80","0.000"],["64082.30","0.002"],["64082.40","2.948"],["64082.60","0.018"],["64082.70","3.566"],["64083.00","0.003"],["64083.20","0.052"],["64083.30","0.094"],["64083.40","0.543"],["64083.50","1.068"],["64083.60","0.013"],["64083.70","0.036"],["64083.90","0.356"],["64084.00","0.378"],["64084.10","0.337"],["64084.20","0.126"],["64084.50","0.100"],["64084.90","0.161"],["64085.00","0.237"],["64085.30","0.000"],["64085.40","0.134"],["64085.50","1.263"],["64085.60","0.858"],["64085.80","0.061"],["64085.90","0.002"],["64086.20","0.001"],["64086.30","0.001"],["64086.40","0.008"],["64086.60","0.302"],["64086.70","0.040"],["64086.90","0.834"],["64087.00","0.641"],["64087.10","0.018"],["64087.30","0.985"],["64087.70","0.061"],["64087.90","0.007"],["64088.60","0.077"],["64088.90","0.014"],["64089.20","0.005"],["64089.40","0.015"],["64089.50","0.063"],["64089.60","1.889"],["64089.90","0.016"],["64090.10","0.020"],["64090.20","0.174"],["64090.30","1.084"],["64090.40","0.013"],["64090.60","0.389"],["64090.70","0.003"],["64090.90","0.899"],["64091.00","0.004"],["64091.10","0.355"],["64091.30","0.001"],["64091.50","0.659"],["64091.80","0.014"],["64091.90","0.524"],["64092.10","0.000"],["64092.80","0.006"],["64093.10","0.090"],["64093.40","0.001"],["64093.50","0.259"],["64093.70","0.000"],["64093.80","0.001"],["64093.90","0.848"],["64094.00","0.672"],["64094.10","0.033"],["64094.20","2.013"],["64094.30","0.112"],["64094.90","0.395"],["64095.10","0.005"],["64095.30","0.001"],["64095.70","0.001"],["64095.80","2.002"],["64096.40","0.169"],["64096.50","0.003"],["64096.70","0.037"],["64096.90","0.073"],["64097.10","0.762"],["64097.20","2.573"],["64097.30","0.216"],["64097.40","0.172"],["64097.70","0.430"],["64098.50","0.003"],["64098.80","0.046"],["64099.00","0.024"],["64099.10","0.000"],["64099.20","2.942"],["64099.40","0.001"],["64099.50","0.001"],["64099.60","1.060"],["64100.00","2.693"],["64100.10","0.468"],["64100.30","0.004"],["64100.90","0.001"],["64101.00","0.001"],["64101.10","0.001"],["64101.40","0.000"],["64101.70","0.025"],["64101.80","0.005"],["64102.10","0.005"],["64102.40","0.023"],["64102.50","0.287"],["64103.30","0.502"],["64103.70","0.063"],["64103.80","1.488"],["64104.20","2.542"],["64104.60","0.005"],["64104.70","0.019"],["64105.00","0.103"],["64105.40","0.060"],["64106.40","0.506"],["64107.00","0.006"],["64107.60","0.000"],["64108.30","0.091"],["64108.50","0.000"],["64108.60","0.596"],["64109.50","1.469"],["64109.60","0.003"],["64109.80","0.017"],["64110.00","0.009"],["64110.30","0.004"],["64111.30","0.004"],["64111.80","0.036"],["64112.00","0.136"],["64112.10","0.000"],["64112.40","0.086"],["64112.50","0.003"],["64112.60","0.481"],["64113.20","0.009"],["64114.30","0.059"],["64114.50","0.000"],["64115.20","0.041"],["64115.60","0.015"],["64116.00","0.006"],["64116.40","0.000"],["64118.20","2.374"],["64118.90","0.438"],["64119.10","0.378"],["64119.60","0.004"],["64121.00","0.211"],["64121.10","0.247"],["64121.70","2.165"],["64121.80","6.397"],["64121.90","2.821"],["64122.50","0.501"],["64123.90","0.103"],["64124.00","0.049"],["64125.90","0.511"],["64126.50","0.471"],["64126.60","0.327"],["64127.70","0.101"],["64128.00","0.023"],["64128.90","0.077"],["64129.70","0.254"],["64130.20","0.025"],["64130.70","0.001"],["64131.90","0.002"],["64132.90","0.000"],["64133.90","0.005"],["64134.00","0.619"],["64134.50","0.370"],["64134.60","2.072"],["64135.20","0.009"],["64135.70","0.001"],["64136.80","0.054"],["64137.60","0.170"],["64137.80","1.381"],["64138.20","0.168"],["64139.00","0.158"],["64140.50","0.531"],["64141.60","0.000"],["64141.70","0.205"],["64142.00","0.004"],["64142.30","0.000"],["64143.10","0.014"],["64143.70","0.049"],["64144.00","0.002"],["64144.20","0.656"],["64144.30","2.336"],["64144.70","0.120"],["64145.30","0.000"],["64145.60","0.028"],["64148.50","0.001"],["64148.60","0.179"],["64149.40","0.000"],["64150.40","0.018"],["64150.90","0.057"],["64151.00","0.111"],["64151.30","0.524"],["64152.50","0.003"],["64152.70","0.500"],["64152.80","3.122"],["64154.30","0.002"],["64154.80","0.017"],["64156.20","2.342"],["64157.90","0.212"],["64158.10","0.004"],["64163.90","0.010"],["64164.60","0.781"],["64165.10","2.571"],["64166.40","4.769"],["64166.70","0.001"],["64167.30","23.717"],["64167.60","0.211"],["64168.00","0.033"],["64168.10","0.000"],["64168.70","0.491"],["64168.80","0.000"],["64171.00","0.781"],["64171.50","0.532"],["64176.00","1.239"],["64176.10","2.344"],["64177.20","0.537"],["64177.40","1.275"],["64178.20","0.000"],["64178.30","0.543"],["64179.20","2.273"],["64179.80","3.904"],["64181.20","0.000"],["64183.00","0.254"],["64183.10","0.004"],["64183.20","0.004"],["64185.00","0.123"],["64185.10","0.056"],["64185.40","0.782"],["64186.30","0.951"],["64186.50","0.000"],["64187.20","0.000"],["64188.20","0.500"],["64188.80","0.494"],["64189.20","0.000"],["64189.50","0.001"],["64190.10","0.518"],["64191.20","2.343"],["64192.30","0.676"],["64193.20","0.718"],["64195.20","0.007"],["64195.80","0.000"],["64196.60","0.000"],["64197.20","0.000"],["64198.60","0.000"],["64198.80","0.648"],["64199.20","0.003"],["64200.60","0.005"],["64201.20","0.494"],["64202.60","0.003"],["64202.90","0.273"],["64203.20","0.000"],["64204.60","0.720"],["64204.90","0.006"],["64205.20","0.008"],["64206.10","0.002"],["64206.40","0.878"],["64206.60","0.008"],["64207.20","0.000"],["64208.60","0.004"],["64209.20","0.000"],["64210.60","0.001"],["64211.20","2.531"],["64211.60","0.000"],["64213.60","0.308"],["64220.10","0.750"],["64221.10","0.489"],["64226.60","0.002"],["64227.20","0.021"],["64228.20","0.000"],["64231.80","0.002"],["64233.50","0.013"],["64235.00","0.000"],["64240.10","3.994"],["64241.90","0.151"],["64246.60","0.003"],["64246.80","0.090"],["64264.80","0.508"],["64268.80","0.242"],["64270.90","0.000"],["64279.70","1.696"],["64279.80","9.601"],["64280.00","0.035"],["64290.40","0.502"],["64297.60","0.000"],["64304.20","0.000"],["64311.20","0.386"],["64318.40","0.258"],["64318.50","0.540"],["64318.60","0.538"],["64319.30","0.000"],["64321.70","0.536"],["64326.40","1.050"],["64326.60","0.007"],["64330.80","0.225"],["64331.00","0.004"],["64331.20","0.117"],["64331.40","0.000"],["64333.40","0.117"],["64345.40","0.000"],["64361.70","0.056"],["64365.00","0.049"],["64365.20","0.144"],["64368.20","0.000"],["64370.20","0.000"],["64371.60","0.109"],["64372.10","0.299"],["64372.90","0.299"],["64374.20","0.002"],["64374.70","0.151"],["64376.40","0.066"],["64432.10","0.000"],["64438.70","0.001"],["64496.30","0.000"],["64502.80","0.001"],["64522.80","0.000"],["64531.70","0.000"],["64532.00","0.000"],["64549.20","0.004"],["64560.20","0.000"],["64563.50","0.000"],["64566.80","0.001"],["64596.90","2.268"],["64686.30","0.002"],["64689.20","0.000"],["64689.50","0.000"],["64689.70","0.000"],["64690.10","1.227"],["64690.50","0.000"],["64692.10","0.000"],["64693.10","6.120"],["64695.60","0.012"],["64782.40","0.002"],["64785.70","0.228"],["64786.20","0.000"],["64786.30","0.011"],["64786.40","0.001"],["64788.10","0.018"],["64789.70","12.104"],["64791.30","1.029"],["64792.10","0.918"],["64821.00","2.013"],["64821.10","11.156"],["64849.60","0.027"],["64849.70","0.000"],["64850.30","0.000"],["64850.40","0.002"],["64853.80","7.650"],["64854.90","1.864"],["64855.30","3.019"],["64916.20","0.000"],["64948.20","0.000"],["64949.10","2.286"],["64949.20","12.220"],["64981.30","4.575"],["64987.70","0.766"],["64995.40","1.036"],["65012.20","0.000"],["65045.30","5.325"],["65322.60","0.141"],["65333.60","0.026"],["67252.10","0.064"]],"b":[["1000.00","37.592"],["13541.70","0.700"],["13649.10","0.014"],["13649.90","0.014"],["13652.50","0.112"],["13745.70","0.028"],["13851.50","0.014"],["13852.50","0.098"],["13854.90","0.014"],["13941.70","0.210"],["13949.50","0.014"],["13949.90","0.014"],["13951.50","0.014"],["13952.50","0.098"],["13954.90","0.014"],["57644.00","0.050"],["57644.50","0.051"],["57646.30","0.000"],["57647.20","0.000"],["57649.40","0.002"],["62760.90","1.051"],["62773.90","0.008"],["62965.90","0.000"],["63038.80","0.009"],["63044.70","0.000"],["63045.20","0.002"],["63045.70","0.004"],["63048.60","0.787"],["63049.50","0.009"],["63052.50","0.021"],["63054.90","0.016"],["63082.20","11.696"],["63114.20","20.879"],["63117.00","6.711"],["63149.10","5.494"],["63210.20","6.582"],["63226.70","0.000"],["63242.20","21.471"],["63245.10","3.883"],["63277.20","3.132"],["63307.70","0.000"],["63408.60","1.594"],["63409.00","1.877"],["63412.00","0.007"],["63413.80","0.000"],["63414.40","0.006"],["63596.40","0.000"],["63603.10","0.004"],["63619.60","0.002"],["63677.10","0.002"],["63678.80","0.179"],["63700.00","18.172"],["63706.80","0.000"],["63708.30","0.067"],["63709.60","0.043"],["63718.00","0.106"],["63721.60","0.010"],["63722.80","0.000"],["63744.10","0.029"],["63754.30","0.003"],["63773.70","0.621"],["63774.20","4.436"],["63778.40","0.525"],["63778.90","0.157"],["63787.60","0.000"],["63788.50","0.010"],["63795.30","0.001"],["63799.20","0.000"],["63812.00","0.018"],["63812.50","0.005"],["63825.30","0.096"],["63843.20","0.002"],["63849.70","0.076"],["63852.60","1.340"],["63856.10","0.000"],["63858.20","0.029"],["63862.50","0.000"],["63863.80","2.414"],["63864.20","0.069"],["63864.40","0.071"],["63865.60","3.485"],["63866.70","0.117"],["63872.30","0.234"],["63875.30","0.026"],["63876.20","0.000"],["63877.50","0.000"],["63877.90","0.000"],["63878.30","0.783"],["63879.20","0.502"],["63879.80","0.006"],["63880.60","0.000"],["63880.90","0.004"],["63882.30","0.001"],["63882.40","0.499"],["63884.80","0.528"],["63885.10","0.013"],["63885.40","0.022"],["63885.50","0.011"],["63887.30","0.009"],["63887.90","0.000"],["63889.30","0.001"],["63889.40","0.020"],["63891.40","5.514"],["63892.50","0.047"],["63892.60","0.001"],["63894.30","0.000"],["63895.00","0.003"],["63896.10","0.126"],["63896.20","0.001"],["63897.70","0.229"],["63898.70","0.399"],["63898.80","0.124"],["63900.00","9.324"],["63903.00","0.245"],["63909.50","0.034"],["63909.80","0.000"],["63910.40","1.770"],["63911.70","0.004"],["63913.60","3.076"],["63913.70","2.341"],["63914.90","0.081"],["63915.20","0.000"],["63915.30","2.270"],["63916.40","1.170"],["63917.30","0.507"],["63920.30","0.000"],["63920.90","0.035"],["63921.30","0.000"],["63921.70","0.094"],["63923.60","3.903"],["63925.70","0.242"],["63926.20","1.857"],["63926.40","0.502"],["63929.10","1.482"],["63932.40","0.001"],["63932.90","0.027"],["63933.40","0.030"],["63933.90","0.000"],["63934.10","0.000"],["63934.70","0.000"],["63936.60","0.063"],["63937.30","0.001"],["63938.50","0.374"],["63939.10","0.000"],["63940.10","0.600"],["63940.50","0.010"],["63942.00","0.782"],["63942.10","0.511"],["63945.90","0.092"],["63946.30","0.574"],["63947.60","0.032"],["63948.50","0.075"],["63950.30","0.010"],["63950.80","0.498"],["63950.90","0.583"],["63952.10","0.203"],["63952.60","0.027"],["63954.40","0.001"],["63954.60","1.549"],["63955.20","0.031"],["63956.40","2.841"],["63956.60","0.003"],["63957.20","0.055"],["63957.60","0.481"],["63958.00","0.000"],["63958.10","0.554"],["63960.80","0.001"],["63963.30","0.394"],["63964.70","0.491"],["63965.90","0.000"],["63966.60","0.568"],["63967.10","0.000"],["63968.00","0.506"],["63968.90","0.003"],["63969.10","0.148"],["63969.80","0.238"],["63969.90","0.083"],["63970.00","0.484"],["63970.30","0.064"],["63971.00","0.453"],["63972.00","0.004"],["63972.50","0.000"],["63973.00","0.062"],["63973.30","0.936"],["63973.70","0.147"],["63973.80","0.001"],["63975.50","3.124"],["63977.30","0.746"],["63977.40","0.500"],["63977.90","0.506"],["63978.50","0.002"],["63979.60","0.609"],["63981.30","0.000"],["63981.40","1.254"],["63982.90","0.002"],["63983.40","0.017"],["63984.10","0.004"],["63984.80","2.142"],["63984.90","0.022"],["63985.80","0.000"],["63987.10","0.094"],["63987.40","0.000"],["63988.00","0.111"],["63988.40","0.062"],["63988.50","0.201"],["63988.60","0.521"],["63988.90","0.001"],["63989.60","0.184"],["63989.70","0.072"],["63990.00","0.062"],["63990.40","2.006"],["63991.80","0.000"],["63992.20","0.074"],["63992.40","0.006"],["63992.60","0.003"],["63992.90","0.072"],["63993.60","0.722"],["63993.70","0.027"],["63994.30","0.000"],["63994.50","0.031"],["63994.60","1.255"],["63994.70","0.003"],["63994.90","0.004"],["63995.70","2.038"],["63995.80","0.000"],["63996.00","0.002"],["63996.90","0.030"],["63997.00","0.000"],["63997.70","2.336"],["63998.00","0.005"],["63998.40","0.006"],["63998.50","0.025"],["63998.60","0.000"],["63998.70","0.000"],["63999.00","0.906"],["63999.20","0.000"],["63999.40","0.258"],["63999.60","0.001"],["63999.90","0.001"],["64000.00","10.993"],["64000.30","0.676"],["64000.40","0.000"],["64001.20","0.062"],["64001.30","0.314"],["64001.60","0.009"],["64001.90","0.004"],["64002.20","0.060"],["64002.30","0.588"],["64002.40","0.003"],["64002.70","2.342"],["64002.80","0.000"],["64003.00","0.001"],["64003.10","0.001"],["64003.20","3.869"],["64003.40","0.001"],["64003.50","0.000"],["64003.80","0.003"],["64003.90","0.532"],["64004.00","0.002"],["64004.40","0.005"],["64004.50","0.005"],["64004.70","0.003"],["64005.10","0.060"],["64005.30","0.313"],["64005.70","0.005"],["64005.90","0.060"],["64006.00","0.379"],["64006.10","0.001"],["64006.30","0.063"],["64006.50","0.016"],["64006.80","0.011"],["64008.10","0.085"],["64008.40","0.107"],["64008.50","0.713"],["64009.10","0.018"],["64009.50","0.532"],["64009.80","0.109"],["64009.90","0.781"],["64011.20","0.096"],["64011.80","0.116"],["64012.70","0.007"],["64012.90","0.021"],["64013.00","0.004"],["64013.10","0.135"],["64013.30","0.095"],["64013.40","2.886"],["64013.50","1.748"],["64013.60","0.002"],["64013.70","0.000"],["64014.10","0.531"],["64014.50","0.000"],["64014.60","1.250"],["64015.00","0.531"],["64015.40","0.000"],["64015.60","0.001"],["64015.80","0.011"],["64016.30","0.096"],["64016.40","0.845"],["64016.60","0.064"],["64016.70","0.001"],["64016.80","0.347"],["64017.00","0.004"],["64017.30","0.003"],["64017.50","0.007"],["64017.60","0.004"],["64017.70","0.021"],["64017.80","0.472"],["64018.00","0.541"],["64018.20","0.002"],["64018.50","0.003"],["64018.60","0.000"],["64018.80","0.007"],["64019.10","1.151"],["64019.40","0.006"],["64020.00","0.012"],["64020.10","0.315"],["64020.20","0.048"],["64020.40","0.002"],["64020.50","0.117"],["64020.60","0.000"],["64020.80","0.924"],["64020.90","0.002"],["64021.00","0.002"],["64021.20","0.195"],["64021.30","0.005"],["64021.50","0.000"],["64021.80","0.092"],["64022.20","0.060"],["64022.30","1.554"],["64022.50","0.013"],["64022.80","0.263"],["64022.90","0.007"],["64023.10","0.094"],["64023.30","1.077"],["64023.40","1.099"],["64023.50","0.000"],["64023.60","0.000"],["64023.70","0.538"],["64023.80","0.001"],["64023.90","0.299"],["64024.00","0.009"],["64024.10","0.020"],["64024.30","0.051"],["64024.60","0.000"],["64024.90","0.121"],["64025.00","0.014"],["64025.20","0.314"],["64025.40","0.577"],["64025.60","2.299"],["64025.70","2.648"],["64025.80","0.521"],["64025.90","0.007"],["64026.20","1.739"],["64026.30","0.641"],["64026.40","0.007"],["64026.60","0.508"],["64026.80","0.050"],["64026.90","0.043"],["64027.10","0.046"],["64027.30","0.000"],["64027.40","0.021"],["64027.60","0.977"],["64027.80","0.004"],["64028.10","0.001"],["64028.20","0.004"],["64028.40","2.227"],["64028.50","0.384"],["64028.60","0.044"],["64028.80","0.089"],["64028.90","0.523"],["64029.00","0.139"],["64029.10","1.749"],["64029.20","0.312"],["64029.40","0.012"],["64029.60","0.053"],["64029.80","0.001"],["64030.00","0.958"],["64030.20","0.002"],["64030.60","0.063"],["64030.90","0.017"],["64031.10","0.000"],["64031.40","0.382"],["64031.50","0.008"],["64031.60","0.000"],["64031.70","0.003"],["64031.80","0.708"],["64032.00","0.688"],["64032.20","0.064"],["64032.50","0.007"],["64032.60","0.004"],["64032.70","0.024"],["64032.80","0.002"],["64032.90","0.052"],["64033.00","0.376"],["64033.20","0.122"],["64033.40","0.178"],["64033.50","0.800"],["64033.60","0.002"],["64033.80","0.353"],["64034.00","0.268"],["64034.10","0.001"],["64034.20","0.010"],["64034.40","0.003"],["64034.60","0.003"],["64034.70","0.000"],["64034.80","2.393"],["64035.20","1.385"],["64035.30","0.011"],["64035.40","0.504"],["64035.60","0.004"],["64035.70","0.000"],["64035.90","0.000"],["64036.10","0.016"],["64036.40","0.006"],["64036.50","0.002"],["64036.70","0.049"],["64036.80","0.123"],["64036.90","0.063"],["64037.00","0.036"],["64037.10","0.060"],["64037.20","0.236"],["64037.30","0.000"],["64037.70","0.000"],["64037.90","0.001"],["64038.00","0.004"],["64038.30","0.581"],["64038.60","0.004"],["64038.70","0.047"],["64038.80","0.000"],["64038.90","0.002"],["64039.10","0.026"],["64039.20","0.062"],["64039.30","0.002"],["64039.50","0.003"],["64039.80","0.002"],["64039.90","0.000"],["64040.00","0.042"],["64040.10","0.001"],["64040.30","0.018"],["64040.40","0.529"],["64040.90","10.011"],["64041.00","0.158"],["64041.20","0.001"],["64041.60","0.005"],["64041.70","4.638"],["64041.80","0.759"],["64041.90","1.080"],["64042.00","0.067"],["64042.10","0.235"],["64042.20","0.446"],["64042.40","0.371"],["64042.60","0.001"],["64042.70","1.266"],["64042.90","0.094"],["64043.10","0.001"],["64043.20","0.003"],["64043.60","0.001"],["64043.70","0.002"],["64043.80","3.375"],["64044.60","0.000"],["64044.70","0.324"],["64044.80","0.605"],["64045.00","0.002"],["64045.10","0.001"],["64045.20","0.000"],["64045.30","2.342"],["64045.40","0.019"],["64045.70","0.803"],["64045.80","1.333"],["64045.90","0.185"],["64046.00","0.610"],["64046.10","0.002"],["64046.20","0.001"],["64046.30","0.244"],["64046.40","0.001"],["64046.50","0.395"],["64046.60","0.002"],["64046.70","0.000"],["64046.80","0.009"],["64047.00","0.314"],["64047.10","1.886"],["64047.20","0.001"],["64047.30","0.002"],["64047.50","0.001"],["64047.60","0.001"],["64047.70","0.001"],["64047.80","0.003"],["64047.90","2.340"],["64048.00","0.001"],["64048.10","0.000"],["64048.20","0.001"],["64048.30","0.002"],["64048.40","0.001"],["64048.50","0.128"],["64048.60","0.878"],["64048.70","2.502"],["64048.80","0.065"],["64048.90","0.083"],["64049.00","0.001"],["64049.10","1.507"],["64049.20","0.009"],["64049.30","0.001"],["64049.40","0.001"],["64049.50","0.203"],["64049.60","2.502"],["64049.70","0.525"],["64049.80","0.010"],["64049.90","0.316"],["64050.00","0.004"],["64050.10","0.001"],["64050.20","0.000"],["64050.30","0.003"],["64050.40","2.100"],["64050.50","0.000"],["64050.60","0.000"],["64050.70","0.001"],["64050.90","0.004"],["64051.00","0.009"],["64051.10","2.342"],["64051.20","0.041"],["64051.30","0.257"],["64051.40","0.001"],["64051.50","0.252"],["64051.60","0.003"],["64051.70","0.000"],["64051.80","0.723"],["64051.90","0.001"],["64052.00","0.000"],["64052.10","0.001"],["64052.20","0.000"],["64052.30","0.000"],["64052.40","0.001"],["64052.50","3.932"],["64052.60","2.505"],["64052.70","0.433"],["64052.80","0.001"],["64052.90","0.000"],["64053.00","0.000"],["64053.10","0.003"],["64053.30","0.000"],["64053.40","0.001"],["64053.60","0.001"],["64053.70","0.000"],["64053.80","0.001"],["64053.90","0.000"],["64054.00","0.018"],["64054.10","0.000"],["64054.20","0.002"],["64054.30","3.935"],["64054.40","0.002"],["64054.50","0.000"],["64054.60","0.071"],["64054.70","0.006"],["64054.80","0.018"],["64054.90","16.900"]],"e":"depthUpdate","ps":"BTCUSDT","pu":11165393770155,"s":"BTCUSDT","st":1,"u":11165393811005}
{"E":1785353516474,"T":1785353516472,"U":11165393811018,"a":[["64055.00","3.471"],["64055.10","0.003"],["64055.80","0.000"],["64056.00","0.003"],["64056.70","0.000"],["64057.70","0.010"],["64057.80","0.005"],["64058.10","0.045"],["64058.40","0.001"],["64058.80","0.006"],["64058.90","0.001"],["64059.00","0.038"],["64059.40","0.001"],["64059.60","0.006"],["64059.80","0.047"],["64060.00","0.007"],["64060.50","0.001"],["64060.70","0.002"],["64061.00","0.002"],["64061.30","0.001"],["64061.40","0.593"],["64061.70","0.525"],["64061.90","0.000"],["64062.00","0.003"],["64062.60","0.057"],["64062.70","0.086"],["64062.80","0.170"],["64062.90","1.051"],["64063.20","0.170"],["64063.30","0.567"],["64063.40","0.026"],["64063.50","0.000"],["64063.60","0.442"],["64063.70","0.093"],["64063.90","0.047"],["64064.00","0.260"],["64064.30","0.022"],["64064.40","2.523"],["64064.50","1.031"],["64064.60","0.706"],["64064.70","1.417"],["64064.80","0.003"],["64065.20","0.169"],["64065.40","0.004"],["64065.60","0.241"],["64065.80","0.000"],["64065.90","0.140"],["64066.10","0.306"],["64066.60","0.170"],["64066.70","0.890"],["64066.80","0.682"],["64067.10","2.440"],["64067.30","1.075"],["64068.40","0.009"],["64068.90","0.003"],["64069.20","0.003"],["64069.50","0.001"],["64069.60","0.254"],["64069.80","2.654"],["64069.90","0.002"],["64070.50","0.010"],["64071.30","0.001"],["64071.60","0.337"],["64071.70","0.001"],["64072.00","0.010"],["64072.60","0.003"],["64072.70","0.001"],["64073.30","0.004"],["64073.40","0.160"],["64073.50","0.649"],["64073.70","2.460"],["64074.10","3.402"],["64074.70","0.320"],["64075.30","0.294"],["64075.60","0.326"],["64075.90","0.001"],["64076.60","0.260"],["64076.90","0.008"],["64077.20","0.011"],["64077.50","0.480"],["64077.80","0.500"],["64077.90","0.136"],["64078.20","0.082"],["64078.40","1.617"],["64078.90","0.436"],["64079.00","0.001"],["64079.30","0.048"],["64079.40","0.126"],["64080.60","0.042"],["64080.80","0.001"],["64081.00","0.045"],["64081.80","0.094"],["64082.60","0.010"],["64083.20","0.060"],["64083.30","0.001"],["64083.40","0.539"],["64083.60","0.000"],["64083.70","0.004"],["64083.90","0.396"],["64084.10","0.341"],["64084.20","0.043"],["64084.30","0.100"],["64084.80","0.102"],["64085.00","0.235"],["64085.40","0.144"],["64085.60","0.860"],["64085.90","0.006"],["64086.00","0.051"],["64086.70","0.005"],["64086.90","1.038"],["64087.00","0.735"],["64087.20","1.751"],["64088.90","0.000"],["64089.40","0.001"],["64089.60","2.945"],["64090.40","0.001"],["64090.50","0.000"],["64091.00","0.003"],["64091.60","4.412"],["64091.70","0.001"],["64091.80","0.028"],["64091.90","10.526"],["64092.20","0.044"],["64092.60","0.012"],["64092.70","0.002"],["64093.10","0.002"],["64093.30","0.001"],["64093.50","1.080"],["64093.70","0.005"],["64093.90","1.303"],["64094.30","0.127"],["64094.50","0.002"],["64094.80","1.954"],["64095.10","0.006"],["64095.50","0.122"],["64095.70","0.033"],["64095.80","0.002"],["64096.00","1.079"],["64096.80","0.048"],["64096.90","0.001"],["64097.10","0.798"],["64097.40","0.004"],["64097.80","0.008"],["64098.10","0.003"],["64098.30","0.002"],["64099.00","0.000"],["64099.10","0.000"],["64099.20","1.475"],["64099.30","2.536"],["64099.70","1.946"],["64099.80","0.021"],["64100.10","0.000"],["64101.00","0.091"],["64101.30","0.976"],["64101.80","0.024"],["64102.00","0.634"],["64103.70","0.063"],["64103.80","1.487"],["64104.10","0.000"],["64104.80","0.197"],["64105.20","0.026"],["64105.30","1.042"],["64108.30","0.001"],["64110.30","0.000"],["64110.60","1.983"],["64113.50","0.005"],["64116.70","0.001"],["64117.20","0.001"],["64117.50","2.735"],["64118.00","0.002"],["64118.40","0.795"],["64120.80","0.000"],["64121.60","0.018"],["64123.90","0.130"],["64128.10","0.511"],["64130.40","0.106"],["64130.50","0.076"],["64131.00","0.083"],["64132.00","3.107"],["64135.90","0.016"],["64137.80","1.549"],["64138.00","0.151"],["64138.20","0.000"],["64138.50","0.349"],["64138.70","0.509"],["64139.40","0.246"],["64139.50","0.180"],["64140.50","0.614"],["64140.80","4.510"],["64143.20","0.003"],["64143.50","0.187"],["64144.30","2.336"],["64145.30","0.000"],["64145.90","0.000"],["64147.50","0.004"],["64148.20","0.215"],["64148.90","0.000"],["64160.20","1.257"],["64161.70","4.685"],["64166.40","1.471"],["64167.30","23.717"],["64174.70","0.000"],["64176.50","0.118"],["64186.80","0.325"],["64189.80","0.281"],["64196.50","0.000"],["64220.80","0.070"],["64220.90","1.775"],["64228.10","0.228"],["64234.40","0.001"],["64237.60","0.001"],["64240.00","1.597"],["64240.60","0.000"],["64247.50","1.949"],["64247.70","0.007"],["64256.00","0.884"],["64258.20","3.022"],["64266.00","2.467"],["64266.20","0.001"],["64324.10","1.837"],["64330.40","0.117"],["64331.20","0.000"],["64333.40","0.000"],["64353.30","0.000"],["64375.30","0.152"],["64384.10","0.802"],["64618.40","0.000"],["64623.90","0.540"],["64627.60","0.031"],["64687.70","0.002"],["64695.60","0.006"],["64789.70","1.100"],["64791.30","0.112"],["64792.20","5.533"],["64792.30","6.419"],["64853.80","0.020"],["64855.30","2.256"],["64856.10","3.052"],["64856.20","3.815"],["64856.30","3.817"],["64887.30","0.006"],["64896.70","0.800"],["64951.30","0.537"],["64951.80","2.306"],["64983.80","1.066"],["65170.00","4.039"]],"b":[["13541.70","0.588"],["13654.90","0.126"],["13741.70","0.784"],["13741.80","0.000"],["13745.20","0.000"],["13745.70","0.000"],["13854.90","0.140"],["13941.70","0.084"],["13954.90","0.126"],["57649.40","0.002"],["61492.70","0.003"],["62760.90","1.045"],["62773.90","0.014"],["63054.90","0.018"],["63274.30","3.134"],["63279.60","1.894"],["63312.60","7.115"],["63395.30","0.079"],["63401.30","0.514"],["63414.40","0.000"],["63438.10","0.015"],["63479.20","0.112"],["63803.80","0.146"],["63806.40","0.009"],["63829.80","0.004"],["63861.40","0.000"],["63876.40","0.310"],["63882.20","0.001"],["63886.80","0.001"],["63900.70","0.456"],["63901.30","0.126"],["63902.20","0.107"],["63904.90","1.310"],["63906.90","0.881"],["63908.90","0.881"],["63910.90","0.897"],["63912.90","0.883"],["63914.90","0.962"],["63915.30","2.271"],["63916.90","0.881"],["63918.90","0.946"],["63920.90","0.916"],["63930.30","0.026"],["63933.70","1.959"],["63933.80","0.013"],["63942.30","0.001"],["63943.10","0.001"],["63943.60","0.001"],["63952.10","0.215"],["63952.20","0.087"],["63958.50","0.020"],["63960.00","0.230"],["63961.30","0.103"],["63962.90","0.000"],["63969.60","0.064"],["63971.60","0.001"],["63972.00","0.003"],["63974.60","0.039"],["63975.30","0.268"],["63982.30","4.234"],["63988.60","0.496"],["63989.00","0.000"],["63990.50","0.548"],["63992.90","0.080"],["63993.20","0.003"],["63993.60","0.022"],["63993.80","1.755"],["63994.90","0.000"],["63996.00","0.001"],["63996.30","0.005"],["63998.20","0.027"],["64002.30","0.500"],["64002.50","0.404"],["64002.60","0.637"],["64003.30","0.336"],["64003.60","0.049"],["64003.80","0.000"],["64006.00","0.381"],["64007.10","0.001"],["64007.20","0.549"],["64007.70","0.000"],["64007.80","0.052"],["64008.30","0.001"],["64008.90","0.001"],["64009.40","0.529"],["64009.90","0.755"],["64010.10","0.317"],["64010.50","0.000"],["64011.00","0.001"],["64012.00","1.494"],["64013.50","0.027"],["64013.80","0.000"],["64014.10","0.559"],["64014.30","0.066"],["64016.40","1.020"],["64016.50","3.070"],["64016.80","0.287"],["64017.70","0.001"],["64019.00","0.025"],["64020.50","0.133"],["64022.50","0.012"],["64022.80","0.264"],["64022.90","1.728"],["64023.40","0.787"],["64023.70","0.554"],["64023.90","0.359"],["64025.30","0.100"],["64025.40","0.015"],["64025.60","2.298"],["64026.20","0.823"],["64026.30","0.363"],["64026.90","0.001"],["64028.80","0.709"],["64029.00","1.219"],["64029.10","2.322"],["64029.20","0.312"],["64029.30","0.322"],["64029.40","0.007"],["64030.00","0.963"],["64030.20","0.003"],["64030.50","0.000"],["64030.70","0.002"],["64030.90","0.035"],["64031.30","0.011"],["64031.70","0.137"],["64031.90","0.121"],["64032.00","1.854"],["64032.20","0.064"],["64032.70","0.006"],["64033.00","0.316"],["64033.10","0.070"],["64033.40","0.058"],["64033.50","1.112"],["64034.00","0.037"],["64034.40","10.003"],["64034.50","0.000"],["64035.40","0.472"],["64035.50","0.001"],["64035.90","0.001"],["64036.40","0.006"],["64037.20","0.021"],["64038.50","0.075"],["64039.10","0.186"],["64039.20","0.060"],["64039.40","0.231"],["64039.80","0.003"],["64040.00","0.102"],["64040.10","0.063"],["64040.30","0.078"],["64040.90","0.510"],["64041.00","0.538"],["64041.50","0.032"],["64041.60","0.008"],["64041.70","4.579"],["64041.80","0.759"],["64041.90","0.424"],["64042.10","0.236"],["64042.40","0.403"],["64042.60","0.216"],["64042.80","0.067"],["64042.90","0.101"],["64043.10","0.982"],["64043.30","0.336"],["64043.80","1.716"],["64044.20","0.228"],["64045.00","0.003"],["64045.30","2.344"],["64045.70","0.802"],["64045.80","0.004"],["64045.90","0.025"],["64046.00","0.003"],["64046.30","0.000"],["64046.50","0.372"],["64046.90","0.002"],["64047.10","0.048"],["64047.90","2.341"],["64048.00","1.165"],["64048.50","0.002"],["64048.60","0.879"],["64049.00","0.192"],["64049.50","0.201"],["64049.60","2.504"],["64050.00","0.005"],["64050.10","0.001"],["64050.30","0.001"],["64050.40","1.326"],["64050.50","0.061"],["64051.20","0.002"],["64051.30","0.255"],["64051.40","0.004"],["64051.50","0.252"],["64051.60","0.005"],["64051.80","0.549"],["64051.90","0.127"],["64052.00","0.001"],["64052.20","0.019"],["64052.30","0.000"],["64052.50","2.899"],["64052.60","2.737"],["64052.80","0.041"],["64053.10","0.002"],["64053.90","0.000"],["64054.00","0.000"],["64054.20","0.003"],["64054.30","1.598"],["64054.40","3.842"],["64054.50","0.002"],["64054.60","0.000"],["64054.70","0.000"],["64054.80","0.006"],["64054.90","12.181"]],"e":"depthUpdate","ps":"BTCUSDT","pu":11165393811005,"s":"BTCUSDT","st":1,"u":11165393832381}
{"E":1785353516576,"T":1785353516575,"U":11165393832581,"a":[["64055.00","0.000"],["64055.10","0.000"],["64055.20","0.814"],["64057.30","0.000"],["64058.10","0.002"],["64058.20","0.001"],["64058.80","0.004"],["64058.90","0.140"],["64059.00","0.016"],["64059.10","0.004"],["64059.50","0.002"],["64059.60","0.004"],["64060.00","0.030"],["64060.70","0.000"],["64060.90","0.006"],["64061.00","0.008"],["64061.30","0.002"],["64061.40","0.170"],["64061.60","0.119"],["64061.70","0.212"],["64061.90","0.000"],["64062.20","0.002"],["64062.40","0.004"],["64062.70","0.139"],["64062.80","0.783"],["64062.90","0.926"],["64063.00","0.375"],["64063.20","0.013"],["64063.40","0.024"],["64063.60","0.449"],["64063.80","0.000"],["64064.00","0.366"],["64064.20","0.002"],["64064.30","0.950"],["64064.40","0.275"],["64064.50","0.000"],["64064.60","0.160"],["64064.70","0.083"],["64065.00","0.010"],["64065.10","0.100"],["64065.40","0.160"],["64065.70","0.473"],["64065.80","0.156"],["64065.90","0.452"],["64066.00","0.468"],["64066.10","0.474"],["64066.50","0.150"],["64066.60","0.013"],["64066.70","0.566"],["64066.80","0.074"],["64066.90","0.161"],["64067.00","0.000"],["64067.10","0.191"],["64067.20","0.772"],["64067.30","0.673"],["64067.80","0.004"],["64067.90","0.000"],["64068.00","0.118"],["64068.10","0.021"],["64068.70","0.001"],["64069.40","0.316"],["64069.60","0.097"],["64069.70","0.607"],["64069.80","2.655"],["64070.60","1.260"],["64070.70","0.002"],["64071.00","2.434"],["64071.10","0.003"],["64071.30","0.021"],["64071.90","1.002"],["64072.00","0.010"],["64072.40","0.002"],["64072.80","0.013"],["64073.20","0.065"],["64073.40","0.003"],["64073.50","0.315"],["64073.60","1.475"],["64073.80","0.621"],["64073.90","0.134"],["64074.00","0.067"],["64074.40","0.392"],["64074.60","10.778"],["64074.80","0.020"],["64076.00","0.009"],["64076.10","0.657"],["64076.20","0.125"],["64077.40","0.017"],["64080.80","0.001"],["64081.30","0.003"],["64083.20","0.052"],["64083.50","0.962"],["64083.80","0.346"],["64083.90","0.235"],["64084.00","0.378"],["64084.10","0.337"],["64084.20","0.016"],["64084.30","0.104"],["64084.40","0.000"],["64084.80","0.011"],["64084.90","0.005"],["64085.70","0.080"],["64086.40","0.010"],["64086.70","0.005"],["64086.90","1.481"],["64087.00","0.391"],["64088.90","0.002"],["64089.20","0.005"],["64089.60","1.702"],["64089.90","0.001"],["64090.10","0.000"],["64091.10","0.176"],["64091.40","0.008"],["64091.60","4.414"],["64091.80","0.098"],["64091.90","0.524"],["64092.00","0.533"],["64092.20","0.066"],["64092.30","0.015"],["64092.70","0.022"],["64092.80","0.010"],["64093.90","1.305"],["64094.00","0.623"],["64094.80","0.002"],["64094.90","0.396"],["64095.50","0.123"],["64096.10","0.101"],["64096.70","0.038"],["64096.90","0.001"],["64097.20","2.405"],["64097.60","0.318"],["64099.20","2.997"],["64100.20","10.504"],["64100.40","0.000"],["64102.70","0.005"],["64103.00","0.008"],["64103.70","1.547"],["64103.80","0.003"],["64104.10","0.000"],["64108.80","0.037"],["64109.30","0.102"],["64111.10","1.052"],["64112.00","0.138"],["64112.90","0.030"],["64113.00","0.839"],["64113.50","0.001"],["64113.80","0.121"],["64115.20","0.043"],["64118.20","2.343"],["64118.40","0.797"],["64120.50","0.131"],["64121.00","0.226"],["64123.80","0.022"],["64124.10","1.484"],["64124.20","0.012"],["64128.10","0.496"],["64130.20","0.025"],["64130.50","0.076"],["64135.00","0.008"],["64137.60","0.290"],["64137.70","0.156"],["64137.80","2.011"],["64137.90","0.203"],["64138.30","0.179"],["64139.80","0.106"],["64140.10","0.095"],["64140.80","4.525"],["64141.40","0.099"],["64143.10","0.086"],["64143.20","23.345"],["64143.70","0.041"],["64144.50","1.484"],["64144.60","0.002"],["64145.30","0.000"],["64147.40","1.959"],["64147.60","0.000"],["64154.30","0.016"],["64164.10","0.011"],["64164.30","0.001"],["64166.40","1.471"],["64167.30","0.375"],["64173.30","0.227"],["64179.50","0.000"],["64184.10","0.005"],["64193.50","0.384"],["64193.60","0.003"],["64198.80","0.651"],["64213.20","0.004"],["64226.80","0.000"],["64230.30","0.004"],["64237.20","51.375"],["64330.40","0.000"],["64372.10","0.299"],["64372.30","0.326"],["64372.90","0.000"],["64374.70","0.002"],["64375.30","0.002"],["64529.00","0.096"],["64541.80","0.097"],["64682.10","0.000"],["64695.60","0.006"],["64695.80","0.013"],["64831.00","0.297"],["65336.00","0.008"]],"b":[["1000.00","37.592"],["13541.70","0.462"],["13654.90","0.238"],["13741.70","0.672"],["13754.90","0.028"],["13854.90","0.196"],["13941.70","0.000"],["13954.90","0.252"],["51244.00","0.002"],["57649.40","0.002"],["60839.60","0.004"],["60839.70","0.010"],["61492.70","0.000"],["62730.00","0.487"],["62734.40","0.002"],["62773.80","0.796"],["62773.90","0.017"],["62774.00","0.009"],["63018.10","5.355"],["63022.00","1.100"],["63045.70","0.002"],["63048.60","0.785"],["63048.90","0.000"],["63049.50","0.003"],["63051.50","0.000"],["63052.50","0.019"],["63054.90","0.034"],["63056.40","1.099"],["63089.00","19.362"],["63120.50","1.098"],["63121.00","26.025"],["63152.50","3.932"],["63201.60","0.007"],["63242.20","19.906"],["63242.30","12.530"],["63249.00","32.020"],["63280.60","1.564"],["63283.90","1.831"],["63286.20","3.933"],["63338.20","11.691"],["63347.70","0.002"],["63376.70","3.124"],["63414.40","0.000"],["63414.50","0.022"],["63725.50","0.000"],["63806.40","0.155"],["63872.10","0.003"],["63904.90","0.510"],["63906.90","0.000"],["63908.90","0.000"],["63910.90","0.016"],["63912.90","0.002"],["63913.50","0.000"],["63913.60","1.483"],["63914.90","0.081"],["63916.90","0.000"],["63918.90","0.065"],["63920.80","11.709"],["63920.90","0.035"],["63921.50","0.009"],["63923.80","0.012"],["63933.40","0.031"],["63938.60","0.664"],["63938.80","0.001"],["63941.00","1.486"],["63941.20","0.063"],["63942.10","0.514"],["63961.30","1.588"],["63961.50","1.343"],["63973.00","0.000"],["63983.40","0.002"],["63985.30","2.340"],["63987.30","0.383"],["63987.40","0.003"],["63990.10","0.527"],["63990.50","0.518"],["63993.70","0.000"],["63998.90","0.000"],["64000.10","2.500"],["64000.80","1.502"],["64001.60","0.001"],["64003.30","0.058"],["64003.40","0.092"],["64003.60","0.000"],["64003.80","0.008"],["64004.20","0.000"],["64006.20","0.391"],["64006.30","0.001"],["64009.70","0.319"],["64010.90","2.031"],["64011.10","0.000"],["64011.80","0.111"],["64012.90","0.003"],["64013.20","0.063"],["64013.50","0.000"],["64015.20","1.418"],["64015.90","0.466"],["64016.40","1.841"],["64016.60","0.064"],["64016.80","0.292"],["64017.00","0.000"],["64017.30","0.003"],["64017.50","0.005"],["64017.90","0.004"],["64018.00","0.537"],["64018.50","0.030"],["64021.30","0.003"],["64021.70","0.094"],["64021.80","0.002"],["64021.90","0.080"],["64022.30","1.304"],["64022.50","0.009"],["64022.80","0.258"],["64022.90","1.732"],["64023.30","1.057"],["64023.70","0.554"],["64024.30","0.002"],["64025.80","0.522"],["64026.20","0.807"],["64026.30","0.363"],["64027.80","0.001"],["64028.10","0.001"],["64028.30","2.348"],["64028.50","0.314"],["64028.90","0.613"],["64029.10","1.760"],["64029.30","0.044"],["64030.00","0.016"],["64030.20","0.015"],["64030.60","0.062"],["64031.50","0.570"],["64032.00","1.870"],["64032.10","2.343"],["64032.20","0.063"],["64032.80","0.025"],["64033.20","0.062"],["64033.80","0.293"],["64033.90","0.001"],["64034.00","0.002"],["64034.10","0.936"],["64034.40","0.005"],["64034.80","2.359"],["64035.10","0.592"],["64035.20","1.384"],["64035.30","0.011"],["64035.50","0.001"],["64037.00","0.142"],["64038.50","0.013"],["64039.00","0.002"],["64039.40","0.232"],["64040.20","0.001"],["64040.30","0.120"],["64040.40","0.061"],["64040.50","0.060"],["64040.80","0.075"],["64041.00","0.538"],["64041.10","0.061"],["64041.20","0.061"],["64041.30","0.060"],["64041.40","0.060"],["64041.60","0.536"],["64041.80","1.449"],["64041.90","0.315"],["64042.00","0.004"],["64042.10","0.300"],["64042.20","0.339"],["64042.80","0.047"],["64042.90","0.007"],["64043.70","0.000"],["64043.80","0.023"],["64043.90","0.000"],["64044.00","0.023"],["64044.10","0.000"],["64044.20","10.230"],["64044.30","3.845"],["64044.40","0.035"],["64044.70","0.244"],["64044.80","0.507"],["64045.30","2.358"],["64045.50","0.002"],["64045.60","0.001"],["64045.70","0.760"],["64045.80","0.003"],["64045.90","0.002"],["64047.30","0.001"],["64047.40","0.000"],["64047.90","2.342"],["64048.60","0.901"],["64048.70","0.002"],["64048.80","0.002"],["64048.90","0.083"],["64049.00","0.001"],["64049.20","1.258"],["64049.70","0.980"],["64050.40","0.001"],["64051.10","2.343"],["64051.20","1.062"],["64051.40","0.001"],["64051.60","0.007"],["64051.70","0.015"],["64051.90","0.129"],["64052.00","0.013"],["64052.10","0.002"],["64052.50","2.881"],["64052.60","2.503"],["64052.70","0.001"],["64052.80","1.368"],["64052.90","0.598"],["64053.00","0.008"],["64053.10","0.002"],["64053.50","0.003"],["64053.90","0.000"],["64054.00","0.313"],["64054.30","0.374"],["64054.40","2.360"],["64054.50","0.002"],["64054.80","0.004"],["64054.90","2.846"],["64055.00","2.820"],["64055.10","26.746"]],"e":"depthUpdate","ps":"BTCUSDT","pu":11165393832381,"s":"BTCUSDT","st":1,"u":11165393848881}
{"E":1785353516678,"T":1785353516677,"U":11165393848882,"a":[["64055.20","0.000"],["64055.50","0.000"],["64055.60","0.000"],["64055.70","0.000"],["64056.00","0.000"],["64056.10","0.000"],["64056.20","0.000"],["64056.30","0.000"],["64056.40","0.000"],["64056.60","0.000"],["64056.80","0.000"],["64057.10","0.000"],["64057.20","0.000"],["64057.40","0.000"],["64057.50","0.000"],["64057.60","0.000"],["64057.70","0.000"],["64057.80","0.000"],["64058.00","0.000"],["64058.10","0.000"],["64058.20","0.000"],["64058.30","0.000"],["64058.40","0.000"],["64058.60","0.000"],["64058.70","0.000"],["64058.80","0.000"],["64058.90","0.000"],["64059.00","0.000"],["64059.10","0.000"],["64059.20","0.000"],["64059.40","0.000"],["64059.50","0.000"],["64059.60","0.000"],["64059.80","0.000"],["64059.90","0.000"],["64060.00","0.633"],["64060.10","0.000"],["64060.20","0.001"],["64060.30","0.001"],["64060.40","0.000"],["64060.50","0.000"],["64060.60","0.001"],["64060.80","0.005"],["64060.90","0.002"],["64061.00","0.001"],["64061.20","0.000"],["64061.30","0.001"],["64061.40","0.015"],["64061.50","0.001"],["64061.60","0.001"],["64061.70","0.212"],["64061.80","0.005"],["64062.00","0.002"],["64062.10","0.014"],["64062.20","0.001"],["64062.50","0.003"],["64062.60","0.000"],["64062.70","0.000"],["64062.80","0.120"],["64062.90","0.008"],["64063.00","0.000"],["64063.20","0.001"],["64063.30","0.001"],["64063.40","0.004"],["64063.50","0.001"],["64063.60","0.003"],["64063.70","0.139"],["64063.80","0.001"],["64063.90","0.000"],["64064.00","0.008"],["64064.10","0.000"],["64064.20","0.003"],["64064.30","0.052"],["64064.40","0.003"],["64064.60","0.003"],["64064.70","0.000"],["64064.80","0.004"],["64064.90","0.002"],["64065.00","0.001"],["64065.10","0.001"],["64065.20","0.002"],["64065.30","0.003"],["64065.40","0.002"],["64065.50","0.011"],["64065.60","0.003"],["64065.70","0.051"],["64065.80","0.001"],["64065.90","0.002"],["64066.00","0.005"],["64066.10","0.000"],["64066.40","0.119"],["64066.50","0.000"],["64066.60","0.011"],["64066.70","0.000"],["64066.80","0.054"],["64066.90","0.004"],["64067.10","0.003"],["64067.20","0.165"],["64067.40","0.001"],["64067.70","0.001"],["64067.80","0.017"],["64067.90","0.000"],["64068.00","0.052"],["64068.10","0.017"],["64068.20","0.018"],["64068.50","0.002"],["64068.60","0.002"],["64068.90","0.285"],["64069.00","0.439"],["64069.10","0.002"],["64069.20","0.805"],["64069.30","0.002"],["64069.40","0.318"],["64069.50","0.158"],["64069.60","0.223"],["64069.80","0.010"],["64070.30","0.019"],["64070.40","0.011"],["64070.50","0.004"],["64070.60","0.000"],["64070.70","0.006"],["64070.80","0.015"],["64070.90","0.005"],["64071.00","0.094"],["64071.10","0.549"],["64071.20","1.192"],["64071.50","0.002"],["64071.60","0.001"],["64071.80","0.002"],["64071.90","0.001"],["64072.00","0.003"],["64072.20","2.003"],["64072.30","0.175"],["64072.40","0.002"],["64072.70","0.001"],["64072.80","0.569"],["64072.90","0.007"],["64073.00","0.378"],["64073.10","0.087"],["64073.20","0.003"],["64073.30","0.004"],["64073.40","0.174"],["64073.50","0.768"],["64073.60","1.412"],["64073.70","0.004"],["64073.80","0.002"],["64073.90","0.000"],["64074.00","2.420"],["64074.10","2.338"],["64074.30","0.000"],["64074.40","0.314"],["64074.50","0.229"],["64074.60","10.198"],["64074.70","0.320"],["64074.80","0.001"],["64075.20","0.122"],["64075.30","0.001"],["64075.40","0.585"],["64075.50","0.002"],["64075.60","0.327"],["64075.70","0.341"],["64075.80","0.001"],["64076.00","0.003"],["64076.10","0.004"],["64076.20","1.047"],["64076.40","0.376"],["64076.50","0.564"],["64076.60","0.340"],["64076.70","2.342"],["64076.80","0.078"],["64076.90","0.008"],["64077.00","1.189"],["64077.10","0.009"],["64077.20","0.134"],["64077.50","0.107"],["64077.60","0.005"],["64077.70","0.001"],["64077.80","0.497"],["64078.20","0.022"],["64078.30","0.004"],["64078.40","1.615"],["64078.50","1.707"],["64078.60","0.160"],["64078.80","0.314"],["64079.20","0.065"],["64079.30","0.013"],["64079.40","0.028"],["64079.50","0.327"],["64079.70","0.023"],["64079.90","0.393"],["64080.00","0.801"],["64080.10","1.756"],["64080.20","0.035"],["64080.30","0.083"],["64080.40","1.114"],["64080.60","0.000"],["64080.80","0.043"],["64080.90","0.316"],["64081.00","0.025"],["64081.20","0.008"],["64081.30","0.005"],["64081.50","0.118"],["64081.60","1.245"],["64081.70","0.009"],["64082.20","0.063"],["64082.30","0.217"],["64082.50","0.000"],["64082.60","0.090"],["64082.80","0.012"],["64083.10","1.655"],["64083.20","0.051"],["64083.50","0.959"],["64083.60","0.376"],["64083.80","0.367"],["64084.10","0.340"],["64084.30","0.260"],["64084.50","0.089"],["64084.60","0.012"],["64084.70","0.832"],["64084.80","0.003"],["64084.90","0.000"],["64085.30","0.000"],["64085.40","0.144"],["64085.60","0.242"],["64085.70","0.471"],["64085.80","0.562"],["64085.90","0.056"],["64086.00","0.001"],["64086.20","0.008"],["64086.40","0.010"],["64086.70","0.005"],["64086.80","0.732"],["64086.90","0.397"],["64087.00","0.392"],["64087.10","0.017"],["64087.20","0.000"],["64087.40","0.000"],["64087.60","0.004"],["64087.70","0.004"],["64087.80","0.513"],["64088.00","0.002"],["64088.10","0.004"],["64088.20","0.001"],["64088.40","0.000"],["64088.50","0.009"],["64088.60","0.073"],["64089.00","0.080"],["64089.10","0.024"],["64089.20","0.006"],["64089.30","0.611"],["64089.60","1.699"],["64090.00","0.064"],["64090.40","0.005"],["64090.60","0.378"],["64090.80","0.000"],["64090.90","0.913"],["64091.10","0.001"],["64091.30","0.058"],["64091.40","0.106"],["64091.60","2.346"],["64091.80","0.000"],["64092.00","0.529"],["64092.10","0.005"],["64092.20","0.007"],["64092.50","0.001"],["64092.70","0.069"],["64092.80","0.006"],["64093.00","0.000"],["64093.50","0.025"],["64094.00","2.571"],["64094.20","2.040"],["64094.30","0.015"],["64094.70","0.000"],["64094.90","0.392"],["64095.00","0.000"],["64095.30","0.090"],["64095.40","0.001"],["64095.70","0.033"],["64096.10","0.150"],["64096.30","0.001"],["64096.40","0.173"],["64096.70","0.042"],["64096.80","0.081"],["64096.90","0.001"],["64097.00","1.219"],["64097.20","5.901"],["64097.30","0.121"],["64097.40","0.404"],["64097.50","0.333"],["64097.70","0.262"],["64097.80","0.004"],["64097.90","0.003"],["64098.10","0.004"],["64098.20","0.095"],["64098.50","0.315"],["64098.80","0.050"],["64099.00","0.000"],["64099.10","0.000"],["64099.20","1.480"],["64099.30","0.000"],["64099.40","0.000"],["64099.60","1.059"],["64099.80","0.001"],["64099.90","0.033"],["64100.00","2.691"],["64100.20","0.504"],["64100.50","0.618"],["64100.80","0.000"],["64101.00","0.001"],["64101.10","10.003"],["64101.20","0.195"],["64101.80","0.001"],["64101.90","0.180"],["64102.20","0.505"],["64102.40","0.021"],["64102.60","0.838"],["64102.70","0.002"],["64103.00","0.008"],["64103.40","0.002"],["64103.60","0.001"],["64103.90","0.014"],["64104.10","0.000"],["64104.20","0.802"],["64104.30","0.004"],["64104.40","2.340"],["64104.50","1.251"],["64104.80","0.171"],["64105.20","0.022"],["64105.40","0.062"],["64105.90","0.003"],["64106.30","0.176"],["64107.00","0.007"],["64107.10","0.003"],["64107.30","0.072"],["64107.40","0.000"],["64107.60","0.000"],["64107.80","0.000"],["64108.70","0.065"],["64109.10","0.011"],["64109.30","0.103"],["64111.00","0.051"],["64111.30","1.062"],["64112.60","0.482"],["64112.90","0.026"],["64113.00","0.847"],["64113.60","2.610"],["64115.40","0.003"],["64116.00","0.008"],["64116.30","0.001"],["64117.70","0.004"],["64117.80","0.002"],["64118.10","0.004"],["64118.30","0.000"],["64118.90","0.391"],["64119.10","0.212"],["64120.70","1.626"],["64121.00","0.001"],["64121.60","0.018"],["64122.20","0.000"],["64122.50","0.001"],["64122.60","0.004"],["64122.90","0.391"],["64123.20","0.001"],["64124.00","0.024"],["64124.10","1.690"],["64124.60","2.343"],["64124.70","0.002"],["64125.20","0.042"],["64126.60","0.374"],["64127.20","0.210"],["64127.80","0.002"],["64127.90","0.668"],["64129.40","0.024"],["64129.50","0.000"],["64130.20","0.097"],["64130.50","0.076"],["64131.50","0.314"],["64132.00","4.417"],["64132.30","2.506"],["64132.40","0.000"],["64133.10","10.915"],["64133.30","0.029"],["64135.00","0.000"],["64136.00","0.002"],["64136.40","4.135"],["64137.10","0.002"],["64137.40","0.650"],["64137.60","0.170"],["64137.80","1.861"],["64138.00","0.152"],["64138.60","0.514"],["64140.00","0.030"],["64140.20","0.008"],["64140.80","4.516"],["64140.90","23.342"],["64141.50","0.000"],["64143.10","0.014"],["64143.20","0.003"],["64143.30","0.014"],["64143.60","0.490"],["64144.70","0.000"],["64148.90","0.065"],["64149.60","2.347"],["64150.30","0.374"],["64151.00","0.103"],["64151.10","1.140"],["64151.30","0.024"],["64152.70","0.500"],["64153.00","2.340"],["64153.20","0.005"],["64153.30","0.059"],["64153.40","0.551"],["64153.90","0.001"],["64154.90","0.281"],["64156.20","2.356"],["64157.00","0.008"],["64157.50","0.008"],["64159.70","0.008"],["64159.80","0.000"],["64159.90","0.000"],["64160.00","0.840"],["64161.80","0.000"],["64161.90","0.001"],["64164.10","0.511"],["64165.60","0.596"],["64166.40","2.216"],["64166.60","0.036"],["64167.30","0.375"],["64168.30","0.528"],["64171.50","4.988"],["64172.90","3.529"],["64173.40","0.044"],["64174.90","0.007"],["64181.10","0.000"],["64181.60","0.000"],["64188.80","0.633"],["64188.90","4.440"],["64189.00","24.407"],["64189.10","0.624"],["64189.60","0.001"],["64192.80","0.001"],["64194.90","1.509"],["64195.10","0.064"],["64195.30","0.416"],["64195.60","0.004"],["64195.70","0.002"],["64196.30","0.519"],["64198.80","1.185"],["64199.40","0.518"],["64200.70","4.699"],["64204.80","3.341"],["64204.90","0.002"],["64206.80","0.000"],["64207.50","0.011"],["64212.70","0.004"],["64213.40","1.914"],["64214.00","0.006"],["64215.80","0.000"],["64216.00","0.001"],["64216.10","0.211"],["64218.00","0.492"],["64223.90","5.472"],["64228.10","3.099"],["64228.20","19.427"],["64230.20","0.003"],["64230.40","0.419"],["64231.40","0.002"],["64234.80","2.759"],["64235.20","0.003"],["64236.50","18.065"],["64237.10","0.072"],["64237.20","0.003"],["64238.20","0.238"],["64239.20","0.001"],["64242.40","0.001"],["64243.60","0.647"],["64243.70","2.453"],["64244.20","0.005"],["64250.20","0.995"],["64254.50","0.025"],["64260.10","0.000"],["64265.90","7.662"],["64268.20","47.937"],["64279.70","0.263"],["64279.80","0.000"],["64290.10","0.500"],["64290.40","0.003"],["64290.60","0.000"],["64303.40","0.001"],["64313.60","0.368"],["64313.70","0.537"],["64314.50","0.407"],["64329.10","1.074"],["64332.30","0.000"],["64371.60","0.154"],["64372.10","0.000"],["64372.30","0.176"],["64373.40","0.150"],["64374.80","0.004"],["64400.70","0.003"],["64403.30","0.002"],["64406.50","0.001"],["64413.30","0.851"],["64529.00","0.000"],["64532.30","0.038"],["64532.90","0.000"],["64533.50","0.000"],["64534.00","0.000"],["64541.80","0.001"],["64544.50","0.002"],["64571.70","0.000"],["64613.80","0.113"],["64681.10","0.233"],["64695.80","0.009"],["64696.90","0.000"],["64698.30","0.000"],["64699.50","0.000"],["64700.60","0.053"],["64792.10","0.001"],["64792.20","0.031"],["64792.30","0.000"],["64793.40","0.000"],["64794.70","0.231"],["64796.00","0.000"],["64797.20","12.838"],["64823.20","0.044"],["64856.10","2.289"],["64856.20","0.000"],["64856.30","0.002"],["64857.40","0.000"],["64858.80","1.998"],["64861.30","8.737"],["64928.70","0.000"],["64954.90","1.090"],["64988.80","1.119"],["65048.50","0.000"],["65082.30","1.065"],["65341.10","0.003"],["67252.10","0.002"],["67261.90","0.062"]],"b":[["1000.00","37.592"],["13541.70","0.350"],["13655.10","0.042"],["13658.80","0.014"],["13659.90","0.070"],["13741.70","0.546"],["13755.10","0.028"],["13756.20","0.014"],["13759.90","0.070"],["13854.90","0.084"],["13955.10","0.028"],["13957.60","0.014"],["13959.90","0.070"],["51244.00","0.000"],["57649.40","0.000"],["57649.50","0.050"],["57651.80","0.000"],["57653.90","0.002"],["61497.50","0.003"],["62960.80","0.000"],["63045.20","0.000"],["63052.50","0.003"],["63056.20","0.962"],["63057.60","0.925"],["63058.80","0.003"],["63210.20","5.799"],["63238.60","2.676"],["63242.30","10.965"],["63254.20","1.492"],["63394.90","0.000"],["63395.80","0.698"],["63414.50","0.016"],["63415.60","0.000"],["63415.70","0.000"],["63417.00","0.000"],["63418.20","0.056"],["63419.30","0.013"],["63431.20","0.936"],["63440.00","1.756"],["63536.70","0.008"],["63543.80","0.001"],["63603.10","0.003"],["63610.40","0.001"],["63667.20","0.003"],["63674.40","0.001"],["63688.30","0.000"],["63718.90","0.033"],["63728.90","0.009"],["63735.90","0.001"],["63736.20","0.088"],["63790.90","0.001"],["63791.70","0.148"],["63794.20","0.015"],["63795.30","0.000"],["63802.60","0.002"],["63804.80","0.002"],["63807.10","1.126"],["63819.50","0.132"],["63824.60","0.000"],["63825.40","0.153"],["63828.20","6.088"],["63830.60","0.011"],["63843.20","1.003"],["63857.00","0.000"],["63862.10","0.002"],["63863.80","0.074"],["63864.00","0.001"],["63867.60","0.003"],["63870.60","0.016"],["63872.30","0.117"],["63875.00","0.169"],["63882.20","0.000"],["63883.40","0.025"],["63885.40","0.021"],["63896.80","0.013"],["63913.60","0.702"],["63919.30","0.012"],["63920.40","0.506"],["63921.00","0.027"],["63921.50","0.008"],["63925.70","0.228"],["63926.40","0.002"],["63927.60","0.002"],["63928.10","0.002"],["63931.80","1.436"],["63936.60","0.000"],["63938.40","0.000"],["63939.20","0.795"],["63940.00","23.844"],["63940.40","4.058"],["63940.60","0.000"],["63941.10","0.000"],["63942.30","0.000"],["63942.70","0.000"],["63946.30","0.044"],["63948.60","0.001"],["63950.00","0.269"],["63951.20","0.001"],["63951.70","0.016"],["63952.60","0.019"],["63954.40","0.002"],["63954.90","0.003"],["63955.20","0.094"],["63957.60","2.823"],["63958.50","0.084"],["63959.00","0.000"],["63961.20","0.186"],["63961.70","0.008"],["63963.00","2.341"],["63963.80","0.482"],["63964.70","0.648"],["63966.20","0.002"],["63968.00","0.626"],["63970.20","0.062"],["63974.00","0.032"],["63974.80","0.034"],["63976.00","0.000"],["63977.40","0.000"],["63977.90","0.499"],["63978.00","2.342"],["63981.90","0.002"],["63982.20","0.000"],["63982.30","4.222"],["63983.30","0.500"],["63984.10","0.003"],["63985.10","0.001"],["63985.40","0.011"],["63985.50","0.496"],["63985.60","0.002"],["63985.90","0.000"],["63986.40","0.059"],["63987.90","4.199"],["63988.40","0.000"],["63989.30","0.000"],["63989.40","0.198"],["63989.50","0.000"],["63989.80","1.836"],["63990.00","0.061"],["63990.10","0.512"],["63990.20","0.998"],["63991.00","0.002"],["63991.50","0.001"],["63992.10","2.345"],["63992.40","0.002"],["63993.80","0.001"],["63994.40","0.000"],["63994.50","0.001"],["63994.80","2.369"],["63994.90","0.000"],["63995.70","1.828"],["63996.30","0.001"],["63996.50","0.017"],["63996.80","0.068"],["63997.70","2.258"],["63998.40","0.003"],["63999.90","0.003"],["64000.10","2.504"],["64001.20","0.140"],["64001.60","0.000"],["64001.80","0.082"],["64002.00","0.002"],["64002.30","0.000"],["64002.50","0.379"],["64003.10","0.013"],["64003.30","0.056"],["64003.40","0.001"],["64003.50","0.111"],["64003.80","0.000"],["64004.30","0.000"],["64004.40","0.005"],["64004.50","0.001"],["64004.60","0.153"],["64004.90","0.000"],["64005.00","0.001"],["64005.10","0.064"],["64005.50","0.000"],["64005.60","0.063"],["64006.40","1.147"],["64006.90","0.032"],["64007.00","0.017"],["64007.20","0.510"],["64007.30","0.063"],["64007.50","0.209"],["64008.00","2.348"],["64008.10","0.001"],["64008.20","0.000"],["64008.60","0.422"],["64008.70","0.500"],["64008.90","0.001"],["64009.10","0.000"],["64009.20","0.004"],["64009.30","0.001"],["64009.90","0.760"],["64010.30","0.540"],["64010.70","0.094"],["64011.00","0.002"],["64011.10","0.082"],["64011.20","0.133"],["64011.30","0.000"],["64011.40","0.031"],["64011.60","0.213"],["64011.70","0.000"],["64011.80","0.064"],["64012.00","1.493"],["64012.10","0.021"],["64012.40","0.366"],["64012.60","1.248"],["64013.20","0.130"],["64014.00","0.114"],["64014.20","0.978"],["64014.60","1.249"],["64016.40","1.432"],["64016.50","2.990"],["64016.80","0.287"],["64017.00","0.000"],["64017.10","0.003"],["64017.30","0.008"],["64017.50","0.002"],["64017.70","0.001"],["64017.90","0.000"],["64018.30","0.058"],["64018.50","0.003"],["64018.60","0.000"],["64018.80","0.027"],["64019.10","1.069"],["64019.20","0.062"],["64019.30","0.593"],["64019.60","0.571"],["64019.70","0.001"],["64019.90","2.681"],["64020.00","0.010"],["64020.20","0.048"],["64020.60","0.000"],["64020.80","0.607"],["64020.90","0.002"],["64021.00","0.001"],["64021.40","1.081"],["64021.70","0.013"],["64021.80","0.005"],["64021.90","0.010"],["64022.00","0.003"],["64022.20","0.010"],["64022.30","1.174"],["64022.50","0.013"],["64022.70","0.514"],["64022.80","0.008"],["64022.90","1.728"],["64023.10","0.098"],["64023.30","0.862"],["64023.40","0.537"],["64023.50","0.027"],["64023.90","0.299"],["64024.10","0.002"],["64024.60","0.005"],["64024.70","0.000"],["64024.90","0.081"],["64025.00","0.002"],["64025.10","0.061"],["64025.40","0.005"],["64025.70","2.408"],["64026.20","0.293"],["64026.40","0.243"],["64026.60","0.170"],["64026.70","0.001"],["64026.80","0.001"],["64027.00","0.004"],["64027.20","0.006"],["64027.40","0.022"],["64027.70","0.000"],["64027.80","0.000"],["64028.00","0.043"],["64028.10","0.019"],["64028.50","0.404"],["64028.90","0.523"],["64029.00","1.213"],["64029.10","1.330"],["64029.20","0.312"],["64029.30","0.002"],["64029.40","0.000"],["64029.50","0.074"],["64029.80","0.121"],["64030.00","0.017"],["64030.20","0.471"],["64030.90","0.017"],["64031.30","0.011"],["64031.40","0.132"],["64031.50","0.008"],["64031.70","0.177"],["64031.80","0.658"],["64032.00","1.784"],["64032.20","0.315"],["64032.30","0.002"],["64032.40","0.023"],["64032.50","0.005"],["64032.60","0.006"],["64032.70","0.000"],["64032.80","0.051"],["64033.10","0.010"],["64033.30","0.060"],["64033.50","1.052"],["64033.80","0.300"],["64033.90","0.000"],["64034.00","1.079"],["64034.10","0.001"],["64034.40","0.001"],["64034.50","0.242"],["64034.60","0.503"],["64034.80","2.361"],["64035.00","0.003"],["64035.10","0.901"],["64035.20","2.646"],["64035.40","0.315"],["64035.50","0.002"],["64035.70","0.000"],["64036.10","0.017"],["64036.40","0.020"],["64036.70","0.003"],["64036.80","0.002"],["64037.00","0.001"],["64037.10","0.109"],["64037.20","0.005"],["64037.50","0.004"],["64037.70","0.000"],["64037.80","0.000"],["64038.00","0.002"],["64038.10","0.077"],["64038.30","0.935"],["64038.40","0.934"],["64038.70","0.127"],["64038.80","0.018"],["64039.10","0.228"],["64039.20","0.059"],["64039.40","0.001"],["64039.50","0.053"],["64039.60","0.017"],["64040.10","0.062"],["64040.20","0.016"],["64040.30","0.120"],["64041.00","0.000"],["64041.10","0.061"],["64041.20","0.062"],["64041.30","0.076"],["64041.60","0.068"],["64041.70","4.639"],["64041.80","1.057"],["64041.90","0.314"],["64042.00","0.007"],["64042.10","0.067"],["64042.20","0.496"],["64042.40","0.634"],["64042.50","2.341"],["64042.60","0.001"],["64042.70","1.252"],["64042.80","0.067"],["64043.40","0.002"],["64043.50","0.157"],["64043.70","0.259"],["64043.80","0.001"],["64044.00","0.240"],["64044.20","0.004"],["64044.30","1.902"],["64044.40","0.000"],["64044.50","0.001"],["64044.60","0.001"],["64044.70","0.224"],["64044.80","0.507"],["64045.00","10.005"],["64045.10","0.000"],["64045.30","2.403"],["64045.40","0.021"],["64045.50","0.001"],["64045.60","0.216"],["64045.70","0.750"],["64045.80","0.003"],["64046.00","0.001"],["64046.10","0.002"],["64046.20","0.001"],["64046.40","0.003"],["64046.50","0.375"],["64046.60","0.002"],["64046.80","0.003"],["64047.00","0.547"],["64047.10","0.050"],["64047.20","0.227"],["64047.80","0.002"],["64047.90","2.362"],["64048.00","1.165"],["64048.10","0.004"],["64048.20","0.001"],["64048.30","0.001"],["64048.40","0.001"],["64048.50","0.000"],["64048.60","0.879"],["64048.70","0.000"],["64048.80","0.019"],["64048.90","0.084"],["64049.00","0.000"],["64049.10","1.505"],["64049.20","1.251"],["64049.30","0.001"],["64049.40","0.021"],["64049.60","0.001"],["64049.70","0.981"],["64049.80","0.003"],["64050.00","0.006"],["64050.30","0.002"],["64050.40","0.003"],["64050.50","0.000"],["64050.60","0.014"],["64050.70","0.000"],["64050.80","0.000"],["64051.00","0.011"],["64051.10","2.345"],["64051.20","1.067"],["64051.30","0.110"],["64051.40","0.000"],["64051.70","0.000"],["64051.80","0.002"],["64051.90","0.003"],["64052.10","0.315"],["64052.20","0.001"],["64052.30","0.001"],["64052.40","0.005"],["64052.50","2.868"],["64052.60","0.511"],["64052.70","0.001"],["64052.80","0.001"],["64052.90","0.233"],["64053.00","0.008"],["64053.20","0.001"],["64053.30","0.372"],["64053.50","0.002"],["64053.60","0.004"],["64053.80","0.192"],["64053.90","0.023"],["64054.00","0.314"],["64054.30","0.001"],["64054.40","2.340"],["64054.50","0.007"],["64054.80","0.002"],["64054.90","0.774"],["64055.00","0.005"],["64055.10","0.441"],["64055.20","2.503"],["64055.30","0.126"],["64055.40","0.049"],["64055.50","0.001"],["64055.60","0.000"],["64055.80","0.001"],["64055.90","0.000"],["64056.00","0.002"],["64056.10","0.022"],["64056.20","0.801"],["64056.30","0.004"],["64056.40","2.500"],["64056.50","0.000"],["64056.60","0.002"],["64056.70","0.000"],["64056.90","0.001"],["64057.00","2.340"],["64057.10","0.000"],["64057.20","0.002"],["64057.30","0.001"],["64057.40","0.001"],["64057.50","0.002"],["64057.60","2.086"],["64057.70","0.432"],["64057.80","0.611"],["64057.90","1.522"],["64058.00","0.000"],["64058.10","0.313"],["64058.20","0.000"],["64058.30","0.000"],["64058.40","0.002"],["64058.50","0.381"],["64058.60","0.001"],["64058.70","0.001"],["64058.80","0.669"],["64058.90","0.002"],["64059.00","0.000"],["64059.10","0.000"],["64059.20","0.014"],["64059.30","0.000"],["64059.40","0.000"],["64059.70","0.001"],["64059.80","2.347"],["64059.90","13.915"]],"e":"depthUpdate","ps":"BTCUSDT","pu":11165393848881,"s":"BTCUSDT","st":1,"u":11165393892974}
{"E":1785353516780,"T":1785353516779,"U":11165393893132,"a":[["64060.00","2.951"],["64060.10","0.001"],["64060.90","0.001"],["64061.40","0.000"],["64062.80","0.000"],["64062.90","0.009"],["64063.10","0.008"],["64063.20","0.025"],["64064.30","0.005"],["64064.80","0.002"],["64065.00","0.003"],["64065.70","0.052"],["64066.30","0.001"],["64066.40","0.017"],["64067.20","0.008"],["64067.70","0.013"],["64067.80","0.015"],["64068.00","0.934"],["64068.70","0.158"],["64068.80","0.283"],["64068.90","0.816"],["64069.10","0.001"],["64069.60","0.698"],["64070.20","0.435"],["64070.40","1.580"],["64070.80","0.015"],["64070.90","0.003"],["64071.00","0.345"],["64071.10","2.345"],["64071.20","1.285"],["64071.50","0.108"],["64072.00","0.778"],["64072.20","2.086"],["64072.30","0.079"],["64072.40","1.002"],["64072.70","0.001"],["64072.80","0.491"],["64072.90","0.175"],["64073.20","0.309"],["64073.40","0.331"],["64073.80","0.159"],["64074.40","0.314"],["64074.60","10.190"],["64074.70","0.316"],["64075.20","0.002"],["64076.10","0.004"],["64076.20","0.047"],["64076.60","0.260"],["64076.90","0.005"],["64077.30","0.089"],["64077.40","0.017"],["64077.50","0.107"],["64077.60","0.165"],["64077.80","0.490"],["64078.10","0.040"],["64078.20","0.020"],["64078.30","0.238"],["64078.40","2.271"],["64078.90","0.144"],["64079.50","0.393"],["64079.90","0.398"],["64080.50","0.117"],["64080.80","0.001"],["64082.30","0.217"],["64083.80","0.639"],["64083.90","0.195"],["64084.20","0.014"],["64084.50","0.049"],["64085.50","1.303"],["64085.60","0.284"],["64085.70","0.237"],["64085.90","0.096"],["64086.70","0.000"],["64087.00","0.387"],["64087.10","0.002"],["64087.50","1.060"],["64087.60","0.014"],["64087.90","0.027"],["64088.50","0.001"],["64088.60","0.122"],["64088.70","0.004"],["64089.00","0.001"],["64090.60","0.376"],["64091.30","0.001"],["64092.20","1.758"],["64092.30","0.000"],["64093.50","0.000"],["64093.90","2.743"],["64094.80","0.059"],["64095.10","0.002"],["64095.20","0.004"],["64095.30","10.090"],["64096.70","0.049"],["64096.80","0.081"],["64097.00","1.223"],["64097.10","0.786"],["64097.20","5.897"],["64097.30","0.136"],["64097.60","0.150"],["64098.40","0.001"],["64098.50","0.003"],["64099.00","0.001"],["64099.20","1.481"],["64099.30","0.001"],["64099.80","0.002"],["64100.30","0.000"],["64100.50","0.619"],["64100.60","0.003"],["64101.10","0.003"],["64101.20","0.105"],["64101.50","0.315"],["64102.40","0.025"],["64103.10","0.015"],["64103.50","1.312"],["64103.60","1.485"],["64103.70","0.063"],["64104.20","0.035"],["64104.30","0.002"],["64104.40","2.342"],["64104.70","0.002"],["64104.80","0.249"],["64104.90","0.115"],["64105.30","1.060"],["64105.40","0.060"],["64106.30","0.952"],["64106.50","0.338"],["64106.70","0.003"],["64107.20","0.207"],["64107.50","0.381"],["64108.10","0.184"],["64109.50","1.494"],["64113.90","0.139"],["64114.00","0.008"],["64116.10","0.020"],["64120.50","0.100"],["64122.00","3.371"],["64122.60","0.016"],["64124.00","1.508"],["64124.10","0.206"],["64124.60","2.342"],["64125.50","0.031"],["64129.40","0.009"],["64130.20","0.025"],["64131.70","0.912"],["64132.70","0.000"],["64136.80","0.069"],["64138.20","0.168"],["64140.50","0.573"],["64140.80","4.515"],["64140.90","0.000"],["64143.10","23.356"],["64143.40","0.010"],["64144.40","4.433"],["64144.50","0.000"],["64145.60","0.000"],["64147.40","1.959"],["64147.50","0.004"],["64151.90","0.000"],["64152.10","0.041"],["64152.20","0.064"],["64154.00","1.209"],["64154.10","0.011"],["64157.10","0.000"],["64158.60","0.028"],["64166.40","0.764"],["64167.60","0.304"],["64167.90","0.106"],["64168.60","0.083"],["64173.40","0.005"],["64176.70","0.000"],["64177.80","0.168"],["64181.30","0.494"],["64186.60","0.010"],["64188.70","0.039"],["64192.90","0.124"],["64195.60","0.000"],["64224.10","0.316"],["64227.40","0.004"],["64242.40","0.000"],["64265.00","0.495"],["64268.10","0.836"],["64285.20","0.779"],["64285.70","0.007"],["64286.50","0.000"],["64295.10","0.000"],["64298.00","0.473"],["64334.30","0.003"],["64371.60","0.074"],["64372.30","0.027"],["64373.40","0.000"],["64373.90","0.000"],["64380.30","0.299"],["64700.60","0.051"],["64860.80","0.908"],["64883.00","0.000"],["64954.90","0.023"],["64988.90","1.980"],["65016.50","0.001"],["65052.90","1.755"]],"b":[["13541.70","0.224"],["13659.90","0.182"],["13741.70","0.434"],["13759.90","0.196"],["13852.50","0.056"],["13854.90","0.000"],["13959.90","0.196"],["57653.90","0.002"],["61497.50","0.000"],["62778.80","0.563"],["63082.20","10.597"],["63126.10","5.368"],["63146.20","6.740"],["63190.20","1.099"],["63312.60","6.411"],["63357.50","0.703"],["63402.20","13.293"],["63419.30","0.013"],["63446.40","0.934"],["63447.20","0.624"],["63710.20","0.000"],["63761.90","0.004"],["63773.70","0.094"],["63778.40","0.000"],["63778.90","0.090"],["63783.40","0.525"],["63802.30","0.004"],["63843.60","3.000"],["63854.00","0.149"],["63878.90","0.001"],["63881.60","0.437"],["63889.40","0.019"],["63892.60","0.000"],["63895.00","0.002"],["63902.40","0.002"],["63904.90","0.000"],["63908.00","0.500"],["63912.80","5.411"],["63913.60","1.498"],["63914.00","0.000"],["63917.10","0.274"],["63927.90","0.000"],["63928.30","0.004"],["63940.90","1.982"],["63941.00","0.000"],["63941.60","0.019"],["63949.90","0.039"],["63950.90","0.000"],["63951.90","0.371"],["63952.00","0.706"],["63954.10","0.000"],["63955.30","0.000"],["63958.10","0.909"],["63959.40","0.581"],["63961.20","1.671"],["63961.30","0.103"],["63961.90","0.042"],["63962.00","0.002"],["63963.40","0.002"],["63963.80","0.483"],["63966.80","0.001"],["63969.10","3.019"],["63970.20","0.000"],["63970.70","2.252"],["63971.70","22.405"],["63972.70","0.001"],["63975.50","3.122"],["63976.40","0.074"],["63977.20","0.454"],["63978.10","0.003"],["63981.00","0.063"],["63981.90","0.000"],["63982.70","0.000"],["63984.00","0.021"],["63986.60","0.229"],["63988.30","0.000"],["63991.50","0.001"],["63992.20","0.000"],["63992.90","0.069"],["63993.50","1.122"],["63996.10","3.162"],["63997.40","0.012"],["63998.70","0.004"],["63998.80","2.301"],["64000.90","0.064"],["64001.00","0.510"],["64001.20","0.062"],["64001.80","0.001"],["64002.20","0.061"],["64003.30","0.040"],["64003.50","0.062"],["64005.00","0.079"],["64005.10","0.274"],["64006.00","0.418"],["64006.40","1.221"],["64007.30","0.000"],["64007.50","0.177"],["64007.80","0.024"],["64008.60","0.459"],["64008.80","0.092"],["64009.90","0.656"],["64011.60","0.003"],["64013.00","0.002"],["64013.50","0.081"],["64013.60","0.001"],["64014.20","0.977"],["64014.30","0.000"],["64014.70","0.000"],["64015.20","1.403"],["64015.30","0.658"],["64015.90","0.465"],["64017.30","0.019"],["64017.90","0.040"],["64019.30","0.553"],["64019.40","0.005"],["64020.20","0.063"],["64020.30","0.002"],["64021.40","1.082"],["64021.70","0.079"],["64022.90","1.732"],["64023.10","0.094"],["64026.40","0.000"],["64027.70","0.004"],["64029.10","1.335"],["64029.50","0.032"],["64030.20","0.003"],["64031.30","0.025"],["64031.70","0.175"],["64032.00","1.783"],["64032.90","0.049"],["64033.20","0.002"],["64033.30","0.000"],["64033.40","0.001"],["64033.50","0.992"],["64034.00","1.082"],["64034.30","0.043"],["64035.60","0.001"],["64036.60","0.616"],["64037.10","0.129"],["64037.40","0.321"],["64038.20","0.524"],["64038.60","0.005"],["64038.70","0.047"],["64039.00","0.238"],["64039.10","0.108"],["64039.60","0.003"],["64040.40","0.001"],["64040.60","0.002"],["64041.10","0.369"],["64041.70","4.637"],["64041.80","0.401"],["64041.90","0.970"],["64042.10","0.069"],["64042.20","0.340"],["64042.60","0.004"],["64043.20","0.060"],["64044.30","1.902"],["64044.60","0.004"],["64045.00","0.471"],["64045.10","0.002"],["64045.30","2.498"],["64045.40","0.243"],["64045.70","0.520"],["64045.80","0.063"],["64045.90","0.062"],["64046.00","0.061"],["64046.90","0.034"],["64047.50","0.033"],["64047.90","2.395"],["64048.00","1.165"],["64048.90","0.084"],["64049.00","0.000"],["64049.10","0.864"],["64049.70","0.373"],["64049.80","0.781"],["64049.90","0.316"],["64050.10","0.021"],["64051.30","0.110"],["64051.60","0.007"],["64053.90","0.000"],["64054.00","0.315"],["64054.20","0.004"],["64054.40","0.000"],["64054.50","0.007"],["64054.70","0.000"],["64054.80","0.003"],["64054.90","0.579"],["64055.10","0.596"],["64055.30","0.148"],["64055.40","0.049"],["64055.50","0.065"],["64056.00","0.003"],["64056.20","0.560"],["64056.60","0.005"],["64056.70","0.029"],["64057.00","0.000"],["64057.10","2.340"],["64057.20","0.003"],["64057.30","0.142"],["64057.80","0.001"],["64057.90","1.326"],["64058.00","0.001"],["64058.10","0.313"],["64058.20","0.567"],["64058.30","0.000"],["64058.70","0.001"],["64058.80","0.668"],["64059.00","0.006"],["64059.20","0.000"],["64059.70","0.000"],["64059.80","0.007"],["64059.90","15.850"]],"e":"depthUpdate","ps":"BTCUSDT","pu":11165393892974,"s":"BTCUSDT","st":1,"u":11165393919461}
{"E":1785353516882,"T":1785353516881,"U":11165393919474,"a":[["64060.00","2.955"],["64061.30","0.000"],["64063.00","0.023"],["64063.10","0.009"],["64063.20","0.032"],["64064.30","0.034"],["64065.70","0.052"],["64066.40","0.095"],["64067.30","1.334"],["64067.80","0.140"],["64067.90","2.340"],["64068.80","0.001"],["64069.60","0.620"],["64070.30","0.113"],["64070.90","0.002"],["64071.00","2.591"],["64071.10","0.005"],["64071.30","0.020"],["64071.90","0.091"],["64072.00","0.003"],["64072.60","0.102"],["64072.70","0.169"],["64073.20","0.477"],["64073.40","0.469"],["64073.60","1.718"],["64073.90","0.080"],["64076.00","0.006"],["64077.80","0.481"],["64078.00","0.060"],["64078.70","0.001"],["64080.50","0.116"],["64081.00","0.015"],["64081.30","0.086"],["64084.20","0.003"],["64085.60","0.149"],["64085.70","0.469"],["64088.80","0.007"],["64090.30","1.069"],["64090.50","0.001"],["64092.00","0.537"],["64094.70","0.120"],["64095.20","0.013"],["64097.20","5.918"],["64098.40","0.011"],["64099.50","0.071"],["64099.90","0.137"],["64101.10","0.004"],["64101.70","0.026"],["64101.90","0.060"],["64102.30","0.007"],["64102.90","0.487"],["64103.10","0.029"],["64106.20","0.159"],["64106.30","0.976"],["64107.30","0.002"],["64108.10","0.094"],["64109.50","1.520"],["64109.70","0.001"],["64110.90","0.395"],["64114.20","0.666"],["64120.80","0.026"],["64123.20","0.002"],["64123.50","0.000"],["64127.20","0.239"],["64128.60","0.011"],["64128.90","0.101"],["64130.40","0.134"],["64133.60","0.041"],["64136.40","4.133"],["64136.80","0.098"],["64138.10","0.000"],["64140.90","23.342"],["64143.10","0.014"],["64143.20","0.031"],["64147.40","1.363"],["64147.70","0.001"],["64156.80","0.505"],["64157.00","0.000"],["64161.60","0.008"],["64167.60","0.211"],["64168.30","0.618"],["64169.70","3.238"],["64178.00","0.019"],["64178.20","0.150"],["64178.50","0.169"],["64178.90","0.170"],["64179.20","1.359"],["64195.30","0.732"],["64195.70","2.123"],["64206.20","0.006"],["64228.10","3.171"],["64237.10","0.000"],["64270.50","0.000"],["64292.40","0.004"],["64546.90","0.220"],["64627.60","0.000"],["64632.70","0.031"],["64700.60","0.051"],["64896.70","0.769"],["64901.70","0.031"],["64988.90","2.095"]],"b":[["1000.00","37.592"],["13541.70","0.112"],["13659.90","0.308"],["13741.70","0.308"],["13759.90","0.322"],["13848.60","0.000"],["13848.90","0.000"],["13849.50","0.000"],["13849.70","0.000"],["13851.50","0.000"],["13852.50","0.000"],["13959.90","0.308"],["51247.90","0.000"],["57653.90","0.002"],["62778.80","0.566"],["63049.10","5.560"],["63086.30","0.000"],["63174.70","0.790"],["63226.20","12.572"],["63242.20","16.775"],["63249.00","30.455"],["63271.30","2.350"],["63273.20","16.969"],["63277.10","3.129"],["63306.30","0.939"],["63325.40","0.308"],["63338.20","3.876"],["63341.20","3.128"],["63349.00","0.021"],["63370.60","0.942"],["63373.20","7.186"],["63382.30","0.783"],["63383.00","1.768"],["63383.40","1.562"],["63395.80","0.002"],["63419.30","0.011"],["63428.30","1.044"],["63434.20","12.684"],["63441.10","3.055"],["63469.30","1.560"],["63725.00","1.058"],["63734.60","0.000"],["63758.10","0.013"],["63779.90","0.004"],["63911.90","0.001"],["63913.90","0.509"],["63915.90","0.009"],["63917.90","0.001"],["63919.90","0.076"],["63930.00","0.440"],["63945.60","0.380"],["63965.00","0.046"],["63968.20","0.492"],["63971.70","0.000"],["63973.30","0.936"],["63974.60","0.012"],["63979.90","0.030"],["63986.30","0.657"],["63988.90","0.028"],["63989.50","0.028"],["63989.70","0.060"],["63991.50","22.406"],["63993.30","0.517"],["63993.50","4.452"],["63995.90","0.030"],["63996.90","0.002"],["63997.70","0.003"],["63999.30","0.614"],["63999.40","0.318"],["64000.10","2.478"],["64000.90","0.064"],["64002.30","0.027"],["64003.50","0.099"],["64005.00","0.179"],["64006.40","1.220"],["64006.50","0.000"],["64008.80","0.118"],["64010.00","0.381"],["64014.10","0.571"],["64016.40","1.431"],["64016.70","0.000"],["64017.30","0.018"],["64017.70","0.000"],["64017.90","0.000"],["64019.00","0.000"],["64019.40","0.003"],["64020.50","0.143"],["64021.50","0.028"],["64022.60","1.251"],["64023.70","0.563"],["64024.70","0.026"],["64025.30","0.080"],["64026.90","0.041"],["64027.90","0.016"],["64028.00","0.068"],["64031.10","0.016"],["64032.00","1.779"],["64032.30","0.001"],["64032.70","0.020"],["64033.10","2.323"],["64033.70","0.000"],["64035.20","3.289"],["64035.90","0.000"],["64036.90","0.003"],["64037.60","0.002"],["64038.40","1.177"],["64038.80","0.018"],["64040.00","0.042"],["64040.10","0.002"],["64041.10","0.369"],["64041.50","0.000"],["64041.80","0.401"],["64042.40","0.602"],["64042.60","2.066"],["64045.40","0.181"],["64045.60","0.336"],["64045.80","0.123"],["64046.10","0.062"],["64046.40","0.063"],["64046.60","0.034"],["64047.10","0.051"],["64047.20","0.263"],["64047.90","2.396"],["64048.90","0.082"],["64049.30","0.548"],["64049.80","0.611"],["64050.10","0.001"],["64051.60","0.005"],["64051.90","0.001"],["64052.50","2.866"],["64052.60","0.003"],["64052.70","1.328"],["64052.80","0.001"],["64053.00","0.776"],["64054.10","0.153"],["64054.90","0.498"],["64055.10","0.386"],["64055.30","0.022"],["64056.00","0.004"],["64056.20","0.770"],["64057.10","2.346"],["64057.20","0.005"],["64057.30","0.143"],["64057.70","0.434"],["64057.80","0.213"],["64057.90","0.000"],["64058.20","0.000"],["64058.30","0.000"],["64058.40","0.002"],["64058.80","0.555"],["64059.10","0.002"],["64059.80","0.003"],["64059.90","13.563"]],"e":"depthUpdate","ps":"BTCUSDT","pu":11165393919461,"s":"BTCUSDT","st":1,"u":11165393933823}
{"E":1785353516984,"T":1785353516983,"U":11165393933902,"a":[["64060.00","0.626"],["64060.10","0.000"],["64063.00","0.000"],["64063.20","0.009"],["64063.40","0.027"],["64064.30","0.149"],["64066.30","0.623"],["64066.40","0.095"],["64066.80","0.060"],["64067.10","0.004"],["64067.20","0.008"],["64067.30","0.673"],["64067.70","0.020"],["64067.90","0.000"],["64068.40","0.007"],["64068.80","0.167"],["64069.60","0.090"],["64070.20","0.326"],["64070.30","0.113"],["64070.90","0.157"],["64071.00","2.515"],["64071.10","0.003"],["64072.10","0.594"],["64072.20","2.084"],["64072.30","0.002"],["64072.40","0.002"],["64072.50","0.060"],["64072.80","0.491"],["64072.90","0.331"],["64073.20","0.597"],["64073.30","0.160"],["64073.40","0.767"],["64073.50","0.918"],["64073.60","2.586"],["64073.80","0.158"],["64074.30","0.000"],["64074.40","0.314"],["64074.50","0.229"],["64074.80","0.003"],["64075.60","1.327"],["64075.70","0.341"],["64077.50","0.224"],["64078.30","0.004"],["64081.50","0.001"],["64081.60","0.901"],["64085.70","0.703"],["64091.20","0.006"],["64091.40","0.104"],["64092.00","0.881"],["64093.80","0.001"],["64093.90","1.436"],["64095.30","0.090"],["64099.20","2.772"],["64099.60","1.059"],["64100.00","2.693"],["64101.10","0.002"],["64102.20","10.505"],["64106.20","0.002"],["64110.90","0.395"],["64114.30","0.056"],["64117.00","0.065"],["64121.60","0.020"],["64123.30","0.000"],["64123.90","0.128"],["64129.20","0.004"],["64137.60","0.290"],["64137.80","2.011"],["64141.20","5.604"],["64143.90","0.002"],["64152.60","0.021"],["64155.40","0.008"],["64168.30","0.528"],["64176.50","3.843"],["64177.90","0.158"],["64178.00","0.175"],["64178.20","0.000"],["64214.00","0.886"],["64216.00","0.881"],["64217.70","0.491"],["64218.00","1.372"],["64227.20","0.044"],["64229.00","0.013"],["64234.50","10.778"],["64265.00","0.495"],["64316.20","0.120"],["64366.10","0.000"],["64380.30","0.299"],["64546.90","0.000"],["64700.60","0.051"]],"b":[["1000.00","37.592"],["13541.70","0.000"],["13659.90","0.420"],["13741.70","0.196"],["13759.90","0.434"],["13845.70","0.714"],["13859.90","0.014"],["13959.90","0.406"],["51248.00","0.000"],["57653.90","0.002"],["61497.50","0.003"],["62760.90","1.042"],["63226.20","10.991"],["63242.20","13.644"],["63242.30","7.834"],["63274.20","10.552"],["63275.20","1.847"],["63277.10","6.258"],["63277.20","6.261"],["63309.20","4.066"],["63312.60","5.082"],["63357.80","0.703"],["63361.60","0.625"],["63402.20","10.170"],["63419.30","0.013"],["63427.00","0.003"],["63434.20","5.661"],["63437.30","5.431"],["63469.30","8.580"],["63725.40","0.001"],["63858.20","0.026"],["63870.90","0.000"],["63873.00","0.007"],["63900.30","0.514"],["63913.90","0.509"],["63915.90","0.009"],["63917.90","0.881"],["63928.30","0.002"],["63960.30","0.000"],["63978.20","0.012"],["63991.50","0.001"],["63992.30","0.003"],["63993.50","1.122"],["63998.10","21.949"],["63999.30","3.826"],["64001.00","0.570"],["64001.30","0.374"],["64002.50","0.379"],["64003.50","0.062"],["64006.00","0.418"],["64010.30","0.542"],["64024.30","0.000"],["64025.60","1.598"],["64030.80","0.196"],["64036.30","0.000"],["64037.20","0.003"],["64040.30","0.060"],["64040.50","0.000"],["64040.70","0.015"],["64040.80","0.015"],["64040.90","0.450"],["64041.60","0.068"],["64041.70","4.633"],["64041.80","0.369"],["64042.10","0.005"],["64042.40","0.604"],["64042.60","0.004"],["64042.80","0.047"],["64043.50","0.122"],["64043.60","0.036"],["64045.10","0.000"],["64045.30","2.500"],["64045.40","0.161"],["64045.70","0.580"],["64045.80","0.243"],["64045.90","0.182"],["64046.10","0.122"],["64046.30","0.060"],["64047.10","10.053"],["64047.20","0.325"],["64047.90","2.394"],["64048.00","2.661"],["64048.10","0.024"],["64048.90","0.084"],["64049.30","0.171"],["64049.40","0.041"],["64049.50","0.205"],["64049.60","0.548"],["64050.10","0.001"],["64052.00","0.001"],["64052.70","0.001"],["64052.90","0.223"],["64053.00","0.570"],["64053.10","1.329"],["64053.20","0.001"],["64055.10","0.408"],["64055.30","0.000"],["64055.40","0.051"],["64056.20","0.536"],["64057.00","0.001"],["64057.20","0.020"],["64057.30","0.002"],["64057.80","0.044"],["64057.90","0.000"],["64058.00","0.001"],["64058.10","0.547"],["64058.20","0.012"],["64058.60","0.346"],["64058.90","0.019"],["64059.70","0.008"],["64059.90","16.227"]],"e":"depthUpdate","ps":"BTCUSDT","pu":11165393933823,"s":"BTCUSDT","st":1,"u":11165393946727}
{"E":1785353517086,"T":1785353517084,"U":11165393946755,"a":[["64060.00","0.628"],["64063.30","0.001"],["64063.40","0.004"],["64063.60","0.026"],["64066.20","0.158"],["64066.30","0.014"],["64066.40","0.511"],["64067.70","0.176"],["64067.80","0.138"],["64069.60","0.012"],["64070.20","0.446"],["64070.30","0.019"],["64071.00","0.175"],["64071.10","0.097"],["64071.50","0.108"],["64073.00","0.546"],["64073.60","1.337"],["64077.20","0.180"],["64077.80","1.730"],["64078.30","0.002"],["64078.40","2.273"],["64080.00","0.801"],["64083.20","0.052"],["64086.30","0.003"],["64086.90","0.391"],["64087.50","1.052"],["64088.40","0.000"],["64089.20","0.013"],["64091.60","2.352"],["64092.20","1.759"],["64094.20","2.013"],["64094.60","0.028"],["64096.70","0.045"],["64097.00","1.219"],["64097.30","0.140"],["64097.70","0.094"],["64098.10","0.008"],["64098.80","0.046"],["64099.90","0.141"],["64102.60","0.370"],["64105.80","0.656"],["64106.30","1.443"],["64109.80","0.016"],["64110.90","0.395"],["64111.00","0.005"],["64123.10","0.027"],["64124.10","0.207"],["64128.10","0.482"],["64137.80","1.855"],["64137.90","0.035"],["64145.20","0.012"],["64167.50","0.014"],["64168.60","0.000"],["64176.00","1.820"],["64177.80","0.000"],["64214.00","0.006"],["64216.00","0.001"],["64218.00","0.492"],["64234.40","4.412"],["64234.80","0.000"],["64265.00","0.378"],["64380.30","0.001"],["64700.00","25.438"],["64700.60","0.051"],["65117.70","0.005"],["65341.10","0.006"]],"b":[["13659.90","0.546"],["13741.70","0.070"],["13759.90","0.560"],["13845.70","0.588"],["13859.90","0.126"],["13959.90","0.294"],["57653.90","0.002"],["61497.50","0.000"],["62574.40","0.002"],["62778.80","0.569"],["62965.60","0.000"],["63082.20","9.498"],["63131.00","1.207"],["63151.50","5.973"],["63210.20","2.667"],["63242.20","10.513"],["63242.30","1.572"],["63245.10","7.014"],["63277.10","12.516"],["63277.20","9.390"],["63306.20","0.553"],["63341.20","6.254"],["63370.20","3.137"],["63370.30","5.467"],["63402.20","4.970"],["63405.20","6.246"],["63419.30","0.011"],["63437.30","8.552"],["63441.40","1.044"],["63451.30","2.075"],["63738.90","0.000"],["63739.60","0.001"],["63760.90","0.004"],["63871.90","1.714"],["63917.90","0.001"],["63971.20","0.002"],["63977.70","0.003"],["63984.00","0.018"],["63989.40","0.138"],["63989.60","0.124"],["63990.40","2.003"],["63995.80","0.001"],["64003.00","0.021"],["64005.10","0.270"],["64006.20","0.395"],["64012.50","0.003"],["64012.60","1.246"],["64012.70","0.005"],["64012.80","0.021"],["64012.90","0.001"],["64013.00","0.000"],["64017.10","0.000"],["64018.50","0.006"],["64022.90","1.728"],["64023.20","0.004"],["64023.50","0.000"],["64023.90","0.326"],["64028.30","2.342"],["64030.70","0.004"],["64030.80","0.198"],["64030.90","0.019"],["64031.00","0.004"],["64031.10","0.018"],["64031.20","0.002"],["64033.10","2.331"],["64034.20","0.008"],["64040.30","0.000"],["64041.10","0.230"],["64041.40","0.000"],["64044.80","0.505"],["64046.30","0.120"],["64048.40","0.001"],["64050.10","0.021"],["64054.40","0.001"],["64054.90","0.472"],["64055.10","0.371"],["64056.50","0.015"],["64057.20","0.005"],["64057.30","0.143"],["64057.80","0.024"],["64058.10","0.313"],["64058.50","0.615"],["64058.90","0.011"],["64059.00","0.016"],["64059.10","0.000"],["64059.70","0.000"],["64059.80","0.005"],["64059.90","15.133"]],"e":"depthUpdate","ps":"BTCUSDT","pu":11165393946727,"s":"BTCUSDT","st":1,"u":11165393957855}
{"E":1785353517188,"T":1785353517187,"U":11165393957978,"a":[["64060.00","0.626"],["64060.70","0.002"],["64064.30","0.085"],["64066.00","0.008"],["64066.20","0.001"],["64066.40","0.511"],["64068.40","0.009"],["64068.60","0.000"],["64069.80","0.008"],["64070.80","0.001"],["64070.90","0.159"],["64071.10","0.095"],["64071.30","0.000"],["64072.40","0.000"],["64072.80","0.491"],["64074.60","10.210"],["64075.60","0.327"],["64075.90","1.001"],["64076.80","0.066"],["64077.40","0.019"],["64079.90","0.401"],["64088.90","0.016"],["64089.20","0.013"],["64097.10","0.618"],["64097.30","0.020"],["64097.50","0.177"],["64097.60","0.000"],["64098.30","2.002"],["64099.20","1.481"],["64102.00","0.632"],["64102.20","0.507"],["64102.90","0.486"],["64109.50","1.522"],["64110.90","0.551"],["64127.10","0.001"],["64127.40","2.356"],["64137.80","1.705"],["64141.60","0.002"],["64167.90","0.000"],["64173.70","0.003"],["64177.90","0.002"],["64178.50","0.001"],["64178.90","0.002"],["64188.70","0.000"],["64188.80","0.672"],["64212.00","0.489"],["64214.00","0.006"],["64216.00","0.001"],["64217.90","0.000"],["64218.00","0.492"],["64380.30","0.001"],["64498.50","0.116"],["64700.60","0.052"],["64837.70","0.000"],["64913.70","0.000"],["65322.60","0.138"],["65963.90","0.000"]],"b":[["1000.00","37.742"],["13559.90","0.042"],["13659.90","0.574"],["13741.70","0.000"],["13759.90","0.672"],["13845.70","0.476"],["13859.90","0.252"],["13959.90","0.168"],["57653.90","0.002"],["61497.50","0.003"],["62062.60","0.707"],["62778.80","0.572"],["62983.60","0.023"],["63024.90","8.014"],["63067.00","1.099"],["63089.00","18.264"],["63131.00","2.305"],["63146.20","5.643"],["63195.10","1.124"],["63206.70","0.790"],["63210.20","1.884"],["63226.20","6.607"],["63259.20","0.782"],["63275.20","6.228"],["63277.20","10.969"],["63338.20","2.313"],["63387.30","1.562"],["63402.20","4.267"],["63419.30","0.011"],["63434.20","3.320"],["63451.30","2.777"],["63469.30","10.920"],["63739.60","0.001"],["63943.40","6.225"],["63945.60","0.412"],["63946.20","2.353"],["63988.10","0.000"],["63997.70","0.001"],["63998.10","21.951"],["64001.00","0.510"],["64003.50","0.099"],["64006.30","0.015"],["64028.60","0.004"],["64034.60","0.500"],["64040.60","0.042"],["64040.90","0.453"],["64041.20","0.002"],["64041.30","0.016"],["64041.60","0.008"],["64041.70","4.573"],["64042.80","0.109"],["64043.20","2.060"],["64045.40","0.181"],["64046.90","0.036"],["64047.10","0.051"],["64047.20","0.263"],["64048.00","1.167"],["64048.10","0.004"],["64049.30","0.171"],["64050.10","0.021"],["64051.00","0.009"],["64052.10","0.317"],["64054.40","0.023"],["64056.20","0.538"],["64056.60","0.002"],["64057.40","0.013"],["64057.80","0.090"],["64058.00","0.235"],["64058.20","0.000"],["64058.50","0.384"],["64058.70","0.011"],["64058.90","0.011"],["64059.00","0.003"],["64059.10","0.000"],["64059.50","0.009"],["64059.60","0.002"],["64059.80","0.003"],["64059.90","15.163"]],"e":"depthUpdate","ps":"BTCUSDT","pu":11165393957855,"s":"BTCUSDT","st":1,"u":11165393967817}
{"E":1785353517290,"T":1785353517288,"U":11165393967880,"a":[["64060.00","0.628"],["64065.30","0.002"],["64066.40","0.212"],["64067.10","0.003"],["64070.30","0.007"],["64071.20","0.350"],["64072.80","1.504"],["64072.90","0.343"],["64076.50","0.002"],["64077.50","0.107"],["64078.00","0.002"],["64078.10","0.602"],["64078.60","0.160"],["64079.30","0.130"],["64079.90","0.398"],["64081.30","0.005"],["64081.80","0.094"],["64086.40","0.011"],["64089.20","0.014"],["64097.20","5.897"],["64097.80","0.004"],["64099.20","1.481"],["64102.20","0.507"],["64108.20","0.001"],["64110.80","0.000"],["64110.90","0.395"],["64119.70","0.025"],["64125.20","0.017"],["64126.60","0.327"],["64127.00","0.097"],["64133.40","0.058"],["64137.00","0.015"],["64141.20","5.448"],["64163.20","0.277"],["64179.20","0.965"],["64179.80","0.001"],["64190.00","3.953"],["64265.00","0.378"],["64290.30","1.236"],["64380.30","0.300"],["64682.20","0.030"],["64700.60","0.052"],["64839.70","0.000"],["65136.30","0.027"],["65322.60","0.135"]],"b":[["1000.00","37.592"],["13559.90","0.168"],["13659.90","0.448"],["13759.90","0.798"],["13845.70","0.350"],["13859.90","0.364"],["13959.90","0.056"],["51233.00","0.000"],["57653.90","0.002"],["60839.70","0.008"],["62942.90","0.000"],["63079.70","1.333"],["63082.20","7.300"],["63131.00","4.501"],["63146.20","3.449"],["63195.10","3.318"],["63210.20","1.101"],["63210.30","0.183"],["63226.20","5.026"],["63259.20","2.346"],["63275.20","7.808"],["63401.40","0.030"],["63419.30","0.011"],["63668.20","0.452"],["63695.20","0.000"],["63695.30","0.000"],["63748.10","0.000"],["63787.00","0.396"],["63915.60","0.003"],["63923.60","0.000"],["63926.20","1.443"],["63933.70","5.862"],["63935.80","1.436"],["63954.10","21.947"],["63954.60","4.772"],["63954.90","0.001"],["63960.70","0.482"],["63985.50","0.489"],["63986.20","0.000"],["63987.10","0.094"],["63987.20","1.629"],["63992.30","0.010"],["63998.10","0.004"],["63998.30","0.100"],["63999.30","0.614"],["64002.50","0.379"],["64003.20","3.869"],["64003.50","0.062"],["64006.00","0.381"],["64008.80","0.031"],["64009.60","0.100"],["64009.90","0.642"],["64013.90","0.003"],["64014.20","0.979"],["64032.00","1.781"],["64035.20","2.996"],["64041.60","0.708"],["64042.80","0.047"],["64043.20","0.060"],["64045.80","0.242"],["64048.00","1.165"],["64048.20","10.003"],["64048.30","0.063"],["64048.60","0.872"],["64049.80","0.670"],["64050.10","0.021"],["64051.00","0.011"],["64051.20","2.530"],["64052.80","0.002"],["64053.20","0.021"],["64056.10","0.315"],["64057.30","0.002"],["64057.40","0.001"],["64057.50","0.003"],["64057.70","0.434"],["64057.80","0.070"],["64058.00","0.001"],["64058.20","0.012"],["64058.40","0.236"],["64058.70","0.001"],["64059.00","0.003"],["64059.50","0.001"],["64059.90","20.988"]],"e":"depthUpdate","ps":"BTCUSDT","pu":11165393967817,"s":"BTCUSDT","st":1,"u":11165393975900}
{"E":1785353517392,"T":1785353517391,"U":11165393976013,"a":[["64060.00","3.486"],["64060.10","0.001"],["64063.20","0.009"],["64063.30","0.023"],["64064.30","0.079"],["64066.10","0.001"],["64066.20","0.313"],["64066.40","0.017"],["64067.50","0.008"],["64069.60","0.090"],["64070.80","1.001"],["64070.90","0.002"],["64071.10","0.095"],["64071.90","0.091"],["64072.00","0.160"],["64072.80","1.504"],["64072.90","0.343"],["64074.80","0.003"],["64075.90","0.001"],["64076.20","0.047"],["64079.30","0.133"],["64095.50","2.123"],["64098.30","0.002"],["64099.20","2.771"],["64099.60","1.047"],["64100.00","2.691"],["64100.20","0.506"],["64103.00","0.005"],["64104.90","0.118"],["64110.90","0.395"],["64113.70","0.306"],["64113.80","0.289"],["64120.90","0.000"],["64140.90","0.000"],["64145.30","0.000"],["64147.50","0.002"],["64149.80","23.694"],["64178.00","0.019"],["64179.20","0.827"],["64230.30","0.001"],["64232.30","0.003"],["64252.60","0.984"],["64265.00","0.495"],["64290.30","1.022"],["64380.30","0.300"],["64556.80","0.116"],["64700.60","0.052"],["64822.30","0.925"]],"b":[["13559.90","0.280"],["13659.90","0.336"],["13759.90","0.910"],["13845.70","0.238"],["13859.90","0.490"],["13954.90","0.224"],["13955.10","0.000"],["13957.60","0.000"],["13959.90","0.000"],["57653.90","0.002"],["61497.50","0.000"],["62961.90","0.840"],["63092.90","0.000"],["63131.00","5.599"],["63146.20","2.352"],["63156.90","0.000"],["63195.10","5.512"],["63220.90","0.355"],["63259.20","3.128"],["63350.60","0.946"],["63419.30","0.011"],["63466.20","0.000"],["63515.40","2.307"],["63750.20","0.000"],["63792.90","0.054"],["63829.80","0.000"],["63850.70","0.004"],["63864.50","0.117"],["63866.70","0.000"],["63875.00","0.052"],["63942.10","0.511"],["63944.10","0.004"],["63954.10","0.000"],["63954.60","1.694"],["63968.30","0.094"],["63970.20","0.141"],["63973.60","0.010"],["63982.70","0.000"],["63983.60","0.001"],["63984.90","21.969"],["63987.20","4.701"],["63990.70","0.000"],["64005.40","2.496"],["64005.50","0.060"],["64005.60","0.123"],["64006.00","0.418"],["64026.00","0.004"],["64040.60","10.045"],["64041.10","1.691"],["64041.40","0.468"],["64041.50","0.000"],["64042.50","2.403"],["64043.20","0.598"],["64044.40","0.000"],["64045.00","0.003"],["64046.20","0.020"],["64047.90","2.377"],["64048.20","0.001"],["64048.30","0.001"],["64049.30","0.001"],["64049.40","0.021"],["64049.60","0.001"],["64050.10","0.001"],["64051.00","0.004"],["64051.20","1.067"],["64053.20","0.001"],["64054.40","0.001"],["64054.90","0.471"],["64055.10","0.371"],["64055.40","0.004"],["64056.40","2.500"],["64057.50","0.003"],["64057.60","2.088"],["64057.70","0.446"],["64057.80","0.177"],["64057.90","0.607"],["64058.10","0.003"],["64058.20","0.010"],["64058.40","0.002"],["64058.90","0.081"],["64059.00","0.008"],["64059.30","0.000"],["64059.90","13.653"]],"e":"depthUpdate","ps":"BTCUSDT","pu":11165393975900,"s":"BTCUSDT","st":1,"u":11165393987094}
{"E":1785353517494,"T":1785353517492,"U":11165393987141,"a":[["64060.00","3.488"],["64063.00","0.023"],["64063.60","0.003"],["64067.20","0.164"],["64067.30","1.007"],["64068.80","0.713"],["64069.20","0.649"],["64070.10","2.342"],["64070.30","1.256"],["64071.00","0.173"],["64071.80","0.018"],["64072.00","0.003"],["64072.10","0.048"],["64074.50","0.541"],["64075.30","0.563"],["64077.00","1.306"],["64078.10","0.040"],["64079.30","0.016"],["64079.70","0.026"],["64080.90","0.004"],["64084.10","0.418"],["64087.60","0.022"],["64088.00","0.003"],["64088.40","0.000"],["64089.20","0.005"],["64090.50","0.157"],["64094.50","0.000"],["64096.90","0.313"],["64097.00","1.223"],["64097.30","0.018"],["64097.80","0.008"],["64098.10","0.004"],["64099.20","1.478"],["64106.00","0.159"],["64106.20","0.002"],["64110.90","0.395"],["64140.80","1.345"],["64140.90","0.000"],["64144.30","5.490"],["64145.30","23.205"],["64147.40","1.363"],["64149.80","0.489"],["64165.40","0.097"],["64290.30","0.000"],["64700.00","25.538"],["64700.60","0.052"],["64800.00","60.138"],["64822.30","1.849"],["65322.60","0.132"],["65341.10","0.009"]],"b":[["1000.00","37.592"],["13559.90","0.406"],["13659.90","0.210"],["13759.90","1.036"],["13845.70","0.112"],["13859.90","0.602"],["13954.90","0.112"],["57653.90","0.002"],["61433.30","0.002"],["61497.50","0.003"],["63082.20","6.201"],["63089.00","17.166"],["63131.00","7.795"],["63217.00","4.700"],["63259.20","3.910"],["63402.30","2.190"],["63419.30","0.011"],["63451.30","5.086"],["63739.60","0.001"],["63983.60","2.714"],["63998.20","0.237"],["64000.00","11.003"],["64005.10","0.060"],["64011.20","0.132"],["64018.20","0.005"],["64018.50","0.003"],["64022.90","1.732"],["64023.20","0.000"],["64026.80","0.313"],["64033.20","0.158"],["64036.10","0.001"],["64036.60","1.551"],["64038.30","0.000"],["64039.00","0.295"],["64039.50","0.051"],["64039.60","0.081"],["64040.60","10.047"],["64043.20","0.541"],["64048.40","0.001"],["64048.80","0.003"],["64049.10","1.157"],["64049.30","0.738"],["64049.60","0.002"],["64049.90","0.314"],["64050.90","0.001"],["64053.10","0.002"],["64054.90","0.470"],["64055.60","0.023"],["64056.10","0.022"],["64056.70","0.263"],["64057.80","0.007"],["64057.90","1.366"],["64058.00","0.001"],["64058.60","0.542"],["64059.90","13.790"]],"e":"depthUpdate","ps":"BTCUSDT","pu":11165393987094,"s":"BTCUSDT","st":1,"u":11165393994743}
{"E":1785353517596,"T":1785353517595,"U":11165393994917,"a":[["64060.00","3.513"],["64063.00","0.023"],["64064.30","0.446"],["64066.40","0.095"],["64067.10","0.126"],["64067.20","2.506"],["64067.80","0.013"],["64072.80","1.426"],["64072.90","0.331"],["64073.60","0.637"],["64076.00","0.008"],["64089.20","0.006"],["64100.40","0.001"],["64105.90","0.160"],["64106.00","0.002"],["64108.20","0.000"],["64123.40","0.024"],["64130.50","0.154"],["64138.30","0.168"],["64140.80","4.500"],["64143.10","23.219"],["64144.30","2.336"],["64145.30","0.000"],["64187.80","0.017"],["64390.40","0.265"],["64546.90","0.220"],["64700.50","1.226"],["64700.60","0.054"],["64933.00","0.829"],["64969.70","0.272"],["65035.50","6.786"]],"b":[["13559.90","0.518"],["13659.90","0.098"],["13759.90","1.148"],["13845.70","0.000"],["13859.90","0.728"],["13952.50","0.084"],["13954.90","0.000"],["57653.90","0.002"],["61497.50","0.000"],["62924.90","1.288"],["62988.90","2.210"],["63082.20","4.003"],["63114.20","18.526"],["63121.00","23.672"],["63131.00","9.991"],["63163.10","4.702"],["63217.00","3.917"],["63249.00","28.890"],["63259.20","4.692"],["63274.20","7.423"],["63274.40","0.000"],["63291.20","1.564"],["63309.20","7.194"],["63419.30","0.011"],["63434.20","0.199"],["63469.40","3.121"],["63650.00","3.113"],["63690.20","0.544"],["63739.60","0.079"],["63960.70","22.429"],["63961.60","15.378"],["63969.20","0.013"],["63984.90","0.022"],["63987.20","1.629"],["63992.70","0.031"],["64001.20","0.005"],["64003.50","0.075"],["64005.00","0.101"],["64014.00","0.002"],["64020.50","0.026"],["64037.40","10.321"],["64040.60","0.047"],["64041.10","0.230"],["64041.70","4.478"],["64049.50","0.204"],["64050.00","0.026"],["64053.90","0.003"],["64055.00","0.005"],["64055.60","0.000"],["64056.70","0.029"],["64057.60","2.090"],["64057.90","1.346"],["64058.90","0.018"],["64059.90","13.879"]],"e":"depthUpdate","ps":"BTCUSDT","pu":11165393994743,"s":"BTCUSDT","st":1,"u":11165394001394}
{"E":1785353517698,"T":1785353517697,"U":11165394001459,"a":[["64060.00","3.154"],["64062.00","0.004"],["64064.20","0.004"],["64066.40","0.095"],["64066.70","0.015"],["64067.10","0.189"],["64067.70","0.200"],["64068.00","1.187"],["64069.60","0.250"],["64074.00","2.420"],["64080.00","0.803"],["64088.80","0.351"],["64089.60","2.952"],["64091.20","0.007"],["64091.70","0.001"],["64092.00","0.537"],["64095.50","0.123"],["64105.80","0.813"],["64105.90","0.003"],["64110.90","0.395"],["64119.60","0.214"],["64127.20","0.029"],["64130.50","0.076"],["64147.20","0.017"],["64179.00","0.003"],["64196.20","0.986"],["64232.30","0.000"],["64232.40","0.546"],["64445.30","0.031"],["64700.60","0.054"],["64726.10","0.100"],["64988.90","1.181"],["65341.10","0.012"],["66007.80","0.680"],["67930.40","0.000"]],"b":[["13559.90","0.644"],["13655.10","0.028"],["13658.80","0.000"],["13659.90","0.000"],["13759.90","1.274"],["13841.70","0.056"],["13844.70","0.000"],["13845.20","0.000"],["13859.90","0.840"],["13949.90","0.000"],["13951.50","0.000"],["13952.50","0.000"],["57653.90","0.002"],["61497.50","0.003"],["62986.20","0.000"],["63018.10","4.255"],["63024.90","6.914"],["63025.90","0.000"],["63034.90","1.129"],["63067.00","4.396"],["63082.20","0.706"],["63128.60","16.030"],["63131.00","13.285"],["63163.10","7.053"],["63217.00","3.134"],["63224.70","0.006"],["63247.50","0.007"],["63256.70","9.391"],["63259.20","6.256"],["63291.20","4.692"],["63402.20","1.144"],["63405.30","0.074"],["63419.30","0.011"],["63432.60","0.002"],["63437.40","4.521"],["63467.80","3.120"],["63783.40","0.000"],["63905.00","0.000"],["63911.10","0.006"],["63914.20","0.002"],["63918.60","0.745"],["63944.10","0.001"],["63944.20","0.004"],["63945.60","0.411"],["63960.70","0.482"],["63961.60","11.894"],["63966.70","0.001"],["63980.50","0.000"],["63980.60","0.970"],["63982.70","21.947"],["63983.60","5.643"],["64003.50","0.062"],["64009.80","0.198"],["64028.10","0.020"],["64034.80","2.362"],["64038.40","2.592"],["64038.80","0.019"],["64041.10","0.431"],["64041.80","0.369"],["64045.60","0.338"],["64047.50","0.048"],["64048.00","1.166"],["64049.40","0.022"],["64053.90","0.040"],["64056.10","0.023"],["64058.20","0.000"],["64058.70","0.011"],["64059.00","0.000"],["64059.20","0.008"],["64059.80","0.003"],["64059.90","15.388"]],"e":"depthUpdate","ps":"BTCUSDT","pu":11165394001394,"s":"BTCUSDT","st":1,"u":11165394007346}
{"E":1785353517800,"T":1785353517798,"U":11165394007407,"a":[["64060.10","0.002"],["64061.40","0.023"],["64063.00","0.000"],["64063.30","0.001"],["64066.40","0.017"],["64067.00","0.608"],["64068.80","0.167"],["64068.90","0.003"],["64070.00","0.554"],["64072.80","1.316"],["64084.10","0.340"],["64089.60","1.699"],["64090.50","0.001"],["64096.90","0.001"],["64105.70","0.160"],["64105.80","0.656"],["64120.90","0.078"],["64130.50","0.154"],["64269.10","0.003"],["64285.20","0.779"],["64285.50","0.002"],["64374.70","0.005"],["64374.80","0.001"],["64380.30","0.455"],["64480.30","0.153"],["64480.50","0.000"],["64700.60","0.052"],["64963.20","0.923"],["65087.40","0.767"]],"b":[["1000.00","37.592"],["13559.90","0.756"],["13654.90","0.154"],["13655.10","0.000"],["13659.90","0.056"],["13759.90","1.274"],["13841.70","0.000"],["13859.90","0.966"],["13945.70","0.434"],["13945.90","0.000"],["13948.60","0.000"],["13949.10","0.000"],["13949.50","0.000"],["51248.00","0.000"],["57653.90","0.002"],["63018.10","2.212"],["63024.90","5.814"],["63067.00","7.536"],["63114.20","16.173"],["63121.00","18.966"],["63128.60","13.678"],["63163.10","16.457"],["63219.70","0.710"],["63242.20","8.948"],["63249.00","27.325"],["63256.70","7.826"],["63259.20","7.038"],["63277.20","12.548"],["63291.20","9.384"],["63338.20","0.000"],["63371.00","0.111"],["63387.30","3.874"],["63407.30","0.427"],["63419.30","0.011"],["63531.10","0.028"],["63567.40","0.093"],["63594.10","0.003"],["63699.80","0.012"],["63699.90","0.000"],["63739.60","0.079"],["63784.90","0.593"],["63805.50","0.232"],["63805.70","0.001"],["63911.90","0.001"],["63913.90","0.509"],["63928.30","0.000"],["63928.40","0.065"],["63928.50","0.010"],["63946.30","0.040"],["63953.30","0.005"],["64039.60","0.003"],["64041.80","2.369"],["64052.60","1.350"],["64057.90","0.000"],["64058.00","0.001"],["64058.10","0.003"],["64058.60","0.346"],["64059.20","0.000"],["64059.30","0.000"],["64059.40","0.008"]],"e":"depthUpdate","ps":"BTCUSDT","pu":11165394007346,"s":"BTCUSDT","st":1,"u":11165394013484}
{"E":1785353517902,"T":1785353517901,"U":11165394013592,"a":[["64073.60","1.337"],["64089.20","0.005"],["64092.80","0.007"],["64110.90","0.551"],["64116.20","0.923"],["64140.90","23.205"],["64143.10","0.014"],["64390.30","0.796"],["64700.60","0.052"],["64858.90","0.019"],["64882.70","0.000"],["65052.80","10.981"],["65533.40","0.762"],["65981.80","1.077"]],"b":[["13559.90","0.882"],["13654.90","0.028"],["13659.90","0.182"],["13759.90","1.148"],["13859.90","1.078"],["13945.70","0.322"],["51247.90","0.000"],["57653.90","0.002"],["61497.50","0.000"],["62138.10","1.125"],["62586.50","0.819"],["63024.90","4.714"],["63067.00","8.635"],["63079.70","0.780"],["63121.00","11.907"],["63163.10","23.510"],["63217.00","2.351"],["63222.00","0.622"],["63249.00","25.760"],["63259.20","7.820"],["63282.00","0.939"],["63291.20","10.948"],["63323.20","0.938"],["63419.30","0.011"],["64014.40","0.046"],["64016.00","0.006"],["64028.80","0.009"],["64035.20","2.296"],["64041.60","0.008"],["64044.80","0.506"],["64052.60","1.330"],["64056.00","0.238"],["64057.80","0.027"]],"e":"depthUpdate","ps":"BTCUSDT","pu":11165394013484,"s":"BTCUSDT","st":1,"u":11165394021648}
{"E":1785353518004,"T":1785353518003,"U":11165394021765,"a":[["64060.00","4.471"],["64062.90","0.009"],["64065.20","0.014"],["64066.40","0.095"],["64066.90","0.005"],["64067.10","0.191"],["64069.60","1.250"],["64070.80","0.001"],["64072.80","1.426"],["64079.70","0.061"],["64080.20","0.034"],["64080.90","0.008"],["64086.80","0.697"],["64087.00","0.387"],["64089.20","10.005"],["64089.60","2.878"],["64091.20","0.007"],["64100.00","2.693"],["64100.20","0.504"],["64110.90","0.551"],["64140.80","1.345"],["64140.90","0.000"],["64144.30","5.491"],["64145.30","23.215"],["64175.90","0.662"],["64498.50","0.000"],["64700.60","0.206"],["64835.60","0.002"],["64988.80","1.887"],["65149.00","0.467"]],"b":[["13559.90","0.994"],["13652.50","0.028"],["13654.90","0.000"],["13659.90","0.294"],["13759.90","1.036"],["13859.90","1.204"],["13945.70","0.196"],["57653.90","0.002"],["60839.60","0.002"],["60839.70","0.010"],["61497.50","0.003"],["62970.90","0.653"],["62992.90","0.000"],["63022.00","0.000"],["63024.90","3.614"],["63034.90","2.228"],["63067.00","10.833"],["63089.00","14.970"],["63121.00","7.201"],["63131.00","15.481"],["63163.10","28.212"],["63249.00","22.630"],["63263.60","0.237"],["63278.00","0.697"],["63281.00","1.721"],["63283.40","1.211"],["63291.20","14.076"],["63313.30","3.128"],["63315.90","3.133"],["63323.20","1.876"],["63402.30","1.565"],["63419.30","0.168"],["63440.70","0.000"],["63451.30","5.710"],["63478.40","2.339"],["63874.90","0.003"],["63911.90","0.001"],["63913.90","0.509"],["63920.80","26.138"],["63999.90","0.028"],["64003.40","0.000"],["64003.50","0.075"],["64010.30","0.517"],["64022.40","0.130"],["64026.80","0.001"],["64029.80","0.001"],["64032.50","0.055"],["64033.10","12.331"],["64033.20","0.002"],["64033.90","0.562"],["64035.20","3.240"],["64037.40","0.323"],["64038.40","0.379"],["64039.50","0.001"],["64041.10","0.230"],["64041.80","0.369"],["64048.20","0.157"],["64049.30","0.582"],["64051.30","0.110"],["64051.40","0.000"],["64052.60","0.003"],["64057.80","0.027"],["64057.90","0.000"],["64058.00","1.327"],["64058.60","0.356"],["64058.70","0.001"],["64059.20","0.008"],["64059.40","0.000"],["64059.80","0.003"],["64059.90","14.811"]],"e":"depthUpdate","ps":"BTCUSDT","pu":11165394021648,"s":"BTCUSDT","st":1,"u":11165394029090}
{"E":1785353518106,"T":1785353518104,"U":11165394029124,"a":[["64060.00","3.760"],["64060.80","0.027"],["64061.10","0.022"],["64061.40","0.000"],["64061.60","0.119"],["64063.30","0.372"],["64063.70","0.000"],["64063.80","0.048"],["64064.00","0.011"],["64064.20","0.317"],["64064.30","0.649"],["64065.50","0.016"],["64066.00","0.780"],["64067.20","2.526"],["64067.30","1.391"],["64067.80","0.072"],["64069.20","0.629"],["64069.80","0.008"],["64070.20","0.435"],["64071.50","0.108"],["64072.60","0.222"],["64072.90","1.266"],["64073.60","0.637"],["64074.70","0.433"],["64077.00","1.190"],["64077.20","0.134"],["64077.60","0.085"],["64078.10","0.000"],["64078.30","0.236"],["64078.80","0.364"],["64080.90","0.007"],["64084.90","0.000"],["64085.70","0.469"],["64085.90","0.046"],["64086.80","0.697"],["64086.90","0.511"],["64088.60","0.171"],["64089.20","0.005"],["64089.60","2.878"],["64091.10","10.001"],["64094.70","0.000"],["64096.10","0.101"],["64103.30","0.505"],["64106.80","0.048"],["64109.50","1.522"],["64110.90","0.395"],["64116.50","0.523"],["64119.60","0.004"],["64120.90","0.000"],["64124.70","0.000"],["64130.50","0.076"],["64132.60","0.007"],["64140.80","4.501"],["64143.20","23.246"],["64144.30","2.336"],["64145.30","0.000"],["64154.40","0.000"],["64206.00","0.013"],["64208.00","0.001"],["64210.00","0.007"],["64212.00","0.489"],["64285.20","1.133"],["64285.50","2.957"],["64289.90","0.037"],["64380.20","0.180"],["64380.30","0.455"],["64559.50","1.216"],["64700.60","0.206"],["64834.60","0.847"],["64959.40","1.306"],["64990.50","11.576"],["65054.60","10.650"],["65322.60","0.129"],["65555.00","65.858"]],"b":[["1000.00","37.592"],["13559.90","1.120"],["13645.70","0.280"],["13648.60","0.000"],["13649.10","0.000"],["13649.50","0.000"],["13649.90","0.000"],["13652.50","0.000"],["13659.90","0.420"],["13759.90","0.910"],["13859.90","1.316"],["13945.70","0.084"],["57653.90","0.002"],["61497.50","0.000"],["62778.80","0.575"],["63089.00","13.087"],["63114.20","13.820"],["63121.00","4.848"],["63128.60","11.326"],["63131.00","17.363"],["63163.10","35.265"],["63217.00","1.568"],["63242.20","7.383"],["63249.00","16.370"],["63256.70","6.261"],["63259.20","8.602"],["63286.30","3.397"],["63291.20","20.332"],["63370.20","0.013"],["63377.00","5.753"],["63405.30","3.197"],["63414.40","1.873"],["63419.30","0.168"],["63626.20","0.157"],["63661.40","0.389"],["63739.60","0.079"],["63875.20","0.458"],["63907.90","0.000"],["63909.90","0.887"],["63911.90","0.882"],["63913.90","1.390"],["63915.90","0.890"],["63917.90","0.882"],["63919.90","0.076"],["63991.70","0.707"],["63998.20","0.027"],["64016.50","3.022"],["64019.50","0.070"],["64022.00","0.093"],["64022.30","0.241"],["64027.40","0.071"],["64028.50","0.314"],["64028.80","0.009"],["64029.10","1.265"],["64032.00","1.283"],["64033.10","2.331"],["64033.20","10.002"],["64035.20","3.210"],["64036.70","0.510"],["64037.00","2.001"],["64037.10","0.115"],["64037.20","0.471"],["64038.40","1.079"],["64041.40","0.000"],["64042.50","2.341"],["64043.60","0.001"],["64044.30","1.882"],["64046.40","0.083"],["64048.20","0.001"],["64048.40","0.001"],["64049.20","1.251"],["64049.80","0.611"],["64051.30","1.437"],["64051.40","0.020"],["64051.50","0.274"],["64051.90","0.001"],["64052.10","0.004"],["64052.40","0.239"],["64052.60","0.221"],["64053.00","0.570"],["64053.30","0.001"],["64053.90","0.018"],["64054.00","0.002"],["64054.30","0.001"],["64054.80","0.002"],["64055.30","0.093"],["64055.60","0.015"],["64056.00","0.004"],["64056.50","2.342"],["64056.70","0.032"],["64057.10","0.006"],["64057.20","0.003"],["64057.30","0.017"],["64057.50","0.006"],["64057.60","1.390"],["64057.70","0.434"],["64057.80","0.014"],["64058.00","0.001"],["64058.10","0.000"],["64058.20","0.000"],["64058.30","0.000"],["64058.50","0.381"],["64058.60","0.167"],["64058.70","0.009"],["64058.80","0.265"],["64058.90","0.018"],["64059.20","0.000"],["64059.80","0.004"],["64059.90","11.573"]],"e":"depthUpdate","ps":"BTCUSDT","pu":11165394029090,"s":"BTCUSDT","st":1,"u":11165394041145}
{"E":1785353518208,"T":1785353518204,"U":11165394041265,"a":[["64060.00","3.480"],["64060.70","0.004"],["64062.90","0.009"],["64066.40","0.017"],["64067.20","2.506"],["64068.00","0.305"],["64068.90","0.023"],["64069.60","0.328"],["64070.60","1.000"],["64072.60","0.102"],["64075.50","0.002"],["64076.20","0.049"],["64076.60","0.380"],["64077.30","0.091"],["64091.10","10.003"],["64091.60","2.350"],["64096.00","3.079"],["64102.00","0.635"],["64110.90","0.395"],["64124.90","0.015"],["64130.50","0.154"],["64136.80","0.083"],["64352.00","0.102"],["64700.60","0.205"],["64822.30","2.773"],["64828.70","1.771"],["64988.80","2.502"],["65215.70","0.785"]],"b":[["13559.90","1.232"],["13645.70","0.168"],["13659.90","0.532"],["13759.90","0.840"],["13859.90","1.358"],["13945.70","0.000"],["57653.90","0.002"],["60095.90","0.000"],["60839.70","0.008"],["60856.90","0.006"],["61374.50","0.000"],["61497.50","0.003"],["62760.90","1.039"],["62778.80","0.578"],["63000.60","0.006"],["63018.10","1.112"],["63034.90","3.327"],["63067.00","11.932"],["63089.00","10.891"],["63091.30","1.879"],["63114.30","0.000"],["63121.00","2.495"],["63131.00","20.657"],["63163.10","39.967"],["63187.60","2.039"],["63195.10","6.064"],["63242.30","0.007"],["63249.00","14.805"],["63257.50","0.000"],["63291.20","25.024"],["63312.60","4.378"],["63361.60","1.328"],["63419.30","0.168"],["63909.90","0.006"],["63911.90","0.001"],["63913.90","0.509"],["63915.90","0.009"],["63917.90","0.001"],["63919.60","0.827"],["63920.90","0.916"],["63921.90","0.881"],["64017.50","0.005"],["64019.50","0.000"],["64021.50","0.029"],["64026.60","0.240"],["64027.40","0.022"],["64033.10","2.329"],["64033.20","0.004"],["64034.50","0.291"],["64035.20","1.968"],["64036.70","0.003"],["64037.30","0.894"],["64041.80","0.431"],["64049.30","0.001"],["64050.00","0.006"],["64051.30","0.110"],["64051.40","0.000"],["64052.40","0.005"],["64052.60","0.003"],["64054.10","0.153"],["64054.80","0.002"],["64055.40","0.238"],["64056.60","2.105"],["64057.60","1.818"],["64059.90","11.593"]],"e":"depthUpdate","ps":"BTCUSDT","pu":11165394041145,"s":"BTCUSDT","st":1,"u":11165394048673}
{"E":1785353518310,"T":1785353518309,"U":11165394048876,"a":[["64060.00","0.627"],["64060.10","0.000"],["64060.80","0.005"],["64061.10","0.000"],["64061.30","0.002"],["64061.40","0.000"],["64061.60","0.001"],["64062.90","0.031"],["64063.20","0.009"],["64063.30","0.001"],["64063.80","0.001"],["64064.20","0.004"],["64064.30","0.287"],["64065.20","0.002"],["64065.90","0.548"],["64066.10","0.000"],["64066.20","0.000"],["64066.40","0.017"],["64066.90","0.162"],["64067.00","0.000"],["64067.10","0.126"],["64067.20","0.166"],["64067.30","0.875"],["64067.70","0.176"],["64067.80","0.013"],["64068.70","0.001"],["64068.80","0.010"],["64069.20","0.083"],["64069.60","0.328"],["64070.20","0.315"],["64070.30","0.007"],["64070.60","0.000"],["64071.00","0.016"],["64071.80","0.002"],["64072.10","0.205"],["64072.70","0.326"],["64072.80","1.426"],["64072.90","1.278"],["64073.40","0.610"],["64073.80","0.001"],["64073.90","0.237"],["64074.50","0.229"],["64075.00","1.004"],["64078.30","0.002"],["64078.80","0.314"],["64079.30","0.013"],["64079.70","0.026"],["64081.30","0.317"],["64082.30","0.217"],["64085.40","0.194"],["64086.50","0.039"],["64086.90","0.391"],["64087.60","0.014"],["64088.40","0.000"],["64088.60","0.122"],["64089.10","0.032"],["64089.60","1.699"],["64091.10","0.001"],["64091.60","2.352"],["64093.40","0.121"],["64096.00","1.079"],["64096.60","0.050"],["64097.00","1.219"],["64097.30","0.022"],["64097.80","0.004"],["64098.10","0.008"],["64101.20","0.105"],["64103.50","2.344"],["64104.70","10.002"],["64110.90","0.395"],["64116.50","0.313"],["64119.70","0.000"],["64123.30","0.210"],["64124.90","0.000"],["64128.70","0.025"],["64130.50","0.076"],["64133.50","0.015"],["64200.00","3.526"],["64202.00","0.896"],["64204.00","0.882"],["64206.00","0.894"],["64208.00","0.882"],["64210.00","0.888"],["64212.00","1.370"],["64214.00","0.887"],["64216.00","0.882"],["64218.00","1.327"],["64265.00","0.495"],["64313.70","0.657"],["64546.90","0.000"],["64700.50","1.249"],["64700.60","0.207"],["64817.00","0.011"],["64988.80","3.578"],["65052.80","12.056"]],"b":[["13559.90","1.358"],["13645.70","0.042"],["13659.90","0.658"],["13759.90","0.826"],["13859.90","1.246"],["57653.90","0.002"],["60735.20","0.001"],["62653.20","0.000"],["62993.90","0.000"],["63024.90","2.514"],["63034.90","4.426"],["63067.00","13.031"],["63089.00","9.322"],["63089.90","0.004"],["63121.00","0.142"],["63126.20","2.358"],["63128.60","8.974"],["63131.00","21.755"],["63163.10","44.669"],["63222.10","0.710"],["63250.00","4.750"],["63256.70","1.566"],["63259.20","8.609"],["63291.20","31.280"],["63299.20","1.902"],["63397.20","0.000"],["63402.20","0.473"],["63415.40","0.000"],["63419.30","0.168"],["63438.50","0.858"],["63440.90","0.000"],["63441.00","0.070"],["63451.30","6.381"],["63457.70","0.723"],["63478.40","5.458"],["63483.40","3.119"],["63668.20","0.000"],["63688.80","0.460"],["63909.90","0.006"],["63911.90","0.001"],["63913.90","0.509"],["63915.90","0.009"],["63917.90","0.001"],["63919.90","0.076"],["63920.90","0.035"],["63921.90","0.000"],["63960.70","0.482"],["63961.60","15.362"],["63982.70","21.840"],["63983.60","2.714"],["63984.90","0.022"],["63987.20","1.629"],["63989.30","0.000"],["63990.20","0.998"],["64003.50","0.062"],["64018.20","0.002"],["64018.40","0.003"],["64022.90","1.728"],["64023.10","0.098"],["64033.00","0.313"],["64035.40","0.331"],["64037.00","0.001"],["64037.30","0.595"],["64039.20","0.062"],["64040.90","0.455"],["64041.10","0.230"],["64041.70","4.476"],["64041.80","0.369"],["64045.20","0.000"],["64045.40","0.161"],["64047.10","0.113"],["64047.80","0.018"],["64048.20","0.001"],["64049.30","0.718"],["64049.40","10.024"],["64049.50","0.303"],["64050.00","0.026"],["64051.10","2.343"],["64051.20","2.567"],["64051.50","0.252"],["64052.00","0.023"],["64052.60","1.330"],["64052.70","0.021"],["64053.20","0.314"],["64053.30","0.372"],["64054.20","0.317"],["64055.30","0.000"],["64055.40","0.004"],["64055.60","0.000"],["64056.00","0.004"],["64056.40","2.500"],["64056.60","0.002"],["64056.70","0.032"],["64057.30","0.002"],["64057.40","0.016"],["64057.60","1.818"],["64057.80","0.004"],["64057.90","0.063"],["64058.00","0.001"],["64058.60","0.179"],["64058.70","0.001"],["64058.90","0.021"],["64059.20","0.000"],["64059.30","0.010"],["64059.90","20.127"]],"e":"depthUpdate","ps":"BTCUSDT","pu":11165394048673,"s":"BTCUSDT","st":1,"u":11165394065365}
{"E":1785353518412,"T":1785353518411,"U":11165394065559,"a":[["64060.00","0.627"],["64060.10","0.000"],["64062.90","0.009"],["64063.10","0.009"],["64063.20","0.009"],["64064.00","0.008"],["64064.30","0.218"],["64065.60","0.003"],["64065.80","0.025"],["64065.90","0.548"],["64066.00","0.005"],["64066.20","0.000"],["64066.30","0.000"],["64066.40","0.017"],["64066.80","0.216"],["64067.20","0.073"],["64068.80","0.030"],["64068.90","0.180"],["64069.20","0.924"],["64069.30","0.016"],["64069.60","0.240"],["64070.10","0.002"],["64070.30","0.007"],["64070.50","0.014"],["64072.10","0.362"],["64072.20","2.004"],["64072.30","0.002"],["64072.50","0.000"],["64072.60","0.111"],["64072.80","1.504"],["64072.90","0.343"],["64073.50","0.918"],["64073.70","0.004"],["64073.90","0.237"],["64074.20","0.065"],["64074.70","0.316"],["64074.80","0.003"],["64075.00","0.004"],["64075.30","0.001"],["64075.50","0.142"],["64075.90","1.001"],["64076.20","0.049"],["64076.30","3.126"],["64076.60","0.260"],["64077.20","0.251"],["64077.30","0.002"],["64077.50","0.227"],["64078.90","0.135"],["64080.00","0.631"],["64081.20","0.320"],["64081.30","0.005"],["64082.60","0.099"],["64085.60","0.147"],["64085.70","0.703"],["64092.10","0.007"],["64098.30","0.003"],["64099.10","0.070"],["64099.50","0.001"],["64100.60","0.003"],["64103.50","1.314"],["64104.30","0.002"],["64104.40","2.340"],["64104.70","0.002"],["64105.70","0.003"],["64106.20","0.002"],["64110.80","2.000"],["64110.90","0.395"],["64111.10","1.208"],["64118.00","0.002"],["64119.80","0.029"],["64122.60","0.018"],["64126.40","0.001"],["64128.70","0.000"],["64140.80","1.345"],["64141.00","0.001"],["64143.20","0.031"],["64144.30","5.491"],["64145.30","23.215"],["64160.00","0.668"],["64163.80","0.000"],["64194.00","0.000"],["64195.30","1.089"],["64196.00","0.000"],["64198.00","0.000"],["64200.00","2.645"],["64201.90","0.335"],["64202.00","0.015"],["64202.90","0.000"],["64204.00","0.001"],["64206.00","0.013"],["64208.00","0.001"],["64210.00","0.007"],["64212.00","0.489"],["64214.00","0.006"],["64216.00","0.001"],["64218.00","0.492"],["64240.00","1.425"],["64265.00","0.495"],["64320.00","0.317"],["64400.00","11.967"],["64700.60","0.205"]],"b":[["1000.00","37.592"],["13559.90","1.330"],["13645.70","0.000"],["13659.90","0.770"],["13759.90","0.840"],["13859.90","1.120"],["13959.90","0.070"],["57653.90","0.002"],["61497.50","0.000"],["62013.80","0.000"],["62760.90","1.036"],["62778.80","0.581"],["62963.30","0.000"],["62985.30","0.002"],["63002.90","1.770"],["63014.50","0.792"],["63024.90","1.414"],["63067.00","14.130"],["63089.00","8.224"],["63103.40","0.042"],["63131.00","22.853"],["63226.20","3.445"],["63256.90","1.680"],["63261.30","4.704"],["63275.20","9.388"],["63281.00","0.782"],["63282.00","0.000"],["63323.20","3.752"],["63419.30","0.168"],["63680.00","3.769"],["63739.60","0.089"],["63760.00","0.308"],["63840.00","1.547"],["63913.90","0.509"],["63920.00","0.693"],["63961.60","11.894"],["63982.70","0.000"],["63983.60","2.714"],["63984.90","21.862"],["63987.10","0.094"],["63987.20","4.685"],["63991.70","0.497"],["63998.90","0.210"],["64000.00","10.831"],["64003.50","0.099"],["64026.60","0.170"],["64027.40","0.002"],["64028.40","1.807"],["64030.60","0.059"],["64033.80","0.363"],["64034.50","0.242"],["64034.90","0.020"],["64037.10","0.118"],["64037.50","0.011"],["64038.10","0.000"],["64040.90","0.453"],["64041.30","0.000"],["64041.70","4.476"],["64042.40","0.606"],["64042.50","2.341"],["64043.50","0.171"],["64044.30","1.882"],["64044.50","0.063"],["64045.10","0.016"],["64045.50","0.001"],["64045.80","0.262"],["64046.30","0.120"],["64046.40","0.109"],["64047.10","0.051"],["64048.40","0.021"],["64049.30","0.718"],["64049.40","0.022"],["64049.50","0.263"],["64050.00","0.006"],["64050.30","0.002"],["64051.10","2.345"],["64051.20","1.067"],["64051.30","0.047"],["64051.60","0.005"],["64052.00","0.001"],["64052.60","0.003"],["64052.70","0.064"],["64054.70","0.023"],["64054.80","2.002"],["64056.30","0.004"],["64056.60","0.002"],["64056.70","1.355"],["64056.80","0.040"],["64056.90","0.001"],["64057.40","0.001"],["64057.70","0.446"],["64057.80","0.004"],["64057.90","0.000"],["64058.00","0.001"],["64058.10","0.003"],["64058.30","0.000"],["64058.60","0.182"],["64058.70","0.001"],["64058.90","0.018"],["64059.20","0.000"],["64059.30","0.000"],["64059.40","0.000"],["64059.50","0.001"],["64059.60","0.010"],["64059.70","0.008"],["64059.80","0.006"],["64059.90","19.658"]],"e":"depthUpdate","ps":"BTCUSDT","pu":11165394065365,"s":"BTCUSDT","st":1,"u":11165394080589}
{"E":1785353518514,"T":1785353518513,"U":11165394080673,"a":[["64060.00","0.625"],["64061.60","0.000"],["64061.80","0.006"],["64062.90","0.007"],["64063.40","0.001"],["64064.20","0.003"],["64064.30","0.004"],["64065.70","0.208"],["64065.80","0.163"],["64066.40","0.017"],["64066.80","0.006"],["64066.90","0.005"],["64067.30","0.610"],["64068.80","0.187"],["64069.20","0.978"],["64069.60","0.318"],["64069.70","0.463"],["64070.00","0.008"],["64070.30","0.019"],["64070.50","0.017"],["64072.10","0.908"],["64074.60","10.150"],["64075.70","0.336"],["64076.30","2.584"],["64077.20","0.134"],["64077.50","0.230"],["64077.60","0.005"],["64077.70","0.603"],["64078.20","0.137"],["64078.50","1.787"],["64082.10","0.004"],["64086.50","0.044"],["64088.50","0.001"],["64089.20","0.006"],["64094.90","0.392"],["64097.30","0.020"],["64099.80","0.004"],["64102.30","0.006"],["64106.30","2.836"],["64106.50","10.340"],["64107.10","0.001"],["64110.80","0.000"],["64111.10","1.052"],["64111.40","0.097"],["64119.80","0.004"],["64119.90","0.608"],["64123.70","0.001"],["64123.90","0.054"],["64128.40","0.000"],["64129.60","0.026"],["64134.10","0.008"],["64137.10","0.151"],["64137.50","0.077"],["64140.80","1.345"],["64143.10","0.014"],["64144.30","2.336"],["64145.30","0.000"],["64152.00","0.002"],["64154.00","4.393"],["64154.10","23.226"],["64241.80","0.083"],["64265.00","0.495"],["64380.30","0.455"],["64700.60","0.207"],["64860.80","1.253"],["64924.80","1.306"],["65060.00","0.622"],["65341.10","0.015"]],"b":[["13559.90","1.204"],["13659.90","0.896"],["13759.90","0.826"],["13859.90","1.008"],["13959.90","0.196"],["57653.90","0.002"],["61497.50","0.003"],["63128.60","6.622"],["63163.10","47.020"],["63249.00","11.675"],["63256.70","0.001"],["63291.20","35.972"],["63297.60","2.157"],["63389.40","0.000"],["63419.30","0.168"],["63438.50","1.553"],["63741.20","0.314"],["63797.50","0.387"],["63954.10","21.840"],["63954.60","4.738"],["63960.70","0.482"],["63983.20","0.409"],["63984.90","0.022"],["63987.10","0.094"],["63987.20","1.629"],["63999.90","0.003"],["64003.50","0.062"],["64008.40","0.132"],["64022.00","0.003"],["64024.80","0.372"],["64029.10","1.355"],["64031.20","0.002"],["64033.90","0.000"],["64034.50","0.323"],["64036.70","0.565"],["64037.10","0.083"],["64037.20","0.003"],["64037.60","0.002"],["64040.60","0.980"],["64041.10","0.444"],["64041.70","4.478"],["64042.40","0.604"],["64044.50","0.001"],["64045.70","0.580"],["64045.80","0.242"],["64046.00","0.529"],["64046.40","0.089"],["64046.60","0.096"],["64046.70","0.035"],["64048.40","0.001"],["64049.30","0.015"],["64050.70","10.002"],["64051.10","2.343"],["64051.20","2.465"],["64051.30","0.790"],["64054.00","0.024"],["64054.40","0.004"],["64054.70","0.000"],["64054.80","0.002"],["64056.60","0.373"],["64056.80","0.020"],["64057.30","0.017"],["64057.50","0.003"],["64057.70","0.434"],["64057.80","0.016"],["64058.60","0.317"],["64058.90","0.280"],["64059.20","0.000"],["64059.30","0.003"],["64059.40","0.234"],["64059.60","0.002"],["64059.70","0.000"],["64059.80","0.004"],["64059.90","17.810"]],"e":"depthUpdate","ps":"BTCUSDT","pu":11165394080589,"s":"BTCUSDT","st":1,"u":11165394093325}
