{"E":1785353522084,"T":1785353522083,"U":11165394691555,"a":[["64046.70","21.836"],["64046.80","0.007"],["64046.90","0.002"],["64047.00","0.000"],["64047.10","0.000"],["64047.20","1.299"],["64047.30","0.000"],["64047.40","0.001"],["64047.60","0.313"],["64047.70","0.002"],["64047.80","0.313"],["64047.90","0.000"],["64048.10","0.000"],["64048.20","0.001"],["64048.30","0.001"],["64048.40","0.009"],["64048.50","0.911"],["64048.60","0.002"],["64048.70","0.000"],["64048.80","0.001"],["64048.90","0.000"],["64049.00","0.000"],["64049.10","0.016"],["64049.20","0.948"],["64049.30","0.000"],["64049.40","0.001"],["64049.50","0.000"],["64049.60","0.094"],["64049.70","0.003"],["64049.80","0.001"],["64049.90","0.000"],["64050.00","0.053"],["64050.10","0.007"],["64050.30","0.003"],["64050.40","0.000"],["64050.50","0.001"],["64050.60","0.001"],["64050.70","0.001"],["64050.80","0.835"],["64050.90","2.362"],["64051.00","0.548"],["64051.10","0.135"],["64051.20","2.501"],["64051.30","0.000"],["64051.40","0.001"],["64051.50","0.000"],["64051.60","2.503"],["64051.70","1.292"],["64051.80","0.005"],["64051.90","0.003"],["64052.00","0.001"],["64052.10","0.001"],["64052.30","0.001"],["64052.40","0.000"],["64052.50","0.000"],["64052.60","0.001"],["64052.70","0.117"],["64052.80","0.329"],["64052.90","0.314"],["64053.10","0.002"],["64053.20","0.001"],["64053.30","0.440"],["64053.40","0.000"],["64053.50","0.000"],["64053.60","2.398"],["64053.70","7.086"],["64053.80","0.003"],["64053.90","0.000"],["64054.00","0.001"],["64054.10","0.003"],["64054.20","0.010"],["64054.40","0.001"],["64054.50","0.000"],["64054.60","0.000"],["64054.70","0.052"],["64054.80","0.000"],["64054.90","0.001"],["64055.00","0.005"],["64055.10","0.001"],["64055.40","0.018"],["64055.60","0.001"],["64055.70","0.001"],["64055.80","0.609"],["64055.90","0.000"],["64056.00","1.003"],["64056.10","0.094"],["64056.20","0.001"],["64056.30","0.159"],["64056.40","2.001"],["64056.50","0.002"],["64056.60","0.562"],["64056.70","0.227"],["64056.80","0.253"],["64056.90","0.001"],["64057.00","0.000"],["64057.20","0.316"],["64057.30","0.001"],["64057.40","0.000"],["64057.50","2.438"],["64057.60","3.093"],["64057.70","1.110"],["64057.80","0.002"],["64057.90","0.016"],["64058.10","0.002"],["64058.20","0.002"],["64058.30","0.059"],["64058.40","0.947"],["64058.50","0.032"],["64058.60","0.007"],["64058.70","0.637"],["64058.80","0.050"],["64058.90","0.080"],["64059.00","0.001"],["64059.10","0.003"],["64059.20","1.250"],["64059.50","0.001"],["64059.60","0.002"],["64059.70","0.740"],["64059.80","0.015"],["64059.90","0.004"],["64060.00","0.358"],["64060.10","2.465"],["64060.20","4.834"],["64060.30","0.795"],["64060.80","0.029"],["64060.90","0.280"],["64061.00","0.502"],["64061.20","0.064"],["64061.30","0.659"],["64061.50","0.355"],["64061.60","0.000"],["64061.70","0.000"],["64061.80","0.012"],["64061.90","0.260"],["64062.10","0.107"],["64062.20","0.001"],["64062.30","2.116"],["64062.40","0.069"],["64062.50","0.001"],["64062.70","0.345"],["64062.80","0.094"],["64062.90","1.971"],["64063.00","2.377"],["64063.10","2.848"],["64063.20","0.399"],["64063.30","0.051"],["64063.40","0.473"],["64063.50","0.259"],["64063.70","0.002"],["64064.00","0.436"],["64064.20","0.001"],["64064.30","0.002"],["64064.50","0.003"],["64064.70","0.002"],["64064.80","0.001"],["64064.90","1.197"],["64065.00","0.003"],["64065.10","0.005"],["64065.30","0.314"],["64065.40","0.002"],["64065.60","0.241"],["64065.90","0.038"],["64066.00","0.344"],["64066.10","0.910"],["64066.20","0.811"],["64066.30","0.000"],["64066.40","0.003"],["64066.70","3.164"],["64066.80","0.005"],["64066.90","0.027"],["64067.00","0.000"],["64067.20","0.022"],["64067.40","0.151"],["64067.50","0.140"],["64067.70","0.116"],["64067.80","1.206"],["64067.90","0.066"],["64068.00","0.003"],["64068.10","0.400"],["64068.30","0.001"],["64068.40","0.126"],["64068.50","0.374"],["64068.60","0.000"],["64068.70","0.008"],["64068.80","0.060"],["64068.90","0.000"],["64069.10","0.002"],["64069.30","1.052"],["64069.40","0.314"],["64069.60","0.000"],["64069.80","0.003"],["64069.90","0.158"],["64070.00","0.234"],["64070.20","0.003"],["64070.40","0.948"],["64070.50","0.696"],["64070.60","0.001"],["64070.80","0.157"],["64070.90","0.005"],["64071.00","0.001"],["64071.10","3.705"],["64071.30","0.001"],["64071.50","0.001"],["64072.00","0.002"],["64072.10","0.088"],["64072.30","1.817"],["64072.40","0.000"],["64072.50","0.175"],["64072.60","0.098"],["64072.70","0.001"],["64072.90","0.107"],["64073.40","0.001"],["64073.50","0.158"],["64073.70","2.345"],["64073.90","0.119"],["64074.00","0.091"],["64074.20","0.687"],["64074.30","0.331"],["64074.40","1.698"],["64074.50","1.061"],["64074.60","10.445"],["64074.70","0.837"],["64074.80","0.601"],["64075.00","0.294"],["64075.10","0.172"],["64075.20","0.076"],["64075.30","0.001"],["64075.40","1.076"],["64075.60","0.232"],["64075.70","0.004"],["64075.80","0.004"],["64076.00","0.003"],["64076.10","0.060"],["64076.20","0.057"],["64076.40","0.688"],["64076.50","0.012"],["64076.70","0.020"],["64076.80","1.389"],["64076.90","0.080"],["64077.00","0.001"],["64077.20","0.000"],["64077.30","0.020"],["64077.40","0.002"],["64077.50","0.138"],["64077.60","0.004"],["64077.70","0.004"],["64077.90","0.001"],["64078.10","0.000"],["64078.20","0.000"],["64078.40","0.002"],["64078.50","0.527"],["64078.60","0.815"],["64078.70","0.001"],["64079.10","0.001"],["64079.20","0.014"],["64079.30","0.000"],["64079.50","0.316"],["64079.70","0.935"],["64079.90","0.472"],["64080.00","1.875"],["64080.10","2.447"],["64080.20","0.000"],["64080.30","2.004"],["64080.50","0.003"],["64080.60","0.005"],["64080.70","0.002"],["64080.80","0.000"],["64080.90","0.100"],["64081.10","0.000"],["64081.30","0.001"],["64081.60","0.524"],["64081.70","0.549"],["64081.80","0.032"],["64081.90","0.011"],["64082.10","0.030"],["64082.50","0.121"],["64082.60","0.049"],["64082.80","0.018"],["64083.30","0.001"],["64083.50","0.014"],["64083.60","0.000"],["64083.80","0.010"],["64083.90","0.000"],["64084.00","0.378"],["64084.10","0.001"],["64084.30","0.021"],["64084.40","0.000"],["64084.60","0.001"],["64084.80","0.003"],["64085.10","2.389"],["64085.20","0.404"],["64085.30","0.060"],["64085.40","0.148"],["64085.50","1.263"],["64085.60","0.002"],["64085.70","0.000"],["64085.90","0.002"],["64086.10","0.012"],["64086.20","0.001"],["64086.40","1.166"],["64086.50","0.002"],["64086.60","0.202"],["64086.70","0.500"],["64086.80","0.750"],["64086.90","0.400"],["64087.30","0.377"],["64087.50","1.064"],["64087.60","0.000"],["64088.10","0.074"],["64088.20","0.000"],["64088.30","0.044"],["64088.50","0.008"],["64088.60","0.048"],["64088.70","0.002"],["64088.90","0.110"],["64089.00","0.047"],["64089.10","0.004"],["64089.20","0.085"],["64089.30","0.610"],["64089.40","0.001"],["64089.70","0.315"],["64090.00","0.063"],["64090.40","0.001"],["64090.90","0.899"],["64091.30","0.001"],["64091.40","0.033"],["64091.90","0.618"],["64092.10","0.000"],["64092.20","0.005"],["64092.30","0.000"],["64092.60","0.011"],["64092.70","0.002"],["64093.00","0.000"],["64093.50","0.002"],["64093.90","0.159"],["64094.20","0.013"],["64094.70","0.018"],["64095.40","0.001"],["64095.50","0.060"],["64095.60","2.752"],["64095.70","0.057"],["64096.00","1.080"],["64096.40","0.081"],["64096.50","0.002"],["64096.90","0.001"],["64097.10","0.565"],["64097.40","0.002"],["64097.50","0.175"],["64098.10","0.003"],["64098.40","0.000"],["64098.80","0.048"],["64099.00","0.000"],["64099.10","0.000"],["64099.30","1.950"],["64099.60","1.046"],["64099.70","0.126"],["64099.80","0.001"],["64100.10","0.390"],["64100.20","0.503"],["64100.30","0.286"],["64100.50","0.016"],["64100.70","0.256"],["64100.90","0.001"],["64101.10","0.001"],["64101.70","0.025"],["64101.80","0.009"],["64102.00","0.636"],["64102.50","0.001"],["64103.00","0.004"],["64103.10","1.624"],["64103.20","0.002"],["64103.30","0.521"],["64103.60","0.027"],["64103.70","0.063"],["64103.90","0.006"],["64104.50","1.266"],["64105.20","0.023"],["64105.30","1.042"],["64106.20","0.101"],["64106.30","0.759"],["64106.40","1.325"],["64106.80","0.048"],["64107.40","0.000"],["64107.90","0.001"],["64108.30","0.000"],["64108.60","0.615"],["64108.80","0.037"],["64108.90","3.290"],["64109.00","0.001"],["64109.30","0.002"],["64110.00","0.033"],["64110.70","0.012"],["64111.60","0.001"],["64112.10","0.000"],["64112.30","0.500"],["64112.40","0.784"],["64112.50","0.003"],["64112.90","0.000"],["64113.00","0.000"],["64113.20","0.009"],["64113.50","0.026"],["64113.60","2.344"],["64114.60","0.000"],["64114.80","0.100"],["64114.90","0.111"],["64115.90","0.000"],["64116.10","0.003"],["64116.20","0.923"],["64116.40","0.000"],["64117.00","0.080"],["64117.20","0.211"],["64117.50","2.763"],["64117.80","0.002"],["64118.50","0.014"],["64120.80","0.000"],["64120.90","0.000"],["64121.00","0.104"],["64121.10","0.247"],["64122.00","0.507"],["64122.60","0.018"],["64123.40","0.171"],["64123.50","1.484"],["64123.60","0.063"],["64124.20","0.087"],["64124.70","0.024"],["64125.30","0.030"],["64125.50","0.000"],["64125.90","0.658"],["64126.50","0.012"],["64127.20","0.000"],["64127.90","0.000"],["64128.00","0.025"],["64128.10","0.482"],["64130.00","0.102"],["64130.40","0.094"],["64130.50","0.076"],["64132.00","4.416"],["64132.80","0.009"],["64133.60","0.011"],["64134.00","0.618"],["64135.30","0.510"],["64136.80","0.017"],["64137.10","0.002"],["64137.50","0.000"],["64137.90","0.535"],["64139.30","0.002"],["64140.00","0.070"],["64140.30","3.726"],["64142.50","0.014"],["64143.20","0.019"],["64143.90","1.486"],["64144.00","0.002"],["64144.50","0.120"],["64145.80","0.029"],["64148.00","0.007"],["64148.30","0.511"],["64152.10","0.000"],["64153.30","0.017"],["64153.70","0.000"],["64154.90","0.001"],["64155.10","0.001"],["64156.20","2.341"],["64158.60","0.000"],["64160.10","0.009"],["64160.20","1.356"],["64161.00","0.034"],["64161.60","0.000"],["64163.50","1.335"],["64167.40","0.004"],["64169.90","0.503"],["64174.80","0.001"],["64176.10","2.341"],["64180.40","2.340"],["64181.80","0.018"],["64183.20","0.004"],["64183.80","2.367"],["64186.70","0.002"],["64192.90","0.000"],["64195.20","0.011"],["64195.40","0.039"],["64195.70","2.123"],["64199.90","0.096"],["64227.80","0.099"],["64232.30","0.000"],["64237.60","0.000"],["64238.80","0.001"],["64238.90","0.002"],["64241.30","0.008"],["64245.90","0.000"],["64265.60","0.014"],["64302.90","0.001"],["64304.50","0.205"],["64304.70","0.007"],["64304.80","0.003"],["64309.90","0.019"],["64324.10","1.299"],["64366.90","0.026"],["64374.00","0.001"],["64431.00","0.002"],["64438.00","0.000"],["64464.00","0.001"],["64466.90","0.024"],["64469.40","0.110"],["64471.20","0.318"],["64482.20","0.206"],["64486.00","0.000"],["64489.00","0.019"],["64495.00","0.042"],["64502.10","0.004"],["64509.60","0.000"],["64559.10","0.002"],["64566.10","0.000"],["64589.70","0.098"],["64687.20","0.000"],["64689.00","0.199"],["64692.20","0.000"],["64797.50","2.751"],["64800.50","2.312"],["65046.70","0.002"],["65051.70","0.012"],["65053.70","0.008"],["65056.80","0.006"],["65060.20","0.000"],["65063.10","1.087"],["65191.10","0.000"],["65341.10","0.012"],["70558.10","0.000"]],"b":[["1000.00","37.592"],["13566.70","0.196"],["13646.60","0.042"],["13648.40","0.056"],["13651.60","0.028"],["13766.70","0.210"],["13846.60","0.042"],["13848.40","0.056"],["13851.20","0.014"],["13851.60","0.014"],["13946.60","0.042"],["13948.40","0.070"],["13951.60","0.028"],["13966.70","0.196"],["44841.90","0.002"],["57641.90","0.002"],["57643.50","0.050"],["57643.60","0.002"],["57646.40","0.000"],["61484.70","0.013"],["63121.10","0.814"],["63142.40","0.322"],["63234.20","0.790"],["63336.30","0.000"],["63406.10","0.002"],["63407.90","0.000"],["63410.70","0.069"],["63411.10","3.747"],["63537.10","0.003"],["63543.60","0.000"],["63718.00","0.107"],["63728.20","0.002"],["63735.70","0.000"],["63761.10","0.001"],["63774.20","4.435"],["63779.40","0.540"],["63781.00","0.543"],["63794.20","0.398"],["63797.50","0.770"],["63799.40","0.003"],["63812.20","0.001"],["63812.50","0.004"],["63825.30","0.095"],["63847.30","0.004"],["63849.80","0.128"],["63856.30","0.001"],["63860.10","0.001"],["63863.70","16.292"],["63863.80","0.074"],["63863.90","0.070"],["63866.00","0.474"],["63866.40","0.002"],["63868.00","0.687"],["63877.80","0.001"],["63878.30","0.822"],["63878.80","0.000"],["63881.00","0.580"],["63881.50","0.221"],["63886.40","0.007"],["63891.40","5.487"],["63895.80","0.004"],["63899.60","0.000"],["63901.50","3.523"],["63901.70","0.000"],["63903.60","0.001"],["63905.60","0.000"],["63907.60","0.000"],["63908.00","1.022"],["63910.00","2.050"],["63911.10","0.528"],["63911.50","0.003"],["63914.40","0.500"],["63917.10","0.000"],["63921.40","0.005"],["63923.90","2.342"],["63926.00","0.032"],["63927.90","0.000"],["63928.70","0.023"],["63932.20","0.000"],["63933.10","2.749"],["63934.70","0.001"],["63935.80","1.007"],["63936.00","1.206"],["63936.60","0.001"],["63939.20","0.781"],["63939.90","0.003"],["63940.10","0.602"],["63940.40","1.518"],["63940.50","0.010"],["63940.60","0.003"],["63940.90","0.496"],["63941.00","4.531"],["63941.60","0.000"],["63942.30","0.005"],["63945.20","0.518"],["63945.90","0.296"],["63946.40","3.123"],["63946.70","0.278"],["63947.40","0.189"],["63947.90","0.000"],["63948.10","0.003"],["63948.90","0.019"],["63949.40","0.042"],["63949.80","0.001"],["63950.70","0.000"],["63952.60","0.027"],["63953.10","0.003"],["63953.20","0.027"],["63953.30","0.001"],["63953.70","0.003"],["63954.10","0.003"],["63954.20","0.278"],["63954.60","5.158"],["63957.40","0.042"],["63958.80","1.474"],["63960.20","0.000"],["63960.70","1.967"],["63960.80","0.001"],["63960.90","0.500"],["63961.20","0.000"],["63961.70","0.000"],["63961.90","0.000"],["63962.70","0.076"],["63963.10","0.003"],["63963.40","0.076"],["63968.00","0.506"],["63969.10","0.148"],["63969.50","0.060"],["63969.80","0.611"],["63969.90","0.293"],["63970.30","0.124"],["63970.40","0.061"],["63970.70","4.082"],["63972.10","0.003"],["63976.00","0.015"],["63976.10","0.000"],["63976.40","0.000"],["63976.80","0.200"],["63977.20","0.380"],["63977.30","1.059"],["63978.20","0.010"],["63979.10","0.003"],["63979.90","0.000"],["63980.30","0.009"],["63981.70","0.094"],["63982.20","1.828"],["63983.50","7.744"],["63983.70","0.001"],["63984.00","0.019"],["63984.40","0.026"],["63984.60","0.030"],["63984.90","0.022"],["63985.10","0.005"],["63985.20","3.237"],["63985.40","0.035"],["63985.70","10.152"],["63985.80","0.000"],["63987.20","3.645"],["63987.90","4.199"],["63988.60","0.521"],["63989.50","0.000"],["63990.30","0.001"],["63990.40","0.007"],["63991.70","0.498"],["63991.90","0.001"],["63992.00","2.068"],["63992.50","0.094"],["63992.90","0.001"],["63993.10","1.832"],["63993.20","0.004"],["63993.30","0.316"],["63993.60","0.038"],["63994.00","0.004"],["63994.40","0.020"],["63994.50","0.058"],["63994.60","1.259"],["63995.00","0.008"],["63995.20","0.001"],["63995.30","0.922"],["63995.40","0.003"],["63995.60","0.001"],["63995.70","0.000"],["63995.90","0.036"],["63996.10","4.139"],["63996.20","1.183"],["63996.50","0.032"],["63996.90","0.000"],["63997.00","0.000"],["63997.10","0.001"],["63997.20","0.001"],["63997.40","0.377"],["63997.70","0.123"],["63998.10","0.001"],["63998.30","0.977"],["63998.40","0.003"],["63999.10","0.005"],["63999.40","0.088"],["63999.50","0.000"],["63999.80","0.314"],["64000.40","0.035"],["64000.50","0.000"],["64000.80","1.501"],["64000.90","0.001"],["64001.00","0.510"],["64001.10","1.260"],["64001.20","0.002"],["64001.30","0.320"],["64001.40","0.001"],["64001.50","0.008"],["64001.60","0.018"],["64001.80","0.006"],["64001.90","10.005"],["64002.00","0.002"],["64002.10","0.067"],["64002.30","0.000"],["64002.40","0.003"],["64002.50","0.439"],["64002.60","0.717"],["64002.70","2.340"],["64002.80","0.001"],["64002.90","0.001"],["64003.00","0.021"],["64003.20","3.869"],["64003.30","0.001"],["64003.50","0.002"],["64003.60","0.030"],["64003.90","0.532"],["64004.00","1.494"],["64004.50","0.002"],["64004.60","0.001"],["64004.70","0.263"],["64004.80","0.313"],["64004.90","0.033"],["64005.00","0.101"],["64005.10","0.013"],["64005.20","0.000"],["64005.40","2.444"],["64005.50","0.000"],["64005.70","0.003"],["64005.80","0.007"],["64006.00","0.379"],["64006.20","0.003"],["64006.40","1.202"],["64006.50","0.037"],["64006.60","0.048"],["64006.70","0.029"],["64006.80","0.011"],["64006.90","0.105"],["64007.00","0.067"],["64007.10","0.064"],["64007.50","0.002"],["64007.60","0.074"],["64007.70","0.032"],["64007.80","0.024"],["64007.90","2.274"],["64008.00","2.347"],["64008.10","0.002"],["64008.60","0.031"],["64008.70","0.004"],["64008.80","0.002"],["64009.20","0.010"],["64009.30","0.001"],["64009.40","0.529"],["64009.50","0.586"],["64009.60","1.195"],["64009.80","0.004"],["64010.00","0.033"],["64010.20","0.061"],["64010.30","0.609"],["64010.40","0.065"],["64010.50","0.135"],["64010.60","0.140"],["64010.70","0.376"],["64011.00","0.345"],["64011.10","0.081"],["64011.20","0.001"],["64011.30","0.000"],["64011.40","0.028"],["64011.50","0.002"],["64011.80","0.039"],["64011.90","0.040"],["64012.10","0.002"],["64012.50","0.002"],["64012.60","1.243"],["64012.90","0.501"],["64013.00","0.000"],["64013.10","0.007"],["64013.30","0.002"],["64013.40","2.854"],["64013.50","0.134"],["64013.70","0.000"],["64014.10","0.531"],["64014.30","0.000"],["64014.50","0.286"],["64014.60","1.251"],["64014.70","0.000"],["64014.90","1.724"],["64015.00","0.533"],["64015.10","0.626"],["64015.20","0.000"],["64015.40","0.001"],["64015.50","0.000"],["64015.80","1.229"],["64015.90","0.369"],["64016.00","0.007"],["64016.30","0.004"],["64016.40","0.625"],["64016.50","2.992"],["64016.60","0.158"],["64016.70","0.223"],["64016.80","0.001"],["64016.90","0.935"],["64017.00","0.000"],["64017.10","0.000"],["64017.30","0.028"],["64017.50","0.636"],["64017.60","0.084"],["64017.70","0.040"],["64017.80","0.494"],["64018.10","0.308"],["64018.20","0.008"],["64018.30","0.001"],["64018.40","0.001"],["64018.50","0.138"],["64018.60","0.312"],["64018.70","0.001"],["64018.80","0.006"],["64018.90","0.000"],["64019.00","0.001"],["64019.10","0.325"],["64019.20","1.045"],["64019.30","0.593"],["64019.40","0.008"],["64019.50","0.100"],["64019.70","0.012"],["64019.90","2.667"],["64020.00","0.034"],["64020.10","0.330"],["64020.20","0.118"],["64020.40","0.001"],["64020.50","0.000"],["64020.60","0.000"],["64020.70","0.000"],["64020.90","0.645"],["64021.00","0.043"],["64021.20","0.035"],["64021.60","0.000"],["64021.70","0.025"],["64021.80","0.116"],["64022.00","0.004"],["64022.10","1.000"],["64022.50","0.547"],["64022.60","1.251"],["64022.70","1.746"],["64022.80","0.026"],["64022.90","0.001"],["64023.00","0.001"],["64023.10","2.345"],["64023.20","0.000"],["64023.30","0.304"],["64023.40","0.539"],["64023.50","0.000"],["64023.60","0.000"],["64023.70","0.549"],["64023.90","0.283"],["64024.00","0.009"],["64024.10","0.109"],["64024.30","0.000"],["64024.50","0.027"],["64024.60","0.094"],["64024.70","0.000"],["64024.80","0.708"],["64024.90","0.016"],["64025.00","0.737"],["64025.20","1.487"],["64025.30","0.160"],["64025.40","0.001"],["64025.60","1.638"],["64025.70","0.074"],["64025.80","0.616"],["64026.00","0.006"],["64026.20","0.000"],["64026.30","0.363"],["64026.40","0.042"],["64026.70","0.004"],["64026.80","0.001"],["64026.90","0.001"],["64027.00","0.192"],["64027.10","0.072"],["64027.20","0.005"],["64027.30","0.000"],["64027.40","0.008"],["64027.50","0.005"],["64027.60","0.120"],["64027.80","0.001"],["64027.90","0.000"],["64028.00","0.042"],["64028.20","0.098"],["64028.30","0.000"],["64028.40","0.034"],["64028.50","0.315"],["64028.60","0.638"],["64028.80","0.007"],["64029.00","1.078"],["64029.20","4.199"],["64029.30","0.411"],["64029.40","0.160"],["64029.50","0.002"],["64029.60","0.295"],["64029.80","0.440"],["64030.20","0.005"],["64030.30","0.000"],["64030.60","0.060"],["64030.70","0.005"],["64030.80","0.001"],["64031.00","0.001"],["64031.30","0.003"],["64031.50","0.000"],["64031.60","0.001"],["64031.70","0.095"],["64031.80","0.029"],["64031.90","0.003"],["64032.00","1.089"],["64032.30","0.252"],["64032.40","0.050"],["64032.50","0.000"],["64032.60","0.005"],["64032.80","0.002"],["64032.90","0.049"],["64033.00","0.735"],["64033.10","0.012"],["64033.30","0.379"],["64033.50","0.679"],["64033.60","0.317"],["64033.70","0.343"],["64033.90","0.001"],["64034.00","0.002"],["64034.20","0.005"],["64034.30","0.001"],["64034.50","0.096"],["64034.60","0.215"],["64034.90","0.001"],["64035.00","0.096"],["64035.10","0.372"],["64035.20","0.875"],["64035.30","2.349"],["64035.40","0.012"],["64035.50","0.003"],["64035.60","0.003"],["64035.70","0.000"],["64035.80","0.002"],["64035.90","0.007"],["64036.00","0.064"],["64036.10","1.500"],["64036.20","0.228"],["64036.40","0.006"],["64036.50","0.001"],["64036.60","0.004"],["64036.90","0.003"],["64037.10","0.000"],["64037.30","0.001"],["64037.40","0.000"],["64037.50","0.004"],["64037.60","0.061"],["64037.70","0.000"],["64037.80","0.002"],["64037.90","0.002"],["64038.00","4.420"],["64038.20","0.006"],["64038.30","0.000"],["64038.40","0.008"],["64038.50","0.014"],["64038.60","0.007"],["64038.70","0.237"],["64038.80","0.002"],["64038.90","0.000"],["64039.00","0.023"],["64039.10","0.026"],["64039.20","0.000"],["64039.80","0.006"],["64039.90","0.001"],["64040.00","0.042"],["64040.10","0.015"],["64040.20","0.082"],["64040.30","0.003"],["64040.40","0.002"],["64040.50","0.023"],["64040.70","0.015"],["64040.90","0.003"],["64041.00","0.006"],["64041.10","0.073"],["64041.20","0.001"],["64041.30","0.001"],["64041.40","0.089"],["64041.60","0.006"],["64041.70","4.085"],["64041.80","0.047"],["64041.90","0.001"],["64042.00","0.004"],["64042.10","0.005"],["64042.20","0.078"],["64042.30","0.001"],["64042.40","0.001"],["64042.60","0.001"],["64042.70","0.003"],["64042.80","0.000"],["64043.00","0.001"],["64043.10","0.001"],["64043.20","0.003"],["64043.30","0.001"],["64043.40","0.001"],["64043.50","0.004"],["64043.90","0.000"],["64044.00","0.005"],["64044.10","0.000"],["64044.20","0.003"],["64044.30","0.657"],["64044.40","0.000"],["64044.50","0.001"],["64044.60","0.002"],["64044.70","0.000"],["64044.80","0.006"],["64044.90","0.000"],["64045.10","0.000"],["64045.20","0.000"],["64045.30","0.000"],["64045.40","0.002"],["64045.50","0.001"],["64045.60","0.000"],["64045.70","0.004"],["64045.80","0.002"],["64045.90","0.002"],["64046.00","0.001"],["64046.10","0.000"],["64046.20","0.000"],["64046.40","0.031"],["64046.50","0.004"],["64046.60","0.559"],["64046.70","0.000"],["64046.80","0.000"],["64046.90","0.000"],["64047.00","0.000"],["64047.10","0.000"],["64047.20","0.000"],["64047.30","0.000"],["64047.50","0.000"],["64047.60","0.000"],["64047.70","0.000"],["64047.80","0.000"],["64047.90","0.000"],["64048.00","0.000"],["64048.10","0.000"],["64048.20","0.000"],["64048.30","0.000"],["64048.40","0.000"],["64048.60","0.000"],["64048.70","0.000"],["64048.80","0.000"],["64048.90","0.000"],["64049.00","0.000"],["64049.20","0.000"],["64049.30","0.000"],["64049.40","0.000"],["64049.50","0.000"],["64049.60","0.000"],["64049.80","0.000"],["64049.90","0.000"],["64050.00","0.000"],["64050.40","0.000"],["64050.50","0.000"],["64050.80","0.000"],["64051.10","0.000"],["64051.20","0.000"],["64051.30","0.000"],["64051.40","0.000"],["64051.50","0.000"],["64051.60","0.000"]],"e":"depthUpdate","ps":"BTCUSDT","pu":11165394691547,"s":"BTCUSDT","st":1,"u":11165394739753}
{"E":1785353522186,"T":1785353522184,"U":11165394739900,"a":[["64046.70","23.740"],["64046.80","0.008"],["64048.00","0.023"],["64048.40","0.006"],["64049.20","0.013"],["64049.40","0.002"],["64049.70","0.008"],["64050.70","0.074"],["64050.80","0.930"],["64051.00","0.001"],["64051.10","0.000"],["64051.20","2.503"],["64051.60","3.050"],["64052.20","0.935"],["64053.00","0.002"],["64053.50","0.000"],["64053.60","2.399"],["64053.70","7.081"],["64054.20","0.013"],["64054.40","0.064"],["64054.90","0.013"],["64055.00","0.011"],["64056.00","1.019"],["64056.40","0.001"],["64056.70","0.226"],["64057.40","0.121"],["64057.50","2.563"],["64057.60","3.162"],["64058.30","0.058"],["64058.50","0.032"],["64059.10","0.004"],["64059.50","0.002"],["64059.60","0.002"],["64059.90","0.026"],["64060.00","0.318"],["64060.10","2.340"],["64060.80","0.030"],["64062.00","0.003"],["64062.30","1.598"],["64062.40","0.002"],["64062.80","0.158"],["64063.00","2.864"],["64063.10","0.251"],["64063.20","2.399"],["64063.30","0.050"],["64063.60","0.093"],["64063.90","0.424"],["64064.00","0.448"],["64064.60","0.083"],["64065.50","0.172"],["64065.60","0.281"],["64065.70","0.815"],["64065.80","1.556"],["64065.90","0.206"],["64066.20","0.899"],["64066.50","0.002"],["64066.60","0.181"],["64066.70","3.320"],["64066.80","0.161"],["64067.10","0.002"],["64067.30","0.000"],["64068.30","0.179"],["64068.40","0.124"],["64068.70","0.008"],["64069.00","0.608"],["64069.50","0.004"],["64069.60","0.000"],["64070.50","0.694"],["64070.80","0.000"],["64071.10","3.707"],["64072.60","0.629"],["64074.10","2.333"],["64074.30","0.175"],["64074.60","10.453"],["64074.80","0.445"],["64074.90","0.170"],["64075.30","0.121"],["64075.70","0.018"],["64076.20","0.049"],["64076.80","1.429"],["64077.90","0.008"],["64078.70","0.008"],["64079.40","0.001"],["64079.60","0.540"],["64079.90","0.499"],["64080.00","1.843"],["64081.50","0.020"],["64081.80","0.032"],["64082.00","0.003"],["64082.10","0.005"],["64082.20","0.065"],["64082.30","0.006"],["64082.50","0.001"],["64082.60","0.053"],["64082.80","0.014"],["64083.30","0.005"],["64084.30","0.034"],["64084.80","0.039"],["64085.40","0.144"],["64086.40","1.170"],["64086.50","0.015"],["64087.70","0.053"],["64087.80","0.535"],["64088.30","0.000"],["64088.50","0.001"],["64088.90","0.096"],["64090.70","0.033"],["64091.00","0.205"],["64091.50","0.685"],["64092.60","0.010"],["64092.70","0.001"],["64092.90","0.026"],["64093.30","0.000"],["64093.70","0.004"],["64094.30","0.014"],["64094.80","0.033"],["64094.90","0.454"],["64095.30","0.001"],["64095.50","0.059"],["64095.70","0.025"],["64096.00","1.068"],["64096.10","0.064"],["64096.70","0.040"],["64097.10","0.529"],["64097.20","5.896"],["64098.30","0.026"],["64101.30","0.000"],["64101.90","0.060"],["64102.00","0.633"],["64102.20","0.005"],["64102.30","0.006"],["64102.40","0.020"],["64104.30","0.031"],["64104.70","0.123"],["64106.30","0.755"],["64106.50","0.315"],["64107.90","0.026"],["64108.50","0.000"],["64110.10","12.910"],["64110.60","1.998"],["64110.70","0.043"],["64111.10","0.106"],["64114.30","0.082"],["64117.00","0.065"],["64117.20","0.001"],["64118.60","0.051"],["64118.70","0.000"],["64118.80","0.984"],["64119.10","0.697"],["64119.30","0.170"],["64120.60","2.074"],["64120.70","1.655"],["64121.00","0.141"],["64121.80","6.398"],["64126.40","0.001"],["64127.10","0.031"],["64132.30","2.341"],["64132.80","0.007"],["64142.70","0.000"],["64145.30","0.008"],["64150.20","0.589"],["64160.10","0.001"],["64163.20","0.177"],["64165.60","0.000"],["64168.00","3.936"],["64177.20","0.661"],["64178.10","0.000"],["64185.00","0.243"],["64195.20","0.050"],["64195.40","0.000"],["64226.00","0.135"],["64229.00","0.012"],["64231.80","0.001"],["64234.40","2.768"],["64234.50","0.000"],["64264.50","0.104"],["64266.30","0.000"],["64302.90","0.095"],["64383.60","0.090"],["64687.20","0.000"],["64719.30","0.149"],["64780.90","0.185"],["64789.70","2.934"],["64790.50","0.148"],["64792.10","0.001"],["64797.50","4.585"],["64804.20","4.066"],["64858.20","1.535"],["64861.70","1.688"],["64868.30","0.000"],["64932.90","0.607"],["64934.30","0.769"],["64983.90","0.000"],["65004.10","0.150"],["65030.00","0.654"],["65048.00","0.005"],["65075.30","0.148"],["65146.50","0.148"],["65217.70","0.148"],["65288.90","0.148"],["65360.10","0.148"],["70451.40","0.002"]],"b":[["13566.70","0.084"],["13646.60","0.168"],["13766.70","0.084"],["13846.60","0.168"],["13946.60","0.154"],["13966.70","0.070"],["57641.90","0.002"],["62778.80","0.566"],["62796.90","0.705"],["62868.10","0.148"],["62939.30","0.148"],["63010.50","0.148"],["63081.70","0.702"],["63152.90","0.148"],["63224.10","0.150"],["63293.80","0.002"],["63295.00","0.177"],["63295.30","1.091"],["63366.50","0.148"],["63406.10","0.001"],["63437.70","0.149"],["63530.80","0.000"],["63532.00","0.031"],["63697.90","0.124"],["63726.40","0.179"],["63777.50","0.542"],["63778.90","0.159"],["63829.30","0.000"],["63832.50","0.000"],["63861.60","0.314"],["63870.00","0.012"],["63873.20","0.148"],["63876.40","0.000"],["63886.50","0.106"],["63902.20","0.001"],["63904.90","0.522"],["63905.80","0.024"],["63920.90","0.011"],["63928.60","0.368"],["63929.10","1.063"],["63939.60","0.033"],["63940.20","0.071"],["63940.60","0.035"],["63946.20","2.359"],["63946.70","0.000"],["63952.60","0.019"],["63954.20","0.000"],["63954.60","1.694"],["63956.30","22.165"],["63957.20","2.140"],["63958.10","4.068"],["63961.00","0.149"],["63961.90","0.000"],["63963.10","0.170"],["63964.50","0.006"],["63966.00","2.368"],["63966.60","0.598"],["63968.10","0.058"],["63969.90","0.083"],["63970.00","0.485"],["63970.30","0.120"],["63970.40","0.121"],["63970.50","0.190"],["63970.70","4.082"],["63972.00","0.004"],["63973.70","0.000"],["63974.00","0.001"],["63974.50","0.028"],["63975.30","0.000"],["63976.00","0.016"],["63976.20","0.517"],["63977.10","0.220"],["63978.00","2.343"],["63979.00","0.008"],["63980.90","0.028"],["63983.00","0.002"],["63983.50","7.743"],["63984.00","0.020"],["63984.60","0.005"],["63985.40","0.028"],["63985.90","0.011"],["63986.10","0.004"],["63988.00","0.115"],["63988.50","0.224"],["63990.30","0.279"],["63990.40","0.003"],["63991.50","0.000"],["63992.80","0.005"],["63993.00","0.014"],["63993.10","1.906"],["63993.50","1.123"],["63994.60","1.255"],["63995.20","0.061"],["63996.60","0.011"],["63996.70","0.089"],["63997.50","0.034"],["63997.70","0.003"],["63999.00","0.907"],["63999.40","0.000"],["64001.90","0.005"],["64002.70","2.407"],["64002.80","0.001"],["64003.30","0.279"],["64003.40","0.015"],["64003.50","0.000"],["64003.70","0.531"],["64005.00","0.221"],["64005.30","0.353"],["64005.50","0.007"],["64005.80","2.003"],["64006.30","0.001"],["64006.50","0.036"],["64006.60","0.047"],["64006.70","0.028"],["64007.00","0.017"],["64007.80","0.001"],["64008.10","0.001"],["64008.20","0.027"],["64008.40","0.077"],["64008.50","0.007"],["64008.70","0.000"],["64008.80","0.023"],["64009.20","0.037"],["64009.50","0.546"],["64010.50","0.120"],["64010.70","0.316"],["64011.00","0.295"],["64011.10","0.060"],["64011.20","0.001"],["64011.40","0.050"],["64011.60","0.004"],["64011.70","0.001"],["64011.80","0.040"],["64013.00","0.292"],["64013.10","0.014"],["64013.50","0.135"],["64014.00","0.002"],["64014.20","0.050"],["64014.40","0.047"],["64014.60","1.266"],["64015.00","0.694"],["64015.50","0.020"],["64016.40","0.626"],["64016.60","0.159"],["64016.70","0.063"],["64016.80","0.081"],["64016.90","0.000"],["64017.00","0.001"],["64017.50","0.633"],["64017.60","0.004"],["64017.80","0.503"],["64018.10","0.065"],["64018.90","0.935"],["64019.30","0.621"],["64019.40","0.011"],["64019.50","0.121"],["64020.00","0.058"],["64020.40","0.004"],["64020.60","0.001"],["64021.00","0.071"],["64021.10","0.040"],["64021.80","0.095"],["64023.30","0.244"],["64024.00","0.016"],["64024.10","0.229"],["64024.30","0.001"],["64024.60","0.000"],["64025.20","1.367"],["64025.90","2.347"],["64026.00","0.163"],["64026.10","0.023"],["64026.40","0.002"],["64028.20","0.471"],["64028.40","0.014"],["64028.60","0.639"],["64028.70","0.756"],["64028.80","0.008"],["64028.90","0.005"],["64029.30","0.411"],["64029.40","0.317"],["64030.10","0.025"],["64030.20","0.008"],["64030.50","0.105"],["64031.50","0.000"],["64032.30","0.314"],["64032.40","0.029"],["64033.30","0.006"],["64033.70","0.000"],["64033.90","0.002"],["64034.60","0.215"],["64035.30","2.349"],["64035.40","0.002"],["64035.80","0.330"],["64036.00","0.002"],["64036.10","1.330"],["64036.60","0.194"],["64036.70","0.021"],["64037.00","0.314"],["64037.20","0.003"],["64037.40","0.094"],["64037.50","0.064"],["64037.60","0.121"],["64037.70","0.120"],["64037.80","0.060"],["64037.90","0.062"],["64038.00","2.427"],["64038.10","1.537"],["64038.20","0.879"],["64038.60","0.007"],["64038.70","0.047"],["64038.80","0.096"],["64038.90","0.032"],["64039.00","0.002"],["64039.50","0.033"],["64039.80","0.034"],["64040.30","0.026"],["64040.40","0.005"],["64040.50","0.000"],["64041.10","0.052"],["64041.80","0.718"],["64041.90","0.581"],["64042.00","0.002"],["64042.10","0.002"],["64042.30","0.004"],["64042.70","0.004"],["64042.80","0.000"],["64043.20","0.002"],["64043.40","0.005"],["64043.60","0.007"],["64044.00","0.010"],["64044.30","0.005"],["64044.40","0.432"],["64045.40","0.000"],["64045.80","0.001"],["64046.10","0.002"],["64046.40","0.003"],["64046.50","0.005"],["64046.60","2.151"]],"e":"depthUpdate","ps":"BTCUSDT","pu":11165394739753,"s":"BTCUSDT","st":1,"u":11165394764121}
{"E":1785353522288,"T":1785353522286,"U":11165394764266,"a":[["64046.70","19.690"],["64047.20","0.000"],["64047.60","0.000"],["64047.80","0.000"],["64047.90","0.000"],["64048.00","0.000"],["64048.10","0.023"],["64048.30","0.001"],["64048.40","0.006"],["64048.50","0.469"],["64048.60","0.003"],["64049.10","0.001"],["64049.70","0.023"],["64050.10","0.007"],["64050.70","0.494"],["64050.80","0.724"],["64050.90","0.000"],["64051.10","0.060"],["64051.20","2.505"],["64051.50","1.801"],["64051.60","2.503"],["64051.70","1.052"],["64051.80","0.006"],["64052.10","0.001"],["64052.20","0.000"],["64052.40","0.001"],["64052.70","0.000"],["64053.20","0.002"],["64053.40","0.020"],["64053.50","0.000"],["64054.00","0.032"],["64054.10","0.001"],["64054.20","0.014"],["64054.80","0.936"],["64055.70","0.548"],["64055.90","0.741"],["64056.00","1.120"],["64056.30","0.175"],["64056.60","0.000"],["64057.40","0.001"],["64057.50","2.436"],["64057.60","1.645"],["64058.30","0.000"],["64058.50","0.001"],["64059.10","0.006"],["64059.60","0.003"],["64059.80","0.577"],["64059.90","0.006"],["64060.00","0.338"],["64060.10","2.465"],["64060.20","4.821"],["64060.80","0.031"],["64061.20","0.220"],["64061.50","0.435"],["64061.60","0.003"],["64062.10","0.110"],["64062.30","1.563"],["64062.40","0.022"],["64062.80","0.158"],["64063.20","0.399"],["64064.10","0.002"],["64064.20","0.091"],["64064.90","1.296"],["64065.30","0.482"],["64065.60","0.281"],["64066.00","0.345"],["64066.40","0.000"],["64066.80","2.161"],["64069.20","0.558"],["64070.20","0.049"],["64070.40","1.583"],["64071.00","2.413"],["64071.10","3.707"],["64071.80","10.002"],["64072.60","0.536"],["64073.50","0.230"],["64073.60","0.706"],["64073.70","2.343"],["64074.00","0.034"],["64074.50","0.893"],["64074.60","10.445"],["64074.70","0.681"],["64074.80","0.307"],["64075.30","0.001"],["64076.00","0.011"],["64076.40","0.745"],["64078.80","2.539"],["64080.30","0.052"],["64080.40","0.062"],["64081.50","0.004"],["64082.50","0.121"],["64084.20","0.750"],["64084.40","0.012"],["64084.50","0.079"],["64087.40","0.000"],["64087.70","0.004"],["64090.30","0.024"],["64096.80","0.003"],["64106.80","0.002"],["64108.50","0.001"],["64122.60","0.016"],["64123.90","0.002"],["64129.00","0.000"],["64161.40","3.595"],["64188.70","0.000"],["64190.70","0.002"],["64192.70","0.001"],["64193.70","0.079"],["64194.70","0.001"],["64195.20","0.011"],["64196.70","0.211"],["64198.70","0.003"],["64375.40","3.411"],["64381.10","0.117"],["64381.90","0.000"],["64682.20","0.000"],["64687.20","0.000"],["64797.50","5.502"],["64804.20","2.224"],["64924.10","0.004"],["65327.60","0.003"]],"b":[["1000.00","37.592"],["13563.10","0.490"],["13566.10","0.000"],["13566.70","0.000"],["13646.60","0.280"],["13763.10","0.490"],["13766.10","0.000"],["13766.70","0.000"],["13846.60","0.280"],["13946.60","0.280"],["13963.10","0.308"],["13965.70","0.000"],["13966.10","0.000"],["13966.70","0.000"],["51237.00","0.000"],["57641.90","0.002"],["61484.70","0.010"],["63246.20","0.237"],["63255.50","0.000"],["63406.10","0.001"],["63649.50","0.452"],["63709.50","0.003"],["63726.30","0.008"],["63734.70","0.784"],["63739.60","0.393"],["63742.70","0.000"],["63742.80","0.011"],["63912.60","3.903"],["63913.60","2.158"],["63923.30","0.005"],["63925.20","0.002"],["63926.20","1.443"],["63939.90","0.035"],["63946.20","2.351"],["63947.50","22.669"],["63947.60","0.008"],["63948.70","4.812"],["63950.50","0.000"],["63956.30","0.006"],["63958.10","0.851"],["63958.40","0.077"],["63959.40","0.002"],["63970.90","0.066"],["63971.00","0.378"],["63977.10","0.010"],["63979.40","0.031"],["63984.70","0.211"],["63986.20","0.003"],["63986.50","0.003"],["63990.30","0.001"],["63992.90","0.002"],["63994.00","0.001"],["63994.70","0.003"],["63999.30","0.003"],["64001.90","0.003"],["64002.70","2.409"],["64004.00","1.497"],["64005.00","0.101"],["64005.70","0.004"],["64005.80","0.003"],["64007.50","0.005"],["64010.30","0.542"],["64010.40","0.065"],["64010.50","0.060"],["64010.80","2.340"],["64010.90","2.092"],["64011.00","0.573"],["64011.50","0.003"],["64011.60","0.003"],["64011.70","0.000"],["64011.80","0.039"],["64012.10","0.123"],["64012.60","2.566"],["64012.70","0.002"],["64013.30","0.003"],["64013.40","2.858"],["64013.50","0.137"],["64014.20","0.000"],["64014.60","3.266"],["64015.30","0.002"],["64016.60","0.158"],["64017.00","0.000"],["64017.70","0.110"],["64018.10","0.016"],["64018.90","0.000"],["64019.20","1.061"],["64020.00","0.058"],["64020.30","0.000"],["64021.30","0.052"],["64022.10","1.935"],["64022.80","0.027"],["64023.20","0.001"],["64023.50","0.001"],["64025.20","1.416"],["64025.70","0.075"],["64025.80","0.522"],["64025.90","2.348"],["64026.00","0.164"],["64026.70","0.002"],["64027.00","0.098"],["64027.60","0.080"],["64028.20","0.377"],["64028.70","1.412"],["64029.30","0.426"],["64032.10","0.022"],["64032.30","0.272"],["64032.40","0.186"],["64033.00","0.544"],["64033.60","0.317"],["64035.20","0.873"],["64035.40","0.002"],["64035.70","0.015"],["64035.80","0.409"],["64036.00","0.042"],["64036.20","0.836"],["64036.30","1.249"],["64036.70","0.083"],["64037.50","0.065"],["64037.90","0.062"],["64038.00","2.407"],["64038.10","1.691"],["64038.20","0.066"],["64038.40","0.165"],["64038.50","0.046"],["64038.60","0.859"],["64038.70","0.204"],["64038.80","0.159"],["64039.00","0.002"],["64039.20","0.032"],["64039.50","0.033"],["64039.80","0.268"],["64040.10","0.109"],["64040.30","0.003"],["64040.70","0.206"],["64041.00","0.008"],["64041.10","0.405"],["64041.20","0.023"],["64041.40","0.112"],["64041.60","0.008"],["64041.70","4.179"],["64041.80","2.447"],["64041.90","0.582"],["64042.00","0.887"],["64042.10","1.024"],["64042.20","0.079"],["64043.10","0.095"],["64046.60","7.269"]],"e":"depthUpdate","ps":"BTCUSDT","pu":11165394764121,"s":"BTCUSDT","st":1,"u":11165394783998}
{"E":1785353522390,"T":1785353522389,"U":11165394784134,"a":[["64046.70","18.561"],["64047.80","0.000"],["64048.40","0.203"],["64048.50","0.325"],["64049.60","0.000"],["64050.10","0.101"],["64050.60","0.001"],["64050.70","0.003"],["64050.80","0.177"],["64051.10","0.000"],["64051.20","0.005"],["64051.40","0.608"],["64053.40","0.000"],["64053.50","0.547"],["64053.60","0.059"],["64054.20","0.011"],["64055.70","0.001"],["64055.80","0.001"],["64056.30","0.176"],["64056.60","0.001"],["64057.20","0.317"],["64057.40","0.158"],["64057.50","2.344"],["64057.80","0.003"],["64058.40","0.948"],["64058.90","0.000"],["64059.10","0.004"],["64059.60","0.160"],["64059.90","0.086"],["64060.00","0.318"],["64060.20","0.992"],["64060.80","0.032"],["64061.90","0.280"],["64062.80","0.084"],["64064.10","0.096"],["64064.50","0.006"],["64065.40","0.170"],["64065.60","0.606"],["64065.70","0.953"],["64066.50","0.005"],["64066.80","0.161"],["64070.20","0.046"],["64070.90","0.162"],["64071.00","2.341"],["64071.80","0.002"],["64072.30","1.814"],["64072.90","0.001"],["64073.30","0.001"],["64073.90","0.020"],["64074.10","4.434"],["64074.50","0.725"],["64074.60","10.157"],["64074.80","0.001"],["64074.90","0.002"],["64075.60","10.232"],["64076.00","0.003"],["64076.40","0.745"],["64076.60","0.164"],["64077.10","1.666"],["64077.20","0.000"],["64077.50","0.138"],["64078.40","0.008"],["64078.50","0.521"],["64078.90","1.751"],["64079.90","0.472"],["64080.30","0.079"],["64082.30","0.002"],["64082.60","0.053"],["64082.80","0.014"],["64083.00","0.007"],["64083.30","0.001"],["64083.60","0.004"],["64086.40","1.166"],["64086.50","0.019"],["64087.70","0.028"],["64090.30","0.000"],["64103.00","1.488"],["64103.10","0.140"],["64105.20","0.022"],["64106.30","1.231"],["64106.40","1.350"],["64108.70","2.867"],["64110.70","0.044"],["64113.50","0.001"],["64115.40","0.141"],["64123.40","1.655"],["64123.50","0.000"],["64130.20","0.097"],["64130.90","0.527"],["64143.70","1.525"],["64143.90","0.002"],["64187.60","0.123"],["64236.30","0.135"],["64300.30","0.094"],["64367.00","0.001"],["64687.20","0.000"],["64788.50","1.834"],["64788.90","0.922"],["64789.70","1.100"],["64804.20","2.232"],["64832.00","2.673"],["64871.40","0.007"],["64989.10","1.109"],["65053.10","1.075"]],"b":[["1000.00","37.592"],["13563.10","0.378"],["13646.60","0.406"],["13763.10","0.364"],["13846.60","0.406"],["13946.60","0.392"],["13963.10","0.182"],["57641.90","0.002"],["60857.00","0.002"],["61484.70","0.013"],["62983.50","0.503"],["63224.80","0.006"],["63406.10","0.001"],["63729.60","0.179"],["63847.00","2.509"],["63876.90","0.005"],["63878.30","0.463"],["63881.30","1.319"],["63881.60","0.461"],["63883.80","0.415"],["63912.30","0.000"],["63923.30","0.005"],["63940.30","4.551"],["63940.40","0.032"],["63940.60","0.003"],["63947.50","0.510"],["63947.60","0.000"],["63948.70","1.139"],["63948.80","2.368"],["63954.10","22.162"],["63954.60","5.157"],["63955.70","2.871"],["63958.10","1.189"],["63960.60","1.496"],["63960.70","0.482"],["63962.20","0.005"],["63970.00","0.545"],["63970.90","0.006"],["63982.60","0.003"],["63985.50","2.243"],["63986.10","0.000"],["63986.40","0.063"],["63994.40","0.080"],["64002.60","0.716"],["64003.30","0.001"],["64003.70","0.528"],["64004.00","1.500"],["64007.90","2.275"],["64008.50","0.004"],["64008.70","0.000"],["64008.90","0.037"],["64009.10","0.001"],["64009.20","0.010"],["64009.60","1.222"],["64009.70","0.319"],["64010.50","0.000"],["64010.60","0.080"],["64010.70","0.196"],["64010.90","2.032"],["64011.00","0.235"],["64012.60","1.243"],["64013.40","2.854"],["64014.30","0.000"],["64014.60","1.266"],["64018.40","0.003"],["64019.00","0.001"],["64019.10","0.323"],["64019.20","1.046"],["64019.90","2.673"],["64020.00","0.330"],["64020.70","0.935"],["64020.90","0.411"],["64022.10","1.000"],["64022.50","2.547"],["64022.80","0.026"],["64023.20","0.000"],["64023.50","0.000"],["64023.70","0.565"],["64025.70","0.074"],["64026.00","0.441"],["64026.10","0.024"],["64028.40","0.013"],["64028.60","0.008"],["64028.80","0.958"],["64029.30","0.427"],["64029.40","0.317"],["64029.50","0.003"],["64032.10","0.006"],["64033.70","0.234"],["64036.70","0.037"],["64037.80","0.120"],["64037.90","0.122"],["64038.00","2.467"],["64038.20","0.128"],["64038.60","0.007"],["64038.80","0.312"],["64039.80","0.034"],["64040.40","0.005"],["64040.80","0.010"],["64041.10","0.182"],["64041.40","0.089"],["64042.00","1.895"],["64042.20","0.651"],["64042.30","0.004"],["64042.90","0.101"],["64043.10","0.001"],["64043.40","0.005"],["64043.80","0.002"],["64046.60","8.260"]],"e":"depthUpdate","ps":"BTCUSDT","pu":11165394783998,"s":"BTCUSDT","st":1,"u":11165394794376}
{"E":1785353522492,"T":1785353522491,"U":11165394794460,"a":[["64046.70","17.780"],["64048.40","0.113"],["64048.80","0.095"],["64050.30","0.003"],["64051.30","0.000"],["64051.70","1.042"],["64054.20","0.014"],["64055.00","0.009"],["64058.70","0.254"],["64059.70","0.357"],["64060.10","2.340"],["64060.20","0.993"],["64060.80","0.033"],["64061.20","0.064"],["64061.30","0.315"],["64061.40","0.004"],["64063.50","0.384"],["64064.00","1.148"],["64064.40","0.001"],["64065.00","0.171"],["64065.90","0.362"],["64068.90","0.003"],["64069.10","0.346"],["64069.90","0.002"],["64070.60","0.001"],["64074.60","20.157"],["64074.70","0.543"],["64075.10","0.009"],["64075.60","0.232"],["64080.10","2.445"],["64080.90","0.095"],["64081.20","0.006"],["64081.40","0.000"],["64082.40","2.948"],["64082.60","0.051"],["64085.00","0.536"],["64090.30","0.024"],["64106.20","0.269"],["64108.50","0.073"],["64110.60","2.166"],["64111.70","1.249"],["64119.50","0.000"],["64121.00","0.138"],["64123.40","1.653"],["64123.90","0.001"],["64130.20","0.025"],["64153.40","0.000"],["64160.20","5.268"],["64162.90","23.884"],["64193.00","0.046"],["64193.70","0.040"],["64375.40","3.256"],["64687.20","0.002"],["64788.90","1.839"],["64804.20","1.315"]],"b":[["13563.10","0.252"],["13646.60","0.518"],["13763.10","0.252"],["13846.60","0.518"],["13946.60","0.518"],["13963.10","0.070"],["57641.90","0.002"],["61484.70","0.010"],["62832.30","0.681"],["63093.60","0.791"],["63246.20","1.027"],["63406.10","0.001"],["63739.60","0.392"],["63879.70","10.060"],["63881.60","1.942"],["63938.40","0.000"],["63939.90","0.003"],["63946.20","2.359"],["63948.80","2.360"],["63950.50","0.493"],["63969.50","0.000"],["63985.70","10.154"],["63990.50","0.520"],["63995.30","1.078"],["63997.30","0.373"],["64004.70","0.173"],["64005.50","0.008"],["64006.10","0.002"],["64006.70","0.029"],["64007.30","0.001"],["64010.20","0.001"],["64011.10","0.000"],["64012.80","0.152"],["64015.50","0.024"],["64017.80","10.503"],["64018.60","0.312"],["64018.70","0.041"],["64019.00","0.001"],["64019.20","2.575"],["64021.10","0.000"],["64022.50","0.547"],["64022.70","1.686"],["64025.60","2.338"],["64032.60","0.007"],["64032.80","0.004"],["64033.30","0.003"],["64037.60","0.181"],["64037.80","0.180"],["64038.40","0.225"],["64038.80","0.159"],["64040.30","0.001"],["64041.80","2.445"],["64042.20","0.651"],["64042.30","0.004"],["64042.90","0.007"],["64043.00","0.001"],["64044.30","0.003"],["64046.60","8.261"]],"e":"depthUpdate","ps":"BTCUSDT","pu":11165394794376,"s":"BTCUSDT","st":1,"u":11165394803276}
{"E":1785353522594,"T":1785353522593,"U":11165394803319,"a":[["64046.70","17.806"],["64046.80","0.010"],["64046.90","0.004"],["64047.50","0.094"],["64048.10","0.000"],["64048.30","0.023"],["64050.70","0.002"],["64050.80","0.013"],["64051.20","0.077"],["64051.30","0.164"],["64051.40","0.609"],["64052.80","0.330"],["64053.70","7.073"],["64055.00","0.011"],["64056.00","1.003"],["64056.60","0.118"],["64057.90","0.014"],["64058.10","0.005"],["64058.40","0.952"],["64058.60","0.000"],["64058.70","0.816"],["64058.90","0.094"],["64059.80","0.015"],["64060.30","0.793"],["64060.50","0.008"],["64062.10","0.107"],["64063.30","0.362"],["64064.00","1.054"],["64065.50","0.480"],["64070.00","0.066"],["64071.20","0.002"],["64074.50","0.413"],["64076.40","0.433"],["64077.70","0.008"],["64080.50","0.001"],["64081.70","0.627"],["64084.70","0.821"],["64088.10","0.230"],["64091.30","0.000"],["64091.90","0.617"],["64092.20","0.004"],["64094.50","0.312"],["64096.90","0.005"],["64103.90","0.002"],["64105.80","0.776"],["64108.50","0.001"],["64160.70","23.895"],["64162.90","0.001"],["64193.00","0.007"],["64193.60","0.042"],["64380.40","0.310"],["64687.20","0.000"],["64700.50","1.224"],["64783.90","0.921"],["64785.70","1.145"],["64788.50","0.000"],["64948.40","0.775"],["65281.70","0.656"],["65327.60","0.006"],["65341.10","0.009"]],"b":[["1000.00","37.592"],["13563.10","0.140"],["13646.60","0.644"],["13746.60","0.056"],["13763.10","0.126"],["13846.60","0.588"],["13863.10","0.126"],["13946.60","0.630"],["13963.10","0.000"],["57641.90","0.002"],["60839.70","0.004"],["60844.30","0.002"],["63016.50","0.000"],["63406.10","0.001"],["63408.10","0.002"],["63726.40","0.336"],["63727.40","0.028"],["63742.80","0.001"],["63863.80","0.077"],["63939.60","0.001"],["63954.10","0.003"],["63954.60","1.694"],["63956.30","22.165"],["63958.10","4.453"],["63984.00","0.018"],["63997.70","0.063"],["63998.90","0.003"],["63999.00","0.906"],["63999.70","0.004"],["64000.40","0.032"],["64001.50","0.004"],["64004.30","0.001"],["64004.90","0.034"],["64006.80","0.012"],["64008.30","0.004"],["64011.00","0.175"],["64014.70","0.004"],["64015.80","0.666"],["64016.00","0.008"],["64016.50","2.988"],["64017.40","0.562"],["64017.70","0.111"],["64017.80","0.503"],["64018.20","0.001"],["64018.50","10.138"],["64018.60","0.000"],["64018.70","0.040"],["64019.80","0.007"],["64021.20","0.000"],["64021.70","0.026"],["64021.90","0.313"],["64022.10","1.394"],["64024.70","0.002"],["64024.80","1.020"],["64029.90","0.009"],["64031.10","0.035"],["64031.30","0.159"],["64032.10","0.007"],["64032.30","0.584"],["64033.60","0.005"],["64036.00","0.045"],["64036.10","0.003"],["64036.60","0.004"],["64037.70","0.198"],["64038.10","1.535"],["64040.30","0.191"],["64040.40","0.002"],["64040.90","0.237"],["64041.00","0.005"],["64041.40","0.089"],["64041.60","0.031"],["64041.70","4.085"],["64042.20","0.079"],["64042.30","1.487"],["64043.00","0.001"],["64044.60","0.008"],["64045.40","0.002"],["64046.50","0.007"],["64046.60","8.193"]],"e":"depthUpdate","ps":"BTCUSDT","pu":11165394803276,"s":"BTCUSDT","st":1,"u":11165394813603}
{"E":1785353522696,"T":1785353522694,"U":11165394813613,"a":[["64046.70","18.366"],["64046.80","0.015"],["64048.30","0.001"],["64049.60","0.002"],["64050.30","0.003"],["64053.30","0.823"],["64053.60","0.153"],["64053.70","7.075"],["64053.80","0.003"],["64055.70","0.957"],["64060.30","0.239"],["64062.20","1.490"],["64062.30","1.244"],["64062.80","0.084"],["64063.20","0.524"],["64063.50","0.259"],["64066.50","0.448"],["64069.30","0.096"],["64069.40","0.314"],["64073.20","0.748"],["64073.60","0.706"],["64074.10","2.333"],["64074.60","12.157"],["64075.90","0.609"],["64076.80","3.314"],["64078.60","0.815"],["64080.10","2.002"],["64080.30","0.079"],["64082.60","0.908"],["64086.10","0.137"],["64086.80","0.005"],["64089.70","0.315"],["64093.20","0.000"],["64096.20","0.000"],["64099.70","0.001"],["64105.60","0.173"],["64141.20","5.955"],["64154.00","1.209"],["64156.30","0.000"],["64160.20","1.356"],["64160.70","0.012"],["64183.80","3.026"],["64195.30","0.784"],["64196.20","0.072"],["64375.40","3.101"],["64687.20","0.000"],["64788.90","2.756"],["64804.20","0.390"],["64827.70","0.020"]],"b":[["13563.10","0.014"],["13646.60","0.756"],["13746.60","0.168"],["13763.10","0.014"],["13863.10","0.014"],["13946.60","0.756"],["57641.90","0.002"],["61484.70","0.013"],["62765.70","0.003"],["62957.80","0.713"],["63149.90","6.202"],["63155.50","1.583"],["63406.10","0.001"],["63426.00","0.004"],["63908.90","0.931"],["63918.60","0.000"],["63940.20","0.039"],["63956.30","0.006"],["63958.10","0.019"],["63958.50","22.243"],["63961.60","4.705"],["63997.90","0.569"],["64010.40","0.005"],["64016.90","0.000"],["64018.50","0.138"],["64019.20","1.046"],["64019.60","10.572"],["64022.60","1.251"],["64024.80","0.708"],["64026.30","0.362"],["64031.30","0.003"],["64034.10","0.002"],["64037.40","0.177"],["64037.70","0.120"],["64041.40","0.089"],["64041.50","0.002"],["64044.10","0.002"],["64044.40","0.438"],["64044.60","0.002"],["64046.60","8.216"]],"e":"depthUpdate","ps":"BTCUSDT","pu":11165394813603,"s":"BTCUSDT","st":1,"u":11165394823664}
{"E":1785353522798,"T":1785353522796,"U":11165394823749,"a":[["64046.70","11.412"],["64046.80","0.014"],["64046.90","0.001"],["64047.50","0.000"],["64048.40","0.000"],["64048.50","0.005"],["64048.80","0.001"],["64049.00","0.000"],["64049.20","0.000"],["64049.60","0.002"],["64049.80","0.001"],["64049.90","0.000"],["64050.00","0.006"],["64050.10","0.007"],["64050.20","0.000"],["64050.30","0.097"],["64050.80","0.001"],["64050.90","0.000"],["64051.20","0.013"],["64051.30","0.002"],["64051.40","0.002"],["64051.60","0.003"],["64051.70","0.098"],["64051.90","0.003"],["64052.00","0.014"],["64052.60","0.034"],["64052.90","0.001"],["64053.00","0.002"],["64053.10","0.156"],["64053.20","0.719"],["64053.30","0.440"],["64053.40","0.001"],["64053.60","0.059"],["64053.70","6.929"],["64053.80","0.005"],["64054.00","0.001"],["64054.20","0.011"],["64054.40","0.002"],["64055.40","0.001"],["64055.80","0.126"],["64056.60","0.001"],["64057.40","0.001"],["64057.50","0.121"],["64058.10","0.022"],["64058.70","0.254"],["64058.90","0.000"],["64059.20","0.001"],["64059.50","0.564"],["64059.60","0.003"],["64059.80","0.002"],["64059.90","0.086"],["64060.10","0.000"],["64060.80","0.053"],["64061.50","0.435"],["64061.90","0.260"],["64062.00","0.008"],["64062.10","0.459"],["64062.60","0.013"],["64062.70","0.001"],["64062.80","0.064"],["64062.90","1.971"],["64063.20","0.399"],["64063.30","0.144"],["64063.90","0.419"],["64064.50","0.006"],["64064.90","1.608"],["64065.20","0.001"],["64065.40","0.168"],["64065.50","0.168"],["64065.60","0.449"],["64065.70","0.297"],["64066.00","0.328"],["64068.10","0.389"],["64068.60","0.002"],["64068.80","0.027"],["64068.90","0.003"],["64069.20","0.523"],["64069.60","0.011"],["64070.00","0.008"],["64070.50","0.681"],["64070.90","0.162"],["64072.30","2.158"],["64073.30","0.014"],["64073.50","0.158"],["64074.60","10.157"],["64074.80","0.001"],["64075.30","0.001"],["64076.00","0.038"],["64076.70","0.003"],["64076.80","1.429"],["64077.10","1.658"],["64077.40","0.010"],["64078.80","1.563"],["64079.40","0.018"],["64079.70","0.000"],["64079.80","2.535"],["64080.30","0.030"],["64080.60","10.005"],["64080.90","0.005"],["64081.70","0.549"],["64082.50","0.001"],["64082.70","3.566"],["64083.20","1.300"],["64083.40","0.539"],["64083.60","0.000"],["64083.80","0.014"],["64085.30","2.000"],["64087.20","1.025"],["64087.30","0.377"],["64087.40","0.000"],["64088.10","0.004"],["64089.60","2.523"],["64092.70","0.061"],["64094.20","0.103"],["64094.50","0.000"],["64094.70","0.088"],["64095.10","0.120"],["64097.60","0.003"],["64098.40","0.976"],["64106.40","1.325"],["64107.30","0.002"],["64107.50","0.452"],["64107.60","0.037"],["64107.80","0.000"],["64109.80","0.008"],["64110.10","12.700"],["64115.00","0.038"],["64117.00","0.066"],["64120.60","2.284"],["64122.60","0.013"],["64130.20","0.097"],["64131.90","0.074"],["64184.70","0.996"],["64186.20","1.524"],["64186.30","2.750"],["64186.70","0.002"],["64188.70","0.000"],["64190.70","0.002"],["64192.70","0.001"],["64193.20","0.200"],["64193.30","0.041"],["64193.60","0.003"],["64194.70","0.001"],["64196.30","0.001"],["64196.70","0.211"],["64198.70","0.003"],["64200.70","4.699"],["64201.90","0.541"],["64202.70","0.000"],["64204.70","0.000"],["64233.90","0.001"],["64262.70","0.590"],["64264.50","0.221"],["64329.10","0.000"],["64330.80","0.225"],["64332.40","0.000"],["64375.40","2.946"],["64380.50","0.155"],["64687.20","0.000"],["64834.00","0.955"],["65327.60","0.009"],["65341.10","0.006"]],"b":[["13560.10","0.210"],["13563.10","0.000"],["13646.60","0.882"],["13746.60","0.294"],["13760.10","0.294"],["13763.00","0.000"],["13763.10","0.000"],["13860.10","0.294"],["13863.10","0.000"],["13946.60","0.868"],["57641.90","0.002"],["61484.70","0.010"],["63117.90","0.316"],["63406.10","0.001"],["63410.70","0.077"],["63732.70","0.001"],["63734.70","0.627"],["63734.80","0.186"],["63957.30","1.198"],["63958.50","0.084"],["63961.60","4.694"],["63962.00","0.064"],["63984.70","0.001"],["63988.30","0.002"],["63991.90","0.211"],["63992.10","2.344"],["63992.80","0.029"],["63996.10","3.162"],["63999.40","0.000"],["64002.50","0.379"],["64004.00","1.497"],["64004.20","0.003"],["64008.80","0.002"],["64009.30","0.061"],["64012.10","0.003"],["64013.50","0.158"],["64014.40","0.048"],["64015.50","0.004"],["64016.70","0.001"],["64016.80","0.081"],["64017.30","0.008"],["64019.50","0.100"],["64019.60","1.507"],["64020.00","0.052"],["64020.10","0.350"],["64020.30","0.195"],["64020.60","0.021"],["64020.70","0.000"],["64021.30","0.002"],["64022.10","1.271"],["64022.30","0.362"],["64023.30","0.279"],["64023.40","0.539"],["64024.10","0.250"],["64025.00","0.697"],["64025.30","0.080"],["64025.90","2.347"],["64026.00","0.163"],["64026.10","0.003"],["64026.40","0.002"],["64027.30","0.933"],["64027.40","10.008"],["64028.40","0.063"],["64028.50","0.377"],["64029.30","0.332"],["64029.40","0.318"],["64029.50","0.003"],["64029.70","0.000"],["64030.10","0.004"],["64030.50","0.011"],["64030.70","0.025"],["64031.10","0.000"],["64032.30","0.564"],["64032.80","0.124"],["64033.60","0.005"],["64033.70","0.254"],["64034.80","0.022"],["64035.60","0.007"],["64036.70","0.017"],["64038.20","0.066"],["64039.20","0.046"],["64039.40","0.059"],["64040.00","0.425"],["64040.20","0.006"],["64040.50","0.012"],["64040.80","0.323"],["64040.90","0.003"],["64041.10","0.279"],["64041.20","0.001"],["64041.30","0.314"],["64041.40","0.109"],["64041.50","0.105"],["64041.60","0.007"],["64041.90","0.021"],["64042.00","1.013"],["64042.10","0.002"],["64042.20","0.079"],["64042.30","0.008"],["64042.40","0.436"],["64042.50","0.001"],["64042.60","0.792"],["64042.70","0.282"],["64042.80","0.094"],["64042.90","0.007"],["64043.10","0.001"],["64043.30","0.384"],["64043.50","0.004"],["64043.80","0.236"],["64044.00","0.010"],["64044.10","0.005"],["64044.20","1.723"],["64044.30","0.003"],["64044.40","0.433"],["64044.50","2.341"],["64044.60","2.046"],["64045.10","0.000"],["64045.20","0.000"],["64045.50","0.041"],["64045.60","0.000"],["64045.90","0.099"],["64046.00","0.041"],["64046.20","0.000"],["64046.60","8.861"]],"e":"depthUpdate","ps":"BTCUSDT","pu":11165394823664,"s":"BTCUSDT","st":1,"u":11165394851907}
{"E":1785353522900,"T":1785353522899,"U":11165394852513,"a":[["64046.70","10.998"],["64049.60","0.002"],["64050.00","0.006"],["64050.30","0.003"],["64050.50","0.001"],["64050.60","0.001"],["64051.30","0.000"],["64051.40","0.096"],["64051.50","1.238"],["64051.60","0.002"],["64051.70","0.002"],["64051.80","0.003"],["64052.60","0.011"],["64053.10","0.096"],["64053.20","0.002"],["64053.40","0.000"],["64053.50","0.003"],["64053.60","0.836"],["64053.80","0.006"],["64054.10","0.023"],["64054.70","0.686"],["64054.80","0.001"],["64055.60","0.548"],["64055.90","0.000"],["64056.10","1.029"],["64057.50","0.004"],["64057.60","0.784"],["64058.70","0.254"],["64059.50","0.002"],["64059.90","0.163"],["64060.10","0.020"],["64060.40","2.340"],["64060.50","0.001"],["64060.60","0.094"],["64060.80","0.053"],["64060.90","0.922"],["64061.40","0.004"],["64061.50","0.355"],["64061.70","0.164"],["64061.80","0.012"],["64061.90","0.260"],["64062.00","0.125"],["64062.10","0.127"],["64062.80","0.221"],["64065.70","0.953"],["64067.90","0.146"],["64068.90","0.315"],["64070.90","0.162"],["64075.10","0.010"],["64080.00","1.843"],["64080.60","0.007"],["64081.50","0.002"],["64083.20","2.583"],["64084.20","0.821"],["64084.50","10.079"],["64085.30","0.000"],["64085.60","0.062"],["64087.00","0.184"],["64087.80","0.655"],["64089.60","1.184"],["64092.70","0.001"],["64094.20","0.013"],["64095.10","0.000"],["64098.50","0.004"],["64106.50","0.471"],["64107.50","0.452"],["64107.80","0.025"],["64112.60","0.692"],["64115.00","0.013"],["64120.60","2.074"],["64154.00","4.622"],["64156.30","24.271"],["64178.70","0.000"],["64180.70","0.000"],["64182.40","1.092"],["64182.70","0.000"],["64184.70","0.996"],["64186.20","1.118"],["64186.70","0.002"],["64188.70","0.000"],["64190.70","0.002"],["64192.30","1.010"],["64192.70","0.001"],["64193.10","0.039"],["64193.30","0.002"],["64194.70","0.001"],["64195.20","0.007"],["64196.70","0.211"],["64198.70","0.007"],["64201.90","0.335"],["64267.70","0.118"],["64380.50","0.310"],["64687.20","0.000"],["64702.20","0.032"],["64847.30","0.570"]],"b":[["1000.00","37.592"],["13560.10","0.084"],["13646.60","0.994"],["13746.60","0.406"],["13760.10","0.182"],["13860.10","0.182"],["13946.60","0.994"],["57641.90","0.002"],["61484.70","0.013"],["63323.20","2.814"],["63406.10","0.003"],["63421.00","0.032"],["63726.40","0.503"],["63927.30","0.003"],["63956.30","22.165"],["63957.30","4.352"],["63961.60","1.587"],["63974.50","0.028"],["63984.40","0.001"],["63986.20","0.000"],["63991.90","0.026"],["63993.90","0.210"],["63996.90","0.060"],["64000.50","0.000"],["64003.10","0.016"],["64009.30","0.001"],["64016.40","0.686"],["64016.80","0.001"],["64017.40","0.000"],["64019.40","0.011"],["64019.60","0.572"],["64019.90","3.235"],["64022.60","2.186"],["64024.60","0.080"],["64025.00","0.540"],["64026.40","0.000"],["64027.40","10.010"],["64028.70","1.569"],["64028.80","2.544"],["64029.40","0.317"],["64029.50","0.280"],["64029.60","0.296"],["64029.70","0.001"],["64032.70","0.021"],["64033.70","0.234"],["64035.00","0.003"],["64035.40","0.002"],["64039.60","0.096"],["64040.30","0.001"],["64041.80","2.385"],["64041.90","0.001"],["64042.00","1.010"],["64042.40","0.158"],["64042.60","0.001"],["64042.70","0.004"],["64042.90","0.197"],["64043.70","0.002"],["64043.80","0.002"],["64044.00","0.104"],["64044.10","0.006"],["64044.20","1.279"],["64044.30","0.237"],["64044.50","2.364"],["64044.70","0.358"],["64045.20","0.094"],["64045.30","0.000"],["64045.40","0.002"],["64045.60","0.022"],["64045.90","0.002"],["64046.00","0.001"],["64046.60","9.078"]],"e":"depthUpdate","ps":"BTCUSDT","pu":11165394851907,"s":"BTCUSDT","st":1,"u":11165394870656}
{"E":1785353523002,"T":1785353523001,"U":11165394870691,"a":[["64049.70","0.008"],["64051.20","0.015"],["64051.60","0.003"],["64052.70","0.001"],["64053.10","0.096"],["64053.20","0.002"],["64053.50","0.003"],["64053.60","0.829"],["64053.90","0.022"],["64054.60","0.547"],["64055.60","0.001"],["64056.00","1.004"],["64060.10","0.027"],["64060.20","0.991"],["64060.70","0.004"],["64062.00","0.120"],["64063.00","2.342"],["64067.70","0.114"],["64070.90","0.160"],["64076.00","0.088"],["64077.40","0.103"],["64080.00","1.826"],["64083.20","2.533"],["64096.00","1.067"],["64096.10","0.066"],["64101.30","0.156"],["64103.20","0.000"],["64107.50","0.452"],["64117.40","0.010"],["64128.20","0.002"],["64135.30","0.508"],["64160.00","0.822"],["64160.30","2.998"],["64167.40","0.002"],["64193.00","0.046"],["64193.10","0.000"],["64240.00","2.320"],["64320.00","0.472"],["64366.90","0.181"],["64375.40","0.620"],["64400.00","12.145"],["64687.20","0.002"],["64820.30","1.554"],["64957.90","0.006"],["65327.60","0.012"]],"b":[["13560.10","0.000"],["13646.60","1.120"],["13746.60","0.532"],["13760.10","0.056"],["13846.60","0.616"],["13860.10","0.056"],["13946.60","1.078"],["13960.10","0.056"],["51237.00","0.000"],["51237.30","0.000"],["57641.90","0.002"],["61484.70","0.010"],["63406.10","0.001"],["63680.00","3.924"],["63726.40","0.660"],["63760.00","0.463"],["63840.00","1.702"],["63920.00","0.848"],["63933.20","2.466"],["63940.10","0.600"],["63952.30","2.345"],["63956.30","0.006"],["63957.30","1.198"],["63962.00","0.064"],["63965.20","0.002"],["63969.50","0.000"],["63970.70","4.082"],["63972.10","0.001"],["63997.20","0.003"],["64000.00","10.986"],["64004.00","1.494"],["64018.20","0.563"],["64019.90","2.673"],["64021.40","2.017"],["64022.60","1.251"],["64028.50","0.379"],["64029.30","0.334"],["64031.50","0.002"],["64032.70","0.001"],["64034.20","0.025"],["64035.40","0.002"],["64035.50","0.001"],["64038.50","0.034"],["64044.10","0.018"],["64044.30","0.003"],["64044.50","2.342"],["64044.60","2.280"],["64044.70","0.359"],["64045.20","0.000"],["64045.60","0.000"],["64046.60","9.112"]],"e":"depthUpdate","ps":"BTCUSDT","pu":11165394870656,"s":"BTCUSDT","st":1,"u":11165394880587}
{"E":1785353523104,"T":1785353523103,"U":11165394880681,"a":[["64046.70","11.474"],["64049.20","0.037"],["64049.30","0.094"],["64049.70","0.008"],["64049.80","0.016"],["64050.30","0.003"],["64050.50","0.095"],["64051.20","0.012"],["64051.30","0.072"],["64051.40","0.159"],["64051.50","1.244"],["64051.80","0.097"],["64052.60","0.009"],["64052.80","0.353"],["64053.10","0.096"],["64053.20","0.002"],["64053.40","0.438"],["64053.50","2.567"],["64053.60","0.769"],["64053.90","0.000"],["64054.10","0.011"],["64054.20","0.167"],["64054.50","0.777"],["64054.60","1.482"],["64054.70","0.052"],["64055.60","0.001"],["64055.80","0.001"],["64056.10","0.094"],["64056.30","0.020"],["64057.50","2.501"],["64057.60","1.150"],["64058.20","0.002"],["64058.80","0.144"],["64058.90","1.249"],["64059.50","0.001"],["64059.90","0.002"],["64060.10","0.157"],["64060.70","0.006"],["64061.70","0.007"],["64062.10","0.147"],["64062.80","0.064"],["64063.30","0.050"],["64064.80","0.158"],["64065.50","0.168"],["64067.90","0.066"],["64068.70","0.320"],["64068.90","0.038"],["64070.10","0.464"],["64074.70","0.543"],["64076.00","0.053"],["64076.40","0.376"],["64077.60","0.061"],["64079.10","0.005"],["64079.50","0.317"],["64080.70","0.122"],["64083.20","1.250"],["64083.60","0.000"],["64084.50","0.079"],["64087.80","0.535"],["64088.40","2.342"],["64091.50","0.659"],["64093.70","0.161"],["64093.90","0.002"],["64098.30","0.002"],["64101.30","0.156"],["64104.30","0.031"],["64104.70","0.095"],["64107.30","0.005"],["64107.50","0.452"],["64108.50","0.001"],["64111.10","0.077"],["64111.50","0.341"],["64117.50","2.759"],["64123.90","0.029"],["64130.20","0.025"],["64130.40","0.123"],["64131.90","0.002"],["64136.80","0.045"],["64137.00","0.014"],["64137.50","0.002"],["64193.00","0.007"],["64193.40","0.039"],["64286.50","0.000"],["64375.40","0.000"],["64687.20","0.000"]],"b":[["13646.60","1.232"],["13746.60","0.644"],["13756.70","0.014"],["13757.60","0.000"],["13759.50","0.000"],["13760.10","0.000"],["13846.60","0.742"],["13856.70","0.000"],["13857.60","0.000"],["13860.10","0.000"],["13956.70","0.000"],["13957.60","0.000"],["13959.50","0.000"],["13960.10","0.000"],["51237.00","0.002"],["57641.90","0.002"],["63112.10","0.276"],["63310.10","1.877"],["63406.10","0.001"],["63734.70","0.001"],["63851.30","0.117"],["63851.70","0.027"],["63960.70","0.482"],["63961.60","1.587"],["63962.00","0.002"],["63968.10","0.058"],["63969.50","0.000"],["63970.70","4.082"],["63972.30","0.089"],["63980.90","0.028"],["63986.40","0.273"],["63988.50","0.224"],["63993.90","0.000"],["64015.60","0.121"],["64017.60","0.074"],["64017.70","0.041"],["64019.40","0.011"],["64019.50","10.100"],["64020.20","0.061"],["64020.60","0.021"],["64021.10","0.935"],["64021.40","1.082"],["64021.60","0.000"],["64022.10","2.575"],["64022.30","0.242"],["64022.80","0.026"],["64023.80","0.058"],["64024.20","0.133"],["64024.90","0.016"],["64025.20","1.367"],["64025.50","0.055"],["64025.60","1.638"],["64026.80","0.001"],["64027.40","0.010"],["64028.80","1.658"],["64029.30","0.612"],["64031.30","0.003"],["64032.00","1.493"],["64032.30","0.564"],["64033.20","0.022"],["64033.40","0.096"],["64034.20","0.005"],["64035.10","0.372"],["64035.40","0.022"],["64036.40","0.007"],["64039.20","0.032"],["64040.80","0.010"],["64041.30","0.001"],["64041.90","0.191"],["64042.00","0.002"],["64042.80","0.000"],["64042.90","0.007"],["64043.40","1.013"],["64044.00","0.012"],["64044.10","0.022"],["64044.30","0.025"],["64044.60","2.046"],["64044.70","0.061"],["64044.80","0.242"],["64045.20","0.000"],["64045.30","0.000"],["64045.40","0.002"],["64045.50","0.042"],["64045.80","0.007"],["64045.90","0.005"],["64046.40","0.003"],["64046.60","8.653"]],"e":"depthUpdate","ps":"BTCUSDT","pu":11165394880587,"s":"BTCUSDT","st":1,"u":11165394899360}
{"E":1785353523206,"T":1785353523205,"U":11165394899497,"a":[["64046.70","10.238"],["64047.20","0.002"],["64048.40","0.002"],["64049.20","0.000"],["64049.30","0.000"],["64050.50","0.001"],["64051.30","0.000"],["64051.40","0.002"],["64051.80","0.003"],["64051.90","0.097"],["64053.10","0.291"],["64053.20","0.159"],["64053.40","0.313"],["64053.50","0.043"],["64053.60","0.059"],["64055.80","0.126"],["64056.60","0.001"],["64057.40","0.061"],["64058.80","0.050"],["64059.20","0.002"],["64060.30","0.239"],["64061.50","0.275"],["64062.10","0.823"],["64062.30","1.324"],["64063.00","2.422"],["64063.30","0.147"],["64064.00","0.354"],["64064.10","0.002"],["64065.50","0.168"],["64065.60","0.543"],["64069.30","0.002"],["64070.10","0.384"],["64073.90","0.000"],["64075.00","0.314"],["64079.80","2.535"],["64080.00","1.843"],["64083.20","2.533"],["64085.00","10.536"],["64091.00","0.105"],["64098.50","0.104"],["64101.30","0.156"],["64107.50","0.374"],["64108.50","0.073"],["64124.70","0.025"],["64130.20","0.097"],["64154.00","1.209"],["64156.30","0.000"],["64160.00","0.839"],["64180.70","0.000"],["64182.70","0.000"],["64184.70","0.996"],["64186.70","0.002"],["64188.70","0.000"],["64190.70","0.002"],["64192.30","1.049"],["64192.70","0.001"],["64193.40","0.000"],["64194.70","0.001"],["64196.70","0.211"],["64198.70","0.007"],["64200.70","4.699"],["64201.90","0.335"],["64202.70","0.000"],["64204.70","0.000"],["64240.00","2.337"],["64264.50","0.104"],["64267.70","0.001"],["64272.00","0.463"],["64272.10","9.308"],["64272.20","0.003"],["64285.20","0.680"],["64320.00","0.489"],["64366.90","0.331"],["64386.30","0.149"],["64386.50","0.149"],["64387.10","0.149"],["64400.00","12.162"],["64687.20","0.000"],["65000.00","153.508"]],"b":[["1000.00","37.592"],["13546.60","0.070"],["13646.60","1.288"],["13648.40","0.042"],["13651.60","0.000"],["13653.60","0.000"],["13746.60","0.770"],["13753.60","0.000"],["13756.70","0.000"],["13846.60","0.854"],["13848.40","0.042"],["13851.20","0.000"],["13851.60","0.000"],["13853.60","0.000"],["13948.40","0.056"],["13951.60","0.000"],["13953.60","0.000"],["51237.00","0.000"],["57641.90","0.002"],["61484.70","0.013"],["62447.80","0.686"],["62765.70","0.009"],["62778.80","0.563"],["63117.00","5.613"],["63187.60","1.101"],["63275.60","1.571"],["63406.10","0.000"],["63410.70","0.069"],["63680.00","3.941"],["63726.30","0.007"],["63726.40","0.650"],["63732.40","0.000"],["63760.00","0.480"],["63840.00","1.719"],["63896.60","0.016"],["63898.60","0.000"],["63900.60","0.017"],["63902.60","0.001"],["63904.60","0.000"],["63920.00","0.865"],["63960.70","22.800"],["63961.60","4.717"],["64000.00","11.003"],["64009.50","0.532"],["64017.60","0.004"],["64018.60","0.004"],["64019.50","0.100"],["64020.00","0.066"],["64022.10","1.271"],["64023.60","0.000"],["64024.70","0.072"],["64025.30","0.084"],["64028.50","0.317"],["64028.70","1.412"],["64028.80","11.658"],["64028.90","0.067"],["64030.20","0.165"],["64031.70","0.001"],["64032.00","2.635"],["64032.40","0.343"],["64033.20","0.002"],["64033.40","0.002"],["64034.10","0.002"],["64035.40","0.022"],["64041.00","0.003"],["64041.20","0.314"],["64042.70","0.098"],["64043.90","0.094"],["64044.70","0.104"],["64044.80","0.008"],["64045.10","0.000"],["64045.20","0.234"],["64045.50","0.002"],["64045.80","0.039"],["64046.30","0.000"],["64046.60","9.156"]],"e":"depthUpdate","ps":"BTCUSDT","pu":11165394899360,"s":"BTCUSDT","st":1,"u":11165394920676}
{"E":1785353523308,"T":1785353523304,"U":11165394920730,"a":[["64046.70","10.240"],["64049.70","0.008"],["64050.30","0.003"],["64050.40","0.000"],["64050.50","0.001"],["64051.40","0.002"],["64051.90","0.003"],["64053.10","0.291"],["64053.60","0.059"],["64057.40","0.231"],["64060.30","0.333"],["64062.00","0.120"],["64062.10","0.653"],["64080.50","0.001"],["64083.20","1.250"],["64085.00","0.536"],["64086.40","2.500"],["64087.20","11.025"],["64101.30","0.000"],["64107.50","0.374"],["64130.20","0.097"],["64156.80","4.057"],["64158.50","0.019"],["64163.20","0.277"],["64192.30","1.010"],["64193.10","0.039"],["64264.50","0.104"],["64267.70","0.001"],["64272.00","1.787"],["64272.10","9.263"],["64364.80","0.735"],["64366.90","2.658"],["64367.00","0.621"],["64687.20","0.000"],["65640.00","0.279"]],"b":[["13546.60","0.182"],["13646.60","1.218"],["13648.40","0.000"],["13746.60","0.882"],["13846.60","0.910"],["13848.40","0.000"],["13946.60","1.008"],["13948.40","0.000"],["44841.90","0.000"],["51237.00","0.000"],["57641.90","0.002"],["61484.70","0.010"],["62778.80","0.560"],["63091.50","0.003"],["63246.00","0.953"],["63406.10","0.000"],["63649.50","0.000"],["63671.10","3.588"],["63726.40","1.276"],["63960.70","0.482"],["63961.60","1.587"],["63969.50","0.000"],["63970.70","6.749"],["63988.30","0.102"],["64023.90","0.283"],["64028.80","1.658"],["64028.90","0.005"],["64029.20","4.261"],["64029.30","0.334"],["64029.50","0.002"],["64032.00","1.347"],["64032.10","10.007"],["64035.20","2.240"],["64037.30","0.003"],["64039.60","0.003"],["64041.70","4.086"],["64044.70","0.382"],["64045.20","0.094"],["64045.50","0.280"],["64046.60","9.424"]],"e":"depthUpdate","ps":"BTCUSDT","pu":11165394920676,"s":"BTCUSDT","st":1,"u":11165394936747}
{"E":1785353523410,"T":1785353523409,"U":11165394937635,"a":[["64046.70","0.000"],["64046.80","0.000"],["64046.90","0.000"],["64047.20","0.000"],["64047.40","0.000"],["64047.70","0.000"],["64048.20","0.000"],["64048.30","0.000"],["64048.40","0.000"],["64048.50","0.000"],["64048.60","0.000"],["64048.80","0.000"],["64049.10","0.000"],["64049.40","0.000"],["64049.60","0.000"],["64049.70","0.000"],["64049.80","0.000"],["64050.00","0.000"],["64050.10","0.000"],["64050.30","0.000"],["64050.50","0.000"],["64050.60","0.000"],["64050.70","0.000"],["64050.80","0.000"],["64051.00","0.000"],["64051.20","0.000"],["64051.40","0.000"],["64051.50","0.000"],["64051.60","0.000"],["64051.70","0.000"],["64051.80","0.000"],["64051.90","0.000"],["64052.00","0.000"],["64052.10","0.000"],["64052.30","0.000"],["64052.40","0.000"],["64052.60","0.000"],["64052.70","0.000"],["64052.80","0.000"],["64052.90","0.000"],["64053.00","0.000"],["64053.10","0.000"],["64053.20","0.000"],["64053.30","0.000"],["64053.40","0.000"],["64053.50","0.000"],["64053.60","0.000"],["64053.70","0.000"],["64053.80","0.000"],["64054.00","0.000"],["64054.10","0.000"],["64054.20","0.000"],["64054.30","0.000"],["64054.40","0.000"],["64054.50","0.000"],["64054.60","0.000"],["64054.70","0.000"],["64054.80","5.185"],["64054.90","0.002"],["64055.00","0.001"],["64055.10","0.000"],["64055.20","0.000"],["64055.30","0.000"],["64055.40","0.000"],["64055.50","0.000"],["64055.60","0.000"],["64055.70","0.000"],["64055.80","0.000"],["64056.00","0.000"],["64056.10","0.000"],["64056.20","0.000"],["64056.30","0.001"],["64056.40","0.002"],["64056.60","0.001"],["64056.70","0.002"],["64056.80","0.001"],["64057.10","0.000"],["64057.20","0.002"],["64057.30","0.014"],["64057.40","0.002"],["64057.50","0.003"],["64057.60","0.005"],["64057.70","0.024"],["64057.80","0.003"],["64057.90","0.000"],["64058.00","0.001"],["64058.10","0.002"],["64058.20","0.075"],["64058.30","0.560"],["64058.40","0.002"],["64058.60","0.000"],["64058.70","0.001"],["64058.80","0.978"],["64058.90","0.007"],["64059.10","0.002"],["64059.20","0.049"],["64059.30","0.000"],["64059.40","0.003"],["64059.60","0.002"],["64059.70","0.001"],["64059.90","1.599"],["64060.00","0.175"],["64060.10","0.094"],["64060.20","0.521"],["64060.30","0.001"],["64060.40","0.001"],["64060.50","0.001"],["64060.60","0.000"],["64060.70","0.004"],["64060.80","0.007"],["64060.90","0.000"],["64061.00","0.314"],["64061.10","0.001"],["64061.20","0.001"],["64061.30","0.001"],["64061.40","0.054"],["64061.50","0.001"],["64061.60","0.003"],["64061.70","0.001"],["64061.80","0.177"],["64061.90","0.003"],["64062.00","0.003"],["64062.10","1.502"],["64062.20","0.823"],["64062.30","0.637"],["64062.40","0.003"],["64062.50","0.002"],["64062.60","0.002"],["64062.70","2.498"],["64062.80","0.002"],["64062.90","1.913"],["64063.00","0.001"],["64063.10","0.251"],["64063.20","0.396"],["64063.30","0.144"],["64063.40","0.003"],["64063.60","1.028"],["64063.70","0.002"],["64063.90","0.965"],["64064.00","0.018"],["64064.10","0.015"],["64064.30","0.002"],["64064.50","0.096"],["64064.60","0.097"],["64064.70","0.159"],["64064.80","0.126"],["64064.90","1.341"],["64065.00","0.171"],["64065.10","0.006"],["64065.20","0.159"],["64065.30","0.483"],["64065.40","3.757"],["64065.50","0.609"],["64065.60","1.453"],["64065.70","0.390"],["64065.80","0.307"],["64065.90","0.329"],["64066.00","0.005"],["64066.10","0.388"],["64066.20","0.807"],["64066.30","0.120"],["64066.50","0.449"],["64066.60","0.021"],["64066.70","0.157"],["64066.80","0.255"],["64067.00","0.562"],["64067.10","0.150"],["64067.20","0.006"],["64067.40","0.158"],["64067.50","0.140"],["64067.60","0.838"],["64067.70","0.170"],["64067.80","0.202"],["64067.90","0.081"],["64068.00","0.191"],["64068.10","0.036"],["64068.20","0.000"],["64068.30","0.178"],["64068.40","0.128"],["64068.50","0.082"],["64068.60","0.000"],["64068.70","0.008"],["64068.80","0.945"],["64068.90","0.083"],["64069.00","0.292"],["64069.10","0.002"],["64069.20","0.096"],["64069.60","0.000"],["64069.90","0.013"],["64070.00","0.165"],["64070.20","0.315"],["64070.30","0.329"],["64070.40","1.570"],["64070.60","0.001"],["64070.70","0.000"],["64070.90","2.341"],["64071.00","0.001"],["64071.20","0.000"],["64071.50","0.004"],["64072.10","0.380"],["64072.20","0.314"],["64072.30","1.906"],["64072.40","0.001"],["64072.50","0.000"],["64072.70","0.001"],["64072.80","0.134"],["64073.00","0.001"],["64073.30","0.001"],["64073.50","2.594"],["64073.60","0.707"],["64073.70","0.001"],["64073.80","0.160"],["64074.00","0.194"],["64074.10","3.400"],["64074.20","0.313"],["64074.30","0.175"],["64074.40","1.698"],["64074.50","0.319"],["64074.70","0.544"],["64074.80","0.094"],["64075.00","0.897"],["64075.10","0.008"],["64075.20","0.368"],["64075.60","0.232"],["64075.70","0.014"],["64075.80","0.001"],["64076.00","0.003"],["64076.80","1.389"],["64076.90","0.091"],["64077.10","2.479"],["64077.30","0.014"],["64077.40","0.095"],["64077.50","0.295"],["64077.60","0.004"],["64077.70","0.004"],["64077.90","0.009"],["64078.20","0.000"],["64078.40","0.002"],["64078.50","1.180"],["64078.60","0.159"],["64078.70","0.001"],["64078.90","0.000"],["64079.20","0.400"],["64079.30","0.390"],["64079.40","0.001"],["64079.50","0.352"],["64079.80","2.537"],["64080.00","1.830"],["64080.20","0.000"],["64080.30","0.003"],["64080.40","0.391"],["64080.50","0.001"],["64080.60","0.002"],["64080.70","0.002"],["64080.90","0.022"],["64081.80","0.001"],["64081.90","0.003"],["64082.00","0.003"],["64082.20","0.065"],["64082.50","0.001"],["64082.60","0.871"],["64082.80","0.016"],["64083.00","0.003"],["64083.10","0.008"],["64083.30","0.002"],["64083.80","0.010"],["64083.90","0.000"],["64084.10","0.051"],["64084.20","0.861"],["64084.30","0.008"],["64084.50","0.093"],["64084.70","0.821"],["64085.00","0.538"],["64085.10","2.389"],["64085.20","0.007"],["64085.40","0.282"],["64085.50","1.320"],["64085.60","0.007"],["64085.70","0.001"],["64085.80","0.062"],["64086.10","0.125"],["64086.20","0.001"],["64086.40","2.409"],["64086.50","0.002"],["64086.70","0.000"],["64086.90","0.391"],["64087.00","0.094"],["64087.20","0.002"],["64087.30","0.392"],["64087.50","1.052"],["64087.60","0.009"],["64087.70","0.004"],["64087.80","0.535"],["64087.90","0.000"],["64088.00","0.003"],["64088.10","0.053"],["64088.40","2.340"],["64088.70","0.102"],["64088.90","0.006"],["64089.20","0.085"],["64089.30","0.610"],["64089.40","0.001"],["64089.50","0.063"],["64089.80","0.009"],["64090.00","0.063"],["64090.30","0.000"],["64090.60","0.378"],["64090.70","0.010"],["64090.90","0.899"],["64091.00","0.003"],["64091.10","0.022"],["64091.20","0.006"],["64091.30","0.000"],["64091.40","0.008"],["64091.60","2.363"],["64091.90","0.523"],["64092.00","0.653"],["64092.10","10.400"],["64092.50","0.000"],["64092.60","0.011"],["64092.70","0.048"],["64092.80","0.103"],["64092.90","0.071"],["64093.30","0.312"],["64093.40","1.152"],["64093.50","0.002"],["64093.70","0.161"],["64094.20","0.013"],["64094.40","2.343"],["64094.50","0.000"],["64094.60","0.001"],["64094.70","0.018"],["64094.80","0.002"],["64094.90","0.454"],["64095.00","0.060"],["64095.10","0.001"],["64095.20","0.004"],["64095.70","0.001"],["64095.80","0.096"],["64096.00","1.067"],["64096.50","0.003"],["64096.90","0.001"],["64097.00","1.591"],["64097.10","0.502"],["64097.20","5.894"],["64097.30","0.001"],["64097.50","0.177"],["64097.60","0.017"],["64097.70","0.094"],["64097.80","0.005"],["64098.70","0.090"],["64098.80","0.046"],["64099.20","1.962"],["64099.30","0.004"],["64099.40","0.003"],["64099.70","0.501"],["64099.90","0.802"],["64100.00","2.644"],["64100.40","0.046"],["64100.70","0.257"],["64101.20","0.011"],["64101.30","0.003"],["64101.60","0.006"],["64101.80","0.040"],["64102.00","0.633"],["64102.20","0.007"],["64102.40","0.020"],["64102.90","0.487"],["64103.40","0.102"],["64103.50","0.001"],["64104.00","0.006"],["64104.30","0.027"],["64104.70","0.132"],["64105.50","0.025"],["64105.90","0.003"],["64106.00","0.080"],["64106.60","0.977"],["64107.50","0.374"],["64107.80","0.000"],["64108.10","0.094"],["64108.50","0.001"],["64108.60","0.616"],["64108.90","3.390"],["64109.80","0.008"],["64110.60","2.151"],["64110.70","0.012"],["64111.20","0.001"],["64111.60","0.005"],["64112.30","0.000"],["64112.60","0.482"],["64113.30","0.110"],["64113.50","0.026"],["64114.90","0.502"],["64115.00","0.013"],["64116.60","0.000"],["64116.70","0.001"],["64117.70","0.002"],["64119.30","0.395"],["64120.00","0.118"],["64120.20","0.000"],["64120.40","0.509"],["64121.70","2.165"],["64122.00","0.507"],["64123.30","0.000"],["64123.90","0.056"],["64124.20","0.087"],["64125.30","0.022"],["64125.40","0.501"],["64125.50","0.000"],["64126.50","0.325"],["64129.80","0.003"],["64130.00","0.003"],["64130.20","0.025"],["64130.30","1.249"],["64131.50","0.001"],["64131.70","0.078"],["64131.90","0.002"],["64132.00","4.417"],["64132.80","0.004"],["64134.00","0.619"],["64135.90","0.016"],["64137.90","0.035"],["64142.80","0.001"],["64143.90","0.002"],["64145.30","0.000"],["64146.60","0.001"],["64147.10","0.000"],["64149.00","0.009"],["64150.90","3.179"],["64151.00","0.594"],["64151.30","0.024"],["64152.40","0.001"],["64153.40","0.000"],["64153.90","0.004"],["64156.20","2.342"],["64156.40","0.094"],["64156.80","0.505"],["64158.10","0.004"],["64160.00","0.840"],["64161.30","0.010"],["64162.70","2.342"],["64163.50","0.835"],["64168.20","0.001"],["64169.90","0.502"],["64171.30","0.010"],["64173.60","0.001"],["64174.70","0.000"],["64174.80","0.000"],["64175.60","0.000"],["64176.30","0.001"],["64176.60","0.500"],["64176.70","0.000"],["64178.70","0.883"],["64180.70","0.883"],["64181.70","0.430"],["64181.90","0.338"],["64182.70","0.883"],["64183.00","0.008"],["64184.70","1.879"],["64186.50","0.001"],["64186.70","0.885"],["64188.70","0.884"],["64190.20","0.040"],["64190.70","0.885"],["64192.70","0.884"],["64193.10","0.000"],["64193.20","0.722"],["64194.70","0.884"],["64196.70","1.094"],["64198.70","0.886"],["64200.70","5.582"],["64201.90","0.546"],["64202.60","0.885"],["64202.70","0.000"],["64203.10","0.004"],["64204.70","0.000"],["64206.70","0.006"],["64209.30","0.002"],["64209.40","0.002"],["64211.40","0.022"],["64226.00","0.000"],["64229.60","0.001"],["64232.80","0.027"],["64236.30","0.000"],["64238.80","0.000"],["64245.80","0.001"],["64247.30","0.000"],["64247.40","1.945"],["64263.00","0.133"],["64264.50","0.104"],["64265.90","7.662"],["64266.00","2.462"],["64267.70","0.001"],["64268.60","0.004"],["64268.70","0.000"],["64268.80","0.242"],["64286.10","1.028"],["64291.30","1.258"],["64300.30","0.000"],["64302.90","0.000"],["64309.80","0.535"],["64366.90","2.507"],["64371.60","0.154"],["64371.70","0.006"],["64371.90","0.299"],["64373.90","0.001"],["64374.20","0.002"],["64386.30","0.000"],["64386.50","0.000"],["64387.10","0.000"],["64403.30","0.002"],["64406.50","0.001"],["64413.30","0.851"],["64431.00","0.001"],["64437.90","0.001"],["64464.00","0.003"],["64495.00","0.041"],["64502.00","0.446"],["64559.10","0.001"],["64566.00","0.852"],["64687.20","0.000"],["64687.30","0.000"],["64691.90","0.000"],["64694.10","0.000"],["64695.30","0.141"],["64783.90","0.004"],["64785.70","0.228"],["64788.20","0.014"],["64788.40","0.917"],["64788.90","0.005"],["64790.50","1.065"],["64790.60","1.834"],["64790.90","0.960"],["64870.20","0.581"]],"b":[["13546.60","0.224"],["13551.30","0.014"],["13553.30","0.014"],["13553.50","0.042"],["13554.70","0.014"],["13646.60","1.092"],["13746.60","0.924"],["13751.30","0.014"],["13753.50","0.056"],["13754.70","0.014"],["13846.60","0.812"],["13848.40","0.014"],["13851.30","0.014"],["13853.50","0.042"],["13854.70","0.014"],["13946.60","0.896"],["57641.90","0.000"],["57646.10","0.073"],["57648.10","0.000"],["61491.30","0.003"],["62778.80","0.557"],["63051.30","0.031"],["63053.30","0.231"],["63053.50","0.004"],["63056.20","0.950"],["63057.60","0.921"],["63058.80","0.001"],["63059.90","0.935"],["63060.70","0.001"],["63117.90","1.424"],["63137.10","1.422"],["63403.10","0.003"],["63403.20","0.000"],["63406.10","0.000"],["63410.80","0.000"],["63413.00","5.117"],["63414.20","0.010"],["63718.00","0.106"],["63726.30","0.008"],["63726.40","1.433"],["63729.60","0.000"],["63734.20","0.179"],["63849.80","0.011"],["63852.70","0.118"],["63863.80","0.074"],["63882.00","0.000"],["63892.40","0.003"],["63894.90","0.007"],["63896.60","0.016"],["63898.60","0.000"],["63900.60","0.017"],["63902.60","0.001"],["63904.60","0.000"],["63905.80","0.000"],["63910.00","1.550"],["63911.50","0.002"],["63914.40","2.454"],["63914.70","0.000"],["63916.50","0.000"],["63920.90","0.035"],["63924.10","0.001"],["63925.20","0.001"],["63927.90","0.500"],["63932.10","0.375"],["63932.80","2.466"],["63933.20","0.509"],["63934.70","0.000"],["63936.00","0.706"],["63936.60","0.000"],["63938.50","0.374"],["63940.60","0.000"],["63945.90","2.638"],["63946.20","2.351"],["63946.40","0.000"],["63948.70","1.142"],["63950.00","0.270"],["63951.30","0.017"],["63951.60","0.001"],["63952.30","0.003"],["63952.60","0.027"],["63953.50","0.500"],["63960.00","0.230"],["63960.90","0.000"],["63963.90","0.005"],["63964.30","3.134"],["63964.40","1.103"],["63966.00","2.367"],["63967.80","0.035"],["63969.50","0.000"],["63969.80","0.298"],["63970.00","0.544"],["63970.70","4.082"],["63972.30","0.027"],["63974.00","0.001"],["63975.20","0.004"],["63976.00","0.001"],["63976.20","0.517"],["63976.40","0.000"],["63977.30","0.746"],["63978.60","0.501"],["63979.10","0.000"],["63979.40","0.000"],["63981.10","0.000"],["63981.30","0.000"],["63982.10","0.012"],["63983.30","0.015"],["63983.60","2.714"],["63984.30","0.001"],["63985.50","0.489"],["63985.60","0.002"],["63986.40","0.063"],["63986.50","0.002"],["63987.10","0.097"],["63987.20","3.145"],["63988.00","0.111"],["63988.50","0.434"],["63989.00","0.000"],["63989.80","1.898"],["63990.30","0.001"],["63991.90","0.000"],["63992.30","0.065"],["63992.80","0.001"],["63994.50","0.058"],["63994.90","0.000"],["63995.00","0.000"],["63995.30","1.078"],["63995.40","0.007"],["63996.00","0.001"],["63996.20","1.183"],["63996.60","0.011"],["63996.70","0.000"],["63997.40","0.377"],["63997.50","0.009"],["63997.60","0.000"],["63998.30","0.000"],["63998.50","0.025"],["63998.60","0.000"],["63998.90","0.000"],["63999.40","0.115"],["63999.60","0.460"],["63999.70","0.008"],["63999.90","0.002"],["64000.40","0.032"],["64000.50","0.000"],["64000.90","0.001"],["64001.00","0.510"],["64001.30","0.316"],["64001.80","0.009"],["64002.00","0.001"],["64002.20","0.038"],["64002.90","0.000"],["64003.40","0.000"],["64003.70","0.531"],["64004.20","0.000"],["64004.30","0.474"],["64004.40","0.065"],["64004.90","0.033"],["64005.10","0.000"],["64005.20","0.000"],["64005.30","0.313"],["64005.50","0.007"],["64006.10","0.001"],["64006.60","0.072"],["64006.70","0.028"],["64006.80","0.016"],["64007.30","0.000"],["64007.40","0.000"],["64007.70","0.032"],["64007.90","1.297"],["64008.10","0.001"],["64008.20","0.027"],["64008.30","0.004"],["64008.50","0.003"],["64008.90","0.033"],["64009.10","0.001"],["64009.20","0.013"],["64009.30","0.001"],["64009.60","1.195"],["64009.80","0.001"],["64010.30","0.533"],["64011.00","0.453"],["64011.10","0.000"],["64011.60","0.003"],["64012.70","0.002"],["64012.80","0.038"],["64012.90","0.001"],["64013.00","0.000"],["64013.40","2.894"],["64013.50","0.137"],["64013.80","0.000"],["64014.20","0.000"],["64014.60","1.265"],["64014.70","0.000"],["64014.80","0.027"],["64015.00","0.569"],["64015.10","0.716"],["64015.20","0.000"],["64015.60","0.001"],["64015.80","0.666"],["64016.20","0.000"],["64016.30","0.004"],["64016.40","0.626"],["64016.60","0.436"],["64016.70","0.121"],["64017.40","0.977"],["64017.60","0.041"],["64017.70","0.040"],["64017.80","0.507"],["64018.10","0.001"],["64018.20","0.001"],["64018.30","0.004"],["64018.40","0.073"],["64018.50","0.002"],["64018.60","0.000"],["64018.90","0.000"],["64019.00","0.001"],["64019.10","0.147"],["64019.20","1.046"],["64019.30","0.622"],["64019.40","0.011"],["64019.50","0.100"],["64019.80","0.000"],["64019.90","2.667"],["64020.00","0.052"],["64020.10","0.330"],["64020.40","0.001"],["64020.80","0.528"],["64020.90","0.002"],["64021.00","0.029"],["64021.10","0.000"],["64021.70","0.014"],["64022.10","1.271"],["64022.60","1.251"],["64022.70","1.723"],["64023.00","0.022"],["64023.10","2.342"],["64023.30","0.246"],["64023.40","0.537"],["64023.50","0.000"],["64023.70","0.549"],["64023.80","0.001"],["64023.90","0.287"],["64024.10","0.791"],["64024.20","0.118"],["64024.50","0.034"],["64024.60","0.080"],["64024.70","0.002"],["64024.80","0.386"],["64024.90","0.015"],["64025.10","0.001"],["64025.20","1.075"],["64025.30","0.080"],["64025.50","0.006"],["64026.00","0.159"],["64026.10","0.053"],["64026.40","0.000"],["64026.70","0.008"],["64026.80","0.001"],["64026.90","0.001"],["64027.10","0.072"],["64027.20","0.002"],["64027.30","0.000"],["64027.40","0.010"],["64027.60","0.255"],["64027.70","0.000"],["64027.80","0.001"],["64027.90","0.042"],["64028.10","0.001"],["64028.40","0.013"],["64028.50","0.315"],["64028.60","0.004"],["64028.80","1.661"],["64028.90","0.576"],["64029.00","1.077"],["64029.10","0.136"],["64029.20","4.199"],["64029.30","0.005"],["64029.40","1.252"],["64029.50","0.002"],["64029.60","0.455"],["64029.70","0.020"],["64029.80","0.456"],["64030.00","0.212"],["64030.10","0.007"],["64030.20","0.164"],["64030.30","0.012"],["64030.40","0.815"],["64030.50","0.000"],["64030.60","0.099"],["64030.70","0.002"],["64031.10","0.002"],["64031.20","0.000"],["64031.30","0.002"],["64031.50","0.059"],["64031.70","0.002"],["64032.00","1.359"],["64032.10","0.006"],["64032.20","2.407"],["64032.30","0.407"],["64032.40","0.183"],["64032.50","0.000"],["64032.60","0.006"],["64032.80","0.004"],["64033.00","0.313"],["64033.40","0.002"],["64033.70","0.021"],["64033.90","0.001"],["64034.00","0.294"],["64034.10","0.001"],["64034.20","0.938"],["64034.30","0.001"],["64034.50","0.002"],["64034.60","0.000"],["64034.80","0.001"],["64034.90","0.001"],["64035.20","0.873"],["64035.30","2.411"],["64035.40","0.235"],["64035.60","10.007"],["64035.70","0.021"],["64035.80","0.315"],["64035.90","0.010"],["64036.00","0.042"],["64036.10","0.001"],["64036.20","0.612"],["64036.50","0.001"],["64036.70","0.001"],["64036.80","0.002"],["64037.00","0.545"],["64037.10","0.000"],["64037.30","0.002"],["64037.40","0.000"],["64037.90","0.125"],["64038.00","2.468"],["64038.20","0.066"],["64038.30","0.000"],["64038.50","0.035"],["64038.60","0.222"],["64038.70","0.047"],["64038.80","0.064"],["64038.90","0.033"],["64039.00","0.013"],["64039.10","0.025"],["64039.20","0.033"],["64039.80","0.033"],["64039.90","0.000"],["64040.10","0.095"],["64040.20","0.227"],["64040.30","0.020"],["64040.40","0.002"],["64040.50","0.120"],["64040.70","0.015"],["64040.90","0.002"],["64041.10","0.182"],["64041.40","0.002"],["64041.50","0.094"],["64041.60","0.006"],["64041.70","4.492"],["64041.90","0.002"],["64042.00","0.002"],["64042.10","0.002"],["64042.20","0.006"],["64042.30","0.001"],["64042.40","0.017"],["64042.70","0.098"],["64043.00","0.082"],["64043.40","0.005"],["64043.50","0.003"],["64043.70","0.000"],["64043.80","0.002"],["64043.90","0.094"],["64044.00","0.066"],["64044.10","0.014"],["64044.20","0.003"],["64044.30","0.021"],["64044.40","0.336"],["64044.50","2.347"],["64044.60","1.548"],["64044.70","0.000"],["64044.80","0.008"],["64044.90","0.000"],["64045.10","0.003"],["64045.20","0.000"],["64045.30","1.951"],["64045.40","0.258"],["64045.50","0.047"],["64045.60","0.000"],["64045.70","0.002"],["64045.80","0.003"],["64045.90","0.025"],["64046.10","0.003"],["64046.30","0.001"],["64046.50","0.005"],["64046.60","3.087"],["64046.70","2.675"],["64046.80","2.877"],["64046.90","1.821"],["64047.00","0.001"],["64047.10","0.001"],["64047.20","0.001"],["64047.30","0.001"],["64047.40","0.000"],["64047.50","0.000"],["64047.60","2.343"],["64047.70","0.102"],["64047.80","1.327"],["64047.90","0.094"],["64048.00","0.008"],["64048.10","0.001"],["64048.20","0.047"],["64048.30","0.002"],["64048.40","0.010"],["64048.50","0.000"],["64048.60","0.001"],["64048.70","0.000"],["64048.80","0.017"],["64048.90","0.000"],["64049.00","0.000"],["64049.10","0.001"],["64049.20","0.002"],["64049.30","0.000"],["64049.40","0.000"],["64049.50","0.003"],["64049.60","0.000"],["64049.70","0.003"],["64049.90","0.001"],["64050.00","0.005"],["64050.20","0.095"],["64050.30","0.001"],["64050.40","0.000"],["64050.50","1.010"],["64050.60","0.367"],["64050.70","0.001"],["64050.80","0.001"],["64050.90","0.001"],["64051.00","0.021"],["64051.10","0.003"],["64051.20","0.501"],["64051.30","0.550"],["64051.40","0.500"],["64051.50","0.000"],["64051.60","0.003"],["64051.70","0.000"],["64051.80","0.002"],["64051.90","0.000"],["64052.00","0.001"],["64052.20","0.001"],["64052.30","0.000"],["64052.40","0.094"],["64052.50","0.666"],["64052.60","0.002"],["64052.70","0.003"],["64052.80","0.000"],["64052.90","0.000"],["64053.20","0.001"],["64053.30","0.004"],["64053.40","0.001"],["64053.50","0.102"],["64053.60","5.949"],["64053.70","0.000"],["64053.80","0.001"],["64053.90","0.072"],["64054.00","0.001"],["64054.10","0.000"],["64054.30","0.000"],["64054.40","0.000"],["64054.50","0.000"],["64054.60","0.002"],["64054.70","9.980"]],"e":"depthUpdate","ps":"BTCUSDT","pu":11165394936747,"s":"BTCUSDT","st":1,"u":11165394973843}
{"E":1785353523512,"T":1785353523510,"U":11165394973876,"a":[["64054.80","2.107"],["64054.90","0.003"],["64056.40","0.001"],["64056.70","0.000"],["64057.30","0.094"],["64057.50","0.003"],["64057.70","0.002"],["64058.20","0.003"],["64058.30","0.008"],["64058.40","0.002"],["64058.50","0.001"],["64058.70","0.001"],["64058.80","0.002"],["64058.90","0.007"],["64059.00","0.095"],["64059.20","0.024"],["64059.30","0.000"],["64059.80","0.317"],["64059.90","1.199"],["64060.00","0.017"],["64060.10","0.000"],["64060.30","0.001"],["64060.50","0.095"],["64061.00","0.001"],["64061.20","0.038"],["64061.60","0.000"],["64061.80","0.021"],["64061.90","0.154"],["64062.00","1.289"],["64062.10","0.107"],["64062.20","0.008"],["64062.30","0.637"],["64062.50","0.005"],["64062.60","0.002"],["64062.70","0.464"],["64062.80","0.553"],["64063.00","0.000"],["64063.20","0.396"],["64063.40","0.000"],["64063.60","0.093"],["64063.70","0.000"],["64063.90","0.419"],["64064.00","0.006"],["64064.70","0.159"],["64064.80","0.302"],["64065.10","0.001"],["64065.20","0.159"],["64065.30","0.483"],["64065.40","3.760"],["64065.60","0.453"],["64065.70","0.391"],["64066.10","0.388"],["64066.30","0.000"],["64066.50","0.910"],["64066.90","0.027"],["64067.00","0.000"],["64067.10","0.033"],["64067.20","0.342"],["64067.40","0.151"],["64067.50","0.686"],["64067.70","0.284"],["64067.90","0.081"],["64068.10","0.016"],["64068.40","1.063"],["64068.70","0.008"],["64068.80","1.945"],["64069.20","0.096"],["64069.80","0.010"],["64069.90","0.013"],["64070.00","0.165"],["64070.70","0.120"],["64072.00","0.022"],["64072.10","0.429"],["64072.60","0.657"],["64072.80","0.137"],["64073.10","0.684"],["64073.20","0.652"],["64073.90","0.003"],["64074.30","0.176"],["64074.50","0.320"],["64074.60","10.150"],["64075.00","0.875"],["64075.60","0.244"],["64077.20","0.002"],["64077.90","0.002"],["64078.40","0.004"],["64078.90","0.040"],["64079.20","0.358"],["64080.40","0.433"],["64080.50","0.410"],["64082.60","0.846"],["64082.80","0.014"],["64083.60","0.005"],["64084.50","0.062"],["64084.60","0.021"],["64084.80","0.003"],["64084.90","0.001"],["64085.00","0.537"],["64085.50","1.263"],["64085.70","0.000"],["64085.90","0.006"],["64086.10","0.489"],["64086.40","1.166"],["64086.60","0.209"],["64086.80","0.011"],["64087.10","0.003"],["64087.20","0.000"],["64087.40","0.000"],["64088.40","2.349"],["64089.40","0.058"],["64089.60","1.184"],["64090.30","0.002"],["64091.40","0.008"],["64091.60","2.361"],["64091.70","0.002"],["64092.10","0.402"],["64092.30","0.001"],["64092.80","0.100"],["64092.90","0.072"],["64093.30","0.324"],["64093.50","0.003"],["64095.60","2.755"],["64096.30","0.000"],["64096.50","0.015"],["64096.70","3.178"],["64096.80","10.003"],["64097.00","0.002"],["64097.20","5.896"],["64097.30","0.033"],["64097.50","0.175"],["64097.80","0.041"],["64099.70","0.523"],["64100.60","0.003"],["64102.20","0.058"],["64102.90","1.995"],["64103.00","0.004"],["64104.70","0.095"],["64106.00","0.002"],["64108.50","0.001"],["64111.60","0.001"],["64112.30","0.004"],["64118.60","0.004"],["64118.90","0.746"],["64123.20","1.486"],["64123.40","0.169"],["64125.90","0.705"],["64130.20","0.097"],["64130.50","0.148"],["64131.70","0.078"],["64136.00","0.001"],["64143.20","0.003"],["64143.60","1.993"],["64143.70","0.041"],["64150.80","1.264"],["64151.10","0.006"],["64153.80","0.036"],["64160.20","2.070"],["64161.30","0.002"],["64168.00","0.033"],["64178.20","3.903"],["64178.70","0.000"],["64180.70","0.000"],["64182.70","0.000"],["64184.60","0.000"],["64184.70","0.996"],["64186.70","0.002"],["64186.80","0.325"],["64188.70","0.001"],["64190.20","0.001"],["64190.70","0.002"],["64192.70","0.001"],["64193.40","0.039"],["64194.70","0.001"],["64196.70","0.211"],["64196.80","0.000"],["64198.70","0.003"],["64198.80","1.185"],["64200.60","0.005"],["64200.70","4.699"],["64201.90","0.335"],["64202.60","0.003"],["64227.60","0.004"],["64237.20","0.004"],["64266.20","0.118"],["64323.70","0.540"],["64687.20","0.159"],["64695.30","0.139"],["64788.40","0.000"],["64790.50","0.148"],["64790.60","0.000"],["64790.90","0.043"],["64793.70","4.585"],["64857.70","1.526"],["64864.60","2.292"],["64946.80","0.922"],["65341.10","0.003"]],"b":[["1000.00","37.592"],["13554.70","0.126"],["13646.60","0.980"],["13754.70","0.126"],["13846.60","0.700"],["13854.70","0.140"],["13946.60","0.770"],["57649.20","0.002"],["60844.30","0.004"],["61491.30","0.000"],["63156.40","0.916"],["63414.20","0.010"],["63541.70","0.000"],["63554.70","0.000"],["63726.40","1.443"],["63732.30","0.000"],["63733.60","1.232"],["63779.40","0.000"],["63873.20","0.147"],["63877.80","0.000"],["63881.00","0.579"],["63884.10","0.016"],["63900.70","0.456"],["63902.70","0.001"],["63904.70","0.001"],["63906.70","0.000"],["63908.70","0.006"],["63910.70","0.491"],["63912.60","0.000"],["63912.70","0.011"],["63913.60","1.590"],["63923.10","7.411"],["63940.10","2.086"],["63940.30","3.065"],["63951.70","0.013"],["63960.40","1.485"],["63960.60","0.011"],["63962.30","0.016"],["63962.90","0.000"],["63964.40","1.103"],["63969.50","0.000"],["63970.70","4.082"],["63972.00","0.003"],["63987.50","2.219"],["63988.30","0.002"],["63988.50","0.224"],["63994.40","0.020"],["63994.50","0.058"],["63995.40","0.003"],["63995.60","0.211"],["63996.30","0.005"],["64003.10","0.013"],["64008.40","0.011"],["64009.10","0.000"],["64009.60","0.893"],["64009.70","0.318"],["64010.60","0.000"],["64011.00","0.175"],["64013.10","0.007"],["64015.10","0.626"],["64016.60","0.158"],["64016.70","0.001"],["64017.70","0.000"],["64018.40","0.003"],["64018.70","0.000"],["64019.20","1.049"],["64019.30","0.582"],["64019.60","0.652"],["64019.90","2.655"],["64020.00","0.028"],["64020.10","0.316"],["64020.60","0.001"],["64022.30","0.332"],["64022.70","1.727"],["64023.00","0.022"],["64023.20","0.007"],["64023.30","0.246"],["64023.80","0.121"],["64024.00","0.009"],["64024.10","0.229"],["64024.60","0.000"],["64025.30","0.100"],["64025.50","0.076"],["64025.90","2.344"],["64026.00","0.199"],["64026.80","0.021"],["64027.90","0.000"],["64028.70","1.432"],["64028.80","1.663"],["64029.00","1.252"],["64029.10","0.178"],["64029.40","0.317"],["64030.20","0.004"],["64030.60","0.064"],["64031.50","0.002"],["64031.90","0.001"],["64032.00","1.881"],["64032.10","0.568"],["64032.40","0.183"],["64032.50","0.080"],["64034.00","0.329"],["64034.40","0.936"],["64034.80","0.008"],["64035.30","2.347"],["64035.60","0.009"],["64035.70","0.178"],["64036.10","0.004"],["64036.70","0.058"],["64038.10","1.535"],["64039.30","0.001"],["64039.70","0.001"],["64040.40","2.002"],["64040.50","0.120"],["64041.00","0.064"],["64041.10","0.000"],["64041.20","0.374"],["64041.30","0.369"],["64041.70","4.399"],["64041.80","2.621"],["64041.90","0.064"],["64044.40","10.338"],["64044.50","2.345"],["64044.60","2.934"],["64045.40","0.101"],["64045.50","0.339"],["64045.90","0.002"],["64046.00","0.003"],["64046.20","0.093"],["64046.60","3.062"],["64046.70","2.675"],["64046.90","1.821"],["64047.00","0.158"],["64047.30","0.001"],["64047.80","1.328"],["64047.90","0.257"],["64048.00","0.565"],["64048.10","0.279"],["64048.20","0.559"],["64048.30","0.003"],["64048.40","0.011"],["64048.80","0.208"],["64049.00","0.001"],["64049.60","0.001"],["64049.90","0.002"],["64050.00","0.028"],["64050.20","0.096"],["64050.30","0.076"],["64050.60","0.503"],["64050.70","2.343"],["64050.80","0.754"],["64051.10","0.001"],["64051.50","0.001"],["64051.60","0.003"],["64051.80","0.002"],["64051.90","0.003"],["64052.10","0.000"],["64052.20","0.001"],["64052.40","0.000"],["64052.50","0.432"],["64052.70","0.001"],["64053.20","0.235"],["64053.40","0.001"],["64053.50","0.138"],["64053.60","2.858"],["64053.70","2.340"],["64053.80","0.001"],["64053.90","0.000"],["64054.10","0.000"],["64054.20","0.000"],["64054.30","0.000"],["64054.40","0.005"],["64054.60","0.005"],["64054.70","15.834"]],"e":"depthUpdate","ps":"BTCUSDT","pu":11165394973843,"s":"BTCUSDT","st":1,"u":11165394992942}
{"E":1785353523614,"T":1785353523612,"U":11165394993058,"a":[["64054.80","2.109"],["64055.90","0.000"],["64058.30","0.007"],["64058.90","0.029"],["64059.00","0.095"],["64061.00","0.003"],["64061.20","0.116"],["64061.90","0.992"],["64062.00","0.631"],["64062.20","0.008"],["64062.60","0.252"],["64062.70","0.160"],["64062.90","1.915"],["64064.40","0.001"],["64064.80","0.146"],["64065.50","0.611"],["64067.20","0.006"],["64067.40","0.152"],["64067.50","0.550"],["64069.20","0.002"],["64069.80","0.003"],["64070.00","0.166"],["64070.20","0.322"],["64070.30","0.018"],["64070.40","2.164"],["64070.80","0.001"],["64071.20","0.002"],["64072.00","0.022"],["64072.20","0.564"],["64072.30","1.384"],["64072.40","0.337"],["64072.50","0.117"],["64073.10","0.005"],["64073.40","0.314"],["64073.80","0.000"],["64074.00","0.193"],["64074.10","2.333"],["64074.30","0.487"],["64074.50","0.319"],["64075.20","0.528"],["64076.60","0.169"],["64077.90","0.001"],["64078.60","0.159"],["64080.40","1.502"],["64081.80","0.000"],["64082.50","0.003"],["64084.90","0.000"],["64085.00","0.535"],["64085.10","2.396"],["64087.00","1.845"],["64087.30","0.377"],["64088.50","0.016"],["64090.30","0.000"],["64091.10","2.022"],["64091.20","0.008"],["64091.40","0.008"],["64094.10","0.033"],["64094.70","0.019"],["64095.30","0.002"],["64095.90","0.108"],["64096.00","1.065"],["64096.40","0.081"],["64096.70","1.640"],["64096.80","0.005"],["64100.00","2.664"],["64101.60","0.002"],["64101.80","0.009"],["64102.90","2.026"],["64105.00","0.007"],["64106.00","0.002"],["64106.30","1.231"],["64106.40","1.325"],["64108.90","3.290"],["64110.10","12.233"],["64114.90","0.503"],["64131.70","0.000"],["64141.20","5.448"],["64151.90","24.271"],["64161.40","0.000"],["64176.50","0.117"],["64193.30","0.041"],["64193.40","0.000"],["64196.30","0.523"],["64214.80","0.198"],["64215.10","0.750"],["64264.90","0.135"],["64290.50","0.099"],["64310.50","0.177"],["64311.00","0.094"],["64375.10","0.299"],["64572.70","0.309"],["64695.30","0.139"],["64793.70","5.502"],["64800.60","0.917"],["64974.40","0.263"],["65341.10","0.000"],["65342.90","0.003"]],"b":[["13554.70","0.252"],["13646.60","0.854"],["13754.70","0.252"],["13846.60","0.574"],["13854.70","0.252"],["13946.60","0.658"],["57649.20","0.002"],["62574.40","0.002"],["62773.70","0.005"],["63131.00","22.069"],["63414.20","0.010"],["63562.20","0.016"],["63871.90","0.786"],["63879.70","0.000"],["63881.60","0.499"],["63904.50","0.000"],["63943.40","2.500"],["63945.40","1.163"],["63950.50","0.000"],["63970.60","0.004"],["63971.70","22.318"],["63973.30","4.088"],["63983.30","0.000"],["63990.40","0.018"],["63993.60","1.792"],["63999.70","0.004"],["64003.70","0.528"],["64007.10","0.067"],["64007.80","0.005"],["64010.30","0.532"],["64010.90","2.031"],["64011.50","0.002"],["64012.10","0.002"],["64016.50","3.054"],["64019.10","0.122"],["64019.60","0.572"],["64021.50","0.005"],["64021.90","0.001"],["64024.50","0.027"],["64026.10","0.003"],["64026.30","0.442"],["64027.90","0.000"],["64029.50","0.009"],["64030.70","0.564"],["64032.10","0.006"],["64032.30","0.095"],["64033.10","0.324"],["64033.20","0.052"],["64034.30","0.001"],["64035.70","0.021"],["64036.40","0.007"],["64037.50","10.067"],["64037.60","0.244"],["64037.90","0.065"],["64038.00","2.406"],["64038.10","2.720"],["64038.20","0.067"],["64039.40","0.216"],["64040.40","0.002"],["64041.10","0.060"],["64041.60","0.066"],["64041.80","2.622"],["64041.90","0.003"],["64042.90","0.008"],["64043.20","0.314"],["64044.40","0.338"],["64044.60","1.548"],["64045.40","0.102"],["64045.50","0.294"],["64046.00","0.004"],["64046.20","0.000"],["64046.50","0.004"],["64046.60","1.453"],["64046.70","2.685"],["64046.80","2.876"],["64047.70","0.062"],["64047.80","0.001"],["64047.90","0.094"],["64048.00","0.012"],["64048.10","0.279"],["64048.20","0.560"],["64048.30","0.002"],["64048.40","0.003"],["64048.80","0.193"],["64049.90","0.001"],["64050.00","0.006"],["64050.10","0.023"],["64050.80","0.753"],["64051.20","0.503"],["64051.30","0.541"],["64051.50","0.000"],["64052.00","0.002"],["64052.40","0.002"],["64052.50","0.666"],["64053.20","0.001"],["64053.30","0.003"],["64053.50","0.098"],["64053.60","2.903"],["64053.80","0.601"],["64053.90","1.483"],["64054.00","0.001"],["64054.40","0.003"],["64054.50","0.008"],["64054.60","0.006"],["64054.70","10.162"]],"e":"depthUpdate","ps":"BTCUSDT","pu":11165394992942,"s":"BTCUSDT","st":1,"u":11165395003151}
{"E":1785353523716,"T":1785353523715,"U":11165395003269,"a":[["64054.80","0.000"],["64054.90","0.000"],["64055.00","0.000"],["64056.30","0.000"],["64056.40","0.000"],["64056.50","0.000"],["64056.60","0.000"],["64056.80","4.677"],["64056.90","0.003"],["64057.00","0.000"],["64057.10","0.000"],["64057.20","0.000"],["64057.30","0.000"],["64057.50","0.007"],["64057.60","0.004"],["64057.70","0.000"],["64057.80","0.001"],["64058.00","0.001"],["64058.10","0.001"],["64058.30","0.008"],["64058.40","0.001"],["64058.60","0.000"],["64058.70","0.081"],["64058.80","0.100"],["64058.90","0.006"],["64059.00","0.001"],["64059.10","0.096"],["64059.20","0.002"],["64059.40","0.001"],["64059.50","0.000"],["64059.60","0.002"],["64059.70","0.025"],["64059.80","0.003"],["64059.90","0.001"],["64060.00","0.004"],["64060.20","0.387"],["64060.30","0.001"],["64060.50","0.095"],["64060.70","0.002"],["64061.20","0.001"],["64061.40","0.003"],["64061.50","0.001"],["64061.60","0.000"],["64061.70","0.158"],["64061.80","0.001"],["64061.90","0.656"],["64062.00","0.059"],["64062.20","0.001"],["64062.30","0.001"],["64062.40","0.003"],["64062.50","0.002"],["64062.60","0.002"],["64062.70","0.160"],["64062.80","0.702"],["64062.90","1.913"],["64063.00","0.052"],["64063.10","0.001"],["64063.20","0.409"],["64063.60","0.001"],["64063.90","0.000"],["64064.10","0.002"],["64064.20","0.004"],["64064.50","0.108"],["64064.60","0.014"],["64064.70","0.166"],["64064.80","0.165"],["64064.90","1.242"],["64065.00","0.003"],["64065.10","0.001"],["64065.20","0.161"],["64065.30","0.315"],["64065.40","0.000"],["64065.50","0.443"],["64065.60","0.165"],["64066.00","0.006"],["64066.10","0.384"],["64066.40","0.013"],["64066.50","0.906"],["64066.60","0.001"],["64067.50","0.675"],["64067.60","0.931"],["64067.70","0.051"],["64067.80","0.139"],["64067.90","1.121"],["64068.00","0.097"],["64068.20","2.430"],["64068.30","1.122"],["64068.40","0.124"],["64068.50","0.046"],["64068.60","0.083"],["64068.80","0.945"],["64068.90","0.003"],["64069.00","0.000"],["64069.20","0.096"],["64069.40","0.314"],["64069.50","0.172"],["64069.60","0.110"],["64069.70","0.318"],["64070.20","0.315"],["64070.30","0.001"],["64070.70","0.120"],["64070.80","0.067"],["64071.30","0.333"],["64071.90","0.008"],["64072.00","0.102"],["64072.10","0.047"],["64072.20","0.002"],["64072.30","1.501"],["64072.50","0.000"],["64072.60","0.140"],["64072.80","0.074"],["64073.00","0.021"],["64073.10","0.005"],["64073.40","0.313"],["64073.50","2.500"],["64073.60","0.007"],["64073.90","0.565"],["64074.00","0.283"],["64074.30","0.000"],["64074.80","0.081"],["64074.90","0.002"],["64075.20","0.162"],["64075.50","0.002"],["64075.60","0.245"],["64076.00","0.066"],["64076.20","0.361"],["64076.50","0.302"],["64077.00","0.002"],["64077.10","2.492"],["64077.50","1.127"],["64077.70","0.140"],["64077.90","0.001"],["64079.30","0.000"],["64079.50","0.317"],["64079.70","0.292"],["64079.90","0.378"],["64080.40","1.460"],["64080.90","0.005"],["64082.00","0.006"],["64082.40","2.990"],["64082.50","0.724"],["64082.60","0.010"],["64082.70","4.101"],["64083.10","0.000"],["64083.30","0.019"],["64083.40","0.542"],["64083.80","0.005"],["64083.90","0.024"],["64084.00","0.392"],["64084.10","0.001"],["64084.20","0.869"],["64084.30","0.001"],["64084.40","0.000"],["64084.70","0.829"],["64085.40","0.269"],["64085.60","0.002"],["64085.80","0.069"],["64085.90","0.002"],["64086.10","0.524"],["64087.30","0.536"],["64087.70","0.017"],["64087.90","0.004"],["64088.10","0.004"],["64088.60","0.048"],["64088.90","0.007"],["64089.60","1.574"],["64090.80","0.052"],["64090.90","0.904"],["64091.10","0.022"],["64091.40","0.080"],["64091.60","2.344"],["64092.00","0.533"],["64092.80","0.006"],["64092.90","0.002"],["64093.00","0.004"],["64093.30","0.012"],["64093.40","1.148"],["64093.90","0.019"],["64094.30","0.018"],["64095.00","0.000"],["64095.20","0.004"],["64095.40","0.001"],["64095.50","0.180"],["64095.60","2.757"],["64095.80","0.002"],["64096.10","0.160"],["64096.50","0.048"],["64096.70","1.657"],["64096.80","10.003"],["64097.10","0.503"],["64097.90","0.004"],["64098.50","0.105"],["64098.90","0.879"],["64099.10","0.095"],["64099.20","1.962"],["64099.40","0.003"],["64104.80","0.250"],["64105.00","0.003"],["64105.50","0.037"],["64106.80","0.072"],["64107.00","0.011"],["64108.10","0.119"],["64108.60","0.676"],["64112.30","0.000"],["64113.50","0.001"],["64115.80","0.101"],["64116.10","0.007"],["64119.30","0.170"],["64120.10","0.001"],["64120.40","0.534"],["64127.30","0.221"],["64129.30","0.079"],["64129.90","0.000"],["64130.20","0.025"],["64130.30","1.264"],["64130.50","0.154"],["64131.50","0.314"],["64131.70","0.078"],["64140.30","3.685"],["64142.50","0.000"],["64146.80","0.170"],["64149.00","0.001"],["64149.40","0.000"],["64150.80","4.718"],["64151.80","0.503"],["64152.40","0.042"],["64158.20","0.012"],["64161.00","0.127"],["64161.40","0.106"],["64161.60","0.098"],["64162.00","0.083"],["64184.20","0.001"],["64191.90","0.001"],["64198.80","1.185"],["64200.80","0.000"],["64201.90","0.335"],["64202.80","0.001"],["64204.80","3.341"],["64206.80","0.000"],["64208.80","3.237"],["64210.80","0.065"],["64212.80","0.002"],["64214.80","0.198"],["64216.80","0.000"],["64239.20","0.001"],["64241.30","0.005"],["64242.20","0.375"],["64242.40","0.001"],["64263.00","0.133"],["64265.00","0.495"],["64266.20","0.001"],["64325.90","0.552"],["64371.90","0.299"],["64372.70","0.299"],["64373.90","0.300"],["64375.10","0.000"],["64469.40","0.000"],["64471.20","0.208"],["64530.80","0.350"],["64687.20","0.000"],["64695.30","0.139"],["64697.40","0.040"],["64793.70","6.419"],["64803.60","0.000"],["64857.70","3.052"],["64864.50","0.763"],["64864.60","1.529"],["65085.50","0.001"],["65337.90","2.011"],["65342.90","0.000"],["65464.50","0.000"]],"b":[["13554.70","0.294"],["13556.70","0.070"],["13646.60","0.742"],["13754.70","0.294"],["13756.70","0.070"],["13846.60","0.462"],["13854.70","0.308"],["13856.70","0.056"],["13946.60","0.546"],["57649.20","0.000"],["57651.00","0.060"],["61492.50","0.003"],["62775.60","0.797"],["63056.70","0.020"],["63063.50","0.002"],["63063.90","0.146"],["63064.80","0.003"],["63126.00","2.578"],["63230.40","0.270"],["63414.20","0.010"],["63416.10","0.002"],["63537.10","0.002"],["63544.20","0.001"],["63556.70","0.000"],["63726.40","3.793"],["63726.90","0.782"],["63728.20","0.001"],["63736.20","0.088"],["63736.40","0.001"],["63777.50","0.002"],["63778.90","0.090"],["63781.00","0.003"],["63799.40","0.002"],["63812.20","0.000"],["63812.40","0.001"],["63825.20","0.001"],["63856.30","0.000"],["63864.50","0.001"],["63900.30","3.308"],["63904.90","0.000"],["63908.00","0.500"],["63918.50","0.495"],["63921.40","0.004"],["63928.60","0.369"],["63933.00","0.022"],["63940.40","0.031"],["63953.10","0.000"],["63954.00","0.493"],["63957.20","2.076"],["63958.40","0.002"],["63961.00","0.000"],["63966.60","0.568"],["63970.20","0.064"],["63970.40","0.061"],["63971.20","0.077"],["63971.70","0.000"],["63973.30","0.936"],["63973.50","0.148"],["63974.00","0.000"],["63974.80","0.002"],["63978.30","0.000"],["63980.30","0.001"],["63980.60","4.074"],["63982.70","22.318"],["63984.40","0.000"],["63986.40","0.059"],["63990.40","0.003"],["63991.40","0.013"],["63992.60","0.002"],["63994.70","0.002"],["63995.60","0.001"],["63996.30","0.001"],["63996.80","0.101"],["63997.10","0.000"],["63999.10","0.009"],["63999.40","0.130"],["63999.70","0.000"],["64000.30","0.656"],["64001.80","0.001"],["64002.20","0.001"],["64002.70","2.409"],["64002.80","0.014"],["64002.90","0.008"],["64003.00","0.025"],["64005.50","0.285"],["64006.80","0.011"],["64007.10","0.065"],["64007.90","1.250"],["64009.00","0.003"],["64009.20","0.010"],["64010.10","0.322"],["64010.30","0.517"],["64010.70","0.195"],["64011.50","0.227"],["64012.70","0.001"],["64013.10","0.002"],["64013.30","0.002"],["64013.50","0.134"],["64014.00","0.001"],["64014.40","0.047"],["64014.60","1.268"],["64018.10","0.000"],["64018.30","0.001"],["64019.30","0.581"],["64019.70","0.001"],["64019.80","0.003"],["64020.00","0.015"],["64020.30","0.200"],["64022.70","0.594"],["64023.00","0.001"],["64023.20","0.285"],["64023.50","0.001"],["64023.80","0.001"],["64024.10","0.109"],["64024.30","0.120"],["64024.70","0.003"],["64024.80","0.372"],["64026.00","0.042"],["64026.60","0.141"],["64027.40","0.010"],["64028.80","1.660"],["64029.10","0.136"],["64029.30","0.004"],["64029.40","0.000"],["64029.60","0.002"],["64029.70","0.000"],["64030.00","0.223"],["64030.10","0.004"],["64030.30","0.000"],["64030.60","0.151"],["64030.70","0.564"],["64030.80","0.004"],["64030.90","0.312"],["64031.10","0.044"],["64031.80","0.041"],["64031.90","0.001"],["64032.30","0.095"],["64032.40","0.026"],["64032.70","0.017"],["64033.10","0.322"],["64033.20","0.072"],["64033.70","0.000"],["64034.20","0.940"],["64034.30","0.936"],["64034.40","0.001"],["64034.90","0.015"],["64035.10","0.895"],["64035.20","2.335"],["64035.30","2.349"],["64035.50","0.001"],["64035.60","0.007"],["64035.70","0.003"],["64036.70","0.057"],["64037.20","0.026"],["64037.30","0.282"],["64037.50","0.065"],["64037.60","0.061"],["64037.80","0.120"],["64038.00","2.408"],["64038.10","1.475"],["64038.20","0.066"],["64038.40","2.068"],["64038.50","0.098"],["64038.90","0.001"],["64039.50","0.001"],["64039.80","0.001"],["64040.10","0.001"],["64040.30","0.000"],["64040.80","0.013"],["64041.30","0.676"],["64041.60","0.068"],["64041.80","2.622"],["64041.90","0.659"],["64042.20","0.006"],["64042.30","0.021"],["64042.40","0.017"],["64042.50","0.000"],["64042.70","0.097"],["64042.90","0.007"],["64043.10","0.001"],["64043.40","0.005"],["64043.60","0.067"],["64043.70","0.881"],["64043.80","0.062"],["64043.90","0.174"],["64044.00","0.053"],["64044.10","0.074"],["64044.30","0.000"],["64044.70","0.000"],["64045.00","0.035"],["64045.10","0.002"],["64045.40","0.166"],["64045.60","0.032"],["64046.00","0.036"],["64046.60","1.452"],["64046.70","0.183"],["64046.80","2.815"],["64046.90","0.546"],["64047.00","0.002"],["64047.10","0.001"],["64047.40","0.014"],["64047.70","1.805"],["64047.80","0.002"],["64047.90","0.115"],["64048.10","0.001"],["64048.20","0.282"],["64048.30","0.001"],["64048.70","0.022"],["64048.80","0.002"],["64048.90","0.001"],["64049.20","0.001"],["64049.30","0.003"],["64049.70","0.004"],["64049.80","0.001"],["64050.10","0.000"],["64050.20","0.389"],["64050.30","0.003"],["64050.60","0.503"],["64050.70","2.437"],["64050.80","0.944"],["64050.90","0.001"],["64051.00","0.001"],["64051.20","0.003"],["64051.30","0.495"],["64051.40","0.000"],["64051.50","0.001"],["64051.70","0.094"],["64051.80","0.017"],["64052.00","0.315"],["64052.20","0.002"],["64052.30","0.122"],["64052.40","0.001"],["64052.50","0.000"],["64052.60","0.003"],["64052.70","0.001"],["64052.90","0.000"],["64053.00","0.000"],["64053.10","0.001"],["64053.20","0.001"],["64053.30","0.001"],["64053.40","0.095"],["64053.60","2.549"],["64053.80","0.590"],["64053.90","2.289"],["64054.00","0.186"],["64054.20","0.094"],["64054.40","0.003"],["64054.50","0.460"],["64054.60","0.003"],["64054.70","1.025"],["64054.80","2.513"],["64054.90","0.000"],["64055.00","0.002"],["64055.10","0.001"],["64055.20","0.001"],["64055.30","0.234"],["64055.40","0.001"],["64055.50","0.003"],["64055.70","0.000"],["64055.90","0.001"],["64056.00","0.000"],["64056.20","0.000"],["64056.30","0.002"],["64056.40","0.005"],["64056.50","0.000"],["64056.60","0.081"],["64056.70","11.603"]],"e":"depthUpdate","ps":"BTCUSDT","pu":11165395003151,"s":"BTCUSDT","st":1,"u":11165395036547}
{"E":1785353523818,"T":1785353523817,"U":11165395036770,"a":[["64056.80","0.933"],["64056.90","0.001"],["64057.30","0.001"],["64057.50","0.005"],["64058.70","0.000"],["64058.80","0.100"],["64059.10","0.002"],["64059.20","0.002"],["64059.50","0.000"],["64059.70","0.002"],["64060.20","0.409"],["64060.40","0.001"],["64060.50","0.001"],["64060.70","0.096"],["64060.80","0.007"],["64061.00","0.003"],["64061.90","0.144"],["64062.00","0.153"],["64062.10","0.013"],["64062.60","0.002"],["64062.80","0.000"],["64062.90","0.002"],["64063.00","0.050"],["64063.20","0.327"],["64063.50","0.002"],["64064.40","0.366"],["64064.50","0.538"],["64064.60","0.716"],["64064.80","0.338"],["64064.90","0.828"],["64065.00","0.005"],["64065.40","0.271"],["64065.50","0.441"],["64066.00","0.005"],["64066.40","0.013"],["64066.90","0.027"],["64067.00","0.238"],["64067.10","0.002"],["64067.50","0.707"],["64067.60","1.252"],["64067.80","0.202"],["64067.90","0.121"],["64068.00","0.098"],["64068.10","2.356"],["64068.20","0.090"],["64068.30","1.124"],["64068.60","0.340"],["64068.70","0.008"],["64068.90","0.102"],["64069.60","0.436"],["64070.30","0.001"],["64070.40","2.258"],["64070.80","0.001"],["64071.30","0.041"],["64071.50","0.001"],["64071.90","0.001"],["64072.00","0.022"],["64072.10","0.078"],["64072.20","0.002"],["64072.30","1.384"],["64072.40","0.001"],["64072.60","0.020"],["64072.90","0.081"],["64073.30","0.008"],["64073.40","0.313"],["64073.50","3.500"],["64073.90","0.565"],["64074.00","0.193"],["64074.50","0.533"],["64074.80","0.001"],["64075.00","1.211"],["64075.60","0.325"],["64076.30","2.682"],["64076.50","0.368"],["64077.30","0.010"],["64078.50","1.183"],["64080.90","0.001"],["64081.10","0.094"],["64081.30","0.293"],["64082.00","0.004"],["64082.10","0.003"],["64082.20","0.063"],["64083.60","0.055"],["64084.00","0.416"],["64084.10","0.040"],["64084.20","0.798"],["64084.40","0.012"],["64084.50","0.048"],["64084.70","0.821"],["64085.20","0.015"],["64085.30","0.074"],["64086.50","0.016"],["64087.80","0.539"],["64088.50","0.001"],["64089.50","0.063"],["64090.50","0.015"],["64090.80","0.002"],["64091.40","0.008"],["64092.00","0.529"],["64093.70","0.008"],["64094.30","0.014"],["64094.50","0.004"],["64094.60","0.050"],["64095.50","0.059"],["64095.60","2.755"],["64096.00","1.065"],["64096.60","0.073"],["64096.70","2.977"],["64096.80","0.005"],["64097.20","6.016"],["64097.40","0.003"],["64098.10","10.003"],["64098.90","0.759"],["64099.70","0.524"],["64100.30","0.287"],["64100.70","0.002"],["64101.00","0.001"],["64101.50","0.375"],["64101.80","0.001"],["64102.70","0.002"],["64102.80","1.486"],["64102.90","0.511"],["64104.90","0.048"],["64108.50","0.001"],["64108.60","0.616"],["64113.10","0.618"],["64114.20","0.767"],["64114.50","0.003"],["64115.10","0.163"],["64118.40","1.172"],["64120.40","0.509"],["64120.50","0.000"],["64123.10","1.511"],["64123.20","0.017"],["64124.10","0.025"],["64125.00","0.734"],["64127.30","0.011"],["64128.70","0.000"],["64129.30","0.001"],["64130.20","0.097"],["64130.30","1.249"],["64130.50","0.076"],["64131.70","0.000"],["64140.00","0.071"],["64140.20","0.008"],["64143.50","1.486"],["64143.60","0.509"],["64144.30","2.336"],["64145.30","0.000"],["64146.10","0.123"],["64150.20","0.000"],["64150.80","1.256"],["64151.40","0.518"],["64151.90","0.000"],["64155.50","0.014"],["64162.90","0.100"],["64165.70","0.588"],["64167.50","3.523"],["64190.10","6.535"],["64203.10","0.000"],["64204.80","3.341"],["64206.80","0.000"],["64208.80","3.237"],["64209.40","0.006"],["64210.80","0.065"],["64212.80","0.002"],["64214.80","0.304"],["64216.80","0.000"],["64242.40","0.000"],["64261.80","0.136"],["64263.00","0.016"],["64265.00","0.495"],["64295.10","0.099"],["64313.00","0.505"],["64471.20","0.002"],["64482.20","0.000"],["64530.80","0.240"],["64697.40","0.042"],["64791.40","0.001"],["64857.50","0.345"],["64858.20","3.061"],["64864.60","0.766"],["64867.70","1.081"],["64960.00","1.131"]],"b":[["1000.00","37.592"],["13556.70","0.196"],["13646.60","0.616"],["13656.70","0.084"],["13756.70","0.028"],["13846.60","0.420"],["13856.70","0.182"],["13946.60","0.420"],["51237.00","0.000"],["57651.00","0.060"],["61492.50","0.000"],["62987.30","0.006"],["63301.70","0.003"],["63346.40","0.019"],["63416.10","0.000"],["63726.40","3.783"],["63733.20","0.095"],["63887.30","0.009"],["63920.90","6.052"],["63923.10","9.306"],["63928.30","0.002"],["63928.40","0.066"],["63928.50","0.012"],["63940.00","25.330"],["63940.10","0.600"],["63943.40","6.009"],["63959.40","0.514"],["63968.10","0.032"],["63974.50","0.001"],["63977.30","0.497"],["63979.80","0.320"],["63980.60","0.970"],["63980.90","0.002"],["63982.70","0.000"],["63983.60","2.714"],["63985.70","10.152"],["63986.30","0.686"],["63988.50","0.201"],["63990.50","0.517"],["63992.30","0.065"],["63992.90","0.042"],["63993.10","1.832"],["63994.50","0.031"],["63995.20","0.001"],["63997.70","0.061"],["63999.00","1.116"],["63999.10","0.036"],["63999.40","0.000"],["64000.30","0.693"],["64001.50","0.004"],["64003.20","3.943"],["64004.00","0.002"],["64004.30","0.474"],["64005.50","0.007"],["64008.80","0.004"],["64011.50","0.002"],["64012.10","0.002"],["64012.80","1.529"],["64013.20","0.060"],["64013.50","0.149"],["64014.60","1.265"],["64014.90","0.006"],["64015.00","0.568"],["64016.60","0.158"],["64017.40","0.000"],["64017.80","0.499"],["64019.30","0.553"],["64019.40","0.008"],["64019.50","0.000"],["64019.60","0.576"],["64019.70","0.001"],["64020.20","0.049"],["64020.60","0.000"],["64022.10","0.946"],["64022.30","0.242"],["64023.20","0.007"],["64023.30","0.245"],["64023.70","2.259"],["64024.20","0.001"],["64024.30","0.000"],["64025.50","0.006"],["64026.80","0.998"],["64027.10","0.060"],["64027.40","0.014"],["64027.50","0.007"],["64027.60","0.257"],["64027.70","0.002"],["64027.80","0.003"],["64027.90","0.002"],["64028.00","0.044"],["64028.90","0.527"],["64029.30","0.004"],["64029.50","0.002"],["64030.00","0.313"],["64031.70","0.122"],["64032.50","0.087"],["64032.60","0.076"],["64034.00","0.305"],["64034.50","0.119"],["64035.20","1.573"],["64035.40","0.282"],["64036.40","0.056"],["64037.00","0.314"],["64037.60","0.001"],["64037.70","0.132"],["64037.80","0.000"],["64037.90","0.005"],["64038.20","0.006"],["64038.40","0.008"],["64038.50","0.004"],["64038.60","0.007"],["64038.70","2.047"],["64039.20","0.001"],["64039.90","0.000"],["64040.10","0.063"],["64040.20","0.232"],["64041.10","0.095"],["64041.30","0.580"],["64041.50","0.000"],["64041.80","2.853"],["64041.90","0.658"],["64042.30","0.001"],["64042.50","10.000"],["64043.00","0.084"],["64043.10","0.002"],["64043.40","0.220"],["64043.70","0.941"],["64043.80","0.182"],["64043.90","0.235"],["64044.00","0.056"],["64044.10","0.134"],["64044.30","0.060"],["64044.40","0.336"],["64044.60","1.580"],["64044.70","0.000"],["64045.00","0.261"],["64045.30","1.983"],["64045.40","0.165"],["64045.60","0.032"],["64046.00","0.034"],["64046.60","1.284"],["64046.70","0.172"],["64047.00","0.002"],["64047.40","0.015"],["64047.80","0.299"],["64047.90","0.115"],["64048.70","0.000"],["64049.90","0.001"],["64050.00","0.008"],["64050.20","0.391"],["64050.50","0.002"],["64050.80","0.742"],["64050.90","0.001"],["64052.80","0.001"],["64052.90","0.094"],["64053.20","0.023"],["64053.40","0.384"],["64053.50","0.051"],["64053.60","2.549"],["64053.80","0.572"],["64053.90","2.289"],["64054.00","0.166"],["64054.10","0.063"],["64054.20","0.094"],["64054.30","0.000"],["64054.40","0.000"],["64054.60","0.003"],["64054.70","0.938"],["64054.80","2.514"],["64054.90","1.645"],["64055.00","0.002"],["64055.30","0.000"],["64055.40","0.001"],["64055.50","0.000"],["64055.80","0.000"],["64055.90","0.001"],["64056.00","0.000"],["64056.40","0.234"],["64056.50","0.003"],["64056.60","0.005"],["64056.70","12.371"]],"e":"depthUpdate","ps":"BTCUSDT","pu":11165395036547,"s":"BTCUSDT","st":1,"u":11165395087753}
{"E":1785353523920,"T":1785353523918,"U":11165395088150,"a":[["64056.80","2.920"],["64056.90","0.002"],["64057.70","0.000"],["64058.70","0.000"],["64059.00","0.095"],["64059.20","0.002"],["64059.50","0.000"],["64059.70","0.001"],["64059.80","0.002"],["64060.10","0.001"],["64060.40","0.095"],["64060.70","0.002"],["64060.80","0.007"],["64063.10","0.001"],["64063.20","0.327"],["64064.10","0.074"],["64064.20","0.927"],["64064.30","0.793"],["64064.40","1.309"],["64064.50","0.233"],["64064.80","0.185"],["64065.80","1.556"],["64067.50","0.004"],["64068.00","0.099"],["64068.20","0.091"],["64068.30","0.189"],["64068.80","0.609"],["64069.00","0.080"],["64069.20","0.097"],["64069.30","0.264"],["64069.40","0.482"],["64069.50","1.172"],["64069.60","0.436"],["64070.00","0.165"],["64070.30","0.000"],["64070.40","2.164"],["64070.80","0.000"],["64072.00","0.002"],["64072.10","0.078"],["64072.20","0.002"],["64072.80","0.074"],["64073.30","0.008"],["64073.50","2.500"],["64073.90","0.901"],["64074.40","1.718"],["64074.50","0.453"],["64075.00","0.838"],["64075.20","0.002"],["64077.30","0.170"],["64080.00","2.203"],["64080.80","0.004"],["64083.80","0.008"],["64084.00","0.421"],["64086.40","2.612"],["64087.40","0.000"],["64089.20","0.085"],["64090.00","0.183"],["64093.40","1.148"],["64095.00","2.000"],["64095.70","0.073"],["64096.60","0.001"],["64096.70","1.659"],["64096.80","0.003"],["64097.20","5.894"],["64098.10","0.005"],["64101.50","0.532"],["64108.10","0.094"],["64108.50","0.001"],["64119.30","0.002"],["64130.20","0.025"],["64130.50","0.076"],["64132.00","4.583"],["64145.80","0.197"],["64147.60","24.324"],["64159.70","0.000"],["64161.00","0.034"],["64162.90","0.001"],["64192.80","0.000"],["64193.30","0.002"],["64193.60","0.042"],["64194.80","0.000"],["64196.80","0.000"],["64198.80","1.185"],["64200.80","0.000"],["64201.90","0.335"],["64202.80","0.001"],["64204.80","3.341"],["64206.80","0.000"],["64208.80","3.237"],["64210.80","0.065"],["64212.80","0.002"],["64214.70","0.198"],["64214.80","0.002"],["64222.20","10.105"],["64265.00","0.495"],["64543.60","0.096"],["64697.40","0.040"],["64794.10","0.936"],["64800.60","0.000"],["64858.20","4.587"],["64864.50","0.000"],["64864.60","0.003"],["65058.50","0.307"],["65200.50","0.765"]],"b":[["13556.70","0.308"],["13646.60","0.504"],["13656.70","0.196"],["13754.70","0.210"],["13756.70","0.000"],["13856.70","0.308"],["13946.60","0.294"],["57651.00","0.060"],["61494.40","0.003"],["63416.10","0.000"],["63863.80","0.002"],["63890.30","10.029"],["63895.80","0.076"],["63920.90","6.028"],["63923.20","0.043"],["63979.00","0.001"],["63982.70","22.318"],["63983.60","5.900"],["63985.50","0.496"],["63992.70","0.026"],["63992.90","0.017"],["64002.10","0.092"],["64005.60","0.089"],["64006.40","1.138"],["64012.00","0.072"],["64012.70","0.061"],["64015.10","0.653"],["64016.60","0.436"],["64017.50","0.001"],["64017.60","0.105"],["64020.30","0.202"],["64023.40","0.627"],["64024.20","0.121"],["64026.60","0.141"],["64029.30","0.282"],["64030.00","0.223"],["64031.60","0.936"],["64031.70","0.634"],["64031.90","10.001"],["64032.00","3.465"],["64032.30","0.252"],["64033.00","0.313"],["64034.30","0.001"],["64035.40","0.004"],["64036.70","2.057"],["64037.50","0.005"],["64038.20","0.225"],["64038.40","0.008"],["64038.70","0.047"],["64039.40","0.059"],["64040.10","0.001"],["64040.30","0.094"],["64041.30","0.369"],["64041.50","0.094"],["64041.70","4.397"],["64041.90","0.658"],["64042.50","0.002"],["64042.60","0.001"],["64043.00","0.082"],["64043.10","0.001"],["64043.30","0.541"],["64043.90","0.235"],["64044.00","0.059"],["64044.60","1.582"],["64044.70","0.001"],["64045.40","0.166"],["64047.00","0.002"],["64047.70","1.806"],["64047.80","0.021"],["64047.90","0.115"],["64050.00","0.006"],["64051.30","0.589"],["64051.60","0.026"],["64051.70","0.000"],["64052.00","0.002"],["64052.20","0.002"],["64052.60","0.096"],["64052.90","0.000"],["64053.00","1.008"],["64053.20","0.001"],["64053.50","0.051"],["64053.60","2.504"],["64053.80","0.571"],["64053.90","1.329"],["64054.00","1.633"],["64054.10","0.063"],["64054.20","0.000"],["64054.60","0.004"],["64054.70","1.157"],["64054.90","0.637"],["64055.50","0.003"],["64055.70","0.000"],["64056.00","0.003"],["64056.30","0.009"],["64056.40","0.000"],["64056.70","11.231"]],"e":"depthUpdate","ps":"BTCUSDT","pu":11165395087753,"s":"BTCUSDT","st":1,"u":11165395113642}
{"E":1785353524022,"T":1785353524021,"U":11165395114098,"a":[["64056.80","1.225"],["64056.90","0.001"],["64058.10","0.001"],["64058.30","0.008"],["64058.90","0.006"],["64059.00","0.001"],["64059.20","0.002"],["64059.50","0.000"],["64059.60","0.002"],["64060.40","0.001"],["64060.80","0.101"],["64061.40","0.002"],["64062.00","0.099"],["64062.60","0.056"],["64063.20","0.444"],["64064.10","0.002"],["64064.20","0.129"],["64064.30","1.798"],["64064.40","0.530"],["64064.50","0.108"],["64064.90","0.000"],["64065.70","0.391"],["64065.80","0.307"],["64066.60","0.001"],["64067.50","0.612"],["64068.00","2.985"],["64068.10","0.016"],["64068.50","0.047"],["64068.60","1.275"],["64068.80","0.001"],["64069.00","0.168"],["64069.20","0.096"],["64069.30","0.264"],["64069.50","0.172"],["64069.60","0.604"],["64069.80","0.005"],["64070.20","0.315"],["64070.40","2.164"],["64070.80","2.340"],["64070.90","0.001"],["64071.20","0.002"],["64071.30","0.001"],["64071.50","0.001"],["64071.90","1.001"],["64072.80","0.016"],["64073.00","0.021"],["64074.40","1.758"],["64074.50","0.533"],["64078.70","0.059"],["64086.40","1.166"],["64086.80","0.007"],["64093.40","1.592"],["64094.30","0.074"],["64094.40","4.343"],["64095.00","0.000"],["64095.50","0.063"],["64096.60","0.073"],["64096.70","1.659"],["64097.20","5.894"],["64098.10","0.003"],["64098.90","0.761"],["64099.60","1.116"],["64101.50","0.472"],["64104.30","0.028"],["64106.80","0.002"],["64108.50","0.073"],["64117.00","0.090"],["64120.50","0.000"],["64124.10","0.000"],["64128.20","0.000"],["64130.20","0.025"],["64130.50","0.076"],["64147.40","4.829"],["64151.20","0.169"],["64152.60","0.002"],["64159.20","0.177"],["64160.30","2.996"],["64161.60","0.008"],["64193.60","0.003"],["64193.70","0.079"],["64220.90","2.006"],["64265.00","0.378"],["64307.30","0.263"],["64307.40","0.000"],["64371.90","0.000"],["64372.70","0.000"],["64373.90","0.300"],["64374.90","0.605"],["64375.00","0.013"],["64377.10","2.309"],["64543.60","0.000"],["64697.40","0.042"],["64794.10","2.770"],["64797.50","3.668"],["64858.20","6.113"],["64861.60","1.984"],["64921.60","0.549"],["65133.00","0.103"],["65370.00","1.959"]],"b":[["1000.00","37.592"],["13556.70","0.434"],["13646.60","0.378"],["13656.70","0.322"],["13754.70","0.084"],["13856.70","0.420"],["13946.60","0.182"],["51245.40","0.000"],["57651.00","0.060"],["61494.40","0.000"],["63249.80","0.009"],["63416.10","0.000"],["63703.50","0.006"],["63705.20","0.318"],["63732.70","0.000"],["63780.90","0.027"],["63890.80","3.099"],["63906.70","0.000"],["63908.70","0.006"],["63910.70","0.491"],["63912.70","0.011"],["63914.70","0.000"],["63916.70","0.001"],["63933.20","0.507"],["63965.20","0.000"],["63982.70","0.000"],["63983.60","2.714"],["63997.20","0.001"],["64000.30","0.693"],["64000.90","0.061"],["64001.00","0.570"],["64016.60","0.158"],["64025.60","1.708"],["64029.30","0.280"],["64030.50","0.007"],["64031.60","0.001"],["64031.90","0.001"],["64032.00","1.881"],["64032.30","0.095"],["64032.50","0.080"],["64032.60","0.006"],["64033.90","0.001"],["64035.80","1.250"],["64036.70","0.000"],["64036.80","0.280"],["64037.60","0.058"],["64037.70","0.012"],["64038.00","2.348"],["64038.20","0.006"],["64038.70","0.047"],["64040.10","0.001"],["64040.30","0.000"],["64041.30","0.369"],["64041.50","0.094"],["64041.70","4.399"],["64041.90","0.720"],["64042.50","0.000"],["64043.00","10.084"],["64044.60","3.429"],["64047.00","0.001"],["64047.70","1.806"],["64047.80","0.022"],["64049.60","0.002"],["64052.30","0.144"],["64052.60","0.002"],["64053.10","0.095"],["64053.80","0.006"],["64054.60","0.098"],["64054.70","0.923"],["64055.00","0.549"],["64055.10","0.021"],["64055.20","0.045"],["64055.30","0.000"],["64055.70","0.000"],["64056.50","0.003"],["64056.70","11.231"]],"e":"depthUpdate","ps":"BTCUSDT","pu":11165395113642,"s":"BTCUSDT","st":1,"u":11165395143344}
{"E":1785353524124,"T":1785353524123,"U":11165395143363,"a":[["64056.80","2.125"],["64056.90","0.002"],["64058.30","0.008"],["64059.50","0.094"],["64059.80","0.025"],["64059.90","0.001"],["64063.20","0.249"],["64064.10","0.227"],["64064.20","0.201"],["64066.40","0.559"],["64066.80","0.255"],["64067.70","0.052"],["64067.80","1.137"],["64067.90","0.122"],["64068.00","2.439"],["64068.30","0.188"],["64068.50","0.046"],["64068.60","0.340"],["64069.60","0.604"],["64070.90","1.001"],["64071.90","0.001"],["64073.60","0.707"],["64096.60","0.001"],["64099.90","0.803"],["64100.40","0.047"],["64104.30","0.027"],["64107.90","0.051"],["64108.10","0.094"],["64108.50","0.001"],["64109.50","0.481"],["64110.70","0.011"],["64117.00","0.065"],["64120.90","0.001"],["64130.50","0.076"],["64159.20","0.009"],["64161.40","0.000"],["64162.00","0.000"],["64193.40","0.039"],["64193.70","0.040"],["64265.00","0.495"],["64697.40","0.042"],["64794.10","3.687"],["64797.50","2.751"],["64815.40","0.000"],["65191.30","1.324"],["65337.90","2.014"],["65348.10","0.016"]],"b":[["1000.00","37.592"],["13556.70","0.546"],["13646.60","0.266"],["13656.70","0.434"],["13753.50","0.028"],["13754.70","0.000"],["13856.70","0.546"],["13946.60","0.056"],["57651.00","0.060"],["62724.00","0.166"],["63246.00","1.189"],["63336.50","0.006"],["63416.10","0.000"],["63733.20","0.085"],["63736.40","0.001"],["63851.30","0.000"],["63864.50","0.118"],["63982.60","0.002"],["63982.70","22.520"],["63983.60","5.930"],["63992.60","0.003"],["64003.30","0.001"],["64016.20","0.060"],["64026.00","0.002"],["64033.70","0.935"],["64034.60","0.000"],["64035.20","1.613"],["64035.80","0.315"],["64036.20","0.669"],["64036.80","0.002"],["64036.90","0.004"],["64037.60","0.001"],["64040.80","0.014"],["64041.90","0.658"],["64042.00","0.064"],["64044.00","0.058"],["64045.20","0.000"],["64046.90","0.547"],["64047.00","0.001"],["64047.70","1.805"],["64047.80","0.021"],["64050.00","0.008"],["64050.10","0.023"],["64050.20","0.391"],["64051.60","0.003"],["64052.30","0.122"],["64052.50","0.094"],["64052.70","0.001"],["64053.10","0.001"],["64053.70","2.434"],["64053.80","0.004"],["64053.90","1.330"],["64054.10","0.064"],["64054.40","0.000"],["64054.60","0.004"],["64054.70","0.920"],["64055.30","0.237"],["64055.50","0.003"],["64056.00","0.000"],["64056.70","11.234"]],"e":"depthUpdate","ps":"BTCUSDT","pu":11165395143344,"s":"BTCUSDT","st":1,"u":11165395167033}
{"E":1785353524226,"T":1785353524225,"U":11165395167125,"a":[["64056.80","0.000"],["64056.90","0.000"],["64057.30","0.000"],["64057.40","0.000"],["64057.50","0.000"],["64057.60","0.000"],["64057.80","0.000"],["64058.00","0.000"],["64058.10","0.000"],["64058.20","0.000"],["64058.30","0.000"],["64058.40","0.000"],["64058.50","0.000"],["64058.80","0.000"],["64058.90","0.000"],["64059.00","0.000"],["64059.10","0.000"],["64059.20","0.000"],["64059.30","0.000"],["64059.40","0.000"],["64059.50","0.000"],["64059.60","4.296"],["64059.70","0.001"],["64059.80","0.000"],["64060.00","0.001"],["64060.10","0.000"],["64060.20","0.000"],["64060.40","0.001"],["64060.50","0.000"],["64060.70","0.000"],["64060.80","0.003"],["64060.90","0.000"],["64061.10","0.000"],["64061.20","0.000"],["64061.30","0.000"],["64061.40","0.001"],["64061.70","0.001"],["64061.90","0.002"],["64062.00","0.003"],["64062.10","0.014"],["64062.20","0.001"],["64062.40","0.003"],["64062.60","0.006"],["64062.70","0.003"],["64063.00","0.000"],["64063.10","0.002"],["64063.20","0.014"],["64063.30","0.003"],["64064.00","0.006"],["64064.10","0.004"],["64064.20","0.001"],["64064.30","0.739"],["64064.40","0.207"],["64064.50","0.002"],["64064.60","0.000"],["64064.70","0.002"],["64064.80","0.003"],["64064.90","0.000"],["64065.00","0.005"],["64065.10","0.001"],["64065.20","0.099"],["64065.30","0.001"],["64065.40","0.001"],["64065.50","0.441"],["64065.60","0.008"],["64065.70","0.003"],["64065.80","0.095"],["64065.90","0.003"],["64066.00","0.005"],["64066.10","0.021"],["64066.20","0.004"],["64066.30","0.000"],["64066.40","0.001"],["64066.70","0.001"],["64066.80","0.005"],["64066.90","0.122"],["64067.00","0.094"],["64067.10","0.096"],["64067.20","0.100"],["64067.30","0.094"],["64067.40","0.152"],["64067.50","0.004"],["64067.60","0.585"],["64067.70","0.052"],["64067.80","0.003"],["64067.90","0.107"],["64068.00","0.018"],["64068.10","0.016"],["64068.20","0.092"],["64068.30","0.008"],["64068.40","0.007"],["64068.50","0.095"],["64068.60","0.137"],["64068.70","0.021"],["64069.10","0.002"],["64069.20","0.002"],["64069.30","0.170"],["64069.40","0.169"],["64069.50","0.298"],["64069.60","0.288"],["64069.70","0.314"],["64069.90","0.852"],["64070.00","0.218"],["64070.20","0.315"],["64070.30","0.546"],["64070.40","1.023"],["64070.60","0.002"],["64070.80","0.000"],["64070.90","0.003"],["64071.10","3.100"],["64071.20","0.003"],["64071.30","0.000"],["64071.50","0.096"],["64071.70","0.001"],["64072.30","0.001"],["64072.40","0.005"],["64072.60","0.003"],["64072.70","0.095"],["64072.80","0.018"],["64072.90","0.001"],["64073.00","0.001"],["64073.10","0.162"],["64073.30","0.003"],["64073.40","0.158"],["64073.50","0.317"],["64073.60","0.007"],["64073.70","1.911"],["64073.90","0.995"],["64074.00","0.161"],["64074.20","0.570"],["64074.30","2.948"],["64074.40","0.155"],["64074.50","0.439"],["64074.60","10.170"],["64074.70","0.005"],["64074.80","0.001"],["64074.90","0.018"],["64075.00","0.002"],["64075.10","0.102"],["64075.40","0.554"],["64075.60","0.183"],["64075.90","0.008"],["64076.00","0.003"],["64076.20","0.237"],["64076.50","0.068"],["64076.60","0.170"],["64077.10","0.002"],["64077.20","0.000"],["64077.40","0.096"],["64077.50","1.102"],["64077.60","0.067"],["64077.90","0.081"],["64078.00","0.118"],["64078.10","3.589"],["64078.40","0.002"],["64078.50","0.527"],["64078.60","0.159"],["64078.70","0.116"],["64078.80","0.314"],["64078.90","0.051"],["64079.20","0.014"],["64079.40","0.014"],["64079.70","0.293"],["64079.80","0.159"],["64079.90","0.690"],["64080.40","1.116"],["64080.50","0.235"],["64080.80","0.340"],["64080.90","0.002"],["64081.10","0.000"],["64081.20","2.348"],["64081.40","0.094"],["64081.60","0.603"],["64082.00","0.083"],["64082.30","0.315"],["64082.40","0.000"],["64082.50","0.547"],["64082.60","0.012"],["64082.70","4.393"],["64082.80","0.013"],["64083.30","0.002"],["64083.40","0.699"],["64083.80","0.005"],["64083.90","0.576"],["64084.50","0.870"],["64084.60","0.657"],["64084.70","0.833"],["64085.10","0.056"],["64085.20","0.001"],["64085.40","0.242"],["64085.50","0.030"],["64085.60","0.610"],["64085.70","0.000"],["64085.80","0.062"],["64085.90","0.002"],["64086.40","0.009"],["64086.60","0.304"],["64086.80","0.007"],["64087.00","0.003"],["64087.10","0.002"],["64087.20","1.043"],["64087.60","0.195"],["64087.70","0.004"],["64087.80","0.514"],["64087.90","0.000"],["64088.20","0.000"],["64088.40","0.009"],["64088.60","0.068"],["64088.70","0.002"],["64088.80","0.008"],["64088.90","2.344"],["64089.10","0.010"],["64089.20","0.086"],["64089.30","0.002"],["64089.40","0.001"],["64089.60","1.137"],["64090.00","0.077"],["64090.40","0.001"],["64090.50","0.016"],["64090.70","0.011"],["64091.20","0.013"],["64091.30","0.066"],["64091.50","0.503"],["64091.60","0.004"],["64091.70","0.029"],["64093.20","0.032"],["64093.70","0.004"],["64093.90","0.002"],["64094.00","2.980"],["64094.30","0.014"],["64094.40","2.343"],["64094.50","0.000"],["64094.60","0.001"],["64094.70","0.001"],["64094.80","0.346"],["64095.10","0.101"],["64095.30","0.614"],["64095.60","2.752"],["64096.00","1.067"],["64096.20","0.016"],["64096.70","1.655"],["64096.80","0.007"],["64097.00","0.074"],["64097.20","5.896"],["64097.30","0.328"],["64097.90","0.025"],["64098.30","0.002"],["64098.50","0.005"],["64098.70","0.004"],["64098.90","0.759"],["64099.10","2.041"],["64099.20","0.016"],["64099.60","1.046"],["64099.70","0.024"],["64100.90","0.002"],["64101.10","0.001"],["64101.50","0.315"],["64102.20","0.056"],["64102.50","0.061"],["64102.90","0.511"],["64103.70","0.065"],["64104.30","0.027"],["64104.50","1.268"],["64105.30","1.060"],["64105.40","2.115"],["64105.50","0.012"],["64106.20","0.269"],["64106.70","0.071"],["64106.80","0.080"],["64107.90","0.026"],["64108.10","0.107"],["64108.20","0.000"],["64108.70","0.003"],["64109.60","10.003"],["64110.80","0.008"],["64111.00","0.105"],["64113.60","2.369"],["64114.30","1.057"],["64114.70","0.001"],["64116.00","0.007"],["64116.10","0.028"],["64116.60","0.090"],["64117.10","0.500"],["64117.40","0.014"],["64117.80","0.014"],["64118.90","0.715"],["64122.90","0.391"],["64124.70","0.024"],["64125.40","0.001"],["64129.30","0.079"],["64130.50","0.076"],["64131.00","0.161"],["64136.50","0.314"],["64136.60","0.000"],["64137.40","0.982"],["64140.00","0.031"],["64140.80","1.345"],["64143.20","0.003"],["64144.50","0.000"],["64146.10","0.003"],["64146.80","0.002"],["64147.40","1.363"],["64147.60","0.000"],["64150.80","4.806"],["64151.00","0.094"],["64151.20","0.001"],["64151.90","24.324"],["64153.90","0.001"],["64154.40","0.120"],["64156.10","0.000"],["64158.20","0.004"],["64158.70","0.000"],["64159.80","1.249"],["64160.60","0.003"],["64161.60","0.616"],["64161.90","0.001"],["64163.80","0.001"],["64164.00","0.040"],["64168.30","1.028"],["64170.50","2.006"],["64176.60","0.000"],["64177.20","0.537"],["64178.90","0.021"],["64191.50","0.879"],["64192.80","0.881"],["64193.40","0.000"],["64193.70","0.079"],["64193.90","2.344"],["64194.20","0.500"],["64194.80","0.881"],["64196.80","0.000"],["64198.80","2.066"],["64199.40","0.523"],["64200.80","0.881"],["64201.90","0.556"],["64202.80","0.001"],["64204.80","3.341"],["64206.80","0.000"],["64208.80","3.237"],["64210.80","0.946"],["64212.80","0.002"],["64214.70","0.436"],["64214.80","0.002"],["64216.80","0.881"],["64218.80","0.881"],["64220.80","0.923"],["64242.20","0.372"],["64242.50","0.003"],["64247.40","0.000"],["64247.50","1.943"],["64265.00","0.495"],["64265.50","0.117"],["64266.00","0.518"],["64266.10","1.943"],["64327.90","0.541"],["64367.00","0.620"],["64371.60","0.074"],["64373.90","0.001"],["64377.10","2.309"],["64377.60","0.402"],["64379.10","0.313"],["64400.70","0.003"],["64543.60","0.096"],["64543.70","0.222"],["64544.10","0.110"],["64545.60","0.207"],["64697.40","0.040"],["64697.60","0.000"],["64699.40","0.119"],["64793.70","2.751"],["64794.10","0.936"],["64795.50","3.678"],["64795.70","4.585"],["64797.50","0.917"],["64857.70","2.289"],["64858.20","2.298"],["64859.60","3.945"],["64859.80","1.528"],["65217.20","4.134"],["65223.80","0.000"],["65689.50","0.049"],["67259.70","0.067"]],"b":[["13556.70","0.616"],["13558.70","0.042"],["13646.60","0.154"],["13656.70","0.490"],["13656.90","0.014"],["13658.70","0.028"],["13659.40","0.014"],["13746.60","0.854"],["13751.30","0.000"],["13753.50","0.000"],["13757.20","0.014"],["13758.70","0.028"],["13759.40","0.014"],["13856.70","0.546"],["13946.60","0.000"],["57651.00","0.058"],["57652.80","0.002"],["60853.80","0.006"],["60853.90","0.003"],["61494.40","0.003"],["62775.60","0.803"],["63051.30","0.015"],["63058.70","0.018"],["63063.50","0.000"],["63147.50","1.066"],["63416.10","0.000"],["63416.60","0.009"],["63418.10","2.389"],["63418.90","0.002"],["63557.20","0.001"],["63603.20","0.001"],["63609.90","0.001"],["63667.30","0.013"],["63671.10","3.136"],["63674.00","0.002"],["63682.80","0.452"],["63784.50","0.540"],["63795.40","0.000"],["63802.10","0.001"],["63852.70","0.001"],["63861.60","0.003"],["63864.50","0.001"],["63866.50","0.121"],["63876.80","0.326"],["63886.50","0.000"],["63892.40","0.000"],["63903.20","0.110"],["63914.10","2.193"],["63914.40","0.499"],["63920.80","14.429"],["63926.00","0.018"],["63927.90","0.000"],["63932.60","1.953"],["63932.80","0.512"],["63933.60","0.500"],["63938.90","0.795"],["63942.30","0.000"],["63945.90","2.497"],["63947.40","0.002"],["63949.50","11.742"],["63950.20","0.004"],["63951.10","0.006"],["63951.30","0.009"],["63953.50","0.000"],["63954.00","0.490"],["63954.20","0.003"],["63955.70","0.000"],["63957.30","0.760"],["63958.80","1.354"],["63960.20","0.187"],["63960.60","0.511"],["63963.10","0.003"],["63968.70","3.150"],["63971.70","0.000"],["63973.30","4.129"],["63975.80","0.001"],["63976.00","0.000"],["63976.10","0.167"],["63977.30","0.000"],["63978.60","0.001"],["63979.80","0.007"],["63982.20","0.000"],["63982.70","0.000"],["63983.60","2.714"],["63985.30","2.340"],["63986.20","0.500"],["63986.70","0.022"],["63987.50","2.188"],["63992.30","0.003"],["63992.90","0.016"],["63993.10","0.004"],["63993.60","0.038"],["63994.50","0.001"],["63994.60","3.083"],["63997.80","0.000"],["63999.00","0.906"],["63999.10","0.032"],["64000.30","0.656"],["64001.20","0.006"],["64001.60","0.000"],["64002.60","0.716"],["64002.70","2.490"],["64002.80","0.001"],["64002.90","0.000"],["64003.00","0.021"],["64004.30","0.000"],["64004.70","0.173"],["64004.90","0.001"],["64005.00","0.105"],["64005.50","1.834"],["64006.00","0.438"],["64006.10","0.000"],["64006.30","0.001"],["64006.50","0.000"],["64006.60","0.026"],["64006.70","0.036"],["64006.90","0.001"],["64007.60","0.073"],["64008.10","0.091"],["64008.60","0.013"],["64010.10","0.317"],["64010.20","0.006"],["64011.00","0.096"],["64011.80","0.539"],["64011.90","0.058"],["64014.20","0.210"],["64014.40","0.046"],["64014.80","0.000"],["64014.90","0.003"],["64015.00","0.531"],["64015.10","0.715"],["64016.60","0.158"],["64016.70","0.063"],["64017.10","0.003"],["64017.60","0.068"],["64017.70","0.000"],["64018.60","0.104"],["64018.80","0.042"],["64019.10","0.140"],["64019.40","0.003"],["64019.60","0.572"],["64019.80","0.000"],["64020.10","0.315"],["64021.00","0.059"],["64021.20","0.004"],["64022.70","0.522"],["64022.90","0.000"],["64023.30","0.244"],["64023.40","0.537"],["64024.20","0.001"],["64024.90","0.014"],["64025.00","0.002"],["64025.10","0.005"],["64025.30","0.080"],["64025.60","1.708"],["64025.70","0.067"],["64026.50","0.014"],["64026.60","0.120"],["64026.70","0.002"],["64027.10","0.060"],["64027.60","0.193"],["64028.80","1.662"],["64029.30","0.002"],["64029.80","0.440"],["64030.10","0.025"],["64030.40","0.315"],["64030.50","0.097"],["64030.80","0.001"],["64031.10","0.000"],["64031.40","0.202"],["64031.70","0.633"],["64031.80","0.026"],["64031.90","0.001"],["64032.00","1.851"],["64032.20","2.407"],["64032.30","0.095"],["64032.40","0.024"],["64032.60","0.012"],["64032.70","0.578"],["64032.80","0.002"],["64033.00","0.547"],["64033.20","0.052"],["64033.40","0.032"],["64033.60","0.005"],["64033.70","0.000"],["64034.00","0.321"],["64034.10","0.001"],["64034.60","0.000"],["64034.90","0.001"],["64035.00","0.002"],["64035.10","0.896"],["64035.40","0.002"],["64035.70","0.000"],["64035.80","0.314"],["64035.90","0.007"],["64036.00","0.542"],["64036.10","0.939"],["64036.20","0.612"],["64036.30","1.251"],["64036.70","0.021"],["64036.90","0.003"],["64037.20","0.005"],["64037.90","0.002"],["64038.00","2.347"],["64038.20","0.006"],["64038.30","0.057"],["64038.90","0.000"],["64039.60","0.002"],["64040.10","0.047"],["64040.20","0.001"],["64040.60","0.007"],["64040.70","0.037"],["64040.80","0.013"],["64041.30","0.370"],["64041.40","0.000"],["64041.50","0.000"],["64041.60","0.068"],["64041.80","2.388"],["64041.90","0.659"],["64042.00","0.064"],["64042.40","0.111"],["64042.70","0.002"],["64042.80","0.538"],["64043.00","0.082"],["64043.10","0.001"],["64043.40","0.005"],["64043.70","0.120"],["64043.80","0.413"],["64043.90","0.061"],["64044.60","2.247"],["64044.70","0.000"],["64044.80","0.005"],["64045.00","0.035"],["64045.10","0.001"],["64045.40","0.300"],["64045.50","0.295"],["64046.10","2.003"],["64046.40","0.029"],["64046.60","1.283"],["64046.70","0.174"],["64046.80","0.315"],["64046.90","0.562"],["64047.00","0.232"],["64047.10","0.000"],["64047.20","0.016"],["64047.30","0.001"],["64047.40","0.095"],["64047.50","0.060"],["64047.60","2.403"],["64047.70","1.140"],["64047.80","0.021"],["64047.90","0.094"],["64048.00","0.006"],["64048.10","0.003"],["64048.20","0.048"],["64048.60","0.226"],["64048.70","0.005"],["64048.80","0.002"],["64049.10","0.000"],["64049.30","0.000"],["64049.50","0.000"],["64049.70","0.003"],["64049.90","10.001"],["64050.10","0.000"],["64050.30","0.002"],["64050.60","0.314"],["64050.70","2.435"],["64050.80","1.905"],["64050.90","0.001"],["64051.00","0.000"],["64051.40","0.021"],["64051.60","0.009"],["64051.90","0.313"],["64052.20","0.003"],["64052.30","0.062"],["64052.80","0.002"],["64052.90","0.001"],["64053.00","0.000"],["64053.10","0.004"],["64053.50","0.050"],["64053.60","2.505"],["64053.70","2.340"],["64053.80","0.002"],["64053.90","1.328"],["64054.00","1.626"],["64054.10","0.076"],["64054.20","0.000"],["64054.30","0.172"],["64054.40","0.001"],["64054.50","0.009"],["64054.60","0.003"],["64054.70","0.871"],["64054.80","2.503"],["64054.90","0.022"],["64055.00","0.002"],["64055.10","0.008"],["64055.30","0.001"],["64055.40","0.504"],["64055.50","0.094"],["64055.60","0.001"],["64055.70","0.000"],["64055.90","0.002"],["64056.00","0.002"],["64056.10","0.001"],["64056.50","0.432"],["64056.60","0.002"],["64056.70","1.174"],["64056.80","4.936"],["64056.90","0.019"],["64057.00","0.002"],["64057.10","0.000"],["64057.20","0.001"],["64057.30","0.001"],["64057.40","0.007"],["64057.50","2.775"],["64057.60","0.315"],["64057.70","0.000"],["64057.80","0.020"],["64057.90","0.000"],["64058.00","0.020"],["64058.10","0.001"],["64058.20","0.011"],["64058.30","8.933"],["64058.40","0.000"],["64058.50","0.338"],["64058.60","0.001"],["64058.70","7.921"],["64058.80","5.600"],["64058.90","3.004"],["64059.00","0.164"],["64059.10","0.040"],["64059.30","0.001"],["64059.40","6.339"],["64059.50","17.872"]],"e":"depthUpdate","ps":"BTCUSDT","pu":11165395167033,"s":"BTCUSDT","st":1,"u":11165395219652}
{"E":1785353524328,"T":1785353524327,"U":11165395219697,"a":[["64059.60","4.346"],["64059.70","0.001"],["64059.80","0.001"],["64060.50","0.000"],["64060.70","0.001"],["64060.80","0.003"],["64061.00","0.001"],["64061.10","0.001"],["64061.30","0.000"],["64061.40","0.001"],["64061.60","0.038"],["64061.70","0.001"],["64061.90","0.002"],["64062.00","0.001"],["64062.20","0.001"],["64062.30","0.001"],["64062.50","0.001"],["64063.10","0.002"],["64063.20","0.108"],["64064.10","0.004"],["64064.20","0.001"],["64064.30","0.336"],["64064.40","0.301"],["64064.80","0.004"],["64065.00","0.005"],["64065.10","0.023"],["64065.20","0.005"],["64065.40","0.024"],["64065.50","0.042"],["64065.60","0.983"],["64065.70","0.315"],["64065.80","0.001"],["64066.10","0.001"],["64066.20","0.390"],["64066.90","0.028"],["64067.00","0.000"],["64067.10","0.002"],["64067.20","0.040"],["64067.30","0.640"],["64067.40","0.152"],["64067.50","0.004"],["64067.60","1.205"],["64068.60","0.703"],["64068.70","0.021"],["64068.80","0.126"],["64068.90","1.037"],["64069.10","0.002"],["64069.20","0.466"],["64069.30","0.483"],["64069.40","0.169"],["64069.50","0.169"],["64069.60","0.727"],["64069.70","0.315"],["64069.80","0.125"],["64069.90","0.014"],["64070.00","0.164"],["64070.30","0.021"],["64070.40","1.632"],["64070.60","0.002"],["64071.00","3.590"],["64071.20","0.002"],["64071.80","1.002"],["64072.00","0.140"],["64072.40","0.002"],["64072.50","0.004"],["64073.60","0.008"],["64073.80","0.000"],["64073.90","0.565"],["64074.00","0.161"],["64074.10","2.333"],["64074.20","0.570"],["64074.40","0.135"],["64074.70","0.002"],["64075.10","0.008"],["64075.50","0.002"],["64076.20","0.479"],["64076.30","2.565"],["64077.20","0.102"],["64077.30","0.010"],["64077.40","0.002"],["64077.50","0.937"],["64077.70","0.001"],["64078.00","0.118"],["64078.20","0.134"],["64078.30","0.022"],["64078.80","0.431"],["64078.90","0.011"],["64079.20","0.014"],["64079.30","0.292"],["64079.40","0.014"],["64079.50","0.317"],["64079.60","0.540"],["64079.70","0.000"],["64079.80","0.159"],["64080.00","1.830"],["64080.60","0.000"],["64080.70","0.162"],["64080.80","0.633"],["64081.20","2.350"],["64081.30","0.001"],["64081.90","0.139"],["64082.10","0.003"],["64082.20","0.063"],["64082.30","0.314"],["64082.40","0.373"],["64082.70","4.101"],["64083.10","0.292"],["64083.20","0.036"],["64083.60","0.050"],["64083.90","1.255"],["64084.40","0.012"],["64085.10","0.096"],["64085.20","0.043"],["64085.40","1.336"],["64086.10","0.489"],["64086.30","0.003"],["64086.50","0.002"],["64086.60","0.297"],["64086.70","0.007"],["64086.80","0.001"],["64086.90","0.426"],["64087.20","1.292"],["64087.70","0.007"],["64088.30","0.031"],["64088.70","0.006"],["64088.80","0.008"],["64089.60","0.747"],["64089.80","0.001"],["64090.50","0.001"],["64090.70","0.015"],["64091.60","0.348"],["64093.10","3.046"],["64093.20","0.032"],["64093.30","0.015"],["64093.40","0.001"],["64094.00","2.980"],["64094.10","10.033"],["64094.30","0.028"],["64094.80","0.002"],["64096.10","0.230"],["64096.50","0.036"],["64096.80","0.054"],["64097.00","0.002"],["64098.10","0.178"],["64099.70","0.002"],["64100.70","0.001"],["64101.30","0.004"],["64101.60","0.092"],["64101.90","0.061"],["64102.00","0.632"],["64102.50","0.062"],["64102.70","1.486"],["64102.80","0.002"],["64102.90","0.487"],["64103.70","0.063"],["64104.50","1.253"],["64104.90","0.017"],["64105.40","0.115"],["64106.70","0.001"],["64106.80","0.002"],["64107.80","0.031"],["64107.90","0.001"],["64108.70","0.003"],["64108.90","3.290"],["64109.60","0.003"],["64110.80","0.000"],["64111.40","0.004"],["64111.80","0.013"],["64114.30","1.031"],["64115.80","0.118"],["64116.00","0.008"],["64116.60","0.000"],["64117.80","0.002"],["64120.70","1.626"],["64123.00","1.484"],["64123.10","0.027"],["64123.40","0.022"],["64125.90","0.658"],["64127.10","0.001"],["64127.20","0.025"],["64128.70","0.004"],["64129.30","0.001"],["64130.10","0.078"],["64131.00","0.083"],["64131.40","0.153"],["64133.60","0.037"],["64135.00","0.047"],["64136.80","0.195"],["64138.00","0.002"],["64140.00","0.060"],["64143.40","1.679"],["64143.50","0.002"],["64145.80","0.001"],["64146.40","0.032"],["64151.90","24.365"],["64159.00","0.028"],["64176.00","1.239"],["64178.20","0.000"],["64185.00","0.123"],["64186.20","1.682"],["64187.60","0.003"],["64188.30","3.904"],["64191.50","0.001"],["64192.80","0.000"],["64193.90","2.469"],["64194.80","0.000"],["64198.80","1.185"],["64200.80","0.000"],["64201.90","0.335"],["64210.80","0.065"],["64214.70","0.198"],["64216.80","0.000"],["64218.80","0.000"],["64220.80","0.070"],["64227.40","0.000"],["64242.00","0.096"],["64245.20","0.022"],["64247.90","3.242"],["64251.80","0.373"],["64272.00","0.463"],["64272.10","0.000"],["64281.80","0.786"],["64284.70","4.857"],["64379.90","3.533"],["64467.70","0.000"],["64506.10","0.001"],["64543.60","0.000"],["64543.70","0.002"],["64544.10","0.000"],["64545.60","0.001"],["64546.50","0.413"],["64559.30","0.412"],["64699.40","0.117"],["64700.20","0.008"],["64793.70","0.000"],["64794.10","0.019"],["64795.50","0.010"],["64795.70","0.000"],["64796.50","15.920"],["64797.50","0.000"],["64857.70","0.000"],["64858.20","0.772"],["64859.60","0.893"],["64859.80","0.002"],["64859.90","0.261"],["64860.50","4.598"],["64860.60","8.453"],["65181.20","1.320"],["65245.10","0.001"],["65348.10","0.013"]],"b":[["1000.00","37.592"],["13559.50","0.126"],["13646.60","0.028"],["13659.50","0.126"],["13746.60","0.728"],["13759.50","0.126"],["13856.70","0.420"],["57652.80","0.000"],["57653.50","0.052"],["61494.40","0.000"],["62778.40","0.006"],["63059.50","0.004"],["63418.10","2.387"],["63418.90","0.000"],["63542.40","0.320"],["63547.00","0.004"],["63557.20","0.000"],["63726.30","0.007"],["63739.20","0.001"],["63870.50","0.505"],["63886.80","0.002"],["63905.50","0.001"],["63907.50","2.340"],["63909.50","0.034"],["63911.50","0.002"],["63913.50","0.000"],["63915.50","0.003"],["63917.50","0.000"],["63919.50","0.010"],["63921.50","0.008"],["63923.10","5.403"],["63923.50","0.538"],["63934.20","4.391"],["63939.90","1.489"],["63940.00","23.844"],["63952.00","2.356"],["63960.30","1.485"],["63960.40","0.000"],["63960.50","0.002"],["63963.30","0.386"],["63972.30","0.027"],["63973.30","0.936"],["63976.20","0.489"],["63976.70","0.030"],["63977.10","0.276"],["63985.10","0.001"],["63985.40","0.011"],["63985.50","0.489"],["63989.00","1.561"],["63989.30","0.313"],["63989.80","1.836"],["63990.20","6.093"],["63990.30","0.341"],["63993.90","0.007"],["63994.50","0.026"],["63995.40","0.002"],["63995.50","0.211"],["63996.10","3.179"],["63997.90","0.509"],["64002.00","0.001"],["64002.10","0.067"],["64005.60","0.102"],["64006.60","0.001"],["64006.70","0.000"],["64007.10","0.001"],["64007.70","0.000"],["64008.30","0.005"],["64010.40","0.000"],["64013.30","0.039"],["64013.40","2.854"],["64013.50","0.213"],["64014.20","0.000"],["64014.60","1.264"],["64015.10","0.653"],["64015.40","0.000"],["64015.60","0.026"],["64015.90","0.406"],["64016.00","0.007"],["64016.30","0.019"],["64016.40","0.625"],["64016.70","0.062"],["64017.30","0.007"],["64017.90","0.028"],["64018.30","0.065"],["64018.90","0.032"],["64019.50","0.040"],["64022.90","0.000"],["64024.80","0.492"],["64024.90","0.002"],["64027.80","0.024"],["64027.90","0.129"],["64028.20","0.004"],["64028.70","1.096"],["64030.10","0.004"],["64030.50","0.007"],["64030.60","0.150"],["64031.40","0.082"],["64032.10","0.006"],["64032.70","0.578"],["64032.90","0.590"],["64033.10","0.322"],["64033.70","0.827"],["64033.90","0.042"],["64034.40","0.002"],["64034.50","0.139"],["64034.60","0.935"],["64034.70","0.012"],["64035.20","2.141"],["64035.70","0.007"],["64035.90","0.019"],["64036.00","10.542"],["64036.10","0.004"],["64036.40","0.213"],["64036.70","0.001"],["64036.80","0.059"],["64037.60","0.001"],["64038.00","2.344"],["64038.10","2.770"],["64038.30","0.000"],["64038.50","0.025"],["64040.30","0.005"],["64040.70","0.016"],["64041.30","0.275"],["64041.70","4.402"],["64042.00","0.221"],["64043.00","0.082"],["64043.50","0.004"],["64043.70","0.060"],["64044.10","0.132"],["64044.20","0.097"],["64045.00","0.003"],["64045.10","0.021"],["64045.40","0.394"],["64045.50","0.295"],["64045.60","0.000"],["64046.00","0.002"],["64046.10","0.003"],["64046.50","0.238"],["64047.40","0.075"],["64047.50","0.060"],["64047.60","2.463"],["64047.80","0.081"],["64047.90","0.154"],["64048.30","0.001"],["64048.40","0.002"],["64048.50","0.000"],["64048.70","0.036"],["64048.80","0.375"],["64049.10","0.053"],["64049.30","0.368"],["64049.70","0.035"],["64049.80","0.001"],["64049.90","0.002"],["64050.20","0.098"],["64050.70","2.437"],["64050.80","0.551"],["64050.90","0.001"],["64051.20","0.006"],["64051.40","0.000"],["64052.10","0.293"],["64052.20","0.003"],["64052.30","0.085"],["64052.90","0.001"],["64053.20","0.002"],["64053.60","0.197"],["64053.90","1.422"],["64054.00","0.813"],["64054.10","0.684"],["64054.30","0.078"],["64054.60","0.316"],["64054.70","0.859"],["64054.80","2.503"],["64054.90","0.000"],["64055.10","0.102"],["64055.20","0.001"],["64055.40","0.191"],["64055.50","0.000"],["64055.60","0.002"],["64055.80","0.020"],["64056.00","0.003"],["64056.20","0.001"],["64056.50","0.000"],["64056.70","1.001"],["64056.80","4.844"],["64056.90","0.096"],["64057.00","0.001"],["64057.20","0.001"],["64057.30","0.433"],["64057.40","0.002"],["64057.50","2.372"],["64057.60","0.779"],["64057.70","0.021"],["64057.80","0.000"],["64057.90","0.234"],["64058.00","0.045"],["64058.10","0.004"],["64058.20","0.002"],["64058.30","0.000"],["64058.50","0.000"],["64058.60","0.000"],["64058.70","0.212"],["64058.80","0.003"],["64058.90","0.002"],["64059.00","0.000"],["64059.10","0.121"],["64059.20","0.002"],["64059.30","0.000"],["64059.40","0.178"],["64059.50","10.577"]],"e":"depthUpdate","ps":"BTCUSDT","pu":11165395219652,"s":"BTCUSDT","st":1,"u":11165395251850}
{"E":1785353524430,"T":1785353524429,"U":11165395251992,"a":[["64059.60","7.571"],["64060.20","0.094"],["64060.30","0.001"],["64061.40","0.091"],["64061.50","0.095"],["64061.60","0.313"],["64062.90","0.096"],["64063.10","0.001"],["64063.20","0.014"],["64063.50","0.049"],["64064.30","0.897"],["64065.40","0.001"],["64065.50","0.015"],["64065.70","0.316"],["64067.10","0.002"],["64067.20","0.006"],["64067.30","0.214"],["64067.50","0.885"],["64067.60","0.881"],["64068.50","0.095"],["64068.60","0.157"],["64068.70","0.889"],["64068.80","0.747"],["64069.00","0.169"],["64069.10","0.002"],["64069.40","0.189"],["64069.50","0.715"],["64069.70","0.314"],["64069.90","0.014"],["64070.30","0.001"],["64070.50","1.681"],["64070.90","0.003"],["64071.00","3.684"],["64071.70","0.017"],["64071.80","0.002"],["64072.20","0.158"],["64072.40","0.018"],["64072.50","0.238"],["64073.10","0.163"],["64073.60","0.007"],["64073.90","0.565"],["64074.90","0.002"],["64075.80","2.001"],["64076.20","0.492"],["64077.20","0.011"],["64078.80","0.775"],["64079.40","0.001"],["64080.00","1.830"],["64080.50","0.001"],["64080.90","0.001"],["64081.20","2.348"],["64081.70","0.551"],["64082.00","0.427"],["64082.30","0.330"],["64084.80","0.017"],["64085.50","0.014"],["64085.80","0.111"],["64086.70","0.007"],["64086.80","0.014"],["64087.80","0.522"],["64088.30","0.031"],["64088.80","0.000"],["64089.60","1.079"],["64090.00","0.064"],["64090.20","0.297"],["64090.40","0.391"],["64090.60","0.376"],["64091.60","0.004"],["64091.80","1.752"],["64092.80","0.007"],["64093.00","0.020"],["64093.10","1.758"],["64093.20","0.000"],["64094.00","2.587"],["64094.10","0.035"],["64094.30","0.014"],["64096.20","0.000"],["64097.30","0.208"],["64102.70","1.490"],["64103.10","0.141"],["64103.70","0.063"],["64104.10","0.025"],["64111.80","0.013"],["64114.30","0.056"],["64116.10","0.003"],["64121.30","0.001"],["64121.60","2.883"],["64122.60","0.015"],["64130.10","0.000"],["64147.20","0.173"],["64165.00","0.081"],["64187.90","0.595"],["64281.80","0.090"],["64284.70","0.000"],["64322.80","0.000"],["64326.40","1.058"],["64700.20","0.008"]],"b":[["1000.00","37.592"],["13559.50","0.056"],["13646.60","0.000"],["13659.50","0.252"],["13746.60","0.602"],["13759.50","0.238"],["13856.70","0.308"],["13959.50","0.098"],["57653.50","0.052"],["61497.10","0.003"],["62938.70","3.702"],["63211.50","0.790"],["63277.90","0.000"],["63418.90","0.002"],["63736.40","0.011"],["63915.10","0.003"],["63949.40","0.000"],["63952.30","0.000"],["63961.10","0.048"],["63968.60","2.871"],["63972.30","0.027"],["63978.30","0.000"],["63980.60","0.970"],["63984.90","22.542"],["63987.20","5.896"],["63988.30","0.000"],["63990.20","2.640"],["63990.30","0.063"],["63994.50","0.001"],["63998.40","1.757"],["63999.60","0.658"],["64001.60","0.025"],["64003.10","0.050"],["64008.30","0.003"],["64016.00","0.006"],["64018.70","10.000"],["64020.00","0.018"],["64022.10","1.016"],["64022.80","2.026"],["64024.40","0.362"],["64024.70","0.001"],["64025.60","1.844"],["64026.10","0.024"],["64027.80","0.003"],["64028.60","0.053"],["64030.00","0.223"],["64032.80","0.022"],["64034.00","0.305"],["64034.50","0.119"],["64036.00","0.542"],["64036.40","0.164"],["64036.80","0.080"],["64038.10","1.477"],["64038.50","0.004"],["64040.70","0.110"],["64040.90","0.002"],["64041.10","0.035"],["64041.20","0.314"],["64041.30","0.215"],["64041.80","2.482"],["64042.00","0.159"],["64043.00","0.176"],["64043.40","0.025"],["64043.80","0.353"],["64044.60","2.215"],["64045.10","0.001"],["64045.30","1.951"],["64045.50","0.452"],["64045.60","0.000"],["64045.90","0.002"],["64046.70","0.004"],["64046.90","0.546"],["64047.40","0.156"],["64047.70","1.200"],["64047.80","0.218"],["64047.90","0.236"],["64048.20","0.108"],["64048.30","0.033"],["64049.10","0.032"],["64050.60","0.001"],["64051.30","0.495"],["64051.40","0.094"],["64051.90","0.000"],["64052.30","0.062"],["64052.50","0.023"],["64053.00","0.023"],["64053.30","0.001"],["64053.40","0.001"],["64053.90","1.328"],["64054.10","0.096"],["64054.60","0.065"],["64054.70","0.306"],["64054.80","2.505"],["64054.90","0.000"],["64055.00","0.002"],["64055.10","0.008"],["64055.20","0.001"],["64055.50","1.008"],["64055.80","0.000"],["64055.90","0.002"],["64056.00","0.004"],["64056.30","0.009"],["64056.50","0.003"],["64056.70","0.130"],["64056.80","0.003"],["64056.90","0.002"],["64057.30","0.433"],["64057.50","0.769"],["64057.60","0.719"],["64057.70","0.001"],["64057.80","0.003"],["64057.90","0.000"],["64058.30","0.003"],["64058.70","0.172"],["64059.40","0.100"],["64059.50","6.036"]],"e":"depthUpdate","ps":"BTCUSDT","pu":11165395251850,"s":"BTCUSDT","st":1,"u":11165395275214}
{"E":1785353524532,"T":1785353524531,"U":11165395275255,"a":[["64059.60","8.384"],["64061.00","0.002"],["64061.50","0.959"],["64062.10","0.014"],["64062.90","0.479"],["64063.50","0.595"],["64063.60","0.876"],["64064.10","0.006"],["64064.20","1.408"],["64064.30","1.393"],["64064.40","0.323"],["64064.70","0.137"],["64065.00","0.059"],["64065.10","0.001"],["64065.20","0.003"],["64065.30","2.344"],["64065.40","0.777"],["64065.50","0.109"],["64065.60","0.983"],["64065.80","0.002"],["64066.10","0.001"],["64066.20","0.387"],["64066.30","0.935"],["64067.20","0.006"],["64067.30","0.297"],["64067.40","0.759"],["64067.50","0.885"],["64067.70","0.051"],["64067.90","0.106"],["64068.00","0.017"],["64068.60","0.084"],["64068.70","0.008"],["64068.80","0.126"],["64068.90","0.102"],["64069.00","0.168"],["64069.10","0.003"],["64069.20","0.395"],["64069.40","0.169"],["64069.50","0.169"],["64069.80","0.222"],["64069.90","0.002"],["64070.00","0.508"],["64070.70","0.120"],["64070.90","0.659"],["64071.00","3.804"],["64071.50","0.096"],["64071.60","0.157"],["64072.00","0.278"],["64072.10","0.234"],["64072.40","0.018"],["64072.50","1.173"],["64072.80","0.076"],["64073.10","0.164"],["64073.60","0.007"],["64074.80","0.001"],["64075.10","0.008"],["64075.70","10.014"],["64075.80","0.001"],["64076.50","0.118"],["64076.80","2.745"],["64077.00","0.001"],["64077.30","0.090"],["64077.80","0.470"],["64077.90","0.083"],["64078.80","0.658"],["64078.90","0.011"],["64079.80","0.316"],["64079.90","0.690"],["64080.10","2.051"],["64081.60","0.523"],["64082.00","0.427"],["64082.50","0.235"],["64083.40","0.542"],["64083.60","0.000"],["64084.10","0.075"],["64084.20","0.798"],["64085.80","0.062"],["64086.80","0.022"],["64086.90","0.391"],["64087.30","0.536"],["64087.60","0.252"],["64087.80","0.514"],["64088.10","0.124"],["64089.00","0.117"],["64089.20","0.085"],["64090.20","0.177"],["64090.60","0.376"],["64091.30","0.009"],["64091.50","0.003"],["64092.60","0.011"],["64093.10","1.601"],["64093.80","0.005"],["64094.00","2.589"],["64094.10","0.033"],["64095.30","0.626"],["64095.60","3.252"],["64096.10","0.158"],["64096.50","0.040"],["64096.80","0.050"],["64097.20","5.900"],["64098.10","0.490"],["64098.70","0.000"],["64099.50","0.005"],["64100.10","0.000"],["64100.30","0.377"],["64101.60","0.002"],["64103.60","0.184"],["64104.10","0.000"],["64108.30","0.012"],["64108.70","0.003"],["64109.80","0.016"],["64110.60","2.176"],["64111.80","0.005"],["64115.20","0.043"],["64116.20","0.923"],["64117.10","0.000"],["64122.00","0.717"],["64123.70","0.032"],["64125.00","0.524"],["64131.40","0.015"],["64134.50","0.526"],["64146.90","0.527"],["64147.20","0.017"],["64155.30","0.529"],["64156.00","0.637"],["64160.20","1.356"],["64162.70","0.000"],["64168.30","0.528"],["64172.50","0.527"],["64175.60","2.342"],["64194.20","0.000"],["64227.80","0.000"],["64261.80","0.001"],["64264.90","0.000"],["64281.80","0.382"],["64284.70","2.147"],["64471.60","0.004"],["64587.80","0.000"],["64635.90","0.031"],["64639.50","0.007"],["64700.20","0.008"],["64736.40","1.223"],["64905.00","0.591"],["64908.60","0.000"],["65284.60","0.307"],["65340.70","2.803"],["65348.70","0.306"],["65661.10","0.076"]],"b":[["13556.70","0.602"],["13558.70","0.000"],["13559.50","0.000"],["13659.50","0.364"],["13746.60","0.490"],["13759.50","0.364"],["13856.70","0.182"],["13959.50","0.210"],["57653.50","0.052"],["61497.10","0.000"],["63347.10","0.000"],["63418.90","0.002"],["63493.30","0.016"],["63607.90","0.000"],["63920.90","6.052"],["63923.20","0.019"],["63943.30","0.002"],["63948.20","0.500"],["63960.60","0.011"],["63960.90","0.008"],["63963.30","0.378"],["63970.30","0.060"],["63973.80","0.501"],["63975.30","0.002"],["63984.90","0.022"],["63986.20","0.000"],["63987.10","22.617"],["63988.70","0.210"],["63990.30","0.204"],["63992.30","0.034"],["63995.50","0.001"],["63996.90","0.000"],["63999.40","0.500"],["64005.00","0.101"],["64005.60","0.164"],["64005.80","0.007"],["64007.00","0.020"],["64007.50","0.982"],["64011.80","0.039"],["64012.30","0.090"],["64015.40","0.070"],["64015.70","11.186"],["64017.10","0.000"],["64017.60","0.191"],["64018.70","0.000"],["64019.20","1.046"],["64019.50","0.040"],["64019.60","0.652"],["64019.80","0.000"],["64020.60","0.000"],["64021.00","0.234"],["64021.10","0.000"],["64021.20","0.000"],["64022.10","0.946"],["64022.30","0.246"],["64022.80","0.026"],["64024.40","0.360"],["64024.80","0.372"],["64024.90","0.002"],["64025.60","1.846"],["64025.80","0.557"],["64026.20","0.050"],["64026.30","0.362"],["64026.70","0.002"],["64026.80","0.021"],["64027.10","0.060"],["64027.90","0.039"],["64028.10","0.563"],["64029.00","1.077"],["64030.70","0.002"],["64031.10","0.935"],["64032.30","0.095"],["64033.20","0.002"],["64033.40","0.032"],["64033.50","0.679"],["64033.80","0.235"],["64034.20","0.007"],["64034.60","0.000"],["64034.80","0.065"],["64036.80","0.023"],["64037.10","0.094"],["64038.30","0.094"],["64038.70","0.127"],["64039.50","0.095"],["64040.50","0.040"],["64041.00","0.004"],["64041.10","0.000"],["64041.90","0.003"],["64042.90","1.256"],["64043.60","0.007"],["64043.70","0.373"],["64043.80","0.689"],["64045.30","0.000"],["64045.60","0.770"],["64046.50","0.004"],["64046.60","1.189"],["64046.90","0.388"],["64047.20","0.110"],["64047.30","0.061"],["64047.50","0.120"],["64047.60","0.183"],["64047.70","1.260"],["64047.80","0.312"],["64047.90","0.122"],["64048.00","2.406"],["64048.10","1.601"],["64048.50","0.094"],["64048.70","1.363"],["64048.80","0.002"],["64048.90","0.001"],["64049.10","0.032"],["64049.30","0.094"],["64049.40","0.000"],["64049.60","0.002"],["64050.20","0.004"],["64050.30","0.002"],["64050.50","0.002"],["64050.60","0.001"],["64050.70","0.003"],["64050.90","2.498"],["64051.40","0.213"],["64051.50","0.001"],["64051.90","0.000"],["64052.10","0.000"],["64052.20","0.005"],["64052.30","0.015"],["64052.40","1.009"],["64052.50","0.000"],["64053.00","0.000"],["64053.40","0.001"],["64053.50","0.050"],["64053.60","0.005"],["64053.70","0.000"],["64053.80","0.000"],["64053.90","0.001"],["64054.00","0.813"],["64054.10","0.033"],["64054.40","0.004"],["64054.60","0.003"],["64054.70","0.096"],["64054.80","0.003"],["64054.90","0.000"],["64055.00","0.002"],["64055.40","0.001"],["64055.50","0.003"],["64055.60","0.002"],["64055.70","0.001"],["64055.80","0.003"],["64056.30","0.002"],["64056.50","0.000"],["64056.70","0.079"],["64057.00","0.001"],["64057.50","0.000"],["64057.60","0.002"],["64057.70","0.000"],["64057.80","0.000"],["64058.00","0.001"],["64058.10","0.001"],["64058.20","0.001"],["64058.30","0.000"],["64058.80","0.001"],["64059.00","0.002"],["64059.10","0.000"],["64059.20","0.000"],["64059.30","0.000"],["64059.40","0.001"],["64059.50","1.666"]],"e":"depthUpdate","ps":"BTCUSDT","pu":11165395275214,"s":"BTCUSDT","st":1,"u":11165395298468}
{"E":1785353524634,"T":1785353524633,"U":11165395298554,"a":[["64059.60","15.941"],["64059.70","0.004"],["64060.10","0.235"],["64060.20","0.430"],["64061.10","0.024"],["64061.30","0.022"],["64061.40","0.014"],["64061.50","0.095"],["64061.90","0.002"],["64062.10","0.017"],["64062.60","0.060"],["64063.40","0.000"],["64063.50","0.049"],["64063.60","0.060"],["64064.10","0.003"],["64064.40","0.301"],["64064.50","0.004"],["64065.00","0.005"],["64065.20","0.548"],["64065.40","0.041"],["64065.50","0.096"],["64065.60","0.102"],["64065.80","0.001"],["64066.20","0.512"],["64067.30","0.376"],["64067.50","0.066"],["64068.00","0.137"],["64068.30","0.125"],["64068.50","0.111"],["64068.80","0.001"],["64069.00","0.188"],["64069.10","0.712"],["64069.50","0.738"],["64069.70","10.314"],["64070.10","0.384"],["64070.30","0.313"],["64070.40","2.346"],["64070.60","0.002"],["64070.90","0.657"],["64071.00","3.687"],["64071.30","0.004"],["64071.70","0.001"],["64071.90","0.036"],["64072.00","0.590"],["64072.10","0.353"],["64072.20","0.326"],["64072.30","0.008"],["64072.80","0.388"],["64073.00","0.014"],["64073.30","0.001"],["64073.50","0.315"],["64073.60","0.709"],["64073.90","0.003"],["64074.10","2.333"],["64074.50","0.319"],["64074.70","0.158"],["64075.40","1.077"],["64075.70","0.014"],["64075.90","0.001"],["64076.20","0.479"],["64076.80","1.389"],["64077.90","0.081"],["64078.20","0.150"],["64079.20","0.014"],["64079.90","0.378"],["64080.10","2.002"],["64080.80","0.297"],["64081.20","2.368"],["64081.30","0.003"],["64082.30","0.002"],["64082.70","4.114"],["64084.10","0.040"],["64086.80","0.009"],["64086.90","0.440"],["64088.60","0.048"],["64089.00","0.047"],["64089.80","0.017"],["64091.00","0.003"],["64091.90","0.525"],["64092.00","0.619"],["64093.00","0.004"],["64096.00","1.065"],["64096.50","0.110"],["64098.10","0.494"],["64100.30","0.287"],["64102.70","1.486"],["64104.50","1.276"],["64107.00","0.007"],["64108.30","0.012"],["64109.80","0.020"],["64111.40","0.160"],["64112.50","0.003"],["64113.60","2.344"],["64118.40","1.636"],["64119.20","0.360"],["64122.00","0.507"],["64156.80","0.720"],["64159.20","0.321"],["64159.30","0.001"],["64159.40","0.671"],["64193.50","0.423"],["64193.70","0.040"],["64205.10","0.031"],["64209.40","0.002"],["64242.50","0.000"],["64243.10","0.825"],["64264.50","0.005"],["64281.80","1.021"],["64284.70","6.428"],["64324.10","3.231"],["64326.20","13.144"],["64400.00","12.033"],["64471.50","0.153"],["64500.00","7.487"],["64700.20","0.008"],["64825.50","0.005"],["64930.70","0.386"],["64937.20","0.544"],["65340.70","2.806"],["65348.10","0.010"]],"b":[["1000.00","37.592"],["13556.70","0.476"],["13659.50","0.490"],["13746.60","0.364"],["13759.50","0.476"],["13856.70","0.070"],["13959.50","0.336"],["57653.50","0.052"],["60859.90","0.006"],["60860.00","0.186"],["62778.40","0.009"],["63136.50","2.051"],["63157.00","0.001"],["63288.00","1.611"],["63418.90","0.004"],["63726.40","3.604"],["63734.20","0.000"],["63739.20","0.180"],["63851.30","0.117"],["63866.50","0.004"],["63870.50","0.388"],["63901.50","4.368"],["63903.50","0.882"],["63905.50","0.882"],["63907.50","3.221"],["63909.50","0.915"],["63911.50","0.883"],["63913.50","0.881"],["63954.20","0.000"],["63954.80","0.003"],["63970.40","0.001"],["63976.10","0.167"],["63977.10","3.603"],["63982.70","0.000"],["63984.70","0.016"],["63987.10","0.097"],["63987.20","3.145"],["63988.70","0.000"],["63992.90","0.001"],["63996.30","0.211"],["64001.80","0.001"],["64007.80","0.001"],["64008.30","0.003"],["64009.00","0.000"],["64011.70","0.003"],["64011.80","0.000"],["64011.90","0.019"],["64012.30","0.000"],["64012.60","1.247"],["64015.10","1.752"],["64015.40","0.000"],["64015.70","0.000"],["64015.80","0.666"],["64016.20","10.060"],["64017.50","0.041"],["64017.90","0.028"],["64019.20","2.438"],["64019.50","0.000"],["64020.10","0.405"],["64021.50","0.005"],["64022.40","0.011"],["64023.70","2.280"],["64023.80","0.071"],["64025.10","0.001"],["64025.30","0.080"],["64025.60","1.866"],["64025.80","0.522"],["64026.10","0.003"],["64027.10","0.060"],["64027.50","0.011"],["64028.10","0.563"],["64028.80","1.254"],["64029.20","4.199"],["64030.40","0.335"],["64030.50","0.000"],["64030.70","0.009"],["64031.50","0.314"],["64032.70","2.968"],["64032.80","0.003"],["64033.10","0.010"],["64033.20","0.094"],["64034.00","0.013"],["64034.40","0.023"],["64034.80","0.008"],["64035.20","1.441"],["64036.00","0.545"],["64036.80","0.002"],["64037.10","0.000"],["64038.00","2.345"],["64038.80","0.104"],["64039.00","0.349"],["64040.50","0.000"],["64040.80","0.305"],["64041.00","0.024"],["64041.10","0.001"],["64041.40","0.312"],["64041.60","0.008"],["64042.60","0.294"],["64043.20","0.002"],["64043.40","0.005"],["64043.80","0.629"],["64043.90","0.001"],["64044.10","0.074"],["64044.30","0.000"],["64044.40","0.000"],["64044.50","2.344"],["64044.70","0.000"],["64045.00","0.024"],["64045.50","0.160"],["64046.20","0.003"],["64046.90","0.482"],["64047.20","0.207"],["64047.40","0.135"],["64047.50","0.180"],["64047.60","0.182"],["64047.70","0.785"],["64047.80","0.278"],["64047.90","0.060"],["64048.00","2.408"],["64048.10","0.884"],["64048.20","0.128"],["64048.50","0.000"],["64048.60","0.320"],["64048.70","0.032"],["64048.80","0.064"],["64049.00","0.001"],["64049.50","0.000"],["64049.60","0.002"],["64049.80","0.191"],["64050.00","0.008"],["64050.10","0.234"],["64050.70","0.001"],["64050.80","0.002"],["64050.90","2.343"],["64051.00","2.076"],["64051.20","0.005"],["64051.30","0.518"],["64051.40","0.000"],["64051.50","0.882"],["64051.60","0.009"],["64051.70","0.020"],["64052.50","2.044"],["64052.60","0.002"],["64052.70","0.053"],["64053.10","0.052"],["64053.30","0.004"],["64053.50","0.000"],["64053.70","0.003"],["64054.00","0.746"],["64054.10","0.001"],["64054.20","0.000"],["64054.40","0.004"],["64054.60","0.002"],["64054.70","0.094"],["64054.80","0.003"],["64055.10","0.001"],["64055.50","0.000"],["64055.70","0.002"],["64055.80","0.000"],["64056.70","0.074"],["64057.40","0.002"],["64059.40","0.003"],["64059.50","1.919"]],"e":"depthUpdate","ps":"BTCUSDT","pu":11165395298468,"s":"BTCUSDT","st":1,"u":11165395326309}
{"E":1785353524736,"T":1785353524735,"U":11165395326423,"a":[["64059.60","14.004"],["64059.70","0.003"],["64060.10","0.341"],["64060.20","0.484"],["64060.30","0.004"],["64060.80","0.003"],["64061.00","0.030"],["64061.10","0.001"],["64061.30","0.000"],["64061.50","0.101"],["64061.70","0.001"],["64062.00","0.001"],["64062.10","0.014"],["64062.60","0.006"],["64062.70","0.003"],["64063.00","0.009"],["64063.10","0.001"],["64064.00","0.579"],["64064.10","0.712"],["64064.20","1.251"],["64064.30","1.121"],["64064.40","0.311"],["64064.70","1.072"],["64065.10","0.001"],["64065.20","0.004"],["64065.60","0.101"],["64066.10","0.001"],["64066.20","0.387"],["64066.30","0.000"],["64066.50","0.002"],["64066.80","0.021"],["64067.20","0.248"],["64067.30","0.511"],["64067.60","2.562"],["64067.80","0.003"],["64068.00","0.179"],["64068.30","0.008"],["64069.00","0.248"],["64069.10","0.003"],["64069.20","0.504"],["64069.50","0.169"],["64069.70","0.316"],["64069.80","0.102"],["64070.30","10.875"],["64070.60","0.002"],["64071.00","3.684"],["64071.10","3.098"],["64071.30","0.192"],["64071.90","0.001"],["64072.40","0.002"],["64073.20","0.003"],["64074.10","3.401"],["64074.70","0.002"],["64075.50","0.159"],["64075.70","0.055"],["64077.30","0.090"],["64077.50","0.105"],["64077.90","0.001"],["64078.60","0.194"],["64079.80","0.159"],["64081.40","0.096"],["64082.00","0.083"],["64086.00","0.009"],["64086.10","0.000"],["64086.80","0.001"],["64087.30","0.377"],["64090.10","0.000"],["64090.50","0.001"],["64091.20","0.007"],["64091.30","0.015"],["64091.40","0.006"],["64091.70","0.002"],["64093.50","0.030"],["64095.10","0.101"],["64096.20","0.004"],["64096.50","0.106"],["64097.00","0.006"],["64097.20","5.896"],["64098.10","0.490"],["64098.40","1.036"],["64099.70","0.002"],["64102.50","0.002"],["64107.60","0.115"],["64108.30","0.000"],["64110.80","0.001"],["64123.40","0.024"],["64123.90","0.056"],["64128.50","0.048"],["64134.50","0.370"],["64135.00","0.000"],["64159.20","0.165"],["64189.60","0.001"],["64191.60","0.000"],["64193.60","0.003"],["64195.60","0.000"],["64196.30","0.001"],["64197.60","0.822"],["64199.40","0.000"],["64199.60","0.000"],["64201.60","0.001"],["64203.60","0.000"],["64205.60","0.155"],["64207.60","0.020"],["64209.60","0.000"],["64315.80","0.120"],["64559.30","0.096"],["64697.40","0.140"],["64700.20","0.008"]],"b":[["1000.00","37.592"],["13556.70","0.364"],["13659.50","0.602"],["13746.60","0.252"],["13759.50","0.602"],["13854.70","0.252"],["13856.70","0.000"],["13959.50","0.448"],["57653.50","0.052"],["61497.10","0.003"],["62414.30","0.002"],["63213.00","0.002"],["63418.90","0.000"],["63721.60","1.458"],["63736.20","0.089"],["63736.40","0.001"],["63738.40","0.005"],["63739.20","0.180"],["63740.10","0.281"],["63784.50","0.000"],["63828.90","0.010"],["63851.30","0.117"],["63901.50","3.523"],["63903.50","0.001"],["63905.50","0.001"],["63907.50","2.340"],["63907.60","0.000"],["63909.50","0.034"],["63911.10","0.006"],["63911.50","0.002"],["63913.50","0.000"],["63914.20","0.002"],["63915.50","0.003"],["63917.50","0.000"],["63919.50","0.010"],["63921.50","0.008"],["63923.50","0.538"],["63925.50","0.000"],["63927.50","2.342"],["63929.50","0.051"],["63931.50","0.006"],["63977.10","0.276"],["63978.30","0.000"],["63980.60","3.983"],["63984.70","0.001"],["63987.30","0.389"],["63993.90","0.000"],["63994.50","0.016"],["63997.70","0.001"],["64005.70","0.008"],["64005.80","0.003"],["64007.70","0.060"],["64009.50","0.532"],["64010.70","0.196"],["64013.40","12.854"],["64013.90","0.003"],["64014.70","0.117"],["64015.10","3.104"],["64016.20","0.060"],["64017.30","0.010"],["64017.60","0.068"],["64019.20","1.046"],["64021.00","0.207"],["64022.10","0.950"],["64022.30","0.242"],["64023.90","0.283"],["64024.70","0.121"],["64027.20","0.564"],["64027.50","0.011"],["64028.10","0.001"],["64028.60","0.004"],["64029.20","4.203"],["64029.30","0.009"],["64029.90","0.944"],["64030.60","0.146"],["64030.70","0.002"],["64031.10","0.000"],["64032.60","0.006"],["64032.70","2.970"],["64032.80","0.009"],["64034.20","0.005"],["64035.70","0.056"],["64035.90","0.023"],["64037.00","0.471"],["64038.20","0.166"],["64039.70","0.313"],["64040.80","0.496"],["64041.30","0.324"],["64041.40","0.000"],["64042.90","1.256"],["64043.00","0.784"],["64043.30","0.384"],["64043.80","0.569"],["64044.10","0.014"],["64044.50","0.004"],["64044.60","2.156"],["64044.70","2.434"],["64045.40","0.390"],["64045.60","0.002"],["64046.20","0.000"],["64046.60","1.189"],["64047.20","0.016"],["64048.00","0.492"],["64048.10","2.437"],["64048.20","0.284"],["64048.30","0.033"],["64048.60","0.226"],["64048.90","0.001"],["64049.80","0.001"],["64050.10","0.022"],["64050.20","1.012"],["64050.70","0.001"],["64050.90","0.007"],["64051.10","0.001"],["64051.30","0.335"],["64051.40","0.000"],["64051.60","0.570"],["64051.70","0.742"],["64051.80","1.387"],["64052.10","0.003"],["64052.30","0.018"],["64052.40","0.001"],["64052.50","0.000"],["64052.70","0.013"],["64052.80","0.002"],["64052.90","0.001"],["64053.00","0.000"],["64053.10","0.052"],["64053.30","0.001"],["64053.60","0.004"],["64053.70","0.000"],["64054.00","0.485"],["64054.40","0.001"],["64056.30","0.001"],["64056.70","0.002"],["64056.90","0.002"],["64059.50","1.991"]],"e":"depthUpdate","ps":"BTCUSDT","pu":11165395326309,"s":"BTCUSDT","st":1,"u":11165395349195}
{"E":1785353524838,"T":1785353524836,"U":11165395349357,"a":[["64060.00","0.026"],["64061.00","0.007"],["64063.90","0.176"],["64064.00","0.559"],["64064.10","0.010"],["64066.20","0.390"],["64067.10","0.002"],["64067.20","0.677"],["64068.50","0.228"],["64069.10","0.003"],["64069.20","0.582"],["64070.60","0.082"],["64074.20","0.727"],["64075.50","0.002"],["64076.50","0.068"],["64077.30","0.010"],["64080.40","0.047"],["64083.30","0.052"],["64086.90","0.391"],["64088.10","0.004"],["64094.20","0.062"],["64094.80","0.122"],["64098.00","0.005"],["64107.60","0.037"],["64119.20","0.150"],["64126.60","0.537"],["64140.80","4.872"],["64140.90","24.324"],["64150.80","1.256"],["64151.90","0.041"],["64155.30","0.373"],["64156.00","0.499"],["64700.20","0.008"]],"b":[["13556.70","0.238"],["13659.50","0.728"],["13746.60","0.126"],["13759.50","0.714"],["13854.70","0.140"],["13959.50","0.574"],["51248.00","0.000"],["57653.50","0.052"],["60857.00","0.000"],["61497.10","0.000"],["63418.90","0.000"],["63739.20","0.180"],["63851.30","0.117"],["63976.10","22.687"],["63977.10","3.603"],["63980.60","0.970"],["64006.70","0.060"],["64014.70","0.000"],["64022.90","0.027"],["64026.20","0.000"],["64028.60","0.084"],["64031.50","0.354"],["64031.70","0.690"],["64032.50","0.000"],["64033.20","0.037"],["64033.60","0.055"],["64034.70","0.132"],["64035.20","1.401"],["64036.10","0.007"],["64037.80","0.003"],["64038.70","0.047"],["64038.80","0.064"],["64040.80","0.305"],["64042.60","0.297"],["64043.90","0.235"],["64044.80","0.012"],["64047.20","0.207"],["64048.00","0.258"],["64048.10","2.437"],["64048.20","0.838"],["64048.30","0.033"],["64048.40","0.002"],["64048.50","0.000"],["64049.40","0.094"],["64050.10","0.000"],["64051.00","1.604"],["64051.40","2.340"],["64051.50","0.882"],["64051.60","0.009"],["64051.70","0.177"],["64051.90","0.000"],["64053.10","0.052"],["64054.00","0.835"],["64058.70","0.004"],["64058.90","0.004"],["64059.50","1.999"]],"e":"depthUpdate","ps":"BTCUSDT","pu":11165395349195,"s":"BTCUSDT","st":1,"u":11165395363421}
{"E":1785353524940,"T":1785353524938,"U":11165395364330,"a":[["64059.60","8.231"],["64059.70","0.004"],["64060.10","0.235"],["64061.00","0.002"],["64061.40","0.001"],["64061.50","0.095"],["64061.80","0.013"],["64062.00","0.001"],["64063.00","0.008"],["64063.50","0.062"],["64063.90","0.000"],["64064.00","0.006"],["64064.10","2.586"],["64064.20","3.653"],["64064.30","0.377"],["64064.50","0.002"],["64064.80","0.005"],["64065.20","0.098"],["64065.30","0.004"],["64065.40","0.021"],["64065.50","0.002"],["64067.00","0.002"],["64067.10","3.257"],["64067.20","0.006"],["64067.50","0.004"],["64067.60","0.881"],["64068.50","0.111"],["64068.60","0.086"],["64068.80","0.021"],["64069.00","0.373"],["64069.10","1.040"],["64069.20","0.081"],["64069.70","0.314"],["64070.00","0.625"],["64070.30","0.313"],["64070.50","1.761"],["64070.60","0.002"],["64070.90","0.001"],["64071.00","4.342"],["64071.90","0.563"],["64073.10","0.007"],["64073.50","0.158"],["64074.00","0.004"],["64074.10","3.467"],["64077.30","0.010"],["64077.40","0.093"],["64078.20","0.134"],["64078.30","0.002"],["64078.50","2.527"],["64078.60","0.159"],["64080.30","0.019"],["64082.00","0.427"],["64082.70","4.101"],["64084.80","0.030"],["64086.40","0.044"],["64094.80","0.002"],["64096.50","0.036"],["64102.00","0.752"],["64104.20","0.087"],["64108.30","0.012"],["64153.90","0.004"],["64164.00","0.037"],["64172.80","1.449"],["64174.80","3.903"],["64186.20","1.118"],["64188.30","0.001"],["64362.00","0.151"],["64559.30","0.412"],["64628.80","0.464"],["64700.20","0.008"],["64902.30","1.553"]],"b":[["1000.00","37.592"],["13556.70","0.126"],["13659.50","0.840"],["13746.60","0.014"],["13759.50","0.840"],["13854.70","0.014"],["13959.50","0.686"],["57653.50","0.052"],["60839.70","0.002"],["60853.80","0.000"],["61497.10","0.003"],["62778.40","0.012"],["62873.80","1.031"],["63117.80","0.554"],["63243.50","0.792"],["63418.90","0.000"],["63920.80","18.332"],["63934.20","0.488"],["63971.70","22.245"],["63973.30","4.088"],["63976.10","0.167"],["63977.10","0.276"],["63996.30","0.001"],["64005.00","0.311"],["64007.10","0.061"],["64007.80","0.026"],["64008.30","0.042"],["64013.40","2.854"],["64014.70","0.039"],["64015.10","1.752"],["64015.60","0.001"],["64018.60","0.104"],["64020.00","2.018"],["64023.10","2.340"],["64023.80","10.073"],["64024.70","0.001"],["64025.40","0.001"],["64025.60","2.843"],["64027.20","0.002"],["64029.90","0.009"],["64030.00","0.785"],["64031.70","1.568"],["64032.20","2.527"],["64033.00","0.547"],["64033.90","0.099"],["64035.50","0.001"],["64038.30","0.000"],["64042.60","0.294"],["64043.90","0.001"],["64044.80","0.005"],["64044.90","0.020"],["64045.60","0.064"],["64046.90","0.480"],["64047.20","0.016"],["64048.00","0.258"],["64048.10","2.439"],["64048.20","0.108"],["64048.30","0.033"],["64048.60","0.226"],["64048.80","0.002"],["64049.00","0.001"],["64049.40","0.000"],["64050.00","0.125"],["64050.10","0.000"],["64050.70","0.314"],["64051.00","0.800"],["64051.40","2.340"],["64051.50","0.882"],["64051.60","0.726"],["64051.70","0.177"],["64051.80","0.020"],["64051.90","1.347"],["64052.00","0.022"],["64053.10","0.013"],["64053.50","0.881"],["64053.60","0.005"],["64054.00","0.003"],["64054.10","0.158"],["64054.20","0.929"],["64054.50","0.048"],["64055.50","0.862"],["64055.70","0.001"],["64059.50","1.991"]],"e":"depthUpdate","ps":"BTCUSDT","pu":11165395363421,"s":"BTCUSDT","st":1,"u":11165395384235}
{"E":1785353525042,"T":1785353525040,"U":11165395384396,"a":[["64059.60","8.076"],["64059.70","0.181"],["64060.10","0.468"],["64060.60","0.001"],["64061.40","0.006"],["64061.80","0.007"],["64063.40","0.002"],["64063.50","0.218"],["64063.60","0.863"],["64064.00","0.887"],["64064.10","2.040"],["64064.30","0.376"],["64064.40","0.155"],["64064.60","0.546"],["64065.20","0.004"],["64066.60","0.081"],["64067.00","0.283"],["64067.10","2.376"],["64067.50","0.006"],["64068.40","0.007"],["64069.00","0.248"],["64069.10","0.003"],["64070.40","2.346"],["64070.50","1.683"],["64071.10","3.103"],["64073.50","0.315"],["64073.60","0.709"],["64074.00","0.161"],["64075.00","0.005"],["64077.00","0.003"],["64077.30","0.010"],["64078.20","0.174"],["64078.50","0.527"],["64079.80","0.002"],["64079.90","0.535"],["64085.10","0.056"],["64094.90","0.574"],["64102.00","0.632"],["64103.30","0.678"],["64103.50","0.001"],["64103.60","0.027"],["64104.50","1.279"],["64107.30","0.002"],["64109.10","0.009"],["64140.80","1.345"],["64140.90","0.000"],["64141.20","5.450"],["64145.30","0.000"],["64173.30","0.229"],["64193.20","0.761"],["64193.50","0.384"],["64700.20","0.008"]],"b":[["1000.00","37.592"],["13556.70","0.000"],["13559.50","0.112"],["13659.50","0.742"],["13746.60","0.000"],["13759.50","0.952"],["13846.60","0.392"],["13848.40","0.000"],["13851.30","0.000"],["13853.50","0.000"],["13854.70","0.000"],["13959.50","0.812"],["51247.60","0.000"],["57653.50","0.052"],["63220.90","0.001"],["63229.90","0.070"],["63418.90","0.000"],["63739.20","0.190"],["63971.70","0.000"],["63973.30","0.936"],["63973.90","22.245"],["63979.80","0.007"],["63981.80","0.001"],["63981.90","0.039"],["64007.20","0.570"],["64007.50","1.042"],["64010.10","0.319"],["64020.00","0.018"],["64023.80","0.003"],["64024.10","2.109"],["64027.40","0.016"],["64028.00","0.606"],["64030.00","0.223"],["64030.70","0.937"],["64030.90","0.382"],["64031.70","0.633"],["64032.00","2.551"],["64033.20","0.002"],["64036.20","0.610"],["64036.40","0.163"],["64040.50","0.035"],["64043.60","0.010"],["64047.20","0.207"],["64047.90","0.060"],["64048.00","0.263"],["64048.40","0.236"],["64048.60","0.228"],["64049.40","0.094"],["64050.00","0.031"],["64050.70","0.001"],["64051.20","0.007"],["64054.10","0.157"],["64055.30","0.003"],["64055.60","0.003"],["64059.50","2.119"]],"e":"depthUpdate","ps":"BTCUSDT","pu":11165395384235,"s":"BTCUSDT","st":1,"u":11165395398576}
{"E":1785353525144,"T":1785353525142,"U":11165395398863,"a":[["64059.60","7.793"],["64059.80","0.023"],["64060.60","0.000"],["64061.40","0.001"],["64061.50","0.096"],["64061.80","0.001"],["64062.00","0.001"],["64062.40","0.009"],["64062.90","0.485"],["64063.00","0.000"],["64063.40","0.022"],["64063.60","0.060"],["64063.90","1.249"],["64064.00","0.014"],["64064.20","2.406"],["64064.60","0.000"],["64064.70","0.137"],["64065.20","0.002"],["64065.30","0.002"],["64066.30","0.935"],["64066.90","0.185"],["64067.00","0.704"],["64067.10","2.356"],["64067.30","0.391"],["64069.10","0.128"],["64069.20","0.082"],["64070.30","0.470"],["64071.10","3.098"],["64073.50","0.315"],["64073.70","1.913"],["64074.00","0.161"],["64076.90","0.248"],["64079.90","0.378"],["64080.30","10.019"],["64081.40","0.094"],["64083.40","0.556"],["64085.10","0.056"],["64107.60","0.115"],["64131.40","0.000"],["64143.20","24.321"],["64159.20","0.009"],["64159.40","0.503"],["64193.20","0.722"],["64193.50","0.423"],["64201.60","0.882"],["64203.10","0.120"],["64203.60","0.881"],["64205.60","1.036"],["64207.60","0.901"],["64209.60","0.881"],["64211.60","0.881"],["64213.60","0.882"],["64243.10","0.822"],["64243.30","1.529"],["64390.50","16.643"],["64487.10","21.373"],["64533.60","0.322"],["64559.30","0.096"],["64603.20","25.578"],["64700.20","0.008"],["65340.70","2.809"],["65348.10","0.007"]],"b":[["13554.70","0.182"],["13559.50","0.224"],["13659.50","0.630"],["13759.50","1.078"],["13846.60","0.266"],["13959.50","0.924"],["57653.50","0.052"],["61497.10","0.000"],["62778.40","0.015"],["63418.90","0.000"],["63510.80","25.860"],["63625.30","21.611"],["63720.90","16.454"],["63791.10","13.621"],["63791.70","2.226"],["63828.90","0.189"],["63954.80","0.000"],["63955.00","0.003"],["63973.90","0.000"],["63976.10","22.412"],["64001.80","0.118"],["64005.00","0.101"],["64010.70","0.195"],["64012.20","0.210"],["64014.60","1.265"],["64023.10","2.342"],["64023.80","0.001"],["64024.10","0.109"],["64024.30","0.020"],["64025.60","1.866"],["64026.80","0.001"],["64027.60","0.193"],["64029.90","10.009"],["64030.70","0.002"],["64033.50","1.614"],["64048.00","0.258"],["64048.40","0.002"],["64048.80","0.002"],["64049.40","0.000"],["64049.60","0.236"],["64050.30","0.025"],["64050.70","0.001"],["64050.80","0.002"],["64050.90","0.007"],["64051.10","0.001"],["64051.80","0.017"],["64051.90","1.441"],["64052.00","0.022"],["64052.10","0.000"],["64052.30","0.051"],["64053.30","0.001"],["64054.00","0.006"],["64054.10","0.160"],["64054.40","0.010"],["64057.40","0.222"],["64059.50","3.928"]],"e":"depthUpdate","ps":"BTCUSDT","pu":11165395398576,"s":"BTCUSDT","st":1,"u":11165395416749}
{"E":1785353525246,"T":1785353525245,"U":11165395417046,"a":[["64059.60","5.388"],["64059.70","0.179"],["64059.80","0.001"],["64060.00","0.097"],["64060.10","0.151"],["64060.20","0.390"],["64060.30","0.004"],["64060.40","0.024"],["64061.60","0.000"],["64062.80","0.015"],["64062.90","0.096"],["64063.40","0.002"],["64063.60","0.001"],["64063.70","0.002"],["64063.80","0.007"],["64063.90","0.000"],["64064.00","0.054"],["64064.10","2.020"],["64064.20","2.344"],["64064.40","0.145"],["64064.70","0.002"],["64064.80","0.004"],["64065.40","0.001"],["64065.50","0.000"],["64065.70","0.326"],["64066.20","0.387"],["64066.40","0.001"],["64066.60","0.001"],["64066.80","0.005"],["64066.90","0.185"],["64067.10","2.358"],["64067.20","0.007"],["64067.30","0.157"],["64068.00","0.059"],["64068.50","0.095"],["64068.80","0.001"],["64069.20","0.097"],["64069.80","0.102"],["64069.90","0.064"],["64070.00","0.508"],["64070.30","0.158"],["64070.50","1.763"],["64070.70","0.136"],["64071.30","0.156"],["64071.70","0.118"],["64072.20","0.346"],["64072.30","0.530"],["64072.80","0.386"],["64073.00","0.001"],["64073.50","0.629"],["64073.60","0.711"],["64075.20","0.015"],["64075.60","0.198"],["64080.30","0.021"],["64081.20","2.368"],["64081.70","0.549"],["64082.50","0.547"],["64083.30","0.002"],["64086.00","0.001"],["64086.10","0.000"],["64086.70","0.007"],["64086.80","0.001"],["64087.00","0.003"],["64087.40","0.008"],["64088.50","10.001"],["64089.80","0.063"],["64090.00","0.114"],["64090.40","0.429"],["64091.50","0.003"],["64092.00","0.635"],["64092.80","0.007"],["64094.90","0.454"],["64095.30","0.610"],["64096.20","0.003"],["64096.40","0.085"],["64097.00","0.002"],["64097.20","5.900"],["64098.10","0.178"],["64101.40","0.120"],["64107.60","0.037"],["64143.20","0.003"],["64152.00","24.320"],["64153.90","0.001"],["64199.60","0.000"],["64201.60","0.001"],["64203.60","0.000"],["64205.10","0.027"],["64205.60","0.155"],["64207.60","0.020"],["64209.60","0.000"],["64210.00","0.011"],["64211.60","0.000"],["64213.60","0.001"],["64264.60","0.216"],["64265.00","0.378"],["64265.50","0.000"],["64267.80","0.124"],["64377.10","2.010"],["64377.60","0.103"],["64379.90","3.832"],["64697.40","0.040"],["64700.20","0.008"],["64751.80","33.185"],["64906.20","0.772"]],"b":[["1000.00","37.592"],["13554.70","0.056"],["13559.50","0.350"],["13659.50","0.504"],["13759.50","1.190"],["13846.60","0.154"],["13959.50","1.050"],["57653.50","0.052"],["61497.10","0.003"],["63364.70","32.475"],["63418.90","0.000"],["63682.80","0.000"],["63694.60","0.452"],["63981.80","0.040"],["63981.90","0.000"],["63993.30","0.416"],["64002.20","0.211"],["64004.30","0.000"],["64005.70","0.004"],["64005.80","0.007"],["64012.20","0.000"],["64012.50","0.002"],["64017.30","0.007"],["64017.50","0.044"],["64021.40","1.084"],["64022.10","0.946"],["64022.30","0.246"],["64022.50","0.542"],["64025.40","0.001"],["64027.50","0.016"],["64029.20","4.201"],["64029.90","0.011"],["64031.60","0.001"],["64031.80","0.042"],["64033.60","0.005"],["64034.70","0.012"],["64035.70","0.007"],["64035.80","0.329"],["64036.00","0.545"],["64037.40","0.002"],["64038.00","2.344"],["64039.50","0.001"],["64040.60","0.005"],["64040.70","0.016"],["64041.40","0.002"],["64041.50","0.050"],["64041.70","4.393"],["64041.90","0.004"],["64042.20","0.021"],["64042.80","0.554"],["64043.10","0.121"],["64043.30","0.433"],["64044.80","0.005"],["64044.90","0.000"],["64045.60","0.002"],["64047.20","0.001"],["64048.00","0.066"],["64048.20","2.541"],["64049.50","0.828"],["64049.60","0.002"],["64049.80","0.001"],["64049.90","0.096"],["64050.00","0.008"],["64050.30","0.002"],["64050.40","0.000"],["64050.50","0.096"],["64050.60","0.191"],["64050.80","0.315"],["64050.90","0.243"],["64051.00","1.137"],["64051.10","0.001"],["64051.30","0.355"],["64051.40","0.000"],["64051.50","0.882"],["64051.60","0.009"],["64051.70","2.519"],["64051.80","0.611"],["64051.90","0.302"],["64052.00","0.002"],["64052.20","0.099"],["64052.30","0.066"],["64052.50","0.000"],["64052.70","0.001"],["64052.90","0.384"],["64053.40","0.001"],["64053.50","0.975"],["64053.60","0.196"],["64054.00","0.006"],["64054.20","0.694"],["64054.40","0.013"],["64054.50","0.009"],["64054.70","0.094"],["64055.60","0.003"],["64055.70","0.001"],["64056.30","0.001"],["64057.40","0.002"],["64057.50","0.881"],["64057.60","0.434"],["64059.40","0.004"],["64059.50","4.551"]],"e":"depthUpdate","ps":"BTCUSDT","pu":11165395416749,"s":"BTCUSDT","st":1,"u":11165395438032}
